{"rx":1788854549236930173, "m":{"e":"depthUpdate","E":1788854549214,"s":"BTCUSDT","U":99829863764,"u":99829863773,"b":[["77113.42000000","0.00032000"],["70458.96000000","0.00313000"],["62630.19000000","0.00217000"],["62630.00000000","0.01596000"]],"a":[["78287.74000000","0.21638000"],["78294.27000000","0.21090000"],["78295.56000000","0.00000000"]]}}
{"rx":1788854549337319530, "m":{"e":"depthUpdate","E":1788854549314,"s":"BTCUSDT","U":99829863774,"u":99829863844,"b":[["78287.73000000","12.44992000"],["78287.01000000","0.00255000"],["78286.51000000","0.00014000"],["78264.28000000","0.34508000"],["78263.76000000","0.00408000"],["78253.99000000","1.26548000"],["78250.94000000","0.55714000"],["78235.23000000","0.00000000"],["78215.10000000","0.11556000"],["78214.93000000","0.00000000"],["78210.95000000","1.00234000"],["78207.15000000","1.30661000"],["78206.65000000","4.03962000"],["78203.88000000","0.03373000"],["78200.43000000","0.00138000"],["78098.83000000","0.00000000"],["77113.42000000","0.00032000"],["70458.96000000","0.00304000"],["70458.95000000","0.00009000"],["62630.00000000","0.01596000"]],"a":[["78287.74000000","0.02373000"],["78291.42000000","0.00000000"],["78294.27000000","0.00000000"],["78295.57000000","0.00286000"],["78296.63000000","0.00000000"],["78297.99000000","0.00000000"],["78298.56000000","0.00400000"],["78298.57000000","0.01200000"],["78298.58000000","0.67105000"],["78298.59000000","0.00000000"],["78298.92000000","0.00000000"],["78299.66000000","0.00030000"],["78299.93000000","0.00000000"],["78300.07000000","0.01327000"],["78300.53000000","0.00000000"],["78301.00000000","0.00000000"],["78301.01000000","0.00000000"],["78301.02000000","0.00000000"],["78301.42000000","0.00000000"],["78301.91000000","0.00638000"],["78301.92000000","0.00000000"],["78301.94000000","0.00400000"],["78302.73000000","0.00400000"],["78304.24000000","0.00638000"],["78310.67000000","0.00400000"],["78312.98000000","0.02000000"],["78375.45000000","1.19876000"]]}}
{"rx":1788854549438089942, "m":{"e":"depthUpdate","E":1788854549414,"s":"BTCUSDT","U":99829863845,"u":99829864124,"b":[["78288.99000000","8.00830000"],["78288.98000000","0.00027000"],["78288.97000000","0.00013000"],["78288.95000000","0.05000000"],["78288.90000000","0.05000000"],["78287.80000000","0.79445000"],["78287.79000000","5.15185000"],["78287.78000000","0.00000000"],["78287.75000000","0.00000000"],["78287.74000000","0.97364000"],["78287.73000000","1.05304000"],["78287.72000000","0.00000000"],["78287.71000000","0.00000000"],["78287.70000000","0.00014000"],["78287.65000000","0.00014000"],["78287.19000000","0.02142000"],["78287.01000000","0.00000000"],["78286.51000000","0.00000000"],["78286.48000000","0.07514000"],["78286.47000000","0.13666000"],["78285.47000000","0.01325000"],["78285.40000000","0.00000000"],["78281.16000000","0.00008000"],["78278.64000000","0.20250000"],["78272.96000000","0.00000000"],["78272.75000000","0.00000000"],["78268.37000000","0.50678000"],["78255.23000000","0.00000000"],["78239.61000000","0.00628000"],["78227.73000000","0.00000000"],["78190.10000000","0.00000000"],["78051.85000000","0.00007000"],["77113.42000000","0.00000000"],["77113.41000000","0.00000000"],["70458.96000000","0.00000000"],["62630.19000000","0.00186000"]],"a":[["78287.74000000","0.00000000"],["78287.75000000","0.00000000"],["78287.76000000","0.00000000"],["78287.79000000","0.00000000"],["78287.80000000","0.00000000"],["78289.00000000","0.05168000"],["78289.01000000","0.00049000"],["78290.24000000","0.00014000"],["78292.10000000","0.00014000"],["78294.00000000","0.03014000"],["78294.31000000","0.00000000"],["78296.00000000","0.03014000"],["78296.83000000","0.00008000"],["78298.56000000","0.00000000"],["78298.57000000","0.00000000"],["78301.91000000","0.00000000"],["78302.18000000","0.00000000"],["78303.39000000","0.00638000"],["78305.32000000","0.01600000"],["78318.26000000","0.00000000"],["78322.25000000","0.00000000"],["78327.00000000","0.00400000"],["78327.69000000","0.00014000"],["78329.00000000","0.01000000"],["78344.07000000","0.03829000"],["78355.67000000","0.00000000"],["78357.27000000","0.00317000"],["78383.84000000","0.00007000"],["78432.48000000","0.18165000"],["78435.92000000","0.00127000"],["79462.06000000","0.00000000"]]}}
{"rx":1788854549537888901, "m":{"e":"depthUpdate","E":1788854549514,"s":"BTCUSDT","U":99829864125,"u":99829864253,"b":[["78288.99000000","8.02625000"],["78288.95000000","0.05014000"],["78288.90000000","0.05014000"],["78288.66000000","0.00400000"],["78288.28000000","0.00000000"],["78287.81000000","0.00800000"],["78287.80000000","0.00014000"],["78287.79000000","1.34625000"],["78287.74000000","0.17933000"],["78287.73000000","1.03408000"],["78287.70000000","0.00000000"],["78287.65000000","0.00000000"],["78287.45000000","0.00255000"],["78287.19000000","0.02156000"],["78286.47000000","0.13652000"],["78286.02000000","1.86192000"],["78286.00000000","0.03048000"],["78283.18000000","0.00000000"],["78282.13000000","0.68632000"],["78281.60000000","0.00000000"],["78280.34000000","0.00000000"],["78279.09000000","0.00000000"],["78277.84000000","0.00000000"],["78274.12000000","1.95596000"],["78272.16000000","0.10262000"],["78269.24000000","0.00000000"],["78267.29000000","0.00000000"],["78253.56000000","0.00000000"],["78249.00000000","0.01000000"],["78248.00000000","0.03000000"],["78052.43000000","0.00007000"],["78048.52000000","0.00000000"],["77114.66000000","0.00008000"],["73111.37000000","0.00000000"],["70460.00000000","0.01024000"],["62631.20000000","0.00124000"],["62631.19000000","0.00000000"]],"a":[["78289.00000000","0.20846000"],["78289.01000000","0.00056000"],["78290.24000000","0.00000000"],["78290.25000000","0.00014000"],["78291.50000000","0.00014000"],["78292.00000000","0.03014000"],["78292.10000000","0.00000000"],["78292.64000000","0.00014000"],["78295.57000000","0.00000000"],["78296.26000000","0.00000000"],["78296.28000000","0.13342000"],["78296.29000000","0.12785000"],["78296.83000000","0.00294000"],["78299.47000000","0.00000000"],["78301.43000000","0.00000000"],["78303.10000000","0.00255000"],["78303.40000000","0.00000000"],["78303.93000000","0.00000000"],["78304.66000000","0.00286000"],["78306.13000000","0.00000000"],["78311.23000000","0.00000000"],["78312.49000000","0.00286000"],["78319.06000000","0.00000000"],["78320.32000000","0.00286000"]]}}
{"rx":1788854549643013104, "m":{"e":"depthUpdate","E":1788854549614,"s":"BTCUSDT","U":99829864254,"u":99829864322,"b":[["78288.99000000","8.78853000"],["78288.98000000","0.00041000"],["78288.90000000","0.05014000"],["78287.81000000","0.00814000"],["78287.80000000","0.00000000"],["78287.79000000","1.18701000"],["78287.73000000","0.87328000"],["78283.55000000","0.00452000"],["78282.29000000","0.00754000"],["78281.04000000","0.00905000"],["78279.79000000","0.00905000"],["78115.61000000","0.00000000"],["77114.66000000","0.00016000"],["70460.10000000","0.00016000"],["70458.95000000","0.00000000"],["62631.00000000","0.00200000"],["62630.19000000","0.00155000"]],"a":[["78289.00000000","0.21933000"],["78289.01000000","0.00070000"],["78290.25000000","0.00000000"],["78290.26000000","0.01800000"],["78291.50000000","0.00000000"],["78291.51000000","0.02160000"],["78292.76000000","0.02160000"],["78293.72000000","0.06584000"],["78296.00000000","0.03014000"],["78296.28000000","0.13356000"],["78296.61000000","0.31878000"],["78296.83000000","0.20544000"],["78298.57000000","0.47751000"],["78301.46000000","0.00000000"],["78301.50000000","0.00000000"],["78477.67000000","0.00000000"],["78513.26000000","0.00007000"],["78517.17000000","0.00000000"]]}}
{"rx":1788854549737049237, "m":{"e":"depthUpdate","E":1788854549714,"s":"BTCUSDT","U":99829864323,"u":99829864380,"b":[["78288.99000000","8.78934000"],["78287.45000000","0.00000000"],["77114.66000000","0.00024000"],["70460.10000000","0.00032000"],["62631.00000000","0.00000000"]],"a":[["78289.00000000","0.14608000"],["78290.26000000","0.01814000"],["78291.51000000","0.02174000"],["78292.65000000","0.06879000"],["78292.76000000","0.02174000"],["78296.00000000","0.03000000"],["78296.12000000","0.47751000"],["78296.26000000","0.32792000"],["78296.27000000","0.00000000"],["78296.28000000","0.00000000"],["78296.29000000","0.12771000"],["78296.61000000","0.31864000"],["78296.70000000","0.02128000"],["78296.83000000","0.20544000"],["78298.57000000","0.00000000"],["78301.46000000","0.00000000"],["78301.50000000","0.00000000"],["78302.05000000","0.00255000"],["78303.10000000","0.00000000"],["79463.34000000","0.00030000"]]}}
{"rx":1788854549839039809, "m":{"e":"depthUpdate","E":1788854549814,"s":"BTCUSDT","U":99829864381,"u":99829864400,"b":[["78279.29000000","0.02000000"],["78266.71000000","0.00000000"],["78122.23000000","4.57265000"],["77114.66000000","0.00032000"],["62630.19000000","0.00124000"]],"a":[["78289.00000000","0.14594000"],["78289.38000000","0.00000000"],["78290.94000000","0.00007000"],["78295.71000000","0.00000000"],["78296.11000000","0.20108000"],["78296.12000000","0.00000000"],["78296.26000000","0.00000000"],["78296.70000000","0.00000000"],["78299.66000000","0.00000000"],["78300.35000000","0.00031000"],["78477.40000000","4.52188000"]]}}
{"rx":1788854549938814442, "m":{"e":"depthUpdate","E":1788854549914,"s":"BTCUSDT","U":99829864401,"u":99829864423,"b":[["78288.99000000","8.78942000"],["78128.63000000","0.00000000"],["78079.17000000","0.02000000"],["77114.66000000","0.00040000"],["73187.23000000","0.00061000"],["70460.10000000","0.00048000"]],"a":[["78289.00000000","0.04103000"],["78296.11000000","0.13428000"],["78296.83000000","0.00008000"],["78300.07000000","0.00000000"],["78300.26000000","0.00000000"],["78300.35000000","0.00000000"],["78301.10000000","0.00031000"],["78301.94000000","0.00000000"],["78302.78000000","0.00400000"],["78304.66000000","0.00000000"],["78312.49000000","0.00000000"],["78320.32000000","0.00000000"]]}}
{"rx":1788854550038586551, "m":{"e":"depthUpdate","E":1788854550014,"s":"BTCUSDT","U":99829864424,"u":99829864457,"b":[["78280.60000000","0.00000000"],["78274.17000000","0.00007000"],["78215.09000000","0.08329000"],["77114.66000000","0.00040000"],["70460.00000000","0.01054000"],["62631.20000000","0.00248000"],["62630.19000000","0.00093000"]],"a":[["78289.00000000","0.04103000"],["78292.65000000","0.00014000"],["78294.82000000","0.00000000"],["78296.81000000","0.00000000"],["78296.83000000","0.00236000"],["78297.67000000","0.00007000"],["78300.29000000","0.00000000"],["78304.66000000","0.00228000"],["78312.49000000","0.00228000"],["78320.32000000","0.00228000"],["78349.35000000","0.04400000"],["86422.88000000","0.22692000"]]}}
{"rx":1788854550137071914, "m":{"e":"depthUpdate","E":1788854550114,"s":"BTCUSDT","U":99829864458,"u":99829864498,"b":[["78265.00000000","0.70000000"],["78264.00000000","0.03000000"],["77583.14000000","0.00000000"],["77114.66000000","0.00032000"],["77114.65000000","0.00030000"],["70460.10000000","0.00064000"],["70460.00000000","0.01024000"]],"a":[["78289.00000000","0.04081000"],["78289.01000000","0.00063000"],["78290.25000000","0.00014000"],["78292.33000000","0.00801000"],["78292.64000000","0.00000000"],["78292.65000000","0.00000000"],["78293.72000000","0.06598000"],["78299.48000000","0.00000000"],["78300.74000000","0.00007000"],["78301.46000000","0.00000000"],["78301.50000000","0.00000000"],["78302.05000000","0.00000000"],["78302.73000000","0.00000000"],["78303.16000000","0.00255000"],["78303.72000000","0.00400000"],["78417.11000000","0.00000000"],["86422.88000000","0.24583000"]]}}
{"rx":1788854550237255845, "m":{"e":"depthUpdate","E":1788854550214,"s":"BTCUSDT","U":99829864499,"u":99829864514,"b":[["78079.18000000","0.00802000"],["78075.15000000","0.00000000"],["77114.66000000","0.00032000"],["70460.10000000","0.00089000"],["70460.00000000","0.01024000"],["62630.19000000","0.00062000"]],"a":[["78289.00000000","0.02988000"],["78296.00000000","0.03014000"],["78417.11000000","0.10344000"],["78497.89000000","0.00000000"],["84202.54000000","0.03094000"]]}}
{"rx":1788854550337755398, "m":{"e":"depthUpdate","E":1788854550314,"s":"BTCUSDT","U":99829864515,"u":99829864566,"b":[["78288.99000000","7.75416000"],["78288.90000000","0.00014000"],["78287.79000000","0.52932000"],["78287.73000000","0.55386000"],["78265.37000000","0.00000000"],["78262.57000000","0.02517000"],["77114.66000000","0.00032000"],["70460.00000000","0.01024000"]],"a":[["78289.00000000","0.01280000"],["78289.38000000","0.00007000"],["78301.46000000","0.47751000"],["78305.31000000","0.01200000"],["78305.32000000","0.01200000"],["78307.94000000","0.00000000"],["78322.25000000","0.00000000"],["78498.24000000","0.00000000"],["84202.54000000","0.03536000"]]}}
{"rx":1788854550444809614, "m":{"e":"depthUpdate","E":1788854550414,"s":"BTCUSDT","U":99829864567,"u":99829864599,"b":[["78288.99000000","7.73416000"],["78288.95000000","0.05014000"],["78288.90000000","0.05000000"],["78287.81000000","0.00014000"],["78286.47000000","0.13666000"],["78286.03000000","0.00800000"],["77114.66000000","0.00032000"],["70460.10000000","0.00105000"],["70460.00000000","0.01024000"],["62630.19000000","0.00031000"]],"a":[["78289.00000000","0.01295000"],["78301.45000000","0.01600000"],["78305.31000000","0.00800000"],["78305.32000000","0.00000000"],["78319.87000000","0.00000000"],["78498.22000000","0.00000000"]]}}
{"rx":1788854550541256331, "m":{"e":"depthUpdate","E":1788854550514,"s":"BTCUSDT","U":99829864600,"u":99829864624,"b":[["78288.99000000","7.73544000"],["78288.95000000","0.05014000"],["78288.90000000","0.05014000"],["78287.81000000","0.00000000"],["78286.47000000","0.13666000"],["78212.01000000","0.00000000"],["78132.44000000","0.00000000"],["77114.66000000","0.00032000"],["72040.91000000","0.00014000"],["70460.00000000","0.01024000"],["62631.19000000","0.00020000"]],"a":[["78289.00000000","0.01280000"],["78301.46000000","0.00000000"],["78371.50000000","0.25548000"],["78379.45000000","0.00000000"]]}}
{"rx":1788854550638202485, "m":{"e":"depthUpdate","E":1788854550614,"s":"BTCUSDT","U":99829864625,"u":99829864650,"b":[["78211.13000000","0.00200000"],["78132.46000000","0.00120000"],["77114.66000000","0.00032000"],["70460.10000000","0.00121000"],["62631.19000000","0.00000000"],["62631.00000000","0.00000000"],["62630.19000000","0.00000000"]],"a":[["78301.44000000","0.47751000"],["78301.45000000","0.00000000"],["78305.32000000","0.01600000"],["78497.41000000","0.00000000"]]}}
{"rx":1788854550737251837, "m":{"e":"depthUpdate","E":1788854550714,"s":"BTCUSDT","U":99829864651,"u":99829864672,"b":[["78288.31000000","0.00255000"],["78287.75000000","0.84788000"],["77114.66000000","0.00032000"]],"a":[["78301.43000000","0.01600000"],["78301.44000000","0.00000000"],["78305.32000000","0.00000000"],["78305.95000000","0.00408000"],["78335.24000000","1.79314000"],["78497.84000000","0.00000000"],["78498.14000000","0.00000000"],["79463.34000000","0.00030000"]]}}
{"rx":1788854550839288996, "m":{"e":"depthUpdate","E":1788854550814,"s":"BTCUSDT","U":99829864673,"u":99829866157,"b":[["78299.99000000","4.46773000"],["78299.98000000","0.00027000"],["78299.97000000","0.00013000"],["78299.76000000","0.00014000"],["78299.60000000","0.00000000"],["78299.28000000","0.00000000"],["78298.99000000","0.20653000"],["78298.98000000","0.07500000"],["78298.97000000","0.30669000"],["78298.83000000","0.00255000"],["78298.59000000","0.00638000"],["78298.58000000","0.37581000"],["78298.57000000","0.00078000"],["78298.55000000","0.05000000"],["78298.50000000","0.05000000"],["78298.34000000","0.06025000"],["78297.99000000","0.14357000"],["78297.70000000","0.00400000"],["78297.21000000","0.00000000"],["78296.82000000","0.00000000"],["78296.60000000","0.00000000"],["78296.28000000","0.00000000"],["78296.14000000","0.00000000"],["78296.10000000","0.00000000"],["78296.03000000","0.00000000"],["78296.00000000","0.21038000"],["78295.99000000","0.00014000"],["78295.79000000","0.00000000"],["78295.77000000","0.00014000"],["78295.76000000","0.00000000"],["78295.50000000","0.03000000"],["78295.44000000","0.00400000"],["78295.16000000","0.00000000"],["78295.00000000","0.10419000"],["78294.26000000","0.15679000"],["78294.00000000","0.15187000"],["78293.99000000","2.30437000"],["78293.71000000","0.00014000"],["78293.65000000","0.00000000"],["78293.30000000","0.00026000"],["78293.18000000","0.00400000"],["78292.76000000","0.00000000"],["78292.75000000","0.00014000"],["78292.47000000","0.00008000"],["78292.32000000","0.16342000"],["78292.11000000","0.01312000"],["78292.00000000","0.07500000"],["78291.99000000","0.00085000"],["78291.98000000","0.34311000"],["78291.97000000","0.00000000"],["78291.84000000","1.57637000"],["78291.83000000","0.00000000"],["78291.82000000","0.00024000"],["78291.78000000","0.00014000"],["78291.53000000","0.00000000"],["78291.51000000","0.00000000"],["78291.50000000","0.17326000"],["78291.49000000","0.00000000"],["78291.48000000","0.00000000"],["78291.30000000","0.00000000"],["78291.25000000","0.00000000"],["78290.98000000","0.00000000"],["78290.93000000","0.26860000"],["78290.92000000","0.00400000"],["78290.91000000","0.00000000"],["78290.33000000","0.00000000"],["78290.26000000","0.07500000"],["78290.25000000","0.41262000"],["78290.24000000","0.00000000"],["78290.11000000","2.29917000"],["78290.10000000","0.01337000"],["78290.06000000","1.86166000"],["78289.91000000","0.00000000"],["78289.90000000","0.00000000"],["78289.85000000","0.00000000"],["78289.84000000","0.00000000"],["78289.37000000","0.16614000"],["78289.09000000","0.00000000"],["78289.00000000","0.00000000"],["78288.99000000","0.76524000"],["78288.98000000","0.00014000"],["78288.97000000","0.00000000"],["78288.95000000","0.00000000"],["78288.90000000","0.00000000"],["78288.57000000","0.00007000"],["78288.31000000","0.00000000"],["78287.88000000","0.00150000"],["78287.80000000","0.88163000"],["78287.79000000","0.37595000"],["78287.75000000","0.00000000"],["78287.74000000","0.00000000"],["78287.73000000","0.54972000"],["78287.30000000","0.00008000"],["78287.19000000","0.02142000"],["78286.48000000","0.00000000"],["78286.47000000","0.09246000"],["78286.03000000","0.00000000"],["78285.86000000","0.00007000"],["78284.66000000","0.00007000"],["78284.43000000","0.38333000"],["78283.98000000","0.00010000"],["78283.78000000","0.31939000"],["78283.77000000","0.00000000"],["78282.70000000","0.00000000"],["78282.49000000","0.09429000"],["78281.97000000","0.00000000"],["78281.30000000","0.00000000"],["78281.16000000","0.00015000"],["78280.68000000","0.00000000"],["78280.53000000","0.10261000"],["78279.20000000","0.00000000"],["78278.65000000","0.31939000"],["78278.09000000","0.00000000"],["78276.16000000","0.00034000"],["78275.26000000","0.00000000"],["78275.08000000","0.00008000"],["78274.17000000","0.00000000"],["78274.13000000","1.23409000"],["78274.12000000","1.86166000"],["78272.25000000","0.00008000"],["78272.16000000","0.00000000"],["78272.13000000","0.00000000"],["78271.17000000","0.00008000"],["78268.33000000","0.00026000"],["78266.53000000","0.00000000"],["78264.42000000","0.00000000"],["78264.30000000","0.00000000"],["78261.60000000","0.00000000"],["78261.54000000","0.00000000"],["78261.33000000","0.00000000"],["78261.12000000","0.00000000"],["78260.50000000","0.00008000"],["78260.39000000","0.00000000"],["78259.86000000","0.00000000"],["78259.42000000","0.00008000"],["78259.28000000","0.00000000"],["78258.72000000","0.00000000"],["78258.70000000","0.00000000"],["78257.02000000","0.00000000"],["78256.59000000","0.00008000"],["78256.44000000","0.00000000"],["78255.87000000","0.00000000"],["78255.00000000","0.00000000"],["78252.67000000","0.00008000"],["78252.56000000","0.00000000"],["78251.92000000","0.36607000"],["78251.88000000","0.00000000"],["78250.00000000","0.07897000"],["78249.92000000","0.03127000"],["78249.00000000","0.00000000"],["78248.65000000","0.00000000"],["78247.84000000","0.77166000"],["78239.45000000","0.00000000"],["78238.98000000","1.14469000"],["78238.30000000","0.00000000"],["78235.79000000","0.00000000"],["78235.37000000","0.00317000"],["78235.10000000","0.00000000"],["78234.67000000","0.00000000"],["78230.25000000","0.00000000"],["78230.24000000","0.00661000"],["78227.50000000","0.00000000"],["78227.36000000","0.02904000"],["78224.59000000","0.00318000"],["78223.89000000","0.00000000"],["78222.38000000","0.00000000"],["78215.70000000","0.00008000"],["78215.56000000","0.00000000"],["78211.12000000","0.00000000"],["78207.72000000","0.00000000"],["78197.84000000","0.00000000"],["78194.32000000","0.00000000"],["78183.14000000","0.00000000"],["78181.89000000","0.00000000"],["78181.68000000","0.00000000"],["78178.94000000","1.45056000"],["78178.93000000","0.00000000"],["78175.30000000","0.00000000"],["78175.29000000","0.00016000"],["78167.54000000","0.00000000"],["78167.45000000","0.00000000"],["78065.55000000","0.00000000"],["78063.58000000","0.00000000"],["78059.67000000","0.00000000"],["78059.11000000","0.00008000"],["78055.76000000","0.00106000"],["78052.43000000","0.00000000"],["78051.15000000","0.00000000"],["77980.81000000","0.00008000"],["77972.87000000","0.00000000"],["77824.23000000","0.00008000"],["77816.29000000","0.00015000"],["77745.93000000","0.00008000"],["77738.01000000","0.00000000"],["77125.50000000","0.00008000"],["77114.66000000","0.00000000"],["77114.65000000","0.00000000"],["70460.10000000","0.00000000"],["70460.09000000","0.00009000"],["62631.20000000","0.00217000"]],"a":[["78289.00000000","0.00000000"],["78289.01000000","0.00000000"],["78289.38000000","0.00000000"],["78290.25000000","0.00000000"],["78290.26000000","0.00000000"],["78290.94000000","0.00000000"],["78291.51000000","0.00000000"],["78291.52000000","0.00000000"],["78291.78000000","0.00000000"],["78291.95000000","0.00000000"],["78291.99000000","0.00000000"],["78292.00000000","0.00000000"],["78292.01000000","0.00000000"],["78292.33000000","0.00000000"],["78292.51000000","0.00000000"],["78292.75000000","0.00000000"],["78292.76000000","0.00000000"],["78292.77000000","0.00000000"],["78293.66000000","0.00000000"],["78293.72000000","0.00000000"],["78294.00000000","0.00000000"],["78294.27000000","0.00000000"],["78295.01000000","0.00000000"],["78295.17000000","0.00000000"],["78295.77000000","0.00000000"],["78295.80000000","0.00000000"],["78296.00000000","0.00000000"],["78296.04000000","0.00000000"],["78296.11000000","0.00000000"],["78296.29000000","0.00000000"],["78296.61000000","0.00000000"],["78296.69000000","0.00000000"],["78296.83000000","0.00000000"],["78296.99000000","0.00000000"],["78297.10000000","0.00000000"],["78297.44000000","0.00000000"],["78297.67000000","0.00000000"],["78298.00000000","0.00000000"],["78298.06000000","0.00000000"],["78298.58000000","0.00000000"],["78298.93000000","0.00000000"],["78298.98000000","0.00000000"],["78299.29000000","0.00000000"],["78299.34000000","0.00000000"],["78299.37000000","0.00000000"],["78299.44000000","0.00000000"],["78299.45000000","0.00000000"],["78299.67000000","0.00000000"],["78299.76000000","0.00000000"],["78299.78000000","0.00000000"],["78299.96000000","0.00000000"],["78300.00000000","0.40007000"],["78300.01000000","0.00056000"],["78300.32000000","0.00000000"],["78300.36000000","0.00000000"],["78300.74000000","0.00000000"],["78301.10000000","0.00000000"],["78301.43000000","0.00014000"],["78301.50000000","0.00000000"],["78301.51000000","0.00014000"],["78301.74000000","0.00000000"],["78301.99000000","0.03882000"],["78302.04000000","0.00000000"],["78302.06000000","0.00000000"],["78302.10000000","0.00000000"],["78302.11000000","0.00000000"],["78302.14000000","0.00000000"],["78302.27000000","0.00000000"],["78302.46000000","0.00000000"],["78302.51000000","0.00000000"],["78302.69000000","0.00000000"],["78302.78000000","0.00000000"],["78303.16000000","0.00000000"],["78303.38000000","0.00000000"],["78303.39000000","0.00000000"],["78303.45000000","0.00000000"],["78303.46000000","0.00000000"],["78303.72000000","0.00000000"],["78303.75000000","0.00007000"],["78303.99000000","0.00007000"],["78304.24000000","0.00000000"],["78304.25000000","0.00000000"],["78304.31000000","0.00000000"],["78304.32000000","0.00000000"],["78304.35000000","0.00000000"],["78304.66000000","0.00000000"],["78304.74000000","0.00000000"],["78304.75000000","0.00000000"],["78305.19000000","0.00007000"],["78305.31000000","0.00400000"],["78305.32000000","0.00000000"],["78305.33000000","0.00000000"],["78305.34000000","0.06114000"],["78305.57000000","0.00000000"],["78305.81000000","0.02139000"],["78305.83000000","0.00000000"],["78305.95000000","0.00000000"],["78306.07000000","0.00000000"],["78306.47000000","0.00000000"],["78306.58000000","0.00000000"],["78306.61000000","0.00000000"],["78306.75000000","0.00000000"],["78306.89000000","0.00000000"],["78307.12000000","0.42989000"],["78307.21000000","0.01278000"],["78307.37000000","0.00000000"],["78307.45000000","0.00000000"],["78307.50000000","0.00038000"],["78307.61000000","0.00000000"],["78307.72000000","0.00000000"],["78307.74000000","0.00007000"],["78307.83000000","0.00228000"],["78307.93000000","0.30203000"],["78307.94000000","2.73738000"],["78307.95000000","0.00000000"],["78307.96000000","0.00000000"],["78308.19000000","0.00008000"],["78308.32000000","0.00007000"],["78308.33000000","0.00000000"],["78308.34000000","0.00000000"],["78309.05000000","0.01000000"],["78309.25000000","0.25583000"],["78309.73000000","0.00000000"],["78309.82000000","0.12769000"],["78310.34000000","0.00048000"],["78310.53000000","0.01325000"],["78310.59000000","0.00000000"],["78310.60000000","1.31113000"],["78310.97000000","0.00000000"],["78311.22000000","0.00000000"],["78311.29000000","0.03400000"],["78311.39000000","1.95060000"],["78311.45000000","0.00007000"],["78311.52000000","0.00008000"],["78311.66000000","0.00000000"],["78311.73000000","0.00014000"],["78311.75000000","0.12007000"],["78312.36000000","0.00638000"],["78312.49000000","0.00000000"],["78312.68000000","0.00000000"],["78312.98000000","0.00000000"],["78313.01000000","0.09426000"],["78313.32000000","0.00638000"],["78313.55000000","0.00159000"],["78314.45000000","0.01306000"],["78314.97000000","0.10257000"],["78314.98000000","0.00000000"],["78314.99000000","0.00000000"],["78315.11000000","0.00000000"],["78315.20000000","0.00000000"],["78315.29000000","0.37581000"],["78315.44000000","0.00000000"],["78315.66000000","0.00243000"],["78315.72000000","0.00007000"],["78315.78000000","0.02000000"],["78316.72000000","0.00000000"],["78317.75000000","0.00000000"],["78317.79000000","0.00400000"],["78317.99000000","0.00400000"],["78318.37000000","0.01340000"],["78319.09000000","0.00000000"],["78319.11000000","0.00000000"],["78319.12000000","0.00000000"],["78319.35000000","0.00000000"],["78319.49000000","0.00000000"],["78319.71000000","0.00014000"],["78320.32000000","0.00000000"],["78321.59000000","0.31939000"],["78321.70000000","0.00255000"],["78322.01000000","1.07613000"],["78322.10000000","0.00000000"],["78322.25000000","0.20000000"],["78322.48000000","0.31936000"],["78323.02000000","0.00000000"],["78323.03000000","0.00000000"],["78323.27000000","0.00008000"],["78323.40000000","0.00000000"],["78323.49000000","0.00236000"],["78323.75000000","0.16897000"],["78323.99000000","0.37581000"],["78324.12000000","0.00000000"],["78324.92000000","0.00000000"],["78325.54000000","0.00000000"],["78326.00000000","0.03000000"],["78326.94000000","0.00000000"],["78327.18000000","0.00000000"],["78327.41000000","0.00008000"],["78328.99000000","0.31939000"],["78329.00000000","0.00000000"],["78329.65000000","0.31936000"],["78329.89000000","0.00000000"],["78330.00000000","0.03000000"],["78331.00000000","0.00000000"],["78331.10000000","0.00000000"],["78331.23000000","0.00008000"],["78331.32000000","0.00235000"],["78331.68000000","0.00014000"],["78331.96000000","0.00000000"],["78333.18000000","0.00000000"],["78335.15000000","0.03057000"],["78335.24000000","0.00000000"],["78335.43000000","0.00000000"],["78335.67000000","0.00014000"],["78338.38000000","0.00400000"],["78339.11000000","0.00000000"],["78339.15000000","0.00008000"],["78339.66000000","2.00671000"],["78340.00000000","0.04000000"],["78341.66000000","0.00000000"],["78342.90000000","0.00400000"],["78343.65000000","0.00007000"],["78343.96000000","0.00000000"],["78344.18000000","0.00000000"],["78344.89000000","0.00000000"],["78345.31000000","0.00000000"],["78346.10000000","0.00008000"],["78347.64000000","0.00007000"],["78347.88000000","0.34471000"],["78350.18000000","0.00000000"],["78353.64000000","0.00318000"],["78357.27000000","0.00000000"],["78359.99000000","0.00000000"],["78364.07000000","0.00000000"],["78367.87000000","0.00318000"],["78367.88000000","1.26364000"],["78370.62000000","0.00000000"],["78376.57000000","0.00000000"],["78376.99000000","0.03726000"],["78377.23000000","0.00000000"],["78378.66000000","0.00008000"],["78380.41000000","0.00000000"],["78384.49000000","2.29917000"],["78384.50000000","0.00000000"],["78384.51000000","0.00000000"],["78386.66000000","0.00000000"],["78390.71000000","0.00000000"],["78405.42000000","0.00000000"],["78417.01000000","0.00000000"],["78419.98000000","0.00000000"],["78431.99000000","0.00127000"],["78435.92000000","0.00000000"],["78445.99000000","0.00127000"],["78456.96000000","0.00008000"],["78498.03000000","0.00000000"],["78505.31000000","0.00000000"],["78515.25000000","0.00007000"],["78519.16000000","0.00007000"],["78527.21000000","0.00000000"],["78535.26000000","0.00008000"],["78605.50000000","0.00000000"],["78613.56000000","0.00188000"],["78613.83000000","7.63449000"],["78682.80000000","0.00014000"],["78691.86000000","0.00008000"],["78762.08000000","0.00000000"],["78770.16000000","0.00018000"],["78840.38000000","0.00000000"],["78848.46000000","0.00008000"],["78918.67000000","0.00000000"],["78926.76000000","0.00008000"],["79463.34000000","0.00000000"]]}}
{"rx":1788854550947630788, "m":{"e":"depthUpdate","E":1788854550914,"s":"BTCUSDT","U":99829866158,"u":99829866438,"b":[["78299.99000000","4.46801000"],["78299.73000000","0.00000000"],["78299.55000000","0.00000000"],["78299.00000000","0.00014000"],["78298.99000000","0.20667000"],["78298.98000000","0.00028000"],["78298.97000000","0.30683000"],["78298.83000000","0.00000000"],["78298.61000000","0.00000000"],["78298.60000000","0.00000000"],["78298.59000000","0.00014000"],["78298.58000000","0.00014000"],["78298.57000000","0.00000000"],["78298.56000000","0.00000000"],["78298.55000000","0.00014000"],["78298.51000000","0.00000000"],["78298.50000000","0.00007000"],["78298.35000000","0.00014000"],["78298.05000000","0.00000000"],["78298.00000000","0.00014000"],["78297.87000000","0.00255000"],["78296.01000000","0.00007000"],["78296.00000000","0.68390000"],["78295.99000000","0.00000000"],["78295.73000000","0.00000000"],["78295.58000000","0.00000000"],["78295.44000000","0.00400000"],["78295.37000000","0.00000000"],["78295.13000000","0.00000000"],["78295.01000000","0.00638000"],["78294.54000000","0.00000000"],["78294.26000000","0.00000000"],["78294.11000000","0.01286000"],["78294.01000000","1.86966000"],["78293.99000000","0.24007000"],["78293.71000000","0.00000000"],["78292.75000000","0.00000000"],["78291.99000000","0.00071000"],["78291.84000000","1.36284000"],["78291.82000000","0.00010000"],["78291.50000000","0.17312000"],["78290.27000000","0.37581000"],["78290.11000000","0.00000000"],["78287.79000000","0.00014000"],["78286.47000000","0.09233000"],["78283.55000000","0.00000000"],["78283.37000000","0.00000000"],["78282.29000000","0.00000000"],["78281.04000000","0.00000000"],["78279.79000000","0.00000000"],["78274.88000000","0.00012000"],["78274.54000000","0.00060000"],["78266.44000000","0.02491000"],["78262.57000000","0.00000000"],["78261.00000000","0.00000000"],["78260.00000000","0.04071000"],["78250.00000000","0.06897000"],["78240.87000000","0.20000000"],["78227.24000000","2.29885000"],["77125.50000000","0.00016000"],["70470.00000000","0.00016000"]],"a":[["78300.00000000","1.70026000"],["78300.01000000","0.00049000"],["78300.23000000","0.00792000"],["78301.43000000","0.00000000"],["78301.49000000","0.01320000"],["78301.51000000","0.00000000"],["78301.59000000","0.00000000"],["78301.99000000","0.18432000"],["78302.00000000","0.03022000"],["78302.74000000","0.01584000"],["78303.63000000","0.00000000"],["78303.99000000","0.01591000"],["78304.00000000","0.03014000"],["78304.45000000","0.00000000"],["78305.33000000","0.00000000"],["78305.34000000","0.06128000"],["78305.81000000","0.02153000"],["78306.00000000","0.03014000"],["78306.23000000","0.00000000"],["78306.48000000","0.00000000"],["78307.09000000","0.00000000"],["78307.10000000","1.57836000"],["78307.11000000","1.95860000"],["78307.12000000","0.00014000"],["78307.21000000","0.01292000"],["78307.50000000","0.00000000"],["78307.92000000","0.00000000"],["78307.93000000","0.00000000"],["78307.94000000","2.29917000"],["78308.24000000","0.00000000"],["78310.35000000","0.31864000"],["78310.96000000","0.00048000"],["78311.73000000","0.00021000"],["78313.31000000","0.00191000"],["78313.52000000","0.00255000"],["78315.72000000","0.00014000"],["78317.79000000","0.00000000"],["78317.99000000","0.00400000"],["78319.23000000","0.00007000"],["78343.86000000","0.20000000"],["78343.88000000","0.00622000"],["78345.01000000","0.00433000"],["78347.42000000","0.00400000"],["78347.64000000","0.00000000"],["78349.36000000","0.00432000"],["78351.99000000","0.00316000"],["78367.26000000","0.01695000"],["78403.99000000","0.01975000"],["78429.32000000","0.00127000"],["78522.56000000","0.02000000"],["78523.24000000","0.00007000"],["78527.15000000","0.00000000"]]}}
{"rx":1788854551058238213, "m":{"e":"depthUpdate","E":1788854551014,"s":"BTCUSDT","U":99829866439,"u":99829866612,"b":[["78299.99000000","3.58215000"],["78299.01000000","0.00024000"],["78298.99000000","0.15364000"],["78298.98000000","0.00014000"],["78298.97000000","0.30683000"],["78298.96000000","0.00740000"],["78298.59000000","0.00000000"],["78298.58000000","0.00000000"],["78298.55000000","0.00000000"],["78298.50000000","0.00000000"],["78298.34000000","0.06039000"],["78298.01000000","0.00117000"],["78297.99000000","0.14371000"],["78297.87000000","0.00000000"],["78297.70000000","0.01634000"],["78296.50000000","0.00400000"],["78296.45000000","0.01480000"],["78296.00000000","0.04574000"],["78295.88000000","0.00255000"],["78295.64000000","0.00400000"],["78295.50000000","0.03007000"],["78295.20000000","0.01480000"],["78294.11000000","0.00000000"],["78294.01000000","0.00800000"],["78294.00000000","0.00000000"],["78292.16000000","0.00008000"],["78291.99000000","0.00007000"],["78291.98000000","0.14061000"],["78291.84000000","0.77571000"],["78291.77000000","0.10419000"],["78291.50000000","0.17312000"],["78291.14000000","0.20250000"],["78290.92000000","0.00400000"],["78288.99000000","0.56274000"],["78288.98000000","0.00000000"],["78284.59000000","0.15189000"],["78283.67000000","0.00000000"],["78283.54000000","0.00000000"],["78283.32000000","0.00008000"],["78282.91000000","0.00008000"],["78282.41000000","0.02000000"],["78282.21000000","0.02000000"],["78281.45000000","0.02000000"],["78281.16000000","0.00007000"],["78280.42000000","0.00008000"],["78278.46000000","0.02000000"],["78277.63000000","0.02000000"],["78277.17000000","0.00000000"],["78276.16000000","0.00026000"],["78272.25000000","0.00000000"],["78270.36000000","0.00000000"],["78268.67000000","0.00008000"],["78268.22000000","0.00000000"],["78263.34000000","0.00008000"],["78260.50000000","0.00000000"],["78256.59000000","0.00000000"],["78256.47000000","0.00000000"],["78252.67000000","0.00000000"],["78234.30000000","1.26580000"],["78180.27000000","0.00000000"],["78137.40000000","0.00008000"],["78129.44000000","0.00000000"],["77902.52000000","0.00008000"],["77894.58000000","0.00000000"],["77667.64000000","0.00008000"],["77659.72000000","0.00000000"],["77125.50000000","0.00024000"],["62640.00000000","0.03298000"]],"a":[["78300.00000000","1.70047000"],["78300.01000000","0.00056000"],["78300.23000000","0.00806000"],["78301.48000000","0.00014000"],["78301.49000000","0.01334000"],["78301.81000000","0.00103000"],["78301.84000000","0.06584000"],["78301.99000000","0.06658000"],["78302.00000000","0.03022000"],["78302.74000000","0.01598000"],["78303.63000000","0.00000000"],["78303.99000000","0.01605000"],["78304.40000000","0.06747000"],["78305.04000000","0.01332000"],["78305.33000000","0.00000000"],["78305.81000000","0.02139000"],["78306.00000000","0.03000000"],["78306.23000000","0.00000000"],["78307.09000000","0.00800000"],["78307.12000000","0.00000000"],["78307.17000000","0.20250000"],["78307.21000000","0.01278000"],["78307.43000000","0.00165000"],["78307.74000000","0.00014000"],["78307.93000000","0.00638000"],["78311.52000000","0.00000000"],["78311.53000000","0.00255000"],["78312.36000000","0.00000000"],["78313.52000000","0.00000000"],["78315.57000000","0.00000000"],["78319.58000000","0.00008000"],["78323.27000000","0.00000000"],["78327.32000000","0.00000000"],["78331.23000000","0.00000000"],["78331.32000000","0.00243000"],["78333.49000000","0.02526000"],["78334.29000000","0.03600000"],["78335.24000000","0.00008000"],["78338.17000000","0.02600000"],["78339.11000000","0.03400000"],["78340.67000000","1.26408000"],["78417.11000000","0.00000000"],["78419.51000000","0.07150000"],["78448.91000000","0.00000000"],["78506.57000000","0.12778000"],["78527.39000000","0.00635000"],["78613.83000000","0.00000000"],["78683.79000000","0.00000000"],["79355.68000000","0.00007000"]]}}
{"rx":1788854551140766517, "m":{"e":"depthUpdate","E":1788854551114,"s":"BTCUSDT","U":99829866613,"u":99829866695,"b":[["78299.99000000","3.58421000"],["78298.99000000","0.09491000"],["78298.97000000","0.10433000"],["78298.96000000","0.00754000"],["78297.99000000","0.14364000"],["78296.89000000","0.00007000"],["78296.00000000","0.11478000"],["78295.88000000","0.00000000"],["78295.50000000","0.03000000"],["78294.01000000","0.00000000"],["78292.27000000","0.00255000"],["78292.01000000","0.00800000"],["78291.50000000","0.17248000"],["78274.61000000","0.00408000"],["78273.37000000","0.00000000"],["78268.58000000","0.00000000"],["78263.76000000","0.00000000"],["78224.58000000","0.00000000"],["78192.28000000","0.00000000"],["78184.60000000","0.03961000"],["78163.60000000","0.00009000"],["78151.41000000","0.00000000"],["77595.29000000","0.00010000"],["77125.49000000","0.00030000"],["72040.91000000","0.00000000"],["70470.00000000","0.00032000"],["62640.00000000","0.03329000"],["62631.20000000","0.00186000"]],"a":[["78300.00000000","1.49900000"],["78300.01000000","0.00049000"],["78301.49000000","0.01334000"],["78301.81000000","0.00000000"],["78301.84000000","0.00014000"],["78303.75000000","0.00014000"],["78304.00000000","0.03014000"],["78305.34000000","0.06114000"],["78307.08000000","0.47744000"],["78307.12000000","0.00000000"],["78307.17000000","0.00000000"],["78307.83000000","0.20478000"],["78307.87000000","0.00400000"],["78307.92000000","0.00255000"],["78311.53000000","0.00000000"],["78335.35000000","0.50707000"],["78343.65000000","0.00000000"],["78359.67000000","0.99480000"],["78384.81000000","0.00000000"],["78392.40000000","2.68103000"],["78395.01000000","0.00000000"],["78397.08000000","0.00025000"],["78400.11000000","0.00000000"],["78405.06000000","0.00000000"],["78506.57000000","0.00000000"]]}}
{"rx":1788854551248932679, "m":{"e":"depthUpdate","E":1788854551214,"s":"BTCUSDT","U":99829866696,"u":99829866748,"b":[["78299.99000000","3.20308000"],["78299.76000000","0.00007000"],["78297.99000000","0.14371000"],["78297.70000000","0.01648000"],["78296.45000000","0.01487000"],["78292.27000000","0.00000000"],["78292.11000000","0.00000000"],["78290.98000000","0.00255000"],["78287.73000000","0.54956000"],["78281.64000000","0.02000000"],["78273.91000000","0.00000000"],["78273.19000000","0.00000000"],["78269.43000000","0.00000000"],["77125.50000000","0.00032000"],["70460.09000000","0.00000000"],["62631.20000000","0.00155000"]],"a":[["78300.00000000","2.48688000"],["78301.49000000","0.01334000"],["78301.84000000","0.00000000"],["78304.40000000","0.06761000"],["78306.23000000","0.00000000"],["78306.63000000","0.00255000"],["78307.92000000","0.00000000"],["78307.95000000","0.00400000"],["78345.16000000","0.00400000"],["78347.42000000","0.00000000"],["78407.24000000","0.00012000"],["78412.33000000","0.00019000"],["78417.29000000","0.00031000"],["79474.72000000","0.00007000"],["79593.94000000","0.00008000"]]}}
{"rx":1788854551363271226, "m":{"e":"depthUpdate","E":1788854551314,"s":"BTCUSDT","U":99829866749,"u":99829866779,"b":[["78299.95000000","0.05000000"],["78289.09000000","0.08308000"],["77125.50000000","0.00032000"],["70470.00000000","0.00048000"],["70469.00000000","0.00000000"],["62630.00000000","0.01596000"]],"a":[["78300.00000000","1.76514000"],["78307.08000000","0.00000000"],["78307.83000000","0.20386000"],["78307.87000000","0.00000000"],["78308.77000000","0.00400000"],["78315.66000000","0.00151000"],["78323.49000000","0.00144000"],["78331.32000000","0.00151000"],["78369.57000000","1.26361000"],["78506.96000000","0.00000000"],["78507.45000000","0.00000000"],["79028.91000000","0.00000000"]]}}
{"rx":1788854551486784633, "m":{"e":"depthUpdate","E":1788854551414,"s":"BTCUSDT","U":99829866780,"u":99829866807,"b":[["78299.99000000","3.20316000"],["78299.96000000","0.00014000"],["78299.95000000","0.05014000"],["78299.91000000","0.00014000"],["78299.90000000","0.05000000"],["78299.76000000","0.00014000"],["78298.79000000","0.00007000"],["78298.00000000","0.00000000"],["78296.01000000","0.00000000"],["78296.00000000","0.11464000"],["78273.43000000","0.00000000"],["78246.70000000","0.61903000"],["78244.07000000","0.00000000"],["77125.50000000","0.00032000"],["62631.20000000","0.00124000"]],"a":[["78300.00000000","1.76529000"],["78326.00000000","0.73000000"],["78380.59000000","0.00000000"]]}}
{"rx":1788854551575292830, "m":{"e":"depthUpdate","E":1788854551514,"s":"BTCUSDT","U":99829866808,"u":99829866830,"b":[["78299.95000000","0.05014000"],["78299.90000000","0.05007000"],["78296.45000000","0.01480000"],["78296.00000000","0.12464000"],["78294.00000000","0.00500000"],["78292.00000000","0.08000000"],["78290.00000000","0.00500000"],["78288.00000000","0.00500000"],["78281.50000000","0.02000000"],["78271.00000000","0.70000000"],["78265.00000000","0.00000000"],["77900.00000000","18.65127000"],["77125.50000000","0.00032000"],["70470.00000000","0.00064000"]],"a":[["78300.00000000","1.56279000"],["78375.78000000","0.00000000"],["78379.67000000","0.00000000"],["78421.38000000","0.04298000"]]}}
{"rx":1788854551661915368, "m":{"e":"depthUpdate","E":1788854551614,"s":"BTCUSDT","U":99829866831,"u":99829866873,"b":[["78299.99000000","3.20339000"],["78299.01000000","0.00000000"],["78294.00000000","0.01000000"],["78292.16000000","0.01326000"],["78292.03000000","0.00255000"],["78292.00000000","0.08500000"],["78291.84000000","1.63192000"],["78290.98000000","0.00000000"],["78290.07000000","2.29885000"],["78290.00000000","0.01000000"],["78288.00000000","0.01000000"],["78273.24000000","0.00000000"],["78227.24000000","0.00000000"],["78214.42000000","0.00000000"],["77125.50000000","0.00032000"],["70470.00000000","0.00080000"],["62639.99000000","0.00000000"],["62631.20000000","0.00093000"]],"a":[["78300.00000000","1.56350000"],["78305.04000000","0.00000000"],["78305.06000000","0.01293000"],["78306.63000000","0.00000000"],["78307.68000000","0.00255000"],["78307.93000000","0.00000000"],["78307.95000000","0.00000000"],["78308.96000000","0.00400000"],["78309.81000000","0.00638000"],["79713.34000000","0.00009000"]]}}
{"rx":1788854551786201906, "m":{"e":"depthUpdate","E":1788854551714,"s":"BTCUSDT","U":99829866874,"u":99829866896,"b":[["78299.99000000","3.20306000"],["78294.14000000","0.01302000"],["78278.48000000","0.02000000"],["78278.14000000","0.50941000"],["77125.50000000","0.00032000"],["70469.99000000","0.00009000"]],"a":[["78300.00000000","1.56172000"],["78303.15000000","0.00007000"],["78304.40000000","0.06761000"],["78305.06000000","0.00000000"],["78351.99000000","0.00000000"],["78369.57000000","0.00000000"],["78429.32000000","0.00000000"],["78609.99000000","7.63486000"],["79474.50000000","0.00030000"],["79832.92000000","0.00011000"]]}}
{"rx":1788854551879025042, "m":{"e":"depthUpdate","E":1788854551814,"s":"BTCUSDT","U":99829866897,"u":99829866954,"b":[["78299.99000000","3.31216000"],["78299.85000000","0.00400000"],["78299.57000000","0.00400000"],["78296.50000000","0.00000000"],["78295.64000000","0.00000000"],["78295.43000000","0.02113000"],["78293.09000000","0.00255000"],["78292.03000000","0.00000000"],["78291.96000000","0.00007000"],["78291.50000000","0.17248000"],["78290.93000000","0.26860000"],["78288.91000000","0.00007000"],["78270.25000000","0.00000000"],["77125.50000000","0.00040000"],["70470.00000000","0.00096000"],["62631.20000000","0.00062000"]],"a":[["78300.00000000","0.69931000"],["78304.40000000","0.06761000"],["78305.31000000","0.00000000"],["78307.08000000","0.48144000"],["78307.68000000","0.00000000"],["78308.74000000","0.00255000"],["78308.77000000","0.00000000"],["78308.96000000","0.00000000"],["78311.75000000","0.12007000"],["78315.44000000","0.12768000"],["78323.27000000","0.12767000"],["78335.03000000","0.04200000"],["78351.99000000","0.00316000"],["78429.32000000","0.00127000"]]}}
{"rx":1788854551958744554, "m":{"e":"depthUpdate","E":1788854551914,"s":"BTCUSDT","U":99829866955,"u":99829867554,"b":[["78301.99000000","6.70226000"],["78301.98000000","0.73373000"],["78301.97000000","0.00030000"],["78301.96000000","0.00000000"],["78301.90000000","0.05000000"],["78301.48000000","0.00000000"],["78301.47000000","0.00000000"],["78301.16000000","0.00026000"],["78301.10000000","0.00000000"],["78300.36000000","0.00008000"],["78300.35000000","0.00000000"],["78300.34000000","0.06025000"],["78300.22000000","0.00000000"],["78300.00000000","0.60500000"],["78299.99000000","0.47795000"],["78299.98000000","0.00000000"],["78299.97000000","0.00000000"],["78299.96000000","0.00000000"],["78299.95000000","0.00014000"],["78299.91000000","0.00000000"],["78299.90000000","0.00007000"],["78299.85000000","0.00000000"],["78299.57000000","0.00000000"],["78299.00000000","0.00000000"],["78298.99000000","0.00014000"],["78298.98000000","0.00000000"],["78298.97000000","0.00014000"],["78298.96000000","0.00014000"],["78298.79000000","0.00000000"],["78298.35000000","0.00000000"],["78298.34000000","0.00014000"],["78298.30000000","0.01277000"],["78298.01000000","0.00000000"],["78298.00000000","0.00000000"],["78297.99000000","0.00000000"],["78297.70000000","0.00400000"],["78297.06000000","0.03057000"],["78296.45000000","0.00000000"],["78296.32000000","0.01298000"],["78295.20000000","0.00150000"],["78295.01000000","0.00000000"],["78295.00000000","0.00000000"],["78294.89000000","0.00000000"],["78294.15000000","0.00008000"],["78294.07000000","1.86166000"],["78293.09000000","0.00000000"],["78292.16000000","0.01318000"],["78292.01000000","0.00000000"],["78291.77000000","0.00000000"],["78290.26000000","0.00000000"],["78287.88000000","0.00000000"],["78287.80000000","0.64066000"],["78287.73000000","0.16637000"],["78285.47000000","0.00000000"],["78283.18000000","0.30402000"],["78279.71000000","0.63892000"],["78276.71000000","0.31755000"],["78269.99000000","0.63900000"],["78269.44000000","0.00000000"],["78263.62000000","0.00000000"],["78262.00000000","0.04000000"],["78260.00000000","0.03071000"],["78254.04000000","0.00000000"],["78253.99000000","0.00000000"],["78250.37000000","0.00436000"],["78246.58000000","0.00428000"],["78246.31000000","0.00430000"],["78244.42000000","0.00000000"],["78239.61000000","0.00000000"],["78237.04000000","0.00000000"],["78234.30000000","0.00000000"],["78233.57000000","0.00000000"],["78233.34000000","0.00000000"],["78223.68000000","0.00008000"],["78215.70000000","0.00000000"],["78210.96000000","0.90728000"],["78209.45000000","0.00000000"],["78209.44000000","0.00000000"],["78205.58000000","0.00010000"],["78145.38000000","0.01122000"],["78137.40000000","0.00000000"],["78067.07000000","0.00008000"],["78059.11000000","0.00000000"],["77988.77000000","0.00008000"],["77980.81000000","0.00000000"],["77910.47000000","0.00008000"],["77902.52000000","0.00000000"],["77832.17000000","0.00008000"],["77824.23000000","0.00000000"],["77753.87000000","0.00008000"],["77745.93000000","0.00000000"],["77675.56000000","0.00008000"],["77667.64000000","0.00000000"],["77127.47000000","0.00008000"],["77125.50000000","0.00000000"],["77125.49000000","0.00000000"],["70470.00000000","0.00000000"]],"a":[["78300.00000000","0.00000000"],["78300.01000000","0.00000000"],["78300.23000000","0.00000000"],["78301.11000000","0.00000000"],["78301.48000000","0.00000000"],["78301.49000000","0.00000000"],["78301.99000000","0.00000000"],["78302.00000000","0.05011000"],["78302.01000000","0.00076000"],["78302.73000000","0.00000000"],["78302.74000000","0.00014000"],["78303.75000000","0.00007000"],["78303.99000000","0.00028000"],["78304.27000000","0.00007000"],["78305.19000000","0.00000000"],["78305.34000000","0.00014000"],["78305.77000000","0.00206000"],["78305.81000000","0.00014000"],["78306.00000000","0.03014000"],["78307.07000000","0.00000000"],["78307.08000000","0.00014000"],["78307.09000000","0.47743000"],["78307.10000000","0.56312000"],["78307.11000000","0.00000000"],["78307.21000000","0.00000000"],["78307.32000000","0.00000000"],["78307.63000000","0.00000000"],["78307.64000000","0.00000000"],["78307.74000000","0.00007000"],["78307.83000000","0.00136000"],["78307.94000000","0.00000000"],["78308.16000000","0.00000000"],["78308.74000000","0.00000000"],["78309.00000000","0.00000000"],["78309.05000000","0.00000000"],["78309.12000000","0.00000000"],["78309.24000000","0.00000000"],["78309.25000000","0.23583000"],["78309.81000000","0.00000000"],["78309.82000000","0.00000000"],["78309.97000000","0.00000000"],["78310.42000000","0.00000000"],["78310.45000000","0.02174000"],["78310.53000000","0.00000000"],["78310.54000000","0.00000000"],["78310.98000000","0.00000000"],["78311.15000000","0.03000000"],["78311.73000000","0.00014000"],["78311.75000000","0.13298000"],["78312.36000000","0.00000000"],["78312.37000000","0.00000000"],["78313.16000000","0.00000000"],["78313.32000000","0.00000000"],["78313.35000000","0.00000000"],["78313.65000000","0.00000000"],["78313.99000000","0.00638000"],["78314.58000000","0.00007000"],["78315.78000000","0.00000000"],["78315.87000000","0.00000000"],["78316.37000000","0.00638000"],["78316.91000000","0.00000000"],["78316.97000000","0.00000000"],["78317.68000000","0.00000000"],["78319.10000000","0.00000000"],["78319.13000000","0.00400000"],["78320.79000000","0.00400000"],["78321.18000000","0.02000000"],["78321.59000000","0.00000000"],["78321.99000000","0.00400000"],["78322.48000000","0.00000000"],["78323.27000000","0.00000000"],["78325.54000000","0.00049000"],["78326.00000000","0.03000000"],["78326.49000000","0.31936000"],["78326.99000000","0.31936000"],["78327.61000000","0.12766000"],["78327.83000000","0.00574000"],["78328.99000000","0.00000000"],["78329.65000000","0.00000000"],["78331.58000000","0.00012000"],["78331.59000000","0.00192000"],["78333.84000000","0.00000000"],["78333.99000000","0.31936000"],["78335.34000000","0.31936000"],["78339.66000000","2.00678000"],["78340.00000000","0.03000000"],["78340.67000000","0.00000000"],["78341.29000000","0.00000000"],["78342.00000000","0.04000000"],["78343.65000000","0.00007000"],["78344.90000000","0.00000000"],["78345.24000000","0.00000000"],["78347.64000000","0.00007000"],["78350.20000000","0.36903000"],["78351.04000000","0.00400000"],["78351.86000000","0.32702000"],["78351.99000000","0.00000000"],["78352.10000000","0.00429000"],["78352.52000000","0.34469000"],["78353.63000000","0.00317000"],["78354.10000000","0.00000000"],["78355.68000000","0.00000000"],["78370.32000000","0.00111000"],["78370.62000000","0.00544000"],["78372.38000000","1.26357000"],["78392.40000000","0.00000000"],["78429.32000000","0.00000000"],["78431.98000000","0.00127000"],["78554.12000000","0.00000000"],["79474.50000000","0.00000000"]]}}
{"rx":1788854552049110878, "m":{"e":"depthUpdate","E":1788854552014,"s":"BTCUSDT","U":99829867555,"u":99829867778,"b":[["78301.99000000","6.68347000"],["78301.98000000","0.53130000"],["78301.96000000","0.00014000"],["78301.95000000","0.05000000"],["78301.91000000","0.00014000"],["78301.90000000","0.05014000"],["78301.16000000","0.00000000"],["78300.87000000","0.00400000"],["78300.73000000","0.01374000"],["78300.35000000","0.00014000"],["78300.34000000","0.06039000"],["78300.01000000","0.00652000"],["78300.00000000","0.55514000"],["78299.99000000","0.47795000"],["78299.95000000","0.00000000"],["78299.90000000","0.00000000"],["78299.48000000","0.01649000"],["78298.99000000","0.00000000"],["78298.97000000","0.00000000"],["78298.96000000","0.00000000"],["78298.34000000","0.00000000"],["78298.30000000","0.00014000"],["78298.23000000","0.01649000"],["78297.71000000","0.00800000"],["78297.06000000","0.03071000"],["78296.00000000","0.64655000"],["78287.74000000","0.00010000"],["78274.36000000","0.00000000"],["78270.07000000","0.00000000"],["78270.00000000","1.55175000"],["78269.86000000","0.88540000"],["78269.57000000","0.00400000"],["78250.59000000","0.00624000"],["78238.41000000","1.26573000"],["78228.90000000","2.21466000"],["77127.47000000","0.00016000"],["70471.80000000","0.00016000"],["70469.99000000","0.00000000"],["70469.98000000","0.00009000"],["62641.60000000","0.00124000"],["62631.20000000","0.00031000"]],"a":[["78302.00000000","0.45802000"],["78302.01000000","0.00069000"],["78302.74000000","0.00000000"],["78303.53000000","0.00707000"],["78303.77000000","0.00000000"],["78303.78000000","0.00000000"],["78303.98000000","0.00014000"],["78303.99000000","0.02922000"],["78304.40000000","0.06761000"],["78304.67000000","0.00000000"],["78304.79000000","0.01179000"],["78305.34000000","0.00000000"],["78305.56000000","0.00000000"],["78305.77000000","0.00000000"],["78305.81000000","0.00000000"],["78306.00000000","0.03014000"],["78306.04000000","0.01415000"],["78306.43000000","0.47743000"],["78306.44000000","0.16953000"],["78306.45000000","0.00000000"],["78307.08000000","0.00000000"],["78307.09000000","0.00014000"],["78307.10000000","0.00014000"],["78307.29000000","0.01415000"],["78307.34000000","0.47743000"],["78307.81000000","0.00000000"],["78308.00000000","0.03014000"],["78308.01000000","0.00026000"],["78308.16000000","0.47743000"],["78308.17000000","0.10230000"],["78308.18000000","0.06962000"],["78309.12000000","0.47743000"],["78309.24000000","0.47743000"],["78309.87000000","0.01313000"],["78310.34000000","0.00848000"],["78310.35000000","0.00000000"],["78310.45000000","0.00000000"],["78310.65000000","0.02086000"],["78311.75000000","0.12007000"],["78311.87000000","0.01313000"],["78313.68000000","0.03400000"],["78315.02000000","0.00255000"],["78320.79000000","0.00000000"],["78321.99000000","0.00000000"],["78352.07000000","0.88447000"],["78356.25000000","0.00221000"],["78419.51000000","0.10344000"],["78528.11000000","0.00007000"],["78532.02000000","0.00000000"],["79952.67000000","0.00026000"]]}}
{"rx":1788854552142277649, "m":{"e":"depthUpdate","E":1788854552114,"s":"BTCUSDT","U":99829867779,"u":99829867887,"b":[["78301.98000000","0.53130000"],["78301.95000000","0.05014000"],["78301.90000000","0.05014000"],["78300.73000000","0.01388000"],["78300.34000000","0.06039000"],["78300.01000000","0.00666000"],["78299.99000000","0.47781000"],["78299.45000000","0.00000000"],["78298.52000000","0.00000000"],["78298.30000000","0.00000000"],["78297.06000000","0.03057000"],["78296.00000000","0.65655000"],["78294.00000000","0.02000000"],["78292.00000000","0.09500000"],["78290.00000000","0.02000000"],["78289.09000000","0.00000000"],["78288.00000000","0.02000000"],["78235.47000000","0.00408000"],["77595.29000000","0.00000000"],["77127.46000000","0.00030000"],["70471.80000000","0.00032000"],["62642.00000000","0.00200000"]],"a":[["78302.00000000","0.45802000"],["78302.01000000","0.00062000"],["78303.53000000","0.00721000"],["78303.91000000","0.05247000"],["78303.92000000","0.06582000"],["78303.99000000","0.00014000"],["78304.40000000","0.06761000"],["78304.79000000","0.01193000"],["78306.00000000","0.03014000"],["78306.04000000","0.01429000"],["78306.42000000","0.17418000"],["78306.43000000","0.00014000"],["78306.44000000","0.00000000"],["78307.09000000","0.00000000"],["78307.10000000","0.00000000"],["78307.34000000","0.00000000"],["78308.00000000","0.03000000"],["78308.16000000","0.00000000"],["78308.17000000","0.10216000"],["78308.18000000","0.06948000"],["78309.11000000","0.01600000"],["78309.12000000","0.00000000"],["78309.24000000","0.00000000"],["78309.87000000","0.00000000"],["78310.34000000","0.00048000"],["78310.57000000","0.47665000"],["78311.73000000","0.00021000"],["78311.96000000","0.00400000"],["78313.22000000","0.00255000"],["78314.21000000","0.00000000"],["78315.02000000","0.00000000"],["78347.64000000","0.00000000"],["78355.25000000","0.00638000"],["78356.25000000","0.00000000"]]}}
{"rx":1788854552237675747, "m":{"e":"depthUpdate","E":1788854552214,"s":"BTCUSDT","U":99829867888,"u":99829867962,"b":[["78301.99000000","6.68569000"],["78301.98000000","0.63609000"],["78273.42000000","0.00012000"],["78263.75000000","0.00000000"],["77127.47000000","0.00024000"],["62642.00000000","0.00000000"],["62631.20000000","0.00000000"]],"a":[["78302.00000000","0.45764000"],["78302.01000000","0.00069000"],["78303.08000000","0.00103000"],["78303.53000000","0.00721000"],["78303.90000000","0.00007000"],["78303.91000000","0.05261000"],["78303.92000000","0.06699000"],["78303.98000000","0.00000000"],["78303.99000000","0.00000000"],["78306.04000000","0.01429000"],["78306.42000000","0.28899000"],["78306.43000000","0.00000000"],["78307.74000000","0.00014000"],["78307.83000000","0.00000000"],["78308.16000000","0.47665000"],["78309.10000000","0.00000000"],["78309.11000000","0.00000000"],["78309.24000000","0.00000000"],["78309.84000000","0.00108000"],["78310.56000000","0.01600000"],["78310.57000000","0.00000000"],["78312.43000000","0.00255000"],["78313.22000000","0.00000000"],["78315.66000000","0.00015000"],["78317.67000000","0.00108000"],["78323.49000000","0.00008000"],["78325.50000000","0.00108000"],["78331.32000000","0.00015000"],["78333.33000000","0.00108000"],["78339.40000000","0.00000000"],["78348.72000000","0.00400000"],["78349.09000000","0.00012000"],["78351.04000000","0.00000000"],["78376.88000000","0.00000000"]]}}
{"rx":1788854552337252829, "m":{"e":"depthUpdate","E":1788854552314,"s":"BTCUSDT","U":99829867963,"u":99829868042,"b":[["78301.99000000","6.68555000"],["78301.96000000","0.00000000"],["78301.91000000","0.00000000"],["78300.35000000","0.00000000"],["78300.01000000","0.38233000"],["78300.00000000","0.17933000"],["78299.50000000","0.02136000"],["78298.59000000","0.01313000"],["78292.01000000","0.37581000"],["78290.27000000","0.00000000"],["78284.70000000","0.02000000"],["78271.00000000","0.00000000"],["78265.79000000","1.26529000"],["78252.00000000","0.03000000"],["78238.32000000","0.00000000"],["78235.47000000","0.00000000"],["78204.16000000","0.00408000"],["77127.47000000","0.00032000"],["70471.80000000","0.00048000"]],"a":[["78302.00000000","0.05136000"],["78302.01000000","0.00062000"],["78303.08000000","0.00000000"],["78303.15000000","0.00000000"],["78303.90000000","0.00000000"],["78303.91000000","0.00014000"],["78303.92000000","0.00014000"],["78303.99000000","0.06795000"],["78304.40000000","0.00014000"],["78306.42000000","0.18909000"],["78306.62000000","0.06747000"],["78307.74000000","0.00007000"],["78308.16000000","0.00000000"],["78310.65000000","0.00000000"],["78310.70000000","0.02087000"],["78311.75000000","0.04007000"],["78311.87000000","0.00000000"],["78311.96000000","0.01311000"],["78312.43000000","0.00000000"],["78313.26000000","0.08000000"],["78313.29000000","0.00255000"],["78313.68000000","0.03400000"],["78314.70000000","0.00400000"],["78347.64000000","0.00000000"],["78353.63000000","0.00317000"],["78431.98000000","0.00127000"],["78525.55000000","0.00007000"],["78528.11000000","0.00000000"]]}}
{"rx":1788854552439240565, "m":{"e":"depthUpdate","E":1788854552414,"s":"BTCUSDT","U":99829868043,"u":99829868088,"b":[["78293.51000000","0.14039000"],["78283.15000000","0.02000000"],["78283.06000000","0.02000000"],["78272.65000000","0.00000000"],["78228.91000000","1.25740000"],["78183.14000000","0.08481000"],["77127.47000000","0.00032000"],["70469.98000000","0.00000000"],["62642.00000000","0.00000000"],["62640.00000000","0.03298000"]],"a":[["78302.00000000","0.05129000"],["78303.53000000","0.00721000"],["78303.91000000","0.00000000"],["78303.92000000","0.00000000"],["78303.99000000","0.06809000"],["78304.00000000","0.03014000"],["78304.40000000","0.00000000"],["78306.42000000","0.18923000"],["78306.62000000","0.06761000"],["78319.53000000","0.00000000"],["78321.46000000","0.03200000"],["78332.78000000","0.00060000"],["78356.48000000","0.65987000"],["78384.48000000","2.07741000"],["78397.00000000","0.03207000"],["78419.50000000","0.06168000"],["78419.99000000","0.00000000"],["78506.47000000","0.05136000"]]}}
{"rx":1788854552539240119, "m":{"e":"depthUpdate","E":1788854552514,"s":"BTCUSDT","U":99829868089,"u":99829868105,"b":[["78301.15000000","0.00007000"],["78283.46000000","0.02000000"],["78223.86000000","0.00000000"],["78214.41000000","0.02000000"],["77127.47000000","0.00032000"],["70471.80000000","0.00064000"],["70471.00000000","0.00000000"],["62641.60000000","0.00248000"]],"a":[["78329.66000000","0.36659000"],["78331.00000000","0.70000000"],["78358.42000000","0.00408000"],["78506.47000000","0.00000000"]]}}
{"rx":1788854552646116120, "m":{"e":"depthUpdate","E":1788854552614,"s":"BTCUSDT","U":99829868106,"u":99829868131,"b":[["78301.28000000","0.00000000"],["78296.00000000","0.66655000"],["78294.00000000","0.03000000"],["78292.00000000","0.10500000"],["78290.00000000","0.03000000"],["78288.00000000","0.03000000"],["78287.73000000","0.15323000"],["78283.15000000","0.04000000"],["78271.43000000","0.00000000"],["78271.01000000","0.00000000"],["77127.47000000","0.00032000"],["62641.59000000","0.00000000"],["62640.00000000","0.03267000"]],"a":[["78302.00000000","0.05122000"],["78321.31000000","0.03200000"],["78380.79000000","0.03200000"],["78506.39000000","0.00000000"]]}}
{"rx":1788854552743211484, "m":{"e":"depthUpdate","E":1788854552714,"s":"BTCUSDT","U":99829868132,"u":99829868147,"b":[["78301.15000000","0.01292000"],["78222.37000000","0.00000000"],["77974.36000000","0.00000000"],["77127.47000000","0.00032000"],["70471.80000000","0.00080000"]],"a":[["78302.00000000","0.05122000"],["78306.42000000","0.00014000"],["78307.99000000","0.16420000"],["78310.55000000","0.47665000"],["78320.53000000","0.04000000"],["78379.97000000","0.04000000"],["78380.79000000","0.00000000"],["78563.55000000","0.00032000"],["79476.53000000","0.00030000"]]}}
{"rx":1788854552837536919, "m":{"e":"depthUpdate","E":1788854552814,"s":"BTCUSDT","U":99829868148,"u":99829868188,"b":[["78301.90000000","0.05014000"],["78295.02000000","0.00007000"],["78291.50000000","0.55577000"],["78272.00000000","0.73007000"],["78271.08000000","0.00000000"],["78265.79000000","0.00000000"],["78194.03000000","0.04636000"],["78172.13000000","0.00000000"],["77983.73000000","0.00032000"],["77127.47000000","0.00040000"],["70471.80000000","0.00096000"],["62640.00000000","0.03236000"]],"a":[["78302.00000000","0.05129000"],["78302.01000000","0.00062000"],["78306.04000000","0.01429000"],["78306.42000000","0.00000000"],["78307.29000000","0.01429000"],["78307.97000000","0.30642000"],["78307.98000000","0.47665000"],["78307.99000000","0.00008000"],["78310.55000000","0.00000000"],["78311.20000000","0.12769000"],["78311.75000000","0.04000000"],["78313.29000000","0.00000000"],["78327.59000000","0.00000000"],["78334.03000000","0.00000000"],["78334.81000000","0.00000000"],["78347.64000000","0.00007000"],["78349.48000000","0.01163000"],["78389.72000000","0.00007000"]]}}
{"rx":1788854552938974483, "m":{"e":"depthUpdate","E":1788854552914,"s":"BTCUSDT","U":99829868189,"u":99829868202,"b":[["78272.00000000","0.03007000"],["78088.78000000","0.00802000"],["78079.18000000","0.00000000"],["77127.47000000","0.00040000"],["62642.00000000","0.00200000"]],"a":[["78307.29000000","0.01429000"],["78313.75000000","0.00007000"],["78314.78000000","0.00255000"],["78383.10000000","0.07599000"],["78397.00000000","0.00007000"],["78400.29000000","2.68103000"]]}}
{"rx":1788854553038397104, "m":{"e":"depthUpdate","E":1788854553014,"s":"BTCUSDT","U":99829868203,"u":99829869036,"b":[["78305.99000000","7.78289000"],["78305.98000000","0.00043000"],["78305.97000000","0.00013000"],["78304.81000000","0.00000000"],["78304.80000000","0.00000000"],["78304.79000000","0.07500000"],["78304.78000000","0.50976000"],["78304.77000000","0.00000000"],["78304.76000000","0.00000000"],["78304.70000000","0.00000000"],["78304.64000000","0.00400000"],["78304.35000000","0.06046000"],["78304.34000000","0.00000000"],["78304.30000000","0.00000000"],["78304.26000000","0.00000000"],["78304.18000000","0.00000000"],["78304.00000000","0.21146000"],["78303.99000000","0.65262000"],["78303.98000000","0.00000000"],["78303.90000000","0.05000000"],["78303.84000000","0.02098000"],["78303.75000000","0.00014000"],["78303.74000000","0.00000000"],["78303.70000000","0.00000000"],["78303.52000000","0.00000000"],["78303.42000000","0.01281000"],["78303.27000000","0.00150000"],["78302.33000000","0.00000000"],["78302.32000000","0.00400000"],["78302.00000000","2.12755000"],["78301.99000000","0.35290000"],["78301.98000000","0.14391000"],["78301.97000000","0.00000000"],["78301.95000000","0.00014000"],["78301.90000000","0.00014000"],["78301.69000000","0.03057000"],["78301.34000000","0.00026000"],["78300.87000000","0.00000000"],["78300.73000000","0.01374000"],["78300.34000000","0.00000000"],["78300.24000000","0.00400000"],["78300.02000000","0.33089000"],["78300.01000000","0.00000000"],["78300.00000000","0.18319000"],["78299.99000000","0.43703000"],["78299.88000000","0.00000000"],["78298.60000000","0.15186000"],["78298.19000000","0.00000000"],["78298.16000000","0.00008000"],["78297.71000000","0.00000000"],["78297.06000000","0.00000000"],["78296.90000000","0.00000000"],["78296.33000000","0.00000000"],["78296.16000000","0.00000000"],["78296.01000000","0.24341000"],["78295.50000000","0.00000000"],["78295.20000000","0.00000000"],["78294.15000000","0.00000000"],["78293.99000000","0.00007000"],["78292.20000000","0.00008000"],["78292.00000000","0.03000000"],["78290.99000000","0.09428000"],["78290.10000000","0.00000000"],["78289.37000000","0.00000000"],["78289.04000000","0.10260000"],["78288.99000000","0.41390000"],["78288.33000000","0.00008000"],["78287.73000000","0.00000000"],["78284.59000000","0.00000000"],["78284.41000000","0.00008000"],["78283.78000000","0.00000000"],["78282.91000000","0.00000000"],["78282.49000000","0.00000000"],["78280.53000000","0.00000000"],["78280.50000000","0.00008000"],["78280.42000000","0.00000000"],["78279.18000000","0.00000000"],["78276.58000000","0.00008000"],["78275.08000000","0.00000000"],["78272.67000000","0.00008000"],["78271.17000000","0.00000000"],["78269.86000000","0.00000000"],["78269.57000000","0.00000000"],["78268.99000000","0.36607000"],["78268.75000000","0.00008000"],["78268.67000000","0.00000000"],["78268.37000000","0.50485000"],["78268.08000000","0.00000000"],["78266.44000000","0.00000000"],["78265.32000000","0.00000000"],["78264.84000000","0.00008000"],["78263.85000000","0.00000000"],["78263.34000000","0.00000000"],["78262.00000000","0.03000000"],["78259.42000000","0.00000000"],["78258.52000000","0.00335000"],["78254.00000000","0.03000000"],["78252.90000000","0.06290000"],["78251.92000000","0.00000000"],["78250.94000000","0.00000000"],["78250.71000000","0.00000000"],["78243.06000000","0.77171000"],["78240.87000000","0.00000000"],["78234.87000000","0.00533000"],["78234.60000000","0.01735000"],["78231.74000000","2.44169000"],["78228.42000000","0.00180000"],["78222.36000000","0.19329000"],["78221.36000000","0.00000000"],["78216.94000000","0.00000000"],["78215.25000000","0.00000000"],["78215.09000000","0.02000000"],["78214.98000000","0.00000000"],["78211.13000000","0.00020000"],["78209.69000000","0.00000000"],["78206.52000000","0.00000000"],["78198.84000000","0.00000000"],["78198.83000000","0.00000000"],["78198.53000000","0.00000000"],["78190.98000000","0.08040000"],["78188.65000000","0.00000000"],["78166.34000000","1.53224000"],["78148.19000000","0.00000000"],["78096.71000000","0.29816000"],["78061.21000000","0.00000000"],["77983.73000000","0.00000000"],["77977.42000000","0.00000000"],["77131.41000000","0.00008000"],["77127.47000000","0.00000000"],["77127.46000000","0.00000000"],["70475.40000000","0.00016000"],["70471.80000000","0.00000000"],["70471.79000000","0.00009000"],["62642.00000000","0.00000000"],["62640.00000000","0.03205000"]],"a":[["78302.00000000","0.00000000"],["78302.01000000","0.00000000"],["78303.53000000","0.00000000"],["78303.75000000","0.00000000"],["78303.99000000","0.00000000"],["78304.00000000","0.00000000"],["78304.17000000","0.00000000"],["78304.27000000","0.00000000"],["78304.79000000","0.00000000"],["78304.80000000","0.00000000"],["78306.00000000","0.04458000"],["78306.01000000","0.00056000"],["78306.03000000","0.00007000"],["78306.62000000","0.00014000"],["78307.22000000","0.00000000"],["78307.96000000","0.00000000"],["78307.97000000","0.00014000"],["78307.98000000","0.00014000"],["78307.99000000","0.00000000"],["78308.00000000","0.03014000"],["78308.01000000","0.00000000"],["78308.17000000","0.10230000"],["78308.18000000","0.00517000"],["78308.19000000","0.00000000"],["78308.25000000","0.00000000"],["78308.32000000","0.00000000"],["78308.53000000","0.00000000"],["78308.61000000","0.00000000"],["78310.13000000","0.00000000"],["78310.34000000","0.00000000"],["78310.46000000","0.00000000"],["78310.55000000","0.00000000"],["78310.56000000","0.00000000"],["78310.58000000","0.00000000"],["78310.60000000","0.00000000"],["78310.67000000","0.00000000"],["78310.70000000","0.00000000"],["78310.95000000","0.00000000"],["78310.96000000","0.00000000"],["78311.07000000","0.00000000"],["78311.15000000","0.00000000"],["78311.20000000","0.00000000"],["78311.29000000","0.00000000"],["78311.34000000","0.00000000"],["78311.36000000","0.00000000"],["78311.37000000","0.00000000"],["78311.39000000","0.00000000"],["78311.73000000","0.00014000"],["78311.75000000","0.00000000"],["78311.83000000","0.00000000"],["78311.96000000","0.00000000"],["78312.00000000","0.03007000"],["78312.95000000","0.00000000"],["78313.01000000","0.00000000"],["78313.07000000","0.00000000"],["78313.17000000","0.15798000"],["78313.26000000","0.00000000"],["78313.31000000","0.00000000"],["78313.35000000","0.00007000"],["78313.55000000","0.00000000"],["78313.68000000","0.00000000"],["78313.75000000","0.00000000"],["78313.83000000","0.00008000"],["78313.99000000","0.01817000"],["78314.45000000","0.00000000"],["78314.47000000","0.00000000"],["78314.48000000","0.00000000"],["78314.70000000","0.00000000"],["78314.78000000","0.00000000"],["78314.95000000","0.00000000"],["78314.97000000","0.00000000"],["78315.00000000","0.00000000"],["78315.23000000","0.00000000"],["78315.29000000","0.00000000"],["78315.30000000","0.00000000"],["78315.31000000","0.00000000"],["78315.39000000","0.00000000"],["78315.44000000","0.00000000"],["78315.66000000","0.00007000"],["78315.68000000","0.47128000"],["78315.71000000","0.12768000"],["78315.72000000","0.00007000"],["78316.18000000","0.00000000"],["78316.37000000","0.00000000"],["78316.56000000","0.47128000"],["78316.68000000","0.47663000"],["78316.71000000","0.00000000"],["78317.57000000","0.47663000"],["78317.71000000","0.00007000"],["78317.75000000","0.00007000"],["78317.99000000","0.00000000"],["78318.13000000","0.00000000"],["78318.76000000","0.00000000"],["78319.13000000","0.00000000"],["78319.58000000","0.00000000"],["78319.66000000","0.00008000"],["78319.71000000","0.00007000"],["78319.96000000","0.00000000"],["78320.44000000","0.00638000"],["78320.45000000","0.00008000"],["78320.53000000","0.00000000"],["78320.56000000","0.00000000"],["78320.86000000","0.07000000"],["78321.18000000","0.00000000"],["78321.31000000","0.00000000"],["78321.46000000","0.00000000"],["78321.70000000","0.00000000"],["78321.86000000","0.08000000"],["78322.00000000","0.03000000"],["78322.01000000","0.75679000"],["78322.08000000","0.00159000"],["78322.25000000","0.00000000"],["78322.48000000","0.00638000"],["78323.49000000","0.00000000"],["78323.54000000","0.12767000"],["78323.58000000","0.00008000"],["78323.70000000","0.00007000"],["78323.75000000","0.00000000"],["78323.99000000","0.00000000"],["78324.00000000","0.03000000"],["78325.54000000","0.00000000"],["78325.69000000","0.00000000"],["78326.48000000","0.00400000"],["78326.49000000","0.00000000"],["78326.99000000","0.00000000"],["78327.41000000","0.00000000"],["78327.49000000","0.00008000"],["78327.60000000","0.01200000"],["78327.61000000","0.00000000"],["78329.41000000","0.00000000"],["78329.66000000","0.13840000"],["78329.68000000","0.00255000"],["78329.79000000","0.00000000"],["78331.00000000","0.00000000"],["78331.32000000","0.00007000"],["78331.41000000","0.00008000"],["78332.77000000","0.00049000"],["78333.32000000","0.31931000"],["78333.49000000","0.00000000"],["78333.56000000","0.00000000"],["78333.79000000","0.02000000"],["78333.99000000","0.00000000"],["78334.76000000","0.00000000"],["78335.24000000","0.00000000"],["78335.32000000","0.00008000"],["78335.34000000","0.00000000"],["78335.35000000","0.00007000"],["78335.41000000","0.00000000"],["78335.70000000","0.00000000"],["78337.76000000","0.31931000"],["78339.14000000","0.60835000"],["78339.15000000","0.00000000"],["78339.24000000","0.00008000"],["78341.19000000","0.31931000"],["78342.00000000","0.03000000"],["78343.15000000","0.00008000"],["78343.27000000","0.00000000"],["78343.46000000","0.00000000"],["78343.65000000","0.00014000"],["78343.86000000","0.00000000"],["78343.88000000","0.00007000"],["78344.00000000","0.03000000"],["78345.01000000","0.00000000"],["78345.99000000","0.31931000"],["78346.00000000","0.04000000"],["78346.93000000","0.63844000"],["78349.89000000","2.29734000"],["78350.20000000","0.00000000"],["78351.63000000","0.00007000"],["78352.07000000","0.00000000"],["78353.36000000","0.00400000"],["78353.63000000","0.00000000"],["78353.64000000","0.00000000"],["78355.12000000","0.00223000"],["78355.62000000","0.00007000"],["78355.68000000","0.00400000"],["78357.90000000","0.34467000"],["78358.00000000","0.03400000"],["78358.16000000","0.00319000"],["78359.61000000","0.00007000"],["78365.76000000","0.77050000"],["78367.87000000","0.00000000"],["78369.90000000","0.03800000"],["78372.37000000","0.00319000"],["78373.91000000","0.00000000"],["78375.05000000","0.00000000"],["78376.06000000","0.00729000"],["78378.74000000","1.26346000"],["78379.67000000","0.02600000"],["78383.10000000","0.00000000"],["78386.38000000","0.00000000"],["78390.95000000","0.00000000"],["78391.86000000","0.00000000"],["78393.89000000","2.29867000"],["78400.29000000","0.00000000"],["78404.17000000","3.82745000"],["78431.98000000","0.00000000"],["78443.99000000","0.01924000"],["78445.71000000","0.00000000"],["78463.93000000","1.53085000"],["78473.57000000","0.03363000"],["78474.27000000","1.57537000"],["78482.93000000","0.00000000"],["78482.94000000","0.00000000"],["78485.35000000","0.03057000"],["78522.56000000","0.00000000"],["78563.55000000","0.00000000"],["78842.44000000","0.00000000"],["79476.53000000","0.00000000"]]}}
{"rx":1788854553139819028, "m":{"e":"depthUpdate","E":1788854553114,"s":"BTCUSDT","U":99829869037,"u":99829869747,"b":[["78307.99000000","7.12692000"],["78307.98000000","0.31424000"],["78307.97000000","0.00029000"],["78307.96000000","0.00000000"],["78307.74000000","0.00014000"],["78307.59000000","0.00000000"],["78307.42000000","0.00000000"],["78307.29000000","0.19309000"],["78307.28000000","0.00014000"],["78307.27000000","0.00000000"],["78307.26000000","0.00000000"],["78306.96000000","0.00400000"],["78306.89000000","0.00000000"],["78306.61000000","0.00000000"],["78306.34000000","0.06046000"],["78306.04000000","0.07500000"],["78306.03000000","0.00000000"],["78306.02000000","0.00000000"],["78306.01000000","0.00000000"],["78306.00000000","2.07648000"],["78305.99000000","0.26821000"],["78305.98000000","0.00000000"],["78305.97000000","0.00000000"],["78305.95000000","0.05000000"],["78305.90000000","0.05000000"],["78304.80000000","0.00000000"],["78304.79000000","0.00014000"],["78304.78000000","0.25261000"],["78304.35000000","0.00014000"],["78304.00000000","0.00014000"],["78303.99000000","0.53202000"],["78303.90000000","0.00000000"],["78303.84000000","0.02098000"],["78302.02000000","0.26226000"],["78302.01000000","0.37581000"],["78302.00000000","2.00241000"],["78301.99000000","0.34452000"],["78301.98000000","0.14377000"],["78301.95000000","0.00000000"],["78301.90000000","0.00000000"],["78301.15000000","0.01285000"],["78300.73000000","0.00000000"],["78300.24000000","0.00000000"],["78300.15000000","0.00008000"],["78300.02000000","0.24083000"],["78300.00000000","0.10819000"],["78299.66000000","0.00010000"],["78299.48000000","0.00000000"],["78298.23000000","0.00000000"],["78298.16000000","0.00000000"],["78296.21000000","0.00007000"],["78292.32000000","0.16350000"],["78291.98000000","0.00000000"],["78291.50000000","0.40503000"],["78290.93000000","0.12229000"],["78288.40000000","0.00008000"],["78288.33000000","0.00000000"],["78285.15000000","0.00189000"],["78284.50000000","0.00127000"],["78284.49000000","0.00008000"],["78284.41000000","0.00000000"],["78280.64000000","0.02519000"],["78280.57000000","0.00008000"],["78280.50000000","0.00000000"],["78276.66000000","0.00008000"],["78276.58000000","0.00000000"],["78272.74000000","0.00008000"],["78272.67000000","0.00000000"],["78271.98000000","0.00000000"],["78268.83000000","0.00008000"],["78268.75000000","0.00000000"],["78267.84000000","0.00000000"],["78266.00000000","0.04000000"],["78264.84000000","0.00000000"],["78264.00000000","0.03000000"],["78251.79000000","0.01145000"],["78250.06000000","0.00000000"],["78248.75000000","0.00638000"],["78246.86000000","0.20000000"],["78239.19000000","0.01153000"],["78235.37000000","0.00428000"],["78233.76000000","0.00000000"],["78231.36000000","0.00000000"],["78209.57000000","0.00000000"],["78193.87000000","0.03960000"],["78184.60000000","0.00000000"],["78169.60000000","0.00009000"],["78163.60000000","0.00000000"],["78067.70000000","0.00000000"],["77992.60000000","0.00032000"],["77601.24000000","0.00010000"],["77131.41000000","0.00000000"],["77131.40000000","0.00030000"],["70475.40000000","0.00000000"],["62645.00000000","0.00284000"]],"a":[["78306.00000000","0.00000000"],["78306.01000000","0.00000000"],["78306.03000000","0.00000000"],["78306.04000000","0.00000000"],["78306.62000000","0.00000000"],["78306.90000000","0.00000000"],["78307.29000000","0.00000000"],["78307.43000000","0.00000000"],["78307.51000000","0.00000000"],["78307.74000000","0.00000000"],["78307.97000000","0.00000000"],["78307.98000000","0.00000000"],["78307.99000000","0.00000000"],["78308.00000000","0.04019000"],["78308.01000000","0.00063000"],["78308.16000000","0.00007000"],["78308.18000000","0.00517000"],["78309.25000000","0.23597000"],["78309.84000000","0.00000000"],["78310.00000000","0.03014000"],["78311.45000000","0.00000000"],["78311.89000000","0.00000000"],["78312.00000000","0.03021000"],["78312.48000000","0.00000000"],["78312.50000000","0.00000000"],["78313.17000000","0.09088000"],["78313.83000000","0.00000000"],["78313.99000000","0.00014000"],["78314.00000000","0.03014000"],["78314.80000000","0.00000000"],["78315.39000000","0.06724000"],["78315.67000000","0.00000000"],["78315.68000000","0.00000000"],["78315.70000000","0.04726000"],["78315.72000000","0.00007000"],["78315.82000000","0.00008000"],["78315.83000000","0.00108000"],["78316.55000000","0.00000000"],["78316.56000000","0.00000000"],["78316.68000000","0.00000000"],["78317.56000000","0.00000000"],["78317.57000000","0.00000000"],["78317.67000000","0.00000000"],["78317.76000000","0.00000000"],["78317.99000000","0.42932000"],["78319.66000000","0.00000000"],["78319.71000000","0.00014000"],["78320.84000000","0.00007000"],["78320.86000000","0.03000000"],["78321.86000000","0.00000000"],["78321.91000000","0.00047000"],["78322.00000000","0.03200000"],["78322.99000000","0.00048000"],["78323.58000000","0.00000000"],["78323.65000000","0.00008000"],["78323.66000000","0.00108000"],["78323.70000000","0.00014000"],["78324.37000000","0.00191000"],["78325.50000000","0.00000000"],["78326.16000000","0.12000000"],["78327.49000000","0.00000000"],["78327.57000000","0.00008000"],["78327.60000000","0.00400000"],["78329.24000000","0.00400000"],["78331.41000000","0.00000000"],["78331.48000000","0.00008000"],["78331.49000000","0.00108000"],["78333.33000000","0.00000000"],["78335.13000000","0.00000000"],["78335.32000000","0.00000000"],["78335.40000000","0.00008000"],["78339.24000000","0.00000000"],["78339.31000000","0.00008000"],["78339.32000000","0.00108000"],["78341.99000000","0.00000000"],["78343.15000000","0.00000000"],["78343.23000000","0.00008000"],["78346.00000000","0.03000000"],["78347.14000000","0.00008000"],["78348.00000000","0.04000000"],["78349.36000000","0.00000000"],["78349.86000000","0.20000000"],["78350.96000000","0.10000000"],["78355.62000000","0.00007000"],["78355.80000000","0.00626000"],["78355.90000000","0.00008000"],["78356.87000000","0.00427000"],["78357.27000000","0.00317000"],["78359.61000000","0.00000000"],["78360.32000000","0.00400000"],["78360.86000000","0.00433000"],["78368.96000000","0.04400000"],["78375.78000000","0.03600000"],["78389.75000000","0.00408000"],["78394.24000000","0.09373000"],["78397.08000000","0.00000000"],["78402.40000000","0.04533000"],["78403.09000000","0.00025000"],["78407.24000000","0.00000000"],["78412.33000000","0.00000000"],["78417.29000000","0.00000000"],["78419.50000000","0.00000000"],["78419.51000000","0.00000000"],["78428.82000000","0.10344000"],["78435.92000000","0.00127000"],["78533.04000000","0.02000000"],["78572.49000000","0.00038000"]]}}
{"rx":1788854553237199958, "m":{"e":"depthUpdate","E":1788854553214,"s":"BTCUSDT","U":99829869748,"u":99829869875,"b":[["78307.99000000","7.01946000"],["78307.98000000","0.31424000"],["78307.95000000","0.05000000"],["78307.90000000","0.05000000"],["78307.71000000","0.00400000"],["78307.29000000","0.19323000"],["78307.28000000","0.00000000"],["78306.73000000","0.01500000"],["78306.34000000","0.06060000"],["78306.10000000","0.00000000"],["78306.05000000","0.00800000"],["78306.04000000","0.07514000"],["78305.99000000","0.17460000"],["78305.95000000","0.00014000"],["78305.90000000","0.00000000"],["78305.48000000","0.01800000"],["78304.79000000","0.00000000"],["78304.78000000","0.25247000"],["78304.35000000","0.00000000"],["78304.23000000","0.01800000"],["78304.00000000","0.00000000"],["78299.99000000","0.43690000"],["78298.21000000","0.00007000"],["78292.16000000","0.00000000"],["78287.05000000","0.00059000"],["78278.80000000","0.88530000"],["78274.54000000","0.00000000"],["78268.00000000","0.04000000"],["78266.00000000","0.03000000"],["78195.66000000","0.00200000"],["78071.61000000","0.00000000"],["77716.67000000","0.00015000"],["77133.38000000","0.00008000"],["70477.20000000","0.00016000"],["62641.60000000","0.00217000"]],"a":[["78308.00000000","0.04047000"],["78308.01000000","0.00077000"],["78310.69000000","0.00632000"],["78311.72000000","0.00206000"],["78311.77000000","0.06582000"],["78311.95000000","0.01053000"],["78313.17000000","0.09088000"],["78313.20000000","0.01264000"],["78313.99000000","0.00000000"],["78314.00000000","0.03014000"],["78314.45000000","0.01264000"],["78315.03000000","0.12868000"],["78315.04000000","0.00000000"],["78315.39000000","0.06738000"],["78315.45000000","0.00158000"],["78315.68000000","0.00000000"],["78315.69000000","0.00000000"],["78315.70000000","0.00000000"],["78315.72000000","0.00014000"],["78315.84000000","0.20250000"],["78316.80000000","0.00000000"],["78317.68000000","0.00000000"],["78317.97000000","0.47127000"],["78317.98000000","0.00807000"],["78317.99000000","0.00000000"],["78321.66000000","0.00400000"],["78323.99000000","0.37581000"],["78329.24000000","0.00000000"],["78355.62000000","0.00000000"],["78363.17000000","0.88435000"],["78370.17000000","0.02800000"],["78413.26000000","0.00012000"],["78418.35000000","0.00019000"],["78423.31000000","0.00031000"],["78527.54000000","0.00007000"],["78530.84000000","0.00000000"],["78534.75000000","0.00000000"]]}}
{"rx":1788854553337191417, "m":{"e":"depthUpdate","E":1788854553314,"s":"BTCUSDT","U":99829869876,"u":99829870000,"b":[["78307.99000000","6.94459000"],["78307.98000000","0.31424000"],["78307.95000000","0.05014000"],["78307.90000000","0.05014000"],["78307.71000000","0.00000000"],["78307.29000000","0.13277000"],["78306.73000000","0.01514000"],["78306.43000000","0.00400000"],["78306.34000000","0.06060000"],["78306.05000000","0.00800000"],["78306.00000000","1.93666000"],["78305.99000000","0.07358000"],["78305.95000000","0.00000000"],["78305.29000000","0.00000000"],["78304.18000000","0.00255000"],["78302.02000000","0.77080000"],["78301.99000000","0.14202000"],["78300.15000000","0.20258000"],["78297.10000000","0.00008000"],["78296.89000000","0.00000000"],["78293.51000000","0.00000000"],["78268.37000000","0.00000000"],["78259.40000000","0.00000000"],["78248.10000000","0.00000000"],["77133.38000000","0.00016000"],["70477.20000000","0.00032000"],["62646.00000000","0.00000000"]],"a":[["78308.00000000","0.04068000"],["78308.01000000","0.00091000"],["78309.24000000","0.00000000"],["78309.93000000","0.00000000"],["78310.00000000","0.03014000"],["78310.69000000","0.00646000"],["78310.99000000","0.00007000"],["78311.77000000","0.06596000"],["78311.95000000","0.01067000"],["78313.16000000","0.00000000"],["78313.17000000","0.09074000"],["78314.00000000","0.03000000"],["78314.15000000","0.13246000"],["78314.16000000","0.00000000"],["78315.02000000","0.00000000"],["78315.03000000","0.00000000"],["78315.39000000","0.06724000"],["78315.70000000","0.00000000"],["78316.80000000","0.00000000"],["78317.68000000","0.00000000"],["78317.96000000","0.00800000"],["78317.97000000","0.00000000"],["78318.06000000","0.00400000"],["78319.26000000","0.00408000"],["78323.98000000","0.37581000"],["78323.99000000","0.00000000"],["78332.11000000","0.03000000"],["78344.99000000","0.50460000"],["78391.35000000","0.03000000"],["78514.87000000","0.00000000"],["78530.86000000","0.00007000"],["78534.77000000","0.00000000"]]}}
{"rx":1788854553438230402, "m":{"e":"depthUpdate","E":1788854553414,"s":"BTCUSDT","U":99829870001,"u":99829870029,"b":[["78307.29000000","0.67665000"],["78306.05000000","0.00000000"],["78304.00000000","0.00800000"],["78289.12000000","0.03828000"],["78282.11000000","1.24356000"],["78231.75000000","0.73481000"],["78199.54000000","0.09323000"],["78176.48000000","0.01908000"],["78096.72000000","0.00802000"],["78088.78000000","0.00000000"],["77292.28000000","0.00000000"],["77133.38000000","0.00024000"],["70471.79000000","0.00000000"],["70471.78000000","0.00009000"],["62641.60000000","0.00186000"]],"a":[["78308.00000000","0.03586000"],["78333.67000000","0.03800000"],["78333.79000000","0.05200000"],["78343.05000000","0.92335000"],["78366.17000000","1.42399000"],["78366.19000000","0.00000000"],["78396.90000000","0.03800000"],["78397.00000000","0.03207000"],["78403.99000000","1.15979000"],["78427.99000000","0.06223000"],["78514.34000000","0.00000000"],["82921.18000000","0.00000000"]]}}
{"rx":1788854553537217997, "m":{"e":"depthUpdate","E":1788854553514,"s":"BTCUSDT","U":99829870030,"u":99829870063,"b":[["78306.34000000","0.06060000"],["78299.87000000","0.21769000"],["78292.97000000","0.02000000"],["78253.74000000","0.22250000"],["78223.86000000","0.02000000"],["77133.38000000","0.00032000"],["70477.20000000","0.00048000"],["62646.40000000","0.00124000"]],"a":[["78314.15000000","0.07201000"],["78315.70000000","0.00000000"],["78315.84000000","0.00000000"],["78317.68000000","0.47125000"],["78317.95000000","0.47125000"],["78333.41000000","0.02800000"],["78337.96000000","0.20000000"],["78370.12000000","0.03400000"],["78382.07000000","0.00000000"],["78514.79000000","0.00000000"]]}}
{"rx":1788854553637224014, "m":{"e":"depthUpdate","E":1788854553614,"s":"BTCUSDT","U":99829870064,"u":99829870105,"b":[["78307.99000000","6.94795000"],["78306.63000000","0.00007000"],["78288.99000000","0.41262000"],["78286.47000000","0.08905000"],["78281.50000000","0.00000000"],["78234.03000000","0.00000000"],["78222.36000000","0.21329000"],["78214.41000000","0.00000000"],["77133.38000000","0.00032000"],["70477.00000000","0.00020000"],["62646.39000000","0.00000000"],["62646.00000000","0.00000000"],["62641.60000000","0.00155000"]],"a":[["78308.00000000","0.03543000"],["78313.35000000","0.00000000"],["78314.15000000","0.12293000"],["78315.83000000","0.00000000"],["78315.84000000","0.20301000"],["78317.95000000","0.00000000"],["78323.66000000","0.00000000"],["78323.67000000","0.00051000"],["78325.11000000","0.00007000"],["78331.49000000","0.00000000"],["78331.50000000","0.00451000"],["78333.64000000","0.03200000"],["78339.32000000","0.00000000"],["78339.33000000","0.00051000"],["78342.84000000","0.00000000"],["78358.16000000","0.00000000"],["78361.99000000","0.00317000"],["78391.35000000","0.00000000"],["78431.99000000","0.00000000"],["78439.99000000","0.00127000"],["79043.65000000","0.00000000"]]}}
{"rx":1788854553739009751, "m":{"e":"depthUpdate","E":1788854553714,"s":"BTCUSDT","U":99829870106,"u":99829871021,"b":[["78315.38000000","6.78750000"],["78315.37000000","0.00013000"],["78315.34000000","0.00007000"],["78315.11000000","0.00000000"],["78314.71000000","0.06000000"],["78314.57000000","0.00000000"],["78314.45000000","0.77438000"],["78314.44000000","5.94108000"],["78314.15000000","2.38891000"],["78314.14000000","0.54642000"],["78314.13000000","0.00000000"],["78314.12000000","0.00000000"],["78314.00000000","0.07500000"],["78313.99000000","0.93075000"],["78313.98000000","0.00016000"],["78313.97000000","0.00000000"],["78313.77000000","0.15184000"],["78313.76000000","0.00014000"],["78313.32000000","0.37581000"],["78313.16000000","0.00000000"],["78312.89000000","0.03057000"],["78312.36000000","0.00000000"],["78311.99000000","0.00000000"],["78311.94000000","0.00000000"],["78311.79000000","0.00000000"],["78311.76000000","0.00000000"],["78311.73000000","0.00014000"],["78311.72000000","0.00000000"],["78311.71000000","0.00000000"],["78311.64000000","0.00000000"],["78311.35000000","0.00400000"],["78310.98000000","0.00000000"],["78310.68000000","0.10630000"],["78310.67000000","0.00000000"],["78310.57000000","0.00000000"],["78310.52000000","0.00000000"],["78310.26000000","0.00000000"],["78309.99000000","0.00000000"],["78309.79000000","0.00026000"],["78309.25000000","0.00000000"],["78309.24000000","0.61533000"],["78309.19000000","0.00000000"],["78309.15000000","0.18412000"],["78309.14000000","0.00000000"],["78309.02000000","1.70490000"],["78309.01000000","0.00000000"],["78308.32000000","0.00000000"],["78308.17000000","0.00000000"],["78308.16000000","0.00000000"],["78308.15000000","0.00000000"],["78308.00000000","0.23703000"],["78307.99000000","0.69724000"],["78307.98000000","0.15333000"],["78307.97000000","0.00000000"],["78307.95000000","0.00000000"],["78307.90000000","0.00000000"],["78307.29000000","0.04077000"],["78306.73000000","0.01500000"],["78306.43000000","0.00000000"],["78306.34000000","0.00000000"],["78306.04000000","0.00000000"],["78306.00000000","1.86166000"],["78305.99000000","0.01958000"],["78305.93000000","0.00008000"],["78304.78000000","0.10247000"],["78304.18000000","0.00000000"],["78304.00000000","0.00000000"],["78302.03000000","2.29861000"],["78302.00000000","2.00249000"],["78301.70000000","0.13845000"],["78300.15000000","0.20250000"],["78300.02000000","0.36702000"],["78300.00000000","0.00400000"],["78299.99000000","0.27730000"],["78298.87000000","0.38326000"],["78298.60000000","0.00000000"],["78298.10000000","0.00008000"],["78295.34000000","0.10259000"],["78294.18000000","0.00008000"],["78294.14000000","0.00000000"],["78293.83000000","0.32702000"],["78292.32000000","0.00000000"],["78290.99000000","0.00000000"],["78290.27000000","0.00008000"],["78289.96000000","0.02000000"],["78289.17000000","0.52460000"],["78289.04000000","0.00000000"],["78288.40000000","0.00000000"],["78286.35000000","0.00008000"],["78284.49000000","0.00000000"],["78283.17000000","0.00000000"],["78282.43000000","0.00008000"],["78280.57000000","0.00000000"],["78280.00000000","0.73113000"],["78278.65000000","0.00000000"],["78278.52000000","0.00008000"],["78276.66000000","0.00000000"],["78275.82000000","0.00007000"],["78274.60000000","0.00008000"],["78273.60000000","0.00000000"],["78272.74000000","0.00000000"],["78271.83000000","0.00007000"],["78270.28000000","0.00000000"],["78268.83000000","0.00000000"],["78267.72000000","0.00335000"],["78262.68000000","0.77151000"],["78253.73000000","0.00000000"],["78252.90000000","0.00000000"],["78249.64000000","0.00318000"],["78247.84000000","0.00000000"],["78246.86000000","0.00000000"],["78242.79000000","0.04432000"],["78239.77000000","0.00000000"],["78238.74000000","0.00318000"],["78235.45000000","0.00008000"],["78235.37000000","0.00111000"],["78224.59000000","0.00000000"],["78223.68000000","0.00000000"],["78215.67000000","0.00000000"],["78171.26000000","0.00127000"],["78158.01000000","0.00127000"],["78157.13000000","0.00008000"],["78145.38000000","0.01114000"],["78143.33000000","0.00000000"],["78132.45000000","0.00000000"],["78103.29000000","0.00000000"],["78078.82000000","0.00008000"],["78067.07000000","0.00000000"],["78000.50000000","0.00153000"],["77988.77000000","0.00000000"],["77922.19000000","0.00008000"],["77910.47000000","0.00000000"],["77843.88000000","0.00008000"],["77832.17000000","0.00000000"],["77765.56000000","0.00033000"],["77753.87000000","0.00000000"],["77687.25000000","0.00008000"],["77675.56000000","0.00000000"],["77133.38000000","0.00000000"],["70477.20000000","0.00000000"],["70477.00000000","0.00000000"],["70471.78000000","0.00000000"]],"a":[["78308.00000000","0.00000000"],["78308.01000000","0.00000000"],["78308.16000000","0.00000000"],["78308.17000000","0.00000000"],["78308.18000000","0.00000000"],["78309.25000000","0.00000000"],["78310.00000000","0.00000000"],["78310.27000000","0.00000000"],["78310.69000000","0.00000000"],["78310.99000000","0.00000000"],["78311.72000000","0.00000000"],["78311.73000000","0.00000000"],["78311.77000000","0.00000000"],["78311.80000000","0.00000000"],["78311.95000000","0.00000000"],["78312.00000000","0.00000000"],["78313.17000000","0.00000000"],["78313.20000000","0.00000000"],["78313.33000000","0.00000000"],["78314.00000000","0.00000000"],["78314.01000000","0.00000000"],["78314.02000000","0.00000000"],["78314.14000000","0.00000000"],["78314.15000000","0.00000000"],["78314.16000000","0.00000000"],["78314.45000000","0.00000000"],["78314.58000000","0.00000000"],["78315.12000000","0.00000000"],["78315.35000000","0.00000000"],["78315.38000000","0.00000000"],["78315.39000000","0.00063000"],["78315.40000000","0.00042000"],["78315.66000000","0.00000000"],["78315.71000000","0.00014000"],["78315.72000000","0.00007000"],["78315.82000000","0.00000000"],["78315.84000000","0.00065000"],["78315.90000000","0.00000000"],["78316.00000000","0.03014000"],["78316.14000000","0.00000000"],["78316.38000000","0.00000000"],["78317.68000000","0.00014000"],["78317.71000000","0.00000000"],["78317.75000000","0.00000000"],["78317.80000000","0.00014000"],["78317.96000000","0.00007000"],["78317.98000000","0.00007000"],["78318.00000000","0.03007000"],["78318.06000000","0.00000000"],["78318.37000000","0.00007000"],["78318.97000000","0.00000000"],["78319.14000000","0.00000000"],["78319.17000000","0.00000000"],["78319.44000000","0.00000000"],["78319.59000000","0.00000000"],["78319.71000000","0.00007000"],["78319.82000000","0.00000000"],["78320.00000000","0.03007000"],["78320.10000000","0.06702000"],["78320.38000000","0.00000000"],["78320.52000000","0.00000000"],["78320.79000000","0.59900000"],["78320.80000000","0.00000000"],["78320.86000000","0.00000000"],["78321.61000000","0.00000000"],["78321.66000000","0.00000000"],["78321.83000000","0.00008000"],["78322.08000000","0.00000000"],["78322.48000000","0.00000000"],["78323.51000000","0.00000000"],["78323.54000000","0.00000000"],["78323.65000000","0.00000000"],["78323.70000000","0.00007000"],["78323.97000000","0.00007000"],["78323.98000000","0.00000000"],["78324.01000000","0.00007000"],["78324.08000000","0.01329000"],["78325.66000000","0.00000000"],["78325.94000000","0.09424000"],["78326.16000000","0.00000000"],["78326.48000000","0.00000000"],["78326.51000000","0.00000000"],["78326.66000000","0.01000000"],["78326.76000000","0.02000000"],["78326.86000000","0.04000000"],["78326.96000000","0.00000000"],["78327.10000000","0.00007000"],["78327.43000000","0.01330000"],["78327.57000000","0.00000000"],["78327.60000000","0.00000000"],["78327.69000000","0.00007000"],["78327.76000000","0.08000000"],["78327.89000000","0.10255000"],["78328.22000000","0.02096000"],["78329.66000000","0.08519000"],["78329.68000000","0.20250000"],["78331.35000000","0.01309000"],["78331.48000000","0.00000000"],["78331.68000000","0.00007000"],["78332.84000000","0.04000000"],["78332.94000000","0.00000000"],["78333.32000000","0.00000000"],["78333.58000000","0.00008000"],["78335.27000000","0.01279000"],["78335.40000000","0.00000000"],["78336.06000000","0.02130000"],["78336.13000000","0.00000000"],["78337.05000000","0.00000000"],["78337.49000000","0.00008000"],["78337.64000000","0.00127000"],["78337.73000000","0.00063000"],["78337.76000000","0.00000000"],["78339.31000000","0.00000000"],["78341.00000000","0.00000000"],["78341.19000000","0.00000000"],["78341.41000000","0.00008000"],["78343.06000000","0.00000000"],["78343.23000000","0.00000000"],["78343.30000000","0.00000000"],["78343.90000000","0.02072000"],["78344.07000000","0.00000000"],["78344.99000000","0.00000000"],["78345.33000000","0.00008000"],["78345.75000000","0.37581000"],["78345.99000000","0.00000000"],["78347.14000000","0.00000000"],["78347.64000000","0.00014000"],["78347.88000000","0.00000000"],["78348.00000000","0.03000000"],["78349.24000000","0.00008000"],["78349.86000000","0.00000000"],["78351.63000000","0.00014000"],["78351.74000000","0.02149000"],["78353.16000000","0.00008000"],["78355.12000000","0.00000000"],["78355.20000000","0.63830000"],["78355.62000000","0.00007000"],["78357.09000000","0.77058000"],["78357.27000000","0.00000000"],["78359.61000000","0.00007000"],["78359.67000000","0.00000000"],["78359.80000000","0.34466000"],["78361.99000000","0.00000000"],["78365.69000000","0.00400000"],["78367.87000000","0.00317000"],["78367.88000000","1.38911000"],["78371.50000000","0.00000000"],["78372.37000000","0.00000000"],["78373.53000000","0.00223000"],["78378.66000000","0.00000000"],["78381.48000000","0.00319000"],["78386.47000000","0.00000000"],["78387.56000000","0.00008000"],["78391.99000000","0.72928000"],["78394.24000000","0.09373000"],["78396.90000000","0.00000000"],["78399.59000000","0.04000000"],["78399.99000000","0.79367000"],["78403.29000000","2.29861000"],["78410.57000000","0.00000000"],["78419.99000000","0.03078000"],["78421.38000000","0.00000000"],["78435.92000000","0.00000000"],["78445.99000000","0.00000000"],["78456.96000000","0.00000000"],["78459.98000000","0.00127000"],["78465.87000000","0.00008000"],["78507.91000000","3.82239000"],["78514.08000000","0.00000000"],["78514.77000000","0.00000000"],["78515.71000000","0.00000000"],["78535.26000000","0.00000000"],["78544.18000000","0.00008000"],["78613.56000000","0.00180000"],["78622.49000000","0.00008000"],["78691.86000000","0.00000000"],["78700.80000000","0.00008000"],["78770.16000000","0.00010000"],["78779.11000000","0.00008000"],["78848.46000000","0.00000000"],["78857.41000000","0.00008000"],["78926.76000000","0.00000000"],["78935.72000000","0.00008000"],["79482.62000000","0.00000000"]]}}
{"rx":1788854553838463410, "m":{"e":"depthUpdate","E":1788854553814,"s":"BTCUSDT","U":99829871022,"u":99829871567,"b":[["78315.99000000","7.05621000"],["78315.98000000","0.00029000"],["78315.97000000","0.00013000"],["78315.89000000","0.00000000"],["78315.83000000","0.00014000"],["78315.81000000","0.00000000"],["78315.72000000","0.00028000"],["78315.71000000","0.14364000"],["78315.70000000","0.26460000"],["78315.69000000","0.00000000"],["78315.68000000","0.00000000"],["78315.65000000","0.00000000"],["78315.45000000","0.00000000"],["78315.44000000","0.00000000"],["78315.39000000","0.00014000"],["78315.38000000","0.40401000"],["78315.37000000","0.00000000"],["78315.36000000","0.00000000"],["78315.34000000","0.00000000"],["78314.72000000","0.00014000"],["78314.71000000","0.07014000"],["78314.47000000","0.00007000"],["78314.46000000","0.37581000"],["78314.45000000","0.00014000"],["78314.44000000","0.00014000"],["78314.36000000","0.06067000"],["78314.15000000","0.00014000"],["78314.14000000","0.24321000"],["78314.00000000","0.00014000"],["78313.99000000","0.52360000"],["78313.98000000","0.00000000"],["78313.82000000","0.00400000"],["78313.77000000","0.00000000"],["78313.76000000","0.00000000"],["78313.75000000","0.00000000"],["78313.33000000","0.06078000"],["78313.32000000","0.00000000"],["78312.94000000","0.02173000"],["78312.54000000","0.00638000"],["78312.53000000","0.04075000"],["78310.68000000","0.10616000"],["78310.07000000","0.01307000"],["78309.24000000","0.61519000"],["78309.15000000","0.00000000"],["78309.14000000","0.00000000"],["78309.02000000","0.73236000"],["78308.25000000","0.00008000"],["78308.16000000","0.00008000"],["78308.00000000","0.16203000"],["78307.99000000","0.68342000"],["78307.50000000","0.00010000"],["78307.29000000","0.00000000"],["78307.23000000","0.00007000"],["78306.74000000","0.03439000"],["78306.73000000","0.00000000"],["78306.01000000","0.15185000"],["78305.99000000","0.01320000"],["78305.93000000","0.00000000"],["78305.48000000","0.00000000"],["78304.23000000","0.00000000"],["78304.18000000","0.00007000"],["78302.30000000","0.00007000"],["78302.04000000","1.53182000"],["78302.02000000","0.00000000"],["78302.00000000","1.86174000"],["78301.99000000","0.00016000"],["78301.98000000","0.00000000"],["78300.02000000","0.24083000"],["78299.99000000","0.26958000"],["78298.88000000","0.13845000"],["78298.59000000","0.00000000"],["78296.32000000","0.00000000"],["78296.01000000","0.00000000"],["78295.03000000","0.03439000"],["78293.08000000","0.02000000"],["78292.79000000","0.00012000"],["78289.01000000","0.20000000"],["78287.19000000","0.00000000"],["78286.80000000","0.02512000"],["78283.18000000","0.00000000"],["78280.64000000","0.00000000"],["78279.29000000","0.00000000"],["78278.48000000","0.00000000"],["78276.71000000","0.00000000"],["78275.82000000","0.00000000"],["78275.52000000","0.00000000"],["78274.88000000","0.00000000"],["78266.11000000","0.00618000"],["78261.30000000","0.00430000"],["78258.97000000","0.00435000"],["78258.52000000","0.00000000"],["78250.59000000","0.00000000"],["78246.58000000","0.00000000"],["78246.31000000","0.00000000"],["78227.57000000","0.06353000"],["78178.94000000","0.00000000"],["78178.79000000","1.33057000"],["78079.43000000","0.00000000"],["78075.52000000","0.00000000"],["77141.26000000","0.00008000"],["62641.60000000","0.00124000"]],"a":[["78315.39000000","0.00000000"],["78315.40000000","0.00000000"],["78315.45000000","0.00000000"],["78315.71000000","0.00000000"],["78315.72000000","0.00000000"],["78315.84000000","0.00000000"],["78316.00000000","0.60984000"],["78316.01000000","0.00063000"],["78317.68000000","0.00000000"],["78317.80000000","0.00000000"],["78317.96000000","0.00000000"],["78317.98000000","0.00000000"],["78317.99000000","0.00007000"],["78318.00000000","0.03014000"],["78318.37000000","0.00000000"],["78318.79000000","0.00206000"],["78319.51000000","0.14982000"],["78319.52000000","0.00000000"],["78319.99000000","0.00000000"],["78320.00000000","0.03021000"],["78320.10000000","0.00014000"],["78320.40000000","0.00000000"],["78320.44000000","0.00014000"],["78320.79000000","0.00014000"],["78321.27000000","0.00463000"],["78321.28000000","0.00000000"],["78321.81000000","0.00000000"],["78321.83000000","0.00000000"],["78321.89000000","0.00000000"],["78321.98000000","0.76889000"],["78321.99000000","2.29861000"],["78322.00000000","0.03214000"],["78322.01000000","0.00014000"],["78322.33000000","0.00000000"],["78322.53000000","0.00772000"],["78322.71000000","0.02090000"],["78323.04000000","0.00000000"],["78323.24000000","0.06702000"],["78323.28000000","0.00000000"],["78323.70000000","0.00014000"],["78323.78000000","0.00927000"],["78323.83000000","0.00008000"],["78323.92000000","0.00000000"],["78324.00000000","0.03014000"],["78324.30000000","0.12767000"],["78324.80000000","0.00000000"],["78325.03000000","0.00927000"],["78325.68000000","0.00000000"],["78325.71000000","0.00000000"],["78325.72000000","1.32523000"],["78325.86000000","0.00400000"],["78327.14000000","0.00007000"],["78327.42000000","0.00000000"],["78327.61000000","0.00000000"],["78327.62000000","2.29861000"],["78327.69000000","0.00014000"],["78327.83000000","0.00000000"],["78328.59000000","0.00638000"],["78329.24000000","0.00638000"],["78329.66000000","0.24856000"],["78330.76000000","0.00159000"],["78331.58000000","0.00000000"],["78331.59000000","0.00000000"],["78331.68000000","0.00014000"],["78332.78000000","0.00000000"],["78332.93000000","0.00400000"],["78332.94000000","0.38781000"],["78332.95000000","1.39311000"],["78333.79000000","0.03200000"],["78336.01000000","0.20000000"],["78336.59000000","0.02000000"],["78337.66000000","0.00255000"],["78340.80000000","0.31928000"],["78343.05000000","0.61534000"],["78344.45000000","0.00574000"],["78344.94000000","0.31928000"],["78346.96000000","0.00012000"],["78347.32000000","0.00193000"],["78347.68000000","0.00060000"],["78348.71000000","0.31928000"],["78352.10000000","0.00000000"],["78352.51000000","0.31928000"],["78363.22000000","0.00400000"],["78366.28000000","0.03828000"],["78366.77000000","0.00319000"],["78367.26000000","0.00000000"],["78367.70000000","0.00424000"],["78368.16000000","0.00400000"],["78370.32000000","0.00000000"],["78370.62000000","0.00000000"],["78376.89000000","0.04200000"],["78376.99000000","0.40962000"],["78384.48000000","1.41769000"],["78385.71000000","0.00112000"],["78386.36000000","0.00567000"],["78386.43000000","0.01690000"],["78398.40000000","0.07609000"],["78404.75000000","0.25548000"],["78407.24000000","0.77418000"],["78407.27000000","0.00000000"],["78410.52000000","2.20953000"],["78412.57000000","0.05107000"],["78419.99000000","0.01795000"],["78445.49000000","0.00127000"],["78451.51000000","0.00000000"],["78481.99000000","0.03041000"],["78519.50000000","0.00000000"],["78520.10000000","0.00000000"],["78535.39000000","0.00007000"],["78539.30000000","0.00007000"],["78543.08000000","0.00007000"],["78546.99000000","0.00007000"]]}}
{"rx":1788854553937784020, "m":{"e":"depthUpdate","E":1788854553914,"s":"BTCUSDT","U":99829871568,"u":99829871713,"b":[["78315.99000000","7.60557000"],["78315.98000000","0.00043000"],["78315.83000000","0.00000000"],["78315.71000000","0.14378000"],["78315.38000000","0.35401000"],["78314.73000000","0.01781000"],["78314.71000000","0.07014000"],["78314.47000000","0.00007000"],["78314.46000000","0.37595000"],["78314.45000000","0.00000000"],["78314.44000000","0.00000000"],["78314.36000000","0.06081000"],["78314.15000000","0.00000000"],["78314.14000000","0.24321000"],["78314.00000000","0.00000000"],["78313.99000000","0.52374000"],["78313.48000000","0.02137000"],["78312.89000000","0.00000000"],["78312.23000000","0.02137000"],["78310.69000000","0.26208000"],["78307.99000000","0.57910000"],["78297.30000000","0.09428000"],["78275.99000000","0.60884000"],["78271.83000000","0.00000000"],["78193.89000000","0.17092000"],["78193.87000000","0.00000000"],["78083.34000000","0.00000000"],["77141.26000000","0.00016000"],["70484.40000000","0.00016000"]],"a":[["78316.00000000","0.59432000"],["78316.01000000","0.00063000"],["78318.00000000","0.03014000"],["78318.83000000","0.00007000"],["78319.51000000","0.00014000"],["78320.00000000","0.03021000"],["78320.10000000","0.00000000"],["78320.29000000","0.26558000"],["78320.30000000","0.42913000"],["78320.44000000","0.00000000"],["78320.79000000","0.00000000"],["78321.14000000","0.46045000"],["78321.15000000","0.00000000"],["78321.16000000","0.00000000"],["78321.96000000","1.78852000"],["78321.97000000","2.95889000"],["78321.98000000","0.00014000"],["78321.99000000","2.29875000"],["78322.00000000","0.03214000"],["78322.01000000","0.00000000"],["78322.53000000","0.00786000"],["78322.71000000","0.02104000"],["78323.48000000","0.00151000"],["78324.00000000","0.03000000"],["78332.93000000","0.00000000"],["78332.94000000","0.38381000"],["78366.77000000","0.00000000"],["78397.00000000","0.00007000"],["78427.99000000","0.03558000"],["78428.82000000","0.00000000"],["78435.99000000","0.05512000"],["78437.87000000","0.10344000"],["78445.49000000","0.00000000"],["78521.28000000","0.00015000"],["78522.35000000","0.00000000"],["78533.01000000","0.00007000"],["78546.99000000","0.00000000"],["79517.05000000","0.00031000"]]}}
{"rx":1788854554039018773, "m":{"e":"depthUpdate","E":1788854554014,"s":"BTCUSDT","U":99829871714,"u":99829871859,"b":[["78315.99000000","7.60826000"],["78315.70000000","0.46710000"],["78315.38000000","0.35401000"],["78315.05000000","0.00000000"],["78315.00000000","0.00000000"],["78314.73000000","0.01795000"],["78314.14000000","0.24321000"],["78313.99000000","0.52360000"],["78313.33000000","0.06078000"],["78310.69000000","0.00000000"],["78309.24000000","0.41269000"],["78307.98000000","0.15333000"],["78307.28000000","0.00000000"],["78305.99000000","0.01320000"],["78299.09000000","0.02000000"],["78296.06000000","0.02000000"],["78295.21000000","0.02000000"],["78287.41000000","0.00012000"],["78278.14000000","0.00000000"],["78276.00000000","0.04025000"],["78273.42000000","0.00000000"],["78268.00000000","0.03000000"],["78265.57000000","0.00435000"],["78259.86000000","0.02000000"],["78250.37000000","0.00000000"],["78202.90000000","0.03960000"],["78193.89000000","0.11245000"],["77141.26000000","0.00024000"],["77131.40000000","0.00000000"],["70484.40000000","0.00032000"],["62652.80000000","0.00124000"],["62641.60000000","0.00093000"]],"a":[["78316.00000000","0.44739000"],["78316.01000000","0.00070000"],["78317.99000000","0.02011000"],["78318.00000000","0.03014000"],["78319.43000000","0.00000000"],["78319.44000000","0.00000000"],["78319.51000000","0.00000000"],["78320.00000000","0.03021000"],["78320.29000000","0.00014000"],["78320.30000000","0.00014000"],["78321.14000000","0.00014000"],["78321.16000000","0.46045000"],["78321.95000000","0.46045000"],["78321.96000000","1.78866000"],["78321.97000000","2.95903000"],["78321.98000000","0.00000000"],["78322.00000000","0.03200000"],["78322.53000000","0.00772000"],["78322.71000000","0.00000000"],["78323.67000000","0.00000000"],["78323.84000000","0.00030000"],["78324.08000000","0.00000000"],["78324.27000000","0.01298000"],["78327.30000000","0.00400000"],["78331.50000000","0.00400000"],["78331.67000000","0.00030000"],["78339.33000000","0.00000000"],["78339.50000000","0.00030000"],["78347.33000000","0.00030000"],["78349.04000000","0.52612000"],["78349.09000000","0.00000000"],["78350.00000000","0.03000000"],["78350.87000000","0.00400000"],["78356.00000000","0.04000000"],["78363.09000000","0.00012000"],["78366.77000000","0.00319000"],["78368.16000000","0.00000000"],["78373.36000000","1.03910000"],["78380.60000000","0.03400000"],["78445.49000000","0.00127000"],["78522.13000000","0.00000000"],["78522.30000000","0.00000000"],["78539.30000000","0.00000000"],["78543.08000000","0.00000000"],["79490.74000000","0.00030000"]]}}
{"rx":1788854554137587772, "m":{"e":"depthUpdate","E":1788854554114,"s":"BTCUSDT","U":99829871860,"u":99829871941,"b":[["78315.71000000","0.76645000"],["78315.70000000","0.31455000"],["78315.15000000","0.00647000"],["78315.10000000","0.00000000"],["78314.47000000","0.00014000"],["78306.63000000","0.00000000"],["78300.01000000","0.02000000"],["78299.87000000","0.00000000"],["78299.84000000","0.02000000"],["78260.61000000","0.02000000"],["78179.58000000","0.00025000"],["78169.60000000","0.00000000"],["77141.25000000","0.00030000"]],"a":[["78316.00000000","0.44760000"],["78316.01000000","0.00070000"],["78317.99000000","0.15765000"],["78320.00000000","0.03021000"],["78320.29000000","0.00000000"],["78320.30000000","0.46045000"],["78321.14000000","0.00000000"],["78321.16000000","0.00014000"],["78321.94000000","0.00400000"],["78321.95000000","0.00000000"],["78321.97000000","2.95103000"],["78322.76000000","0.02132000"],["78323.84000000","0.00000000"],["78324.27000000","0.00000000"],["78324.29000000","0.01335000"],["78329.23000000","0.00000000"],["78331.56000000","0.12766000"],["78331.67000000","0.00000000"],["78332.93000000","0.00400000"],["78339.39000000","0.12764000"],["78339.50000000","0.00000000"],["78347.33000000","0.00000000"],["78399.59000000","0.00000000"],["78413.26000000","0.00000000"],["78418.35000000","0.00000000"],["78423.31000000","0.00000000"],["78521.73000000","0.00000000"],["78522.54000000","0.00000000"]]}}
{"rx":1788854554243015013, "m":{"e":"depthUpdate","E":1788854554214,"s":"BTCUSDT","U":99829871942,"u":99829872011,"b":[["78315.99000000","7.60213000"],["78315.80000000","0.00000000"],["78315.75000000","0.00000000"],["78315.38000000","0.35401000"],["78315.15000000","0.00661000"],["78314.14000000","0.24307000"],["78299.23000000","0.02000000"],["78260.00000000","0.05071000"],["77141.26000000","0.00032000"],["70484.40000000","0.00048000"],["70484.39000000","0.00009000"],["62641.60000000","0.00062000"]],"a":[["78316.00000000","0.60281000"],["78317.99000000","0.02019000"],["78319.23000000","0.00000000"],["78320.00000000","0.03021000"],["78320.30000000","0.00014000"],["78321.16000000","0.00000000"],["78321.94000000","0.00000000"],["78321.95000000","0.46845000"],["78322.00000000","0.03214000"],["78322.76000000","0.00000000"],["78324.29000000","0.00000000"],["78328.41000000","0.00255000"],["78330.99000000","0.00007000"],["78332.77000000","0.00000000"],["78332.93000000","0.00000000"],["78339.38000000","0.00049000"],["78369.20000000","0.00667000"],["78423.26000000","0.00012000"],["78428.36000000","0.00019000"],["78433.32000000","0.00031000"],["78522.10000000","0.00000000"]]}}
{"rx":1788854554337508534, "m":{"e":"depthUpdate","E":1788854554314,"s":"BTCUSDT","U":99829872012,"u":99829872049,"b":[["78315.99000000","7.60180000"],["78296.87000000","0.02000000"],["78274.61000000","0.00000000"],["78270.32000000","1.02892000"],["78237.69000000","0.00000000"],["78204.16000000","0.00000000"],["77292.28000000","0.00010000"],["77141.26000000","0.00032000"]],"a":[["78316.00000000","0.60274000"],["78316.01000000","0.00070000"],["78319.26000000","0.00000000"],["78320.00000000","0.03021000"],["78320.30000000","0.00000000"],["78321.94000000","0.00800000"],["78321.95000000","0.46059000"],["78332.93000000","0.00000000"],["78358.42000000","0.00000000"],["78389.75000000","0.00000000"],["78522.85000000","0.00000000"]]}}
{"rx":1788854554437480255, "m":{"e":"depthUpdate","E":1788854554414,"s":"BTCUSDT","U":99829872050,"u":99829872089,"b":[["78315.99000000","7.61197000"],["78313.99000000","0.51061000"],["78313.52000000","0.01310000"],["78305.57000000","0.15866000"],["78295.32000000","0.02000000"],["78295.23000000","0.02000000"],["78284.70000000","0.00000000"],["78232.36000000","0.00000000"],["77141.26000000","0.00032000"],["70484.40000000","0.00064000"],["62641.60000000","0.00031000"]],"a":[["78316.00000000","0.60296000"],["78316.01000000","0.00077000"],["78317.99000000","0.15383000"],["78320.00000000","0.03021000"],["78321.16000000","0.46050000"],["78321.93000000","0.00800000"],["78321.94000000","0.00014000"],["78322.00000000","0.03200000"],["78327.43000000","0.00000000"],["78327.84000000","0.01335000"],["78350.01000000","0.00223000"],["78373.53000000","0.00000000"],["78398.40000000","0.00000000"]]}}
{"rx":1788854554537555351, "m":{"e":"depthUpdate","E":1788854554514,"s":"BTCUSDT","U":99829872090,"u":99829872156,"b":[["78313.52000000","0.00000000"],["78312.66000000","0.01314000"],["78310.12000000","0.00013000"],["78295.63000000","0.02000000"],["78234.70000000","0.00000000"],["78234.12000000","0.02000000"],["78233.97000000","0.00000000"],["78233.40000000","0.00008000"],["78227.01000000","0.00000000"],["78223.86000000","0.00000000"],["78220.71000000","0.00408000"],["78215.09000000","0.00000000"],["78214.36000000","0.00000000"],["77141.26000000","0.00032000"],["70484.40000000","0.00080000"],["70484.00000000","0.00027000"]],"a":[["78316.00000000","0.60301000"],["78316.01000000","0.00063000"],["78317.99000000","0.27425000"],["78320.00000000","0.03021000"],["78320.30000000","0.46050000"],["78321.16000000","0.46064000"],["78321.93000000","0.00014000"],["78321.94000000","0.00800000"],["78321.95000000","0.00014000"],["78321.99000000","2.29861000"],["78323.84000000","0.00030000"],["78331.67000000","0.00030000"],["78332.93000000","0.00000000"],["78339.50000000","0.00030000"],["78343.00000000","0.70007000"],["78346.86000000","0.00400000"],["78347.33000000","0.00030000"],["78365.69000000","0.00000000"],["78382.07000000","0.02800000"],["78522.35000000","0.00000000"],["82921.18000000","0.00010000"]]}}
{"rx":1788854554637721398, "m":{"e":"depthUpdate","E":1788854554614,"s":"BTCUSDT","U":99829872157,"u":99829872199,"b":[["78315.99000000","7.62757000"],["78295.33000000","0.02000000"],["78283.46000000","0.00000000"],["78283.15000000","0.02000000"],["78283.06000000","0.00000000"],["78234.21000000","0.00000000"],["78215.10000000","0.08506000"],["78214.60000000","0.00000000"],["77141.26000000","0.00032000"],["62652.79000000","0.00000000"],["62641.60000000","0.00000000"]],"a":[["78316.00000000","0.59270000"],["78316.01000000","0.00070000"],["78320.00000000","0.03021000"],["78320.30000000","0.46064000"],["78321.16000000","0.46064000"],["78321.93000000","0.00000000"],["78321.94000000","0.00414000"],["78321.95000000","0.00400000"],["78380.79000000","0.03200000"]]}}
{"rx":1788854554756444173, "m":{"e":"depthUpdate","E":1788854554714,"s":"BTCUSDT","U":99829872200,"u":99829872249,"b":[["78315.99000000","7.63928000"],["78310.08000000","0.00800000"],["78310.00000000","0.00500000"],["78308.00000000","0.16703000"],["78306.00000000","1.86666000"],["78304.00000000","0.00500000"],["78303.28000000","0.00000000"],["78302.00000000","1.86674000"],["78300.00000000","0.00900000"],["78298.00000000","0.00500000"],["78222.36000000","0.19329000"],["78071.82000000","0.00000000"],["77141.26000000","0.00032000"],["70484.40000000","0.00096000"]],"a":[["78316.00000000","0.44294000"],["78316.01000000","0.00077000"],["78317.99000000","0.15647000"],["78321.16000000","0.00014000"],["78321.94000000","0.00400000"],["78321.99000000","2.29875000"],["78331.99000000","0.00000000"],["78336.87000000","0.00007000"],["78364.49000000","0.34464000"],["78416.07000000","2.68103000"]]}}
{"rx":1788854554852894335, "m":{"e":"depthUpdate","E":1788854554814,"s":"BTCUSDT","U":99829872250,"u":99829872301,"b":[["78315.99000000","7.64536000"],["78315.95000000","0.05000000"],["78315.15000000","0.00014000"],["78310.60000000","0.00255000"],["78310.28000000","0.00007000"],["78310.00000000","0.01000000"],["78308.00000000","0.17203000"],["78306.00000000","1.87166000"],["78304.78000000","0.06168000"],["78304.00000000","0.01000000"],["78302.00000000","1.87174000"],["78301.12000000","0.00007000"],["78300.00000000","0.01400000"],["78298.00000000","0.01000000"],["78283.15000000","0.00000000"],["78059.77000000","0.00000000"],["78050.62000000","0.00000000"],["77141.26000000","0.00040000"],["70484.00000000","0.00027000"],["62646.40000000","0.00093000"]],"a":[["78316.00000000","0.61018000"],["78316.01000000","0.00084000"],["78316.50000000","0.06580000"],["78318.79000000","0.00000000"],["78320.30000000","0.46064000"],["78321.16000000","0.00000000"],["78321.95000000","0.01200000"],["78322.00000000","0.03214000"],["78325.47000000","0.00255000"],["78327.14000000","0.00000000"],["78327.75000000","0.00007000"],["78328.41000000","0.00000000"],["78359.61000000","0.00000000"],["78415.14000000","0.96756000"],["78522.46000000","0.00000000"],["78522.91000000","0.00000000"]]}}
{"rx":1788854554950164256, "m":{"e":"depthUpdate","E":1788854554914,"s":"BTCUSDT","U":99829872302,"u":99829872333,"b":[["78315.99000000","7.64550000"],["78315.95000000","0.05014000"],["78315.38000000","0.35387000"],["78315.15000000","0.00000000"],["78291.18000000","0.00408000"],["78273.74000000","0.55709000"],["77141.26000000","0.00040000"],["70484.40000000","0.00112000"]],"a":[["78316.00000000","0.61018000"],["78316.50000000","0.06594000"],["78320.30000000","0.46064000"],["78321.95000000","0.01214000"],["78321.99000000","2.29861000"],["78322.00000000","0.03200000"],["78365.04000000","0.36903000"]]}}
{"rx":1788854555044209956, "m":{"e":"depthUpdate","E":1788854555014,"s":"BTCUSDT","U":99829872334,"u":99829872373,"b":[["78315.99000000","7.64550000"],["78315.90000000","0.05000000"],["78315.38000000","0.36081000"],["78305.57000000","0.00000000"],["77141.26000000","0.00040000"],["70484.00000000","0.00037000"],["62652.80000000","0.00248000"],["62646.40000000","0.00062000"]],"a":[["78316.00000000","0.44307000"],["78316.01000000","0.00097000"],["78316.02000000","0.00013000"],["78316.49000000","0.03785000"],["78317.99000000","0.00021000"],["78320.30000000","0.00014000"],["78321.93000000","0.46050000"],["78321.94000000","0.00000000"],["78321.95000000","0.00014000"],["78332.93000000","0.01600000"],["78522.45000000","0.00000000"],["79490.74000000","0.00030000"]]}}
{"rx":1788854555139717879, "m":{"e":"depthUpdate","E":1788854555114,"s":"BTCUSDT","U":99829872374,"u":99829872467,"b":[["78315.99000000","7.64550000"],["78315.95000000","0.05014000"],["78315.90000000","0.05014000"],["78314.72000000","0.00000000"],["78314.47000000","0.00007000"],["78314.36000000","0.06067000"],["78312.66000000","0.00000000"],["78312.53000000","0.05408000"],["77800.00000000","13.19297000"],["77601.24000000","0.00000000"],["77141.26000000","0.00032000"],["77141.25000000","0.00030000"],["70484.40000000","0.00128000"],["70484.00000000","0.00027000"],["62642.00000000","0.00200000"]],"a":[["78316.00000000","0.03167000"],["78316.01000000","0.00083000"],["78316.49000000","0.00014000"],["78316.50000000","0.06594000"],["78317.99000000","0.00007000"],["78319.99000000","0.13567000"],["78320.00000000","0.03021000"],["78320.30000000","0.00000000"],["78321.16000000","0.00000000"],["78321.92000000","0.00400000"],["78321.93000000","0.00014000"],["78321.95000000","0.00000000"],["78321.96000000","1.78866000"],["78321.99000000","2.29875000"],["78325.86000000","0.00000000"],["78326.81000000","0.00400000"],["78327.84000000","0.00000000"],["78332.92000000","0.00400000"],["78332.93000000","0.00000000"],["78403.09000000","0.00000000"],["78413.10000000","0.00025000"]]}}
{"rx":1788854555241089979, "m":{"e":"depthUpdate","E":1788854555214,"s":"BTCUSDT","U":99829872468,"u":99829872563,"b":[["78315.99000000","7.64536000"],["78315.38000000","0.36095000"],["78312.53000000","0.04075000"],["78312.12000000","0.01330000"],["78300.33000000","0.00008000"],["78283.32000000","0.00000000"],["77141.26000000","0.00032000"],["70484.40000000","0.00144000"],["70484.39000000","0.00000000"],["70484.38000000","0.00009000"],["70484.00000000","0.00027000"],["62646.40000000","0.00031000"],["62642.00000000","0.00000000"]],"a":[["78316.00000000","0.16898000"],["78316.01000000","0.00090000"],["78316.03000000","0.00007000"],["78316.49000000","0.00000000"],["78318.00000000","0.03014000"],["78319.99000000","0.00014000"],["78320.00000000","0.03021000"],["78320.29000000","0.27496000"],["78320.30000000","0.46050000"],["78321.16000000","0.00000000"],["78321.92000000","0.00000000"],["78321.93000000","0.00000000"],["78321.95000000","0.00000000"],["78322.00000000","0.03214000"],["78325.47000000","0.00000000"],["78325.95000000","0.01312000"],["78326.23000000","0.00255000"],["78326.64000000","0.00400000"],["78326.81000000","0.00000000"],["78327.30000000","0.00000000"],["78327.92000000","0.01329000"],["78328.25000000","0.00400000"],["78332.92000000","0.00000000"],["78332.93000000","0.01600000"],["78359.61000000","0.00007000"],["78362.71000000","0.01563000"],["78411.85000000","0.00000000"]]}}
{"rx":1788854555338482430, "m":{"e":"depthUpdate","E":1788854555314,"s":"BTCUSDT","U":99829872564,"u":99829872638,"b":[["78315.99000000","7.64536000"],["78315.38000000","0.35401000"],["78312.00000000","0.00014000"],["78310.00000000","0.02000000"],["78308.00000000","0.18203000"],["78306.09000000","0.17548000"],["78306.00000000","1.88166000"],["78304.00000000","0.02000000"],["78302.00000000","1.88174000"],["77141.26000000","0.00032000"],["70484.00000000","0.00027000"],["62646.00000000","0.00000000"]],"a":[["78316.00000000","0.06392000"],["78316.01000000","0.00090000"],["78318.00000000","0.03014000"],["78319.43000000","0.27440000"],["78319.44000000","0.42818000"],["78319.99000000","0.00000000"],["78320.00000000","0.03021000"],["78320.29000000","0.00014000"],["78320.30000000","0.00014000"],["78321.95000000","0.00000000"],["78322.00000000","0.03200000"],["78332.92000000","0.00800000"],["78332.93000000","0.00000000"]]}}
{"rx":1788854555438081773, "m":{"e":"depthUpdate","E":1788854555414,"s":"BTCUSDT","U":99829872639,"u":99829872700,"b":[["78315.99000000","7.64510000"],["78300.00000000","0.02400000"],["78298.00000000","0.02000000"],["77141.26000000","0.00032000"],["70484.40000000","0.00160000"],["70484.00000000","0.00027000"],["62646.40000000","0.00000000"]],"a":[["78316.00000000","0.19181000"],["78316.01000000","0.00083000"],["78318.00000000","0.03014000"],["78319.43000000","0.00014000"],["78319.44000000","0.00014000"],["78319.99000000","0.14652000"],["78320.00000000","0.03021000"],["78320.29000000","0.00000000"],["78320.30000000","0.00000000"],["78321.16000000","0.46050000"],["78321.95000000","0.00000000"],["78332.93000000","0.00800000"],["78523.27000000","0.00000000"]]}}
{"rx":1788854555537616625, "m":{"e":"depthUpdate","E":1788854555514,"s":"BTCUSDT","U":99829872701,"u":99829872777,"b":[["78315.99000000","7.65148000"],["78315.72000000","0.00014000"],["78315.71000000","0.76631000"],["78315.39000000","0.00000000"],["78315.38000000","0.36033000"],["78315.19000000","0.01333000"],["78314.70000000","0.03057000"],["78312.54000000","0.00000000"],["78310.60000000","0.00000000"],["78301.15000000","0.00000000"],["78298.88000000","0.00000000"],["78298.22000000","0.02026000"],["78286.01000000","1.04420000"],["78286.00000000","0.73048000"],["78282.13000000","0.00000000"],["78223.85000000","0.02000000"],["77141.26000000","0.00032000"],["70484.00000000","0.00027000"]],"a":[["78316.00000000","0.03145000"],["78316.01000000","0.00076000"],["78316.50000000","0.00014000"],["78318.00000000","0.03014000"],["78318.78000000","0.00206000"],["78319.43000000","0.00000000"],["78319.44000000","0.00000000"],["78319.99000000","0.00014000"],["78320.00000000","0.03021000"],["78321.16000000","0.00014000"],["78321.96000000","0.96706000"],["78321.99000000","0.00014000"],["78325.95000000","0.00000000"],["78326.23000000","0.00000000"],["78326.64000000","0.00000000"],["78328.07000000","0.00400000"],["78328.25000000","0.00000000"],["78329.26000000","0.00400000"],["78332.92000000","0.00000000"],["78332.93000000","0.01600000"],["78359.61000000","0.00007000"],["78415.14000000","0.19186000"],["78416.07000000","0.00000000"],["78426.83000000","0.01512000"]]}}
{"rx":1788854555638288190, "m":{"e":"depthUpdate","E":1788854555614,"s":"BTCUSDT","U":99829872778,"u":99829873521,"b":[["78319.99000000","6.33747000"],["78319.98000000","0.00044000"],["78319.97000000","0.00013000"],["78319.71000000","0.20154000"],["78319.70000000","0.16533000"],["78318.82000000","0.00000000"],["78318.77000000","0.00000000"],["78318.48000000","0.00400000"],["78318.36000000","0.06067000"],["78318.29000000","0.00000000"],["78318.01000000","0.00000000"],["78318.00000000","0.39430000"],["78317.99000000","0.40777000"],["78317.98000000","0.00000000"],["78317.97000000","0.00000000"],["78317.72000000","0.00026000"],["78317.59000000","0.02165000"],["78317.40000000","0.05000000"],["78317.17000000","0.01304000"],["78316.69000000","0.00000000"],["78316.39000000","0.00000000"],["78316.36000000","0.00000000"],["78316.14000000","0.00008000"],["78316.01000000","0.20250000"],["78316.00000000","2.83721000"],["78315.99000000","0.68312000"],["78315.98000000","0.00000000"],["78315.97000000","0.00000000"],["78315.95000000","0.00014000"],["78315.90000000","0.00414000"],["78315.71000000","0.00014000"],["78315.38000000","0.36033000"],["78315.24000000","0.00000000"],["78315.19000000","0.01347000"],["78314.73000000","0.01781000"],["78314.71000000","0.07000000"],["78314.46000000","0.00000000"],["78314.36000000","0.00000000"],["78314.14000000","0.23907000"],["78314.12000000","0.00013000"],["78312.95000000","0.00000000"],["78312.67000000","0.00000000"],["78312.53000000","0.00000000"],["78312.16000000","0.00008000"],["78312.12000000","0.01330000"],["78311.12000000","0.00150000"],["78310.16000000","0.00000000"],["78310.12000000","0.00000000"],["78310.08000000","0.00000000"],["78308.16000000","0.00000000"],["78306.90000000","0.00008000"],["78306.74000000","0.00000000"],["78306.29000000","0.38322000"],["78304.78000000","0.00000000"],["78304.30000000","0.00007000"],["78303.99000000","0.41262000"],["78303.42000000","0.00000000"],["78303.27000000","0.00000000"],["78302.78000000","0.09427000"],["78302.33000000","0.00008000"],["78301.70000000","0.00000000"],["78300.82000000","0.10259000"],["78298.88000000","0.00024000"],["78298.41000000","0.00008000"],["78298.22000000","0.00000000"],["78298.10000000","0.00000000"],["78297.30000000","0.00000000"],["78295.34000000","0.00000000"],["78295.03000000","0.00000000"],["78294.49000000","0.00008000"],["78294.18000000","0.00000000"],["78291.50000000","0.38329000"],["78290.58000000","0.00008000"],["78290.27000000","0.00000000"],["78289.01000000","0.00000000"],["78286.66000000","0.00008000"],["78286.35000000","0.00000000"],["78285.50000000","0.34499000"],["78283.92000000","0.34500000"],["78282.75000000","0.00008000"],["78282.43000000","0.00000000"],["78279.81000000","0.00000000"],["78278.83000000","0.00008000"],["78278.80000000","0.00000000"],["78278.52000000","0.00000000"],["78278.40000000","0.00000000"],["78278.00000000","0.04000000"],["78276.80000000","0.00000000"],["78276.00000000","0.03025000"],["78274.60000000","0.00000000"],["78272.29000000","0.00000000"],["78257.90000000","0.00000000"],["78254.04000000","2.29838000"],["78252.30000000","0.00000000"],["78246.70000000","0.40433000"],["78246.14000000","0.00000000"],["78222.36000000","0.21329000"],["78221.77000000","0.00000000"],["78190.98000000","0.00000000"],["78190.97000000","0.00000000"],["78190.01000000","0.01942000"],["78183.14000000","0.02437000"],["78183.13000000","0.00000000"],["78178.55000000","1.53085000"],["78170.68000000","0.09221000"],["78167.91000000","2.59826000"],["78166.34000000","0.00139000"],["78147.69000000","1.20000000"],["78138.34000000","0.00000000"],["78136.15000000","0.00000000"],["78129.06000000","0.00000000"],["77992.60000000","0.00000000"],["77924.70000000","0.00007000"],["77143.23000000","0.00000000"],["77141.26000000","0.00000000"],["77141.25000000","0.00000000"],["70486.20000000","0.94042000"],["70484.40000000","0.00000000"],["70484.38000000","0.00000000"],["62656.00000000","0.00200000"],["62652.80000000","0.00217000"],["62652.79000000","0.00000000"]],"a":[["78316.00000000","0.00000000"],["78316.01000000","0.00000000"],["78316.02000000","0.00000000"],["78316.03000000","0.00000000"],["78316.50000000","0.00000000"],["78316.70000000","0.00000000"],["78317.99000000","0.00000000"],["78318.00000000","0.00000000"],["78318.01000000","0.00000000"],["78318.02000000","0.00000000"],["78318.78000000","0.00000000"],["78318.83000000","0.00000000"],["78319.71000000","0.00000000"],["78319.99000000","0.00000000"],["78320.00000000","0.02720000"],["78320.01000000","0.00056000"],["78320.45000000","0.00000000"],["78320.84000000","0.00000000"],["78321.16000000","0.00000000"],["78321.91000000","0.00000000"],["78321.96000000","0.00014000"],["78321.97000000","0.00014000"],["78321.99000000","0.00007000"],["78322.00000000","0.03214000"],["78322.53000000","0.00786000"],["78322.99000000","0.00000000"],["78323.24000000","0.00014000"],["78323.48000000","0.00000000"],["78323.70000000","0.00007000"],["78323.76000000","0.00000000"],["78323.78000000","0.00941000"],["78323.83000000","0.00000000"],["78323.97000000","0.00000000"],["78324.00000000","0.03014000"],["78324.03000000","0.00000000"],["78324.30000000","0.00014000"],["78324.37000000","0.00000000"],["78325.46000000","0.00000000"],["78325.71000000","0.00000000"],["78325.72000000","0.75723000"],["78325.83000000","0.00000000"],["78325.94000000","0.00000000"],["78326.07000000","0.00206000"],["78326.08000000","0.06580000"],["78326.66000000","0.00000000"],["78326.76000000","0.00000000"],["78326.86000000","0.00000000"],["78327.00000000","0.00000000"],["78327.53000000","0.06702000"],["78327.62000000","0.00000000"],["78327.69000000","0.00007000"],["78327.75000000","0.00000000"],["78327.76000000","0.00000000"],["78327.83000000","0.00008000"],["78327.89000000","0.00000000"],["78327.92000000","0.00000000"],["78328.07000000","0.00000000"],["78328.22000000","0.00000000"],["78328.26000000","0.02000000"],["78328.32000000","0.00000000"],["78328.59000000","0.00000000"],["78329.24000000","0.00000000"],["78329.26000000","0.00000000"],["78329.41000000","0.00000000"],["78329.56000000","0.04000000"],["78329.63000000","0.12766000"],["78329.66000000","0.15155000"],["78329.96000000","0.01000000"],["78330.23000000","0.00007000"],["78330.83000000","0.00000000"],["78331.35000000","0.00000000"],["78331.56000000","0.00000000"],["78331.68000000","0.00014000"],["78331.75000000","0.00007000"],["78331.83000000","0.00000000"],["78332.17000000","0.00000000"],["78332.83000000","0.00638000"],["78332.92000000","0.00000000"],["78332.93000000","0.00000000"],["78332.94000000","0.00800000"],["78333.36000000","0.00007000"],["78333.47000000","0.08048000"],["78333.58000000","0.00000000"],["78333.66000000","0.00016000"],["78334.14000000","0.00400000"],["78334.41000000","0.00255000"],["78334.70000000","0.00638000"],["78335.15000000","0.00000000"],["78335.27000000","0.00000000"],["78335.67000000","0.00014000"],["78335.93000000","0.00190000"],["78336.01000000","0.00000000"],["78336.06000000","0.00000000"],["78337.46000000","0.12765000"],["78337.49000000","0.00000000"],["78337.58000000","0.00008000"],["78337.65000000","0.00400000"],["78337.76000000","0.00400000"],["78339.10000000","0.00800000"],["78339.14000000","0.00000000"],["78339.38000000","0.00000000"],["78339.39000000","0.00000000"],["78339.66000000","2.00678000"],["78340.80000000","0.00000000"],["78341.41000000","0.00000000"],["78341.50000000","0.00008000"],["78343.00000000","0.00007000"],["78343.37000000","0.00000000"],["78343.90000000","0.00000000"],["78344.44000000","0.31928000"],["78344.94000000","0.00000000"],["78345.33000000","0.00000000"],["78345.41000000","0.00008000"],["78345.99000000","0.00049000"],["78348.71000000","0.00000000"],["78349.24000000","0.00000000"],["78349.33000000","0.00008000"],["78350.01000000","0.00000000"],["78350.55000000","0.31927000"],["78351.74000000","0.00000000"],["78352.52000000","0.00000000"],["78353.16000000","0.00000000"],["78353.24000000","0.00008000"],["78354.54000000","0.31927000"],["78355.62000000","0.00014000"],["78355.80000000","0.00000000"],["78356.00000000","0.03000000"],["78356.48000000","0.47798000"],["78356.87000000","0.00000000"],["78357.16000000","0.00008000"],["78358.00000000","0.03400000"],["78358.17000000","0.00000000"],["78360.00000000","0.04000000"],["78360.86000000","0.00000000"],["78363.17000000","0.00000000"],["78365.70000000","0.00008000"],["78366.50000000","0.00624000"],["78366.77000000","0.00000000"],["78367.59000000","0.00007000"],["78367.87000000","0.00000000"],["78368.33000000","1.25195000"],["78369.21000000","0.34462000"],["78370.70000000","0.00223000"],["78370.90000000","0.00318000"],["78372.66000000","0.00400000"],["78373.35000000","0.00319000"],["78381.48000000","0.00000000"],["78387.56000000","0.00000000"],["78387.98000000","0.00318000"],["78389.89000000","1.26329000"],["78396.32000000","0.00008000"],["78401.17000000","0.00000000"],["78412.09000000","0.00000000"],["78412.69000000","2.29838000"],["78426.83000000","0.00000000"],["78439.99000000","0.00000000"],["78445.49000000","0.00000000"],["78449.37000000","0.00127000"],["78451.99000000","0.00127000"],["78463.93000000","0.00000000"],["78465.00000000","0.00000000"],["78465.87000000","0.00000000"],["78474.64000000","0.00008000"],["78476.19000000","1.53085000"],["78490.60000000","0.77521000"],["78497.13000000","0.03057000"],["78522.24000000","0.00000000"],["78533.04000000","0.00000000"],["78544.18000000","0.00000000"],["78552.95000000","0.00008000"],["78572.49000000","0.00000000"],["78582.22000000","0.00032000"],["78622.49000000","0.00000000"],["78631.27000000","0.00008000"],["78700.80000000","0.00000000"],["78709.59000000","0.00008000"],["78722.70000000","0.00000000"],["78779.11000000","0.00000000"],["78787.91000000","0.00008000"],["78857.41000000","0.00000000"],["78866.23000000","0.00008000"],["78935.72000000","0.00000000"],["78944.54000000","0.00008000"],["79490.74000000","0.00000000"]]}}
{"rx":1788854555738456991, "m":{"e":"depthUpdate","E":1788854555714,"s":"BTCUSDT","U":99829873522,"u":99829873752,"b":[["78319.99000000","7.54153000"],["78319.81000000","0.03057000"],["78319.71000000","0.20168000"],["78319.70000000","0.16547000"],["78318.39000000","0.00007000"],["78318.36000000","0.06081000"],["78318.01000000","0.00800000"],["78318.00000000","0.39444000"],["78317.99000000","0.23876000"],["78317.59000000","0.02179000"],["78317.55000000","0.05000000"],["78317.45000000","0.05000000"],["78317.40000000","0.00000000"],["78316.00000000","2.78721000"],["78315.99000000","0.67230000"],["78315.95000000","0.00000000"],["78315.90000000","0.00400000"],["78315.71000000","0.00000000"],["78315.70000000","0.11191000"],["78315.38000000","0.36019000"],["78315.19000000","0.01333000"],["78314.73000000","0.00000000"],["78314.71000000","0.00000000"],["78314.47000000","0.00000000"],["78314.14000000","0.15907000"],["78313.48000000","0.00000000"],["78313.33000000","0.73216000"],["78312.23000000","0.00000000"],["78310.20000000","2.29838000"],["78308.17000000","0.20250000"],["78298.82000000","0.00191000"],["78293.01000000","0.20000000"],["78290.49000000","0.00000000"],["78286.80000000","0.00000000"],["78285.15000000","0.36598000"],["78280.00000000","0.74113000"],["78278.00000000","0.03000000"],["78275.64000000","0.00335000"],["78274.71000000","0.34504000"],["78270.00000000","1.13495000"],["78268.99000000","0.00000000"],["78254.05000000","0.81879000"],["78254.04000000","0.00000000"],["78254.03000000","0.00000000"],["78228.91000000","0.61583000"],["78228.90000000","0.00000000"],["78203.88000000","0.09046000"],["78202.90000000","0.20443000"],["78087.25000000","0.00000000"],["78002.26000000","0.00036000"],["77145.20000000","0.00008000"],["62656.00000000","0.00000000"]],"a":[["78320.00000000","0.02697000"],["78320.01000000","0.00042000"],["78321.26000000","0.00014000"],["78321.27000000","0.00000000"],["78321.96000000","0.00000000"],["78321.97000000","0.00000000"],["78322.53000000","0.00014000"],["78323.24000000","0.00000000"],["78323.78000000","0.00014000"],["78324.00000000","0.03014000"],["78324.30000000","0.00000000"],["78325.03000000","0.00014000"],["78325.72000000","0.04819000"],["78326.00000000","0.03014000"],["78326.07000000","0.00000000"],["78326.08000000","0.00014000"],["78327.63000000","0.00000000"],["78328.03000000","0.00206000"],["78328.81000000","0.00000000"],["78329.25000000","0.00000000"],["78329.46000000","0.46046000"],["78329.56000000","0.00000000"],["78329.62000000","0.46046000"],["78329.66000000","1.53873000"],["78329.74000000","0.00000000"],["78329.96000000","0.00000000"],["78330.42000000","0.00000000"],["78330.68000000","0.00000000"],["78330.90000000","0.00000000"],["78330.95000000","0.00000000"],["78331.68000000","0.00014000"],["78332.11000000","0.00000000"],["78332.83000000","0.00000000"],["78332.84000000","0.00000000"],["78332.90000000","0.00000000"],["78332.93000000","0.00000000"],["78332.94000000","4.88457000"],["78332.95000000","0.09601000"],["78332.96000000","0.00000000"],["78332.97000000","0.00142000"],["78333.04000000","0.00000000"],["78333.41000000","0.00000000"],["78333.42000000","0.00048000"],["78333.47000000","0.00048000"],["78333.64000000","0.00000000"],["78333.67000000","0.00000000"],["78333.79000000","0.00000000"],["78334.14000000","0.00000000"],["78334.38000000","0.00400000"],["78334.41000000","0.00000000"],["78335.75000000","0.00000000"],["78336.17000000","0.13000000"],["78336.29000000","0.00638000"],["78337.65000000","0.00000000"],["78337.96000000","0.00000000"],["78338.80000000","0.00000000"],["78339.10000000","0.39581000"],["78340.01000000","0.20000000"],["78340.94000000","0.00000000"],["78345.75000000","0.00000000"],["78346.93000000","0.00007000"],["78347.35000000","0.37581000"],["78349.04000000","0.00000000"],["78353.65000000","0.00000000"],["78356.48000000","0.71957000"],["78357.37000000","0.37581000"],["78359.05000000","0.63827000"],["78367.50000000","0.00400000"],["78370.90000000","0.00318000"],["78372.92000000","0.00427000"],["78373.36000000","0.00000000"],["78411.84000000","0.71675000"],["78419.99000000","0.70172000"],["78422.09000000","2.29838000"],["78435.99000000","0.01833000"],["78437.87000000","0.00000000"],["78449.37000000","0.00127000"],["78461.97000000","0.38621000"],["78489.85000000","0.30606000"],["78508.91000000","0.03057000"],["78722.70000000","0.00000000"]]}}
{"rx":1788854555837738317, "m":{"e":"depthUpdate","E":1788854555814,"s":"BTCUSDT","U":99829873753,"u":99829873914,"b":[["78319.99000000","7.50930000"],["78319.91000000","0.00400000"],["78319.81000000","0.00014000"],["78319.57000000","0.00000000"],["78319.16000000","0.01285000"],["78318.73000000","0.01781000"],["78318.55000000","0.05000000"],["78318.50000000","0.05000000"],["78318.36000000","0.06081000"],["78318.01000000","0.00000000"],["78317.72000000","0.00000000"],["78317.59000000","0.02165000"],["78317.55000000","0.00000000"],["78317.48000000","0.02137000"],["78317.45000000","0.00000000"],["78316.23000000","0.02137000"],["78316.02000000","0.00800000"],["78316.01000000","0.00000000"],["78315.99000000","0.66830000"],["78313.34000000","0.00007000"],["78310.00000000","0.03000000"],["78309.02000000","1.01883000"],["78307.73000000","0.02000000"],["78306.09000000","0.00000000"],["78305.99000000","0.00000000"],["78301.60000000","0.00007000"],["78298.07000000","0.00007000"],["78295.43000000","0.04582000"],["78293.08000000","0.00000000"],["78284.43000000","0.00000000"],["78268.50000000","0.02000000"],["78267.72000000","0.00000000"],["78235.19000000","3.83572000"],["78203.88000000","0.03373000"],["78202.90000000","0.00000000"],["78132.65000000","0.00000000"],["78099.77000000","0.00802000"],["78096.72000000","0.00000000"],["77145.20000000","0.00016000"],["70488.00000000","0.54170000"],["62652.80000000","0.00186000"]],"a":[["78320.00000000","0.28588000"],["78320.01000000","0.00056000"],["78322.00000000","0.03214000"],["78322.53000000","0.00000000"],["78323.78000000","0.00000000"],["78323.84000000","0.00000000"],["78323.96000000","0.00026000"],["78324.00000000","0.03014000"],["78324.01000000","0.00000000"],["78325.03000000","0.00000000"],["78325.11000000","0.00000000"],["78325.27000000","0.00463000"],["78325.72000000","0.04819000"],["78325.99000000","0.46046000"],["78326.00000000","0.03014000"],["78326.08000000","0.00000000"],["78326.09000000","0.06580000"],["78326.53000000","0.00772000"],["78326.85000000","0.00000000"],["78326.88000000","0.46046000"],["78327.48000000","0.00151000"],["78327.52000000","0.46046000"],["78327.53000000","0.06716000"],["78327.78000000","0.00927000"],["78327.84000000","0.00022000"],["78328.00000000","0.03014000"],["78328.01000000","0.01336000"],["78328.03000000","0.00000000"],["78328.26000000","0.02014000"],["78328.60000000","0.46053000"],["78329.03000000","0.00927000"],["78329.44000000","0.46046000"],["78329.45000000","0.00800000"],["78329.46000000","0.00000000"],["78329.62000000","0.46046000"],["78331.67000000","0.00000000"],["78331.73000000","0.00400000"],["78335.67000000","0.00036000"],["78337.73000000","0.00000000"],["78337.76000000","0.00000000"],["78339.10000000","0.38381000"],["78339.50000000","0.00000000"],["78343.50000000","0.00022000"],["78347.33000000","0.00000000"],["78351.33000000","0.00022000"],["78354.41000000","0.00063000"],["78367.59000000","0.00000000"],["78540.92000000","0.00007000"],["78544.83000000","0.00007000"]]}}
{"rx":1788854555938330864, "m":{"e":"depthUpdate","E":1788854555914,"s":"BTCUSDT","U":99829873915,"u":99829874039,"b":[["78319.99000000","7.50930000"],["78319.81000000","0.00000000"],["78319.70000000","0.16547000"],["78319.16000000","0.01299000"],["78318.73000000","0.01795000"],["78318.55000000","0.00014000"],["78318.50000000","0.00000000"],["78318.36000000","0.06067000"],["78317.99000000","0.23862000"],["78316.01000000","1.10256000"],["78316.00000000","2.31247000"],["78315.38000000","0.35387000"],["78308.00000000","0.19203000"],["78306.00000000","1.89166000"],["78304.00000000","0.03000000"],["78302.00000000","1.89174000"],["78300.00000000","0.03400000"],["78298.00000000","0.03000000"],["78292.62000000","0.88515000"],["78270.32000000","0.00000000"],["78254.05000000","1.37500000"],["78250.94000000","2.21404000"],["78238.98000000","2.14335000"],["77145.20000000","0.00024000"],["70488.00000000","0.54186000"]],"a":[["78320.00000000","0.46995000"],["78320.01000000","0.00063000"],["78323.19000000","0.00000000"],["78325.70000000","0.21359000"],["78325.71000000","0.46046000"],["78325.72000000","0.00014000"],["78325.99000000","0.00014000"],["78326.00000000","0.03014000"],["78326.09000000","0.06594000"],["78326.53000000","0.00786000"],["78326.87000000","0.01600000"],["78326.88000000","0.00014000"],["78327.52000000","0.00000000"],["78327.53000000","0.06702000"],["78328.00000000","0.03000000"],["78328.01000000","0.01322000"],["78328.26000000","0.02000000"],["78328.60000000","0.00007000"],["78329.44000000","0.00000000"],["78329.45000000","0.00000000"],["78329.46000000","0.46046000"],["78329.62000000","0.00000000"],["78338.37000000","0.00000000"],["78352.61000000","0.49285000"],["78376.39000000","0.99265000"],["78376.40000000","1.01105000"],["78376.95000000","0.88419000"],["78376.99000000","0.00000000"],["78401.17000000","0.00000000"],["78453.73000000","0.00000000"],["78514.65000000","0.01528000"],["78538.93000000","0.00007000"]]}}
{"rx":1788854556038823774, "m":{"e":"depthUpdate","E":1788854556014,"s":"BTCUSDT","U":99829874040,"u":99829874101,"b":[["78318.73000000","0.01795000"],["78318.55000000","0.00000000"],["78318.36000000","0.06081000"],["78310.21000000","1.86166000"],["78307.62000000","0.02000000"],["78303.72000000","0.02000000"],["78208.40000000","0.00000000"],["77145.20000000","0.00032000"],["70488.00000000","0.54195000"],["62656.00000000","0.00124000"],["62652.80000000","0.00155000"]],"a":[["78320.00000000","0.43209000"],["78320.01000000","0.00070000"],["78321.99000000","0.01878000"],["78323.54000000","0.00007000"],["78324.00000000","0.03014000"],["78325.70000000","0.21373000"],["78325.71000000","0.46060000"],["78325.72000000","0.00000000"],["78325.99000000","0.00000000"],["78326.53000000","0.00786000"],["78326.87000000","0.00014000"],["78326.88000000","0.00000000"],["78328.11000000","0.00000000"],["78329.45000000","0.01600000"],["78340.91000000","0.03800000"],["78389.52000000","0.03800000"],["78544.83000000","0.00000000"]]}}
{"rx":1788854556137387072, "m":{"e":"depthUpdate","E":1788854556114,"s":"BTCUSDT","U":99829874102,"u":99829874149,"b":[["78319.99000000","7.51011000"],["78319.95000000","0.05000000"],["78318.90000000","0.00255000"],["78318.73000000","0.02359000"],["78313.47000000","0.05708000"],["78313.33000000","1.20502000"],["78308.55000000","0.02000000"],["78308.38000000","0.02000000"],["78307.99000000","0.57582000"],["78304.61000000","0.02000000"],["78300.01000000","0.00000000"],["78295.21000000","0.00000000"],["78291.18000000","0.00000000"],["78252.03000000","0.02000000"],["78220.71000000","0.00000000"],["78210.96000000","0.30871000"],["78183.58000000","0.00009000"],["78179.58000000","0.00016000"],["77615.11000000","0.00010000"],["77145.19000000","0.00030000"],["72040.91000000","0.00014000"],["70488.00000000","0.54211000"]],"a":[["78320.00000000","0.43201000"],["78321.99000000","0.01892000"],["78326.53000000","0.00772000"],["78326.87000000","0.00000000"],["78327.69000000","0.00014000"],["78340.10000000","0.04400000"],["78388.58000000","0.04400000"],["78423.26000000","0.00000000"],["78428.36000000","0.00000000"],["78433.32000000","0.00000000"],["78460.03000000","0.02000000"],["78475.79000000","0.00000000"],["79494.80000000","0.00030000"]]}}
{"rx":1788854556237676620, "m":{"e":"depthUpdate","E":1788854556214,"s":"BTCUSDT","U":99829874150,"u":99829874181,"b":[["78319.99000000","7.50997000"],["78307.75000000","0.02000000"],["78301.99000000","0.00000000"],["78300.59000000","0.43665000"],["78300.58000000","0.49933000"],["78300.02000000","0.00000000"],["78299.84000000","0.00000000"],["78299.09000000","0.00000000"],["78296.06000000","0.00000000"],["78290.00000000","0.73000000"],["78286.00000000","0.03048000"],["78262.25000000","0.00666000"],["78257.74000000","0.00000000"],["78227.49000000","0.00000000"],["77145.20000000","0.00032000"],["70487.00000000","0.00729000"],["62656.00000000","0.00124000"],["62652.80000000","0.00124000"]],"a":[["78320.00000000","0.28631000"],["78326.53000000","0.00786000"],["78340.80000000","0.02800000"],["78349.35000000","0.00000000"],["78350.29000000","0.00000000"],["78389.79000000","0.02800000"],["78427.27000000","0.00012000"],["78432.37000000","0.00019000"]]}}
{"rx":1788854556342471714, "m":{"e":"depthUpdate","E":1788854556314,"s":"BTCUSDT","U":99829874182,"u":99829874204,"b":[["78305.38000000","0.02000000"],["78255.73000000","0.00408000"],["77145.20000000","0.00032000"],["70488.00000000","0.54227000"],["70487.00000000","0.00709000"]],"a":[["78320.00000000","0.44359000"],["78322.30000000","0.00007000"],["78327.84000000","0.00020000"],["78335.67000000","0.00034000"],["78343.14000000","0.03000000"],["78343.50000000","0.00020000"],["78351.33000000","0.00020000"],["78391.35000000","0.03000000"],["78437.33000000","0.00031000"]]}}
{"rx":1788854556439716457, "m":{"e":"depthUpdate","E":1788854556414,"s":"BTCUSDT","U":99829874205,"u":99829874223,"b":[["78319.16000000","0.00014000"],["78303.82000000","0.02000000"],["78303.72000000","0.04000000"],["78299.23000000","0.00000000"],["78296.87000000","0.00000000"],["78295.23000000","0.00000000"],["78264.48000000","0.02000000"],["77145.20000000","0.00032000"],["70488.00000000","0.54243000"],["62652.80000000","0.00093000"]],"a":[["78344.69000000","0.03800000"],["78344.81000000","0.03200000"],["78350.56000000","0.00000000"],["78352.12000000","0.00000000"],["78353.84000000","0.00000000"],["78355.00000000","0.70000000"],["78396.90000000","0.03800000"],["78397.01000000","0.03200000"]]}}
{"rx":1788854556537212152, "m":{"e":"depthUpdate","E":1788854556514,"s":"BTCUSDT","U":99829874224,"u":99829874260,"b":[["78319.99000000","7.51011000"],["78319.95000000","0.05014000"],["78319.70000000","0.16533000"],["78319.16000000","0.00000000"],["78318.90000000","0.00876000"],["78318.73000000","0.01795000"],["78307.63000000","0.02000000"],["78304.12000000","0.02000000"],["78264.89000000","0.02000000"],["78243.47000000","0.00000000"],["78223.85000000","0.00000000"],["77145.20000000","0.00032000"],["62656.00000000","0.00248000"]],"a":[["78320.00000000","0.44366000"],["78320.01000000","0.00077000"],["78321.99000000","0.05154000"],["78323.54000000","0.00000000"],["78323.91000000","0.11516000"],["78324.49000000","0.00206000"],["78340.90000000","0.03400000"],["78344.42000000","0.02800000"],["78389.74000000","0.03400000"],["78401.68000000","0.00000000"]]}}
{"rx":1788854556637493965, "m":{"e":"depthUpdate","E":1788854556614,"s":"BTCUSDT","U":99829874261,"u":99829874304,"b":[["78319.90000000","0.05000000"],["78317.17000000","0.00000000"],["78303.81000000","0.02000000"],["78295.63000000","0.00000000"],["78295.32000000","0.00000000"],["78292.97000000","0.00000000"],["78264.58000000","0.02000000"],["78234.12000000","0.00000000"],["77145.20000000","0.00032000"],["70488.00000000","0.54259000"],["62656.00000000","0.00248000"],["62655.99000000","0.00020000"],["62652.80000000","0.00062000"]],"a":[["78322.00000000","0.03214000"],["78323.91000000","0.11530000"],["78325.70000000","0.32507000"],["78325.71000000","0.00014000"],["78326.53000000","0.00772000"],["78327.52000000","0.46048000"],["78328.60000000","0.00007000"],["78329.46000000","0.00000000"],["78331.75000000","0.00000000"],["78344.67000000","0.03200000"],["78350.51000000","0.00000000"],["78353.75000000","0.00000000"],["78389.74000000","0.00000000"],["78400.41000000","0.03200000"]]}}
{"rx":1788854556738206497, "m":{"e":"depthUpdate","E":1788854556714,"s":"BTCUSDT","U":99829874305,"u":99829874358,"b":[["78319.95000000","0.05014000"],["78319.24000000","0.03057000"],["78304.58000000","0.02000000"],["78273.21000000","0.34504000"],["78241.98000000","0.00000000"],["78222.36000000","0.19329000"],["77145.20000000","0.00032000"],["72040.91000000","0.00000000"],["70488.00000000","0.54250000"],["70487.99000000","0.00009000"],["62655.99000000","0.00000000"]],"a":[["78320.00000000","0.44351000"],["78325.70000000","0.21367000"],["78325.71000000","0.00000000"],["78326.53000000","0.00786000"],["78329.45000000","0.00000000"],["78331.02000000","0.02092000"],["78331.75000000","0.00007000"],["78332.06000000","0.01311000"],["78332.93000000","0.01600000"],["78335.98000000","0.01303000"],["78337.33000000","0.00408000"],["78338.86000000","0.02128000"],["78339.90000000","0.01328000"],["78343.80000000","0.12764000"],["78343.82000000","0.01313000"],["78343.89000000","0.04000000"],["78346.70000000","0.02091000"],["78347.74000000","0.01283000"],["78354.54000000","0.34094000"],["78362.38000000","0.02116000"],["78373.51000000","0.34460000"],["78399.59000000","0.04000000"],["78400.41000000","0.00000000"],["78423.96000000","2.68102000"]]}}
{"rx":1788854556838649232, "m":{"e":"depthUpdate","E":1788854556814,"s":"BTCUSDT","U":99829874359,"u":99829874389,"b":[["78319.99000000","7.50311000"],["78319.90000000","0.05014000"],["78319.70000000","0.16547000"],["78319.24000000","0.03667000"],["78318.90000000","0.00255000"],["78318.00000000","0.39430000"],["78308.56000000","0.01552000"],["78304.65000000","0.01552000"],["78300.83000000","0.01552000"],["78297.11000000","0.01552000"],["78295.33000000","0.00000000"],["78289.96000000","0.00000000"],["77145.20000000","0.00040000"],["70488.00000000","0.54266000"],["62652.80000000","0.00031000"]],"a":[["78320.00000000","0.44323000"],["78327.83000000","0.21104000"],["78333.68000000","0.00000000"],["78398.89000000","0.00007000"],["78405.01000000","0.00007000"],["78423.05000000","0.92116000"],["79284.44000000","0.00000000"]]}}
{"rx":1788854556940546528, "m":{"e":"depthUpdate","E":1788854556914,"s":"BTCUSDT","U":99829874390,"u":99829874421,"b":[["78319.99000000","7.49673000"],["78319.91000000","0.00000000"],["78319.24000000","0.03667000"],["78319.02000000","0.00400000"],["78318.00000000","0.31930000"],["78316.24000000","0.00638000"],["78294.88000000","0.00408000"],["78222.24000000","0.00000000"],["78111.01000000","0.01202000"],["78099.77000000","0.00000000"],["77145.20000000","0.00040000"]],"a":[["78320.00000000","0.62127000"],["78325.69000000","0.46048000"],["78325.70000000","0.38680000"],["78326.88000000","0.00000000"],["78327.51000000","2.29826000"],["78327.52000000","0.00000000"],["78331.36000000","0.00400000"],["78333.71000000","0.00255000"],["78334.38000000","0.00000000"],["78414.26000000","0.07538000"]]}}
{"rx":1788854557040090005, "m":{"e":"depthUpdate","E":1788854557014,"s":"BTCUSDT","U":99829874422,"u":99829874455,"b":[["78318.90000000","0.00000000"],["78318.86000000","0.00000000"],["77145.20000000","0.00040000"],["70488.00000000","0.54282000"],["62652.80000000","0.00000000"]],"a":[["78320.00000000","0.62140000"],["78320.01000000","0.00097000"],["78320.02000000","0.00013000"],["78324.00000000","0.03014000"],["78325.69000000","0.46062000"],["78325.70000000","1.45911000"],["78326.53000000","0.00772000"],["78327.50000000","2.45594000"],["78332.93000000","0.00000000"]]}}
{"rx":1788854557145994001, "m":{"e":"depthUpdate","E":1788854557114,"s":"BTCUSDT","U":99829874456,"u":99829874526,"b":[["78319.96000000","0.00000000"],["78319.95000000","0.00014000"],["78319.91000000","0.00014000"],["78319.86000000","0.00014000"],["78319.85000000","0.05000000"],["78319.72000000","0.00014000"],["78319.71000000","0.20182000"],["78319.25000000","0.00014000"],["78319.24000000","0.03071000"],["78318.85000000","0.00000000"],["78318.37000000","0.00000000"],["78316.54000000","0.00255000"],["78224.41000000","0.00408000"],["78176.46000000","0.02000000"],["78156.78000000","0.00000000"],["77145.20000000","0.00032000"],["77145.19000000","0.00030000"],["70488.00000000","0.54298000"]],"a":[["78320.00000000","0.62140000"],["78320.01000000","0.00097000"],["78321.99000000","0.18486000"],["78323.90000000","0.00000000"],["78324.49000000","0.00000000"],["78325.16000000","0.00000000"],["78325.68000000","0.00000000"],["78325.69000000","0.00014000"],["78326.09000000","0.00014000"],["78327.49000000","0.01600000"],["78327.50000000","2.43994000"],["78332.20000000","0.00255000"],["78333.71000000","0.00000000"],["78413.10000000","0.00000000"],["78414.26000000","0.00000000"],["78417.11000000","0.00025000"],["79494.80000000","0.00030000"]]}}
{"rx":1788854557251125025, "m":{"e":"depthUpdate","E":1788854557214,"s":"BTCUSDT","U":99829874527,"u":99829874578,"b":[["78319.99000000","7.49703000"],["78319.95000000","0.05000000"],["78319.90000000","0.05014000"],["78319.86000000","0.00000000"],["78319.85000000","0.00000000"],["77145.20000000","0.00032000"],["66654.91000000","0.01000000"],["62656.00000000","0.00217000"]],"a":[["78320.00000000","0.62149000"],["78320.01000000","0.00083000"],["78321.99000000","0.05336000"],["78324.00000000","0.03014000"],["78325.69000000","0.46048000"],["78326.00000000","0.03014000"],["78326.09000000","0.00000000"],["78326.53000000","0.00786000"],["78327.49000000","0.01614000"],["78372.15000000","0.00400000"],["78372.66000000","0.00000000"],["78399.59000000","0.00000000"]]}}
{"rx":1788854557356139440, "m":{"e":"depthUpdate","E":1788854557314,"s":"BTCUSDT","U":99829874579,"u":99829874600,"b":[["78319.99000000","7.49110000"],["78319.95000000","0.05014000"],["78319.90000000","0.05000000"],["78319.70000000","0.17132000"],["78285.72000000","0.02000000"],["78162.47000000","0.00000000"],["77145.20000000","0.00032000"],["70488.00000000","0.54314000"],["62656.00000000","0.00217000"]],"a":[["78324.00000000","0.03014000"],["78325.69000000","0.46062000"],["78327.49000000","0.01600000"],["78407.84000000","0.00408000"]]}}
{"rx":1788854557450202001, "m":{"e":"depthUpdate","E":1788854557414,"s":"BTCUSDT","U":99829874601,"u":99829874630,"b":[["78319.99000000","7.49096000"],["78319.96000000","0.00014000"],["78319.90000000","0.05014000"],["78284.16000000","0.02000000"],["77145.20000000","0.00032000"],["70487.99000000","0.00000000"],["70487.00000000","0.00709000"],["62656.00000000","0.00186000"]],"a":[["78320.00000000","0.44311000"],["78320.01000000","0.00083000"],["78325.16000000","0.46048000"],["78325.69000000","0.00014000"],["78327.48000000","0.00551000"],["78327.49000000","0.01200000"],["78331.02000000","0.00000000"],["78331.24000000","0.02118000"],["78331.36000000","0.00000000"],["78332.05000000","0.00400000"],["78332.06000000","0.00000000"],["78332.42000000","0.01281000"]]}}
{"rx":1788854557545206089, "m":{"e":"depthUpdate","E":1788854557514,"s":"BTCUSDT","U":99829874631,"u":99829874658,"b":[["78294.88000000","0.00000000"],["78287.97000000","0.02000000"],["78255.73000000","0.00000000"],["78245.27000000","0.02000000"],["78234.12000000","0.02000000"],["78224.41000000","0.00000000"],["78123.38000000","0.00000000"],["77145.20000000","0.00032000"],["70488.00000000","0.54330000"],["62656.00000000","0.00310000"]],"a":[["78324.00000000","0.03014000"],["78325.16000000","0.46062000"],["78325.69000000","0.00000000"],["78326.53000000","0.00786000"],["78376.50000000","0.00408000"],["78389.74000000","0.03400000"]]}}
{"rx":1788854557639169574, "m":{"e":"depthUpdate","E":1788854557614,"s":"BTCUSDT","U":99829874659,"u":99829874665,"b":[["78244.96000000","0.02000000"],["78234.12000000","0.00000000"],["78233.58000000","0.00000000"],["77145.20000000","0.00032000"],["70488.00000000","0.54346000"],["62656.00000000","0.00279000"]],"a":[]}}
{"rx":1788854557757056258, "m":{"e":"depthUpdate","E":1788854557714,"s":"BTCUSDT","U":99829874666,"u":99829874694,"b":[["78319.70000000","0.16547000"],["78294.98000000","0.00408000"],["78284.92000000","0.02000000"],["78232.42000000","0.00007000"],["77145.20000000","0.00032000"],["70488.00000000","0.54355000"],["62656.00000000","0.00279000"],["62655.99000000","0.00000000"]],"a":[["78320.00000000","0.61943000"],["78325.69000000","0.01600000"],["78327.48000000","0.00151000"],["78327.49000000","0.00000000"],["78331.75000000","0.00007000"],["78412.99000000","0.00000000"],["78535.69000000","0.02000000"]]}}
{"rx":1788854557838195133, "m":{"e":"depthUpdate","E":1788854557814,"s":"BTCUSDT","U":99829874695,"u":99829874729,"b":[["77145.20000000","0.00040000"],["70488.00000000","0.54371000"],["62656.00000000","0.00248000"]],"a":[["78320.00000000","0.62068000"],["78320.01000000","0.00083000"],["78323.90000000","0.46048000"],["78325.16000000","0.46062000"],["78325.68000000","0.00000000"],["78325.69000000","0.00014000"],["78326.53000000","0.00772000"],["78327.49000000","0.01200000"],["78350.61000000","0.60826000"]]}}
{"rx":1788854557947506143, "m":{"e":"depthUpdate","E":1788854557914,"s":"BTCUSDT","U":99829874730,"u":99829874753,"b":[["78314.00000000","0.00500000"],["78312.00000000","0.00514000"],["77145.20000000","0.00040000"]],"a":[["78320.00000000","0.62075000"],["78320.01000000","0.00090000"],["78321.99000000","0.18402000"],["78322.00000000","0.03214000"],["78323.90000000","0.46062000"],["78325.16000000","0.00014000"],["78325.69000000","0.00000000"],["78327.48000000","0.00551000"],["78395.83000000","0.00007000"],["78411.12000000","0.00007000"],["78452.19000000","0.00000000"]]}}
{"rx":1788854558059174316, "m":{"e":"depthUpdate","E":1788854558014,"s":"BTCUSDT","U":99829874754,"u":99829874780,"b":[["78319.99000000","7.48961000"],["78314.00000000","0.01000000"],["78312.00000000","0.01014000"],["78111.01000000","0.00400000"],["78104.65000000","0.00896000"],["77145.20000000","0.00040000"],["70488.00000000","0.54378000"],["70487.99000000","0.00009000"],["62656.00000000","0.00341000"]],"a":[["78320.00000000","0.62187000"],["78320.01000000","0.00083000"],["78324.00000000","0.03014000"],["78325.16000000","0.00000000"],["78326.53000000","0.00786000"]]}}
{"rx":1788854558138573095, "m":{"e":"depthUpdate","E":1788854558114,"s":"BTCUSDT","U":99829874781,"u":99829874805,"b":[["78319.71000000","0.20796000"],["78316.54000000","0.00000000"],["78265.81000000","0.00662000"],["77145.20000000","0.00032000"],["77145.19000000","0.00030000"],["62656.00000000","0.00541000"]],"a":[["78320.00000000","0.63035000"],["78320.01000000","0.00076000"],["78321.99000000","0.05336000"],["78323.90000000","0.00014000"],["79494.80000000","0.00030000"],["80500.00000000","24.96850000"]]}}
{"rx":1788854558241779848, "m":{"e":"depthUpdate","E":1788854558214,"s":"BTCUSDT","U":99829874806,"u":99829874825,"b":[["78319.99000000","7.48794000"],["78318.11000000","0.00255000"],["78231.57000000","0.00000000"],["77145.20000000","0.00032000"],["70488.00000000","0.54394000"],["62656.00000000","0.00310000"]],"a":[["78320.00000000","0.46315000"],["78322.00000000","0.03214000"],["78323.90000000","0.00000000"],["78327.48000000","0.00565000"]]}}
{"rx":1788854558348905004, "m":{"e":"depthUpdate","E":1788854558314,"s":"BTCUSDT","U":99829874826,"u":99829874862,"b":[["77145.20000000","0.00032000"],["70488.00000000","0.54410000"]],"a":[["78320.00000000","0.43689000"],["78320.01000000","0.00090000"],["78321.99000000","0.00021000"],["78323.90000000","0.04349000"],["78325.16000000","0.00000000"],["78325.69000000","0.00000000"],["78327.48000000","0.01365000"],["78327.49000000","0.00000000"],["78429.94000000","0.00000000"],["78454.93000000","0.00107000"]]}}
{"rx":1788854558458893115, "m":{"e":"depthUpdate","E":1788854558414,"s":"BTCUSDT","U":99829874863,"u":99829874913,"b":[["78317.99000000","0.18862000"],["78280.00000000","0.04113000"],["77145.20000000","0.00032000"],["62656.00000000","0.00279000"]],"a":[["78320.00000000","0.60806000"],["78320.01000000","0.00083000"],["78321.99000000","0.00007000"],["78322.00000000","0.03214000"],["78323.90000000","0.04363000"],["78325.16000000","0.46048000"],["78325.69000000","0.46448000"],["78327.47000000","0.01600000"],["78327.48000000","0.00151000"],["78332.20000000","0.00000000"],["78332.21000000","0.00255000"],["78339.10000000","0.37981000"]]}}
{"rx":1788854558574815062, "m":{"e":"depthUpdate","E":1788854558514,"s":"BTCUSDT","U":99829874914,"u":99829874933,"b":[["78316.00000000","2.32247000"],["78314.00000000","0.02000000"],["78312.00000000","0.02000000"],["78224.51000000","0.00408000"],["77145.20000000","0.00032000"],["75500.00000000","26.71340000"],["70488.00000000","0.54426000"]],"a":[["78320.00000000","0.60813000"],["78320.01000000","0.00090000"],["78324.00000000","0.03014000"],["78325.16000000","0.46062000"],["78325.69000000","0.00400000"],["78326.53000000","0.00772000"]]}}
{"rx":1788854558667660939, "m":{"e":"depthUpdate","E":1788854558614,"s":"BTCUSDT","U":99829874934,"u":99829874945,"b":[["78292.33000000","0.00031000"],["77145.20000000","0.00032000"],["70488.00000000","0.54426000"],["70487.00000000","0.00709000"],["62656.00000000","0.00248000"]],"a":[["78325.16000000","0.46062000"]]}}
{"rx":1788854558739255230, "m":{"e":"depthUpdate","E":1788854558714,"s":"BTCUSDT","U":99829874946,"u":99829875125,"b":[["78319.99000000","6.38079000"],["78319.98000000","0.00093000"],["78319.96000000","0.00000000"],["78319.95000000","0.00014000"],["78319.91000000","0.00000000"],["78319.90000000","0.00014000"],["78319.71000000","0.20775000"],["78319.70000000","0.00014000"],["78319.25000000","0.00000000"],["78319.24000000","0.00014000"],["78319.02000000","0.00000000"],["78318.74000000","0.00137000"],["78318.37000000","0.00014000"],["78318.11000000","0.00000000"],["78318.07000000","0.00000000"],["78318.01000000","0.00014000"],["78318.00000000","0.31937000"],["78317.59000000","0.00000000"],["78316.57000000","0.00000000"],["78316.25000000","0.00225000"],["78316.24000000","0.00000000"],["78316.02000000","0.00000000"],["78316.00000000","0.01000000"],["78315.99000000","0.25647000"],["78315.19000000","0.00400000"],["78314.89000000","0.00000000"],["78314.70000000","0.00000000"],["78313.99000000","0.31061000"],["78313.47000000","0.00000000"],["78313.33000000","0.73066000"],["78313.04000000","0.00655000"],["78311.36000000","0.00638000"],["78311.12000000","0.00000000"],["78310.22000000","0.37581000"],["78310.20000000","0.00000000"],["78308.56000000","0.00000000"],["78306.29000000","0.00000000"],["78304.66000000","0.01557000"],["78303.35000000","0.00150000"],["78300.83000000","0.00000000"],["78295.03000000","0.01557000"],["78278.93000000","1.26508000"],["78254.05000000","1.98992000"],["78250.95000000","2.29826000"],["78190.97000000","0.20250000"],["77145.20000000","0.00032000"],["70488.00000000","0.54442000"],["70487.99000000","0.00000000"],["62655.99000000","0.00000000"]],"a":[["78320.00000000","2.41508000"],["78320.01000000","0.00097000"],["78320.05000000","0.05000000"],["78321.72000000","0.00000000"],["78321.99000000","0.07359000"],["78322.58000000","0.00000000"],["78323.32000000","0.00000000"],["78323.33000000","0.00000000"],["78323.37000000","0.00000000"],["78323.70000000","0.00014000"],["78323.89000000","0.00000000"],["78323.90000000","0.00014000"],["78325.15000000","0.01600000"],["78325.16000000","0.00014000"],["78325.68000000","0.00000000"],["78326.53000000","0.00786000"],["78326.76000000","0.02080000"],["78327.47000000","0.00000000"],["78327.49000000","0.37581000"],["78327.77000000","0.00638000"],["78327.98000000","0.01341000"],["78328.46000000","0.00400000"],["78328.69000000","0.00255000"],["78331.75000000","0.00007000"],["78332.21000000","0.00000000"],["78334.70000000","0.00000000"],["78339.10000000","0.37581000"],["78343.05000000","0.89895000"],["78343.32000000","0.00223000"],["78344.61000000","0.63839000"],["78362.51000000","0.02534000"],["78367.01000000","0.00400000"],["78367.50000000","0.00000000"],["78370.70000000","0.00000000"],["78372.15000000","0.00000000"],["78372.38000000","0.00000000"]]}}
{"rx":1788854558852549275, "m":{"e":"depthUpdate","E":1788854558814,"s":"BTCUSDT","U":99829875126,"u":99829875500,"b":[["78319.99000000","0.44041000"],["78319.98000000","0.00076000"],["78319.95000000","0.00000000"],["78319.90000000","0.00000000"],["78319.72000000","0.00000000"],["78319.71000000","0.00021000"],["78319.70000000","0.00000000"],["78319.24000000","0.00000000"],["78318.74000000","0.00014000"],["78318.48000000","0.00000000"],["78318.38000000","0.00014000"],["78318.37000000","0.03706000"],["78318.02000000","0.00000000"],["78318.01000000","0.00000000"],["78318.00000000","0.00028000"],["78317.99000000","0.04087000"],["78317.81000000","0.00000000"],["78317.51000000","0.00000000"],["78317.49000000","0.00007000"],["78317.48000000","0.02151000"],["78317.31000000","0.00000000"],["78316.25000000","0.00000000"],["78316.23000000","0.02151000"],["78316.01000000","0.36841000"],["78315.99000000","0.00013000"],["78315.90000000","0.00000000"],["78315.72000000","0.00007000"],["78315.71000000","0.00000000"],["78315.70000000","0.00772000"],["78315.39000000","0.00206000"],["78315.38000000","0.26556000"],["78315.31000000","0.07000000"],["78315.19000000","0.00000000"],["78314.90000000","0.00000000"],["78314.71000000","0.08000000"],["78313.82000000","0.00000000"],["78313.33000000","0.05934000"],["78313.04000000","0.00000000"],["78312.94000000","0.00000000"],["78312.35000000","0.00000000"],["78312.17000000","0.00131000"],["78312.12000000","0.00000000"],["78311.73000000","0.00014000"],["78311.36000000","0.00000000"],["78310.69000000","0.00233000"],["78310.23000000","0.00000000"],["78310.22000000","0.00000000"],["78310.21000000","0.00000000"],["78309.79000000","0.00000000"],["78309.57000000","0.00026000"],["78309.12000000","0.00048000"],["78309.05000000","0.31934000"],["78308.69000000","0.00400000"],["78308.45000000","0.00000000"],["78308.35000000","0.00000000"],["78308.00000000","0.03000000"],["78307.99000000","0.45353000"],["78307.81000000","0.00190000"],["78307.74000000","0.00014000"],["78306.97000000","0.00000000"],["78306.02000000","1.86166000"],["78306.01000000","0.00000000"],["78306.00000000","0.03000000"],["78305.47000000","0.00000000"],["78304.72000000","0.00400000"],["78304.66000000","0.00000000"],["78304.65000000","0.00000000"],["78304.01000000","0.00000000"],["78302.79000000","0.00638000"],["78302.31000000","0.00800000"],["78302.05000000","2.67407000"],["78302.04000000","0.57381000"],["78302.03000000","0.00000000"],["78302.01000000","0.00000000"],["78299.51000000","0.07606000"],["78298.88000000","0.00000000"],["78298.87000000","0.00000000"],["78297.11000000","0.15187000"],["78295.43000000","0.02113000"],["78295.03000000","0.00000000"],["78294.50000000","0.07606000"],["78292.62000000","0.00000000"],["78289.18000000","0.07514000"],["78286.67000000","0.07606000"],["78285.50000000","0.00000000"],["78285.15000000","0.00000000"],["78279.81000000","0.00007000"],["78278.93000000","0.00000000"],["78277.06000000","0.00400000"],["78275.82000000","0.00000000"],["78271.92000000","0.00400000"],["78268.72000000","0.36595000"],["78266.78000000","0.00400000"],["78263.97000000","0.34508000"],["78247.56000000","1.26558000"],["78242.47000000","0.00180000"],["78238.99000000","0.00000000"],["78228.42000000","0.00000000"],["78190.98000000","0.08019000"],["78190.01000000","0.00000000"],["78164.11000000","0.00072000"],["78132.46000000","0.00048000"],["77924.70000000","0.00014000"],["77145.20000000","0.00040000"],["62656.00000000","0.00217000"]],"a":[["78320.00000000","5.37374000"],["78320.01000000","0.00027000"],["78320.05000000","0.05014000"],["78320.86000000","0.00000000"],["78321.12000000","0.00000000"],["78321.72000000","0.00000000"],["78321.99000000","0.07803000"],["78322.00000000","0.03214000"],["78322.23000000","0.02124000"],["78322.34000000","0.06702000"],["78322.54000000","0.00000000"],["78322.58000000","0.00000000"],["78323.23000000","0.01335000"],["78323.27000000","0.00000000"],["78323.32000000","0.00400000"],["78323.44000000","0.00000000"],["78323.90000000","0.00000000"],["78324.00000000","0.03014000"],["78324.32000000","0.00400000"],["78325.14000000","0.00000000"],["78325.15000000","0.01614000"],["78325.16000000","0.00000000"],["78325.46000000","0.01280000"],["78325.68000000","0.00000000"],["78325.89000000","0.00400000"],["78326.31000000","0.00000000"],["78326.34000000","0.00000000"],["78326.45000000","0.00000000"],["78326.53000000","0.00772000"],["78327.26000000","0.01000000"],["78327.53000000","0.00000000"],["78327.77000000","0.00000000"],["78328.69000000","0.00000000"],["78330.76000000","0.00000000"],["78331.73000000","0.00000000"],["78332.05000000","0.00000000"],["78333.42000000","0.00000000"],["78333.47000000","0.00000000"],["78335.10000000","0.03057000"],["78335.93000000","0.00000000"],["78336.17000000","0.12000000"],["78336.29000000","0.00000000"],["78338.22000000","0.00063000"],["78343.82000000","0.00000000"],["78346.87000000","0.34472000"],["78347.74000000","0.00000000"],["78354.41000000","0.00000000"],["78359.61000000","0.00000000"],["78362.38000000","0.00000000"],["78362.51000000","0.00000000"],["78363.22000000","0.00000000"],["78367.01000000","0.00000000"],["78373.51000000","0.00000000"],["78376.39000000","0.72993000"],["78376.95000000","0.00000000"],["78414.26000000","0.07783000"],["78419.99000000","0.01795000"],["78422.09000000","0.00000000"],["78469.88000000","1.53085000"],["78476.19000000","0.00000000"],["78508.91000000","0.00000000"]]}}
{"rx":1788854558960226457, "m":{"e":"depthUpdate","E":1788854558914,"s":"BTCUSDT","U":99829875501,"u":99829875629,"b":[["78319.99000000","0.43730000"],["78319.98000000","0.00076000"],["78319.71000000","0.00007000"],["78318.73000000","0.01795000"],["78318.37000000","0.02496000"],["78318.36000000","0.06081000"],["78318.00000000","0.00000000"],["78317.99000000","0.00014000"],["78317.49000000","0.00014000"],["78316.90000000","0.12053000"],["78316.24000000","0.00007000"],["78314.03000000","0.04030000"],["78310.74000000","0.00070000"],["78310.07000000","0.00000000"],["78309.25000000","0.00800000"],["78308.16000000","0.00048000"],["78307.99000000","0.44057000"],["78307.84000000","0.00400000"],["78307.67000000","0.01329000"],["78304.72000000","0.00000000"],["78303.92000000","0.01297000"],["78302.79000000","0.00638000"],["78302.31000000","0.00000000"],["78302.06000000","0.68599000"],["78302.05000000","0.37581000"],["78302.04000000","0.00000000"],["78300.00000000","0.04707000"],["78296.08000000","0.01306000"],["78294.98000000","0.00000000"],["78292.16000000","0.01340000"],["78290.00000000","0.03000000"],["78255.83000000","0.00408000"],["78238.99000000","2.29826000"],["78226.73000000","1.00192000"],["78224.51000000","0.00000000"],["78210.95000000","0.00000000"],["77145.20000000","0.00040000"],["70488.00000000","0.54458000"],["62656.00000000","0.00417000"]],"a":[["78320.00000000","5.55211000"],["78321.48000000","0.06702000"],["78321.50000000","0.00400000"],["78322.00000000","0.03214000"],["78322.23000000","0.02138000"],["78322.34000000","0.00014000"],["78323.23000000","0.01349000"],["78324.32000000","0.00000000"],["78325.15000000","0.01600000"],["78325.70000000","1.45897000"],["78326.00000000","0.03000000"],["78355.11000000","0.02512000"],["78376.50000000","0.00000000"],["78383.61000000","0.00007000"],["78414.89000000","0.00007000"]]}}
{"rx":1788854559046888468, "m":{"e":"depthUpdate","E":1788854559014,"s":"BTCUSDT","U":99829875630,"u":99829875687,"b":[["78319.99000000","0.43737000"],["78319.98000000","0.00083000"],["78318.36000000","0.06081000"],["78317.99000000","0.00000000"],["78317.48000000","0.02151000"],["78316.91000000","0.00007000"],["78316.90000000","0.12067000"],["78315.72000000","0.00014000"],["78315.39000000","0.00000000"],["78309.26000000","0.00800000"],["78309.25000000","0.00000000"],["78302.79000000","0.00638000"],["78289.66000000","0.63884000"],["78284.74000000","0.88523000"],["78271.04000000","1.26520000"],["78238.41000000","0.00000000"],["78227.36000000","0.32440000"],["78210.96000000","0.00000000"],["77145.20000000","0.00040000"],["70488.00000000","0.54474000"],["62656.00000000","0.00310000"]],"a":[["78320.05000000","0.05014000"],["78321.48000000","0.06716000"],["78322.23000000","0.02138000"],["78322.34000000","0.00000000"],["78369.64000000","0.88435000"]]}}
{"rx":1788854559139967062, "m":{"e":"depthUpdate","E":1788854559114,"s":"BTCUSDT","U":99829875688,"u":99829875707,"b":[["78319.99000000","0.40940000"],["78316.00000000","0.01196000"],["78314.00000000","0.03000000"],["78312.00000000","0.03000000"],["78300.59000000","0.19376000"],["78300.58000000","0.00000000"],["78274.49000000","0.00400000"],["78266.78000000","0.00000000"],["78104.65000000","0.00094000"],["78099.77000000","0.00802000"],["77145.20000000","0.00032000"],["77145.19000000","0.00030000"],["62656.00000000","0.00310000"]],"a":[["78321.52000000","0.00007000"],["79494.80000000","0.00030000"]]}}
{"rx":1788854559249763211, "m":{"e":"depthUpdate","E":1788854559214,"s":"BTCUSDT","U":99829875708,"u":99829875760,"b":[["78319.99000000","0.07947000"],["78318.37000000","0.00028000"],["78316.90000000","0.00014000"],["78316.01000000","0.00000000"],["78315.72000000","0.00007000"],["78315.63000000","0.02000000"],["78314.14000000","0.00000000"],["78313.99000000","0.00000000"],["78312.17000000","0.00000000"],["78311.73000000","0.00007000"],["78310.69000000","0.00000000"],["78310.29000000","0.00142000"],["78309.26000000","0.00000000"],["78309.24000000","0.00007000"],["78308.70000000","0.00243000"],["78307.99000000","0.41927000"],["78307.84000000","0.00000000"],["78307.67000000","0.00000000"],["78306.07000000","0.01314000"],["78306.03000000","1.86166000"],["78306.02000000","0.00000000"],["78305.25000000","0.00400000"],["78303.73000000","0.00000000"],["78302.79000000","0.01038000"],["78302.05000000","0.00000000"],["78300.16000000","0.37581000"],["78289.66000000","0.00000000"],["78275.82000000","0.00007000"],["78245.38000000","1.26562000"],["77145.20000000","0.00032000"],["70488.00000000","0.54490000"],["62656.00000000","0.00279000"]],"a":[["78320.00000000","5.55226000"],["78324.73000000","0.03057000"],["78327.48000000","0.37732000"],["78327.49000000","0.00000000"],["78328.49000000","0.02000000"],["78336.59000000","0.00000000"],["78497.13000000","0.00000000"]]}}
{"rx":1788854559340045406, "m":{"e":"depthUpdate","E":1788854559314,"s":"BTCUSDT","U":99829875761,"u":99829876142,"b":[["78319.99000000","0.00000000"],["78319.98000000","0.00000000"],["78319.97000000","0.00000000"],["78319.71000000","0.00000000"],["78318.74000000","0.00000000"],["78318.73000000","0.02059000"],["78318.72000000","0.00049000"],["78318.38000000","0.00000000"],["78318.37000000","0.00014000"],["78318.36000000","0.00014000"],["78317.48000000","0.02151000"],["78317.09000000","0.06067000"],["78316.91000000","0.00000000"],["78316.90000000","0.00000000"],["78316.24000000","0.00014000"],["78316.23000000","0.02151000"],["78316.00000000","0.01210000"],["78315.70000000","0.00786000"],["78315.64000000","0.00000000"],["78315.63000000","0.00014000"],["78315.40000000","0.00000000"],["78315.39000000","0.00000000"],["78315.38000000","0.00014000"],["78315.33000000","0.00014000"],["78315.32000000","0.00007000"],["78315.31000000","0.00007000"],["78314.71000000","0.00000000"],["78313.93000000","0.00000000"],["78313.33000000","0.00000000"],["78312.10000000","0.00000000"],["78311.73000000","0.02007000"],["78310.68000000","0.00197000"],["78310.29000000","0.00000000"],["78309.70000000","0.15000000"],["78309.63000000","0.00047000"],["78309.34000000","0.00400000"],["78309.25000000","0.00800000"],["78308.70000000","0.00000000"],["78308.55000000","0.00000000"],["78308.38000000","0.00000000"],["78307.99000000","0.27436000"],["78307.98000000","0.00000000"],["78307.75000000","0.00000000"],["78307.74000000","0.00007000"],["78307.73000000","0.00000000"],["78307.63000000","0.00000000"],["78307.62000000","0.00000000"],["78307.51000000","0.00143000"],["78306.07000000","0.00000000"],["78306.04000000","0.00245000"],["78306.03000000","0.00000000"],["78305.38000000","0.00000000"],["78305.25000000","0.00000000"],["78304.61000000","0.00000000"],["78304.58000000","0.00000000"],["78304.12000000","0.00000000"],["78303.99000000","0.00000000"],["78303.82000000","0.00000000"],["78303.81000000","0.00000000"],["78303.73000000","0.00000000"],["78303.72000000","0.00000000"],["78302.79000000","0.00638000"],["78302.06000000","0.66820000"],["78300.59000000","0.28116000"],["78300.22000000","0.00007000"],["78300.16000000","0.00000000"],["78299.51000000","0.00000000"],["78298.82000000","0.00000000"],["78295.45000000","0.15113000"],["78292.02000000","0.37581000"],["78292.01000000","0.00000000"],["78285.69000000","0.00193000"],["78283.92000000","0.00000000"],["78279.81000000","0.00014000"],["78275.64000000","0.00000000"],["78271.83000000","0.00007000"],["78259.51000000","0.34510000"],["78242.47000000","0.00000000"],["78235.19000000","0.00000000"],["78194.68000000","0.00068000"],["78178.57000000","0.00000000"],["78178.55000000","0.00000000"],["78177.80000000","0.00000000"],["78176.53000000","0.00000000"],["78174.23000000","1.53085000"],["78164.11000000","0.00000000"],["78118.01000000","3.84147000"],["77145.20000000","0.00000000"],["77145.19000000","0.00000000"],["70488.00000000","0.54170000"],["70487.99000000","0.00009000"]],"a":[["78318.74000000","8.64506000"],["78318.75000000","2.99905000"],["78318.76000000","0.00013000"],["78319.60000000","0.00000000"],["78319.71000000","0.00014000"],["78319.72000000","0.00000000"],["78319.96000000","0.00000000"],["78319.98000000","0.00000000"],["78319.99000000","3.39511000"],["78320.00000000","2.76502000"],["78320.01000000","0.00000000"],["78320.02000000","0.00000000"],["78320.05000000","0.00014000"],["78320.22000000","0.06702000"],["78320.77000000","0.00400000"],["78321.48000000","0.00014000"],["78321.50000000","0.00000000"],["78322.58000000","0.00000000"],["78323.22000000","0.00638000"],["78323.44000000","0.00000000"],["78323.90000000","0.00000000"],["78324.00000000","0.03000000"],["78325.14000000","0.00000000"],["78325.15000000","0.00800000"],["78325.47000000","0.12767000"],["78325.68000000","0.00000000"],["78327.47000000","0.38381000"],["78327.48000000","0.00151000"],["78330.22000000","0.31932000"],["78332.95000000","0.27138000"],["78335.06000000","0.03000000"],["78335.20000000","0.63847000"],["78339.90000000","0.00000000"],["78343.32000000","0.00000000"],["78343.80000000","0.00000000"],["78344.44000000","0.00000000"],["78348.76000000","0.34471000"],["78356.79000000","0.00622000"],["78358.11000000","0.00434000"],["78361.60000000","0.00429000"],["78366.50000000","0.00000000"],["78368.33000000","1.24767000"],["78369.21000000","0.00000000"],["78372.92000000","0.00000000"],["78389.89000000","0.00000000"],["78412.69000000","0.00000000"],["79494.80000000","0.00000000"]]}}
