{"rx":1788854502328433844, "m":{"e":"depthUpdate","E":1788854502214,"s":"BTCUSDT","U":99829830469,"u":99829830644,"b":[["78354.91000000","5.19586000"],["78354.90000000","0.00090000"],["78353.66000000","0.00014000"],["78353.65000000","0.01549000"],["78353.36000000","0.00000000"],["78353.33000000","0.00000000"],["78352.98000000","0.03229000"],["78352.97000000","0.10739000"],["78352.41000000","0.00014000"],["78352.40000000","0.01859000"],["78352.21000000","0.00014000"],["78352.19000000","0.21609000"],["78352.18000000","0.16035000"],["78352.17000000","0.00000000"],["78351.99000000","0.00014000"],["78351.85000000","0.00000000"],["78351.50000000","0.00400000"],["78351.39000000","0.00400000"],["78351.14000000","0.01859000"],["78350.92000000","0.00000000"],["78350.52000000","0.00000000"],["78349.47000000","0.00638000"],["78347.08000000","0.00000000"],["78346.59000000","0.00000000"],["78345.14000000","0.00800000"],["78344.48000000","0.00188000"],["78342.76000000","0.00007000"],["78339.55000000","0.02000000"],["78337.17000000","0.02000000"],["78331.54000000","0.12766000"],["78279.63000000","0.02000000"],["78254.68000000","0.00000000"],["78198.81000000","0.20250000"],["77179.59000000","0.00016000"],["70519.42000000","0.00032000"],["62686.40000000","0.00062000"]],"a":[["78354.92000000","3.22156000"],["78354.93000000","0.00034000"],["78354.99000000","0.00000000"],["78355.34000000","0.00000000"],["78355.81000000","0.00014000"],["78355.82000000","0.06520000"],["78355.83000000","0.00014000"],["78355.98000000","0.00014000"],["78355.99000000","0.00014000"],["78356.00000000","0.00014000"],["78356.01000000","0.00519000"],["78356.38000000","0.06801000"],["78356.58000000","0.00000000"],["78356.60000000","0.00000000"],["78357.64000000","0.00000000"],["78357.65000000","0.00014000"],["78357.85000000","0.00000000"],["78358.00000000","0.00014000"],["78358.01000000","0.06980000"],["78358.08000000","0.00601000"],["78359.11000000","0.00048000"],["78359.33000000","0.01002000"],["78359.34000000","0.00014000"],["78359.35000000","0.06222000"],["78360.03000000","0.00000000"],["78360.38000000","0.00000000"],["78360.58000000","0.01202000"],["78361.29000000","0.00000000"],["78361.81000000","0.00000000"],["78361.84000000","2.30916000"],["78362.20000000","0.00400000"],["78362.51000000","0.00638000"],["78362.76000000","0.00032000"],["78365.64000000","0.00000000"],["78366.85000000","0.00000000"],["78367.87000000","0.00000000"],["78370.17000000","0.12759000"],["78370.60000000","0.00040000"],["78375.70000000","0.00008000"],["78378.01000000","0.12758000"],["78378.43000000","0.00032000"],["78383.54000000","0.00000000"],["78386.27000000","0.00032000"],["78516.81000000","0.36423000"],["78540.50000000","0.00000000"],["78971.93000000","0.00000000"]]}}
{"rx":1788854502340788563, "m":{"e":"depthUpdate","E":1788854502314,"s":"BTCUSDT","U":99829830645,"u":99829830733,"b":[["78354.91000000","5.23429000"],["78354.90000000","0.00083000"],["78353.92000000","0.12157000"],["78353.65000000","0.01563000"],["78352.97000000","0.10739000"],["78352.40000000","0.01873000"],["78352.21000000","0.00000000"],["78352.18000000","0.16035000"],["78351.99000000","0.00000000"],["78346.34000000","0.01309000"],["78337.78000000","0.00007000"],["78336.03000000","0.38307000"],["78315.72000000","0.00007000"],["77179.59000000","0.00024000"]],"a":[["78354.92000000","3.24030000"],["78355.82000000","0.06534000"],["78355.83000000","0.00000000"],["78355.98000000","0.00000000"],["78355.99000000","0.00000000"],["78356.00000000","0.00000000"],["78356.01000000","0.00533000"],["78356.38000000","0.06801000"],["78357.65000000","0.00000000"],["78358.01000000","0.06980000"],["78358.08000000","0.00615000"],["78359.33000000","0.01016000"],["78359.35000000","0.06222000"],["78360.42000000","0.00000000"],["78360.58000000","0.01216000"],["78361.85000000","0.00000000"],["78362.20000000","0.00000000"],["78362.54000000","0.00400000"],["78363.37000000","0.00400000"],["78365.77000000","0.00000000"],["78368.26000000","0.00000000"],["78369.69000000","0.00000000"],["78373.61000000","0.00000000"],["78376.10000000","0.00000000"],["78383.94000000","0.00000000"],["78391.78000000","0.00000000"],["78417.40000000","1.26284000"]]}}
{"rx":1788854502437613381, "m":{"e":"depthUpdate","E":1788854502414,"s":"BTCUSDT","U":99829830734,"u":99829830798,"b":[["78354.91000000","5.22952000"],["78354.90000000","0.00097000"],["78353.94000000","0.00014000"],["78353.93000000","0.07334000"],["78353.92000000","0.12171000"],["78353.66000000","0.00000000"],["78353.26000000","0.00014000"],["78353.25000000","0.05976000"],["78352.99000000","0.00000000"],["78352.98000000","0.00028000"],["78352.41000000","0.00000000"],["78352.20000000","0.00014000"],["78352.19000000","0.21609000"],["78351.14000000","0.01873000"],["78335.55000000","0.04000000"],["78325.60000000","0.00000000"],["78323.91000000","0.00000000"],["78290.42000000","0.00318000"],["78279.64000000","0.00318000"],["78274.52000000","0.00000000"],["78272.61000000","0.00000000"],["78271.58000000","0.00000000"],["78266.23000000","0.00000000"],["78262.53000000","0.00000000"],["78204.97000000","1.53184000"],["78204.01000000","0.00000000"],["78201.01000000","0.00127000"],["77179.59000000","0.00032000"],["70519.42000000","0.00048000"],["70519.41000000","0.00009000"],["62686.40000000","0.00031000"]],"a":[["78354.92000000","3.24002000"],["78363.70000000","0.00153000"],["78408.58000000","0.00318000"],["78411.84000000","0.00000000"],["78415.99000000","0.00000000"],["78423.04000000","0.00317000"],["78484.67000000","0.00000000"],["78501.27000000","0.00127000"],["78541.46000000","0.00000000"]]}}
{"rx":1788854502541384086, "m":{"e":"depthUpdate","E":1788854502514,"s":"BTCUSDT","U":99829830799,"u":99829830821,"b":[["78354.91000000","5.23067000"],["78353.93000000","0.07348000"],["78353.65000000","0.01563000"],["78352.98000000","0.00014000"],["78351.14000000","0.01859000"],["78335.97000000","0.02000000"],["78335.59000000","0.02000000"],["78334.72000000","0.00007000"],["78282.69000000","0.00000000"],["78281.62000000","0.00000000"],["78280.88000000","0.00000000"],["78279.63000000","0.00000000"],["77179.59000000","0.00032000"]],"a":[]}}
{"rx":1788854502637177117, "m":{"e":"depthUpdate","E":1788854502614,"s":"BTCUSDT","U":99829830822,"u":99829830886,"b":[["78354.91000000","5.23012000"],["78354.90000000","0.00090000"],["78354.81000000","0.00014000"],["78354.80000000","0.10406000"],["78354.79000000","0.16444000"],["78353.94000000","0.00000000"],["78353.93000000","0.00014000"],["78353.92000000","0.00014000"],["78352.20000000","0.00007000"],["78344.48000000","0.00000000"],["78323.23000000","0.00000000"],["78321.92000000","0.00000000"],["78297.75000000","0.00000000"],["78296.80000000","0.00000000"],["77179.59000000","0.00032000"],["75757.00000000","0.11326000"],["70519.42000000","0.00064000"],["62686.40000000","0.00000000"],["62684.00000000","0.00000000"],["62683.93000000","0.00124000"]],"a":[["78354.92000000","3.24052000"],["78354.93000000","0.00062000"],["78361.82000000","0.01607000"],["78363.37000000","0.00000000"],["78363.94000000","0.00000000"],["78364.42000000","0.00000000"],["78366.67000000","0.00007000"],["78540.89000000","0.00000000"]]}}
{"rx":1788854502736732059, "m":{"e":"depthUpdate","E":1788854502714,"s":"BTCUSDT","U":99829830887,"u":99829830967,"b":[["78354.91000000","5.24202000"],["78354.90000000","0.00027000"],["78354.80000000","0.10420000"],["78353.93000000","0.00000000"],["78353.92000000","0.00000000"],["78351.50000000","0.00000000"],["78351.39000000","0.00000000"],["78349.47000000","0.00000000"],["78323.01000000","0.00000000"],["78133.05000000","0.00809000"],["78114.79000000","0.00000000"],["77179.59000000","0.00032000"],["77179.58000000","0.00030000"],["62683.93000000","0.00124000"]],"a":[["78354.92000000","0.41520000"],["78354.93000000","0.00069000"],["78355.82000000","0.19409000"],["78356.02000000","0.00007000"],["78359.32000000","0.45465000"],["78360.38000000","0.49082000"],["78361.29000000","0.00000000"],["78361.81000000","0.00000000"],["78362.51000000","0.00000000"],["78362.54000000","0.00000000"],["78362.76000000","0.20282000"],["78363.47000000","0.00000000"],["78363.60000000","0.00014000"],["78365.99000000","0.00638000"],["78366.27000000","0.00007000"],["78366.75000000","0.00000000"],["78369.99000000","0.00638000"],["78374.75000000","0.00000000"],["78376.99000000","0.31915000"],["78406.56000000","0.34446000"]]}}
{"rx":1788854502837352782, "m":{"e":"depthUpdate","E":1788854502814,"s":"BTCUSDT","U":99829830968,"u":99829831001,"b":[["78354.26000000","0.00400000"],["77179.59000000","0.00040000"],["70519.42000000","0.00107000"],["62679.56000000","0.00093000"]],"a":[["78354.92000000","0.41128000"],["78354.93000000","0.00083000"],["78355.81000000","0.00000000"],["78355.82000000","0.00014000"],["78358.08000000","0.00615000"],["78358.55000000","0.30276000"],["78358.56000000","0.48560000"],["78359.32000000","0.45479000"],["78359.35000000","0.06222000"],["78360.38000000","0.00000000"],["78360.58000000","0.01202000"],["78367.03000000","0.00400000"],["78379.00000000","0.00000000"]]}}
{"rx":1788854502937670856, "m":{"e":"depthUpdate","E":1788854502914,"s":"BTCUSDT","U":99829831002,"u":99829831056,"b":[["78336.04000000","0.20805000"],["78335.90000000","0.00000000"],["78324.38000000","0.51868000"],["78306.54000000","0.26581000"],["78306.16000000","0.00000000"],["78279.26000000","0.53585000"],["78253.75000000","0.09432000"],["78207.15000000","0.60906000"],["77179.59000000","0.00040000"],["70519.42000000","0.00123000"],["70519.00000000","0.00020000"]],"a":[["78354.92000000","0.41142000"],["78355.82000000","0.00000000"],["78357.63000000","0.00014000"],["78357.64000000","0.17810000"],["78357.65000000","0.00000000"],["78358.08000000","0.00615000"],["78358.55000000","0.00014000"],["78358.56000000","0.00014000"],["78359.32000000","0.00014000"],["78359.34000000","0.00000000"],["78359.35000000","0.06208000"],["78361.81000000","0.49082000"],["78366.17000000","0.00400000"],["78369.62000000","0.00000000"],["78371.62000000","0.02000000"],["78393.28000000","0.71288000"],["78423.04000000","1.49986000"],["78447.77000000","1.50681000"],["78493.99000000","0.47366000"]]}}
{"rx":1788854503039101459, "m":{"e":"depthUpdate","E":1788854503014,"s":"BTCUSDT","U":99829831057,"u":99829831256,"b":[["78354.91000000","5.24193000"],["78354.81000000","0.00000000"],["78354.80000000","0.10406000"],["78354.79000000","0.16458000"],["78353.26000000","0.00000000"],["78353.25000000","0.05990000"],["78352.98000000","0.00000000"],["78352.34000000","0.23000000"],["78352.33000000","0.31916000"],["78352.32000000","0.00355000"],["78352.20000000","0.00000000"],["78352.19000000","0.00014000"],["78352.01000000","0.03057000"],["78350.23000000","0.00000000"],["78349.71000000","0.01333000"],["78349.46000000","0.00000000"],["78349.00000000","0.02093000"],["78345.14000000","0.00000000"],["78343.40000000","0.37981000"],["78343.38000000","0.00000000"],["78341.32000000","0.00000000"],["78332.64000000","0.37581000"],["78332.63000000","1.43679000"],["78332.60000000","0.00000000"],["78327.10000000","0.12766000"],["78323.57000000","0.00000000"],["78321.64000000","0.00000000"],["78315.72000000","0.00000000"],["78310.23000000","0.36748000"],["78309.40000000","0.00000000"],["78283.68000000","0.00000000"],["78269.93000000","0.00000000"],["78200.69000000","0.00000000"],["78026.67000000","0.00000000"],["77179.59000000","0.00040000"],["70519.41000000","0.00000000"],["70519.40000000","0.00009000"],["70519.00000000","0.00000000"],["62683.93000000","0.00248000"],["62679.56000000","0.00062000"]],"a":[["78354.92000000","0.03628000"],["78354.93000000","0.00076000"],["78354.94000000","0.00013000"],["78355.62000000","0.00007000"],["78356.37000000","0.00000000"],["78356.38000000","0.00014000"],["78357.63000000","0.00000000"],["78357.64000000","0.00014000"],["78358.00000000","0.00000000"],["78358.01000000","0.00014000"],["78358.08000000","0.00615000"],["78358.55000000","0.00000000"],["78358.56000000","0.00000000"],["78358.68000000","0.00014000"],["78358.69000000","0.06787000"],["78359.32000000","0.00000000"],["78359.34000000","0.00000000"],["78359.35000000","0.00014000"],["78359.47000000","0.49082000"],["78359.61000000","0.00007000"],["78360.24000000","0.00000000"],["78360.38000000","0.49082000"],["78360.58000000","0.01216000"],["78360.75000000","0.00000000"],["78361.29000000","0.49082000"],["78361.80000000","0.00400000"],["78361.81000000","0.49082000"],["78361.82000000","0.00814000"],["78361.83000000","1.51171000"],["78362.30000000","0.00014000"],["78362.86000000","0.00000000"],["78363.60000000","0.00007000"],["78364.27000000","0.00000000"],["78364.28000000","0.00000000"],["78365.26000000","0.00056000"],["78366.17000000","0.00000000"],["78366.26000000","0.00060000"],["78366.48000000","0.05000000"],["78366.76000000","0.00000000"],["78367.03000000","0.00000000"],["78367.27000000","0.00400000"],["78368.87000000","0.00000000"],["78369.18000000","0.10000000"],["78370.88000000","0.37581000"],["78370.89000000","0.00000000"],["78374.43000000","0.00400000"],["78375.88000000","0.00000000"],["78376.98000000","0.18226000"],["78381.28000000","0.37581000"],["78381.29000000","0.00000000"],["78384.08000000","0.00000000"],["78385.12000000","0.00063000"],["78390.37000000","0.00000000"],["78391.40000000","0.00000000"],["78393.28000000","0.00000000"],["78394.80000000","0.00000000"],["78395.52000000","0.00007000"],["78399.62000000","0.00000000"],["78409.44000000","0.00400000"],["78409.70000000","0.00000000"],["78413.88000000","0.55250000"],["78426.25000000","1.26270000"],["78477.98000000","0.00000000"],["78507.76000000","0.00000000"],["78541.73000000","0.00000000"],["78610.83000000","0.00000000"],["78619.16000000","0.00028000"],["78735.53000000","0.00000000"]]}}
{"rx":1788854503137780186, "m":{"e":"depthUpdate","E":1788854503114,"s":"BTCUSDT","U":99829831257,"u":99829831414,"b":[["78354.91000000","5.24193000"],["78354.27000000","0.00000000"],["78352.40000000","0.01873000"],["78352.35000000","0.37581000"],["78352.34000000","0.23014000"],["78352.33000000","0.31930000"],["78352.19000000","0.00000000"],["78352.18000000","0.16021000"],["78351.27000000","0.00158000"],["78349.71000000","0.00000000"],["78349.12000000","0.00000000"],["78349.00000000","0.00000000"],["78348.94000000","0.00000000"],["78348.41000000","0.00800000"],["78342.81000000","0.00000000"],["78340.49000000","0.32675000"],["78336.96000000","0.09553000"],["78335.01000000","0.10269000"],["78334.30000000","0.00007000"],["78331.88000000","0.00000000"],["78329.92000000","0.00000000"],["78329.59000000","0.02516000"],["78317.77000000","0.00000000"],["78315.72000000","0.63443000"],["78306.54000000","0.00000000"],["78306.53000000","0.00000000"],["78291.52000000","0.20000000"],["78121.71000000","0.00511000"],["78038.93000000","0.00026000"],["77649.72000000","0.00010000"],["77179.59000000","0.00032000"],["70519.42000000","0.00139000"]],"a":[["78354.92000000","0.03607000"],["78354.93000000","0.00069000"],["78356.01000000","0.00033000"],["78356.38000000","0.00000000"],["78356.94000000","0.00007000"],["78356.95000000","0.10724000"],["78357.64000000","0.00000000"],["78357.65000000","0.00000000"],["78358.01000000","0.00000000"],["78358.08000000","0.01115000"],["78358.55000000","0.00000000"],["78358.56000000","0.49082000"],["78358.68000000","0.17019000"],["78358.69000000","0.06801000"],["78359.33000000","0.01016000"],["78359.35000000","0.00000000"],["78359.46000000","0.00000000"],["78359.47000000","0.49096000"],["78359.61000000","0.00014000"],["78360.36000000","0.49082000"],["78360.37000000","0.00400000"],["78360.38000000","0.00014000"],["78360.39000000","0.00026000"],["78360.58000000","0.01216000"],["78361.28000000","0.00400000"],["78361.29000000","0.00014000"],["78361.80000000","0.00000000"],["78361.81000000","0.00000000"],["78361.82000000","0.00014000"],["78363.60000000","0.00014000"],["78363.70000000","0.00000000"],["78366.87000000","0.00000000"],["78367.87000000","0.00400000"],["78368.77000000","0.00000000"],["78368.83000000","0.00000000"],["78369.63000000","0.00638000"],["78369.99000000","0.00000000"],["78371.62000000","0.00000000"],["78371.76000000","0.00153000"],["78377.42000000","0.02000000"],["78388.35000000","0.63384000"],["78400.40000000","0.00000000"],["78401.67000000","0.77692000"],["78401.94000000","0.20000000"],["78405.72000000","0.00316000"],["78415.23000000","0.00000000"],["78438.77000000","0.00408000"],["78455.16000000","0.00000000"],["78483.29000000","0.00127000"],["79043.69000000","0.00018000"],["79530.25000000","0.00030000"]]}}
{"rx":1788854503239908178, "m":{"e":"depthUpdate","E":1788854503214,"s":"BTCUSDT","U":99829831415,"u":99829831485,"b":[["78352.40000000","0.01873000"],["78352.33000000","0.31916000"],["78348.57000000","0.02087000"],["78348.51000000","0.01309000"],["78346.23000000","0.00063000"],["78339.43000000","0.05710000"],["78325.00000000","0.70000000"],["78317.50000000","0.02000000"],["77179.59000000","0.00032000"],["62679.56000000","0.00031000"]],"a":[["78354.92000000","0.03631000"],["78354.93000000","0.00076000"],["78356.01000000","0.00019000"],["78356.95000000","0.10738000"],["78358.04000000","0.00007000"],["78358.08000000","0.00615000"],["78358.55000000","0.17011000"],["78358.56000000","0.49596000"],["78358.68000000","0.00028000"],["78359.11000000","0.00000000"],["78359.47000000","0.00014000"],["78360.36000000","0.00014000"],["78360.38000000","0.00000000"],["78360.58000000","0.01202000"],["78361.28000000","0.00000000"],["78361.29000000","0.00000000"],["78361.81000000","0.49082000"],["78361.82000000","0.01214000"],["78368.86000000","0.00048000"],["78372.09000000","0.00503000"],["78372.15000000","0.00007000"],["78386.00000000","0.54161000"],["78411.62000000","1.01971000"],["78452.07000000","0.00025000"],["78542.77000000","0.00000000"]]}}
{"rx":1788854503339394951, "m":{"e":"depthUpdate","E":1788854503314,"s":"BTCUSDT","U":99829831486,"u":99829831538,"b":[["78353.67000000","0.00007000"],["78340.83000000","0.00007000"],["78258.25000000","0.00408000"],["78193.31000000","0.03631000"],["77179.59000000","0.00032000"],["70519.42000000","0.00155000"],["62670.00000000","0.02248000"]],"a":[["78358.08000000","0.00615000"],["78358.55000000","0.17025000"],["78358.56000000","0.49596000"],["78358.68000000","0.00014000"],["78359.33000000","0.01016000"],["78359.47000000","0.00000000"],["78360.36000000","0.00000000"],["78360.58000000","0.01216000"],["78361.81000000","0.49096000"],["78362.35000000","0.00000000"],["78363.81000000","0.00000000"],["78367.73000000","0.00000000"],["78370.19000000","0.00000000"],["78371.65000000","0.00000000"],["78375.57000000","0.00014000"],["78378.03000000","0.00007000"],["78385.87000000","0.00000000"],["78393.71000000","0.00000000"],["78542.85000000","0.00382000"]]}}
{"rx":1788854503438401674, "m":{"e":"depthUpdate","E":1788854503414,"s":"BTCUSDT","U":99829831539,"u":99829831582,"b":[["78354.91000000","5.28207000"],["78350.53000000","0.01337000"],["78350.22000000","0.00000000"],["78334.93000000","0.00000000"],["77179.59000000","0.00032000"],["70519.42000000","0.00171000"],["70519.40000000","0.00000000"],["62679.56000000","0.00000000"]],"a":[["78354.92000000","0.03539000"],["78354.93000000","0.00069000"],["78356.95000000","0.00014000"],["78358.55000000","0.00014000"],["78358.56000000","0.00514000"],["78359.61000000","0.00007000"],["78360.37000000","0.00000000"],["78360.38000000","0.49082000"],["78361.29000000","0.00000000"],["78361.50000000","0.00000000"],["78361.81000000","0.00014000"],["78361.84000000","0.01202000"],["78370.88000000","0.00000000"],["78371.69000000","0.00187000"],["78432.45000000","2.29723000"],["78542.39000000","0.00000000"],["78542.91000000","0.03631000"],["78543.20000000","0.00000000"],["78543.31000000","0.00040000"]]}}
{"rx":1788854503542975406, "m":{"e":"depthUpdate","E":1788854503514,"s":"BTCUSDT","U":99829831583,"u":99829831702,"b":[["78354.91000000","5.28201000"],["78352.35000000","0.37595000"],["78350.53000000","0.00000000"],["78282.69000000","0.02000000"],["78276.70000000","1.00155000"],["78272.80000000","0.00000000"],["78259.80000000","0.00007000"],["77179.59000000","0.00032000"]],"a":[["78354.92000000","0.03518000"],["78354.93000000","0.00076000"],["78356.94000000","0.00000000"],["78356.95000000","0.00000000"],["78358.08000000","0.01115000"],["78358.54000000","0.00014000"],["78358.55000000","0.00007000"],["78358.56000000","0.00014000"],["78359.33000000","0.01016000"],["78359.45000000","0.00000000"],["78359.46000000","0.00000000"],["78359.47000000","0.00000000"],["78359.61000000","0.00014000"],["78360.37000000","0.00400000"],["78360.38000000","0.00014000"],["78360.58000000","0.01216000"],["78361.81000000","0.00000000"],["78361.82000000","0.49109000"],["78361.83000000","0.81582000"],["78363.10000000","0.00000000"],["78366.19000000","1.32348000"],["78366.20000000","2.29723000"],["78366.77000000","0.00000000"],["78368.23000000","0.00408000"],["78370.90000000","0.37581000"],["78542.91000000","0.00000000"],["78542.92000000","0.00000000"],["78543.25000000","0.03539000"]]}}
{"rx":1788854503639134134, "m":{"e":"depthUpdate","E":1788854503614,"s":"BTCUSDT","U":99829831703,"u":99829831794,"b":[["78354.91000000","5.28164000"],["77179.59000000","0.00032000"],["70519.42000000","0.00196000"],["62683.93000000","0.00217000"]],"a":[["78354.92000000","0.03572000"],["78354.93000000","0.00069000"],["78358.08000000","0.01115000"],["78358.54000000","0.00014000"],["78358.55000000","0.16999000"],["78358.56000000","0.49081000"],["78358.68000000","0.00014000"],["78359.33000000","0.01016000"],["78359.46000000","0.00000000"],["78359.47000000","0.00000000"],["78360.37000000","0.00400000"],["78360.38000000","0.00000000"],["78361.29000000","0.00000000"],["78361.81000000","0.01200000"],["78361.82000000","0.49109000"],["78361.84000000","0.01216000"],["78362.31000000","2.03497000"],["78362.75000000","0.00008000"],["78362.76000000","0.20305000"],["78366.67000000","0.00007000"],["78370.60000000","0.00063000"],["78378.43000000","0.00055000"],["78386.27000000","0.00055000"],["78542.70000000","0.00126000"],["78542.82000000","0.00000000"],["78543.25000000","0.00000000"],["78543.28000000","0.00000000"]]}}
{"rx":1788854503737660124, "m":{"e":"depthUpdate","E":1788854503714,"s":"BTCUSDT","U":99829831795,"u":99829831835,"b":[["78328.75000000","0.00408000"],["78193.31000000","0.00000000"],["78031.48000000","0.00009000"],["77179.59000000","0.00032000"],["77179.58000000","0.00030000"],["62683.93000000","0.00217000"]],"a":[["78354.92000000","0.03572000"],["78358.04000000","0.00000000"],["78358.08000000","0.01115000"],["78358.55000000","0.17013000"],["78358.56000000","0.49095000"],["78360.58000000","0.01216000"],["78361.29000000","0.46759000"],["78361.81000000","0.01214000"],["78361.83000000","0.81568000"],["78361.84000000","0.01202000"],["78362.31000000","2.03483000"],["78542.50000000","0.03572000"],["78542.77000000","0.00000000"],["78542.94000000","0.00000000"],["78543.22000000","0.00014000"],["78678.35000000","0.00009000"]]}}
{"rx":1788854503841246212, "m":{"e":"depthUpdate","E":1788854503814,"s":"BTCUSDT","U":99829831836,"u":99829831892,"b":[["78202.79000000","0.00206000"],["78193.12000000","0.00000000"],["77179.59000000","0.00040000"],["70519.42000000","0.00212000"],["62683.93000000","0.00186000"]],"a":[["78354.92000000","0.03593000"],["78354.93000000","0.00090000"],["78355.23000000","0.00007000"],["78355.99000000","0.00014000"],["78356.00000000","0.05000000"],["78356.91000000","0.10724000"],["78358.00000000","0.00500000"],["78360.00000000","0.00500000"],["78360.58000000","0.01216000"],["78361.27000000","2.28208000"],["78361.28000000","2.30923000"],["78361.29000000","0.00014000"],["78361.81000000","0.00014000"],["78361.82000000","0.00000000"],["78361.83000000","0.00000000"],["78362.00000000","0.00638000"],["78489.65000000","0.00540000"],["78509.57000000","0.00206000"],["78541.49000000","0.00000000"],["78542.50000000","0.00000000"]]}}
{"rx":1788854503947760627, "m":{"e":"depthUpdate","E":1788854503914,"s":"BTCUSDT","U":99829831893,"u":99829831929,"b":[["78304.60000000","0.49465000"],["78289.58000000","0.00408000"],["78266.01000000","1.18825000"],["78242.47000000","0.04530000"],["78201.01000000","0.04869000"],["77179.59000000","0.00040000"],["70519.42000000","0.00185000"]],"a":[["78354.92000000","0.03593000"],["78356.00000000","0.05014000"],["78356.91000000","0.10738000"],["78358.00000000","0.00514000"],["78359.33000000","0.01016000"],["78360.58000000","0.01202000"],["78361.29000000","0.00000000"],["78361.81000000","0.00000000"],["78392.76000000","0.47751000"],["78432.44000000","1.72079000"],["78432.46000000","0.00000000"],["78542.10000000","0.00000000"],["78542.40000000","0.00000000"]]}}
{"rx":1788854504037221012, "m":{"e":"depthUpdate","E":1788854504014,"s":"BTCUSDT","U":99829831930,"u":99829831971,"b":[["78350.55000000","0.01283000"],["78192.85000000","0.03593000"],["77179.59000000","0.00040000"],["70519.42000000","0.00201000"],["62683.93000000","0.00279000"]],"a":[["78354.92000000","0.03586000"],["78356.00000000","0.10014000"],["78358.00000000","0.01014000"],["78360.00000000","0.01000000"],["78361.26000000","0.00400000"],["78362.00000000","0.01138000"],["78373.99000000","0.00400000"],["78374.43000000","0.00000000"],["78374.97000000","0.00000000"],["78375.06000000","0.00000000"],["78375.73000000","0.00000000"],["78375.88000000","0.00000000"],["78395.00000000","0.71000000"],["78541.88000000","0.00000000"],["78961.67000000","0.06586000"]]}}
{"rx":1788854504141671522, "m":{"e":"depthUpdate","E":1788854504114,"s":"BTCUSDT","U":99829831972,"u":99829831982,"b":[["78350.55000000","0.00000000"],["78329.00000000","0.70000000"],["78325.00000000","0.00000000"],["77179.59000000","0.00032000"],["70519.42000000","0.00217000"],["70519.00000000","0.00000000"],["62684.00000000","0.00200000"]],"a":[["79080.12000000","0.07572000"],["79530.25000000","0.00030000"]]}}
{"rx":1788854504244424647, "m":{"e":"depthUpdate","E":1788854504214,"s":"BTCUSDT","U":99829831983,"u":99829831993,"b":[["78329.02000000","0.36562000"],["77179.59000000","0.00032000"],["70519.42000000","0.00208000"],["70519.41000000","0.00009000"],["62684.00000000","0.00000000"],["62683.93000000","0.00248000"]],"a":[["78354.92000000","0.03511000"],["78408.76000000","0.00407000"],["78409.44000000","0.00000000"]]}}
{"rx":1788854504336967737, "m":{"e":"depthUpdate","E":1788854504314,"s":"BTCUSDT","U":99829831994,"u":99829832001,"b":[["78171.27000000","0.00000000"],["77975.35000000","0.00000000"],["77179.59000000","0.00032000"],["72089.37000000","0.00014000"],["70519.42000000","0.00224000"]],"a":[["78358.04000000","0.00007000"],["78362.30000000","0.00193000"],["78370.50000000","0.00000000"],["78563.11000000","0.00000000"],["78759.03000000","0.00000000"]]}}
{"rx":1788854504445277201, "m":{"e":"depthUpdate","E":1788854504414,"s":"BTCUSDT","U":99829832002,"u":99829832062,"b":[["78354.81000000","0.00014000"],["78354.80000000","0.10420000"],["78353.26000000","0.00014000"],["78352.98000000","0.00014000"],["78352.36000000","0.00007000"],["78349.04000000","0.00013000"],["78343.89000000","0.00007000"],["77179.59000000","0.00032000"],["62684.00000000","0.00000000"],["62683.93000000","0.00217000"]],"a":[["78354.92000000","0.03518000"],["78354.93000000","0.00097000"],["78356.00000000","0.20014000"],["78356.73000000","0.00014000"],["78356.74000000","0.49081000"],["78356.80000000","0.00007000"],["78356.90000000","0.00014000"],["78357.64000000","0.00000000"],["78357.65000000","0.00000000"],["78358.00000000","0.02014000"],["78358.54000000","0.00000000"],["78358.55000000","0.02654000"],["78358.56000000","0.00014000"],["78358.68000000","0.00007000"],["78360.38000000","0.49081000"],["78360.79000000","0.00013000"],["78361.25000000","0.49081000"],["78361.27000000","1.79127000"],["78363.25000000","0.00000000"],["78371.09000000","0.00000000"],["78394.61000000","0.00000000"]]}}
{"rx":1788854504554245461, "m":{"e":"depthUpdate","E":1788854504514,"s":"BTCUSDT","U":99829832063,"u":99829832505,"b":[["78354.91000000","0.65035000"],["78354.90000000","0.00076000"],["78354.81000000","0.00000000"],["78354.80000000","0.00014000"],["78354.79000000","0.00014000"],["78354.26000000","0.00000000"],["78353.66000000","0.00014000"],["78353.15000000","0.00000000"],["78352.98000000","0.00000000"],["78352.97000000","0.00014000"],["78352.41000000","0.00014000"],["78352.36000000","0.00000000"],["78352.35000000","0.00014000"],["78352.34000000","0.00014000"],["78352.33000000","0.00000000"],["78352.32000000","0.00000000"],["78352.18000000","0.00038000"],["78352.01000000","0.00000000"],["78351.63000000","0.00007000"],["78351.27000000","0.00000000"],["78351.15000000","0.00014000"],["78349.45000000","0.00000000"],["78349.23000000","0.00007000"],["78349.17000000","0.00000000"],["78348.57000000","0.00000000"],["78348.54000000","0.49081000"],["78348.51000000","0.00000000"],["78348.41000000","0.00000000"],["78348.40000000","0.00000000"],["78348.12000000","0.00000000"],["78348.00000000","0.00000000"],["78347.99000000","0.00014000"],["78347.64000000","0.00007000"],["78347.63000000","0.49081000"],["78346.72000000","0.49081000"],["78346.34000000","0.00000000"],["78346.05000000","0.00000000"],["78345.94000000","0.00000000"],["78345.82000000","0.30020000"],["78345.81000000","0.49081000"],["78345.42000000","0.02000000"],["78345.05000000","0.00400000"],["78344.90000000","0.49081000"],["78344.11000000","0.00000000"],["78344.01000000","0.00000000"],["78344.00000000","0.56921000"],["78343.99000000","0.00000000"],["78343.65000000","0.00007000"],["78343.41000000","0.01200000"],["78343.40000000","0.00000000"],["78343.39000000","0.00000000"],["78342.38000000","0.00000000"],["78341.86000000","0.00000000"],["78341.62000000","0.00158000"],["78341.33000000","0.00000000"],["78341.02000000","0.00000000"],["78340.80000000","0.00000000"],["78340.79000000","0.60013000"],["78340.77000000","0.31921000"],["78340.62000000","0.62534000"],["78340.61000000","0.00000000"],["78339.89000000","0.00000000"],["78339.57000000","0.02026000"],["78339.43000000","0.00000000"],["78339.08000000","0.00000000"],["78338.49000000","0.00000000"],["78338.11000000","2.03759000"],["78338.10000000","0.00000000"],["78337.31000000","0.00007000"],["78337.25000000","0.00000000"],["78336.72000000","0.03828000"],["78336.04000000","0.07378000"],["78336.03000000","0.00000000"],["78333.79000000","0.00000000"],["78333.01000000","2.03759000"],["78332.65000000","0.37581000"],["78332.64000000","0.00000000"],["78332.63000000","0.00000000"],["78332.62000000","0.00000000"],["78331.54000000","0.00000000"],["78329.59000000","0.00000000"],["78329.06000000","2.03759000"],["78329.05000000","0.00000000"],["78329.02000000","0.00000000"],["78329.00000000","0.00000000"],["78324.83000000","4.33482000"],["78324.82000000","0.00000000"],["78324.81000000","0.00000000"],["78324.44000000","0.37581000"],["78324.38000000","0.00000000"],["78324.05000000","0.00000000"],["78323.00000000","0.00000000"],["78322.24000000","0.00000000"],["78321.62000000","0.00000000"],["78320.84000000","0.00008000"],["78320.83000000","0.00000000"],["78315.72000000","0.63450000"],["78314.01000000","0.00000000"],["78311.73000000","0.00078000"],["78310.74000000","0.00000000"],["78310.72000000","0.00000000"],["78310.23000000","0.00000000"],["78307.74000000","0.00007000"],["78306.92000000","0.00400000"],["78304.24000000","0.00400000"],["78292.07000000","0.36748000"],["78290.42000000","0.00000000"],["78279.64000000","0.00000000"],["78277.38000000","2.29723000"],["78276.70000000","0.00007000"],["78274.53000000","0.00000000"],["78264.84000000","2.29723000"],["78259.80000000","3.83458000"],["78255.66000000","1.00148000"],["78202.79000000","0.00000000"],["78201.01000000","0.04742000"],["78196.10000000","0.00000000"],["78196.09000000","0.00000000"],["78192.85000000","0.00000000"],["78159.02000000","0.00012000"],["78114.44000000","0.00007000"],["78035.45000000","0.00007000"],["77179.59000000","0.00032000"],["70519.42000000","0.00240000"],["70519.41000000","0.00000000"],["62683.93000000","0.00341000"]],"a":[["78354.92000000","6.96516000"],["78354.93000000","0.00034000"],["78354.95000000","0.05000000"],["78355.00000000","0.05000000"],["78355.61000000","0.00400000"],["78355.62000000","0.00014000"],["78355.83000000","0.00000000"],["78355.99000000","0.13077000"],["78356.00000000","0.20014000"],["78356.38000000","0.06787000"],["78356.41000000","0.00000000"],["78356.73000000","0.00000000"],["78356.74000000","0.00014000"],["78356.79000000","0.00638000"],["78356.90000000","0.00000000"],["78357.65000000","0.00000000"],["78357.99000000","0.00000000"],["78358.54000000","0.00000000"],["78358.55000000","0.00014000"],["78358.56000000","0.00000000"],["78358.68000000","0.00000000"],["78358.69000000","0.00014000"],["78359.47000000","0.00000000"],["78359.60000000","0.00000000"],["78359.99000000","0.00000000"],["78360.00000000","0.02000000"],["78360.36000000","0.00000000"],["78360.37000000","0.02000000"],["78360.38000000","0.00000000"],["78360.52000000","0.00400000"],["78361.25000000","0.00000000"],["78361.26000000","0.00000000"],["78361.28000000","2.29723000"],["78362.00000000","0.02138000"],["78362.30000000","0.37760000"],["78363.27000000","0.00153000"],["78363.38000000","0.03057000"],["78363.69000000","0.00000000"],["78365.26000000","0.00000000"],["78365.99000000","0.00000000"],["78366.26000000","0.00000000"],["78366.42000000","0.00000000"],["78367.26000000","0.00000000"],["78367.27000000","0.00000000"],["78367.58000000","0.31914000"],["78367.87000000","0.00000000"],["78368.86000000","0.00000000"],["78369.63000000","0.00000000"],["78370.52000000","0.02000000"],["78371.76000000","0.00000000"],["78372.26000000","0.63816000"],["78373.99000000","0.00000000"],["78374.57000000","0.00223000"],["78375.49000000","0.31914000"],["78376.98000000","0.00000000"],["78376.99000000","0.00000000"],["78377.42000000","0.00000000"],["78384.50000000","0.00000000"],["78390.45000000","0.34453000"],["78392.57000000","0.02472000"],["78395.00000000","0.01000000"],["78395.06000000","1.26320000"],["78395.52000000","0.00000000"],["78398.04000000","0.00400000"],["78398.25000000","0.00000000"],["78403.00000000","0.00000000"],["78406.08000000","0.00000000"],["78407.22000000","0.00000000"],["78408.76000000","0.00007000"],["78413.88000000","0.00000000"],["78417.40000000","0.00000000"],["78426.25000000","0.00000000"],["78502.93000000","0.03057000"],["78509.57000000","0.00000000"],["78514.71000000","0.00000000"],["78542.29000000","0.00000000"]]}}
{"rx":1788854504642498840, "m":{"e":"depthUpdate","E":1788854504614,"s":"BTCUSDT","U":99829832506,"u":99829832699,"b":[["78354.91000000","2.12051000"],["78354.90000000","0.00062000"],["78354.80000000","0.00000000"],["78354.79000000","0.00000000"],["78353.25000000","0.05990000"],["78352.97000000","0.00000000"],["78352.40000000","0.01873000"],["78352.35000000","0.00000000"],["78352.34000000","0.00000000"],["78351.14000000","0.01873000"],["78350.36000000","0.00000000"],["78349.47000000","0.00000000"],["78349.46000000","0.00000000"],["78349.45000000","0.00000000"],["78349.22000000","0.03014000"],["78348.54000000","0.00014000"],["78347.75000000","0.00026000"],["78347.64000000","0.00007000"],["78347.63000000","0.00014000"],["78346.72000000","0.00000000"],["78345.82000000","0.00000000"],["78345.81000000","0.00000000"],["78345.66000000","0.00400000"],["78345.50000000","0.00069000"],["78345.43000000","0.03920000"],["78345.30000000","0.10724000"],["78345.20000000","0.00000000"],["78344.90000000","0.00000000"],["78344.00000000","0.27978000"],["78343.83000000","0.00000000"],["78343.65000000","0.00014000"],["78343.41000000","0.00000000"],["78342.52000000","0.00047000"],["78342.00000000","0.00048000"],["78341.21000000","0.00800000"],["78340.84000000","0.00638000"],["78340.80000000","0.00400000"],["78340.63000000","0.37581000"],["78340.62000000","1.14725000"],["78340.05000000","0.00187000"],["78336.04000000","0.74232000"],["78333.79000000","0.20207000"],["78333.02000000","0.00000000"],["78326.22000000","0.00024000"],["78325.81000000","0.20207000"],["78325.76000000","0.02515000"],["78307.74000000","0.00000000"],["78290.42000000","0.00318000"],["78279.27000000","0.00317000"],["78277.39000000","0.00179000"],["78266.02000000","2.29723000"],["78264.84000000","0.00000000"],["78212.01000000","0.00127000"],["78201.02000000","0.00127000"],["78198.82000000","0.00071000"],["78114.44000000","0.00000000"],["77179.59000000","0.00032000"],["70519.42000000","0.00256000"],["62683.93000000","0.00310000"]],"a":[["78354.92000000","6.16507000"],["78354.93000000","0.00069000"],["78354.94000000","0.00027000"],["78354.95000000","0.05014000"],["78354.99000000","0.00014000"],["78355.00000000","0.05014000"],["78355.98000000","0.00014000"],["78355.99000000","0.13105000"],["78356.00000000","0.30014000"],["78356.37000000","0.00007000"],["78356.38000000","0.06801000"],["78356.73000000","0.00500000"],["78356.74000000","0.00000000"],["78356.79000000","0.00014000"],["78356.90000000","0.00039000"],["78357.99000000","0.00638000"],["78358.00000000","0.03014000"],["78358.08000000","0.00601000"],["78358.16000000","0.00400000"],["78358.55000000","0.00000000"],["78358.69000000","0.00000000"],["78359.32000000","0.00638000"],["78359.33000000","0.01002000"],["78359.56000000","0.04005000"],["78360.00000000","0.03000000"],["78362.00000000","0.02000000"],["78365.98000000","0.00188000"],["78366.67000000","0.00000000"],["78371.69000000","0.00000000"],["79198.75000000","0.08671000"]]}}
{"rx":1788854504759705974, "m":{"e":"depthUpdate","E":1788854504714,"s":"BTCUSDT","U":99829832700,"u":99829832769,"b":[["78354.91000000","2.12017000"],["78354.90000000","0.00076000"],["78353.67000000","0.00021000"],["78353.66000000","0.06995000"],["78353.06000000","0.00014000"],["78353.05000000","0.16780000"],["78352.42000000","0.00014000"],["78352.41000000","0.02041000"],["78351.15000000","0.00000000"],["78349.23000000","0.00000000"],["78349.22000000","0.03014000"],["78348.54000000","0.00000000"],["78347.76000000","0.00000000"],["78347.64000000","0.00007000"],["78347.63000000","0.00000000"],["78345.43000000","0.03934000"],["78345.42000000","0.02014000"],["78345.33000000","0.00047000"],["78345.05000000","0.00000000"],["78307.74000000","0.00007000"],["77179.59000000","0.00032000"],["77179.58000000","0.00030000"],["62683.93000000","0.00310000"]],"a":[["78354.92000000","6.16699000"],["78356.38000000","0.06801000"],["78356.73000000","0.00514000"],["78356.79000000","0.00000000"],["78356.83000000","0.00400000"],["78356.91000000","0.10738000"],["78357.99000000","0.00652000"],["78358.00000000","0.03000000"],["78362.00000000","0.03000000"],["78365.98000000","0.00000000"],["78366.67000000","0.00007000"],["78486.62000000","0.00000000"],["79317.55000000","0.09929000"]]}}
{"rx":1788854504862024363, "m":{"e":"depthUpdate","E":1788854504814,"s":"BTCUSDT","U":99829832770,"u":99829832795,"b":[["78354.91000000","2.12031000"],["78353.66000000","0.07009000"],["78353.25000000","0.05990000"],["78347.06000000","0.00408000"],["78345.43000000","0.03920000"],["78345.42000000","0.02000000"],["78333.02000000","2.29723000"],["78320.46000000","0.51940000"],["78294.87000000","1.05581000"],["78266.02000000","0.00000000"],["77179.59000000","0.00040000"],["70519.42000000","0.00272000"],["62683.93000000","0.00279000"]],"a":[["78356.83000000","0.00000000"],["78357.73000000","0.00400000"],["78358.04000000","0.00000000"],["78496.08000000","0.01999000"],["78550.80000000","0.00012000"],["79436.53000000","0.11370000"]]}}
{"rx":1788854504952412629, "m":{"e":"depthUpdate","E":1788854504914,"s":"BTCUSDT","U":99829832796,"u":99829832901,"b":[["78354.91000000","1.71884000"],["78354.90000000","0.00069000"],["78353.67000000","0.00014000"],["78353.66000000","0.02289000"],["78353.06000000","0.00000000"],["78353.05000000","0.00000000"],["78352.42000000","0.00000000"],["78352.41000000","0.00014000"],["78351.15000000","0.00007000"],["78349.22000000","0.00014000"],["78348.05000000","0.00000000"],["78347.75000000","0.00000000"],["78347.62000000","0.00026000"],["78347.06000000","0.00008000"],["78345.94000000","0.00400000"],["78345.66000000","0.00000000"],["78345.43000000","0.00000000"],["78345.32000000","0.01000000"],["78345.31000000","0.00000000"],["78345.30000000","0.00000000"],["78343.65000000","0.00014000"],["78343.22000000","0.02000000"],["78340.63000000","0.00000000"],["78339.92000000","0.00000000"],["78339.22000000","0.00000000"],["78338.12000000","2.03759000"],["78338.11000000","0.00000000"],["78333.03000000","0.37581000"],["78333.02000000","0.00000000"],["78332.65000000","0.00000000"],["78324.84000000","1.50207000"],["78294.88000000","2.73928000"],["78264.84000000","2.29723000"],["78262.02000000","2.10064000"],["78198.82000000","0.07235000"],["78190.97000000","0.20250000"],["78133.05000000","0.00007000"],["78122.37000000","0.00802000"],["77179.59000000","0.00040000"],["72089.37000000","0.00000000"],["62684.00000000","0.00200000"]],"a":[["78354.92000000","6.16657000"],["78354.93000000","0.00027000"],["78354.94000000","0.00013000"],["78354.99000000","0.00000000"],["78355.23000000","0.00000000"],["78355.98000000","0.00000000"],["78355.99000000","0.13091000"],["78356.37000000","0.00000000"],["78357.99000000","0.00014000"],["78361.28000000","2.31723000"],["78361.83000000","0.00638000"],["78362.30000000","0.00179000"],["78366.18000000","0.37581000"],["78369.18000000","0.08000000"],["78369.33000000","0.27156000"],["78370.90000000","0.00000000"],["78392.76000000","0.79353000"],["78397.98000000","0.01563000"],["78419.99000000","0.02812000"],["78447.11000000","0.00000000"],["78453.00000000","0.07857000"],["78496.08000000","0.00000000"],["78537.93000000","0.01999000"],["79555.69000000","0.12796000"],["79675.03000000","0.14652000"]]}}
{"rx":1788854505056856978, "m":{"e":"depthUpdate","E":1788854505014,"s":"BTCUSDT","U":99829832902,"u":99829832965,"b":[["78354.91000000","1.89006000"],["78354.90000000","0.00069000"],["78353.25000000","0.05990000"],["78352.42000000","0.00014000"],["78352.41000000","0.01749000"],["78351.15000000","0.00000000"],["78351.14000000","0.01873000"],["78349.32000000","0.02000000"],["78349.22000000","0.00000000"],["78345.42000000","0.02014000"],["78345.14000000","0.00638000"],["78344.52000000","0.00400000"],["78343.22000000","0.00000000"],["78340.84000000","0.00000000"],["78340.81000000","0.02287000"],["78340.44000000","0.00000000"],["78340.12000000","0.02128000"],["78339.48000000","0.00000000"],["78333.04000000","2.29723000"],["78264.84000000","0.00000000"],["77963.14000000","0.00012000"],["77179.59000000","0.00040000"],["70519.42000000","0.00288000"],["62684.00000000","0.00000000"],["62683.93000000","0.00248000"]],"a":[["78354.92000000","6.16643000"],["78354.93000000","0.00069000"],["78356.37000000","0.00045000"],["78356.91000000","0.10738000"],["78357.99000000","0.00000000"],["78358.00000000","0.03014000"],["78367.58000000","0.00000000"],["78370.16000000","0.31917000"]]}}
{"rx":1788854505143718213, "m":{"e":"depthUpdate","E":1788854505114,"s":"BTCUSDT","U":99829832966,"u":99829832989,"b":[["78354.91000000","1.89020000"],["78354.90000000","0.00083000"],["78353.25000000","0.05990000"],["78352.41000000","0.06067000"],["78351.14000000","0.01859000"],["78350.93000000","0.15185000"],["77179.59000000","0.00032000"],["62684.00000000","0.00000000"]],"a":[["78354.92000000","6.16636000"],["78354.93000000","0.00062000"],["78379.00000000","0.70000000"],["78400.00000000","0.58258000"],["79530.25000000","0.00030000"],["79794.55000000","0.16779000"]]}}
{"rx":1788854505242068784, "m":{"e":"depthUpdate","E":1788854505214,"s":"BTCUSDT","U":99829832990,"u":99829833002,"b":[["78351.14000000","0.01873000"],["78345.42000000","0.02000000"],["78344.45000000","0.10724000"],["77179.59000000","0.00032000"],["70519.42000000","0.00304000"],["62683.93000000","0.00217000"]],"a":[["78356.94000000","0.00400000"],["78376.05000000","0.00200000"],["78398.04000000","0.00000000"],["78746.68000000","0.00012000"]]}}
{"rx":1788854505353134481, "m":{"e":"depthUpdate","E":1788854505314,"s":"BTCUSDT","U":99829833003,"u":99829833072,"b":[["78354.91000000","1.88953000"],["78350.93000000","0.00000000"],["78345.14000000","0.00000000"],["78344.33000000","0.00000000"],["78343.90000000","0.00638000"],["78341.87000000","0.00000000"],["78339.85000000","0.00000000"],["78339.12000000","0.01334000"],["78328.75000000","0.00000000"],["78315.00000000","0.71000000"],["78289.58000000","0.00000000"],["78258.25000000","0.00000000"],["77179.59000000","0.00032000"],["70519.42000000","0.00320000"],["70519.41000000","0.00009000"],["62684.00000000","0.00000000"]],"a":[["78354.92000000","6.16715000"],["78354.93000000","0.00027000"],["78356.37000000","0.00000000"],["78358.07000000","0.00638000"],["78361.83000000","0.00000000"],["78368.23000000","0.00000000"],["78407.42000000","0.00408000"]]}}
{"rx":1788854505446338432, "m":{"e":"depthUpdate","E":1788854505414,"s":"BTCUSDT","U":99829833073,"u":99829833116,"b":[["78354.91000000","1.88946000"],["78354.90000000","0.00076000"],["78352.41000000","0.01763000"],["78351.14000000","0.01873000"],["78346.94000000","0.00007000"],["78340.12000000","0.00000000"],["78339.98000000","0.02112000"],["78339.61000000","0.12764000"],["78339.46000000","0.00000000"],["78339.45000000","0.00000000"],["78339.12000000","0.00000000"],["77179.59000000","0.00032000"],["62683.93000000","0.00186000"]],"a":[["78354.92000000","6.16715000"],["78356.25000000","0.00000000"],["78358.00000000","0.03014000"],["78360.17000000","0.00000000"],["78362.76000000","0.20305000"],["78364.09000000","0.00000000"],["78370.60000000","0.00063000"],["78371.93000000","0.00000000"],["78378.44000000","0.00000000"],["78386.28000000","0.00000000"],["78450.05000000","0.01519000"],["78462.95000000","0.00000000"]]}}
{"rx":1788854505545165637, "m":{"e":"depthUpdate","E":1788854505514,"s":"BTCUSDT","U":99829833117,"u":99829833174,"b":[["78341.61000000","0.00000000"],["78339.63000000","0.01306000"],["78339.18000000","0.00000000"],["78331.91000000","0.12766000"],["78320.46000000","0.00000000"],["78294.88000000","2.03759000"],["78294.87000000","0.00000000"],["77179.59000000","0.00032000"],["70519.42000000","0.00336000"],["70519.00000000","0.00000000"],["62683.93000000","0.00310000"]],"a":[["78354.92000000","6.16757000"],["78354.93000000","0.00069000"],["78386.00000000","0.03000000"],["78411.62000000","0.00000000"],["78441.71000000","0.00007000"],["79914.25000000","0.19214000"]]}}
{"rx":1788854505648647038, "m":{"e":"depthUpdate","E":1788854505614,"s":"BTCUSDT","U":99829833175,"u":99829833191,"b":[["78354.91000000","1.88953000"],["78352.41000000","0.06540000"],["78348.97000000","0.16754000"],["78341.18000000","0.00000000"],["78339.98000000","0.00000000"],["78339.63000000","0.00000000"],["78339.13000000","0.00000000"],["77179.59000000","0.00032000"],["62684.00000000","0.00000000"],["62683.93000000","0.00279000"]],"a":[["80034.13000000","0.22011000"]]}}
{"rx":1788854505747931983, "m":{"e":"depthUpdate","E":1788854505714,"s":"BTCUSDT","U":99829833192,"u":99829833237,"b":[["78354.91000000","1.71545000"],["78343.90000000","0.00000000"],["78342.53000000","0.00638000"],["78341.62000000","0.00000000"],["78340.22000000","0.00000000"],["78339.92000000","0.02151000"],["78339.27000000","0.01327000"],["78339.12000000","0.00000000"],["78333.04000000","0.00000000"],["78264.84000000","2.29723000"],["78222.00000000","0.13244000"],["77179.59000000","0.00032000"],["77179.58000000","0.00030000"],["70519.42000000","0.00352000"],["62683.93000000","0.00279000"]],"a":[["78354.92000000","6.17368000"],["78354.93000000","0.00027000"],["78356.73000000","0.00014000"],["78363.27000000","0.00000000"],["78366.67000000","0.00007000"]]}}
{"rx":1788854505852084564, "m":{"e":"depthUpdate","E":1788854505814,"s":"BTCUSDT","U":99829833238,"u":99829833751,"b":[["78354.91000000","0.00000000"],["78354.90000000","0.00000000"],["78354.89000000","0.00000000"],["78353.67000000","0.00000000"],["78353.66000000","0.00000000"],["78353.65000000","0.04366000"],["78353.64000000","0.00035000"],["78353.26000000","0.00000000"],["78353.25000000","0.00014000"],["78352.42000000","0.00000000"],["78352.41000000","0.00028000"],["78351.99000000","0.00014000"],["78351.98000000","0.05976000"],["78351.15000000","0.00014000"],["78349.33000000","0.00000000"],["78349.32000000","0.00014000"],["78348.97000000","0.00014000"],["78347.62000000","0.00000000"],["78346.92000000","0.00000000"],["78346.23000000","0.00000000"],["78345.94000000","0.00000000"],["78345.80000000","0.00000000"],["78345.43000000","0.00014000"],["78345.42000000","0.02014000"],["78345.32000000","0.00014000"],["78344.52000000","0.00000000"],["78344.45000000","0.00000000"],["78344.21000000","0.00000000"],["78344.01000000","0.00007000"],["78344.00000000","0.27978000"],["78343.65000000","0.00007000"],["78343.47000000","0.00000000"],["78343.20000000","0.00000000"],["78343.02000000","0.03000000"],["78342.92000000","0.00000000"],["78342.53000000","0.00000000"],["78341.27000000","0.00000000"],["78341.26000000","0.00000000"],["78341.21000000","0.00000000"],["78340.82000000","0.00000000"],["78340.81000000","0.00000000"],["78340.80000000","0.00000000"],["78340.79000000","0.36013000"],["78340.62000000","0.40904000"],["78340.49000000","0.00000000"],["78340.00000000","0.00000000"],["78339.92000000","0.00000000"],["78339.66000000","0.00007000"],["78339.61000000","0.00000000"],["78339.39000000","0.00000000"],["78339.35000000","0.41262000"],["78339.27000000","0.00000000"],["78338.94000000","0.00400000"],["78338.27000000","0.00400000"],["78338.12000000","0.00000000"],["78337.31000000","0.00000000"],["78337.18000000","0.00638000"],["78337.08000000","0.00000000"],["78336.96000000","0.00000000"],["78336.91000000","0.00000000"],["78336.72000000","0.00000000"],["78336.41000000","0.00007000"],["78336.04000000","0.11248000"],["78335.67000000","0.00007000"],["78335.66000000","0.12765000"],["78335.01000000","0.00000000"],["78334.98000000","0.00000000"],["78334.22000000","0.00000000"],["78334.21000000","0.12000000"],["78333.79000000","0.00000000"],["78333.04000000","0.00400000"],["78333.03000000","0.00000000"],["78333.01000000","0.00000000"],["78332.99000000","0.01277000"],["78331.91000000","0.00000000"],["78331.68000000","0.00014000"],["78330.43000000","0.00000000"],["78330.01000000","0.62839000"],["78329.07000000","0.01290000"],["78328.80000000","0.00063000"],["78328.78000000","0.00000000"],["78327.52000000","0.02287000"],["78326.23000000","0.20333000"],["78326.22000000","0.00000000"],["78326.14000000","0.00158000"],["78325.81000000","0.00000000"],["78325.76000000","0.00000000"],["78325.15000000","0.01315000"],["78324.84000000","2.29723000"],["78324.83000000","2.03759000"],["78322.30000000","0.00000000"],["78321.23000000","0.01692000"],["78319.82000000","0.52612000"],["78318.22000000","0.20333000"],["78316.40000000","0.00024000"],["78316.31000000","0.32676000"],["78315.72000000","0.63457000"],["78315.00000000","0.70000000"],["78314.16000000","0.00000000"],["78314.00000000","0.04000000"],["78313.78000000","0.00000000"],["78312.61000000","0.03828000"],["78306.32000000","0.00000000"],["78303.75000000","0.00007000"],["78300.03000000","0.00426000"],["78299.76000000","0.00007000"],["78297.32000000","0.00400000"],["78294.23000000","1.06798000"],["78294.07000000","0.34495000"],["78282.89000000","0.34500000"],["78275.43000000","1.26513000"],["78252.30000000","0.00000000"],["78207.15000000","0.17410000"],["78204.97000000","0.00000000"],["78201.57000000","1.53184000"],["78201.02000000","0.00127000"],["78113.15000000","0.00007000"],["78109.24000000","0.00007000"],["78038.93000000","0.00000000"],["78027.37000000","0.00031000"],["77179.59000000","0.00000000"],["77179.58000000","0.00000000"],["77178.35000000","0.00008000"],["70519.42000000","0.00000000"],["70519.41000000","0.00000000"],["70519.40000000","0.00009000"],["70518.29000000","0.00016000"],["62683.93000000","0.00248000"]],"a":[["78353.66000000","9.83093000"],["78353.67000000","3.79277000"],["78353.68000000","2.66614000"],["78353.70000000","0.05000000"],["78353.75000000","0.05000000"],["78353.88000000","0.04005000"],["78354.58000000","0.00000000"],["78354.81000000","0.00000000"],["78354.91000000","0.35095000"],["78354.92000000","0.15388000"],["78354.93000000","0.00000000"],["78354.94000000","0.00000000"],["78354.95000000","0.00014000"],["78355.00000000","0.00014000"],["78355.13000000","0.06787000"],["78355.99000000","0.00014000"],["78356.37000000","0.00000000"],["78356.38000000","0.00014000"],["78356.47000000","0.03057000"],["78356.73000000","0.00000000"],["78356.90000000","0.00000000"],["78356.91000000","0.00014000"],["78357.73000000","0.00000000"],["78357.99000000","0.07887000"],["78358.00000000","0.03000000"],["78358.07000000","0.00000000"],["78358.16000000","0.00000000"],["78358.18000000","0.01000000"],["78358.63000000","0.12761000"],["78359.32000000","0.00000000"],["78359.56000000","0.00000000"],["78360.37000000","0.01200000"],["78361.26000000","0.31918000"],["78362.31000000","2.05483000"],["78362.57000000","0.00000000"],["78364.41000000","0.09550000"],["78366.20000000","2.29723000"],["78366.37000000","0.10265000"],["78366.48000000","0.04000000"],["78366.96000000","0.00063000"],["78370.16000000","0.00000000"],["78370.52000000","0.00000000"],["78370.60000000","0.00008000"],["78378.01000000","0.00000000"],["78378.05000000","0.34458000"],["78379.98000000","0.34457000"],["78380.33000000","0.52800000"],["78385.03000000","1.26336000"],["78385.12000000","0.00000000"],["78386.27000000","0.00000000"],["78392.76000000","0.47751000"],["78393.00000000","0.01000000"],["78394.88000000","0.00400000"],["78395.00000000","0.00000000"],["78395.06000000","0.00000000"],["78395.20000000","0.00000000"],["78397.46000000","0.00000000"],["78402.50000000","0.00000000"],["78405.94000000","1.03887000"],["78406.56000000","0.00000000"],["78408.98000000","0.77684000"],["78423.04000000","0.00317000"],["78423.05000000","0.00000000"],["78432.44000000","0.00000000"],["78432.45000000","0.00000000"],["78502.93000000","0.00000000"],["78607.52000000","0.00026000"],["78619.16000000","0.00000000"],["79530.25000000","0.00000000"]]}}
{"rx":1788854505938085936, "m":{"e":"depthUpdate","E":1788854505914,"s":"BTCUSDT","U":99829833752,"u":99829833891,"b":[["78353.65000000","0.02789000"],["78353.64000000","0.00021000"],["78353.25000000","0.00000000"],["78352.41000000","0.00000000"],["78352.40000000","0.00014000"],["78351.98000000","0.05990000"],["78351.15000000","0.00000000"],["78351.14000000","0.00014000"],["78349.32000000","0.00000000"],["78348.97000000","0.00000000"],["78347.48000000","0.00026000"],["78345.50000000","0.00000000"],["78345.42000000","0.02014000"],["78345.32000000","0.00000000"],["78344.01000000","0.00014000"],["78344.00000000","0.46971000"],["78343.03000000","0.00014000"],["78343.02000000","0.03014000"],["78340.92000000","0.00007000"],["78340.91000000","0.49083000"],["78340.80000000","0.00007000"],["78340.79000000","0.36027000"],["78340.77000000","0.31935000"],["78340.60000000","0.00000000"],["78336.15000000","0.00069000"],["78335.89000000","0.00000000"],["78335.67000000","0.00014000"],["78333.79000000","0.00800000"],["78332.99000000","0.00000000"],["78332.40000000","0.00000000"],["78332.24000000","0.01282000"],["78329.30000000","0.00000000"],["78324.85000000","1.05756000"],["78316.10000000","0.00059000"],["78315.00000000","0.00000000"],["78294.89000000","1.41651000"],["78291.90000000","0.00283000"],["78274.01000000","0.39540000"],["78201.58000000","0.50510000"],["78201.01000000","0.00000000"],["78113.15000000","0.00000000"],["78109.24000000","0.00000000"],["77178.35000000","0.00016000"]],"a":[["78353.66000000","9.83761000"],["78353.67000000","3.79277000"],["78353.68000000","2.66628000"],["78353.70000000","0.05014000"],["78353.75000000","0.05014000"],["78353.88000000","0.04019000"],["78354.91000000","0.14859000"],["78354.92000000","0.15331000"],["78354.95000000","0.00000000"],["78355.00000000","0.00000000"],["78355.13000000","0.06801000"],["78355.59000000","0.00008000"],["78355.99000000","0.00000000"],["78356.00000000","0.30000000"],["78356.38000000","0.00000000"],["78356.91000000","0.00000000"],["78356.93000000","0.00800000"],["78358.08000000","0.00000000"],["78359.33000000","0.00000000"],["78360.58000000","0.00000000"],["78361.84000000","0.00000000"],["78362.76000000","0.20250000"],["78368.76000000","0.03400000"],["78378.04000000","0.31317000"],["78378.43000000","0.00000000"],["78386.43000000","0.00430000"],["78387.69000000","0.02529000"],["78390.51000000","0.00434000"],["78390.54000000","0.00430000"],["78392.57000000","0.00000000"],["78401.01000000","0.00000000"],["78405.93000000","0.32863000"],["78433.92000000","0.92283000"],["83612.96000000","0.00000000"]]}}
{"rx":1788854506038221878, "m":{"e":"depthUpdate","E":1788854506014,"s":"BTCUSDT","U":99829833892,"u":99829834016,"b":[["78353.65000000","0.02817000"],["78353.64000000","0.00941000"],["78352.40000000","0.00014000"],["78352.39000000","0.01487000"],["78352.11000000","0.00007000"],["78351.99000000","0.00000000"],["78351.98000000","0.00014000"],["78351.27000000","0.00014000"],["78351.26000000","0.05976000"],["78351.15000000","0.00014000"],["78351.14000000","0.01785000"],["78349.89000000","0.00014000"],["78349.88000000","0.01785000"],["78345.43000000","0.00000000"],["78345.42000000","0.00014000"],["78345.33000000","0.00000000"],["78344.01000000","0.00007000"],["78344.00000000","0.27992000"],["78343.03000000","0.00000000"],["78343.02000000","0.03014000"],["78342.52000000","0.00000000"],["78342.31000000","0.02000000"],["78341.86000000","0.12792000"],["78340.92000000","0.00000000"],["78340.91000000","0.00014000"],["78340.80000000","0.00000000"],["78340.62000000","0.40918000"],["78340.50000000","0.00400000"],["78340.33000000","0.00000000"],["78340.14000000","0.00000000"],["78339.57000000","0.00026000"],["78339.55000000","0.00000000"],["78339.38000000","0.00000000"],["78338.94000000","0.00000000"],["78337.17000000","0.00000000"],["78336.38000000","0.00000000"],["78335.97000000","0.00000000"],["78335.72000000","0.00000000"],["78335.59000000","0.00000000"],["78335.55000000","0.00000000"],["78334.70000000","0.00400000"],["78333.79000000","0.00800000"],["78333.04000000","0.00000000"],["78332.24000000","0.00000000"],["78331.80000000","0.00000000"],["78331.59000000","0.00000000"],["78331.35000000","0.00000000"],["78331.16000000","0.00000000"],["78327.09000000","0.00000000"],["78313.74000000","0.00193000"],["78298.06000000","0.00000000"],["78201.58000000","0.00000000"],["78201.57000000","0.00000000"],["77178.35000000","0.00024000"],["70518.29000000","0.00032000"],["62683.93000000","0.00217000"],["62682.92000000","0.00124000"]],"a":[["78356.24000000","0.00638000"],["78356.80000000","0.00000000"],["78356.93000000","0.00000000"],["78357.50000000","0.01064000"],["78358.75000000","0.01277000"],["78360.01000000","0.01277000"],["78363.89000000","0.04200000"],["78363.93000000","0.03400000"],["78364.70000000","0.03800000"],["78367.81000000","0.02600000"],["78373.46000000","0.00000000"],["78384.53000000","0.00620000"],["78394.58000000","0.00000000"]]}}
{"rx":1788854506137444425, "m":{"e":"depthUpdate","E":1788854506114,"s":"BTCUSDT","U":99829834017,"u":99829834079,"b":[["78353.65000000","0.02817000"],["78353.64000000","0.00955000"],["78352.39000000","0.01501000"],["78351.98000000","0.00000000"],["78351.26000000","0.05990000"],["78351.14000000","0.01799000"],["78349.88000000","0.01799000"],["78345.42000000","0.00000000"],["78343.02000000","0.03014000"],["78342.31000000","0.00014000"],["78341.86000000","0.00000000"],["78340.91000000","0.00000000"],["78340.79000000","0.36013000"],["78340.77000000","0.31921000"],["78340.62000000","0.40904000"],["78338.71000000","0.02000000"],["78335.95000000","0.00048000"],["78332.90000000","0.00048000"],["78331.62000000","0.00000000"],["78331.27000000","0.00000000"],["78327.92000000","0.00000000"],["78314.65000000","0.00012000"],["78308.86000000","0.00000000"],["78300.01000000","0.00335000"],["78286.55000000","0.00435000"],["78201.44000000","0.00000000"],["78201.36000000","1.53184000"],["77649.72000000","0.00000000"]],"a":[["78354.92000000","0.15321000"],["78357.49000000","0.00800000"],["78368.36000000","0.01200000"],["78369.33000000","0.00000000"],["78372.05000000","0.63817000"],["78372.69000000","0.00000000"],["78377.47000000","0.00000000"],["78680.68000000","0.00000000"],["79528.97000000","0.00030000"]]}}
{"rx":1788854506248708233, "m":{"e":"depthUpdate","E":1788854506214,"s":"BTCUSDT","U":99829834080,"u":99829835045,"b":[["78353.65000000","0.00000000"],["78353.64000000","0.00000000"],["78352.89000000","0.00000000"],["78352.40000000","0.00000000"],["78352.39000000","0.00000000"],["78352.18000000","0.00000000"],["78352.11000000","0.00000000"],["78351.63000000","0.00000000"],["78351.27000000","0.00000000"],["78351.26000000","0.00000000"],["78351.15000000","0.00000000"],["78351.14000000","0.00000000"],["78349.89000000","0.00000000"],["78349.88000000","0.00000000"],["78349.87000000","0.00000000"],["78349.04000000","0.00000000"],["78347.99000000","0.00000000"],["78347.70000000","0.00000000"],["78347.64000000","0.00000000"],["78347.48000000","0.00000000"],["78347.06000000","0.00000000"],["78346.94000000","0.00000000"],["78346.70000000","0.00000000"],["78345.13000000","0.00000000"],["78345.05000000","0.00000000"],["78344.18000000","0.00000000"],["78344.01000000","0.00000000"],["78344.00000000","0.21549000"],["78343.99000000","0.00042000"],["78343.89000000","0.00000000"],["78343.03000000","0.00000000"],["78343.02000000","0.00014000"],["78342.31000000","0.00000000"],["78342.05000000","0.00000000"],["78342.00000000","0.00000000"],["78340.83000000","0.00000000"],["78340.81000000","0.00000000"],["78340.80000000","0.00000000"],["78340.79000000","0.00021000"],["78340.78000000","0.00000000"],["78340.77000000","0.00014000"],["78340.63000000","0.00014000"],["78340.62000000","0.19776000"],["78340.61000000","0.00000000"],["78340.50000000","0.00000000"],["78340.05000000","0.00000000"],["78339.36000000","0.00000000"],["78339.35000000","0.00014000"],["78339.32000000","0.00014000"],["78339.31000000","0.03000000"],["78338.71000000","0.00014000"],["78338.27000000","0.00000000"],["78338.10000000","0.00014000"],["78338.09000000","0.65602000"],["78338.00000000","0.00000000"],["78337.86000000","0.00000000"],["78337.18000000","0.00014000"],["78336.51000000","0.00000000"],["78336.17000000","0.00008000"],["78336.05000000","0.00014000"],["78336.04000000","0.04891000"],["78335.95000000","0.00000000"],["78335.67000000","0.00007000"],["78335.66000000","0.00000000"],["78335.01000000","0.02000000"],["78334.73000000","0.00000000"],["78334.70000000","0.00000000"],["78334.63000000","0.00000000"],["78334.22000000","0.48988000"],["78333.79000000","0.00000000"],["78333.77000000","0.00400000"],["78333.08000000","0.46757000"],["78332.59000000","0.00000000"],["78332.18000000","0.47517000"],["78332.17000000","0.48975000"],["78331.93000000","0.00000000"],["78331.80000000","0.00400000"],["78331.72000000","0.47434000"],["78331.71000000","0.00000000"],["78331.70000000","0.31924000"],["78331.68000000","0.00014000"],["78331.19000000","0.00000000"],["78331.04000000","0.00000000"],["78330.34000000","0.00000000"],["78330.21000000","0.00000000"],["78330.02000000","0.00638000"],["78330.01000000","0.00000000"],["78329.47000000","0.00048000"],["78329.08000000","1.92254000"],["78329.07000000","0.00000000"],["78329.06000000","0.00000000"],["78328.67000000","0.00000000"],["78328.33000000","0.00008000"],["78327.68000000","0.06552000"],["78327.67000000","0.02000000"],["78327.59000000","0.00191000"],["78327.10000000","0.00000000"],["78326.78000000","0.12767000"],["78326.23000000","0.00000000"],["78324.86000000","0.37581000"],["78324.85000000","0.00000000"],["78324.84000000","0.00000000"],["78324.76000000","0.00000000"],["78324.44000000","0.00000000"],["78324.41000000","0.00008000"],["78323.19000000","0.26571000"],["78323.02000000","0.09555000"],["78321.06000000","0.10271000"],["78320.84000000","0.00000000"],["78320.50000000","0.00008000"],["78318.86000000","0.00000000"],["78316.92000000","0.00000000"],["78316.58000000","0.00008000"],["78315.72000000","0.00014000"],["78314.96000000","0.00000000"],["78314.00000000","0.03000000"],["78313.39000000","0.66486000"],["78313.00000000","0.00000000"],["78312.66000000","0.00008000"],["78311.73000000","0.00085000"],["78311.16000000","0.00000000"],["78310.00000000","0.03000000"],["78308.75000000","0.00008000"],["78307.74000000","0.00014000"],["78304.83000000","0.00008000"],["78304.60000000","0.23192000"],["78304.00000000","0.04207000"],["78302.78000000","0.00000000"],["78301.96000000","0.00000000"],["78301.42000000","0.00000000"],["78300.01000000","0.00000000"],["78299.33000000","0.63876000"],["78297.42000000","0.00000000"],["78296.24000000","0.00000000"],["78295.77000000","0.00007000"],["78291.52000000","0.00000000"],["78290.42000000","0.00000000"],["78287.45000000","0.34498000"],["78287.04000000","0.00310000"],["78282.26000000","0.00634000"],["78280.63000000","0.20000000"],["78279.64000000","0.00318000"],["78279.63000000","0.02000000"],["78279.27000000","0.00000000"],["78277.39000000","0.00000000"],["78275.59000000","0.01144000"],["78274.52000000","0.00318000"],["78272.80000000","0.02000000"],["78266.02000000","0.00179000"],["78258.38000000","0.00000000"],["78255.66000000","0.00000000"],["78252.30000000","2.29727000"],["78250.45000000","0.00000000"],["78249.38000000","0.00000000"],["78227.13000000","0.01852000"],["78227.12000000","0.00000000"],["78201.36000000","0.00000000"],["78199.77000000","0.00000000"],["78198.82000000","0.07164000"],["78188.28000000","0.00072000"],["78183.13000000","0.20250000"],["78183.04000000","1.53184000"],["78141.97000000","3.84029000"],["78112.97000000","0.00007000"],["78109.06000000","0.00007000"],["77178.35000000","0.00000000"],["70519.40000000","0.00000000"],["70518.29000000","0.00000000"],["70509.60000000","0.00016000"],["62683.93000000","0.00186000"]],"a":[["78344.01000000","8.43369000"],["78344.02000000","0.00027000"],["78344.03000000","0.00013000"],["78344.09000000","0.03542000"],["78344.10000000","0.05000000"],["78344.92000000","0.00000000"],["78345.14000000","0.00000000"],["78345.45000000","0.06852000"],["78345.83000000","0.00000000"],["78346.54000000","0.00662000"],["78346.55000000","0.00000000"],["78346.71000000","0.00000000"],["78346.74000000","0.00000000"],["78347.49000000","0.00000000"],["78347.64000000","0.00014000"],["78347.65000000","0.00000000"],["78347.71000000","0.00000000"],["78348.00000000","0.00000000"],["78348.56000000","0.00000000"],["78349.05000000","0.00000000"],["78349.09000000","0.12763000"],["78349.47000000","0.00000000"],["78349.74000000","0.00026000"],["78349.88000000","0.46635000"],["78349.89000000","3.06167000"],["78349.90000000","0.52307000"],["78349.91000000","0.00000000"],["78349.94000000","0.00000000"],["78350.06000000","0.00187000"],["78350.21000000","0.00000000"],["78350.22000000","0.00014000"],["78350.31000000","0.00000000"],["78350.40000000","0.00400000"],["78350.42000000","0.03363000"],["78350.43000000","0.00014000"],["78350.50000000","0.05000000"],["78350.59000000","0.00000000"],["78350.87000000","0.00000000"],["78351.13000000","0.00000000"],["78351.15000000","0.00000000"],["78351.27000000","0.00000000"],["78351.28000000","0.10000000"],["78351.34000000","0.00000000"],["78351.43000000","0.00000000"],["78351.63000000","0.00014000"],["78351.64000000","0.20264000"],["78351.71000000","0.00000000"],["78351.84000000","0.00008000"],["78351.99000000","0.00000000"],["78352.12000000","0.00000000"],["78352.19000000","0.00000000"],["78352.27000000","0.00000000"],["78352.40000000","0.41262000"],["78352.41000000","0.00000000"],["78352.55000000","0.00000000"],["78352.64000000","0.00000000"],["78352.90000000","0.36239000"],["78352.92000000","0.00000000"],["78353.01000000","0.00000000"],["78353.08000000","0.00000000"],["78353.09000000","0.00007000"],["78353.10000000","0.00000000"],["78353.13000000","0.00007000"],["78353.29000000","0.00000000"],["78353.38000000","0.00000000"],["78353.63000000","0.00000000"],["78353.65000000","1.68014000"],["78353.66000000","1.19333000"],["78353.67000000","0.00014000"],["78353.68000000","2.29020000"],["78353.70000000","0.00000000"],["78353.75000000","0.00000000"],["78353.79000000","0.00007000"],["78353.88000000","0.04005000"],["78354.31000000","0.02000000"],["78354.55000000","0.00010000"],["78354.91000000","0.14845000"],["78354.92000000","0.15307000"],["78355.13000000","0.00000000"],["78355.61000000","0.00000000"],["78355.90000000","0.00008000"],["78355.93000000","0.00000000"],["78356.23000000","0.00000000"],["78356.26000000","0.00007000"],["78356.34000000","0.09551000"],["78357.49000000","0.00000000"],["78357.70000000","0.00007000"],["78358.27000000","0.00000000"],["78358.30000000","0.10266000"],["78359.39000000","0.00007000"],["78359.68000000","0.00015000"],["78359.74000000","0.03000000"],["78360.14000000","0.00574000"],["78360.37000000","0.00000000"],["78360.70000000","0.02800000"],["78360.79000000","0.00000000"],["78361.28000000","2.29723000"],["78362.31000000","2.03483000"],["78362.50000000","0.63824000"],["78362.52000000","0.00000000"],["78362.75000000","0.00000000"],["78363.60000000","0.00022000"],["78364.41000000","0.00000000"],["78365.65000000","0.00000000"],["78366.37000000","0.00000000"],["78367.51000000","0.00008000"],["78367.86000000","0.00000000"],["78368.78000000","0.00000000"],["78369.18000000","0.00000000"],["78369.58000000","0.00255000"],["78370.17000000","0.00000000"],["78371.43000000","0.00008000"],["78371.78000000","0.00000000"],["78372.26000000","0.00000000"],["78372.65000000","0.00000000"],["78373.43000000","0.00000000"],["78374.27000000","0.63395000"],["78374.57000000","0.00000000"],["78375.35000000","0.00008000"],["78375.46000000","1.26352000"],["78375.70000000","0.00000000"],["78376.14000000","0.00000000"],["78376.57000000","0.00000000"],["78377.12000000","0.34458000"],["78377.56000000","0.00000000"],["78379.26000000","0.00016000"],["78379.61000000","0.00000000"],["78383.18000000","0.00008000"],["78383.53000000","0.00000000"],["78383.55000000","0.00000000"],["78385.03000000","0.00000000"],["78387.45000000","0.00000000"],["78387.54000000","0.00000000"],["78387.59000000","0.77706000"],["78388.35000000","0.00000000"],["78391.37000000","0.00000000"],["78391.53000000","0.00000000"],["78394.74000000","0.00000000"],["78394.88000000","0.00000000"],["78401.67000000","0.00000000"],["78401.94000000","0.00000000"],["78402.53000000","0.00000000"],["78404.90000000","0.00000000"],["78405.72000000","0.00000000"],["78407.86000000","0.00000000"],["78415.14000000","0.00000000"],["78415.15000000","2.42405000"],["78441.71000000","0.00000000"],["78477.99000000","0.48108000"],["78480.69000000","1.53184000"],["78483.29000000","0.00000000"],["78491.15000000","0.00000000"],["78493.99000000","0.01907000"],["78496.42000000","0.00000000"],["78761.85000000","0.00011000"],["78777.55000000","0.00000000"],["81622.54000000","0.00007000"]]}}
{"rx":1788854506344775258, "m":{"e":"depthUpdate","E":1788854506314,"s":"BTCUSDT","U":99829835046,"u":99829835204,"b":[["78344.00000000","0.21591000"],["78343.99000000","0.00070000"],["78343.02000000","0.00000000"],["78341.66000000","0.00654000"],["78340.79000000","0.00007000"],["78340.77000000","0.00000000"],["78340.62000000","0.19776000"],["78340.40000000","0.01091000"],["78339.35000000","0.00000000"],["78339.31000000","0.03014000"],["78339.15000000","0.01309000"],["78339.10000000","0.00014000"],["78339.09000000","0.12533000"],["78338.71000000","0.00000000"],["78338.09000000","0.65595000"],["78337.89000000","0.01309000"],["78337.18000000","0.00000000"],["78336.52000000","0.00588000"],["78336.05000000","0.00000000"],["78336.04000000","0.02637000"],["78335.01000000","0.02014000"],["78334.69000000","0.02014000"],["78334.23000000","0.00000000"],["78334.22000000","0.00014000"],["78334.21000000","0.04000000"],["78333.08000000","0.00000000"],["78332.52000000","0.00007000"],["78332.51000000","0.08000000"],["78332.18000000","0.98844000"],["78332.17000000","0.00000000"],["78331.72000000","0.00000000"],["78331.30000000","0.10724000"],["78329.68000000","0.00000000"],["78329.08000000","1.92654000"],["78328.48000000","0.00000000"],["78318.22000000","0.00000000"],["78314.66000000","0.31922000"],["78122.37000000","0.00000000"],["78114.79000000","0.00802000"],["78109.06000000","0.00000000"],["77168.84000000","0.00008000"]],"a":[["78344.01000000","8.43808000"],["78344.04000000","0.05368000"],["78344.05000000","0.05000000"],["78344.09000000","0.00014000"],["78344.10000000","0.05014000"],["78344.87000000","0.00400000"],["78345.45000000","0.06866000"],["78346.54000000","0.00676000"],["78349.08000000","0.00400000"],["78349.09000000","0.12777000"],["78349.87000000","0.02000000"],["78349.88000000","0.46649000"],["78349.89000000","2.85917000"],["78349.90000000","0.52293000"],["78350.22000000","0.00000000"],["78350.43000000","0.00000000"],["78350.50000000","0.00000000"],["78351.64000000","0.00000000"],["78351.85000000","0.00055000"],["78353.09000000","0.00000000"],["78353.65000000","1.47764000"],["78353.66000000","0.99069000"],["78353.67000000","0.00000000"],["78354.92000000","0.15294000"],["78356.24000000","0.00000000"],["78357.50000000","0.00000000"],["78358.75000000","0.00000000"],["78359.68000000","0.00070000"],["78360.01000000","0.00000000"],["78367.52000000","0.00055000"],["78375.35000000","0.00063000"],["78384.00000000","0.04000000"],["78390.00000000","0.03400000"],["78391.03000000","0.20000000"],["78393.00000000","0.00000000"],["78393.99000000","0.00319000"],["78472.92000000","0.00127000"],["78563.54000000","0.00000000"],["78565.73000000","0.00000000"],["78569.64000000","0.00000000"],["78571.93000000","0.00000000"]]}}
{"rx":1788854506440580982, "m":{"e":"depthUpdate","E":1788854506414,"s":"BTCUSDT","U":99829835205,"u":99829835277,"b":[["78344.00000000","0.24081000"],["78341.66000000","0.00668000"],["78340.62000000","0.19776000"],["78340.40000000","0.01105000"],["78339.31000000","0.03014000"],["78339.15000000","0.01323000"],["78339.09000000","0.12547000"],["78338.09000000","0.65595000"],["78337.89000000","0.01323000"],["78336.52000000","0.00574000"],["78336.04000000","0.02623000"],["78335.01000000","0.02000000"],["78334.69000000","0.02000000"],["78334.22000000","0.00000000"],["78332.19000000","0.48981000"],["78323.68000000","0.02000000"],["78307.91000000","0.00689000"],["78261.45000000","0.02000000"],["78162.38000000","0.00000000"],["77168.84000000","0.00016000"],["70509.60000000","0.00032000"],["62683.93000000","0.00155000"]],"a":[["78344.01000000","8.44711000"],["78344.04000000","0.05382000"],["78344.05000000","0.05014000"],["78344.09000000","0.00000000"],["78345.27000000","0.01461000"],["78346.52000000","0.01753000"],["78347.78000000","0.01753000"],["78349.09000000","0.12763000"],["78349.89000000","2.85903000"],["78357.39000000","0.03400000"],["78359.15000000","0.00007000"],["78361.16000000","0.03800000"],["78361.35000000","0.03200000"],["78405.93000000","0.00000000"],["78405.94000000","0.00000000"]]}}
{"rx":1788854506543158606, "m":{"e":"depthUpdate","E":1788854506514,"s":"BTCUSDT","U":99829835278,"u":99829835346,"b":[["78344.00000000","0.24231000"],["78343.99000000","0.00070000"],["78342.76000000","0.00000000"],["78340.80000000","0.00007000"],["78340.34000000","0.00014000"],["78340.33000000","0.15530000"],["78339.10000000","0.00000000"],["78339.09000000","0.00014000"],["78336.05000000","0.00007000"],["78336.04000000","0.16894000"],["78333.09000000","0.00007000"],["78333.08000000","0.48981000"],["78332.52000000","0.00000000"],["78332.20000000","0.00800000"],["78332.19000000","0.00000000"],["78329.08000000","1.91854000"],["78325.12000000","0.00007000"],["78324.09000000","0.02000000"],["78304.83000000","0.88509000"],["78296.41000000","0.00335000"],["78263.08000000","0.00000000"],["78215.71000000","0.00000000"],["78207.54000000","0.00009000"],["78125.05000000","0.01999000"],["77292.28000000","0.00000000"],["77168.84000000","0.00024000"],["70509.60000000","0.00048000"]],"a":[["78344.10000000","0.05014000"],["78345.27000000","0.01475000"],["78345.45000000","0.06866000"],["78346.52000000","0.01767000"],["78346.54000000","0.00662000"],["78349.88000000","1.11493000"],["78356.10000000","0.00007000"],["78360.96000000","0.02600000"],["78372.15000000","0.00000000"],["78378.03000000","0.00000000"],["78398.24000000","0.88395000"],["78414.96000000","0.00000000"],["78416.22000000","0.00000000"],["78426.20000000","0.00000000"],["78459.50000000","0.00000000"],["78464.60000000","0.00000000"],["78469.56000000","0.00000000"],["82921.18000000","0.00000000"]]}}
{"rx":1788854506643058004, "m":{"e":"depthUpdate","E":1788854506614,"s":"BTCUSDT","U":99829835347,"u":99829835411,"b":[["78344.00000000","0.03584000"],["78343.99000000","0.00063000"],["78342.13000000","0.00000000"],["78340.40000000","0.01105000"],["78340.34000000","0.00000000"],["78340.33000000","0.00000000"],["78339.15000000","0.01309000"],["78339.09000000","0.00000000"],["78336.05000000","0.00014000"],["78332.20000000","0.00000000"],["78329.24000000","0.02130000"],["78329.09000000","0.00800000"],["78324.50000000","0.02000000"],["78323.74000000","0.02000000"],["78319.95000000","0.12768000"],["78310.02000000","0.00000000"],["78270.79000000","0.02000000"],["78261.59000000","0.02000000"],["78250.40000000","1.00149000"],["77168.84000000","0.00032000"],["62683.93000000","0.00124000"]],"a":[["78344.01000000","8.44090000"],["78345.04000000","0.00007000"],["78346.51000000","0.00638000"],["78346.54000000","0.00652000"],["78347.78000000","0.01767000"],["78349.89000000","2.88060000"],["78356.00000000","0.30000000"],["78356.02000000","0.00000000"],["78357.73000000","0.02150000"],["78360.36000000","0.04000000"],["78361.18000000","0.03200000"],["78365.57000000","0.02079000"],["78373.41000000","0.02144000"],["78375.83000000","0.00000000"],["78376.58000000","0.00000000"],["78381.25000000","0.02168000"],["78451.31000000","0.00012000"],["78456.40000000","0.00019000"],["78461.36000000","0.00031000"]]}}
{"rx":1788854506749263588, "m":{"e":"depthUpdate","E":1788854506714,"s":"BTCUSDT","U":99829835412,"u":99829835443,"b":[["78340.40000000","0.01105000"],["78327.66000000","0.02000000"],["78319.82000000","0.00000000"],["78305.00000000","0.70000000"],["78283.73000000","0.34500000"],["78266.71000000","0.02000000"],["78261.59000000","0.00000000"],["78253.85000000","0.00000000"],["77168.84000000","0.00032000"],["62675.20000000","0.00009000"]],"a":[["78345.45000000","0.06866000"],["78346.51000000","0.00652000"],["78347.78000000","0.01753000"],["78355.76000000","0.00007000"],["78357.28000000","0.04000000"],["78366.67000000","0.00000000"],["78370.89000000","0.52682000"],["78376.00000000","0.73000000"],["78407.42000000","0.00000000"],["78416.51000000","0.00000000"],["78438.77000000","0.00000000"]]}}
{"rx":1788854506842645723, "m":{"e":"depthUpdate","E":1788854506814,"s":"BTCUSDT","U":99829835444,"u":99829835478,"b":[["78344.00000000","0.03942000"],["78338.53000000","0.00014000"],["78338.52000000","0.16582000"],["78333.09000000","0.00000000"],["78327.78000000","0.01292000"],["78311.59000000","0.12769000"],["78288.46000000","0.00666000"],["78261.45000000","0.00000000"],["77168.84000000","0.00070000"],["70509.00000000","0.00000000"],["62683.93000000","0.00093000"],["62675.20000000","0.00009000"]],"a":[["78344.01000000","8.55329000"],["78350.22000000","0.01279000"],["78354.14000000","0.01341000"],["78354.92000000","0.14794000"],["78356.00000000","0.30000000"],["78357.38000000","0.12103000"],["78357.99000000","0.00000000"],["78358.06000000","0.01291000"],["78365.89000000","0.12760000"],["78365.90000000","0.01284000"],["78416.61000000","0.00000000"],["79528.97000000","0.00000000"]]}}
{"rx":1788854506959161840, "m":{"e":"depthUpdate","E":1788854506914,"s":"BTCUSDT","U":99829835479,"u":99829835494,"b":[["78342.12000000","0.00000000"],["78324.84000000","0.84571000"],["78323.66000000","0.02000000"],["78277.39000000","1.89758000"],["78271.58000000","0.02000000"],["78253.75000000","0.76799000"],["78190.98000000","0.08040000"],["78190.96000000","0.00000000"],["77168.84000000","0.00070000"],["70509.60000000","0.00064000"]],"a":[["78352.90000000","0.15989000"],["78375.99000000","0.67226000"],["78378.04000000","0.00000000"],["78415.14000000","0.81277000"]]}}
{"rx":1788854507049961217, "m":{"e":"depthUpdate","E":1788854507014,"s":"BTCUSDT","U":99829835495,"u":99829835526,"b":[["78344.00000000","0.03612000"],["78343.99000000","0.00083000"],["78343.98000000","0.00013000"],["78328.44000000","0.02000000"],["78324.50000000","0.04000000"],["78281.62000000","0.02000000"],["78280.88000000","0.02000000"],["78272.62000000","0.02000000"],["78266.23000000","0.02000000"],["78249.38000000","0.07741000"],["77168.84000000","0.00070000"],["62683.93000000","0.00062000"],["62675.20000000","0.00133000"]],"a":[["78347.06000000","0.00007000"],["78349.89000000","2.85903000"],["78350.22000000","0.00000000"],["78354.14000000","0.00000000"],["78357.73000000","0.00000000"],["78358.06000000","0.00000000"],["78365.57000000","0.00000000"],["78365.90000000","0.00000000"],["78373.41000000","0.00000000"],["78381.25000000","0.00000000"]]}}
{"rx":1788854507142705164, "m":{"e":"depthUpdate","E":1788854507114,"s":"BTCUSDT","U":99829835527,"u":99829835546,"b":[["78343.48000000","0.00007000"],["78338.09000000","0.48962000"],["78310.81000000","0.00000000"],["78307.51000000","0.53442000"],["78266.71000000","0.00000000"],["78249.38000000","0.00000000"],["77638.90000000","0.00010000"],["77168.84000000","0.00062000"],["70509.60000000","0.00089000"],["62684.00000000","0.00000000"]],"a":[["78344.01000000","8.55266000"],["78390.69000000","0.00000000"],["78419.99000000","0.00000000"],["78420.99000000","0.00000000"],["78441.15000000","0.00025000"],["78452.07000000","0.00000000"],["79519.18000000","0.00030000"]]}}
{"rx":1788854507256463794, "m":{"e":"depthUpdate","E":1788854507214,"s":"BTCUSDT","U":99829835547,"u":99829835579,"b":[["78344.00000000","0.03605000"],["78343.99000000","0.00076000"],["78338.53000000","0.00000000"],["78338.52000000","0.00000000"],["78338.13000000","0.00013000"],["78335.01000000","0.00000000"],["78333.09000000","0.00007000"],["78332.81000000","0.02000000"],["78311.84000000","0.00000000"],["78274.52000000","0.00000000"],["78268.41000000","0.00318000"],["78201.02000000","0.00000000"],["78190.07000000","0.00127000"],["77168.84000000","0.00062000"],["70509.60000000","0.00105000"],["62683.93000000","0.00031000"]],"a":[["78344.01000000","8.55276000"],["78344.04000000","0.09365000"],["78348.00000000","0.06000000"],["78348.56000000","0.04005000"],["78350.00000000","0.01000000"],["78352.00000000","0.01000000"],["78353.88000000","0.00000000"],["78354.00000000","0.01000000"],["78356.00000000","0.21000000"],["78397.97000000","0.00317000"],["78408.58000000","0.00000000"]]}}
{"rx":1788854507374595393, "m":{"e":"depthUpdate","E":1788854507314,"s":"BTCUSDT","U":99829835580,"u":99829835682,"b":[["78344.00000000","0.03603000"],["78340.75000000","0.00000000"],["78340.62000000","0.00014000"],["78339.57000000","0.00000000"],["78339.32000000","0.00000000"],["78339.31000000","0.00014000"],["78339.15000000","0.01323000"],["78338.10000000","0.15026000"],["78336.04000000","0.02623000"],["78335.91000000","0.00000000"],["78335.40000000","0.00000000"],["78334.69000000","0.00000000"],["78334.22000000","0.00014000"],["78333.77000000","0.00000000"],["78333.71000000","0.03000000"],["78333.09000000","0.00000000"],["78333.08000000","0.00000000"],["78332.52000000","0.00007000"],["78332.18000000","0.22470000"],["78331.80000000","0.00000000"],["78331.68000000","0.00007000"],["78331.30000000","0.00000000"],["78330.55000000","0.00000000"],["78329.67000000","0.00000000"],["78329.09000000","0.00000000"],["78329.08000000","0.00000000"],["78327.52000000","0.00000000"],["78324.87000000","0.01200000"],["78324.86000000","0.00000000"],["78323.19000000","0.00000000"],["78320.12000000","0.31922000"],["78314.66000000","0.00000000"],["78308.76000000","0.31922000"],["78307.51000000","0.00000000"],["78305.00000000","0.00000000"],["78294.23000000","0.00000000"],["78291.78000000","0.00007000"],["78284.02000000","0.55671000"],["78283.74000000","0.00309000"],["78245.40000000","0.00000000"],["78187.75000000","0.00000000"],["78178.92000000","0.37581000"],["77292.28000000","0.00010000"],["77168.84000000","0.00062000"],["62684.00000000","0.00000000"]],"a":[["78344.01000000","8.56957000"],["78344.87000000","0.00000000"],["78345.10000000","0.03057000"],["78345.27000000","0.01875000"],["78346.51000000","0.00014000"],["78346.54000000","0.00014000"],["78347.87000000","0.05000000"],["78352.39000000","0.31922000"],["78356.93000000","0.00049000"],["78358.18000000","0.00000000"],["78361.26000000","0.00000000"],["78362.49000000","0.31922000"],["78366.37000000","0.34463000"],["78366.48000000","0.00000000"],["78375.49000000","0.00000000"],["78385.11000000","0.37044000"],["78385.29000000","0.00000000"],["78387.69000000","0.00000000"],["78390.00000000","0.03000000"],["78390.45000000","0.00000000"],["78406.57000000","0.00127000"],["78428.11000000","0.00408000"],["78462.16000000","0.00000000"],["78479.37000000","0.00000000"],["78491.96000000","0.77442000"],["78516.82000000","0.00000000"],["79551.53000000","0.00000000"],["79964.00000000","0.00046000"]]}}
{"rx":1788854507486073022, "m":{"e":"depthUpdate","E":1788854507414,"s":"BTCUSDT","U":99829835683,"u":99829835934,"b":[["78344.00000000","0.03589000"],["78343.99000000","0.00062000"],["78341.66000000","0.00668000"],["78340.63000000","0.00000000"],["78340.62000000","0.00000000"],["78340.40000000","0.01105000"],["78339.81000000","0.00000000"],["78339.31000000","0.00000000"],["78339.16000000","0.00014000"],["78339.15000000","0.01323000"],["78338.11000000","0.00000000"],["78338.10000000","0.00014000"],["78338.09000000","0.00014000"],["78337.90000000","0.00014000"],["78336.52000000","0.00588000"],["78336.05000000","0.00000000"],["78336.04000000","0.00000000"],["78334.22000000","0.00000000"],["78334.21000000","0.00000000"],["78334.02000000","0.00000000"],["78334.01000000","0.00000000"],["78333.71000000","0.00000000"],["78333.08000000","0.00000000"],["78332.82000000","0.00000000"],["78332.81000000","0.00000000"],["78332.52000000","0.00000000"],["78332.51000000","0.00000000"],["78332.19000000","0.48989000"],["78332.01000000","0.00014000"],["78331.96000000","0.00007000"],["78331.95000000","0.12574000"],["78331.71000000","0.00007000"],["78330.76000000","0.00000000"],["78330.71000000","0.02000000"],["78330.19000000","0.00400000"],["78330.02000000","0.00000000"],["78330.01000000","0.15000000"],["78329.90000000","0.00000000"],["78329.44000000","0.00000000"],["78329.43000000","0.00400000"],["78329.24000000","0.00000000"],["78328.55000000","0.48975000"],["78328.54000000","0.40261000"],["78328.53000000","0.00000000"],["78328.41000000","0.00000000"],["78328.40000000","0.02083000"],["78327.78000000","0.00000000"],["78327.69000000","0.00014000"],["78327.68000000","0.48975000"],["78326.80000000","0.48975000"],["78326.79000000","0.00638000"],["78326.14000000","0.00000000"],["78325.92000000","0.00000000"],["78325.89000000","0.48975000"],["78325.88000000","0.10724000"],["78324.89000000","0.00000000"],["78324.86000000","0.73563000"],["78324.85000000","1.91454000"],["78324.84000000","0.00000000"],["78324.83000000","0.00000000"],["78324.07000000","0.02000000"],["78320.65000000","0.02000000"],["78320.13000000","1.91454000"],["78320.12000000","0.00000000"],["78318.57000000","0.00158000"],["78317.56000000","0.00000000"],["78316.71000000","0.31924000"],["78316.40000000","0.00000000"],["78312.13000000","0.38319000"],["78310.86000000","0.00000000"],["78308.77000000","0.00024000"],["78304.75000000","0.53132000"],["78299.33000000","0.00000000"],["78298.19000000","0.00000000"],["78296.41000000","0.00000000"],["78294.89000000","0.00000000"],["78294.70000000","0.63880000"],["78294.16000000","0.00000000"],["78288.78000000","0.00000000"],["78288.65000000","0.00000000"],["78285.75000000","0.00000000"],["78279.17000000","1.06029000"],["78277.39000000","0.00000000"],["78275.63000000","0.00436000"],["78275.23000000","0.00000000"],["78271.64000000","0.02000000"],["78266.23000000","0.00000000"],["78262.44000000","1.26534000"],["78261.32000000","0.02000000"],["78259.55000000","0.00000000"],["78250.40000000","0.00000000"],["78246.07000000","0.00000000"],["78243.24000000","0.00000000"],["78222.36000000","0.23981000"],["78198.39000000","0.00000000"],["78187.76000000","0.00000000"],["78169.27000000","2.59562000"],["78114.79000000","0.00000000"],["78111.30000000","0.00802000"],["78027.37000000","0.00000000"],["77168.84000000","0.00062000"],["70509.60000000","0.00121000"],["62683.93000000","0.00000000"]],"a":[["78344.01000000","8.56557000"],["78344.10000000","0.05014000"],["78345.10000000","0.03071000"],["78345.45000000","0.06866000"],["78346.51000000","0.00000000"],["78346.52000000","0.01767000"],["78346.54000000","0.00000000"],["78347.63000000","0.00000000"],["78347.70000000","0.00008000"],["78347.78000000","0.01767000"],["78348.00000000","0.12000000"],["78350.00000000","0.02000000"],["78352.00000000","0.02000000"],["78354.00000000","0.02000000"],["78356.00000000","0.12000000"],["78367.82000000","0.34463000"],["78370.89000000","0.00000000"],["78379.52000000","0.01140000"],["78379.78000000","0.02519000"],["78380.33000000","0.00000000"],["78389.22000000","0.00000000"],["78398.24000000","0.00000000"],["78401.38000000","0.00000000"],["78425.46000000","0.04545000"],["78427.22000000","0.07472000"],["78435.59000000","0.00007000"],["78439.05000000","0.82327000"],["78439.06000000","2.20873000"],["78440.15000000","0.02200000"],["78448.91000000","0.00000000"],["78461.97000000","0.00000000"],["78474.56000000","0.00000000"],["78516.81000000","0.00000000"],["78569.15000000","0.11631000"],["78573.96000000","0.11362000"],["78607.52000000","0.00000000"],["78618.84000000","0.00000000"],["78625.56000000","0.00000000"],["78633.32000000","0.00000000"],["78633.54000000","0.00000000"],["78637.66000000","0.00000000"],["78637.79000000","0.00000000"]]}}
{"rx":1788854507558694290, "m":{"e":"depthUpdate","E":1788854507514,"s":"BTCUSDT","U":99829835935,"u":99829836842,"b":[["78344.00000000","0.00000000"],["78343.99000000","0.00000000"],["78343.98000000","0.00000000"],["78343.65000000","0.00000000"],["78343.48000000","0.00000000"],["78341.66000000","0.00000000"],["78341.20000000","0.00000000"],["78340.80000000","0.00000000"],["78340.79000000","0.00000000"],["78340.40000000","0.00000000"],["78339.66000000","0.00000000"],["78339.16000000","0.00000000"],["78339.15000000","0.04673000"],["78339.14000000","0.00040000"],["78338.13000000","0.00000000"],["78338.10000000","0.00000000"],["78338.09000000","0.00000000"],["78337.78000000","0.00000000"],["78336.52000000","0.00014000"],["78336.41000000","0.00000000"],["78336.17000000","0.00000000"],["78336.15000000","0.00000000"],["78334.72000000","0.00000000"],["78334.30000000","0.00000000"],["78333.83000000","0.00000000"],["78332.90000000","0.00000000"],["78332.21000000","0.00007000"],["78332.20000000","0.00400000"],["78332.19000000","0.00014000"],["78332.18000000","0.00014000"],["78332.01000000","0.00014000"],["78332.00000000","0.03014000"],["78331.96000000","0.00000000"],["78331.95000000","0.00014000"],["78331.92000000","0.00008000"],["78331.83000000","0.00008000"],["78331.71000000","0.00000000"],["78331.70000000","0.00014000"],["78331.39000000","0.00000000"],["78331.19000000","0.00000000"],["78331.18000000","0.00014000"],["78330.71000000","0.00000000"],["78330.19000000","0.00000000"],["78330.02000000","0.00000000"],["78330.01000000","0.00014000"],["78329.88000000","0.00000000"],["78329.43000000","0.00000000"],["78328.82000000","0.00014000"],["78328.81000000","0.02000000"],["78328.80000000","0.00000000"],["78328.73000000","0.48985000"],["78328.72000000","0.36549000"],["78328.71000000","0.15000000"],["78328.56000000","0.00000000"],["78328.55000000","0.00000000"],["78328.54000000","0.00000000"],["78328.40000000","0.00000000"],["78328.33000000","0.00000000"],["78327.96000000","0.00000000"],["78327.84000000","0.00000000"],["78327.69000000","0.00007000"],["78327.68000000","0.00000000"],["78327.32000000","0.48978000"],["78327.21000000","0.00400000"],["78326.80000000","0.00000000"],["78326.79000000","0.00000000"],["78326.78000000","0.00000000"],["78326.41000000","0.48978000"],["78325.89000000","0.00000000"],["78325.88000000","0.00000000"],["78325.50000000","0.48978000"],["78325.15000000","0.00000000"],["78324.87000000","0.00000000"],["78324.86000000","0.25298000"],["78324.85000000","0.00000000"],["78324.41000000","0.00000000"],["78323.99000000","0.00008000"],["78323.78000000","0.00000000"],["78323.19000000","0.00638000"],["78323.02000000","0.00000000"],["78322.99000000","0.00400000"],["78322.41000000","0.02070000"],["78322.29000000","0.00000000"],["78322.27000000","0.00000000"],["78321.94000000","0.31928000"],["78321.06000000","0.00000000"],["78320.50000000","0.00000000"],["78320.14000000","1.94788000"],["78320.13000000","0.00000000"],["78320.08000000","0.00008000"],["78319.95000000","0.00000000"],["78319.71000000","0.00007000"],["78318.88000000","0.00574000"],["78316.58000000","0.00000000"],["78316.16000000","0.00008000"],["78316.04000000","0.00000000"],["78316.03000000","0.64980000"],["78316.01000000","0.00000000"],["78316.00000000","0.03000000"],["78315.65000000","0.00127000"],["78314.57000000","0.02147000"],["78313.86000000","0.00025000"],["78312.66000000","0.00000000"],["78312.28000000","0.00063000"],["78312.24000000","0.00008000"],["78312.13000000","0.00000000"],["78311.59000000","0.00000000"],["78309.55000000","2.29755000"],["78308.99000000","0.37581000"],["78308.75000000","0.00000000"],["78308.32000000","0.00008000"],["78306.73000000","0.02158000"],["78304.83000000","0.00000000"],["78304.41000000","0.00008000"],["78304.00000000","0.03207000"],["78303.75000000","0.00014000"],["78302.00000000","0.03008000"],["78301.67000000","0.00000000"],["78300.49000000","0.02008000"],["78299.00000000","0.01000000"],["78298.89000000","0.02097000"],["78294.97000000","0.63460000"],["78294.07000000","0.00000000"],["78293.80000000","0.13072000"],["78293.21000000","0.00000000"],["78292.07000000","0.00000000"],["78291.05000000","0.02123000"],["78288.47000000","0.00000000"],["78287.79000000","0.00007000"],["78283.99000000","0.00000000"],["78283.38000000","1.26500000"],["78280.81000000","0.00400000"],["78280.63000000","0.00000000"],["78277.88000000","0.00400000"],["78275.69000000","0.00432000"],["78274.95000000","0.00400000"],["78272.42000000","0.36748000"],["78271.57000000","0.34505000"],["78271.10000000","0.00000000"],["78270.73000000","0.00000000"],["78270.56000000","0.34505000"],["78270.55000000","0.00000000"],["78269.26000000","0.00000000"],["78264.76000000","0.00000000"],["78262.06000000","0.00008000"],["78262.02000000","0.00000000"],["78261.32000000","0.00000000"],["78260.98000000","0.01160000"],["78259.80000000","0.00007000"],["78239.76000000","0.00000000"],["78238.99000000","0.00000000"],["78238.97000000","1.91454000"],["78234.51000000","0.00000000"],["78233.20000000","0.05915000"],["78231.68000000","2.45116000"],["78212.01000000","0.00000000"],["78207.25000000","0.04637000"],["78198.83000000","0.00127000"],["78192.75000000","0.00000000"],["78191.26000000","0.00000000"],["78183.72000000","0.00008000"],["78179.58000000","0.00681000"],["78166.59000000","0.00000000"],["78134.01000000","3.84068000"],["78114.78000000","0.00000000"],["78114.40000000","0.00000000"],["78107.79000000","0.00007000"],["78105.96000000","0.00000000"],["78105.38000000","0.00008000"],["78103.88000000","0.00007000"],["78059.84000000","0.11587000"],["78036.05000000","0.00000000"],["78027.04000000","0.00008000"],["78019.00000000","0.00029000"],["77957.70000000","0.00000000"],["77948.70000000","0.00008000"],["77879.35000000","0.00000000"],["77870.36000000","0.00008000"],["77801.00000000","0.00000000"],["77792.02000000","0.00008000"],["77722.65000000","0.00000000"],["77713.68000000","0.00008000"],["77168.84000000","0.00000000"],["70509.60000000","0.00000000"],["70509.59000000","0.00009000"]],"a":[["78339.16000000","9.03314000"],["78339.17000000","0.00027000"],["78339.18000000","0.00013000"],["78339.41000000","0.00400000"],["78339.66000000","1.10681000"],["78339.67000000","4.48269000"],["78339.91000000","0.00000000"],["78339.92000000","0.05875000"],["78340.00000000","0.00000000"],["78340.01000000","0.00014000"],["78340.02000000","0.00000000"],["78340.03000000","0.00000000"],["78340.10000000","0.00000000"],["78340.18000000","0.00000000"],["78340.19000000","0.00014000"],["78340.41000000","2.50146000"],["78340.47000000","0.00000000"],["78340.60000000","0.06859000"],["78340.75000000","0.00000000"],["78340.78000000","0.00000000"],["78340.80000000","0.01563000"],["78340.81000000","0.00000000"],["78341.03000000","0.00000000"],["78341.11000000","0.00000000"],["78341.12000000","0.00000000"],["78341.21000000","0.00000000"],["78341.30000000","0.00000000"],["78341.38000000","0.00000000"],["78341.39000000","0.00000000"],["78341.66000000","0.00000000"],["78341.67000000","0.20438000"],["78341.75000000","0.05000000"],["78341.85000000","0.00000000"],["78342.34000000","0.00400000"],["78342.58000000","0.00000000"],["78342.72000000","0.00000000"],["78342.81000000","0.00000000"],["78342.90000000","0.00000000"],["78342.99000000","0.00000000"],["78343.11000000","0.00000000"],["78343.27000000","0.00000000"],["78343.37000000","0.15000000"],["78343.49000000","0.00000000"],["78343.55000000","0.00000000"],["78343.58000000","0.00000000"],["78343.64000000","0.00000000"],["78343.65000000","0.00014000"],["78343.66000000","2.38245000"],["78343.83000000","0.00000000"],["78343.92000000","0.00000000"],["78343.99000000","0.00000000"],["78344.00000000","0.10158000"],["78344.01000000","0.13608000"],["78344.02000000","0.00000000"],["78344.03000000","0.02000000"],["78344.04000000","0.00014000"],["78344.05000000","0.00000000"],["78344.10000000","0.00000000"],["78344.90000000","0.02000000"],["78345.09000000","0.00000000"],["78345.10000000","0.03057000"],["78345.26000000","0.06391000"],["78345.27000000","0.01861000"],["78345.45000000","0.00000000"],["78346.51000000","0.00000000"],["78346.52000000","0.01753000"],["78346.99000000","0.00008000"],["78347.78000000","0.01753000"],["78347.87000000","0.00000000"],["78349.08000000","0.00000000"],["78349.50000000","0.00000000"],["78349.87000000","0.00000000"],["78349.89000000","2.67898000"],["78349.90000000","0.14278000"],["78350.00000000","0.02007000"],["78350.68000000","0.00063000"],["78351.00000000","0.00008000"],["78351.28000000","0.00000000"],["78351.40000000","0.09551000"],["78351.84000000","0.00000000"],["78352.92000000","0.63832000"],["78353.04000000","0.00007000"],["78353.36000000","0.10267000"],["78353.65000000","1.47541000"],["78353.66000000","0.68154000"],["78353.78000000","0.31924000"],["78354.31000000","0.00000000"],["78354.49000000","0.00000000"],["78354.91000000","0.00000000"],["78354.92000000","0.00000000"],["78355.68000000","0.00008000"],["78356.34000000","0.00000000"],["78357.38000000","0.03959000"],["78358.30000000","0.00000000"],["78358.63000000","0.00000000"],["78358.87000000","0.00192000"],["78359.39000000","0.00000000"],["78359.60000000","0.00008000"],["78359.68000000","0.00062000"],["78360.02000000","0.00012000"],["78360.48000000","0.00060000"],["78363.11000000","0.00000000"],["78363.51000000","0.00008000"],["78363.60000000","0.00014000"],["78365.89000000","0.00000000"],["78366.96000000","0.00000000"],["78367.43000000","0.00008000"],["78367.51000000","0.00000000"],["78369.58000000","0.00000000"],["78369.77000000","0.00000000"],["78371.35000000","0.00008000"],["78371.43000000","0.00000000"],["78373.20000000","0.00280000"],["78374.38000000","0.00000000"],["78375.26000000","0.00008000"],["78375.35000000","0.00055000"],["78375.61000000","0.00000000"],["78375.63000000","0.02544000"],["78375.91000000","1.93149000"],["78378.87000000","0.00426000"],["78379.18000000","0.00008000"],["78379.26000000","0.00008000"],["78379.56000000","0.00000000"],["78379.78000000","0.00000000"],["78380.80000000","0.01151000"],["78383.18000000","0.00000000"],["78384.53000000","0.00000000"],["78385.30000000","0.00008000"],["78386.43000000","0.00000000"],["78387.00000000","0.00000000"],["78387.82000000","0.00000000"],["78388.69000000","0.00000000"],["78390.51000000","0.00000000"],["78390.54000000","0.00000000"],["78391.03000000","0.00000000"],["78396.16000000","0.01727000"],["78397.31000000","0.00110000"],["78398.24000000","0.00532000"],["78400.00000000","0.03008000"],["78403.17000000","0.00000000"],["78407.27000000","1.63148000"],["78408.73000000","0.00000000"],["78409.72000000","0.00000000"],["78412.81000000","0.00000000"],["78414.16000000","0.00000000"],["78414.38000000","0.00000000"],["78418.75000000","0.00008000"],["78424.14000000","0.00000000"],["78427.81000000","0.00000000"],["78429.22000000","0.00000000"],["78435.59000000","0.00000000"],["78454.63000000","0.00000000"],["78456.47000000","0.00010000"],["78464.82000000","0.03198000"],["78467.59000000","0.00000000"],["78497.09000000","0.00008000"],["78506.16000000","0.00000000"],["78575.43000000","0.00008000"],["78584.51000000","0.00009000"],["78586.71000000","0.01938000"],["78586.75000000","0.01981000"],["78599.09000000","0.00028000"],["78653.77000000","0.00008000"],["78661.44000000","0.00000000"],["78661.49000000","0.00000000"],["78662.86000000","0.00000000"],["78732.11000000","0.00008000"],["78741.21000000","0.00000000"],["78811.72000000","0.00008000"],["78819.56000000","0.00000000"],["78890.06000000","0.00008000"],["78897.91000000","0.00000000"],["78968.40000000","0.00008000"],["78976.26000000","0.00000000"]]}}
{"rx":1788854507656928211, "m":{"e":"depthUpdate","E":1788854507614,"s":"BTCUSDT","U":99829836843,"u":99829837058,"b":[["78339.15000000","0.03371000"],["78339.14000000","0.00040000"],["78338.86000000","0.00000000"],["78338.78000000","0.00007000"],["78337.90000000","0.00000000"],["78337.89000000","0.00014000"],["78336.52000000","0.00000000"],["78332.21000000","0.00000000"],["78332.20000000","0.00000000"],["78332.19000000","0.00000000"],["78332.18000000","0.00000000"],["78332.02000000","0.00014000"],["78332.01000000","0.02026000"],["78332.00000000","0.03014000"],["78331.95000000","0.00000000"],["78331.70000000","0.00000000"],["78331.18000000","0.00000000"],["78330.42000000","0.00564000"],["78330.06000000","0.00000000"],["78330.05000000","0.00000000"],["78330.01000000","0.00014000"],["78330.00000000","0.03014000"],["78329.15000000","0.00000000"],["78329.14000000","0.00000000"],["78328.82000000","0.01214000"],["78328.81000000","0.02014000"],["78328.77000000","0.00014000"],["78328.76000000","0.08380000"],["78328.75000000","0.00000000"],["78328.74000000","0.00000000"],["78328.73000000","0.00014000"],["78328.72000000","0.00014000"],["78328.71000000","0.15014000"],["78327.32000000","0.48978000"],["78326.41000000","0.00000000"],["78325.50000000","0.48978000"],["78324.87000000","0.48978000"],["78324.86000000","0.41476000"],["78323.75000000","0.48978000"],["78322.59000000","0.12767000"],["78321.85000000","0.00047000"],["78321.31000000","0.10724000"],["78320.15000000","0.42428000"],["78320.14000000","1.91454000"],["78319.71000000","0.00014000"],["78319.24000000","0.00007000"],["78286.55000000","0.00000000"],["78281.65000000","0.77811000"],["78268.34000000","0.77824000"],["78254.37000000","0.00536000"],["78253.68000000","0.00120000"],["78252.46000000","0.01734000"],["78251.75000000","0.20000000"],["78110.05000000","0.00007000"],["78101.68000000","0.00007000"],["78097.77000000","0.00007000"],["78050.04000000","0.11310000"],["77164.07000000","0.00008000"],["70690.07000000","0.00000000"],["70505.24000000","0.00016000"],["62682.92000000","0.00093000"],["62671.00000000","0.00200000"]],"a":[["78339.16000000","9.03678000"],["78339.20000000","0.05000000"],["78339.25000000","0.05000000"],["78339.40000000","0.00400000"],["78339.65000000","0.01600000"],["78339.66000000","1.10695000"],["78339.92000000","0.05875000"],["78340.01000000","0.00000000"],["78340.19000000","0.00000000"],["78340.41000000","2.50146000"],["78340.60000000","0.06873000"],["78340.80000000","0.01577000"],["78341.67000000","0.20438000"],["78341.75000000","0.00000000"],["78344.00000000","0.05158000"],["78344.01000000","0.12318000"],["78344.03000000","0.00800000"],["78344.04000000","0.00000000"],["78345.04000000","0.00000000"],["78345.26000000","0.13600000"],["78345.27000000","0.00400000"],["78346.21000000","0.31864000"],["78346.52000000","0.00000000"],["78347.06000000","0.00000000"],["78347.78000000","0.00000000"],["78361.60000000","0.00255000"],["78378.72000000","0.00433000"],["78379.00000000","0.71000000"],["78381.00000000","0.00000000"],["78384.00000000","0.03000000"],["78404.01000000","0.20000000"],["78412.26000000","0.09308000"],["78428.52000000","0.04517000"],["78605.82000000","0.00497000"],["78606.08000000","0.02375000"],["78606.11000000","0.07529000"],["78661.20000000","0.00007000"],["82921.18000000","0.00010000"]]}}
{"rx":1788854507740841223, "m":{"e":"depthUpdate","E":1788854507714,"s":"BTCUSDT","U":99829837059,"u":99829837492,"b":[["78339.15000000","0.00000000"],["78339.14000000","0.00000000"],["78338.78000000","0.00000000"],["78337.89000000","0.00000000"],["78336.30000000","0.00000000"],["78335.74000000","0.00000000"],["78335.67000000","0.00000000"],["78334.48000000","0.00000000"],["78333.78000000","0.00000000"],["78333.23000000","0.00000000"],["78332.96000000","0.73595000"],["78332.95000000","0.00063000"],["78332.01000000","0.39777000"],["78331.97000000","0.01170000"],["78331.83000000","0.00000000"],["78331.73000000","0.00000000"],["78331.67000000","0.00000000"],["78331.32000000","0.00014000"],["78331.31000000","0.20250000"],["78330.06000000","0.00014000"],["78330.05000000","0.00000000"],["78330.01000000","0.00000000"],["78330.00000000","0.03014000"],["78329.74000000","0.00000000"],["78329.51000000","0.00007000"],["78329.50000000","0.14038000"],["78329.15000000","0.00007000"],["78329.14000000","0.00000000"],["78328.82000000","0.00014000"],["78328.81000000","0.02014000"],["78328.77000000","0.00000000"],["78328.76000000","0.22297000"],["78328.73000000","0.00000000"],["78328.72000000","0.00000000"],["78328.61000000","0.00000000"],["78327.32000000","0.00000000"],["78327.21000000","0.00000000"],["78325.73000000","0.00000000"],["78325.51000000","0.00000000"],["78325.50000000","0.00000000"],["78324.88000000","0.30090000"],["78324.87000000","0.00000000"],["78324.86000000","0.00000000"],["78324.19000000","0.00008000"],["78323.99000000","0.00000000"],["78323.75000000","0.00000000"],["78323.70000000","0.00040000"],["78322.59000000","0.00000000"],["78320.99000000","0.00000000"],["78320.16000000","0.38781000"],["78320.08000000","0.00000000"],["78316.35000000","0.00008000"],["78316.16000000","0.00000000"],["78312.44000000","0.00008000"],["78312.24000000","0.00000000"],["78308.52000000","0.00008000"],["78308.32000000","0.00000000"],["78304.60000000","0.23200000"],["78304.41000000","0.00000000"],["78300.69000000","0.00008000"],["78300.49000000","0.02000000"],["78299.76000000","0.00014000"],["78299.00000000","0.00000000"],["78296.77000000","0.00008000"],["78296.56000000","0.00000000"],["78295.77000000","0.00014000"],["78294.71000000","0.88512000"],["78293.00000000","0.01000000"],["78292.85000000","0.00008000"],["78287.30000000","0.00008000"],["78279.64000000","0.00000000"],["78268.42000000","0.00317000"],["78268.41000000","0.00000000"],["78262.06000000","0.00000000"],["78257.51000000","0.00318000"],["78253.69000000","0.00008000"],["78251.75000000","0.00000000"],["78250.16000000","2.21406000"],["78240.32000000","0.03127000"],["78183.72000000","0.00000000"],["78175.36000000","0.00008000"],["78175.29000000","0.20266000"],["78105.38000000","0.00000000"],["78097.77000000","0.00000000"],["78097.02000000","0.00008000"],["78027.04000000","0.00000000"],["78018.69000000","0.00008000"],["77948.70000000","0.00000000"],["77940.36000000","0.00008000"],["77870.36000000","0.00000000"],["77862.03000000","0.00008000"],["77792.02000000","0.00000000"],["77783.70000000","0.00008000"],["77713.68000000","0.00000000"],["77705.36000000","0.00008000"],["77164.07000000","0.00000000"],["70505.24000000","0.00000000"],["70499.67000000","0.00016000"],["62671.32000000","0.00000000"],["62671.00000000","0.00000000"]],"a":[["78332.97000000","7.79455000"],["78332.98000000","0.00027000"],["78332.99000000","0.00013000"],["78333.00000000","0.05000000"],["78333.05000000","0.05000000"],["78333.22000000","0.00000000"],["78333.24000000","0.00000000"],["78333.26000000","2.29755000"],["78333.88000000","0.00000000"],["78334.49000000","0.00000000"],["78334.79000000","0.00000000"],["78335.04000000","0.00400000"],["78335.24000000","0.00000000"],["78335.67000000","0.00014000"],["78335.68000000","0.00000000"],["78335.70000000","0.00000000"],["78335.75000000","0.00000000"],["78335.76000000","0.37581000"],["78336.31000000","0.01295000"],["78336.61000000","0.00000000"],["78337.09000000","0.04029000"],["78337.52000000","0.00000000"],["78337.90000000","0.00000000"],["78338.43000000","0.00000000"],["78338.79000000","0.00000000"],["78339.15000000","0.77434000"],["78339.16000000","3.17168000"],["78339.17000000","0.00000000"],["78339.18000000","0.00000000"],["78339.20000000","0.00014000"],["78339.25000000","0.00014000"],["78339.66000000","0.00028000"],["78339.67000000","2.07790000"],["78339.76000000","0.00026000"],["78339.92000000","0.00875000"],["78340.41000000","0.02386000"],["78340.42000000","0.01577000"],["78340.60000000","0.06859000"],["78340.80000000","0.01571000"],["78341.67000000","0.12312000"],["78342.93000000","0.01893000"],["78343.74000000","0.00007000"],["78344.01000000","0.08232000"],["78346.71000000","0.00010000"],["78346.87000000","0.00007000"],["78346.99000000","0.00000000"],["78348.64000000","0.00008000"],["78351.16000000","0.30927000"],["78351.85000000","0.00000000"],["78352.55000000","0.00008000"],["78352.90000000","0.00000000"],["78353.13000000","0.00000000"],["78355.68000000","0.00000000"],["78355.76000000","0.00000000"],["78356.01000000","0.00000000"],["78356.26000000","0.00000000"],["78356.47000000","0.03192000"],["78359.60000000","0.00000000"],["78359.68000000","0.00007000"],["78360.39000000","0.00034000"],["78363.04000000","0.52558000"],["78363.51000000","0.00000000"],["78364.30000000","0.00008000"],["78367.43000000","0.00000000"],["78367.52000000","0.00000000"],["78368.22000000","0.00008000"],["78371.35000000","0.00000000"],["78372.14000000","0.00008000"],["78372.74000000","0.00000000"],["78375.26000000","0.00000000"],["78375.35000000","0.00000000"],["78375.57000000","0.00000000"],["78379.18000000","0.00000000"],["78387.70000000","0.88407000"],["78388.64000000","1.04262000"],["78396.69000000","0.00000000"],["78401.71000000","0.00316000"],["78404.01000000","0.00000000"],["78423.04000000","0.00000000"],["78429.47000000","0.00000000"],["78542.71000000","0.01999000"],["78591.97000000","0.00000000"],["78630.63000000","1.19998000"],["78664.99000000","0.00000000"],["78802.97000000","0.00008000"],["78811.72000000","0.00000000"],["78881.30000000","0.00008000"],["78890.06000000","0.00000000"],["78959.63000000","0.00008000"],["78968.40000000","0.00000000"]]}}
{"rx":1788854507842788854, "m":{"e":"depthUpdate","E":1788854507814,"s":"BTCUSDT","U":99829837493,"u":99829837688,"b":[["78332.96000000","0.47352000"],["78332.95000000","0.00063000"],["78332.01000000","0.11693000"],["78332.00000000","0.03014000"],["78331.97000000","0.00014000"],["78331.31000000","0.20264000"],["78330.06000000","0.00000000"],["78330.01000000","0.00014000"],["78330.00000000","0.03014000"],["78329.50000000","0.14052000"],["78329.15000000","0.00000000"],["78328.82000000","0.00000000"],["78328.76000000","0.08255000"],["78328.71000000","0.15000000"],["78324.27000000","0.00400000"],["78318.20000000","0.12768000"],["78317.29000000","0.00008000"],["78316.71000000","0.00000000"],["78313.83000000","0.31926000"],["78313.39000000","1.24592000"],["78312.09000000","0.09556000"],["78310.68000000","0.00012000"],["78310.13000000","0.10273000"],["78309.00000000","0.30250000"],["78304.76000000","0.37719000"],["78304.60000000","0.00008000"],["78294.89000000","1.07209000"],["78286.12000000","0.00335000"],["78286.01000000","0.85664000"],["78281.66000000","1.19143000"],["78279.26000000","0.00000000"],["78278.27000000","0.00663000"],["78277.39000000","1.23973000"],["78274.01000000","0.69081000"],["78269.55000000","0.84756000"],["78262.45000000","1.45146000"],["78250.17000000","1.36070000"],["78250.01000000","0.00000000"],["78245.91000000","0.12319000"],["78245.56000000","0.20000000"],["78240.98000000","0.00000000"],["78238.98000000","0.76551000"],["78238.06000000","0.00000000"],["78234.86000000","0.77179000"],["78205.21000000","0.05616000"],["78201.01000000","0.04742000"],["78183.05000000","0.46785000"],["78114.93000000","0.00007000"],["78099.29000000","0.00007000"],["78096.40000000","0.00007000"],["78092.49000000","0.00000000"],["77157.97000000","0.00008000"],["77157.96000000","0.00030000"],["70509.59000000","0.00000000"],["62682.92000000","0.00062000"],["62666.37000000","0.00000000"]],"a":[["78332.97000000","7.79551000"],["78333.00000000","0.05014000"],["78333.05000000","0.05014000"],["78333.25000000","0.80310000"],["78333.26000000","2.29769000"],["78335.33000000","0.00400000"],["78335.76000000","0.00014000"],["78336.31000000","0.01309000"],["78337.09000000","0.04043000"],["78339.14000000","0.93754000"],["78339.15000000","0.07514000"],["78339.16000000","2.88458000"],["78339.20000000","0.00000000"],["78339.25000000","0.00000000"],["78339.40000000","0.00000000"],["78339.66000000","0.00014000"],["78339.67000000","2.07776000"],["78339.92000000","0.00861000"],["78340.41000000","0.02372000"],["78340.42000000","0.00000000"],["78341.17000000","0.12764000"],["78341.67000000","0.10419000"],["78342.75000000","0.00007000"],["78342.93000000","0.00000000"],["78343.65000000","0.75368000"],["78344.01000000","0.08219000"],["78344.72000000","0.00007000"],["78345.26000000","0.21284000"],["78346.10000000","0.00008000"],["78346.66000000","0.00007000"],["78347.00000000","0.00000000"],["78347.34000000","0.09552000"],["78347.92000000","0.19261000"],["78349.29000000","0.10268000"],["78350.92000000","0.00000000"],["78351.40000000","0.00000000"],["78353.36000000","0.00000000"],["78354.84000000","0.00000000"],["78357.61000000","0.00255000"],["78361.60000000","0.00000000"],["78362.68000000","0.00000000"],["78365.27000000","0.63410000"],["78370.52000000","0.00000000"],["78373.00000000","0.01000000"],["78374.27000000","0.00000000"],["78379.00000000","0.70000000"],["78386.38000000","0.00012000"],["78387.69000000","0.78673000"],["78391.90000000","0.77701000"],["78395.10000000","0.00000000"],["78397.82000000","0.20000000"],["78403.99000000","0.03990000"],["78408.98000000","0.00000000"],["78419.99000000","0.01797000"],["78423.05000000","0.78373000"],["78455.99000000","0.01810000"],["78461.97000000","0.38621000"],["78489.85000000","0.30584000"],["78542.71000000","0.00000000"],["78555.38000000","0.00000000"],["78555.47000000","0.01999000"],["78557.40000000","0.00000000"],["78561.31000000","0.00000000"]]}}
{"rx":1788854507950986217, "m":{"e":"depthUpdate","E":1788854507914,"s":"BTCUSDT","U":99829837689,"u":99829837739,"b":[["78332.96000000","0.47359000"],["78332.00000000","0.03014000"],["78331.97000000","0.00000000"],["78328.76000000","0.08269000"],["78327.88000000","0.00475000"],["78326.62000000","0.00793000"],["78325.37000000","0.00951000"],["78324.12000000","0.00952000"],["78320.15000000","0.58871000"],["78289.60000000","0.00400000"],["78286.12000000","0.00000000"],["78274.95000000","0.00000000"],["78111.30000000","0.00000000"],["78099.77000000","0.00802000"],["78099.29000000","0.00000000"],["78096.40000000","0.00000000"],["77157.97000000","0.00016000"],["70499.67000000","0.00032000"]],"a":[["78332.97000000","7.82806000"],["78333.05000000","0.05014000"],["78333.25000000","0.80324000"],["78333.26000000","2.29769000"],["78334.23000000","0.01759000"],["78335.48000000","0.02111000"],["78335.76000000","0.00000000"],["78336.73000000","0.02111000"],["78337.09000000","0.04043000"],["78339.16000000","2.86771000"],["78344.01000000","0.07719000"],["78348.64000000","0.00016000"],["78354.73000000","0.03400000"],["78357.58000000","0.00408000"],["78362.00000000","0.73000000"],["78363.67000000","0.00000000"],["79519.18000000","0.00000000"]]}}
{"rx":1788854508041128120, "m":{"e":"depthUpdate","E":1788854508014,"s":"BTCUSDT","U":99829837740,"u":99829837802,"b":[["78332.96000000","1.41281000"],["78332.95000000","0.00063000"],["78332.01000000","0.07266000"],["78330.58000000","0.00000000"],["78330.57000000","0.00000000"],["78329.51000000","0.00000000"],["78329.50000000","0.00014000"],["78328.77000000","0.00007000"],["78323.60000000","0.01330000"],["78322.03000000","0.03057000"],["78307.91000000","0.00026000"],["78284.03000000","2.29035000"],["78207.54000000","0.00000000"],["78196.52000000","0.00009000"],["78175.29000000","0.00016000"],["77157.97000000","0.00024000"],["70641.24000000","0.00496000"],["70499.00000000","0.00000000"],["62682.92000000","0.00031000"],["62666.37000000","0.00124000"]],"a":[["78332.97000000","7.82789000"],["78333.26000000","2.29769000"],["78334.23000000","0.01773000"],["78335.33000000","0.00000000"],["78335.48000000","0.02125000"],["78336.31000000","0.01309000"],["78336.41000000","0.00400000"],["78337.09000000","0.04029000"],["78339.15000000","0.07500000"],["78349.93000000","0.03400000"],["78349.99000000","0.04200000"],["78350.79000000","0.03800000"],["78353.82000000","0.02600000"],["78363.89000000","0.00000000"],["78364.70000000","0.00000000"],["78451.31000000","0.00000000"],["78456.40000000","0.00000000"],["78461.36000000","0.00000000"]]}}
{"rx":1788854508139985551, "m":{"e":"depthUpdate","E":1788854508114,"s":"BTCUSDT","U":99829837803,"u":99829837961,"b":[["78332.96000000","3.84413000"],["78332.01000000","0.02271000"],["78331.32000000","0.00000000"],["78331.31000000","0.00014000"],["78331.00000000","0.00000000"],["78330.28000000","0.00400000"],["78330.00000000","0.03014000"],["78329.88000000","0.00400000"],["78329.50000000","0.00000000"],["78329.47000000","0.00000000"],["78328.82000000","0.00014000"],["78327.92000000","0.10724000"],["78327.69000000","0.00014000"],["78324.88000000","0.78093000"],["78324.27000000","0.00000000"],["78324.10000000","1.91454000"],["78322.99000000","0.00000000"],["78321.85000000","0.00000000"],["78321.31000000","0.00000000"],["78320.18000000","1.44464000"],["78320.17000000","2.29788000"],["78320.15000000","0.00000000"],["78313.36000000","0.00007000"],["78311.39000000","0.38319000"],["78308.67000000","0.02471000"],["78293.80000000","0.34453000"],["78291.78000000","0.00000000"],["78290.43000000","0.63883000"],["78287.79000000","0.00000000"],["78286.01000000","1.43363000"],["78277.39000000","0.86089000"],["78275.43000000","0.00000000"],["78258.01000000","0.39536000"],["78256.83000000","1.26543000"],["78253.75000000","0.09432000"],["78252.30000000","0.00000000"],["70499.67000000","0.00048000"]],"a":[["78332.97000000","2.28907000"],["78332.98000000","0.00041000"],["78332.99000000","0.05353000"],["78333.04000000","0.00014000"],["78333.24000000","0.00000000"],["78333.25000000","0.00014000"],["78333.26000000","0.00014000"],["78334.22000000","0.00014000"],["78335.04000000","0.00000000"],["78335.47000000","0.00007000"],["78336.41000000","0.00000000"],["78336.61000000","0.00000000"],["78336.73000000","0.02125000"],["78339.12000000","1.35078000"],["78339.13000000","2.29788000"],["78339.14000000","0.00000000"],["78339.15000000","0.00000000"],["78339.16000000","0.11116000"],["78339.65000000","0.00000000"],["78339.66000000","2.00678000"],["78339.67000000","0.00000000"],["78339.72000000","0.00000000"],["78340.81000000","0.20305000"],["78343.36000000","0.00638000"],["78343.64000000","0.00000000"],["78344.00000000","0.04935000"],["78344.03000000","0.00400000"],["78344.95000000","0.91975000"],["78344.96000000","2.29788000"],["78345.10000000","0.00000000"],["78345.26000000","0.00000000"],["78346.86000000","0.01600000"],["78347.33000000","0.00400000"],["78348.64000000","0.00071000"],["78351.84000000","0.18274000"],["78356.47000000","0.03247000"],["78360.54000000","0.00223000"],["78363.93000000","0.00000000"],["78364.31000000","0.00055000"],["78366.27000000","0.00000000"],["78368.76000000","0.00000000"],["78410.56000000","2.29788000"],["78440.25000000","0.00012000"],["78445.35000000","0.00019000"],["78450.31000000","0.00031000"],["78472.93000000","0.00000000"],["78476.59000000","0.03057000"],["78521.58000000","0.00000000"],["79507.97000000","0.00030000"]]}}
{"rx":1788854508246011638, "m":{"e":"depthUpdate","E":1788854508214,"s":"BTCUSDT","U":99829837962,"u":99829838027,"b":[["78332.96000000","3.86508000"],["78332.95000000","0.00077000"],["78332.01000000","0.06610000"],["78332.00000000","0.03014000"],["78331.31000000","0.00000000"],["78330.89000000","0.00014000"],["78330.88000000","0.15550000"],["78330.28000000","0.00000000"],["78329.82000000","0.00007000"],["78329.31000000","0.00400000"],["78328.77000000","0.00000000"],["78310.11000000","0.00400000"],["78291.78000000","0.00007000"],["78277.88000000","0.00000000"],["77157.97000000","0.00032000"],["62682.92000000","0.00000000"]],"a":[["78332.97000000","2.49171000"],["78332.99000000","0.05367000"],["78333.05000000","0.05014000"],["78333.25000000","0.00000000"],["78333.26000000","0.00000000"],["78334.85000000","0.00007000"],["78335.37000000","0.06859000"],["78337.09000000","0.04043000"],["78339.11000000","0.01600000"],["78339.16000000","0.10478000"],["78340.59000000","0.00400000"],["78340.60000000","0.00000000"],["78340.72000000","0.00000000"],["78341.19000000","0.00400000"],["78341.66000000","0.00638000"],["78343.31000000","0.00094000"],["78346.86000000","0.00000000"],["78350.70000000","0.02800000"],["78360.70000000","0.00000000"],["78367.81000000","0.00000000"]]}}
{"rx":1788854508354020436, "m":{"e":"depthUpdate","E":1788854508314,"s":"BTCUSDT","U":99829838028,"u":99829838064,"b":[["78332.96000000","3.86508000"],["78332.95000000","0.00070000"],["78332.52000000","0.00014000"],["78332.51000000","0.06410000"],["78332.50000000","0.14354000"],["78332.02000000","0.00000000"],["78332.01000000","0.00028000"],["78332.00000000","0.03014000"],["78330.89000000","0.00000000"],["78330.88000000","0.00000000"],["78329.31000000","0.00000000"],["78328.41000000","0.00400000"],["77157.97000000","0.00032000"],["70499.67000000","0.00064000"]],"a":[["78334.23000000","0.01773000"],["78335.37000000","0.06873000"],["78337.09000000","0.04029000"],["78357.58000000","0.00000000"],["78396.76000000","0.00000000"],["78428.11000000","0.00000000"]]}}
{"rx":1788854508442911170, "m":{"e":"depthUpdate","E":1788854508414,"s":"BTCUSDT","U":99829838065,"u":99829838123,"b":[["78332.96000000","3.22158000"],["78332.95000000","0.00063000"],["78332.51000000","0.02117000"],["78332.50000000","0.00014000"],["78332.01000000","0.00014000"],["78332.00000000","0.03000000"],["78329.88000000","0.00000000"],["78328.95000000","0.00400000"],["78328.77000000","0.00007000"],["78328.41000000","0.00000000"],["78327.05000000","0.00000000"],["78326.50000000","0.00408000"],["78324.89000000","0.00800000"],["78320.16000000","0.37981000"],["78286.12000000","0.00335000"],["77157.97000000","0.00032000"],["70499.67000000","0.00089000"],["62675.20000000","0.00102000"]],"a":[["78332.97000000","3.06433000"],["78337.51000000","0.00400000"],["78339.10000000","0.00000000"],["78341.19000000","0.00000000"],["78343.88000000","0.00007000"],["78344.00000000","0.04675000"],["78348.56000000","0.00000000"],["78355.76000000","0.22315000"],["78407.83000000","0.00722000"],["78423.59000000","0.00000000"]]}}
{"rx":1788854508556999149, "m":{"e":"depthUpdate","E":1788854508514,"s":"BTCUSDT","U":99829838124,"u":99829838140,"b":[["78332.51000000","0.02117000"],["78332.50000000","0.00000000"],["78332.00000000","0.03014000"],["77157.97000000","0.00032000"],["62666.37000000","0.00248000"]],"a":[["78332.97000000","3.06358000"],["78346.93000000","0.00007000"],["78348.13000000","0.00408000"]]}}
{"rx":1788854508651238122, "m":{"e":"depthUpdate","E":1788854508614,"s":"BTCUSDT","U":99829838141,"u":99829838182,"b":[["78332.96000000","2.75612000"],["78332.95000000","0.00070000"],["78332.51000000","0.06136000"],["78329.28000000","0.00014000"],["78329.27000000","0.14765000"],["78328.77000000","0.00000000"],["78325.12000000","0.00000000"],["78323.18000000","0.00058000"],["78323.17000000","0.00054000"],["78320.18000000","0.75633000"],["78320.17000000","0.00000000"],["78310.11000000","0.13169000"],["78302.28000000","0.12771000"],["78253.75000000","0.77371000"],["78252.30000000","2.29788000"],["78175.29000000","0.20266000"],["77157.97000000","0.00032000"],["70499.67000000","0.00105000"],["62675.20000000","0.00071000"],["62666.00000000","4.06391000"]],"a":[["78332.97000000","3.06215000"],["78343.31000000","0.00000000"],["78356.56000000","0.09158000"],["78356.57000000","0.12762000"],["78357.38000000","0.00000000"],["78393.83000000","0.03200000"],["86166.26000000","0.00000000"]]}}
{"rx":1788854508748044323, "m":{"e":"depthUpdate","E":1788854508714,"s":"BTCUSDT","U":99829838183,"u":99829838214,"b":[["78332.96000000","2.75612000"],["78332.95000000","0.00070000"],["78332.51000000","0.06059000"],["78331.72000000","0.00007000"],["78330.59000000","0.00014000"],["78330.58000000","0.14771000"],["78330.00000000","0.03014000"],["78329.28000000","0.00000000"],["78329.27000000","0.00000000"],["78328.82000000","0.00007000"],["77157.97000000","0.00032000"],["62666.37000000","0.00248000"]],"a":[["78332.97000000","3.06262000"],["78418.65000000","0.00408000"],["78441.04000000","0.00000000"]]}}
{"rx":1788854508873690666, "m":{"e":"depthUpdate","E":1788854508814,"s":"BTCUSDT","U":99829838215,"u":99829838249,"b":[["78332.96000000","2.75605000"],["78332.95000000","0.00063000"],["78332.51000000","0.02008000"],["78332.00000000","0.03014000"],["78330.59000000","0.00000000"],["78330.58000000","0.00014000"],["78330.00000000","0.03000000"],["78328.82000000","0.00014000"],["78328.77000000","0.00007000"],["78300.00000000","2.20941000"],["78245.91000000","0.41576000"],["78245.14000000","1.00176000"],["78190.07000000","0.00000000"],["78178.93000000","0.00127000"],["77157.97000000","0.00040000"],["77157.96000000","0.00030000"],["70499.67000000","0.00121000"],["62675.20000000","0.00040000"],["62666.37000000","0.00248000"]],"a":[["78344.72000000","0.00007000"],["78464.81000000","0.00127000"],["78489.84000000","0.00000000"],["79100.00000000","0.06119000"]]}}
{"rx":1788854508962966764, "m":{"e":"depthUpdate","E":1788854508914,"s":"BTCUSDT","U":99829838250,"u":99829838282,"b":[["78332.96000000","2.75605000"],["78332.00000000","0.03014000"],["78330.58000000","0.00000000"],["78330.00000000","0.03014000"],["77157.97000000","0.00040000"],["70499.67000000","0.00137000"]],"a":[["78338.60000000","0.00000000"],["78346.44000000","0.00000000"],["78347.49000000","0.00000000"],["78348.13000000","0.00000000"],["78351.41000000","0.00000000"],["78354.28000000","0.00000000"],["78355.33000000","0.00000000"],["78362.12000000","0.00000000"],["78369.96000000","0.00000000"],["78387.31000000","0.00408000"],["78418.65000000","0.00000000"],["78452.51000000","0.04298000"]]}}
{"rx":1788854509058954739, "m":{"e":"depthUpdate","E":1788854509014,"s":"BTCUSDT","U":99829838283,"u":99829838302,"b":[["78332.96000000","2.75607000"],["78332.95000000","0.00083000"],["78332.94000000","0.00013000"],["78332.51000000","0.05806000"],["78330.33000000","0.00014000"],["78330.32000000","0.13590000"],["78328.77000000","0.00000000"],["78328.71000000","0.15014000"],["78111.30000000","0.00802000"],["78099.77000000","0.00000000"],["77157.97000000","0.00040000"],["70499.67000000","0.00128000"],["70499.66000000","0.00009000"],["62675.20000000","0.00009000"]],"a":[["78332.97000000","3.06248000"]]}}
{"rx":1788854509152578948, "m":{"e":"depthUpdate","E":1788854509114,"s":"BTCUSDT","U":99829838303,"u":99829838316,"b":[["78332.96000000","2.95849000"],["78330.42000000","0.00564000"],["77638.90000000","0.00000000"],["77157.97000000","0.00032000"],["70499.67000000","0.00144000"]],"a":[["78419.84000000","0.00408000"],["78430.09000000","0.00025000"],["78441.15000000","0.00000000"],["79507.97000000","0.00030000"]]}}
{"rx":1788854509253460208, "m":{"e":"depthUpdate","E":1788854509214,"s":"BTCUSDT","U":99829838317,"u":99829838338,"b":[["78332.96000000","2.95867000"],["78332.14000000","0.00014000"],["78332.13000000","0.00000000"],["78331.72000000","0.00000000"],["78330.33000000","0.00000000"],["78330.32000000","0.00000000"],["78328.95000000","0.00000000"],["78327.16000000","0.00400000"],["78326.50000000","0.00008000"],["78325.27000000","0.00400000"],["77157.97000000","0.00032000"],["70499.00000000","0.00000000"],["62666.37000000","0.00217000"]],"a":[["78332.97000000","5.36021000"],["78344.01000000","0.07709000"]]}}
{"rx":1788854509352996884, "m":{"e":"depthUpdate","E":1788854509314,"s":"BTCUSDT","U":99829838339,"u":99829838359,"b":[["78332.96000000","2.95853000"],["78332.95000000","0.00076000"],["78332.51000000","0.02008000"],["78332.14000000","0.00000000"],["78330.42000000","0.00564000"],["78328.77000000","0.00007000"],["78304.85000000","0.00408000"],["77157.97000000","0.00032000"],["70499.67000000","0.00160000"],["62666.00000000","4.06391000"]],"a":[["78408.73000000","0.25529000"],["78449.28000000","0.00000000"]]}}
{"rx":1788854509458336292, "m":{"e":"depthUpdate","E":1788854509414,"s":"BTCUSDT","U":99829838360,"u":99829838365,"b":[["78332.36000000","0.12416000"],["77157.97000000","0.00032000"],["76500.62000000","0.00523000"],["62666.37000000","0.00186000"]],"a":[["78340.82000000","0.00007000"]]}}
{"rx":1788854509568017058, "m":{"e":"depthUpdate","E":1788854509514,"s":"BTCUSDT","U":99829838366,"u":99829838388,"b":[["78332.96000000","2.95860000"],["78332.95000000","0.00083000"],["78332.51000000","0.05453000"],["78332.37000000","0.00014000"],["78328.77000000","0.00000000"],["77157.97000000","0.00032000"],["70499.67000000","0.00176000"],["62666.37000000","0.00310000"]],"a":[["78332.97000000","5.36037000"],["78349.32000000","0.00408000"],["78349.99000000","0.04207000"],["78362.30000000","0.00000000"]]}}
{"rx":1788854509681790736, "m":{"e":"depthUpdate","E":1788854509614,"s":"BTCUSDT","U":99829838389,"u":99829838408,"b":[["78332.96000000","2.95778000"],["78332.95000000","0.00076000"],["78332.51000000","0.02008000"],["78332.37000000","0.00000000"],["78332.36000000","0.00000000"],["78328.77000000","0.00007000"],["78324.89000000","0.00000000"],["78320.86000000","0.00800000"],["77157.97000000","0.00032000"],["70499.67000000","0.00192000"],["70499.66000000","0.00000000"],["62666.37000000","0.00279000"]],"a":[["78332.97000000","5.36036000"],["78340.35000000","0.00179000"]]}}
{"rx":1788854509760676000, "m":{"e":"depthUpdate","E":1788854509714,"s":"BTCUSDT","U":99829838409,"u":99829838425,"b":[["78332.51000000","0.02008000"],["78245.91000000","0.12578000"],["78245.14000000","0.00000000"],["77157.97000000","0.00032000"]],"a":[["78338.00000000","0.00500000"],["78340.00000000","0.00500000"],["78342.00000000","0.00500000"],["78344.00000000","0.05175000"],["78346.00000000","0.00500000"],["78356.00000000","0.07000000"]]}}
{"rx":1788854509846657203, "m":{"e":"depthUpdate","E":1788854509814,"s":"BTCUSDT","U":99829838426,"u":99829838446,"b":[["78332.96000000","2.95741000"],["78331.72000000","0.00007000"],["78327.92000000","0.00000000"],["77157.97000000","0.00040000"],["77157.96000000","0.00030000"],["70499.67000000","0.00208000"],["62666.37000000","0.00248000"]],"a":[["78344.72000000","0.00007000"],["78348.00000000","0.12500000"],["78350.00000000","0.02507000"],["78352.00000000","0.02500000"],["78354.00000000","0.02500000"],["78356.00000000","0.07500000"],["78521.39000000","0.00000000"]]}}
{"rx":1788854509944450477, "m":{"e":"depthUpdate","E":1788854509914,"s":"BTCUSDT","U":99829838447,"u":99829838470,"b":[["78332.96000000","2.96317000"],["78330.12000000","0.14508000"],["78325.44000000","0.10724000"],["78234.37000000","0.00408000"],["77157.97000000","0.00040000"],["72089.37000000","0.00014000"]],"a":[["78335.36000000","0.00007000"],["78335.47000000","0.00000000"],["78338.00000000","0.01000000"],["78340.00000000","0.01000000"],["78342.00000000","0.01000000"],["78356.00000000","0.02500000"],["78393.99000000","0.00000000"],["78472.92000000","0.00000000"],["78521.74000000","0.00000000"]]}}
{"rx":1788854510037220392, "m":{"e":"depthUpdate","E":1788854510014,"s":"BTCUSDT","U":99829838471,"u":99829838506,"b":[["78332.96000000","2.96316000"],["78332.95000000","0.00083000"],["78332.51000000","0.06080000"],["78330.42000000","0.00564000"],["78330.13000000","0.00014000"],["78328.77000000","0.00000000"],["78317.78000000","0.07560000"],["78245.91000000","0.12311000"],["77157.97000000","0.00040000"],["70499.67000000","0.00233000"],["62666.37000000","0.00341000"]],"a":[["78332.97000000","5.36005000"],["78344.00000000","0.05675000"],["78346.00000000","0.01000000"],["78348.00000000","0.13000000"],["78350.00000000","0.03007000"],["78352.00000000","0.03000000"],["78354.00000000","0.03000000"],["78356.00000000","0.03000000"],["78383.84000000","0.00317000"],["78461.96000000","0.00127000"],["78521.77000000","0.00000000"]]}}
{"rx":1788854510138467849, "m":{"e":"depthUpdate","E":1788854510114,"s":"BTCUSDT","U":99829838507,"u":99829838550,"b":[["78332.96000000","2.96441000"],["78331.30000000","0.13884000"],["78330.12000000","0.00000000"],["78304.85000000","0.00000000"],["78276.17000000","0.00424000"],["78265.69000000","0.00408000"],["78234.37000000","0.00000000"],["78083.61000000","0.00007000"],["77627.96000000","0.00010000"],["77157.97000000","0.00032000"],["62666.00000000","4.06591000"]],"a":[["78332.97000000","5.26005000"],["78338.98000000","0.00000000"],["78339.76000000","0.00026000"],["78341.89000000","0.00007000"],["78343.68000000","0.00000000"],["78346.82000000","0.00000000"],["78347.60000000","0.00000000"],["78349.32000000","0.00000000"],["78350.00000000","0.03014000"],["78351.52000000","0.00000000"],["78355.44000000","0.00000000"],["78370.34000000","0.00000000"],["78373.54000000","0.00632000"],["78374.67000000","0.00424000"],["78387.31000000","0.00000000"],["78419.84000000","0.00000000"],["78521.45000000","0.00000000"],["78579.15000000","0.01885000"],["78579.51000000","0.02811000"],["79043.69000000","0.00000000"],["79507.97000000","0.00030000"]]}}
{"rx":1788854510246828848, "m":{"e":"depthUpdate","E":1788854510214,"s":"BTCUSDT","U":99829838551,"u":99829838575,"b":[["78332.96000000","2.96441000"],["78332.95000000","0.00083000"],["78332.00000000","0.03014000"],["78331.31000000","0.00014000"],["78331.30000000","0.13898000"],["78330.42000000","0.00550000"],["78330.13000000","0.00000000"],["77157.97000000","0.00032000"],["70499.67000000","0.00249000"],["62666.37000000","0.00310000"],["62666.00000000","4.06391000"]],"a":[["78332.97000000","5.26015000"],["78521.62000000","0.00000000"],["78521.73000000","0.12773000"]]}}
{"rx":1788854510338656945, "m":{"e":"depthUpdate","E":1788854510315,"s":"BTCUSDT","U":99829838576,"u":99829838591,"b":[["78332.51000000","0.02008000"],["78331.31000000","0.00000000"],["78331.30000000","0.00014000"],["78329.82000000","0.00000000"],["78328.77000000","0.00007000"],["78304.81000000","0.00408000"],["78232.63000000","0.00000000"],["77157.97000000","0.00032000"],["70499.67000000","0.00256000"],["70499.66000000","0.00009000"],["70499.00000000","0.00020000"]],"a":[["78332.97000000","5.25875000"],["78521.73000000","0.00000000"]]}}
{"rx":1788854510437230453, "m":{"e":"depthUpdate","E":1788854510414,"s":"BTCUSDT","U":99829838592,"u":99829838625,"b":[["78332.96000000","2.96434000"],["78332.95000000","0.00076000"],["78332.00000000","0.03014000"],["78331.30000000","0.00000000"],["78330.94000000","0.00007000"],["78330.42000000","0.00564000"],["77157.97000000","0.00032000"],["72089.37000000","0.00000000"],["70499.00000000","0.00000000"],["62666.37000000","0.00279000"],["62666.00000000","4.06391000"]],"a":[["78332.97000000","5.25896000"],["78332.98000000","0.00062000"],["78337.77000000","0.00007000"],["78338.00000000","0.02000000"],["78340.00000000","0.02000000"],["78342.00000000","0.02000000"],["78344.00000000","0.06675000"],["78346.00000000","0.02000000"],["78348.00000000","0.08000000"],["78521.77000000","0.00000000"]]}}
{"rx":1788854510537989764, "m":{"e":"depthUpdate","E":1788854510514,"s":"BTCUSDT","U":99829838626,"u":99829838661,"b":[["78332.96000000","2.53025000"],["78332.51000000","0.06699000"],["78329.58000000","0.00014000"],["78329.57000000","0.16582000"],["78328.77000000","0.00000000"],["78323.19000000","0.00000000"],["78308.77000000","0.00000000"],["78259.76000000","0.00000000"],["78238.99000000","0.00000000"],["78236.56000000","0.00007000"],["78212.17000000","0.00107000"],["78193.51000000","0.00000000"],["77157.97000000","0.00032000"],["70499.67000000","0.00272000"],["65146.32000000","0.00000000"],["62666.00000000","4.06391000"]],"a":[["78332.97000000","5.25896000"],["78332.98000000","0.00062000"],["78427.22000000","0.00000000"],["78521.75000000","0.00000000"]]}}
{"rx":1788854510642972361, "m":{"e":"depthUpdate","E":1788854510614,"s":"BTCUSDT","U":99829838662,"u":99829838681,"b":[["78332.96000000","2.53020000"],["78332.95000000","0.00083000"],["78330.00000000","0.03014000"],["77157.97000000","0.00032000"],["70499.66000000","0.00000000"],["62666.37000000","0.00248000"]],"a":[["78338.00000000","0.03000000"],["78340.00000000","0.03000000"],["78342.00000000","0.03000000"],["78344.00000000","0.07675000"],["78346.00000000","0.03000000"],["78348.00000000","0.03000000"],["78366.19000000","1.32348000"]]}}
{"rx":1788854510748043575, "m":{"e":"depthUpdate","E":1788854510714,"s":"BTCUSDT","U":99829838682,"u":99829838711,"b":[["78329.57000000","0.00000000"],["78327.69000000","0.00007000"],["78325.44000000","0.00000000"],["78325.27000000","0.00000000"],["78324.32000000","0.00400000"],["78249.60000000","0.00000000"],["77157.97000000","0.00032000"],["70499.67000000","0.00288000"]],"a":[["78332.97000000","5.25850000"],["78332.98000000","0.00041000"],["78419.79000000","0.00408000"],["78483.37000000","0.00000000"]]}}
{"rx":1788854510862706482, "m":{"e":"depthUpdate","E":1788854510814,"s":"BTCUSDT","U":99829838712,"u":99829838913,"b":[["78332.96000000","0.21450000"],["78332.95000000","0.00076000"],["78332.52000000","0.00000000"],["78332.51000000","0.00014000"],["78330.00000000","0.03014000"],["78329.58000000","0.00000000"],["78328.77000000","0.00000000"],["78328.76000000","0.00014000"],["78328.72000000","0.00014000"],["78328.45000000","0.00000000"],["78328.44000000","0.00000000"],["78328.01000000","0.00007000"],["78327.67000000","0.00000000"],["78327.66000000","0.00000000"],["78327.16000000","0.00000000"],["78325.68000000","0.48981000"],["78324.89000000","0.48981000"],["78324.88000000","0.43788000"],["78324.81000000","0.00000000"],["78324.50000000","0.00000000"],["78324.32000000","0.00000000"],["78324.10000000","0.00000000"],["78324.09000000","0.00000000"],["78323.74000000","0.00000000"],["78323.70000000","0.00033000"],["78323.68000000","0.00000000"],["78323.66000000","0.00000000"],["78323.60000000","0.00000000"],["78323.01000000","0.00070000"],["78322.95000000","0.44625000"],["78322.59000000","0.00000000"],["78322.41000000","0.00000000"],["78322.32000000","0.00000000"],["78322.03000000","0.00000000"],["78321.44000000","0.00400000"],["78321.23000000","0.00400000"],["78320.86000000","0.00000000"],["78320.23000000","0.10615000"],["78320.22000000","0.00000000"],["78320.20000000","0.00000000"],["78320.19000000","0.00000000"],["78320.18000000","0.00000000"],["78320.16000000","0.00000000"],["78320.14000000","0.00000000"],["78320.09000000","0.00000000"],["78319.86000000","0.02103000"],["78319.72000000","0.00638000"],["78319.71000000","0.00007000"],["78319.69000000","0.00000000"],["78319.33000000","0.01325000"],["78317.21000000","0.00000000"],["78316.10000000","0.00000000"],["78315.77000000","0.01329000"],["78315.72000000","0.00007000"],["78314.65000000","0.00000000"],["78313.74000000","0.00000000"],["78313.39000000","1.34845000"],["78311.85000000","0.01307000"],["78311.73000000","0.00078000"],["78311.39000000","0.00000000"],["78309.56000000","2.29788000"],["78309.55000000","0.00000000"],["78309.00000000","0.21643000"],["78308.76000000","0.00000000"],["78307.93000000","0.01310000"],["78307.74000000","0.00007000"],["78304.61000000","0.00024000"],["78304.25000000","0.29689000"],["78304.01000000","0.01297000"],["78303.75000000","0.00007000"],["78301.73000000","0.00059000"],["78299.76000000","0.00007000"],["78295.77000000","0.00007000"],["78287.79000000","0.00007000"],["78252.62000000","0.00010000"],["78239.76000000","0.00000000"],["78237.44000000","0.07614000"],["78018.22000000","7.69277000"],["77157.97000000","0.00040000"],["77157.96000000","0.00030000"],["70499.67000000","0.00304000"],["62666.37000000","0.00217000"]],"a":[["78332.97000000","5.26233000"],["78332.98000000","0.00027000"],["78332.99000000","0.05353000"],["78333.04000000","0.00000000"],["78334.22000000","0.00040000"],["78335.36000000","0.00000000"],["78337.51000000","0.00000000"],["78339.16000000","0.10209000"],["78339.81000000","0.00008000"],["78340.59000000","0.00000000"],["78340.94000000","0.03057000"],["78344.72000000","0.00000000"],["78352.36000000","0.00400000"],["78355.19000000","0.34468000"],["78361.95000000","1.26374000"],["78379.98000000","0.00000000"],["78380.67000000","0.55270000"],["78382.85000000","0.00000000"],["78391.89000000","0.42863000"],["78392.76000000","0.00000000"],["78393.29000000","0.00000000"],["78476.59000000","0.00000000"],["78513.73000000","3.82211000"],["78559.54000000","0.00000000"]]}}
{"rx":1788854510954712534, "m":{"e":"depthUpdate","E":1788854510914,"s":"BTCUSDT","U":99829838914,"u":99829839207,"b":[["78332.96000000","0.21284000"],["78332.95000000","0.00083000"],["78332.94000000","0.00013000"],["78332.51000000","0.00000000"],["78331.92000000","0.00000000"],["78331.02000000","0.00000000"],["78328.82000000","0.00000000"],["78328.81000000","0.00014000"],["78328.76000000","0.00000000"],["78328.73000000","0.00000000"],["78328.72000000","0.00000000"],["78328.71000000","0.00014000"],["78328.01000000","0.00014000"],["78328.00000000","0.03014000"],["78327.59000000","0.00000000"],["78327.50000000","0.48981000"],["78326.62000000","0.00807000"],["78326.60000000","0.29721000"],["78326.59000000","0.48981000"],["78326.39000000","0.13975000"],["78326.21000000","0.00000000"],["78326.01000000","0.00014000"],["78325.80000000","0.00000000"],["78325.69000000","0.00000000"],["78325.68000000","0.46553000"],["78324.91000000","0.00000000"],["78324.90000000","0.32836000"],["78324.89000000","0.00000000"],["78324.88000000","0.00000000"],["78324.21000000","0.00000000"],["78324.07000000","0.00000000"],["78324.01000000","0.01000000"],["78323.77000000","0.00026000"],["78323.70000000","0.00007000"],["78322.95000000","0.00000000"],["78322.94000000","0.00047000"],["78322.60000000","0.00000000"],["78322.59000000","0.00000000"],["78322.01000000","0.00000000"],["78321.58000000","0.00400000"],["78321.44000000","0.00000000"],["78320.65000000","0.00000000"],["78320.24000000","0.00000000"],["78319.86000000","0.00000000"],["78319.72000000","0.00000000"],["78319.71000000","0.00007000"],["78319.63000000","0.10724000"],["78319.42000000","0.00000000"],["78319.41000000","0.14000000"],["78319.33000000","0.00000000"],["78318.68000000","0.02000000"],["78318.40000000","0.00000000"],["78318.20000000","0.00000000"],["78317.79000000","0.00000000"],["78317.78000000","0.00000000"],["78317.43000000","0.00190000"],["78316.40000000","0.00638000"],["78316.36000000","0.00000000"],["78316.32000000","0.73952000"],["78316.04000000","1.91454000"],["78316.03000000","0.00000000"],["78316.02000000","0.00000000"],["78315.77000000","0.00000000"],["78315.72000000","0.00014000"],["78315.43000000","0.01311000"],["78314.10000000","0.00000000"],["78313.83000000","0.00000000"],["78313.39000000","1.42829000"],["78311.73000000","0.00085000"],["78310.69000000","0.00000000"],["78310.65000000","1.91454000"],["78310.64000000","0.00000000"],["78309.62000000","0.02000000"],["78309.57000000","2.67369000"],["78309.56000000","0.00000000"],["78309.00000000","0.00000000"],["78308.99000000","0.00000000"],["78308.67000000","0.00000000"],["78307.74000000","0.00014000"],["78306.93000000","0.31926000"],["78305.37000000","1.91454000"],["78304.76000000","0.00000000"],["78304.75000000","0.00000000"],["78304.25000000","0.00000000"],["78303.75000000","0.00014000"],["78301.40000000","0.00012000"],["78300.35000000","0.00192000"],["78300.00000000","1.50941000"],["78299.76000000","0.00014000"],["78299.25000000","0.31926000"],["78295.98000000","0.52030000"],["78295.77000000","0.00014000"],["78287.87000000","0.00000000"],["78282.26000000","0.00000000"],["78281.66000000","0.87691000"],["78279.81000000","0.00000000"],["78279.17000000","0.00000000"],["78273.52000000","0.00400000"],["78271.00000000","1.03257000"],["78269.79000000","0.00630000"],["78266.02000000","0.00000000"],["78261.57000000","0.06314000"],["78254.38000000","0.00179000"],["78251.97000000","0.02000000"],["78239.76000000","0.00000000"],["78237.44000000","0.00000000"],["78194.47000000","0.02006000"],["78188.28000000","0.00000000"],["78185.46000000","0.00000000"],["78183.14000000","0.07104000"],["78183.05000000","0.00000000"],["78183.04000000","0.00000000"],["78176.48000000","0.00072000"],["78167.53000000","1.53184000"],["78133.04000000","0.00000000"],["78098.03000000","0.29786000"],["78097.77000000","0.00007000"],["78093.86000000","0.00007000"],["78088.80000000","0.00000000"],["78072.67000000","0.00000000"],["78019.00000000","0.00000000"],["78008.74000000","0.00038000"],["77157.97000000","0.00040000"],["70499.66000000","0.00009000"],["65146.32000000","0.01188000"],["62666.00000000","4.06591000"]],"a":[["78332.97000000","5.27881000"],["78332.99000000","0.08293000"],["78334.22000000","0.00000000"],["78334.40000000","0.06897000"],["78334.84000000","0.00400000"],["78335.15000000","0.03057000"],["78335.37000000","0.00014000"],["78336.19000000","0.02000000"],["78336.53000000","0.00223000"],["78336.61000000","0.00000000"],["78337.06000000","0.00000000"],["78337.52000000","0.00000000"],["78338.43000000","0.00000000"],["78339.10000000","0.00000000"],["78339.11000000","0.01200000"],["78339.16000000","0.10056000"],["78341.65000000","0.31926000"],["78341.66000000","0.00000000"],["78343.36000000","0.00000000"],["78344.72000000","0.00007000"],["78344.90000000","0.00000000"],["78351.16000000","0.00000000"],["78352.39000000","0.00000000"],["78356.56000000","0.05348000"],["78356.57000000","0.00000000"],["78360.54000000","0.00000000"],["78363.04000000","0.00000000"],["78364.23000000","0.32678000"],["78370.62000000","0.02455000"],["78375.63000000","0.00000000"],["78380.28000000","0.00000000"],["78383.84000000","0.00000000"],["78388.26000000","0.00000000"],["78388.64000000","0.00000000"],["78461.96000000","0.00000000"],["78461.97000000","0.78492000"],["78464.82000000","0.00000000"],["78465.12000000","1.53184000"],["78477.99000000","0.00000000"],["78480.69000000","0.00000000"],["78520.18000000","0.12775000"],["78522.61000000","0.00000000"],["78599.09000000","0.00000000"],["78601.55000000","0.00456000"],["78723.35000000","0.00000000"]]}}
{"rx":1788854511048718629, "m":{"e":"depthUpdate","E":1788854511014,"s":"BTCUSDT","U":99829839208,"u":99829839359,"b":[["78332.96000000","0.21292000"],["78332.95000000","0.00097000"],["78330.94000000","0.00000000"],["78330.00000000","0.03014000"],["78328.81000000","0.00000000"],["78328.71000000","0.00000000"],["78328.00000000","0.03014000"],["78327.54000000","0.00014000"],["78327.53000000","0.05600000"],["78327.52000000","0.00000000"],["78327.51000000","0.00000000"],["78327.50000000","0.00014000"],["78326.62000000","0.00807000"],["78326.61000000","0.00000000"],["78326.60000000","0.00014000"],["78326.59000000","0.00000000"],["78326.40000000","0.00007000"],["78326.01000000","0.00000000"],["78325.68000000","0.00000000"],["78324.91000000","0.48981000"],["78324.90000000","0.43767000"],["78322.95000000","0.48981000"],["78322.59000000","0.00000000"],["78321.66000000","0.00000000"],["78319.71000000","0.00014000"],["78316.33000000","0.00800000"],["78314.45000000","0.02000000"],["78310.51000000","0.02000000"],["78287.34000000","0.00100000"],["78266.23000000","0.02000000"],["78253.00000000","0.02008000"],["78225.41000000","0.00387000"],["78125.05000000","0.00000000"],["78114.08000000","0.01999000"],["78093.86000000","0.00000000"],["77157.97000000","0.00040000"],["70499.67000000","0.00320000"],["62666.37000000","0.00310000"],["62666.00000000","4.06391000"]],"a":[["78332.97000000","5.28272000"],["78334.23000000","0.01773000"],["78334.40000000","0.06911000"],["78335.15000000","0.03071000"],["78335.37000000","0.00000000"],["78335.48000000","0.02125000"],["78336.19000000","0.02014000"],["78336.31000000","0.01295000"],["78336.73000000","0.02111000"],["78343.72000000","0.00387000"],["78383.84000000","0.00317000"],["78387.69000000","0.00000000"],["78405.73000000","0.00000000"],["78461.96000000","0.00127000"],["78588.55000000","0.00036000"]]}}
{"rx":1788854511154815938, "m":{"e":"depthUpdate","E":1788854511114,"s":"BTCUSDT","U":99829839360,"u":99829839438,"b":[["78332.96000000","0.21285000"],["78332.95000000","0.00090000"],["78328.21000000","0.00014000"],["78328.20000000","0.06623000"],["78328.19000000","0.00000000"],["78328.00000000","0.03014000"],["78327.54000000","0.00000000"],["78327.53000000","0.00014000"],["78327.50000000","0.00000000"],["78326.62000000","0.00807000"],["78326.60000000","0.00000000"],["78326.59000000","0.00000000"],["78326.40000000","0.00000000"],["78326.39000000","0.00014000"],["78325.68000000","0.48981000"],["78324.91000000","0.48981000"],["78324.90000000","0.74474000"],["78323.86000000","0.48981000"],["78322.95000000","0.00000000"],["78322.59000000","0.00000000"],["78322.01000000","0.00000000"],["78320.88000000","0.00400000"],["78305.45000000","0.00000000"],["78165.76000000","0.12775000"],["77157.97000000","0.00032000"],["62666.00000000","4.06391000"]],"a":[["78335.00000000","0.01324000"],["78337.99000000","0.00400000"],["78338.92000000","0.01322000"],["78341.74000000","0.02132000"],["78342.84000000","0.01309000"],["78346.76000000","0.01305000"],["78349.58000000","0.02148000"],["78357.42000000","0.02113000"],["78365.26000000","0.02124000"],["79507.97000000","0.00030000"]]}}
{"rx":1788854511250753068, "m":{"e":"depthUpdate","E":1788854511214,"s":"BTCUSDT","U":99829839439,"u":99829839564,"b":[["78332.96000000","0.03421000"],["78332.95000000","0.00076000"],["78332.00000000","0.03014000"],["78330.00000000","0.03014000"],["78328.21000000","0.00000000"],["78328.20000000","0.00014000"],["78328.00000000","0.03014000"],["78327.53000000","0.00000000"],["78326.62000000","0.00807000"],["78326.39000000","0.00000000"],["78326.01000000","0.00014000"],["78326.00000000","0.03014000"],["78325.68000000","0.00000000"],["78324.93000000","0.00007000"],["78324.92000000","0.18215000"],["78324.91000000","0.00000000"],["78324.90000000","0.00000000"],["78323.86000000","0.00000000"],["78322.06000000","0.00000000"],["78321.58000000","0.00000000"],["78320.49000000","0.00000000"],["78320.23000000","0.24586000"],["78319.69000000","0.00000000"],["78318.57000000","0.00000000"],["78317.51000000","0.48981000"],["78316.59000000","0.35056000"],["78316.58000000","0.00000000"],["78316.57000000","0.00000000"],["78316.34000000","0.00000000"],["78316.32000000","0.00400000"],["78316.04000000","0.00000000"],["78313.66000000","0.02000000"],["78313.39000000","0.66486000"],["78310.65000000","0.00000000"],["78310.47000000","0.00158000"],["78309.58000000","1.91454000"],["78309.57000000","0.37581000"],["78299.24000000","0.00000000"],["78287.45000000","0.00000000"],["78268.36000000","0.34506000"],["78260.02000000","0.02000000"],["78239.76000000","2.29788000"],["78201.00000000","0.00191000"],["78111.30000000","0.00000000"],["78104.65000000","0.00896000"],["77157.97000000","0.00032000"],["70499.67000000","0.00336000"],["62666.37000000","0.00279000"],["62666.00000000","4.06391000"]],"a":[["78332.97000000","5.28272000"],["78334.40000000","0.06911000"],["78335.00000000","0.00014000"],["78336.19000000","0.02000000"],["78338.43000000","0.48981000"],["78338.84000000","0.00013000"],["78338.92000000","0.00000000"],["78339.10000000","0.00000000"],["78341.74000000","0.00000000"],["78341.75000000","0.02800000"],["78342.84000000","0.00000000"],["78344.09000000","0.03000000"],["78345.70000000","0.66460000"],["78346.76000000","0.00000000"],["78349.58000000","0.00000000"],["78350.70000000","0.00000000"],["78357.42000000","0.00000000"],["78363.62000000","0.03828000"],["78365.26000000","0.00000000"],["78380.97000000","0.02800000"],["78389.79000000","0.00000000"]]}}
{"rx":1788854511344309739, "m":{"e":"depthUpdate","E":1788854511314,"s":"BTCUSDT","U":99829839565,"u":99829839622,"b":[["78332.96000000","0.03049000"],["78330.00000000","0.03014000"],["78328.20000000","0.00000000"],["78326.00000000","0.03014000"],["78325.37000000","0.00965000"],["78320.23000000","0.10615000"],["78319.71000000","0.00007000"],["78319.63000000","0.00000000"],["78318.08000000","0.00400000"],["78317.51000000","0.48981000"],["78316.62000000","0.48981000"],["78316.61000000","0.34816000"],["78316.60000000","0.00000000"],["78316.59000000","0.00000000"],["78316.33000000","0.00000000"],["78315.35000000","0.00800000"],["78242.47000000","0.71800000"],["78201.01000000","0.00000000"],["78169.77000000","0.09192000"],["78165.76000000","0.00000000"],["77157.97000000","0.00032000"],["70499.66000000","0.00000000"],["70499.65000000","0.00009000"],["62666.00000000","4.06391000"]],"a":[["78332.97000000","5.29046000"],["78334.40000000","0.06911000"],["78335.00000000","0.00000000"],["78336.19000000","0.02014000"],["78337.52000000","0.46904000"],["78338.43000000","0.00000000"],["78339.10000000","0.46857000"],["78345.70000000","0.00000000"],["78354.52000000","0.00000000"],["78359.74000000","0.00000000"],["80459.44000000","0.00008000"],["80525.58000000","0.00000000"]]}}
{"rx":1788854511443732641, "m":{"e":"depthUpdate","E":1788854511414,"s":"BTCUSDT","U":99829839623,"u":99829839656,"b":[["78329.82000000","0.00007000"],["78323.18000000","0.00010000"],["78321.89000000","0.15629000"],["78320.23000000","0.10615000"],["78319.24000000","0.00000000"],["78317.51000000","0.00000000"],["78316.64000000","0.48981000"],["78316.63000000","0.20436000"],["78316.62000000","0.00000000"],["78316.61000000","0.00000000"],["78313.58000000","0.02000000"],["78309.79000000","0.02000000"],["78309.70000000","0.02000000"],["78275.69000000","0.00000000"],["78275.63000000","0.00000000"],["78261.46000000","0.02000000"],["78261.32000000","0.02000000"],["78252.03000000","0.02000000"],["78251.97000000","0.00000000"],["78240.07000000","0.00007000"],["77157.97000000","0.00032000"],["70499.67000000","0.00352000"],["62666.37000000","0.00248000"]],"a":[["78341.84000000","0.03400000"],["78344.00000000","0.77675000"],["78345.65000000","0.03800000"],["78345.76000000","0.03200000"],["78361.16000000","0.00000000"],["78375.99000000","0.00000000"],["78379.00000000","0.00000000"]]}}
{"rx":1788854511554873247, "m":{"e":"depthUpdate","E":1788854511514,"s":"BTCUSDT","U":99829839657,"u":99829839716,"b":[["78332.51000000","0.00007000"],["78324.01000000","0.00000000"],["78323.24000000","0.16370000"],["78321.89000000","0.00000000"],["78320.91000000","0.01000000"],["78320.85000000","0.00000000"],["78320.28000000","0.00400000"],["78320.11000000","0.00000000"],["78318.08000000","0.00000000"],["78317.51000000","0.45059000"],["78316.69000000","0.35276000"],["78316.68000000","0.48981000"],["78316.67000000","0.00000000"],["78316.66000000","0.00000000"],["78316.65000000","0.00000000"],["78316.64000000","0.00000000"],["78316.63000000","0.00000000"],["78316.32000000","0.00000000"],["78315.43000000","0.00000000"],["78314.46000000","0.00400000"],["78313.46000000","0.00048000"],["78300.68000000","0.00000000"],["78300.55000000","0.00000000"],["78279.81000000","0.00000000"],["78263.58000000","0.00425000"],["78263.44000000","0.00428000"],["78263.08000000","0.02000000"],["78254.38000000","0.00000000"],["78253.00000000","0.00008000"],["78176.48000000","0.00000000"],["78027.72000000","0.00047000"],["77157.97000000","0.00032000"],["70499.67000000","0.00368000"]],"a":[["78334.79000000","0.00000000"],["78335.07000000","0.03000000"],["78335.70000000","0.00000000"],["78336.61000000","0.00000000"],["78337.52000000","0.00000000"],["78338.43000000","0.00000000"],["78339.09000000","0.37581000"],["78339.10000000","0.00000000"],["78343.37000000","0.12000000"],["78343.66000000","2.00664000"],["78345.38000000","0.02600000"],["78356.56000000","0.00000000"],["78357.39000000","0.00000000"],["78361.35000000","0.00000000"],["78394.21000000","0.00000000"],["78424.06000000","0.00000000"]]}}
{"rx":1788854511693014622, "m":{"e":"depthUpdate","E":1788854511614,"s":"BTCUSDT","U":99829839717,"u":99829840087,"b":[["78332.96000000","0.00000000"],["78332.95000000","0.00000000"],["78332.94000000","0.00000000"],["78332.51000000","0.00000000"],["78332.01000000","0.00000000"],["78332.00000000","0.00000000"],["78331.72000000","0.00000000"],["78331.68000000","0.00000000"],["78331.40000000","0.00000000"],["78330.42000000","0.00000000"],["78330.01000000","0.00000000"],["78330.00000000","0.00000000"],["78329.82000000","0.00000000"],["78328.10000000","0.00000000"],["78328.01000000","0.00000000"],["78328.00000000","0.23091000"],["78327.99000000","0.00076000"],["78327.98000000","0.00013000"],["78327.93000000","0.00000000"],["78326.63000000","0.01437000"],["78324.93000000","0.00014000"],["78324.92000000","0.21400000"],["78324.19000000","0.00000000"],["78324.12000000","0.00966000"],["78324.01000000","0.00014000"],["78324.00000000","0.03014000"],["78323.25000000","0.00014000"],["78323.24000000","0.16384000"],["78323.17000000","0.00047000"],["78322.59000000","0.00007000"],["78322.58000000","0.20264000"],["78320.88000000","0.00000000"],["78320.28000000","0.00000000"],["78320.23000000","0.21687000"],["78320.17000000","0.00008000"],["78318.40000000","0.00000000"],["78318.34000000","0.00400000"],["78317.76000000","0.00400000"],["78317.51000000","0.00000000"],["78317.21000000","0.10724000"],["78316.69000000","0.20775000"],["78316.68000000","0.00000000"],["78316.35000000","0.00000000"],["78315.35000000","0.00000000"],["78314.46000000","0.00000000"],["78312.44000000","0.00000000"],["78312.33000000","0.00008000"],["78312.10000000","0.00400000"],["78312.09000000","0.00000000"],["78311.68000000","0.00800000"],["78310.13000000","0.00000000"],["78309.18000000","0.02000000"],["78308.52000000","0.00000000"],["78308.42000000","0.00008000"],["78304.60000000","0.00000000"],["78304.50000000","0.00008000"],["78300.69000000","0.00000000"],["78300.59000000","0.00008000"],["78296.77000000","0.00000000"],["78296.67000000","0.00008000"],["78294.97000000","0.00000000"],["78293.00000000","0.00000000"],["78292.85000000","0.00000000"],["78292.75000000","0.00008000"],["78291.78000000","0.00014000"],["78288.84000000","0.00008000"],["78288.00000000","0.04000000"],["78261.59000000","0.02000000"],["78254.38000000","0.00179000"],["78251.18000000","0.02000000"],["78245.56000000","0.00000000"],["78198.83000000","0.00000000"],["78194.20000000","0.00008000"],["78185.01000000","0.00127000"],["78176.48000000","0.00072000"],["78170.23000000","0.00000000"],["77976.72000000","0.00250000"],["77157.97000000","0.00000000"],["77157.96000000","0.00000000"],["70499.67000000","0.00000000"],["70499.65000000","0.00000000"],["70499.00000000","0.00000000"],["62666.37000000","0.00217000"],["62666.00000000","4.06391000"]],"a":[["78328.01000000","6.38052000"],["78328.02000000","0.00027000"],["78328.03000000","0.00013000"],["78328.05000000","0.05000000"],["78328.10000000","0.05000000"],["78328.92000000","0.00000000"],["78329.44000000","0.06897000"],["78329.83000000","0.00000000"],["78330.00000000","1.88670000"],["78330.01000000","0.00000000"],["78330.43000000","0.00000000"],["78331.29000000","0.04029000"],["78331.68000000","0.00014000"],["78332.01000000","0.00000000"],["78332.02000000","0.16895000"],["78332.52000000","0.00000000"],["78332.95000000","0.00000000"],["78332.96000000","3.75942000"],["78332.97000000","2.50741000"],["78332.98000000","0.00000000"],["78332.99000000","0.00014000"],["78333.00000000","0.00014000"],["78333.05000000","0.00014000"],["78333.88000000","0.00013000"],["78334.40000000","0.00014000"],["78335.07000000","0.03014000"],["78335.48000000","0.02111000"],["78335.84000000","0.00008000"],["78336.19000000","0.02000000"],["78336.31000000","0.00000000"],["78337.09000000","0.00000000"],["78337.48000000","0.00007000"],["78338.84000000","0.00000000"],["78338.87000000","0.00010000"],["78339.78000000","0.09553000"],["78340.61000000","0.00007000"],["78340.80000000","0.01563000"],["78341.20000000","0.00008000"],["78341.65000000","0.00000000"],["78341.74000000","0.10269000"],["78341.89000000","0.00000000"],["78343.17000000","0.00574000"],["78343.68000000","0.00008000"],["78344.40000000","0.04000000"],["78345.18000000","0.03200000"],["78346.87000000","0.00000000"],["78347.34000000","0.00000000"],["78347.59000000","0.00008000"],["78348.64000000","0.00063000"],["78349.29000000","0.00000000"],["78350.00000000","0.03007000"],["78350.06000000","0.00000000"],["78351.51000000","0.00008000"],["78352.55000000","0.00000000"],["78353.78000000","0.00000000"],["78354.53000000","0.52998000"],["78355.42000000","0.00008000"],["78356.47000000","0.03239000"],["78357.72000000","0.63409000"],["78359.34000000","0.00008000"],["78360.14000000","0.00000000"],["78360.39000000","0.00026000"],["78362.49000000","0.00000000"],["78363.26000000","0.00008000"],["78364.30000000","0.00000000"],["78365.27000000","0.00007000"],["78367.17000000","0.00008000"],["78367.59000000","0.00000000"],["78368.22000000","0.00000000"],["78370.85000000","0.10000000"],["78371.03000000","0.77722000"],["78371.58000000","0.00000000"],["78372.14000000","0.00000000"],["78379.53000000","1.08221000"],["78381.48000000","0.00318000"],["78387.59000000","0.00000000"],["78392.77000000","0.00000000"],["78397.82000000","0.00000000"],["78397.97000000","0.00000000"],["78406.34000000","0.00008000"],["78410.56000000","0.00000000"],["78418.75000000","0.00000000"],["78426.41000000","0.00000000"],["78484.67000000","0.00008000"],["78495.67000000","0.00000000"],["78497.09000000","0.00000000"],["78537.47000000","0.00000000"],["78562.99000000","0.00008000"],["78575.43000000","0.00000000"],["78641.32000000","0.00008000"],["78653.77000000","0.00000000"],["78719.65000000","0.00008000"],["78722.70000000","0.00000000"],["78732.11000000","0.00000000"],["78772.78000000","0.00000000"],["78843.15000000","0.00250000"],["79507.97000000","0.00000000"]]}}
{"rx":1788854511770487114, "m":{"e":"depthUpdate","E":1788854511714,"s":"BTCUSDT","U":99829840088,"u":99829840233,"b":[["78328.00000000","0.23433000"],["78327.99000000","0.00076000"],["78327.88000000","0.00000000"],["78326.64000000","0.00000000"],["78326.63000000","0.00014000"],["78326.62000000","0.00014000"],["78325.37000000","0.00014000"],["78324.12000000","0.00014000"],["78322.59000000","0.00007000"],["78322.58000000","0.20250000"],["78320.23000000","0.19781000"],["78318.34000000","0.00000000"],["78318.01000000","0.43991000"],["78317.50000000","0.02400000"],["78317.23000000","0.23678000"],["78317.22000000","0.00000000"],["78316.69000000","0.00000000"],["78310.68000000","0.00000000"],["78278.27000000","0.00000000"],["78266.71000000","0.02000000"],["78252.03000000","0.00000000"],["78245.91000000","0.00000000"],["78240.61000000","0.20000000"],["78237.25000000","1.00176000"],["78093.42000000","0.00007000"],["78089.51000000","0.00007000"],["77153.08000000","0.00008000"],["70495.20000000","0.00016000"]],"a":[["78328.01000000","6.41256000"],["78328.05000000","0.05014000"],["78328.09000000","0.09801000"],["78328.10000000","0.05014000"],["78329.43000000","0.00638000"],["78329.44000000","0.06911000"],["78330.00000000","0.00014000"],["78331.29000000","0.04043000"],["78331.92000000","0.00400000"],["78332.02000000","0.16909000"],["78332.95000000","0.92388000"],["78332.96000000","2.08178000"],["78332.97000000","2.47643000"],["78332.99000000","0.00000000"],["78333.00000000","0.00000000"],["78333.05000000","0.00000000"],["78334.23000000","0.00000000"],["78334.40000000","0.00000000"],["78335.07000000","0.03000000"],["78335.15000000","0.03057000"],["78335.48000000","0.00000000"],["78335.85000000","0.00055000"],["78336.73000000","0.00000000"],["78337.99000000","0.00000000"],["78339.11000000","0.00400000"],["78340.81000000","0.20250000"],["78341.32000000","0.04000000"],["78341.66000000","0.31929000"],["78342.94000000","0.45737000"],["78343.68000000","0.00063000"],["78348.64000000","0.00008000"],["78349.08000000","0.31929000"],["78349.63000000","0.00255000"],["78351.51000000","0.00063000"],["78355.28000000","0.00400000"],["78356.47000000","0.03184000"],["78357.61000000","0.00000000"],["78359.35000000","0.00055000"],["78360.96000000","0.00000000"],["78364.31000000","0.00000000"],["78368.00000000","0.04000000"],["78373.00000000","0.00000000"],["78376.80000000","0.00000000"],["78378.30000000","0.00000000"],["78386.38000000","0.00000000"],["78388.45000000","0.00408000"],["78392.85000000","0.20000000"],["78416.46000000","0.00000000"],["78551.47000000","0.00000000"]]}}
{"rx":1788854511846870331, "m":{"e":"depthUpdate","E":1788854511814,"s":"BTCUSDT","U":99829840234,"u":99829840313,"b":[["78328.00000000","0.23097000"],["78327.99000000","0.00083000"],["78326.63000000","0.00000000"],["78326.62000000","0.00000000"],["78326.00000000","0.03014000"],["78325.37000000","0.00000000"],["78324.92000000","0.21400000"],["78324.12000000","0.00000000"],["78322.92000000","0.00476000"],["78322.58000000","0.20264000"],["78322.00000000","0.03014000"],["78321.94000000","0.31942000"],["78321.66000000","0.00793000"],["78320.91000000","0.01014000"],["78320.41000000","0.00952000"],["78319.71000000","0.00014000"],["78319.16000000","0.00952000"],["78306.26000000","0.09557000"],["78304.30000000","0.10274000"],["78299.54000000","0.00012000"],["78141.26000000","4.44313000"],["78089.51000000","0.00000000"],["77153.08000000","0.00046000"],["62666.37000000","0.00186000"],["62662.40000000","0.00000000"]],"a":[["78328.01000000","6.42341000"],["78328.05000000","0.05014000"],["78328.09000000","0.09815000"],["78328.10000000","0.05014000"],["78328.37000000","0.00400000"],["78329.27000000","0.01760000"],["78329.43000000","0.00652000"],["78329.44000000","0.06911000"],["78330.00000000","0.00000000"],["78330.52000000","0.02112000"],["78331.77000000","0.02112000"],["78332.02000000","0.16909000"],["78332.96000000","2.08164000"],["78332.97000000","2.47605000"],["78375.22000000","0.00012000"],["78507.46000000","4.51021000"]]}}
{"rx":1788854511937975201, "m":{"e":"depthUpdate","E":1788854511914,"s":"BTCUSDT","U":99829840314,"u":99829840364,"b":[["78328.00000000","0.23097000"],["78323.25000000","0.00000000"],["78323.24000000","0.00014000"],["78322.59000000","0.00014000"],["78322.01000000","0.00007000"],["78321.94000000","0.31942000"],["78320.91000000","0.01000000"],["78317.76000000","0.00000000"],["78316.87000000","0.00400000"],["77153.08000000","0.00054000"],["70495.20000000","0.00032000"],["62662.40000000","0.00000000"],["62662.00000000","0.00000000"]],"a":[["78328.01000000","6.42385000"],["78328.10000000","0.05014000"],["78329.27000000","0.01774000"],["78329.44000000","0.06911000"],["78330.52000000","0.02126000"],["78331.29000000","0.04043000"],["78331.38000000","0.00007000"],["78332.02000000","0.16895000"],["78339.76000000","0.00033000"],["78344.72000000","0.00000000"],["78345.41000000","0.03400000"],["78349.27000000","0.00408000"],["78384.63000000","0.03400000"]]}}
{"rx":1788854512038172366, "m":{"e":"depthUpdate","E":1788854512014,"s":"BTCUSDT","U":99829840365,"u":99829840416,"b":[["78328.00000000","0.23090000"],["78327.99000000","0.00076000"],["78324.00000000","0.03014000"],["78323.24000000","0.00000000"],["78321.66000000","0.00807000"],["78312.92000000","0.02000000"],["78312.90000000","0.00419000"],["78312.15000000","0.02000000"],["78305.38000000","0.86421000"],["78301.24000000","0.00000000"],["78296.99000000","0.12771000"],["78286.00000000","0.73000000"],["78274.01000000","0.96246000"],["78262.01000000","0.02000000"],["78261.27000000","0.02000000"],["78203.51000000","0.02903000"],["78196.52000000","0.00000000"],["78191.57000000","0.00009000"],["77153.08000000","0.00062000"],["70495.20000000","0.00048000"],["62666.37000000","0.00155000"],["62662.40000000","0.00124000"]],"a":[["78328.01000000","6.42933000"],["78331.89000000","0.00026000"],["78332.95000000","1.32019000"],["78332.97000000","2.47105000"],["78334.85000000","0.00000000"],["78335.61000000","0.12765000"],["78340.63000000","0.03400000"],["78340.72000000","0.04200000"],["78341.52000000","0.03800000"],["78344.53000000","0.02600000"],["78349.99000000","0.00007000"],["78353.82000000","0.00000000"],["78357.71000000","0.20807000"],["78379.85000000","0.03400000"],["78383.75000000","0.02600000"],["78387.69000000","0.36776000"],["78435.29000000","0.00012000"],["78440.25000000","0.00000000"],["78445.35000000","0.00000000"],["78450.27000000","0.00000000"],["78450.31000000","0.00000000"],["78477.99000000","0.01808000"]]}}
{"rx":1788854512138178883, "m":{"e":"depthUpdate","E":1788854512114,"s":"BTCUSDT","U":99829840417,"u":99829840433,"b":[["78300.49000000","0.00000000"],["78251.18000000","0.00000000"],["77627.96000000","0.00000000"]],"a":[["78329.36000000","0.00007000"],["78332.97000000","2.49255000"],["78340.81000000","0.22355000"],["78348.65000000","0.02169000"],["78349.93000000","0.00000000"],["78350.79000000","0.00000000"],["78354.73000000","0.00000000"],["78356.49000000","0.02083000"],["78364.33000000","0.02072000"],["78396.47000000","0.00000000"],["78440.16000000","0.00000000"],["78440.38000000","0.00019000"],["78445.34000000","0.00031000"]]}}
{"rx":1788854512237957242, "m":{"e":"depthUpdate","E":1788854512214,"s":"BTCUSDT","U":99829840434,"u":99829840447,"b":[["78104.65000000","0.00094000"],["78099.77000000","0.00802000"],["77153.08000000","0.00062000"],["70495.20000000","0.00073000"],["62666.37000000","0.00124000"]],"a":[["78328.01000000","6.42896000"],["78332.02000000","0.01154000"],["78332.97000000","2.50588000"],["78336.89000000","0.01310000"],["78340.81000000","0.23654000"],["78348.65000000","0.03480000"],["78384.15000000","0.00013000"],["79502.94000000","0.00030000"]]}}
{"rx":1788854512338322984, "m":{"e":"depthUpdate","E":1788854512314,"s":"BTCUSDT","U":99829840448,"u":99829840564,"b":[["78328.00000000","0.05825000"],["78324.93000000","0.00000000"],["78324.92000000","0.00014000"],["78323.77000000","0.00000000"],["78323.17000000","0.00000000"],["78322.01000000","0.00014000"],["78321.95000000","0.00007000"],["78321.23000000","0.00000000"],["78320.91000000","0.00000000"],["78320.23000000","0.00000000"],["78320.11000000","0.03000000"],["78320.10000000","0.07238000"],["78320.09000000","0.15384000"],["78319.71000000","0.00007000"],["78319.41000000","0.00000000"],["78318.01000000","0.00000000"],["78317.50000000","0.02000000"],["78317.23000000","0.10009000"],["78317.21000000","0.00000000"],["78316.87000000","0.00000000"],["78316.54000000","0.00400000"],["78316.40000000","0.00000000"],["78316.31000000","0.00000000"],["78315.72000000","0.00007000"],["78315.26000000","0.48985000"],["78314.57000000","0.00000000"],["78314.35000000","0.48985000"],["78314.03000000","0.00000000"],["78313.44000000","0.48985000"],["78313.40000000","0.48985000"],["78312.90000000","0.00000000"],["78312.89000000","0.00000000"],["78312.76000000","0.02141000"],["78312.61000000","0.00000000"],["78312.34000000","0.00638000"],["78312.10000000","0.00000000"],["78311.85000000","0.00000000"],["78311.73000000","0.00078000"],["78311.68000000","0.00400000"],["78311.65000000","0.01315000"],["78311.10000000","0.12000000"],["78310.52000000","0.00400000"],["78310.29000000","0.00400000"],["78309.59000000","1.91454000"],["78309.58000000","0.00000000"],["78307.74000000","0.00014000"],["78306.94000000","0.20690000"],["78304.81000000","0.00000000"],["78301.49000000","2.29802000"],["78301.48000000","0.00000000"],["78301.47000000","0.00000000"],["78295.98000000","0.00000000"],["78294.71000000","0.00000000"],["78288.73000000","0.32679000"],["78286.12000000","0.00000000"],["78279.81000000","0.00007000"],["78278.95000000","0.03828000"],["78269.76000000","0.00400000"],["78265.69000000","0.00000000"],["78260.91000000","0.00008000"],["78234.33000000","0.00000000"],["78231.09000000","0.00000000"],["78227.22000000","0.00000000"],["78163.33000000","0.12775000"],["77292.28000000","0.00000000"],["77153.08000000","0.00062000"]],"a":[["78328.01000000","6.54896000"],["78328.09000000","0.07179000"],["78329.43000000","0.00014000"],["78332.97000000","2.46457000"],["78336.89000000","0.00000000"],["78340.81000000","0.20250000"],["78347.52000000","0.00400000"],["78348.65000000","0.00000000"],["78349.27000000","0.00000000"],["78356.49000000","0.00000000"],["78364.33000000","0.00000000"],["78374.76000000","0.00000000"],["78387.70000000","0.00000000"],["78388.45000000","0.00000000"],["78419.79000000","0.00000000"],["78427.22000000","0.07839000"],["78668.09000000","0.00000000"],["82921.18000000","0.00000000"]]}}
{"rx":1788854512438533364, "m":{"e":"depthUpdate","E":1788854512414,"s":"BTCUSDT","U":99829840565,"u":99829840659,"b":[["78328.00000000","0.23689000"],["78327.99000000","0.00076000"],["78326.00000000","0.03014000"],["78324.92000000","0.00000000"],["78324.10000000","0.00026000"],["78323.18000000","0.00000000"],["78322.60000000","0.00014000"],["78322.59000000","0.16809000"],["78321.95000000","0.00000000"],["78321.66000000","0.00807000"],["78320.97000000","0.08303000"],["78320.96000000","0.13691000"],["78320.41000000","0.00966000"],["78320.10000000","0.00000000"],["78320.09000000","0.00000000"],["78317.50000000","0.00000000"],["78317.24000000","0.48985000"],["78317.23000000","0.37553000"],["78316.22000000","0.00400000"],["78316.17000000","0.48985000"],["78315.27000000","0.00800000"],["78315.26000000","0.00000000"],["78314.35000000","0.00000000"],["78313.44000000","0.00000000"],["78313.40000000","0.00000000"],["78312.56000000","0.00048000"],["78311.68000000","0.00000000"],["78310.52000000","0.00000000"],["78310.29000000","0.00000000"],["78279.81000000","0.00000000"],["78277.32000000","0.00335000"],["78163.33000000","0.00000000"],["78066.92000000","0.00000000"],["78066.72000000","0.00000000"],["78002.82000000","0.02751000"],["78002.48000000","0.01920000"],["77153.08000000","0.00062000"],["70495.20000000","0.00089000"],["62666.37000000","0.00093000"]],"a":[["78328.01000000","6.54911000"],["78329.27000000","0.01774000"],["78329.43000000","0.00000000"],["78331.77000000","0.02126000"],["78363.56000000","0.00619000"],["78364.71000000","0.00426000"],["78373.54000000","0.00000000"],["78374.67000000","0.00000000"],["78387.69000000","0.00000000"],["78422.65000000","0.00007000"],["78424.94000000","0.00000000"],["78436.23000000","0.00000000"]]}}
{"rx":1788854512537635153, "m":{"e":"depthUpdate","E":1788854512514,"s":"BTCUSDT","U":99829840660,"u":99829840718,"b":[["78328.00000000","0.26479000"],["78324.00000000","0.03014000"],["78322.59000000","0.16823000"],["78321.66000000","0.00807000"],["78320.41000000","0.00952000"],["78319.71000000","0.00014000"],["78317.25000000","0.36375000"],["78317.24000000","0.00000000"],["78317.23000000","0.00000000"],["78316.17000000","0.48985000"],["78315.72000000","0.00014000"],["78315.27000000","0.00000000"],["78315.26000000","0.48985000"],["78314.18000000","0.01309000"],["78311.73000000","0.00085000"],["78311.11000000","0.01200000"],["78288.66000000","0.53616000"],["78286.50000000","0.88522000"],["78244.78000000","0.00010000"],["78207.63000000","0.00068000"],["78062.55000000","0.00000000"],["77997.63000000","0.01888000"],["77153.08000000","0.00062000"],["62662.40000000","0.00248000"]],"a":[["78328.01000000","6.54911000"],["78334.71000000","0.00007000"],["78343.06000000","0.00408000"],["78378.15000000","0.88418000"],["78396.61000000","0.02600000"],["78440.15000000","0.00000000"]]}}
{"rx":1788854512638641877, "m":{"e":"depthUpdate","E":1788854512614,"s":"BTCUSDT","U":99829840719,"u":99829840878,"b":[["78328.00000000","0.05621000"],["78327.99000000","0.00076000"],["78324.10000000","0.00000000"],["78324.02000000","0.00014000"],["78324.01000000","0.02323000"],["78323.01000000","0.00000000"],["78323.00000000","0.00000000"],["78322.60000000","0.00000000"],["78322.59000000","0.00014000"],["78322.58000000","0.00014000"],["78321.94000000","0.00014000"],["78320.98000000","0.00007000"],["78320.97000000","0.04212000"],["78320.96000000","0.00000000"],["78320.11000000","0.00000000"],["78319.71000000","0.00007000"],["78319.41000000","0.03000000"],["78318.76000000","0.00000000"],["78318.68000000","0.00000000"],["78317.26000000","0.48985000"],["78317.25000000","0.70016000"],["78317.08000000","0.02000000"],["78316.54000000","0.00000000"],["78316.22000000","0.00000000"],["78316.17000000","0.00000000"],["78315.72000000","0.00014000"],["78315.33000000","0.00000000"],["78315.26000000","0.00000000"],["78315.09000000","0.10724000"],["78315.07000000","0.00000000"],["78314.35000000","0.00000000"],["78314.18000000","0.00000000"],["78313.97000000","0.00000000"],["78313.44000000","0.00000000"],["78313.40000000","0.00000000"],["78313.39000000","0.88702000"],["78312.76000000","0.00000000"],["78312.54000000","0.00069000"],["78312.09000000","0.31932000"],["78311.65000000","0.00000000"],["78311.60000000","0.00000000"],["78311.12000000","0.00400000"],["78311.11000000","0.00800000"],["78310.99000000","0.00000000"],["78309.60000000","1.91454000"],["78309.59000000","0.00000000"],["78304.61000000","0.00000000"],["78303.67000000","0.00000000"],["78297.33000000","0.00024000"],["78288.46000000","0.00000000"],["78283.38000000","0.00000000"],["78281.91000000","0.63890000"],["78279.81000000","0.00007000"],["78279.50000000","0.00667000"],["78276.17000000","0.00000000"],["78275.82000000","0.00000000"],["78266.88000000","0.00400000"],["78264.66000000","0.00430000"],["78254.38000000","0.00000000"],["78250.61000000","0.00180000"],["78250.60000000","1.26553000"],["78237.25000000","0.00000000"],["78176.48000000","0.00000000"],["78169.78000000","0.00072000"],["78167.45000000","0.20250000"],["78062.41000000","0.00000000"],["77996.17000000","0.01940000"],["77924.70000000","0.00007000"],["77153.08000000","0.00062000"],["70495.20000000","0.00096000"],["70495.19000000","0.00009000"],["62666.37000000","0.00062000"]],"a":[["78328.01000000","6.54900000"],["78330.14000000","0.00007000"],["78332.94000000","0.00400000"],["78339.11000000","0.00000000"],["78341.99000000","1.26114000"],["78343.30000000","0.63840000"],["78343.65000000","0.00014000"],["78357.00000000","0.34467000"],["78367.47000000","0.00860000"],["78372.05000000","0.00000000"],["78378.05000000","0.00000000"],["78378.72000000","0.00000000"],["78378.87000000","0.00000000"]]}}
{"rx":1788854512738268251, "m":{"e":"depthUpdate","E":1788854512714,"s":"BTCUSDT","U":99829840879,"u":99829840976,"b":[["78326.00000000","0.03014000"],["78324.02000000","0.00000000"],["78324.01000000","0.00028000"],["78324.00000000","0.03014000"],["78322.94000000","0.00000000"],["78322.59000000","0.00000000"],["78322.58000000","0.00000000"],["78322.00000000","0.03014000"],["78321.94000000","0.00000000"],["78320.98000000","0.00014000"],["78320.97000000","0.16834000"],["78320.41000000","0.00966000"],["78320.01000000","0.00007000"],["78318.01000000","0.46428000"],["78317.27000000","0.10725000"],["78317.26000000","0.00000000"],["78317.25000000","0.00000000"],["78317.08000000","0.00000000"],["78316.64000000","0.00400000"],["78315.72000000","0.00007000"],["78315.26000000","0.48985000"],["78315.09000000","0.00000000"],["78315.08000000","0.02000000"],["78314.39000000","0.00400000"],["78314.35000000","0.48985000"],["78313.44000000","0.48985000"],["78313.40000000","0.44905000"],["78313.39000000","0.87971000"],["78311.12000000","0.00400000"],["78311.11000000","0.00000000"],["78310.64000000","0.00400000"],["78310.52000000","0.00400000"],["78309.63000000","2.29035000"],["78309.60000000","0.00000000"],["78309.57000000","0.00000000"],["78286.00000000","0.03000000"],["78227.76000000","0.00408000"],["78179.58000000","0.00016000"],["78171.69000000","0.00665000"],["78168.52000000","0.00068000"],["77924.70000000","0.00014000"],["77153.08000000","0.00062000"],["70495.20000000","0.00112000"],["70495.00000000","0.00020000"],["62666.00000000","4.06391000"]],"a":[["78328.01000000","6.55032000"],["78332.97000000","2.46304000"],["78445.18000000","0.96083000"],["78445.19000000","0.00000000"]]}}
{"rx":1788854512839296787, "m":{"e":"depthUpdate","E":1788854512814,"s":"BTCUSDT","U":99829840977,"u":99829841053,"b":[["78328.00000000","0.22871000"],["78326.00000000","0.03014000"],["78324.02000000","0.00014000"],["78324.01000000","0.02267000"],["78323.71000000","0.00026000"],["78320.97000000","0.34904000"],["78320.01000000","0.00000000"],["78320.00000000","0.03014000"],["78318.96000000","0.48985000"],["78318.95000000","0.14379000"],["78318.90000000","0.00000000"],["78318.02000000","0.00000000"],["78318.01000000","0.00000000"],["78317.27000000","0.52625000"],["78316.17000000","0.00000000"],["78315.72000000","0.00014000"],["78315.28000000","0.00000000"],["78315.27000000","0.01200000"],["78315.26000000","0.00000000"],["78314.35000000","0.00000000"],["78313.56000000","0.00048000"],["78313.44000000","0.00000000"],["78313.40000000","0.00000000"],["78313.39000000","0.85662000"],["78311.12000000","0.00000000"],["78310.64000000","0.00000000"],["78310.52000000","0.00000000"],["77924.70000000","0.00007000"],["77153.08000000","0.00070000"],["70495.00000000","0.00000000"],["62666.37000000","0.00031000"],["62662.40000000","0.00248000"]],"a":[["78328.01000000","6.55032000"],["78347.07000000","0.00059000"],["78360.48000000","0.00000000"],["78419.99000000","0.75282000"],["78422.08000000","2.46943000"],["78423.32000000","3.68317000"]]}}
{"rx":1788854512939617333, "m":{"e":"depthUpdate","E":1788854512914,"s":"BTCUSDT","U":99829841054,"u":99829841102,"b":[["78326.00000000","0.03014000"],["78320.98000000","0.00014000"],["78320.97000000","0.07914000"],["78320.52000000","0.14726000"],["78319.81000000","0.00000000"],["78318.96000000","0.00000000"],["78318.95000000","0.00000000"],["78317.28000000","0.48985000"],["78317.27000000","0.10725000"],["78316.17000000","0.00000000"],["78315.27000000","0.00000000"],["78315.26000000","0.48985000"],["78314.69000000","0.48985000"],["78314.68000000","0.10724000"],["78314.35000000","0.00000000"],["78311.11000000","0.01200000"],["78298.23000000","0.00408000"],["77153.08000000","0.00070000"],["70495.20000000","0.00128000"],["62662.40000000","0.00248000"]],"a":[["78339.76000000","0.00033000"],["78342.94000000","0.00000000"],["78458.29000000","0.00111000"]]}}
{"rx":1788854513050805368, "m":{"e":"depthUpdate","E":1788854513014,"s":"BTCUSDT","U":99829841103,"u":99829841170,"b":[["78328.00000000","0.05621000"],["78324.01000000","0.02281000"],["78320.97000000","0.17688000"],["78320.52000000","0.00000000"],["78320.00000000","0.03000000"],["78318.90000000","0.48985000"],["78318.01000000","0.48985000"],["78317.29000000","0.56138000"],["78317.28000000","0.00000000"],["78317.27000000","0.00000000"],["78316.17000000","0.48985000"],["78315.27000000","0.00400000"],["78315.26000000","0.48985000"],["78314.69000000","0.00000000"],["78313.44000000","0.00000000"],["78313.40000000","0.00000000"],["78311.11000000","0.00400000"],["78304.71000000","0.00000000"],["78301.50000000","1.99563000"],["78281.73000000","0.00015000"],["78278.40000000","0.00400000"],["78266.88000000","0.00000000"],["78245.91000000","0.07282000"],["77153.08000000","0.00070000"],["62666.37000000","0.00000000"]],"a":[["78328.01000000","6.55032000"],["78356.99000000","0.32291000"],["78357.71000000","0.00000000"],["78387.99000000","0.10265000"]]}}
{"rx":1788854513152216902, "m":{"e":"depthUpdate","E":1788854513114,"s":"BTCUSDT","U":99829841171,"u":99829841223,"b":[["78328.00000000","0.05621000"],["78320.97000000","0.17497000"],["78320.64000000","0.00000000"],["78319.81000000","0.48985000"],["78318.90000000","0.00000000"],["78318.01000000","0.00000000"],["78317.29000000","0.26775000"],["78316.17000000","0.48985000"],["78315.27000000","0.00000000"],["78315.26000000","0.48985000"],["78311.11000000","0.01200000"],["78310.18000000","0.01309000"],["78162.05000000","0.00047000"],["78095.56000000","0.00007000"],["77623.05000000","0.00010000"],["77153.08000000","0.00062000"],["70495.20000000","0.00144000"],["62666.00000000","4.06591000"]],"a":[["78328.01000000","6.55050000"],["78331.38000000","0.00000000"],["78337.49000000","0.06088000"],["78399.28000000","0.00000000"],["78412.29000000","0.00000000"],["78413.57000000","0.00408000"],["78425.13000000","0.00025000"],["78430.09000000","0.00000000"],["78497.51000000","0.00111000"]]}}
{"rx":1788854513247885717, "m":{"e":"depthUpdate","E":1788854513214,"s":"BTCUSDT","U":99829841224,"u":99829841296,"b":[["78328.00000000","0.05621000"],["78320.97000000","0.32309000"],["78319.89000000","0.14674000"],["78319.81000000","0.00000000"],["78318.90000000","0.48985000"],["78318.01000000","0.48985000"],["78317.30000000","0.48985000"],["78317.29000000","0.13951000"],["78316.18000000","0.00000000"],["78316.17000000","0.00000000"],["78315.26000000","0.00000000"],["78313.44000000","0.00000000"],["78310.67000000","0.02141000"],["78310.18000000","0.00000000"],["78309.93000000","0.01286000"],["78308.53000000","0.02000000"],["78253.19000000","0.02000000"],["78249.74000000","0.00000000"],["78234.62000000","1.00182000"],["78202.05000000","0.01533000"],["78161.49000000","0.05621000"],["77292.28000000","0.00010000"],["77153.08000000","0.00062000"],["70495.20000000","0.00160000"],["62666.00000000","4.06391000"],["62662.40000000","0.00217000"]],"a":[["78328.01000000","6.56377000"],["78335.85000000","0.00055000"],["78339.77000000","0.01330000"],["78343.69000000","0.01326000"],["78351.53000000","0.00000000"],["78359.37000000","0.00000000"],["79502.94000000","0.00030000"]]}}
{"rx":1788854513340084409, "m":{"e":"depthUpdate","E":1788854513314,"s":"BTCUSDT","U":99829841297,"u":99829841337,"b":[["78328.00000000","0.05978000"],["78321.47000000","0.15187000"],["78320.99000000","0.37133000"],["78320.98000000","0.48992000"],["78320.97000000","0.00014000"],["78319.89000000","0.00000000"],["78318.01000000","0.00000000"],["78317.30000000","0.00000000"],["78317.29000000","0.39771000"],["78316.17000000","0.48985000"],["78315.26000000","0.00000000"],["78259.08000000","0.00408000"],["77153.08000000","0.00062000"],["62662.00000000","0.00000000"]],"a":[["78328.01000000","6.55049000"],["78332.00000000","0.00364000"],["78334.00000000","0.00500000"],["78339.77000000","0.00000000"],["78343.69000000","0.00000000"]]}}
{"rx":1788854513450858176, "m":{"e":"depthUpdate","E":1788854513414,"s":"BTCUSDT","U":99829841338,"u":99829841391,"b":[["78328.00000000","0.23478000"],["78324.01000000","0.06534000"],["78321.66000000","0.00807000"],["78321.48000000","0.00007000"],["78321.47000000","0.15201000"],["78320.99000000","0.30517000"],["78320.98000000","0.00000000"],["78320.97000000","0.00000000"],["78320.41000000","0.00952000"],["78319.81000000","0.48985000"],["78317.30000000","0.48985000"],["78317.29000000","0.26790000"],["78316.17000000","0.48985000"],["78237.02000000","0.00007000"],["78161.49000000","0.00000000"],["77153.08000000","0.00062000"],["70495.20000000","0.00176000"],["70495.19000000","0.00000000"],["62662.40000000","0.00186000"]],"a":[["78328.01000000","6.55015000"],["78336.00000000","0.00500000"],["80900.00000000","4.97265000"]]}}
{"rx":1788854513547667582, "m":{"e":"depthUpdate","E":1788854513514,"s":"BTCUSDT","U":99829841392,"u":99829841517,"b":[["78328.00000000","0.73764000"],["78327.99000000","0.00090000"],["78324.01000000","0.07296000"],["78322.55000000","0.00000000"],["78322.54000000","0.00000000"],["78322.52000000","0.00014000"],["78322.51000000","0.16747000"],["78322.01000000","0.00007000"],["78321.63000000","0.00000000"],["78321.49000000","0.00000000"],["78321.48000000","0.00000000"],["78321.47000000","0.00014000"],["78321.00000000","0.00007000"],["78320.99000000","0.32424000"],["78320.72000000","0.48985000"],["78319.81000000","0.48985000"],["78319.71000000","0.00014000"],["78318.90000000","0.48985000"],["78317.61000000","0.00400000"],["78317.30000000","0.00000000"],["78317.29000000","0.13951000"],["78316.17000000","0.00000000"],["78314.68000000","0.00000000"],["78314.39000000","0.00000000"],["78312.45000000","0.01293000"],["78301.97000000","0.38324000"],["78298.23000000","0.00000000"],["78288.66000000","0.00000000"],["78279.81000000","0.00000000"],["78271.00000000","0.00000000"],["78259.08000000","0.00000000"],["78253.19000000","0.00000000"],["78250.60000000","0.00000000"],["78246.18000000","0.00007000"],["78227.76000000","0.00000000"],["78162.68000000","0.00000000"],["78160.46000000","0.00000000"],["78160.41000000","0.00000000"],["77153.08000000","0.00062000"],["62662.40000000","0.00310000"]],"a":[["78328.01000000","6.49979000"],["78331.28000000","0.00638000"],["78331.89000000","0.00000000"],["78334.00000000","0.01000000"],["78335.85000000","0.00056000"],["78336.00000000","0.01000000"],["78343.06000000","0.00000000"],["78343.68000000","0.00064000"],["78351.51000000","0.00064000"],["78354.53000000","0.00000000"],["78359.35000000","0.00056000"],["78379.53000000","0.00000000"],["78382.24000000","0.00408000"],["78413.57000000","0.00000000"],["82921.18000000","0.00010000"]]}}
{"rx":1788854513649215021, "m":{"e":"depthUpdate","E":1788854513614,"s":"BTCUSDT","U":99829841518,"u":99829841659,"b":[["78328.00000000","0.60543000"],["78327.99000000","0.00090000"],["78324.20000000","0.00000000"],["78324.19000000","0.00000000"],["78324.01000000","0.02291000"],["78324.00000000","0.03014000"],["78322.55000000","0.00000000"],["78322.54000000","0.00000000"],["78322.52000000","0.00000000"],["78322.51000000","0.00014000"],["78322.01000000","0.00014000"],["78321.66000000","0.00807000"],["78321.63000000","0.00000000"],["78321.47000000","0.00000000"],["78321.00000000","0.00007000"],["78320.99000000","0.46549000"],["78320.72000000","0.00000000"],["78319.81000000","0.48985000"],["78318.90000000","0.48985000"],["78318.01000000","0.48985000"],["78317.30000000","0.47362000"],["78313.39000000","0.94032000"],["78312.45000000","0.00000000"],["78312.22000000","0.01326000"],["78309.64000000","0.00000000"],["78242.47000000","0.04530000"],["78239.77000000","2.29802000"],["78239.76000000","0.00000000"],["78229.01000000","0.07808000"],["77153.08000000","0.00062000"],["70495.20000000","0.00192000"],["62662.40000000","0.00279000"],["62662.00000000","0.00200000"]],"a":[["78328.01000000","6.39249000"],["78328.04000000","0.00014000"],["78328.08000000","0.00014000"],["78328.09000000","0.07186000"],["78328.37000000","0.00000000"],["78329.43000000","0.00400000"],["78329.55000000","0.00400000"],["78330.52000000","0.02126000"],["78331.28000000","0.00652000"],["78331.68000000","0.00007000"],["78331.77000000","0.02112000"],["78332.94000000","0.01200000"],["78335.67000000","0.00007000"],["78339.66000000","2.00671000"],["78343.65000000","0.00007000"],["78344.03000000","0.00000000"],["78347.33000000","0.00000000"],["78347.64000000","0.00007000"]]}}
{"rx":1788854513737170579, "m":{"e":"depthUpdate","E":1788854513714,"s":"BTCUSDT","U":99829841660,"u":99829841716,"b":[["78328.00000000","0.60619000"],["78327.99000000","0.00076000"],["78324.00000000","0.03014000"],["78322.51000000","0.00000000"],["78321.02000000","0.00007000"],["78321.01000000","0.16996000"],["78321.00000000","0.44788000"],["78320.99000000","0.00014000"],["78320.41000000","0.00966000"],["78319.81000000","0.00000000"],["78318.90000000","0.00000000"],["78318.01000000","0.00000000"],["78317.30000000","0.48985000"],["78312.47000000","0.01286000"],["78312.22000000","0.00000000"],["78275.52000000","0.00400000"],["78269.76000000","0.00000000"],["78159.78000000","0.00000000"],["77153.08000000","0.00062000"],["62662.00000000","0.00000000"]],"a":[["78328.01000000","6.39249000"],["78331.68000000","0.00014000"],["78335.67000000","0.00014000"],["78337.49000000","0.00000000"],["78339.66000000","2.00678000"],["78341.42000000","0.00408000"],["78343.65000000","0.00014000"],["78347.64000000","0.00014000"],["78520.18000000","0.00000000"]]}}
{"rx":1788854513837545638, "m":{"e":"depthUpdate","E":1788854513814,"s":"BTCUSDT","U":99829841717,"u":99829841761,"b":[["78328.00000000","0.60779000"],["78322.62000000","0.15856000"],["78321.66000000","0.00807000"],["78321.01000000","0.42490000"],["78320.99000000","0.00000000"],["78318.01000000","0.48985000"],["78314.65000000","0.00000000"],["78312.47000000","0.00000000"],["78312.43000000","0.01317000"],["78292.05000000","0.50436000"],["78267.06000000","1.03583000"],["78103.95000000","0.00000000"],["77995.41000000","0.10000000"],["77153.08000000","0.00070000"],["70495.20000000","0.00217000"],["70495.00000000","0.00000000"],["62662.40000000","0.00248000"]],"a":[["78328.01000000","6.39204000"],["78331.84000000","0.00026000"],["78349.60000000","0.51019000"],["78374.60000000","1.02347000"],["78389.27000000","0.00637000"],["78527.19000000","0.00000000"]]}}
{"rx":1788854513941202105, "m":{"e":"depthUpdate","E":1788854513914,"s":"BTCUSDT","U":99829841762,"u":99829841800,"b":[["78328.00000000","0.60779000"],["78327.99000000","0.00083000"],["78324.01000000","0.06732000"],["78324.00000000","0.03014000"],["78322.63000000","0.00014000"],["78322.62000000","0.15870000"],["78321.02000000","0.00000000"],["78321.01000000","0.31723000"],["78321.00000000","0.00000000"],["78320.41000000","0.00952000"],["78318.90000000","0.45132000"],["78317.30000000","0.00000000"],["78226.14000000","0.00408000"],["77153.08000000","0.00070000"],["70495.20000000","0.00233000"],["62662.40000000","0.00248000"]],"a":[["78328.01000000","6.39173000"],["78339.76000000","0.00033000"],["78526.85000000","0.00000000"],["78526.89000000","0.00007000"],["78617.60000000","0.00000000"]]}}
{"rx":1788854514040804774, "m":{"e":"depthUpdate","E":1788854514014,"s":"BTCUSDT","U":99829841801,"u":99829841851,"b":[["78328.00000000","0.50360000"],["78324.01000000","0.02291000"],["78322.63000000","0.00000000"],["78322.62000000","0.00014000"],["78321.02000000","0.00007000"],["78321.01000000","0.17101000"],["78318.01000000","0.00000000"],["78317.30000000","0.48985000"],["78317.29000000","0.21988000"],["78316.17000000","0.44023000"],["78250.61000000","0.00000000"],["78250.18000000","0.00179000"],["78242.47000000","0.77776000"],["78229.01000000","0.00000000"],["78171.70000000","0.00072000"],["78169.78000000","0.00000000"],["77153.08000000","0.00070000"],["62662.40000000","0.00341000"]],"a":[["78328.01000000","6.39106000"],["78334.00000000","0.02000000"],["78336.00000000","0.02000000"],["78339.66000000","2.29960000"],["78349.59000000","2.00664000"],["78375.99000000","0.63548000"],["78423.05000000","1.76474000"],["78445.98000000","0.00000000"],["78527.30000000","0.00000000"],["78527.62000000","0.00000000"]]}}
{"rx":1788854514143079568, "m":{"e":"depthUpdate","E":1788854514114,"s":"BTCUSDT","U":99829841852,"u":99829841888,"b":[["78328.00000000","0.22978000"],["78327.99000000","0.00076000"],["78324.00000000","0.03014000"],["78322.62000000","0.00000000"],["78321.01000000","0.29539000"],["78320.41000000","0.00966000"],["78317.61000000","0.00000000"],["78317.29000000","0.13951000"],["78316.46000000","0.00400000"],["78316.17000000","0.00000000"],["78312.43000000","0.00000000"],["78296.61000000","0.00408000"],["77153.08000000","0.00062000"],["70495.20000000","0.00249000"]],"a":[["78328.04000000","0.00000000"],["78328.08000000","0.00000000"],["78328.09000000","0.07179000"],["78349.58000000","1.80295000"],["78349.88000000","0.00000000"],["78366.19000000","1.32348000"],["78445.18000000","0.00000000"],["78527.45000000","0.00000000"]]}}
{"rx":1788854514237748717, "m":{"e":"depthUpdate","E":1788854514214,"s":"BTCUSDT","U":99829841889,"u":99829841898,"b":[["78273.60000000","0.00400000"],["78273.52000000","0.00000000"],["77153.08000000","0.00062000"],["62666.00000000","4.06391000"],["62662.40000000","0.00310000"]],"a":[["78334.00000000","0.03000000"],["79502.94000000","0.00030000"]]}}
{"rx":1788854514344016596, "m":{"e":"depthUpdate","E":1788854514314,"s":"BTCUSDT","U":99829841899,"u":99829841971,"b":[["78328.00000000","0.22970000"],["78323.71000000","0.00000000"],["78321.10000000","0.00000000"],["78321.09000000","0.00000000"],["78321.04000000","0.00007000"],["78321.03000000","0.03500000"],["78321.02000000","0.00000000"],["78321.01000000","0.00014000"],["78319.71000000","0.00007000"],["78318.90000000","0.00000000"],["78317.30000000","0.00000000"],["78317.29000000","0.52714000"],["78316.46000000","0.00000000"],["78316.17000000","0.48985000"],["78315.26000000","0.48985000"],["78314.68000000","0.00000000"],["78314.35000000","0.48985000"],["78301.97000000","0.00000000"],["78286.00000000","0.73000000"],["78279.81000000","0.00007000"],["78251.26000000","1.26552000"],["77153.08000000","0.00062000"],["70495.20000000","0.00265000"]],"a":[["78328.01000000","6.39744000"],["78328.23000000","0.00000000"],["78329.56000000","0.00000000"],["78331.28000000","0.00014000"],["78333.48000000","0.00000000"],["78336.00000000","0.03000000"],["78337.40000000","0.00000000"],["78341.32000000","0.04000000"],["78345.24000000","0.00000000"],["78351.75000000","0.00000000"],["78359.59000000","0.00000000"],["78411.93000000","0.00408000"]]}}
{"rx":1788854514449693396, "m":{"e":"depthUpdate","E":1788854514414,"s":"BTCUSDT","U":99829841972,"u":99829842014,"b":[["78328.00000000","0.23554000"],["78321.66000000","0.00807000"],["78321.03000000","0.18045000"],["78321.01000000","0.00000000"],["78318.01000000","0.48985000"],["78317.30000000","0.01200000"],["78317.29000000","0.48976000"],["78315.60000000","0.00400000"],["78314.35000000","0.00000000"],["78311.11000000","0.00000000"],["78020.00000000","0.51381000"],["77153.08000000","0.00062000"],["62662.40000000","0.00279000"]],"a":[["78328.80000000","0.00400000"],["78330.52000000","0.02126000"],["78331.28000000","0.00000000"],["78331.77000000","0.02126000"],["78337.08000000","0.00400000"],["78370.68000000","0.00000000"],["78372.72000000","0.00000000"],["78419.09000000","0.01513000"],["78450.05000000","0.00007000"]]}}
{"rx":1788854514541415413, "m":{"e":"depthUpdate","E":1788854514514,"s":"BTCUSDT","U":99829842015,"u":99829842044,"b":[["78321.03000000","0.37835000"],["78318.90000000","0.48985000"],["78317.31000000","0.00000000"],["78317.30000000","0.00000000"],["78317.29000000","0.13951000"],["78316.17000000","0.00000000"],["78315.26000000","0.00000000"],["78313.40000000","0.00000000"],["78311.11000000","0.01200000"],["78252.28000000","0.00007000"],["77153.08000000","0.00062000"],["70495.20000000","0.00281000"]],"a":[["78332.97000000","2.46312000"],["78450.47000000","0.00028000"]]}}
{"rx":1788854514640062478, "m":{"e":"depthUpdate","E":1788854514614,"s":"BTCUSDT","U":99829842045,"u":99829842065,"b":[["78328.00000000","0.23546000"],["78323.71000000","0.00026000"],["78320.08000000","0.13458000"],["77153.08000000","0.00062000"],["70495.20000000","0.00297000"],["62662.40000000","0.00248000"],["62662.00000000","0.00000000"]],"a":[["78328.01000000","6.39776000"],["78421.33000000","2.68103000"],["78468.67000000","0.00000000"],["78526.85000000","0.00000000"],["78527.05000000","0.00000000"],["79040.64000000","0.00122000"]]}}
{"rx":1788854514738172355, "m":{"e":"depthUpdate","E":1788854514714,"s":"BTCUSDT","U":99829842066,"u":99829842093,"b":[["78328.00000000","0.23652000"],["78321.03000000","0.22151000"],["78320.41000000","0.00966000"],["78318.01000000","0.00000000"],["78317.29000000","0.36979000"],["78316.17000000","0.48985000"],["78315.26000000","0.48985000"],["78314.35000000","0.00000000"],["78285.00000000","0.63468000"],["77153.08000000","0.00062000"],["70495.20000000","0.00288000"],["70495.19000000","0.00009000"]],"a":[["78328.01000000","6.29205000"],["78465.91000000","0.01864000"],["79159.21000000","0.00139000"]]}}
