{"rx":1788854514853604064, "m":{"e":"depthUpdate","E":1788854514814,"s":"BTCUSDT","U":99829842094,"u":99829842113,"b":[["78328.00000000","0.23994000"],["78322.32000000","0.14946000"],["78321.03000000","0.33943000"],["78320.09000000","0.48985000"],["78320.08000000","0.00000000"],["78317.29000000","0.25372000"],["78315.26000000","0.00000000"],["78301.76000000","0.38324000"],["78290.43000000","0.00000000"],["77153.08000000","0.00070000"],["70495.20000000","0.00304000"],["62662.40000000","0.00217000"]],"a":[["78328.01000000","6.29130000"]]}}
{"rx":1788854514943440221, "m":{"e":"depthUpdate","E":1788854514914,"s":"BTCUSDT","U":99829842114,"u":99829842182,"b":[["78328.00000000","0.51235000"],["78327.99000000","0.00083000"],["78324.01000000","0.06461000"],["78324.00000000","0.03014000"],["78323.97000000","0.00014000"],["78323.96000000","0.12577000"],["78322.33000000","0.00000000"],["78322.32000000","0.00014000"],["78321.63000000","0.48984000"],["78321.04000000","0.43692000"],["78320.41000000","0.00952000"],["78320.09000000","0.00000000"],["78318.90000000","0.00000000"],["78317.29000000","0.10750000"],["78316.17000000","0.00000000"],["78315.10000000","0.00000000"],["78314.95000000","0.00000000"],["78314.87000000","0.00000000"],["78314.81000000","0.00000000"],["78314.78000000","0.00000000"],["78314.61000000","0.00000000"],["78312.73000000","0.00000000"],["78312.64000000","0.01303000"],["78296.61000000","0.00000000"],["78278.95000000","1.30336000"],["78257.46000000","0.00408000"],["78251.26000000","0.00000000"],["78226.14000000","0.00000000"],["77153.08000000","0.00070000"],["70495.00000000","0.00000000"],["62662.40000000","0.00217000"]],"a":[["78339.76000000","0.00026000"],["78341.42000000","0.00000000"],["78411.93000000","0.00000000"],["78459.62000000","0.02000000"],["78537.93000000","0.00000000"]]}}
{"rx":1788854515037864110, "m":{"e":"depthUpdate","E":1788854515014,"s":"BTCUSDT","U":99829842183,"u":99829842234,"b":[["78328.00000000","0.51235000"],["78327.99000000","0.00083000"],["78324.01000000","0.19850000"],["78324.00000000","0.03014000"],["78323.96000000","0.12591000"],["78322.32000000","0.00000000"],["78321.66000000","0.00807000"],["78321.63000000","0.48998000"],["78321.05000000","0.30478000"],["78321.04000000","0.00000000"],["78321.03000000","0.00000000"],["78318.01000000","0.48984000"],["78317.30000000","0.48984000"],["77153.08000000","0.00070000"],["70495.20000000","0.00320000"],["62662.40000000","0.00310000"]],"a":[["78339.76000000","0.00033000"],["78419.99000000","1.45916000"],["78443.99000000","0.02838000"]]}}
{"rx":1788854515136831376, "m":{"e":"depthUpdate","E":1788854515114,"s":"BTCUSDT","U":99829842235,"u":99829842247,"b":[["78328.00000000","0.51198000"],["78323.97000000","0.00000000"],["78323.96000000","0.00014000"],["78321.64000000","0.00007000"],["78321.63000000","0.48998000"],["77153.08000000","0.00062000"],["70495.19000000","0.00000000"]],"a":[["78459.62000000","0.00000000"],["79277.95000000","0.00160000"]]}}
{"rx":1788854515241816256, "m":{"e":"depthUpdate","E":1788854515214,"s":"BTCUSDT","U":99829842248,"u":99829842283,"b":[["78328.00000000","0.23615000"],["78327.99000000","0.00076000"],["78324.01000000","0.02293000"],["78324.00000000","0.03014000"],["78323.96000000","0.00000000"],["78321.64000000","0.00000000"],["78321.63000000","0.00014000"],["78321.06000000","0.00007000"],["78321.05000000","0.16739000"],["78317.30000000","0.00000000"],["78317.29000000","0.38620000"],["78316.17000000","0.48984000"],["78315.26000000","0.48984000"],["78312.64000000","0.00000000"],["77153.08000000","0.00062000"],["62662.40000000","0.00279000"]],"a":[["78508.36000000","0.02000000"]]}}
{"rx":1788854515341901701, "m":{"e":"depthUpdate","E":1788854515314,"s":"BTCUSDT","U":99829842284,"u":99829842381,"b":[["78328.00000000","0.23608000"],["78327.99000000","0.00076000"],["78324.02000000","0.00000000"],["78324.01000000","0.02281000"],["78323.71000000","0.00000000"],["78321.66000000","0.00807000"],["78321.63000000","0.00000000"],["78321.06000000","0.00014000"],["78321.05000000","0.03512000"],["78320.41000000","0.00966000"],["78320.01000000","0.00007000"],["78318.90000000","0.00000000"],["78318.01000000","0.00000000"],["78317.29000000","0.49501000"],["78316.17000000","0.00000000"],["78315.60000000","0.00000000"],["78315.26000000","0.48984000"],["78314.39000000","0.00400000"],["78314.35000000","0.48984000"],["78313.44000000","0.48984000"],["78313.40000000","0.00000000"],["78310.77000000","0.02094000"],["78310.67000000","0.00000000"],["78310.10000000","0.00000000"],["78309.97000000","0.01308000"],["78309.93000000","0.00000000"],["78295.53000000","0.00408000"],["77153.08000000","0.00062000"],["70495.20000000","0.00336000"]],"a":[["78328.01000000","6.29129000"],["78329.80000000","0.00000000"],["78333.72000000","0.00000000"],["78335.85000000","0.00058000"],["78337.64000000","0.00000000"],["78341.56000000","0.00000000"],["78343.68000000","0.00066000"],["78344.05000000","0.00000000"],["78345.48000000","0.00000000"],["78351.51000000","0.00066000"],["78351.89000000","0.00000000"],["78359.35000000","0.00058000"],["78359.73000000","0.00000000"],["79502.94000000","0.00030000"]]}}
{"rx":1788854515438010511, "m":{"e":"depthUpdate","E":1788854515414,"s":"BTCUSDT","U":99829842382,"u":99829842427,"b":[["78328.00000000","0.23597000"],["78327.99000000","0.00083000"],["78324.02000000","0.00014000"],["78323.67000000","0.00026000"],["78321.05000000","0.22511000"],["78320.01000000","0.00000000"],["78319.86000000","0.00000000"],["78318.01000000","0.00000000"],["78317.30000000","0.00000000"],["78317.29000000","0.27407000"],["78316.26000000","0.10724000"],["78315.27000000","0.00800000"],["78315.26000000","0.00000000"],["78314.35000000","0.48984000"],["78313.44000000","0.00000000"],["78312.19000000","0.00000000"],["78312.14000000","0.00000000"],["78312.05000000","0.00000000"],["78311.11000000","0.00400000"],["78250.18000000","0.00000000"],["78171.70000000","0.00000000"],["78012.27000000","0.00007000"],["77153.08000000","0.00062000"],["62662.40000000","0.00248000"]],"a":[["78328.01000000","6.39838000"]]}}
{"rx":1788854515537553358, "m":{"e":"depthUpdate","E":1788854515514,"s":"BTCUSDT","U":99829842428,"u":99829842454,"b":[["78321.05000000","0.17686000"],["78318.01000000","0.48984000"],["78317.30000000","0.00000000"],["78317.29000000","0.10988000"],["78315.28000000","0.46226000"],["78314.35000000","0.48984000"],["78312.09000000","0.31932000"],["78310.77000000","0.00000000"],["78309.97000000","0.00000000"],["78255.33000000","0.00007000"],["78250.18000000","0.00179000"],["78234.62000000","0.00000000"],["78231.99000000","1.00182000"],["78225.06000000","0.00437000"],["78171.70000000","0.00072000"],["77153.08000000","0.00062000"],["72089.37000000","0.00014000"],["70495.20000000","0.00352000"]],"a":[]}}
{"rx":1788854515647358095, "m":{"e":"depthUpdate","E":1788854515614,"s":"BTCUSDT","U":99829842455,"u":99829842479,"b":[["78328.00000000","0.23590000"],["78327.99000000","0.00076000"],["78324.02000000","0.00000000"],["78324.01000000","0.00028000"],["78320.01000000","0.00007000"],["78319.53000000","0.12143000"],["78318.90000000","0.48984000"],["78317.29000000","0.41193000"],["78315.28000000","0.00000000"],["78315.27000000","0.00000000"],["78314.35000000","0.48984000"],["78313.66000000","0.00000000"],["78313.44000000","0.00000000"],["78311.11000000","0.01200000"],["78279.63000000","0.00000000"],["78260.02000000","0.00000000"],["77153.08000000","0.00062000"],["62662.40000000","0.00217000"]],"a":[["78341.75000000","0.00000000"],["78380.97000000","0.00000000"],["78404.45000000","0.00000000"],["79396.87000000","0.00183000"]]}}
{"rx":1788854515749563398, "m":{"e":"depthUpdate","E":1788854515714,"s":"BTCUSDT","U":99829842480,"u":99829842523,"b":[["78328.00000000","0.06292000"],["78327.99000000","0.00083000"],["78326.00000000","0.03014000"],["78324.02000000","0.00014000"],["78324.01000000","0.02275000"],["78321.05000000","0.07141000"],["78320.01000000","0.00000000"],["78320.00000000","0.03014000"],["78318.90000000","0.00000000"],["78318.01000000","0.00000000"],["78317.29000000","0.38216000"],["78315.26000000","0.47555000"],["78315.08000000","0.00000000"],["78314.35000000","0.48984000"],["78313.28000000","0.02000000"],["78310.91000000","0.02135000"],["78310.10000000","0.01296000"],["77153.08000000","0.00062000"],["70495.20000000","0.00377000"]],"a":[["78328.01000000","6.39853000"]]}}
{"rx":1788854515852266777, "m":{"e":"depthUpdate","E":1788854515814,"s":"BTCUSDT","U":99829842524,"u":99829842581,"b":[["78328.00000000","0.23527000"],["78327.99000000","0.00076000"],["78326.00000000","0.03014000"],["78324.02000000","0.00000000"],["78324.01000000","0.00014000"],["78321.05000000","0.21765000"],["78320.01000000","0.00007000"],["78318.01000000","0.48984000"],["78317.30000000","0.00000000"],["78317.29000000","0.12995000"],["78315.28000000","0.48984000"],["78315.27000000","0.00800000"],["78315.26000000","0.00000000"],["78314.35000000","0.48984000"],["78312.11000000","0.00000000"],["78311.11000000","0.00400000"],["78310.91000000","0.00000000"],["78310.84000000","0.02107000"],["78310.10000000","0.00000000"],["78309.99000000","0.01327000"],["77153.08000000","0.00070000"],["70495.20000000","0.00393000"],["62662.40000000","0.00186000"]],"a":[["78328.01000000","6.39855000"],["78335.85000000","0.00060000"],["78343.68000000","0.00068000"],["78351.51000000","0.00068000"],["78359.35000000","0.00060000"]]}}
{"rx":1788854515959448440, "m":{"e":"depthUpdate","E":1788854515914,"s":"BTCUSDT","U":99829842582,"u":99829842611,"b":[["78328.00000000","0.23534000"],["78326.00000000","0.03014000"],["78320.70000000","0.00007000"],["78320.69000000","0.14888000"],["78319.53000000","0.00000000"],["78317.29000000","0.40579000"],["78315.27000000","0.00000000"],["78314.31000000","0.00000000"],["78312.22000000","0.00000000"],["78311.97000000","0.00000000"],["78311.11000000","0.01200000"],["77153.08000000","0.00070000"],["70495.20000000","0.00377000"],["62662.40000000","0.00186000"]],"a":[]}}
{"rx":1788854516072549124, "m":{"e":"depthUpdate","E":1788854516014,"s":"BTCUSDT","U":99829842612,"u":99829842645,"b":[["78328.00000000","0.06285000"],["78321.05000000","0.21765000"],["78320.70000000","0.00000000"],["78320.69000000","0.00014000"],["78320.00000000","0.03000000"],["78317.29000000","0.12995000"],["78315.28000000","0.00000000"],["78314.35000000","0.00000000"],["78313.44000000","0.47709000"],["78310.93000000","0.02145000"],["78310.84000000","0.00000000"],["78310.17000000","0.01279000"],["78309.99000000","0.00000000"],["77153.08000000","0.00070000"],["72089.37000000","0.00000000"],["70495.20000000","0.00393000"],["70495.00000000","0.00000000"],["62662.40000000","0.00279000"]],"a":[["78339.76000000","0.00033000"]]}}
{"rx":1788854516171510067, "m":{"e":"depthUpdate","E":1788854516114,"s":"BTCUSDT","U":99829842646,"u":99829842684,"b":[["78328.00000000","0.23542000"],["78327.99000000","0.00083000"],["78324.02000000","0.00014000"],["78324.01000000","0.02275000"],["78321.05000000","0.21765000"],["78320.69000000","0.00000000"],["78320.01000000","0.00000000"],["78320.00000000","0.03014000"],["78317.29000000","0.34330000"],["78314.35000000","0.48984000"],["78313.44000000","0.00000000"],["78301.76000000","0.00000000"],["78281.88000000","1.45198000"],["78281.87000000","0.63890000"],["78281.66000000","0.00000000"],["77153.08000000","0.00062000"],["70495.20000000","0.00377000"],["62662.00000000","0.00200000"]],"a":[["78340.35000000","0.00587000"],["78739.98000000","0.00000000"]]}}
{"rx":1788854516279534182, "m":{"e":"depthUpdate","E":1788854516214,"s":"BTCUSDT","U":99829842685,"u":99829842707,"b":[["78326.00000000","0.03014000"],["78311.96000000","0.00007000"],["78311.09000000","0.02000000"],["78310.93000000","0.00000000"],["78310.79000000","0.02154000"],["78310.17000000","0.00000000"],["78309.91000000","0.01301000"],["78291.35000000","0.63882000"],["78281.87000000","0.00000000"],["78271.87000000","0.02000000"],["77153.08000000","0.00062000"],["70495.20000000","0.00377000"],["62662.40000000","0.00248000"],["62662.00000000","0.00000000"]],"a":[["78338.97000000","0.02800000"],["78358.58000000","0.02800000"],["78378.19000000","0.02800000"]]}}
{"rx":1788854516377193934, "m":{"e":"depthUpdate","E":1788854516314,"s":"BTCUSDT","U":99829842708,"u":99829842744,"b":[["78328.00000000","0.06284000"],["78324.01000000","0.00014000"],["78318.36000000","0.13754000"],["78234.62000000","1.00182000"],["78231.99000000","0.00000000"],["77153.08000000","0.00062000"],["70495.20000000","0.00393000"]],"a":[["78328.01000000","6.39855000"],["78331.93000000","0.00000000"],["78335.85000000","0.00060000"],["78339.77000000","0.00000000"],["78343.69000000","0.00000000"],["78351.53000000","0.00000000"],["78359.37000000","0.00000000"],["79502.94000000","0.00030000"]]}}
{"rx":1788854516487404913, "m":{"e":"depthUpdate","E":1788854516414,"s":"BTCUSDT","U":99829842745,"u":99829842814,"b":[["78328.00000000","0.00000000"],["78327.99000000","0.00000000"],["78327.98000000","0.00000000"],["78326.00000000","0.03014000"],["78324.03000000","0.00000000"],["78324.02000000","0.00000000"],["78323.67000000","0.00000000"],["78320.01000000","0.00007000"],["78319.41000000","0.00000000"],["78318.36000000","0.00000000"],["78318.01000000","0.00000000"],["78316.64000000","0.00000000"],["78316.26000000","0.00000000"],["78315.72000000","0.00007000"],["78314.82000000","0.00000000"],["78314.47000000","0.00400000"],["78314.39000000","0.00000000"],["78314.35000000","0.00000000"],["78313.73000000","0.00400000"],["78313.36000000","0.00000000"],["78312.38000000","0.00000000"],["78311.11000000","0.00400000"],["78310.79000000","0.00000000"],["78310.63000000","0.00000000"],["78309.91000000","0.00000000"],["78309.63000000","0.00000000"],["78291.35000000","0.00000000"],["78286.00000000","0.03000000"],["78283.73000000","0.00000000"],["78278.95000000","0.03828000"],["78278.69000000","0.63893000"],["78275.82000000","0.00007000"],["78262.15000000","0.34509000"],["78250.18000000","0.00000000"],["78247.38000000","1.26559000"],["78228.59000000","0.00000000"],["78171.70000000","0.00000000"],["77924.70000000","0.00014000"],["77153.08000000","0.00062000"],["70495.20000000","0.00368000"],["70495.19000000","0.00009000"],["62662.40000000","0.00217000"],["62662.00000000","0.00000000"]],"a":[["78327.73000000","0.73056000"],["78328.00000000","0.00185000"],["78328.01000000","6.41145000"],["78329.41000000","0.03057000"],["78439.06000000","0.00000000"],["78453.05000000","0.00000000"]]}}
{"rx":1788854516570708088, "m":{"e":"depthUpdate","E":1788854516514,"s":"BTCUSDT","U":99829842815,"u":99829843557,"b":[["78327.69000000","0.00000000"],["78326.50000000","0.00000000"],["78326.49000000","0.00000000"],["78326.48000000","0.00000000"],["78326.01000000","0.00000000"],["78326.00000000","0.00000000"],["78325.56000000","0.00000000"],["78324.01000000","0.00000000"],["78324.00000000","0.22615000"],["78323.99000000","0.00076000"],["78323.98000000","0.00013000"],["78322.92000000","0.00000000"],["78322.50000000","0.00000000"],["78322.31000000","0.00007000"],["78321.66000000","0.00014000"],["78321.06000000","0.00000000"],["78321.05000000","0.00014000"],["78320.41000000","0.00014000"],["78320.17000000","0.00000000"],["78320.02000000","0.00014000"],["78320.01000000","0.02643000"],["78320.00000000","0.03014000"],["78319.16000000","0.00014000"],["78318.88000000","0.00588000"],["78318.66000000","0.00000000"],["78318.21000000","0.00000000"],["78318.01000000","0.00014000"],["78318.00000000","0.03014000"],["78317.61000000","0.00000000"],["78317.43000000","0.00000000"],["78317.30000000","0.00014000"],["78317.29000000","0.37092000"],["78317.20000000","0.00000000"],["78316.81000000","0.01000000"],["78316.17000000","0.00008000"],["78316.01000000","0.00000000"],["78315.81000000","0.00000000"],["78314.90000000","0.00000000"],["78314.81000000","0.02000000"],["78314.47000000","0.00000000"],["78314.45000000","0.00000000"],["78314.36000000","0.00000000"],["78314.01000000","0.00000000"],["78313.73000000","0.00000000"],["78313.58000000","0.00000000"],["78313.40000000","0.00000000"],["78313.39000000","0.24282000"],["78312.33000000","0.00000000"],["78312.17000000","0.00000000"],["78311.77000000","0.00400000"],["78311.74000000","0.00400000"],["78311.73000000","0.00085000"],["78311.11000000","0.00000000"],["78310.94000000","0.10724000"],["78310.51000000","0.00000000"],["78309.79000000","0.00000000"],["78309.70000000","0.00000000"],["78309.64000000","0.00000000"],["78309.62000000","0.00000000"],["78309.18000000","0.00000000"],["78308.42000000","0.00000000"],["78308.34000000","0.00008000"],["78306.95000000","0.01200000"],["78306.94000000","0.08844000"],["78306.93000000","0.00000000"],["78306.71000000","0.00192000"],["78305.37000000","0.00000000"],["78304.50000000","0.00000000"],["78304.42000000","0.00008000"],["78302.99000000","0.00000000"],["78301.50000000","0.00000000"],["78301.49000000","0.00000000"],["78300.91000000","0.31929000"],["78300.59000000","0.00000000"],["78300.50000000","0.00008000"],["78299.25000000","0.00000000"],["78296.99000000","0.00000000"],["78296.67000000","0.00000000"],["78296.59000000","0.00008000"],["78292.88000000","0.12772000"],["78292.76000000","0.31929000"],["78292.75000000","0.00000000"],["78292.67000000","0.00008000"],["78288.84000000","0.00000000"],["78288.75000000","0.00008000"],["78288.00000000","0.03000000"],["78287.79000000","0.00014000"],["78287.32000000","0.00000000"],["78287.00000000","0.00000000"],["78286.01000000","0.00000000"],["78284.84000000","0.00008000"],["78284.02000000","0.00000000"],["78284.00000000","0.04000000"],["78282.89000000","0.00000000"],["78281.88000000","1.40221000"],["78280.93000000","0.00000000"],["78277.50000000","0.00008000"],["78271.65000000","0.00000000"],["78268.42000000","0.00000000"],["78268.08000000","0.00200000"],["78261.32000000","0.00000000"],["78259.36000000","0.00317000"],["78257.51000000","0.00000000"],["78255.98000000","0.00000000"],["78253.69000000","0.00000000"],["78253.62000000","0.00000000"],["78251.66000000","0.34514000"],["78250.18000000","0.00316000"],["78246.01000000","0.00179000"],["78245.68000000","0.00008000"],["78240.61000000","0.00000000"],["78240.31000000","0.00000000"],["78236.61000000","0.20000000"],["78234.62000000","0.00000000"],["78233.97000000","0.00000000"],["78227.24000000","0.70686000"],["78227.23000000","2.29802000"],["78227.13000000","0.00000000"],["78224.64000000","0.00000000"],["78208.97000000","0.00000000"],["78205.21000000","0.00000000"],["78193.30000000","0.00000000"],["78177.63000000","0.00000000"],["78175.93000000","0.05616000"],["78175.36000000","0.00000000"],["78167.54000000","0.00072000"],["78167.35000000","0.00008000"],["78161.96000000","0.00000000"],["78146.29000000","0.00000000"],["78130.62000000","0.00000000"],["78114.95000000","0.00000000"],["78099.28000000","0.00000000"],["78097.02000000","0.00000000"],["78089.89000000","0.00007000"],["78089.03000000","0.00008000"],["78085.98000000","0.00007000"],["78083.61000000","0.00000000"],["78018.69000000","0.00000000"],["78010.70000000","0.00008000"],["77976.72000000","0.00000000"],["77940.36000000","0.00000000"],["77932.38000000","0.00008000"],["77862.03000000","0.00000000"],["77854.06000000","0.00008000"],["77783.70000000","0.00000000"],["77775.73000000","0.00008000"],["77705.36000000","0.00000000"],["77697.41000000","0.00008000"],["77153.08000000","0.00000000"],["77149.14000000","0.00008000"],["70495.20000000","0.00000000"],["70491.60000000","0.00016000"],["62662.00000000","0.00000000"],["62659.20000000","0.00124000"]],"a":[["78324.01000000","6.14832000"],["78324.02000000","0.00027000"],["78324.03000000","0.00013000"],["78324.92000000","0.00000000"],["78325.46000000","0.06839000"],["78325.57000000","0.00000000"],["78325.83000000","0.00000000"],["78326.01000000","0.00000000"],["78326.02000000","0.00000000"],["78326.04000000","0.00400000"],["78326.49000000","0.00372000"],["78326.50000000","1.63829000"],["78326.51000000","3.28253000"],["78326.52000000","0.00000000"],["78326.53000000","0.00000000"],["78327.37000000","0.00000000"],["78327.46000000","0.00000000"],["78327.55000000","0.00000000"],["78327.63000000","2.38245000"],["78327.64000000","0.00000000"],["78327.69000000","0.00014000"],["78327.70000000","0.35931000"],["78327.72000000","0.01200000"],["78327.73000000","0.50264000"],["78327.80000000","0.05000000"],["78327.96000000","0.00000000"],["78327.99000000","0.00000000"],["78328.00000000","0.12500000"],["78328.01000000","0.38175000"],["78328.02000000","0.00000000"],["78328.03000000","0.00000000"],["78328.05000000","0.00014000"],["78328.09000000","0.00014000"],["78328.10000000","0.00014000"],["78329.27000000","0.00014000"],["78329.36000000","0.00000000"],["78329.41000000","0.03071000"],["78329.43000000","0.00000000"],["78329.44000000","0.00000000"],["78329.55000000","0.00000000"],["78330.14000000","0.00000000"],["78330.51000000","0.06638000"],["78330.52000000","0.00000000"],["78331.29000000","0.04029000"],["78331.50000000","0.12766000"],["78331.66000000","0.00007000"],["78331.77000000","0.00000000"],["78331.84000000","0.00034000"],["78331.92000000","0.00408000"],["78332.00000000","0.00464000"],["78332.02000000","0.00000000"],["78332.94000000","0.00400000"],["78332.95000000","1.30819000"],["78334.35000000","0.00007000"],["78335.61000000","0.00000000"],["78335.84000000","0.00000000"],["78336.30000000","0.00008000"],["78337.20000000","0.12765000"],["78339.08000000","0.37581000"],["78339.09000000","0.00000000"],["78339.67000000","0.00008000"],["78341.17000000","0.00000000"],["78341.84000000","0.00000000"],["78343.59000000","0.00008000"],["78343.68000000","0.00060000"],["78343.74000000","0.00000000"],["78344.01000000","0.07690000"],["78344.44000000","0.00189000"],["78345.25000000","0.00012000"],["78345.62000000","0.12763000"],["78347.51000000","0.00008000"],["78347.59000000","0.00000000"],["78349.09000000","0.00000000"],["78349.89000000","2.40153000"],["78349.90000000","0.00000000"],["78350.00000000","0.03000000"],["78351.42000000","0.00008000"],["78351.51000000","0.00060000"],["78353.65000000","1.37122000"],["78353.96000000","1.26386000"],["78355.34000000","0.00008000"],["78355.42000000","0.00000000"],["78358.87000000","0.00000000"],["78359.26000000","0.00008000"],["78359.34000000","0.00000000"],["78360.02000000","0.00000000"],["78362.50000000","0.00000000"],["78363.17000000","0.00008000"],["78363.26000000","0.00000000"],["78365.39000000","0.02511000"],["78365.67000000","0.00000000"],["78367.00000000","0.01000000"],["78367.17000000","0.00000000"],["78368.00000000","0.03000000"],["78368.64000000","0.00000000"],["78370.62000000","0.00000000"],["78373.50000000","0.00000000"],["78381.34000000","0.00000000"],["78383.95000000","0.00542000"],["78385.11000000","0.00000000"],["78385.30000000","0.00000000"],["78388.85000000","0.20000000"],["78392.85000000","0.00000000"],["78397.01000000","0.00000000"],["78397.18000000","0.98113000"],["78397.19000000","0.00000000"],["78398.24000000","0.00000000"],["78399.99000000","0.08153000"],["78402.33000000","2.84618000"],["78406.58000000","0.00000000"],["78412.68000000","0.00000000"],["78414.89000000","0.00007000"],["78420.30000000","0.00000000"],["78422.65000000","0.00000000"],["78428.35000000","0.00000000"],["78437.98000000","0.00000000"],["78437.99000000","0.00007000"],["78439.05000000","0.13947000"],["78443.99000000","0.00000000"],["78444.02000000","0.00000000"],["78444.28000000","0.00000000"],["78450.98000000","0.03198000"],["78459.69000000","0.00000000"],["78475.36000000","0.00000000"],["78491.03000000","0.00000000"],["78506.70000000","0.00000000"],["78522.37000000","0.00000000"],["78538.04000000","0.00000000"],["78553.71000000","0.00000000"],["78569.38000000","0.00000000"],["78585.05000000","0.00000000"],["78600.72000000","0.00000000"],["78764.99000000","0.00000000"],["78793.95000000","0.00008000"],["78802.97000000","0.00000000"],["78843.15000000","0.00000000"],["78872.28000000","0.00008000"],["78881.30000000","0.00000000"],["78950.60000000","0.00008000"],["78959.63000000","0.00000000"],["79502.94000000","0.00000000"]]}}
{"rx":1788854516660110832, "m":{"e":"depthUpdate","E":1788854516614,"s":"BTCUSDT","U":99829843558,"u":99829844827,"b":[["78324.00000000","0.00000000"],["78323.99000000","0.00000000"],["78323.98000000","0.00000000"],["78323.70000000","0.00000000"],["78322.31000000","0.00000000"],["78322.01000000","0.00000000"],["78322.00000000","0.00000000"],["78321.66000000","0.00000000"],["78321.61000000","0.00000000"],["78321.60000000","0.00000000"],["78321.05000000","0.00000000"],["78320.41000000","0.00000000"],["78320.02000000","0.00000000"],["78320.01000000","0.00000000"],["78320.00000000","0.00000000"],["78319.71000000","0.00000000"],["78319.45000000","0.00000000"],["78319.16000000","0.00000000"],["78318.92000000","0.00000000"],["78318.88000000","0.00000000"],["78318.01000000","0.00000000"],["78318.00000000","0.00000000"],["78317.66000000","0.00000000"],["78317.30000000","0.00000000"],["78317.29000000","0.00000000"],["78316.81000000","0.00000000"],["78316.70000000","0.00000000"],["78316.39000000","0.00000000"],["78316.21000000","0.00000000"],["78316.17000000","0.00000000"],["78316.14000000","0.00000000"],["78316.01000000","0.00000000"],["78316.00000000","0.00000000"],["78315.82000000","0.00000000"],["78315.72000000","0.00000000"],["78315.65000000","0.00000000"],["78315.34000000","0.00000000"],["78314.83000000","0.00000000"],["78314.82000000","0.00000000"],["78314.81000000","0.00000000"],["78314.21000000","0.00000000"],["78314.15000000","0.00000000"],["78314.00000000","0.00000000"],["78313.86000000","0.00000000"],["78313.82000000","0.00000000"],["78313.56000000","0.00000000"],["78313.46000000","0.00000000"],["78313.39000000","0.00000000"],["78313.34000000","0.00000000"],["78313.28000000","0.00000000"],["78312.99000000","0.00000000"],["78312.92000000","0.00000000"],["78312.56000000","0.00000000"],["78312.54000000","0.00000000"],["78312.34000000","0.00000000"],["78312.28000000","0.00000000"],["78312.17000000","0.00000000"],["78312.15000000","0.00000000"],["78312.12000000","0.00000000"],["78312.09000000","0.00000000"],["78312.00000000","0.00000000"],["78311.96000000","0.00000000"],["78311.80000000","0.00000000"],["78311.77000000","0.00000000"],["78311.74000000","0.00000000"],["78311.73000000","0.00000000"],["78311.67000000","0.00000000"],["78311.10000000","0.00000000"],["78311.09000000","0.00000000"],["78310.94000000","0.00000000"],["78310.47000000","0.00000000"],["78310.28000000","0.00000000"],["78310.11000000","0.00000000"],["78310.00000000","0.00000000"],["78309.44000000","0.00000000"],["78309.20000000","0.00000000"],["78308.55000000","0.00000000"],["78308.54000000","0.00000000"],["78308.53000000","0.00000000"],["78308.34000000","0.00000000"],["78308.25000000","0.00000000"],["78308.22000000","0.00000000"],["78308.17000000","3.28934000"],["78308.16000000","0.00042000"],["78308.03000000","0.00000000"],["78308.00000000","0.00000000"],["78307.93000000","0.00000000"],["78307.91000000","0.00000000"],["78307.75000000","0.00000000"],["78307.74000000","0.00007000"],["78307.69000000","0.00000000"],["78307.62000000","0.00000000"],["78307.50000000","0.00000000"],["78307.27000000","0.00014000"],["78307.26000000","0.16730000"],["78307.25000000","0.56000000"],["78307.24000000","0.00000000"],["78307.23000000","0.00000000"],["78306.97000000","0.00000000"],["78306.96000000","0.00000000"],["78306.95000000","0.00000000"],["78306.94000000","0.00000000"],["78306.92000000","0.00000000"],["78306.90000000","0.00000000"],["78306.73000000","0.00000000"],["78306.71000000","0.00000000"],["78306.51000000","0.00000000"],["78306.29000000","0.00000000"],["78306.27000000","0.00000000"],["78306.26000000","0.00000000"],["78306.21000000","0.00000000"],["78306.15000000","0.00000000"],["78306.00000000","0.00000000"],["78305.93000000","0.00000000"],["78305.38000000","0.00000000"],["78305.29000000","0.04206000"],["78305.28000000","0.14038000"],["78305.24000000","0.00000000"],["78304.47000000","0.00000000"],["78304.42000000","0.00000000"],["78304.31000000","0.00000000"],["78304.30000000","0.00000000"],["78304.24000000","0.00000000"],["78304.20000000","0.00000000"],["78304.08000000","0.00000000"],["78304.01000000","0.00000000"],["78304.00000000","0.00000000"],["78303.99000000","0.00000000"],["78303.75000000","0.00007000"],["78302.31000000","0.00000000"],["78302.28000000","0.00000000"],["78302.02000000","0.00000000"],["78302.00000000","0.00000000"],["78301.87000000","0.10732000"],["78301.73000000","0.00000000"],["78301.69000000","0.00000000"],["78301.50000000","0.00000000"],["78301.40000000","0.00000000"],["78301.35000000","0.00014000"],["78301.34000000","0.67725000"],["78301.33000000","0.06275000"],["78301.32000000","0.30000000"],["78301.31000000","0.00000000"],["78301.30000000","0.04000000"],["78301.26000000","0.00000000"],["78301.08000000","0.00000000"],["78300.92000000","0.00000000"],["78300.91000000","0.00000000"],["78300.90000000","0.00000000"],["78300.86000000","0.00000000"],["78300.75000000","0.00000000"],["78300.70000000","0.00000000"],["78300.50000000","0.00000000"],["78300.35000000","0.00000000"],["78300.34000000","0.00008000"],["78300.33000000","0.20250000"],["78300.02000000","0.00000000"],["78300.01000000","0.37581000"],["78299.99000000","0.00000000"],["78299.76000000","0.00007000"],["78298.39000000","0.00007000"],["78297.40000000","0.01284000"],["78297.33000000","0.00000000"],["78297.20000000","0.00000000"],["78296.59000000","0.00000000"],["78296.42000000","0.00000000"],["78296.14000000","0.00000000"],["78295.77000000","0.00007000"],["78295.54000000","0.00000000"],["78294.90000000","0.00000000"],["78294.89000000","0.61720000"],["78294.70000000","0.00000000"],["78293.80000000","1.08824000"],["78293.49000000","0.00000000"],["78293.48000000","0.01332000"],["78292.89000000","0.31931000"],["78292.88000000","0.00000000"],["78292.76000000","0.00000000"],["78292.72000000","0.00000000"],["78292.67000000","0.00000000"],["78292.51000000","0.00008000"],["78292.06000000","0.37581000"],["78292.05000000","0.00000000"],["78291.78000000","0.00007000"],["78290.60000000","0.09688000"],["78289.94000000","2.29802000"],["78289.93000000","1.63316000"],["78289.92000000","0.00000000"],["78289.61000000","0.00024000"],["78289.56000000","0.01321000"],["78288.75000000","0.00000000"],["78288.64000000","0.10276000"],["78288.59000000","0.00008000"],["78287.94000000","0.00060000"],["78287.86000000","0.01400000"],["78287.79000000","0.00007000"],["78287.68000000","0.00012000"],["78286.50000000","0.00000000"],["78285.66000000","0.00008000"],["78285.64000000","0.01311000"],["78285.01000000","1.28476000"],["78285.00000000","0.00000000"],["78284.84000000","0.00000000"],["78284.68000000","0.00008000"],["78284.67000000","0.00000000"],["78284.04000000","0.37607000"],["78284.03000000","1.91454000"],["78284.00000000","0.03000000"],["78283.80000000","0.00007000"],["78283.34000000","0.00192000"],["78281.88000000","0.00000000"],["78281.65000000","0.00000000"],["78281.21000000","0.83011000"],["78280.76000000","0.00008000"],["78279.81000000","0.00007000"],["78279.57000000","0.00000000"],["78279.50000000","0.00000000"],["78277.32000000","0.00000000"],["78276.85000000","0.00008000"],["78276.84000000","0.00000000"],["78276.78000000","0.00000000"],["78275.92000000","0.00000000"],["78275.82000000","0.00014000"],["78275.59000000","0.00000000"],["78275.19000000","0.00000000"],["78274.51000000","0.00000000"],["78274.01000000","0.27165000"],["78272.93000000","0.00008000"],["78272.42000000","0.00000000"],["78271.83000000","0.00014000"],["78271.57000000","0.00000000"],["78271.14000000","0.37581000"],["78271.13000000","0.00000000"],["78270.80000000","0.00667000"],["78269.79000000","0.00000000"],["78269.02000000","0.00008000"],["78268.34000000","0.00000000"],["78268.33000000","0.00026000"],["78267.84000000","0.00007000"],["78267.06000000","0.00000000"],["78265.32000000","0.00355000"],["78264.66000000","0.00000000"],["78263.85000000","0.00000000"],["78263.58000000","0.00000000"],["78263.44000000","0.00000000"],["78262.00000000","0.04000000"],["78261.60000000","0.00000000"],["78260.98000000","0.00000000"],["78259.80000000","0.00007000"],["78258.01000000","0.68867000"],["78256.02000000","0.77541000"],["78255.08000000","0.36761000"],["78254.37000000","0.00000000"],["78253.69000000","0.01154000"],["78253.68000000","0.00009000"],["78252.46000000","0.00000000"],["78251.74000000","0.00000000"],["78251.18000000","0.02000000"],["78250.18000000","0.00000000"],["78247.22000000","0.12547000"],["78246.01000000","0.00000000"],["78245.68000000","0.00000000"],["78245.13000000","0.00008000"],["78242.71000000","0.77536000"],["78237.68000000","0.00008000"],["78236.94000000","0.00010000"],["78236.61000000","0.00000000"],["78231.01000000","0.00319000"],["78230.97000000","0.01731000"],["78230.77000000","0.00180000"],["78230.21000000","0.64994000"],["78229.10000000","0.00010000"],["78228.78000000","1.91454000"],["78227.35000000","0.03127000"],["78222.38000000","0.00000000"],["78222.36000000","0.19329000"],["78218.60000000","0.59330000"],["78218.59000000","1.91454000"],["78218.40000000","0.00000000"],["78218.23000000","0.00000000"],["78205.16000000","0.03127000"],["78175.94000000","0.09203000"],["78175.93000000","0.00000000"],["78169.78000000","0.15285000"],["78169.28000000","0.37581000"],["78169.27000000","0.00000000"],["78167.54000000","0.16992000"],["78167.53000000","0.00000000"],["78167.35000000","0.00000000"],["78165.75000000","0.00000000"],["78165.52000000","0.00667000"],["78162.21000000","0.20000000"],["78159.37000000","0.00008000"],["78155.18000000","0.37581000"],["78153.81000000","0.00000000"],["78150.86000000","0.00072000"],["78150.85000000","1.53184000"],["78144.94000000","0.00000000"],["78143.67000000","0.00222000"],["78136.15000000","2.59562000"],["78135.12000000","0.00222000"],["78129.06000000","1.20000000"],["78122.36000000","0.00000000"],["78106.99000000","0.00000000"],["78092.70000000","0.00000000"],["78090.09000000","0.00220000"],["78089.03000000","0.00000000"],["78087.25000000","0.00007000"],["78085.98000000","0.00000000"],["78084.02000000","0.00220000"],["78083.34000000","0.00007000"],["78081.05000000","0.00008000"],["78079.43000000","0.00007000"],["78073.34000000","0.00220000"],["78071.27000000","0.03188000"],["78040.03000000","0.00000000"],["78039.98000000","0.00009000"],["78039.73000000","0.00000000"],["78010.70000000","0.00000000"],["78008.74000000","0.00000000"],["78002.74000000","0.00008000"],["78002.20000000","0.00000000"],["77994.29000000","0.00030000"],["77991.05000000","0.00026000"],["77983.21000000","0.00026000"],["77969.89000000","0.07678000"],["77969.71000000","0.00490000"],["77969.52000000","0.02387000"],["77964.63000000","1.77656000"],["77932.38000000","0.00000000"],["77924.70000000","0.00021000"],["77924.42000000","0.00008000"],["77854.06000000","0.00000000"],["77846.10000000","0.00008000"],["77775.73000000","0.00000000"],["77771.59000000","0.06255000"],["77767.79000000","0.00008000"],["77697.41000000","0.00000000"],["77689.47000000","0.00008000"],["77149.14000000","0.00000000"],["77133.55000000","0.00008000"],["70491.60000000","0.00000000"],["62662.40000000","0.00186000"]],"a":[["78307.26000000","0.00000000"],["78308.18000000","4.67563000"],["78308.19000000","0.00041000"],["78308.20000000","0.05013000"],["78308.24000000","0.00007000"],["78308.25000000","0.05000000"],["78308.35000000","0.00000000"],["78308.52000000","1.45799000"],["78308.53000000","0.73386000"],["78308.54000000","0.00000000"],["78308.55000000","0.00000000"],["78309.42000000","0.00000000"],["78309.43000000","0.00000000"],["78309.75000000","0.00000000"],["78309.76000000","0.00000000"],["78309.94000000","0.00000000"],["78310.33000000","0.00000000"],["78310.61000000","2.00664000"],["78310.94000000","2.29953000"],["78310.95000000","0.00000000"],["78311.09000000","0.00000000"],["78311.10000000","0.00000000"],["78311.19000000","0.00000000"],["78311.23000000","0.00000000"],["78311.72000000","0.00638000"],["78311.73000000","0.00021000"],["78311.88000000","0.00000000"],["78312.01000000","0.00000000"],["78312.10000000","0.00000000"],["78312.12000000","0.00075000"],["78312.13000000","0.00000000"],["78313.02000000","0.00000000"],["78313.03000000","0.00000000"],["78313.40000000","0.00000000"],["78313.93000000","0.00000000"],["78314.01000000","0.00014000"],["78314.15000000","0.00000000"],["78314.16000000","0.00000000"],["78314.19000000","0.00000000"],["78314.20000000","0.00000000"],["78314.82000000","0.00014000"],["78314.83000000","0.00000000"],["78315.37000000","0.74658000"],["78315.38000000","0.00000000"],["78315.57000000","0.00007000"],["78315.72000000","0.00014000"],["78315.73000000","0.00000000"],["78315.83000000","2.29802000"],["78315.86000000","0.00026000"],["78316.00000000","0.00000000"],["78316.01000000","0.00014000"],["78316.18000000","0.20250000"],["78316.20000000","0.00000000"],["78316.36000000","0.00008000"],["78316.63000000","0.00000000"],["78316.81000000","0.00000000"],["78316.82000000","0.00014000"],["78317.30000000","0.00014000"],["78317.53000000","0.00000000"],["78317.76000000","0.00400000"],["78317.98000000","0.00007000"],["78318.00000000","0.65173000"],["78318.01000000","0.14204000"],["78318.43000000","0.00000000"],["78318.70000000","0.00000000"],["78318.78000000","0.00000000"],["78318.89000000","0.00000000"],["78318.98000000","0.00000000"],["78319.33000000","0.00000000"],["78319.71000000","0.00014000"],["78319.93000000","0.00007000"],["78320.00000000","0.00000000"],["78320.01000000","0.00014000"],["78320.02000000","0.00000000"],["78320.09000000","0.00000000"],["78320.23000000","0.00000000"],["78320.52000000","0.00400000"],["78320.80000000","2.00664000"],["78321.13000000","0.00000000"],["78321.42000000","0.00000000"],["78321.62000000","0.00000000"],["78321.83000000","0.00007000"],["78321.89000000","0.00007000"],["78322.00000000","0.14354000"],["78322.01000000","0.30000000"],["78322.02000000","0.14790000"],["78322.03000000","0.00000000"],["78322.32000000","0.00000000"],["78322.92000000","0.59743000"],["78322.93000000","0.00000000"],["78323.19000000","0.00010000"],["78323.28000000","0.00400000"],["78323.36000000","0.15000000"],["78323.70000000","0.00014000"],["78323.71000000","0.00000000"],["78323.76000000","0.00026000"],["78323.83000000","0.00000000"],["78323.99000000","0.00000000"],["78324.00000000","0.11086000"],["78324.01000000","3.00418000"],["78324.02000000","0.00000000"],["78324.03000000","0.00000000"],["78324.05000000","0.00000000"],["78324.10000000","0.00000000"],["78324.16000000","0.09684000"],["78324.92000000","0.00000000"],["78324.96000000","0.00007000"],["78325.27000000","0.01760000"],["78325.46000000","0.30000000"],["78325.83000000","0.00000000"],["78326.04000000","0.30400000"],["78326.11000000","0.10271000"],["78326.48000000","0.00000000"],["78326.49000000","0.00372000"],["78326.50000000","0.97363000"],["78326.51000000","0.75427000"],["78326.52000000","0.02112000"],["78326.61000000","0.00008000"],["78326.82000000","0.00574000"],["78327.09000000","0.02000000"],["78327.62000000","0.31931000"],["78327.63000000","2.00664000"],["78327.70000000","0.15681000"],["78327.72000000","0.00000000"],["78327.73000000","0.00000000"],["78327.77000000","0.02112000"],["78327.80000000","0.00000000"],["78328.00000000","0.07500000"],["78328.01000000","0.17660000"],["78328.05000000","0.00000000"],["78328.09000000","0.00000000"],["78328.10000000","0.00000000"],["78329.27000000","0.00000000"],["78329.41000000","0.03057000"],["78329.69000000","0.00007000"],["78330.51000000","0.19668000"],["78330.53000000","0.00008000"],["78331.03000000","0.00010000"],["78331.22000000","0.00000000"],["78331.29000000","0.00000000"],["78331.50000000","0.00000000"],["78331.84000000","0.00026000"],["78332.93000000","0.31931000"],["78332.94000000","0.37581000"],["78332.96000000","2.00664000"],["78332.97000000","2.45939000"],["78333.55000000","0.00000000"],["78333.56000000","0.63848000"],["78333.67000000","0.00255000"],["78334.35000000","0.00000000"],["78334.44000000","0.00008000"],["78334.96000000","0.00063000"],["78335.07000000","0.00000000"],["78335.51000000","0.00000000"],["78336.19000000","0.00000000"],["78336.53000000","0.00000000"],["78337.20000000","0.00000000"],["78337.48000000","0.00000000"],["78338.36000000","0.00008000"],["78339.08000000","0.00000000"],["78339.67000000","0.00000000"],["78339.76000000","0.00026000"],["78339.78000000","0.00000000"],["78340.56000000","0.00127000"],["78340.61000000","0.00000000"],["78340.80000000","0.00000000"],["78341.42000000","0.00007000"],["78341.65000000","0.00000000"],["78341.66000000","0.00000000"],["78341.74000000","0.00000000"],["78342.04000000","0.66010000"],["78342.27000000","0.00008000"],["78342.75000000","0.00000000"],["78343.06000000","0.37581000"],["78343.17000000","0.00000000"],["78343.37000000","0.00000000"],["78343.59000000","0.00000000"],["78343.98000000","0.34473000"],["78344.00000000","0.73000000"],["78344.01000000","0.00000000"],["78345.62000000","0.00000000"],["78345.64000000","0.00000000"],["78345.82000000","0.34472000"],["78345.83000000","0.00000000"],["78346.19000000","0.00008000"],["78346.21000000","0.00000000"],["78347.51000000","0.00000000"],["78347.64000000","0.00000000"],["78349.08000000","0.00000000"],["78349.63000000","0.00000000"],["78349.96000000","0.00622000"],["78350.11000000","0.00008000"],["78350.68000000","0.00000000"],["78351.00000000","0.01008000"],["78351.29000000","0.00429000"],["78351.42000000","0.00000000"],["78351.63000000","0.00000000"],["78353.65000000","1.85244000"],["78353.66000000","0.41262000"],["78355.34000000","0.00000000"],["78355.35000000","0.77425000"],["78355.62000000","0.00000000"],["78356.01000000","0.00428000"],["78356.47000000","0.03057000"],["78356.99000000","0.14133000"],["78357.72000000","0.00000000"],["78359.26000000","0.00000000"],["78359.61000000","0.00000000"],["78360.52000000","0.00000000"],["78363.17000000","0.00000000"],["78363.22000000","0.00000000"],["78363.56000000","0.00000000"],["78364.00000000","0.03000000"],["78364.71000000","0.00000000"],["78365.39000000","0.00000000"],["78365.69000000","0.00000000"],["78367.00000000","0.00000000"],["78367.47000000","0.00000000"],["78367.82000000","0.00000000"],["78370.85000000","0.00000000"],["78371.03000000","0.00000000"],["78377.12000000","0.00000000"],["78378.07000000","0.77413000"],["78378.15000000","0.00000000"],["78379.52000000","0.00000000"],["78380.37000000","0.82020000"],["78380.67000000","0.00000000"],["78381.30000000","0.01728000"],["78381.31000000","0.00000000"],["78382.30000000","0.00110000"],["78383.85000000","0.00000000"],["78384.51000000","0.52148000"],["78386.10000000","0.00000000"],["78388.85000000","0.00000000"],["78389.26000000","0.00008000"],["78391.89000000","0.00000000"],["78391.90000000","0.00000000"],["78392.85000000","0.04781000"],["78393.03000000","0.00000000"],["78396.16000000","0.00000000"],["78397.00000000","0.00007000"],["78397.31000000","0.00000000"],["78399.99000000","0.93043000"],["78403.84000000","0.02947000"],["78403.99000000","0.00127000"],["78405.01000000","0.00000000"],["78406.34000000","0.00000000"],["78411.12000000","0.00000000"],["78412.26000000","0.00000000"],["78414.18000000","0.00000000"],["78414.89000000","0.00000000"],["78425.46000000","0.00000000"],["78427.21000000","0.06391000"],["78427.76000000","0.00000000"],["78427.77000000","0.00000000"],["78432.48000000","0.18168000"],["78433.92000000","0.00000000"],["78433.93000000","0.00000000"],["78434.70000000","0.02743000"],["78443.99000000","0.01924000"],["78448.38000000","1.53184000"],["78450.98000000","0.00000000"],["78452.90000000","0.00011000"],["78465.00000000","0.77442000"],["78465.12000000","0.00000000"],["78467.57000000","0.00008000"],["78472.29000000","0.00010000"],["78476.92000000","0.00012000"],["78479.99000000","0.00000000"],["78484.67000000","0.00000000"],["78487.83000000","0.00000000"],["78489.85000000","0.09606000"],["78491.96000000","0.00000000"],["78545.88000000","0.00008000"],["78547.93000000","0.00000000"],["78549.04000000","0.00000000"],["78562.99000000","0.00000000"],["78588.55000000","0.00000000"],["78592.70000000","0.00000000"],["78624.19000000","0.00008000"],["78641.32000000","0.00000000"],["78702.50000000","0.00008000"],["78719.65000000","0.00000000"],["78730.47000000","0.00000000"],["78749.39000000","0.00000000"],["78757.19000000","0.00000000"],["78780.82000000","0.00008000"],["78793.95000000","0.00000000"],["78832.33000000","0.00000000"],["78859.13000000","0.00008000"],["78872.28000000","0.00000000"],["78937.44000000","0.00008000"],["78950.60000000","0.00000000"],["79515.97000000","0.00206000"]]}}
{"rx":1788854516767054899, "m":{"e":"depthUpdate","E":1788854516714,"s":"BTCUSDT","U":99829844828,"u":99829845082,"b":[["78308.17000000","2.22677000"],["78308.16000000","0.00084000"],["78307.26000000","0.04500000"],["78307.25000000","0.00014000"],["78306.91000000","0.00014000"],["78306.90000000","0.15000000"],["78306.29000000","0.00000000"],["78306.28000000","0.00000000"],["78305.30000000","0.00014000"],["78305.29000000","0.04206000"],["78305.28000000","0.00014000"],["78303.75000000","0.00014000"],["78302.31000000","0.00425000"],["78301.88000000","0.00014000"],["78301.87000000","0.10746000"],["78301.54000000","0.31937000"],["78301.35000000","0.00007000"],["78301.34000000","0.67739000"],["78301.33000000","0.06275000"],["78301.30000000","0.00000000"],["78301.05000000","0.00709000"],["78300.78000000","0.00000000"],["78300.54000000","0.00000000"],["78300.02000000","0.37581000"],["78300.01000000","0.00000000"],["78299.80000000","0.00850000"],["78299.76000000","0.00014000"],["78299.32000000","0.00400000"],["78298.55000000","0.00850000"],["78298.21000000","0.00048000"],["78298.17000000","0.00048000"],["78298.16000000","0.02000000"],["78297.18000000","0.00188000"],["78295.77000000","0.00014000"],["78295.54000000","0.00400000"],["78295.53000000","0.00000000"],["78294.90000000","0.00400000"],["78293.80000000","0.20048000"],["78292.89000000","0.00000000"],["78291.78000000","0.00014000"],["78289.94000000","0.00000000"],["78289.45000000","2.29861000"],["78289.04000000","0.02463000"],["78288.74000000","0.31935000"],["78287.86000000","0.00000000"],["78287.79000000","0.00014000"],["78285.92000000","0.00662000"],["78285.01000000","1.02006000"],["78284.68000000","0.00135000"],["78283.80000000","0.00014000"],["78282.90000000","0.00000000"],["78281.73000000","0.00000000"],["78281.06000000","0.50502000"],["78279.81000000","0.00014000"],["78276.79000000","0.88532000"],["78271.73000000","0.00015000"],["78269.00000000","0.01000000"],["78262.00000000","0.03000000"],["78257.46000000","0.00000000"],["78256.58000000","0.00663000"],["78256.07000000","0.99361000"],["78253.99000000","0.34513000"],["78252.44000000","0.00436000"],["78251.85000000","0.00621000"],["78250.16000000","0.00000000"],["78249.49000000","0.00428000"],["78249.17000000","0.00428000"],["78247.10000000","0.02000000"],["78246.70000000","0.15806000"],["78246.69000000","0.25533000"],["78245.91000000","0.00000000"],["78234.56000000","0.01134000"],["78233.20000000","0.00000000"],["78231.18000000","0.00540000"],["78230.84000000","0.00110000"],["78230.77000000","0.00000000"],["78225.06000000","0.00029000"],["78214.70000000","0.00000000"],["78194.75000000","0.04539000"],["78177.40000000","0.05617000"],["78171.69000000","0.00000000"],["78162.22000000","0.06329000"],["78159.50000000","0.00665000"],["78150.86000000","0.00000000"],["78075.52000000","0.00007000"],["78071.61000000","0.00007000"],["77133.55000000","0.00016000"],["70477.36000000","0.00016000"]],"a":[["78308.18000000","6.97600000"],["78308.20000000","0.05027000"],["78308.25000000","0.05014000"],["78308.52000000","1.45799000"],["78308.53000000","0.73386000"],["78310.61000000","2.00678000"],["78310.94000000","2.29967000"],["78311.56000000","0.00000000"],["78311.72000000","0.00014000"],["78313.72000000","0.04029000"],["78314.01000000","0.00000000"],["78314.82000000","0.00000000"],["78315.35000000","0.00638000"],["78315.36000000","0.00800000"],["78315.37000000","0.74672000"],["78316.01000000","0.00000000"],["78316.02000000","0.00060000"],["78316.82000000","0.00000000"],["78317.30000000","0.00000000"],["78317.99000000","0.01200000"],["78318.01000000","0.14190000"],["78319.25000000","0.31864000"],["78320.01000000","0.00000000"],["78322.02000000","0.44790000"],["78322.92000000","0.89743000"],["78323.28000000","0.30400000"],["78323.85000000","0.00060000"],["78324.01000000","2.99267000"],["78325.27000000","0.00000000"],["78325.46000000","0.00000000"],["78326.04000000","0.00400000"],["78326.51000000","0.45427000"],["78326.52000000","0.00000000"],["78327.77000000","0.00000000"],["78331.68000000","0.00074000"],["78335.85000000","0.00000000"],["78339.51000000","0.00060000"],["78340.35000000","0.00179000"],["78343.68000000","0.00000000"],["78348.00000000","0.04000000"],["78349.60000000","0.00000000"],["78351.00000000","0.00008000"],["78351.46000000","0.01135000"],["78351.51000000","0.00000000"],["78355.14000000","0.00433000"],["78356.11000000","0.02505000"],["78359.35000000","0.00000000"],["78366.10000000","0.88432000"],["78374.60000000","0.00000000"],["78382.24000000","0.00000000"],["78390.56000000","0.09250000"],["78399.62000000","0.04552000"],["78409.46000000","2.20956000"],["78410.86000000","0.00000000"],["78416.47000000","0.40257000"],["78451.51000000","0.05108000"],["78541.33000000","0.00000000"],["78543.35000000","0.00000000"],["78546.34000000","0.00000000"],["78548.52000000","0.00000000"],["78574.39000000","0.00036000"],["79635.25000000","0.00237000"]]}}
{"rx":1788854516870966886, "m":{"e":"depthUpdate","E":1788854516814,"s":"BTCUSDT","U":99829845083,"u":99829845188,"b":[["78308.17000000","2.22608000"],["78308.16000000","0.00091000"],["78307.26000000","0.04500000"],["78307.25000000","0.00000000"],["78306.90000000","0.15014000"],["78305.29000000","0.04206000"],["78305.28000000","0.00000000"],["78303.75000000","0.00007000"],["78301.87000000","0.10746000"],["78301.55000000","0.00007000"],["78301.54000000","0.31951000"],["78301.40000000","0.50000000"],["78299.54000000","0.00000000"],["78298.65000000","0.00400000"],["78298.50000000","0.00069000"],["78287.34000000","0.00000000"],["78285.92000000","0.00000000"],["78279.72000000","0.00012000"],["78274.01000000","0.42844000"],["78272.52000000","0.63905000"],["78259.36000000","0.00000000"],["78244.01000000","0.00318000"],["78238.32000000","1.26573000"],["78230.85000000","0.00180000"],["78210.01000000","0.02693000"],["78208.95000000","0.05889000"],["78207.25000000","0.00000000"],["78194.47000000","0.00007000"],["78185.01000000","0.00000000"],["78184.40000000","0.00008000"],["78181.75000000","0.04614000"],["78178.93000000","0.00000000"],["78165.53000000","0.00127000"],["78150.87000000","0.00127000"],["78150.86000000","0.00072000"],["78140.09000000","0.00100000"],["78099.77000000","0.00000000"],["78092.71000000","0.00802000"],["78083.87000000","0.00007000"],["78067.70000000","0.00007000"],["78063.79000000","0.00007000"],["77133.55000000","0.00024000"],["77133.54000000","0.00030000"],["62662.40000000","0.00155000"]],"a":[["78308.18000000","6.98770000"],["78309.44000000","0.01844000"],["78309.93000000","0.00400000"],["78310.69000000","0.02213000"],["78310.82000000","0.00400000"],["78310.94000000","2.29967000"],["78311.72000000","0.00000000"],["78311.94000000","0.02213000"],["78313.72000000","0.04043000"],["78315.00000000","0.00400000"],["78315.35000000","0.00652000"],["78315.36000000","0.01200000"],["78315.37000000","0.74658000"],["78323.84000000","0.00008000"],["78331.40000000","0.00008000"],["78333.62000000","0.00060000"],["78339.66000000","2.00678000"],["78344.39000000","1.26402000"],["78347.07000000","0.00000000"],["78348.64000000","0.00000000"],["78353.96000000","0.00000000"],["78355.39000000","0.00012000"],["78356.94000000","0.00000000"],["78359.17000000","0.00100000"],["78361.94000000","0.00318000"],["78364.60000000","0.12547000"],["78375.22000000","0.00000000"],["78375.88000000","0.00318000"],["78381.48000000","0.00000000"],["78389.27000000","0.00000000"],["78401.71000000","0.00000000"],["78425.03000000","0.00382000"],["78455.98000000","0.00127000"],["78488.20000000","0.00000000"],["78501.27000000","0.00000000"],["78542.12000000","0.00000000"],["78617.60000000","0.00100000"],["78721.70000000","0.00000000"],["78746.15000000","0.00000000"],["78821.40000000","0.00000000"],["79754.71000000","0.00272000"]]}}
{"rx":1788854516971011394, "m":{"e":"depthUpdate","E":1788854516914,"s":"BTCUSDT","U":99829845189,"u":99829845252,"b":[["78308.17000000","2.22573000"],["78301.54000000","0.31951000"],["78301.40000000","0.50014000"],["78286.32000000","0.00000000"],["78251.97000000","0.02000000"],["78166.29000000","0.00000000"],["78150.72000000","0.00000000"],["78110.81000000","0.02000000"],["77133.55000000","0.00032000"],["70495.19000000","0.00000000"],["70477.36000000","0.00032000"],["62647.00000000","0.00200000"],["62646.54000000","0.00000000"]],"a":[["78308.18000000","6.90054000"],["78308.53000000","0.73386000"],["78309.44000000","0.01858000"],["78310.61000000","2.00678000"],["78310.69000000","0.02227000"],["78310.82000000","0.00000000"],["78310.94000000","2.29967000"],["78311.69000000","0.00400000"],["78313.72000000","0.04029000"],["78315.35000000","0.00638000"],["78315.36000000","0.00400000"],["78317.75000000","0.00800000"],["78319.23000000","0.00007000"],["78322.92000000","1.31482000"],["78332.05000000","0.03400000"],["78332.97000000","2.46066000"],["78332.98000000","0.00408000"],["78355.70000000","0.01140000"],["78379.27000000","0.00637000"],["78380.80000000","0.00000000"],["78463.56000000","0.00228000"],["79874.35000000","0.00310000"]]}}
{"rx":1788854517044647404, "m":{"e":"depthUpdate","E":1788854517014,"s":"BTCUSDT","U":99829845253,"u":99829845298,"b":[["78308.17000000","2.22580000"],["78308.16000000","0.00098000"],["78305.29000000","0.07446000"],["78304.45000000","0.00014000"],["78304.44000000","0.15500000"],["78301.55000000","0.00000000"],["78301.35000000","0.00000000"],["78298.93000000","0.02000000"],["78298.76000000","0.02000000"],["78297.99000000","0.02000000"],["78253.01000000","0.02013000"],["78246.62000000","0.02000000"],["78242.40000000","0.02000000"],["78241.66000000","0.02000000"],["78230.21000000","1.23944000"],["78229.66000000","2.21464000"],["78191.57000000","0.00000000"],["78171.77000000","0.00009000"],["78141.26000000","0.00000000"],["78114.08000000","0.00000000"],["77133.55000000","0.00040000"],["70477.36000000","0.00048000"],["62662.40000000","0.00124000"],["62647.00000000","0.00000000"]],"a":[["78309.76000000","0.00007000"],["78324.03000000","0.00008000"],["78327.21000000","0.03400000"],["78327.27000000","0.04200000"],["78328.06000000","0.03800000"],["78331.10000000","0.02600000"],["78333.88000000","0.00000000"],["78337.80000000","0.53071000"],["78340.72000000","0.00000000"],["78344.53000000","0.00000000"],["78362.80000000","1.09233000"],["78366.49000000","0.04200000"],["78367.28000000","0.03800000"],["78434.49000000","0.00000000"],["78435.29000000","0.00000000"],["78440.38000000","0.00000000"],["78445.34000000","0.00000000"],["78507.46000000","0.00000000"],["79994.17000000","0.00350000"]]}}
{"rx":1788854517140876630, "m":{"e":"depthUpdate","E":1788854517114,"s":"BTCUSDT","U":99829845299,"u":99829845416,"b":[["78308.17000000","0.46351000"],["78308.16000000","0.00063000"],["78307.26000000","0.00014000"],["78306.91000000","0.00000000"],["78306.90000000","0.00014000"],["78305.29000000","0.00014000"],["78305.28000000","0.00000000"],["78305.27000000","0.00000000"],["78304.45000000","0.00000000"],["78304.44000000","0.00014000"],["78301.88000000","0.00000000"],["78301.87000000","0.00014000"],["78301.55000000","0.00014000"],["78301.41000000","0.00014000"],["78301.35000000","0.00007000"],["78301.33000000","0.06261000"],["78301.20000000","0.15000000"],["78300.03000000","0.38007000"],["78300.02000000","0.00000000"],["78299.76000000","0.00014000"],["78298.65000000","0.00000000"],["78297.30000000","0.00400000"],["78285.01000000","0.70075000"],["78280.22000000","0.31936000"],["78274.43000000","0.00664000"],["78263.85000000","0.00000000"],["78230.85000000","0.00000000"],["78150.86000000","0.00000000"],["77910.00000000","0.00544000"],["77623.05000000","0.00000000"],["77133.55000000","0.00032000"],["62647.00000000","0.00000000"]],"a":[["78308.18000000","6.90569000"],["78308.19000000","0.00027000"],["78308.24000000","0.00000000"],["78309.93000000","0.00000000"],["78310.86000000","0.00400000"],["78316.14000000","0.00008000"],["78321.60000000","0.00008000"],["78324.01000000","2.99078000"],["78328.01000000","0.17150000"],["78341.52000000","0.00000000"],["78345.25000000","0.00000000"],["78345.41000000","0.00000000"],["78405.27000000","0.00025000"],["78415.43000000","0.00012000"],["78420.52000000","0.00019000"],["78425.13000000","0.00000000"],["78452.51000000","0.00000000"]]}}
{"rx":1788854517245898640, "m":{"e":"depthUpdate","E":1788854517214,"s":"BTCUSDT","U":99829845417,"u":99829845510,"b":[["78308.17000000","0.46194000"],["78308.16000000","0.00063000"],["78307.27000000","0.00000000"],["78307.26000000","0.00000000"],["78306.90000000","0.00000000"],["78305.30000000","0.00000000"],["78305.29000000","0.00000000"],["78304.44000000","0.00000000"],["78303.75000000","0.00014000"],["78301.87000000","0.00000000"],["78301.55000000","0.00814000"],["78301.35000000","0.00014000"],["78301.34000000","0.67753000"],["78301.33000000","0.06282000"],["78301.32000000","0.30014000"],["78301.20000000","0.15014000"],["78301.05000000","0.00723000"],["78298.42000000","0.00047000"],["78297.54000000","0.02000000"],["78295.54000000","0.00000000"],["78294.90000000","0.00000000"],["78285.84000000","0.00000000"],["78271.73000000","0.00000000"],["78253.19000000","0.02000000"],["78230.85000000","0.00180000"],["78150.88000000","0.00072000"],["78120.49000000","4.57786000"],["77789.44000000","0.00000000"],["77133.55000000","0.00032000"],["70477.36000000","0.00064000"],["70477.00000000","0.00000000"],["62662.40000000","0.00093000"]],"a":[["78308.18000000","6.90771000"],["78310.00000000","0.03000000"],["78310.60000000","0.00029000"],["78312.00000000","0.01000000"],["78314.00000000","0.01000000"],["78316.00000000","0.01000000"],["78316.02000000","0.00067000"],["78323.85000000","0.00067000"],["78324.01000000","2.99065000"],["78326.00000000","0.70000000"],["78327.99000000","0.02800000"],["78330.33000000","0.03000000"],["78331.68000000","0.00081000"],["78331.77000000","0.00012000"],["78339.51000000","0.00067000"],["78340.63000000","0.00000000"],["78375.99000000","0.29765000"],["78376.00000000","0.03000000"],["78425.48000000","0.00031000"],["78489.04000000","4.48096000"]]}}
{"rx":1788854517340655312, "m":{"e":"depthUpdate","E":1788854517314,"s":"BTCUSDT","U":99829845511,"u":99829845593,"b":[["78308.17000000","0.28389000"],["78308.16000000","0.00070000"],["78304.43000000","0.15015000"],["78303.75000000","0.00007000"],["78300.81000000","0.00000000"],["78300.34000000","0.37589000"],["78300.03000000","0.00426000"],["78299.52000000","0.10732000"],["78298.89000000","0.00000000"],["78298.41000000","0.02168000"],["78297.36000000","0.00400000"],["78297.30000000","0.00000000"],["78289.61000000","0.00000000"],["78289.04000000","0.00000000"],["78282.01000000","0.00024000"],["78278.69000000","0.00000000"],["78266.13000000","0.63903000"],["78263.85000000","0.00000000"],["78258.74000000","0.00638000"],["78230.85000000","0.00000000"],["78213.76000000","0.07861000"],["78150.88000000","0.00000000"],["77133.55000000","0.00032000"],["62647.00000000","0.00000000"]],"a":[["78308.18000000","6.90840000"],["78309.44000000","0.01858000"],["78309.62000000","0.00000000"],["78310.00000000","0.03014000"],["78310.65000000","0.00000000"],["78310.94000000","2.29953000"],["78312.12000000","0.00000000"],["78314.57000000","0.00000000"],["78317.46000000","0.00000000"],["78318.00000000","0.66173000"],["78320.00000000","0.01000000"],["78322.00000000","0.15354000"],["78322.41000000","0.00000000"],["78324.00000000","0.12086000"],["78325.30000000","0.00000000"],["78326.00000000","0.71000000"],["78326.33000000","0.00000000"],["78328.00000000","0.08500000"],["78330.00000000","0.01000000"],["78332.00000000","0.01464000"],["78333.14000000","0.00000000"],["78338.97000000","0.00000000"],["78340.98000000","0.00000000"],["78344.09000000","0.00000000"],["78344.44000000","0.00000000"],["78366.26000000","0.00638000"],["78379.27000000","0.00000000"],["78402.61000000","0.04542000"],["78403.48000000","0.00408000"],["78428.52000000","0.00000000"],["78428.69000000","0.04298000"],["79482.81000000","0.00030000"]]}}
{"rx":1788854517456327772, "m":{"e":"depthUpdate","E":1788854517414,"s":"BTCUSDT","U":99829845594,"u":99829845661,"b":[["78308.17000000","0.48084000"],["78308.16000000","0.00049000"],["78304.45000000","0.00014000"],["78304.44000000","0.04625000"],["78301.34000000","0.67739000"],["78301.33000000","0.06275000"],["78301.05000000","0.00709000"],["78296.31000000","0.02000000"],["78292.42000000","0.02000000"],["78257.09000000","0.02000000"],["78252.03000000","0.02000000"],["78241.85000000","0.02000000"],["78230.85000000","0.00180000"],["78150.88000000","0.00072000"],["77133.55000000","0.00032000"],["70477.36000000","0.00080000"],["62662.40000000","0.00062000"]],"a":[["78308.18000000","6.91597000"],["78323.49000000","0.05370000"],["78328.06000000","0.07200000"],["78331.08000000","0.00188000"],["78331.88000000","0.03800000"],["78332.04000000","0.03200000"],["78345.65000000","0.00000000"],["78347.67000000","0.03400000"],["78352.16000000","0.02529000"],["78356.11000000","0.00000000"],["78367.28000000","0.07200000"]]}}
{"rx":1788854517538575536, "m":{"e":"depthUpdate","E":1788854517514,"s":"BTCUSDT","U":99829845662,"u":99829845748,"b":[["78308.17000000","0.74340000"],["78308.16000000","0.00063000"],["78305.53000000","0.00014000"],["78305.52000000","0.05135000"],["78305.51000000","0.16695000"],["78304.45000000","0.00000000"],["78304.44000000","0.00000000"],["78304.43000000","0.00000000"],["78301.41000000","0.37595000"],["78301.20000000","0.01000000"],["78300.34000000","0.00008000"],["78299.70000000","0.14000000"],["78297.99000000","0.00000000"],["78292.81000000","0.02000000"],["78282.69000000","0.00000000"],["78281.07000000","0.00000000"],["78280.88000000","0.00000000"],["78270.00000000","0.73050000"],["78267.70000000","0.00008000"],["78263.85000000","0.00007000"],["78261.27000000","0.00000000"],["78258.01000000","0.92822000"],["78243.47000000","0.02000000"],["78242.40000000","0.00000000"],["78241.66000000","0.00000000"],["78213.76000000","0.00000000"],["77133.55000000","0.00032000"],["70477.36000000","0.00096000"],["62646.54000000","0.00124000"]],"a":[["78310.00000000","0.06014000"],["78312.00000000","0.02000000"],["78314.00000000","0.02000000"],["78316.00000000","0.02000000"],["78316.53000000","0.12768000"],["78318.00000000","0.67173000"],["78320.00000000","0.02000000"],["78322.00000000","0.16354000"],["78322.49000000","0.00007000"],["78324.00000000","0.13086000"],["78324.33000000","0.12767000"],["78325.55000000","0.00007000"],["78326.00000000","0.72000000"],["78326.50000000","0.97371000"],["78328.06000000","0.03400000"],["78330.51000000","0.27422000"],["78331.63000000","0.02800000"],["78332.16000000","0.12766000"],["78345.38000000","0.00000000"],["78345.76000000","0.00000000"],["78366.19000000","1.32348000"],["78367.28000000","0.03400000"],["78375.50000000","0.00000000"],["78390.59000000","0.00000000"],["78396.61000000","0.00000000"],["78409.31000000","0.00000000"],["78410.20000000","0.00000000"],["78429.33000000","0.05904000"],["78478.40000000","0.00000000"],["78499.89000000","0.00000000"]]}}
{"rx":1788854517658607158, "m":{"e":"depthUpdate","E":1788854517614,"s":"BTCUSDT","U":99829845749,"u":99829845806,"b":[["78308.17000000","0.57436000"],["78308.16000000","0.00063000"],["78305.52000000","0.05149000"],["78305.51000000","0.00000000"],["78301.55000000","0.00014000"],["78301.54000000","0.31937000"],["78301.42000000","0.00000000"],["78301.41000000","0.00014000"],["78301.35000000","0.00007000"],["78301.32000000","0.30000000"],["78294.90000000","0.00800000"],["78291.95000000","0.02000000"],["78288.74000000","0.32085000"],["78263.85000000","0.00000000"],["78241.98000000","0.02000000"],["77133.55000000","0.00032000"],["62662.40000000","0.00031000"],["62647.00000000","0.00000000"]],"a":[["78310.10000000","0.06849000"],["78314.98000000","0.00000000"],["78319.93000000","0.00007000"],["78324.01000000","2.95036000"],["78328.00000000","0.09500000"],["78330.00000000","0.02000000"],["78331.08000000","0.04188000"],["78331.87000000","0.03200000"],["78332.00000000","0.02464000"]]}}
{"rx":1788854517745031691, "m":{"e":"depthUpdate","E":1788854517714,"s":"BTCUSDT","U":99829845807,"u":99829845861,"b":[["78308.17000000","0.31022000"],["78305.53000000","0.00000000"],["78305.52000000","0.00014000"],["78301.55000000","0.00814000"],["78301.54000000","0.31951000"],["78301.35000000","0.00014000"],["78301.34000000","0.67753000"],["78301.33000000","0.06282000"],["78301.32000000","0.30014000"],["78301.20000000","0.01014000"],["78301.05000000","0.00723000"],["78294.90000000","0.00000000"],["78281.20000000","0.00000000"],["78269.29000000","0.66078000"],["78136.02000000","0.02000000"],["77133.55000000","0.00032000"],["70477.36000000","0.00121000"]],"a":[["78308.18000000","6.91560000"],["78310.00000000","0.06014000"],["78310.10000000","0.06863000"],["78310.69000000","0.02213000"],["78327.92000000","0.04200000"],["78344.40000000","0.00000000"],["78345.18000000","0.00000000"],["78383.95000000","0.00000000"]]}}
{"rx":1788854517839801118, "m":{"e":"depthUpdate","E":1788854517814,"s":"BTCUSDT","U":99829845862,"u":99829845905,"b":[["78308.17000000","0.27183000"],["78308.16000000","0.00063000"],["78305.52000000","0.00000000"],["78304.03000000","0.14753000"],["78303.75000000","0.00014000"],["78301.88000000","0.14445000"],["78301.87000000","0.00000000"],["78301.57000000","0.00014000"],["78301.56000000","0.00000000"],["78301.55000000","0.00828000"],["78301.34000000","0.67739000"],["78301.33000000","0.06275000"],["78299.52000000","0.00000000"],["78261.57000000","0.00000000"],["77133.55000000","0.00040000"],["77133.54000000","0.00030000"],["62662.40000000","0.00000000"]],"a":[["78369.99000000","0.00542000"],["78525.87000000","0.22250000"],["78555.47000000","0.00000000"]]}}
{"rx":1788854517942194303, "m":{"e":"depthUpdate","E":1788854517914,"s":"BTCUSDT","U":99829845906,"u":99829845974,"b":[["78308.17000000","0.43999000"],["78308.16000000","0.00077000"],["78304.88000000","0.15254000"],["78304.05000000","0.00014000"],["78304.04000000","0.04553000"],["78304.03000000","0.00014000"],["78301.89000000","0.00000000"],["78301.88000000","0.00014000"],["78301.87000000","0.48345000"],["78301.57000000","0.00000000"],["78301.56000000","0.48345000"],["78301.35000000","0.00007000"],["78301.20000000","0.01000000"],["78301.05000000","0.00709000"],["78293.54000000","0.01391000"],["78238.98000000","1.06445000"],["78238.70000000","0.06328000"],["78159.50000000","0.00000000"],["78151.41000000","0.00665000"],["78092.71000000","0.00000000"],["78075.15000000","0.00802000"],["77133.55000000","0.00040000"],["70477.36000000","0.00137000"],["62646.54000000","0.00124000"]],"a":[["78332.98000000","0.00000000"],["78340.77000000","0.32683000"],["78341.32000000","0.00000000"],["78364.23000000","0.00000000"],["78372.15000000","0.00000000"],["78403.48000000","0.00000000"],["79015.88000000","0.00000000"],["79043.69000000","0.00018000"]]}}
{"rx":1788854518039940747, "m":{"e":"depthUpdate","E":1788854518014,"s":"BTCUSDT","U":99829845975,"u":99829846061,"b":[["78308.17000000","0.43956000"],["78308.16000000","0.00048000"],["78308.15000000","0.00013000"],["78304.89000000","0.00014000"],["78304.88000000","0.15268000"],["78304.04000000","0.14000000"],["78304.03000000","0.00000000"],["78301.88000000","0.00014000"],["78301.87000000","0.48359000"],["78301.57000000","0.00000000"],["78301.56000000","0.00014000"],["78301.41000000","0.00007000"],["78301.35000000","0.00000000"],["78301.33000000","0.06261000"],["78301.32000000","0.30000000"],["78295.72000000","0.02000000"],["78256.50000000","0.02000000"],["78253.77000000","0.55709000"],["78238.98000000","1.03746000"],["77133.55000000","0.00040000"],["62659.20000000","0.00093000"],["62646.54000000","0.00248000"]],"a":[["78328.00000000","0.13300000"],["78340.67000000","0.03828000"],["78347.61000000","0.03800000"],["78356.48000000","0.30663000"],["78356.49000000","0.55287000"],["78356.99000000","0.00000000"],["78363.62000000","0.00000000"],["78367.22000000","0.03800000"]]}}
{"rx":1788854518140652446, "m":{"e":"depthUpdate","E":1788854518114,"s":"BTCUSDT","U":99829846062,"u":99829846117,"b":[["78308.17000000","0.42726000"],["78308.16000000","0.00076000"],["78304.90000000","0.00014000"],["78304.89000000","0.04715000"],["78304.05000000","0.00000000"],["78304.04000000","0.00014000"],["78301.88000000","0.00000000"],["78301.87000000","0.00014000"],["78301.57000000","0.00014000"],["78301.56000000","0.44652000"],["78301.41000000","0.00014000"],["78301.35000000","0.00000000"],["78301.33000000","0.06275000"],["78218.85000000","0.89244000"],["78218.84000000","1.00208000"],["78218.60000000","0.00000000"],["77603.40000000","0.00010000"],["77133.55000000","0.00032000"],["70477.36000000","0.00153000"]],"a":[["78743.93000000","0.00000000"]]}}
{"rx":1788854518252301014, "m":{"e":"depthUpdate","E":1788854518214,"s":"BTCUSDT","U":99829846118,"u":99829846219,"b":[["78308.17000000","0.54845000"],["78308.16000000","0.00076000"],["78305.83000000","0.00014000"],["78305.82000000","0.03958000"],["78305.81000000","0.13214000"],["78304.89000000","0.00014000"],["78304.88000000","0.00014000"],["78304.04000000","0.00000000"],["78301.88000000","0.00000000"],["78301.87000000","0.00000000"],["78301.57000000","0.00000000"],["78301.56000000","0.00014000"],["78301.55000000","0.00828000"],["78301.41000000","0.00007000"],["78300.34000000","0.37589000"],["78261.37000000","0.00000000"],["78259.89000000","0.00663000"],["78252.26000000","0.02000000"],["77292.28000000","0.00000000"],["77133.55000000","0.00032000"],["70477.36000000","0.00169000"],["62659.20000000","0.00062000"]],"a":[["78308.18000000","6.91570000"],["78354.99000000","0.00400000"],["78355.28000000","0.00000000"],["78621.41000000","0.00127000"],["78796.02000000","0.00000000"],["82921.18000000","0.00000000"]]}}
{"rx":1788854518361916515, "m":{"e":"depthUpdate","E":1788854518314,"s":"BTCUSDT","U":99829846220,"u":99829846320,"b":[["78308.17000000","0.51791000"],["78308.16000000","0.00076000"],["78305.82000000","0.03972000"],["78305.81000000","0.00014000"],["78304.90000000","0.00000000"],["78304.89000000","0.00000000"],["78304.88000000","0.00000000"],["78303.75000000","0.00007000"],["78301.56000000","0.00000000"],["78301.55000000","0.00028000"],["78301.41000000","0.00014000"],["78301.35000000","0.00007000"],["78301.33000000","0.00014000"],["78301.32000000","0.30014000"],["78301.20000000","0.00000000"],["78300.34000000","0.00008000"],["78300.01000000","0.37581000"],["78299.76000000","0.00007000"],["78299.70000000","0.15000000"],["78299.32000000","0.00000000"],["78298.41000000","0.00000000"],["78297.89000000","0.00400000"],["78297.58000000","0.02105000"],["78297.36000000","0.00000000"],["78297.19000000","0.00400000"],["78294.90000000","2.30922000"],["78294.88000000","0.00000000"],["78291.06000000","0.00000000"],["78289.45000000","0.00000000"],["78263.85000000","0.00007000"],["78254.02000000","2.30922000"],["78230.85000000","0.00000000"],["78214.70000000","0.00000000"],["78150.88000000","0.00000000"],["78088.95000000","0.00000000"],["77133.55000000","0.00032000"]],"a":[["78308.18000000","6.91570000"],["78311.69000000","0.00000000"],["78312.10000000","0.00000000"],["78315.26000000","0.03000000"],["78316.02000000","0.00067000"],["78319.94000000","0.00000000"],["78323.36000000","0.12000000"],["78323.86000000","0.00000000"],["78332.92000000","0.37581000"],["78332.94000000","0.00000000"],["78396.53000000","0.00408000"],["79482.81000000","0.00030000"]]}}
{"rx":1788854518460852331, "m":{"e":"depthUpdate","E":1788854518414,"s":"BTCUSDT","U":99829846321,"u":99829846410,"b":[["78308.17000000","0.51776000"],["78308.16000000","0.00090000"],["78305.83000000","0.00000000"],["78305.82000000","0.00014000"],["78305.81000000","0.00000000"],["78301.89000000","0.00014000"],["78301.88000000","0.14445000"],["78301.87000000","0.48345000"],["78301.56000000","0.00000000"],["78301.55000000","0.00814000"],["78301.35000000","0.00014000"],["78301.34000000","0.67739000"],["78301.33000000","0.00000000"],["78301.32000000","0.30014000"],["78301.22000000","0.10732000"],["78301.05000000","0.00723000"],["78300.33000000","0.20264000"],["78300.01000000","0.37595000"],["78299.76000000","0.00014000"],["78294.91000000","0.62590000"],["78294.89000000","0.00000000"],["78289.46000000","2.29861000"],["78263.85000000","0.00000000"],["78254.03000000","1.87954000"],["78253.75000000","0.00000000"],["78237.48000000","0.02000000"],["78230.85000000","0.00180000"],["78218.85000000","0.86707000"],["78151.42000000","0.00072000"],["77133.55000000","0.00032000"],["70477.36000000","0.00185000"],["62659.20000000","0.00031000"]],"a":[["78308.87000000","0.00000000"],["78310.33000000","0.00400000"],["78466.04000000","0.00000000"]]}}
{"rx":1788854518562257933, "m":{"e":"depthUpdate","E":1788854518514,"s":"BTCUSDT","U":99829846411,"u":99829846443,"b":[["78308.17000000","0.51784000"],["78305.82000000","0.00000000"],["78303.57000000","0.15903000"],["78301.88000000","0.14459000"],["78301.87000000","0.48359000"],["78301.55000000","0.00828000"],["78301.32000000","0.30014000"],["78301.22000000","0.10746000"],["78301.05000000","0.00709000"],["78300.33000000","0.20250000"],["78300.01000000","0.37581000"],["78298.76000000","0.00000000"],["78281.62000000","0.00000000"],["78262.01000000","0.00000000"],["78259.97000000","0.00335000"],["77133.55000000","0.00032000"]],"a":[["78319.44000000","0.00007000"],["78327.27000000","0.00000000"],["78365.20000000","0.00408000"],["78366.49000000","0.00000000"],["78389.69000000","0.00000000"],["78396.61000000","0.02800000"]]}}
{"rx":1788854518658272846, "m":{"e":"depthUpdate","E":1788854518614,"s":"BTCUSDT","U":99829846444,"u":99829846476,"b":[["78308.17000000","0.78166000"],["78308.16000000","0.00097000"],["78304.48000000","0.00014000"],["78304.47000000","0.13533000"],["78303.58000000","0.00000000"],["78303.57000000","0.00014000"],["78301.35000000","0.00000000"],["78301.22000000","0.10732000"],["78300.85000000","0.00574000"],["78300.01000000","0.37644000"],["77133.55000000","0.00032000"],["70477.36000000","0.00201000"],["62659.20000000","0.00000000"]],"a":[["78328.60000000","0.00007000"]]}}
{"rx":1788854518759934940, "m":{"e":"depthUpdate","E":1788854518714,"s":"BTCUSDT","U":99829846477,"u":99829846598,"b":[["78308.17000000","0.06696000"],["78308.16000000","0.00076000"],["78304.49000000","0.00000000"],["78304.48000000","0.00000000"],["78304.47000000","0.00014000"],["78303.57000000","0.00000000"],["78302.41000000","0.00014000"],["78302.40000000","0.02000000"],["78301.89000000","0.00800000"],["78301.88000000","0.00014000"],["78301.87000000","0.00014000"],["78301.55000000","0.00028000"],["78301.35000000","0.00014000"],["78301.33000000","0.00014000"],["78301.22000000","0.00000000"],["78300.34000000","0.00008000"],["78300.01000000","0.00063000"],["78299.76000000","0.00007000"],["78299.70000000","0.01000000"],["78297.89000000","0.00000000"],["78297.58000000","0.00000000"],["78297.00000000","0.07238000"],["78296.99000000","0.00000000"],["78296.94000000","0.00000000"],["78294.91000000","0.00000000"],["78294.90000000","0.00000000"],["78294.63000000","0.00400000"],["78294.50000000","0.12000000"],["78292.07000000","0.37581000"],["78292.06000000","0.00000000"],["78291.20000000","0.00000000"],["78289.46000000","0.00000000"],["78288.74000000","0.00150000"],["78285.02000000","0.31937000"],["78270.80000000","0.00000000"],["78270.56000000","0.00000000"],["78263.85000000","0.00007000"],["78261.91000000","0.00667000"],["78250.71000000","0.34514000"],["78242.07000000","0.00408000"],["78214.71000000","1.91077000"],["78214.70000000","2.29861000"],["78213.54000000","0.00000000"],["77133.55000000","0.00032000"],["70477.36000000","0.00192000"],["70477.35000000","0.00009000"]],"a":[["78308.18000000","6.91761000"],["78309.62000000","0.06849000"],["78310.10000000","0.00014000"],["78310.60000000","0.00000000"],["78310.94000000","2.29802000"],["78315.28000000","0.03057000"],["78319.18000000","0.02000000"],["78319.93000000","0.00007000"],["78323.55000000","0.63856000"],["78327.09000000","0.00000000"],["78330.51000000","0.39170000"],["78332.88000000","0.34478000"],["78366.37000000","0.00000000"],["78439.21000000","0.00000000"],["78626.56000000","0.00000000"]]}}
{"rx":1788854518852516499, "m":{"e":"depthUpdate","E":1788854518814,"s":"BTCUSDT","U":99829846599,"u":99829846663,"b":[["78308.17000000","0.06710000"],["78304.47000000","0.00000000"],["78302.40000000","0.02014000"],["78301.89000000","0.00014000"],["78301.88000000","0.00000000"],["78301.87000000","0.00000000"],["78301.55000000","0.00014000"],["78301.32000000","0.30014000"],["78301.05000000","0.00723000"],["78299.76000000","0.00014000"],["78296.75000000","0.00000000"],["78292.08000000","0.00000000"],["78290.42000000","0.00800000"],["78277.57000000","0.00000000"],["78270.00000000","0.03050000"],["78123.12000000","0.00007000"],["78081.55000000","0.00000000"],["78063.79000000","0.00000000"],["77133.55000000","0.00040000"],["77133.54000000","0.00030000"],["70477.36000000","0.00208000"],["62646.54000000","0.00217000"]],"a":[["78308.18000000","6.92417000"],["78309.44000000","0.01858000"],["78309.62000000","0.06863000"],["78310.00000000","0.06014000"],["78310.10000000","0.00000000"],["78310.60000000","0.01600000"],["78315.35000000","0.00000000"],["78317.75000000","0.00000000"],["78317.99000000","0.00400000"]]}}
{"rx":1788854518957780092, "m":{"e":"depthUpdate","E":1788854518914,"s":"BTCUSDT","U":99829846664,"u":99829846758,"b":[["78308.17000000","0.43083000"],["78308.16000000","0.00076000"],["78303.67000000","0.48345000"],["78302.78000000","0.33939000"],["78302.77000000","0.48345000"],["78302.41000000","0.00000000"],["78302.40000000","0.02014000"],["78302.10000000","0.00014000"],["78302.09000000","0.14508000"],["78301.89000000","0.00000000"],["78301.88000000","0.00014000"],["78301.87000000","0.00000000"],["78301.55000000","0.00014000"],["78301.35000000","0.00000000"],["78301.33000000","0.00000000"],["78300.85000000","0.00588000"],["78298.38000000","0.00400000"],["78297.00000000","0.07202000"],["78296.67000000","0.02092000"],["78294.63000000","0.00000000"],["78289.45000000","2.29861000"],["78287.94000000","0.00000000"],["78287.68000000","0.00000000"],["78274.79000000","0.00059000"],["78274.42000000","0.00012000"],["78259.89000000","0.00000000"],["78214.70000000","0.00000000"],["77133.55000000","0.00040000"],["70477.36000000","0.00224000"],["62646.54000000","0.00217000"]],"a":[["78310.00000000","0.06014000"],["78310.59000000","0.00000000"],["78310.60000000","0.00014000"],["78310.61000000","2.00664000"],["78310.67000000","0.00400000"],["78313.99000000","0.01600000"],["78326.03000000","0.00408000"],["78352.22000000","0.00400000"],["78352.36000000","0.00000000"],["78354.99000000","0.00000000"],["78368.15000000","0.00112000"],["78382.30000000","0.00000000"]]}}
{"rx":1788854519073443294, "m":{"e":"depthUpdate","E":1788854519014,"s":"BTCUSDT","U":99829846759,"u":99829846884,"b":[["78308.17000000","0.06738000"],["78308.16000000","0.00090000"],["78303.78000000","0.00000000"],["78303.77000000","0.00000000"],["78303.76000000","0.00000000"],["78303.69000000","0.00000000"],["78303.68000000","0.00000000"],["78303.67000000","0.00014000"],["78302.79000000","0.00000000"],["78302.78000000","0.00014000"],["78302.77000000","0.00014000"],["78302.41000000","0.00000000"],["78302.40000000","0.00000000"],["78302.10000000","0.00000000"],["78302.09000000","0.00000000"],["78301.88000000","0.00000000"],["78301.51000000","0.00014000"],["78301.50000000","0.02000000"],["78301.41000000","0.00014000"],["78301.35000000","0.00014000"],["78301.33000000","0.00007000"],["78301.32000000","0.30000000"],["78301.05000000","0.00709000"],["78300.85000000","0.00574000"],["78300.11000000","0.10732000"],["78298.38000000","0.00000000"],["78297.05000000","0.00000000"],["78296.09000000","0.00400000"],["78293.14000000","0.02000000"],["78289.45000000","0.00000000"],["78253.92000000","0.02000000"],["78236.89000000","0.02000000"],["78214.73000000","1.91077000"],["78214.72000000","2.29861000"],["78214.71000000","0.00000000"],["77133.55000000","0.00040000"],["62646.54000000","0.00310000"]],"a":[["78310.00000000","0.06014000"],["78310.60000000","0.00000000"],["78310.61000000","2.00678000"],["78325.65000000","0.04200000"],["78345.26000000","0.04200000"],["78364.87000000","0.04200000"]]}}
{"rx":1788854519171582044, "m":{"e":"depthUpdate","E":1788854519114,"s":"BTCUSDT","U":99829846885,"u":99829846939,"b":[["78308.17000000","0.23973000"],["78308.16000000","0.00076000"],["78303.67000000","0.00000000"],["78302.78000000","0.00000000"],["78302.77000000","0.00000000"],["78301.54000000","0.31951000"],["78301.50000000","0.02014000"],["78301.33000000","0.00000000"],["78301.32000000","0.00014000"],["78300.34000000","0.00015000"],["78300.11000000","0.00000000"],["78299.76000000","0.00014000"],["78281.22000000","0.00408000"],["78276.79000000","0.00000000"],["78269.13000000","0.88541000"],["78210.81000000","0.04974000"],["78210.80000000","0.07587000"],["78210.01000000","0.00000000"],["77994.29000000","0.00000000"],["77292.28000000","0.00010000"],["77133.55000000","0.00032000"],["70477.36000000","0.00240000"],["62662.00000000","0.00000000"]],"a":[["78323.49000000","0.00000000"],["78346.69000000","0.02548000"],["78352.16000000","0.00000000"],["78574.39000000","0.00000000"]]}}
{"rx":1788854519279561654, "m":{"e":"depthUpdate","E":1788854519214,"s":"BTCUSDT","U":99829846940,"u":99829846959,"b":[["78308.17000000","0.24573000"],["78303.13000000","0.14802000"],["78301.34000000","0.67739000"],["78301.32000000","0.00000000"],["78301.05000000","0.00723000"],["77986.12000000","0.00037000"],["77133.55000000","0.00032000"],["62646.54000000","0.00279000"]],"a":[["78565.96000000","0.00029000"]]}}
{"rx":1788854519385992718, "m":{"e":"depthUpdate","E":1788854519314,"s":"BTCUSDT","U":99829846960,"u":99829846999,"b":[["78308.17000000","0.23920000"],["78308.16000000","0.00090000"],["78303.15000000","0.00014000"],["78303.14000000","0.04559000"],["78301.51000000","0.00000000"],["78300.34000000","0.00008000"],["78281.22000000","0.00000000"],["78210.81000000","0.05096000"],["78210.76000000","0.00408000"],["77133.55000000","0.00032000"],["70477.36000000","0.00256000"],["70477.35000000","0.00000000"],["62647.00000000","0.00000000"]],"a":[["78308.18000000","6.92493000"],["78316.02000000","0.00066000"],["78323.85000000","0.00000000"],["78331.68000000","0.00014000"],["78339.51000000","0.00000000"],["78365.20000000","0.00000000"],["78396.53000000","0.00000000"],["79482.81000000","0.00030000"],["82921.18000000","0.00010000"]]}}
{"rx":1788854519470887741, "m":{"e":"depthUpdate","E":1788854519414,"s":"BTCUSDT","U":99829847000,"u":99829847054,"b":[["78308.17000000","0.24520000"],["78308.16000000","0.00090000"],["78303.94000000","0.00014000"],["78303.93000000","0.04536000"],["78303.92000000","0.14703000"],["78303.15000000","0.00000000"],["78303.14000000","0.00000000"],["78303.13000000","0.00000000"],["78293.54000000","0.00000000"],["77985.35000000","0.02500000"],["77133.55000000","0.00032000"],["70477.36000000","0.00272000"],["70477.00000000","0.00020000"],["62646.54000000","0.00248000"]],"a":[["78309.14000000","0.00000000"],["78309.79000000","0.00000000"],["78313.71000000","0.00000000"],["78316.98000000","0.00000000"],["78317.63000000","0.00000000"],["78319.50000000","0.04804000"],["78321.55000000","0.00000000"],["78323.85000000","0.00066000"],["78324.82000000","0.00000000"],["78325.47000000","0.00000000"],["78331.68000000","0.00080000"],["78339.51000000","0.00066000"]]}}
{"rx":1788854519577751046, "m":{"e":"depthUpdate","E":1788854519514,"s":"BTCUSDT","U":99829847055,"u":99829847072,"b":[["78308.17000000","0.23920000"],["78308.16000000","0.00090000"],["78303.92000000","0.00000000"],["78296.09000000","0.00000000"],["78295.21000000","0.00400000"],["77133.55000000","0.00032000"],["75000.00000000","244.61243000"],["70477.00000000","0.00000000"]],"a":[["78310.60000000","0.00400000"],["78316.38000000","0.00007000"],["78317.99000000","0.00000000"]]}}
{"rx":1788854519675554877, "m":{"e":"depthUpdate","E":1788854519614,"s":"BTCUSDT","U":99829847073,"u":99829847090,"b":[["78308.17000000","0.23905000"],["78308.16000000","0.00083000"],["78303.94000000","0.00000000"],["78303.93000000","0.00000000"],["78301.51000000","0.00014000"],["78300.34000000","0.00015000"],["78267.00000000","0.70000000"],["77133.55000000","0.00032000"],["70477.36000000","0.00288000"],["62647.00000000","0.00200000"],["62646.54000000","0.00217000"]],"a":[["78399.36000000","0.00007000"]]}}
{"rx":1788854519771988617, "m":{"e":"depthUpdate","E":1788854519714,"s":"BTCUSDT","U":99829847091,"u":99829847104,"b":[["78308.17000000","0.23898000"],["78308.16000000","0.00076000"],["78303.75000000","0.00045000"],["77133.55000000","0.00032000"],["62647.00000000","0.00000000"]],"a":[["78310.00000000","0.07514000"],["78312.00000000","0.02500000"],["78314.00000000","0.02500000"],["78316.00000000","0.02500000"],["78318.00000000","0.67673000"],["78319.93000000","0.00007000"],["78320.00000000","0.02500000"]]}}
{"rx":1788854519857143477, "m":{"e":"depthUpdate","E":1788854519814,"s":"BTCUSDT","U":99829847105,"u":99829847138,"b":[["78308.17000000","0.23920000"],["78308.16000000","0.00090000"],["78301.74000000","0.00014000"],["78301.73000000","0.04630000"],["78301.72000000","0.15465000"],["78301.51000000","0.00000000"],["78300.34000000","0.00008000"],["77133.55000000","0.00040000"],["77133.54000000","0.00030000"],["70477.36000000","0.00304000"],["62646.54000000","0.00186000"]],"a":[["78308.18000000","6.92492000"],["78310.00000000","0.09014000"],["78310.60000000","0.00000000"],["78312.00000000","0.03000000"],["78313.98000000","0.00400000"],["78314.00000000","0.03000000"],["78322.00000000","0.16854000"],["78324.00000000","0.13586000"],["78326.00000000","0.72500000"],["78328.00000000","0.13800000"],["78330.00000000","0.02500000"],["78332.00000000","0.02500000"],["78340.35000000","0.00000000"]]}}
{"rx":1788854519955968304, "m":{"e":"depthUpdate","E":1788854519914,"s":"BTCUSDT","U":99829847139,"u":99829847169,"b":[["78308.17000000","0.23920000"],["78308.16000000","0.00090000"],["78302.59000000","0.00014000"],["78302.58000000","0.04249000"],["78302.57000000","0.13749000"],["78301.74000000","0.00000000"],["78301.73000000","0.00000000"],["78301.72000000","0.00000000"],["77133.55000000","0.00040000"],["62646.54000000","0.00206000"]],"a":[["78310.60000000","0.00400000"],["78313.98000000","0.00000000"],["78316.00000000","0.03000000"],["78318.00000000","0.68173000"],["78320.00000000","0.03000000"],["78322.00000000","0.17354000"],["78324.00000000","0.14086000"],["78326.00000000","0.73000000"],["78328.00000000","0.14300000"],["78330.00000000","0.03000000"],["78332.00000000","0.03000000"],["78366.10000000","0.00000000"]]}}
{"rx":1788854520051331464, "m":{"e":"depthUpdate","E":1788854520014,"s":"BTCUSDT","U":99829847170,"u":99829847256,"b":[["78308.17000000","0.24512000"],["78308.16000000","0.00090000"],["78304.31000000","0.13670000"],["78302.57000000","0.00000000"],["78293.58000000","0.00007000"],["78289.94000000","0.15188000"],["78285.88000000","0.31937000"],["78285.02000000","0.00000000"],["78284.34000000","0.00007000"],["78282.01000000","0.00000000"],["78281.92000000","0.31937000"],["78280.22000000","0.00000000"],["78279.26000000","0.00024000"],["78278.01000000","0.31937000"],["78274.02000000","0.31937000"],["78269.55000000","1.28904000"],["78268.68000000","0.00007000"],["78253.02000000","0.00015000"],["78237.36000000","0.00007000"],["78234.31000000","0.02000000"],["78221.70000000","0.00007000"],["78210.81000000","0.04788000"],["78206.04000000","0.00007000"],["78190.38000000","0.00007000"],["78174.72000000","0.00007000"],["78159.06000000","0.00007000"],["78143.40000000","0.00007000"],["78127.74000000","0.00007000"],["78112.08000000","0.00007000"],["78096.42000000","0.00007000"],["78080.76000000","0.00007000"],["78065.10000000","0.00007000"],["77133.55000000","0.00040000"],["70477.36000000","0.00320000"],["62646.54000000","0.00279000"]],"a":[["78308.18000000","6.93449000"],["78313.98000000","0.00400000"],["78315.36000000","0.37581000"],["78315.56000000","0.00179000"],["78317.09000000","0.00007000"],["78320.51000000","0.48834000"],["78323.27000000","0.37581000"],["78324.32000000","0.31937000"],["78325.64000000","0.00049000"],["78327.62000000","0.00000000"],["78328.59000000","0.31937000"],["78331.32000000","0.00007000"],["78332.15000000","0.31937000"],["78332.93000000","0.00000000"],["78346.98000000","0.00007000"],["78356.48000000","0.53142000"],["78356.93000000","0.00000000"],["78358.57000000","0.00318000"],["78359.50000000","0.88439000"],["78362.64000000","0.00007000"],["78378.30000000","0.00007000"],["78383.84000000","0.00000000"],["78393.96000000","0.00007000"],["78409.62000000","0.00007000"],["78425.28000000","0.00007000"],["78437.99000000","0.00134000"],["78440.94000000","0.00007000"],["78456.60000000","0.00007000"],["78461.96000000","0.00000000"],["78472.26000000","0.00007000"],["78487.92000000","0.00007000"],["78503.58000000","0.00007000"],["78519.24000000","0.00007000"],["78525.57000000","0.00012000"],["78534.90000000","0.00017000"],["78539.68000000","0.00007000"],["78550.56000000","0.00007000"],["86422.88000000","0.22692000"]]}}
{"rx":1788854520153544150, "m":{"e":"depthUpdate","E":1788854520114,"s":"BTCUSDT","U":99829847257,"u":99829847304,"b":[["78308.17000000","0.24512000"],["78308.16000000","0.00090000"],["78304.33000000","0.00014000"],["78304.32000000","0.04243000"],["78302.59000000","0.00000000"],["78302.58000000","0.00000000"],["78298.47000000","0.10732000"],["78195.44000000","0.03960000"],["78145.65000000","0.00206000"],["77162.44000000","0.00127000"],["77133.55000000","0.00032000"],["70477.36000000","0.00336000"]],"a":[["78310.60000000","0.00400000"],["78313.97000000","0.00000000"],["78313.98000000","0.00400000"],["78323.27000000","0.67581000"],["78324.01000000","2.65036000"],["78395.45000000","0.00408000"],["78427.21000000","0.10358000"],["78430.38000000","0.10344000"],["78446.79000000","0.00000000"],["78453.16000000","0.00206000"],["78512.29000000","0.00000000"],["78513.45000000","0.00000000"],["78525.56000000","0.00000000"],["78539.67000000","0.00000000"],["86422.88000000","0.24583000"]]}}
{"rx":1788854520257024756, "m":{"e":"depthUpdate","E":1788854520214,"s":"BTCUSDT","U":99829847305,"u":99829847357,"b":[["78308.17000000","0.50722000"],["78308.16000000","0.00090000"],["78305.26000000","0.00014000"],["78305.25000000","0.03897000"],["78305.24000000","0.12509000"],["78304.33000000","0.00000000"],["78304.32000000","0.00000000"],["78304.31000000","0.00000000"],["77133.55000000","0.00032000"],["70477.35000000","0.00009000"],["62646.54000000","0.00248000"]],"a":[["78308.18000000","6.93463000"],["78308.51000000","0.00000000"],["78310.60000000","0.00000000"],["78313.98000000","0.00400000"],["78314.99000000","0.00400000"],["78315.35000000","0.00000000"],["78320.51000000","0.16897000"],["78321.59000000","0.31937000"],["78322.91000000","1.60440000"],["78322.92000000","0.30000000"],["78699.71000000","0.00127000"],["84202.54000000","0.03094000"]]}}
{"rx":1788854520355332293, "m":{"e":"depthUpdate","E":1788854520314,"s":"BTCUSDT","U":99829847358,"u":99829847405,"b":[["78308.17000000","0.23822000"],["78305.25000000","0.03911000"],["78305.24000000","0.12523000"],["78300.85000000","0.00588000"],["77994.93000000","0.00128000"],["77133.55000000","0.00032000"],["70477.36000000","0.00352000"]],"a":[["78308.18000000","6.93500000"],["78310.60000000","0.00400000"],["78313.98000000","0.00400000"],["78314.99000000","0.00000000"],["78322.91000000","1.90440000"],["78323.28000000","0.00400000"],["78364.12000000","0.00408000"],["78512.60000000","0.00000000"],["79482.81000000","0.00030000"],["84202.54000000","0.03536000"]]}}
{"rx":1788854520443482615, "m":{"e":"depthUpdate","E":1788854520414,"s":"BTCUSDT","U":99829847406,"u":99829847439,"b":[["78308.17000000","0.24058000"],["78308.16000000","0.00076000"],["78305.26000000","0.00000000"],["78305.25000000","0.00014000"],["78305.24000000","0.00014000"],["78301.56000000","0.00014000"],["78301.55000000","0.48359000"],["78301.51000000","0.00000000"],["78300.34000000","0.00015000"],["77133.55000000","0.00032000"],["62646.54000000","0.00217000"]],"a":[["78308.72000000","0.02124000"],["78310.60000000","0.00400000"],["78313.98000000","0.00400000"],["78316.56000000","0.02083000"],["78324.40000000","0.02094000"],["78332.24000000","0.02107000"],["78340.08000000","0.02169000"],["78512.80000000","0.12778000"]]}}
{"rx":1788854520546969372, "m":{"e":"depthUpdate","E":1788854520514,"s":"BTCUSDT","U":99829847440,"u":99829847812,"b":[["78308.17000000","0.00000000"],["78308.16000000","0.00000000"],["78308.15000000","0.00000000"],["78307.74000000","0.00000000"],["78305.33000000","0.52392000"],["78305.32000000","0.00063000"],["78305.25000000","0.00000000"],["78305.24000000","0.00000000"],["78301.56000000","0.00000000"],["78301.55000000","0.00014000"],["78301.54000000","0.00014000"],["78301.51000000","0.00014000"],["78300.34000000","0.00014000"],["78300.33000000","0.20264000"],["78300.01000000","0.00070000"],["78297.42000000","0.00008000"],["78297.40000000","0.00000000"],["78297.19000000","0.00000000"],["78296.67000000","0.00000000"],["78295.79000000","0.00400000"],["78295.21000000","0.00000000"],["78295.03000000","0.00000000"],["78294.30000000","0.00400000"],["78293.80000000","0.30892000"],["78293.48000000","0.00000000"],["78292.29000000","0.31941000"],["78291.56000000","0.00000000"],["78290.60000000","0.00000000"],["78288.64000000","0.00000000"],["78285.88000000","0.00000000"],["78285.02000000","0.31937000"],["78281.92000000","0.00000000"],["78281.91000000","0.00000000"],["78280.22000000","0.31937000"],["78280.16000000","0.00408000"],["78278.01000000","0.00000000"],["78276.17000000","0.31937000"],["78269.55000000","1.25901000"],["78269.00000000","0.00000000"],["78267.84000000","0.00014000"],["78266.00000000","0.04000000"],["78262.44000000","0.00000000"],["78260.23000000","0.63908000"],["78257.90000000","0.00008000"],["78237.68000000","0.00000000"],["78230.70000000","1.26586000"],["78226.94000000","0.00008000"],["78218.85000000","0.00000000"],["78218.84000000","0.00000000"],["78210.81000000","0.00000000"],["78210.80000000","0.00000000"],["78159.37000000","0.00000000"],["78148.64000000","0.00008000"],["78081.05000000","0.00000000"],["78070.33000000","0.00008000"],["78002.74000000","0.00000000"],["77992.03000000","0.00008000"],["77976.72000000","0.00250000"],["77924.42000000","0.00000000"],["77913.72000000","0.00008000"],["77846.10000000","0.00000000"],["77835.42000000","0.00008000"],["77767.79000000","0.00000000"],["77757.11000000","0.00008000"],["77689.47000000","0.00000000"],["77678.81000000","0.00008000"],["77133.55000000","0.00000000"],["77133.54000000","0.00000000"],["77130.75000000","0.00008000"],["70477.36000000","0.00000000"],["70477.35000000","0.00000000"],["70477.34000000","0.00009000"],["70474.80000000","0.00016000"],["62644.27000000","0.00124000"]],"a":[["78305.34000000","8.85886000"],["78305.35000000","0.05027000"],["78305.36000000","0.00013000"],["78305.40000000","0.05000000"],["78306.24000000","0.00000000"],["78306.34000000","0.00000000"],["78306.53000000","0.00400000"],["78306.78000000","0.06849000"],["78306.91000000","0.00000000"],["78307.14000000","0.00000000"],["78307.65000000","0.00400000"],["78307.73000000","0.00000000"],["78307.74000000","0.00014000"],["78307.75000000","0.00000000"],["78308.04000000","0.00000000"],["78308.16000000","0.20250000"],["78308.17000000","0.91759000"],["78308.18000000","2.59868000"],["78308.19000000","0.00000000"],["78308.20000000","0.00014000"],["78308.25000000","0.00014000"],["78308.52000000","0.00014000"],["78308.53000000","0.11199000"],["78308.72000000","0.00014000"],["78309.45000000","0.00000000"],["78309.62000000","0.00014000"],["78310.00000000","0.09000000"],["78310.33000000","0.00000000"],["78310.60000000","0.63045000"],["78310.61000000","2.00664000"],["78310.86000000","0.00000000"],["78310.94000000","0.00000000"],["78312.44000000","0.00007000"],["78313.17000000","0.00008000"],["78313.33000000","0.00007000"],["78313.98000000","0.00000000"],["78315.12000000","0.00007000"],["78315.35000000","0.00010000"],["78316.36000000","0.00000000"],["78316.56000000","0.00000000"],["78316.70000000","0.00008000"],["78317.09000000","0.00000000"],["78317.29000000","0.00000000"],["78317.45000000","0.09684000"],["78318.01000000","0.00000000"],["78319.41000000","0.10272000"],["78321.00000000","0.00008000"],["78321.21000000","0.00000000"],["78322.02000000","0.30000000"],["78324.01000000","2.65029000"],["78324.16000000","0.00000000"],["78324.40000000","0.00000000"],["78324.92000000","0.00008000"],["78324.96000000","0.00000000"],["78325.13000000","0.00000000"],["78326.11000000","0.00000000"],["78326.61000000","0.00000000"],["78326.85000000","0.00007000"],["78328.00000000","0.06800000"],["78328.83000000","0.00008000"],["78329.68000000","0.00255000"],["78330.53000000","0.00000000"],["78332.24000000","0.00000000"],["78332.75000000","0.00008000"],["78333.67000000","0.00000000"],["78334.44000000","0.00000000"],["78336.66000000","0.00008000"],["78338.36000000","0.00000000"],["78340.08000000","0.00000000"],["78340.41000000","0.00000000"],["78340.58000000","0.00008000"],["78342.27000000","0.00000000"],["78344.49000000","0.00008000"],["78345.00000000","0.01000000"],["78346.19000000","0.00000000"],["78347.92000000","0.00000000"],["78348.00000000","0.03000000"],["78350.11000000","0.00000000"],["78361.95000000","2.03792000"],["78364.12000000","0.00000000"],["78365.70000000","0.00000000"],["78375.99000000","0.00000000"],["78378.07000000","0.00010000"],["78395.45000000","0.00000000"],["78399.36000000","0.00000000"],["78435.77000000","0.00107000"],["78472.15000000","0.00000000"],["78498.94000000","0.00000000"],["78512.80000000","0.00000000"],["78513.55000000","0.12778000"],["78843.15000000","0.00250000"],["79482.81000000","0.00000000"]]}}
{"rx":1788854520655900428, "m":{"e":"depthUpdate","E":1788854520614,"s":"BTCUSDT","U":99829847813,"u":99829847936,"b":[["78305.33000000","0.19361000"],["78305.32000000","0.00063000"],["78302.31000000","0.00000000"],["78301.56000000","0.02000000"],["78301.55000000","0.00000000"],["78301.54000000","0.00000000"],["78301.06000000","0.00014000"],["78301.05000000","0.14974000"],["78300.06000000","0.00026000"],["78300.03000000","0.00000000"],["78300.01000000","0.00063000"],["78300.00000000","1.50955000"],["78299.80000000","0.00014000"],["78298.55000000","0.00000000"],["78295.79000000","0.00000000"],["78293.80000000","0.23654000"],["78293.61000000","0.00400000"],["78292.08000000","0.37581000"],["78292.07000000","0.00000000"],["78289.94000000","0.00000000"],["78285.02000000","0.00000000"],["78281.91000000","0.31938000"],["78281.22000000","0.15190000"],["78274.02000000","0.00000000"],["78270.01000000","0.31938000"],["77130.75000000","0.00016000"],["70474.80000000","0.00032000"],["70474.00000000","0.00020000"],["62646.54000000","0.00186000"],["62644.00000000","0.00000000"]],"a":[["78305.34000000","8.86723000"],["78305.35000000","0.05041000"],["78305.40000000","0.05014000"],["78306.43000000","0.00000000"],["78306.78000000","0.06863000"],["78307.60000000","0.00400000"],["78307.90000000","0.00026000"],["78308.15000000","0.02400000"],["78308.16000000","0.00014000"],["78308.17000000","0.91773000"],["78308.18000000","2.37685000"],["78308.20000000","0.00000000"],["78308.25000000","0.00000000"],["78308.52000000","0.00000000"],["78308.53000000","0.11185000"],["78308.72000000","0.00000000"],["78309.44000000","0.00000000"],["78309.62000000","0.00000000"],["78310.27000000","0.00007000"],["78310.60000000","0.62245000"],["78310.69000000","0.00000000"],["78311.94000000","0.00000000"],["78312.61000000","0.12769000"],["78313.99000000","0.00000000"],["78316.52000000","0.31938000"],["78316.53000000","0.00000000"],["78320.40000000","0.12768000"],["78321.59000000","0.00000000"],["78332.16000000","0.00000000"],["78349.60000000","0.00400000"],["78350.40000000","0.00000000"],["78352.22000000","0.00000000"],["78367.17000000","0.01726000"],["78381.30000000","0.00000000"],["78513.55000000","0.00000000"],["78535.51000000","0.00000000"],["78538.83000000","0.00000000"],["78699.09000000","0.00000000"],["78824.48000000","0.00000000"]]}}
{"rx":1788854520765698612, "m":{"e":"depthUpdate","E":1788854520714,"s":"BTCUSDT","U":99829847937,"u":99829848199,"b":[["78305.33000000","0.19340000"],["78305.32000000","0.00063000"],["78303.68000000","0.00000000"],["78301.57000000","0.00014000"],["78301.56000000","0.02014000"],["78301.51000000","0.00000000"],["78301.50000000","0.00014000"],["78301.35000000","0.00000000"],["78301.34000000","0.00014000"],["78301.06000000","0.00000000"],["78301.05000000","0.00014000"],["78300.36000000","0.00000000"],["78300.34000000","0.00000000"],["78300.33000000","0.00014000"],["78300.06000000","0.00000000"],["78300.01000000","0.00077000"],["78300.00000000","1.50955000"],["78299.80000000","0.00000000"],["78299.76000000","0.00007000"],["78299.70000000","0.00000000"],["78299.47000000","0.00425000"],["78298.93000000","0.00000000"],["78298.47000000","0.00000000"],["78298.21000000","0.00757000"],["78298.16000000","0.00000000"],["78297.54000000","0.00000000"],["78297.51000000","0.00000000"],["78297.50000000","0.07252000"],["78297.49000000","0.20250000"],["78297.00000000","0.00000000"],["78296.96000000","0.00851000"],["78296.31000000","0.00000000"],["78295.77000000","0.00007000"],["78295.72000000","0.00000000"],["78295.71000000","0.00851000"],["78295.70000000","0.00000000"],["78294.60000000","0.01000000"],["78294.50000000","0.00000000"],["78294.30000000","0.00000000"],["78293.89000000","0.00000000"],["78293.83000000","0.00000000"],["78293.81000000","0.00007000"],["78293.80000000","0.20048000"],["78293.61000000","0.00000000"],["78292.81000000","0.00000000"],["78292.42000000","0.00000000"],["78292.41000000","0.00000000"],["78292.30000000","0.00000000"],["78292.23000000","0.00000000"],["78292.20000000","0.14008000"],["78292.08000000","0.00000000"],["78291.95000000","0.00000000"],["78291.78000000","0.00007000"],["78291.25000000","0.00000000"],["78291.19000000","0.00000000"],["78291.05000000","0.00000000"],["78290.42000000","0.00000000"],["78290.41000000","0.00000000"],["78290.02000000","0.02123000"],["78289.94000000","0.37581000"],["78289.93000000","0.13884000"],["78289.56000000","0.00000000"],["78289.44000000","0.00000000"],["78289.01000000","0.01277000"],["78288.74000000","0.00000000"],["78287.79000000","0.00007000"],["78286.01000000","0.03091000"],["78285.61000000","0.02000000"],["78285.01000000","0.00000000"],["78284.04000000","0.00026000"],["78284.03000000","0.00000000"],["78283.80000000","0.00014000"],["78282.19000000","0.02106000"],["78281.35000000","1.99367000"],["78281.23000000","2.29861000"],["78281.21000000","0.00000000"],["78281.11000000","0.00150000"],["78281.06000000","0.00000000"],["78279.26000000","0.37581000"],["78279.25000000","0.00000000"],["78277.40000000","1.99367000"],["78277.39000000","0.00000000"],["78277.38000000","0.00000000"],["78276.17000000","0.00000000"],["78274.43000000","0.00000000"],["78274.36000000","0.02080000"],["78273.31000000","2.29861000"],["78272.94000000","0.31938000"],["78270.80000000","0.00024000"],["78268.36000000","0.00000000"],["78267.00000000","0.00000000"],["78266.53000000","0.02090000"],["78266.13000000","0.64567000"],["78259.97000000","0.00000000"],["78259.86000000","0.00007000"],["78258.70000000","0.02097000"],["78258.01000000","0.23955000"],["78256.83000000","0.00000000"],["78256.07000000","0.00000000"],["78255.87000000","0.00007000"],["78237.24000000","0.34528000"],["78234.86000000","0.03836000"],["78231.68000000","0.00000000"],["78230.85000000","0.00000000"],["78227.49000000","0.02000000"],["78214.73000000","0.00000000"],["78214.72000000","0.00000000"],["78208.40000000","1.99367000"],["78202.19000000","0.00000000"],["78198.53000000","2.45280000"],["78198.21000000","1.99367000"],["78195.44000000","0.24759000"],["78165.52000000","0.00000000"],["78159.61000000","0.20250000"],["78151.42000000","0.00000000"],["78145.65000000","0.00000000"],["77130.75000000","0.00024000"],["70474.00000000","0.00000000"]],"a":[["78305.34000000","9.28636000"],["78306.60000000","0.01845000"],["78306.78000000","0.06863000"],["78307.15000000","0.15000000"],["78307.65000000","0.00000000"],["78307.85000000","0.02214000"],["78307.88000000","0.03057000"],["78308.16000000","0.00000000"],["78308.18000000","2.37618000"],["78309.10000000","0.02214000"],["78313.18000000","0.00066000"],["78315.26000000","0.00000000"],["78315.34000000","1.56263000"],["78315.35000000","2.00674000"],["78315.37000000","0.00000000"],["78316.02000000","0.00000000"],["78317.09000000","0.00007000"],["78319.93000000","0.00000000"],["78320.40000000","0.00000000"],["78321.01000000","0.00066000"],["78323.27000000","0.37581000"],["78323.36000000","0.00000000"],["78323.85000000","0.00000000"],["78328.84000000","0.00066000"],["78331.68000000","0.00014000"],["78332.95000000","1.86600000"],["78333.84000000","0.34478000"],["78335.20000000","1.26417000"],["78336.67000000","0.00066000"],["78339.51000000","0.00000000"],["78340.25000000","0.02470000"],["78344.39000000","0.00000000"],["78346.69000000","0.00000000"],["78349.96000000","0.00000000"],["78351.29000000","0.00000000"],["78356.01000000","0.00000000"],["78356.48000000","0.22479000"],["78357.00000000","0.00000000"],["78359.50000000","0.00000000"],["78364.16000000","0.00408000"],["78419.99000000","0.00000000"],["78422.08000000","0.00000000"],["78423.05000000","0.00000000"],["78423.06000000","0.37581000"],["78423.32000000","0.00000000"],["78424.19000000","0.04442000"],["78430.38000000","0.00000000"],["78434.70000000","0.00000000"],["78434.71000000","0.00000000"],["78453.16000000","0.00000000"],["78636.38000000","0.00000000"]]}}
{"rx":1788854520865252106, "m":{"e":"depthUpdate","E":1788854520814,"s":"BTCUSDT","U":99829848200,"u":99829848285,"b":[["78305.33000000","0.19340000"],["78305.32000000","0.00070000"],["78301.56000000","0.02014000"],["78301.50000000","0.00000000"],["78301.42000000","0.00014000"],["78301.41000000","0.61535000"],["78301.40000000","0.50014000"],["78301.34000000","0.00000000"],["78301.05000000","0.00000000"],["78300.85000000","0.00588000"],["78300.33000000","0.00000000"],["78300.17000000","0.00026000"],["78300.00000000","1.50955000"],["78298.21000000","0.00771000"],["78297.50000000","0.08845000"],["78295.05000000","0.00400000"],["78294.08000000","0.00400000"],["78293.81000000","0.00000000"],["78293.80000000","0.28727000"],["78292.37000000","0.10732000"],["78291.78000000","0.00014000"],["78287.80000000","0.00800000"],["78287.79000000","0.00014000"],["78255.87000000","0.00000000"],["78228.01000000","0.00180000"],["78195.44000000","0.00000000"],["78190.78000000","0.04344000"],["78146.01000000","0.00072000"],["77130.75000000","0.00032000"],["70474.80000000","0.00048000"],["62646.54000000","0.00155000"]],"a":[["78305.34000000","9.28802000"],["78305.40000000","0.05014000"],["78306.60000000","0.01859000"],["78306.62000000","0.00007000"],["78306.78000000","0.06863000"],["78307.15000000","0.15014000"],["78307.85000000","0.02228000"],["78307.88000000","0.03071000"],["78308.15000000","0.02414000"],["78308.17000000","0.91759000"],["78308.18000000","2.37604000"],["78309.76000000","0.00000000"],["78340.04000000","0.00622000"],["78341.45000000","0.00425000"],["78345.93000000","0.00424000"],["78351.84000000","0.00000000"]]}}
{"rx":1788854520953578028, "m":{"e":"depthUpdate","E":1788854520914,"s":"BTCUSDT","U":99829848286,"u":99829848325,"b":[["78305.33000000","0.19340000"],["78301.56000000","0.31559000"],["78298.21000000","0.00723000"],["78298.17000000","0.00000000"],["78297.18000000","0.00000000"],["78295.77000000","0.00014000"],["78294.08000000","0.00000000"],["78288.08000000","0.00048000"],["78287.94000000","0.00047000"],["78286.59000000","0.00192000"],["78283.34000000","0.00000000"],["78281.62000000","0.02000000"],["78280.16000000","0.00000000"],["78269.48000000","0.00189000"],["78267.76000000","0.51903000"],["78242.78000000","1.04521000"],["78242.07000000","0.00000000"],["78232.36000000","0.02000000"],["78210.76000000","0.00000000"],["77130.75000000","0.00070000"]],"a":[["78305.34000000","9.29202000"],["78307.88000000","0.00014000"],["78321.77000000","0.03400000"],["78326.03000000","0.00000000"],["78344.90000000","0.00433000"],["78352.61000000","0.88447000"],["78355.14000000","0.00000000"],["78360.99000000","0.03400000"],["78362.80000000","0.00000000"],["78364.16000000","0.00000000"],["78366.90000000","0.46019000"],["78395.49000000","0.00000000"],["78438.26000000","0.02892000"]]}}
{"rx":1788854521054781520, "m":{"e":"depthUpdate","E":1788854521014,"s":"BTCUSDT","U":99829848326,"u":99829848387,"b":[["78305.33000000","0.19355000"],["78305.32000000","0.00077000"],["78301.56000000","0.02014000"],["78299.26000000","0.12468000"],["78293.28000000","0.00400000"],["78286.40000000","0.02000000"],["78285.46000000","0.02000000"],["78282.81000000","0.31938000"],["78282.46000000","0.02000000"],["78281.91000000","0.00000000"],["78281.36000000","1.61852000"],["78280.22000000","0.00000000"],["78278.96000000","0.31938000"],["78277.51000000","0.00024000"],["78275.01000000","0.31938000"],["78272.94000000","0.00000000"],["78271.58000000","0.00000000"],["78271.15000000","0.31938000"],["78270.80000000","0.00000000"],["78270.01000000","0.00000000"],["78269.13000000","0.00000000"],["78258.01000000","0.34358000"],["78252.68000000","0.00335000"],["78251.85000000","0.00000000"],["78233.40000000","0.02008000"],["78227.01000000","0.02000000"],["78217.28000000","0.02000000"],["78213.54000000","1.15471000"],["78203.87000000","0.07544000"],["77130.75000000","0.00070000"],["70474.80000000","0.00064000"],["62646.54000000","0.00124000"],["62644.26000000","0.00000000"]],"a":[["78305.34000000","9.29297000"],["78307.85000000","0.02228000"],["78307.88000000","0.00000000"],["78308.17000000","0.91773000"],["78315.33000000","0.16897000"],["78316.52000000","0.00000000"],["78316.95000000","0.03400000"],["78317.01000000","0.04200000"],["78317.44000000","0.31938000"],["78317.80000000","0.03800000"],["78320.51000000","0.00000000"],["78320.84000000","0.02600000"],["78321.59000000","0.31938000"],["78324.32000000","0.00000000"],["78325.54000000","0.31938000"],["78328.59000000","0.00000000"],["78329.40000000","0.31938000"],["78332.05000000","0.00000000"],["78332.15000000","0.00000000"],["78355.69000000","0.00318000"],["78355.76000000","0.00000000"],["78356.17000000","0.03400000"],["78358.57000000","0.00000000"],["78360.06000000","0.02600000"],["78366.19000000","1.32348000"],["78366.90000000","1.03523000"],["78376.99000000","0.05515000"],["78433.93000000","0.00127000"],["78437.99000000","0.00007000"]]}}
{"rx":1788854521159990349, "m":{"e":"depthUpdate","E":1788854521114,"s":"BTCUSDT","U":99829848388,"u":99829848441,"b":[["78305.33000000","0.02105000"],["78305.32000000","0.00077000"],["78301.57000000","0.00000000"],["78301.56000000","0.00014000"],["78301.41000000","0.61549000"],["78300.33000000","0.00000000"],["78300.32000000","0.00000000"],["78300.00000000","1.50941000"],["78299.26000000","0.00000000"],["78298.55000000","0.02000000"],["78293.81000000","0.00007000"],["78272.62000000","0.00000000"],["78240.79000000","0.00625000"],["78236.10000000","0.00408000"],["78227.49000000","0.00000000"],["78213.58000000","1.00208000"],["78136.02000000","0.00000000"],["78085.16000000","0.02000000"],["77603.40000000","0.00000000"],["77130.75000000","0.00062000"],["72089.37000000","0.00014000"]],"a":[["78307.90000000","0.00000000"],["78308.15000000","0.00814000"],["78308.16000000","0.00400000"],["78308.18000000","2.37594000"],["78312.60000000","0.01200000"],["78319.50000000","0.00000000"],["78325.65000000","0.00000000"],["78328.00000000","0.03000000"],["78330.51000000","0.27422000"],["78331.10000000","0.00000000"],["78402.43000000","0.00025000"],["78405.27000000","0.00000000"],["78439.36000000","0.01529000"],["78453.73000000","0.01529000"],["78508.87000000","0.00000000"],["78515.49000000","0.00000000"],["78529.87000000","0.00000000"]]}}
{"rx":1788854521257906861, "m":{"e":"depthUpdate","E":1788854521214,"s":"BTCUSDT","U":99829848442,"u":99829848466,"b":[["78305.33000000","0.02119000"],["78301.56000000","0.00000000"],["78295.05000000","0.00000000"],["78294.14000000","0.00400000"],["78285.63000000","0.02000000"],["78283.25000000","0.02000000"],["78233.58000000","0.02000000"],["78232.65000000","0.02000000"],["77130.75000000","0.00062000"],["70474.80000000","0.00080000"],["62646.54000000","0.00093000"]],"a":[["78305.34000000","9.29797000"],["78308.16000000","0.01600000"],["78308.18000000","2.37094000"],["78312.60000000","0.00000000"],["78317.74000000","0.02800000"],["78320.07000000","0.03000000"],["78326.57000000","0.52662000"],["78327.21000000","0.00000000"]]}}
{"rx":1788854521375529140, "m":{"e":"depthUpdate","E":1788854521314,"s":"BTCUSDT","U":99829848467,"u":99829848517,"b":[["78305.33000000","0.19283000"],["78305.32000000","0.00070000"],["78301.41000000","0.92109000"],["78300.00000000","1.50955000"],["78298.55000000","0.02014000"],["78298.00000000","0.03014000"],["78272.80000000","0.00000000"],["78271.87000000","0.00000000"],["78267.00000000","0.70000000"],["78262.55000000","0.88549000"],["78225.53000000","1.26594000"],["78207.63000000","0.00000000"],["77130.75000000","0.00062000"],["70477.34000000","0.00000000"],["70474.80000000","0.00096000"],["62644.00000000","0.00000000"]],"a":[["78305.34000000","9.29645000"],["78308.15000000","0.00814000"],["78308.16000000","0.01614000"],["78308.17000000","0.91759000"],["78316.77000000","0.39592000"],["78327.99000000","0.00000000"],["78330.33000000","0.00000000"],["78506.60000000","0.00000000"],["79479.93000000","0.00030000"]]}}
{"rx":1788854521474492998, "m":{"e":"depthUpdate","E":1788854521414,"s":"BTCUSDT","U":99829848518,"u":99829848546,"b":[["78305.33000000","0.19290000"],["78305.32000000","0.00077000"],["78301.41000000","0.61549000"],["78300.05000000","0.00014000"],["78300.04000000","0.15288000"],["78293.81000000","0.00000000"],["78285.51000000","0.02000000"],["78281.67000000","0.02000000"],["78281.62000000","0.04000000"],["78256.58000000","0.00000000"],["78232.42000000","0.02007000"],["78222.24000000","0.02000000"],["78217.87000000","0.02000000"],["78215.61000000","0.00000000"],["78149.41000000","0.01533000"],["78128.89000000","0.00000000"],["77130.75000000","0.00062000"],["62646.54000000","0.00062000"]],"a":[["78307.41000000","0.00007000"],["78317.82000000","0.03400000"],["78321.64000000","0.03800000"],["78321.78000000","0.03200000"],["78408.59000000","0.00000000"]]}}
{"rx":1788854521558478022, "m":{"e":"depthUpdate","E":1788854521514,"s":"BTCUSDT","U":99829848547,"u":99829848596,"b":[["78305.33000000","0.01668000"],["78300.85000000","0.00588000"],["78292.37000000","0.00000000"],["78282.02000000","0.02000000"],["78271.64000000","0.00000000"],["78227.01000000","0.00000000"],["78223.86000000","0.02000000"],["78217.87000000","0.00000000"],["78217.28000000","0.00000000"],["78205.58000000","0.00007000"],["78168.52000000","0.00000000"],["78141.28000000","0.00206000"],["77130.75000000","0.00062000"],["70474.80000000","0.00112000"],["62644.27000000","0.00248000"]],"a":[["78305.34000000","9.19285000"],["78305.93000000","0.04029000"],["78311.21000000","0.00013000"],["78313.72000000","0.00000000"],["78321.40000000","0.02800000"],["78326.49000000","0.00000000"],["78328.06000000","0.00000000"],["78331.63000000","0.00000000"],["78331.88000000","0.00000000"],["78332.04000000","0.00000000"],["78396.61000000","0.00000000"],["78403.84000000","0.02052000"],["78403.85000000","0.00000000"],["78407.77000000","0.00000000"],["78448.90000000","0.00206000"]]}}
{"rx":1788854521656128014, "m":{"e":"depthUpdate","E":1788854521614,"s":"BTCUSDT","U":99829848597,"u":99829848654,"b":[["78305.33000000","0.01676000"],["78290.02000000","0.00000000"],["78289.96000000","0.02121000"],["78282.47000000","0.02000000"],["78281.67000000","0.04000000"],["78231.57000000","0.02000000"],["78222.37000000","0.02000000"],["78004.55000000","0.00007000"],["77130.75000000","0.00062000"],["72089.37000000","0.00000000"],["70474.80000000","0.00121000"],["62646.54000000","0.00031000"]],"a":[["78305.34000000","9.22905000"],["78305.40000000","0.05014000"],["78305.93000000","0.04043000"],["78308.15000000","0.01214000"],["78308.16000000","0.00000000"],["78309.26000000","0.01311000"],["78312.60000000","0.00400000"],["78313.18000000","0.02246000"],["78317.10000000","0.01324000"],["78320.84000000","0.06600000"],["78321.01000000","0.00142000"],["78321.02000000","0.03444000"],["78321.64000000","0.07000000"],["78328.84000000","0.00142000"],["78328.86000000","0.02153000"],["78336.67000000","0.00142000"],["78336.70000000","0.02161000"],["78424.19000000","0.07334000"],["78576.79000000","0.00044000"]]}}
{"rx":1788854521771489639, "m":{"e":"depthUpdate","E":1788854521714,"s":"BTCUSDT","U":99829848655,"u":99829848673,"b":[["78305.33000000","0.18918000"],["78270.79000000","0.00000000"],["78222.37000000","0.00000000"],["77130.75000000","0.00062000"],["70474.80000000","0.00137000"]],"a":[["78308.15000000","0.01214000"],["78308.16000000","0.00800000"],["78317.09000000","0.00000000"],["78317.70000000","0.04200000"],["78319.93000000","0.12768000"],["78331.08000000","0.00188000"],["78331.87000000","0.00000000"],["78458.29000000","0.00000000"]]}}
{"rx":1788854521851022938, "m":{"e":"depthUpdate","E":1788854521814,"s":"BTCUSDT","U":99829848674,"u":99829848694,"b":[["78305.33000000","0.01516000"],["78301.41000000","0.91618000"],["78285.71000000","0.09688000"],["78283.75000000","0.10276000"],["78222.24000000","0.00000000"],["77130.75000000","0.00070000"],["70474.00000000","0.00000000"],["62646.54000000","0.00000000"]],"a":[["78308.15000000","0.01214000"],["78317.09000000","0.00007000"]]}}
{"rx":1788854521965893101, "m":{"e":"depthUpdate","E":1788854521914,"s":"BTCUSDT","U":99829848695,"u":99829848723,"b":[["78305.33000000","0.01516000"],["78301.41000000","0.61549000"],["78300.05000000","0.00000000"],["78300.04000000","0.00000000"],["78293.81000000","0.00007000"],["78293.80000000","0.20048000"],["78289.94000000","0.00000000"],["78228.01000000","0.00000000"],["78146.01000000","0.00000000"],["77130.75000000","0.00070000"],["70474.80000000","0.00153000"]],"a":[["78305.34000000","9.19473000"],["78309.26000000","0.00000000"],["78313.18000000","0.00142000"],["78317.10000000","0.00000000"],["78321.02000000","0.00000000"],["78327.92000000","0.00000000"],["78328.86000000","0.00000000"],["78336.70000000","0.00000000"],["78497.51000000","0.00000000"]]}}
{"rx":1788854522045303067, "m":{"e":"depthUpdate","E":1788854522014,"s":"BTCUSDT","U":99829848724,"u":99829848762,"b":[["78305.33000000","0.18764000"],["78305.32000000","0.00083000"],["78305.31000000","0.00013000"],["78300.85000000","0.00588000"],["78293.57000000","0.08228000"],["78282.82000000","0.15190000"],["78281.22000000","0.00000000"],["78274.01000000","1.04901000"],["78242.79000000","1.28108000"],["78242.47000000","0.00000000"],["78228.01000000","0.00180000"],["78223.86000000","0.00000000"],["78208.41000000","0.59513000"],["78149.42000000","0.00072000"],["77130.75000000","0.00070000"],["70474.80000000","0.00169000"],["62644.27000000","0.00341000"],["62644.26000000","0.00000000"]],"a":[["78305.34000000","9.27701000"],["78421.32000000","0.80926000"]]}}
{"rx":1788854522138909670, "m":{"e":"depthUpdate","E":1788854522114,"s":"BTCUSDT","U":99829848763,"u":99829848772,"b":[["78305.33000000","0.01522000"],["78301.41000000","0.90800000"],["78299.08000000","0.00014000"],["78299.07000000","0.14978000"],["78293.81000000","0.00000000"],["77600.58000000","0.00010000"],["77130.75000000","0.00062000"],["62644.00000000","0.00200000"]],"a":[]}}
{"rx":1788854522236875925, "m":{"e":"depthUpdate","E":1788854522214,"s":"BTCUSDT","U":99829848773,"u":99829848800,"b":[["78305.33000000","0.18760000"],["78305.32000000","0.00090000"],["78301.41000000","0.61549000"],["78300.00000000","1.65987000"],["78299.08000000","0.00000000"],["78299.07000000","0.00000000"],["78293.81000000","0.00007000"],["77130.75000000","0.00062000"],["70474.80000000","0.00176000"],["70474.79000000","0.00009000"],["62644.27000000","0.00310000"],["62644.00000000","0.00000000"]],"a":[["78305.34000000","9.27387000"],["78340.87000000","0.00400000"],["78349.60000000","0.00000000"]]}}
{"rx":1788854522340556476, "m":{"e":"depthUpdate","E":1788854522314,"s":"BTCUSDT","U":99829848801,"u":99829848861,"b":[["78305.33000000","0.18708000"],["78305.32000000","0.00083000"],["78300.00000000","1.65987000"],["78297.50000000","0.08859000"],["78204.79000000","0.00408000"],["77130.75000000","0.00062000"]],"a":[["78305.34000000","9.23920000"],["78308.17000000","0.82272000"],["78326.50000000","0.89871000"],["78508.01000000","0.00000000"],["79479.93000000","0.00030000"]]}}
{"rx":1788854522442917189, "m":{"e":"depthUpdate","E":1788854522414,"s":"BTCUSDT","U":99829848862,"u":99829848890,"b":[["78305.33000000","0.18708000"],["78301.41000000","0.61549000"],["78291.83000000","0.00638000"],["78244.01000000","0.00000000"],["78240.80000000","0.00318000"],["78231.01000000","0.00000000"],["78230.22000000","0.00319000"],["78165.53000000","0.00000000"],["78162.23000000","0.00127000"],["78151.42000000","0.00127000"],["78150.87000000","0.00000000"],["77130.75000000","0.00062000"],["70474.80000000","0.00192000"],["62644.27000000","0.00279000"],["62644.00000000","0.00000000"]],"a":[["78305.34000000","9.23282000"],["78305.92000000","0.00638000"],["78306.52000000","0.00638000"],["78359.16000000","0.00318000"],["78361.94000000","0.00000000"],["78373.19000000","0.00318000"],["78375.88000000","0.00000000"],["78437.99000000","0.00134000"],["78451.50000000","0.00127000"],["78455.98000000","0.00000000"],["78464.81000000","0.00000000"],["78508.81000000","0.00000000"],["80000.00000000","15.10018000"],["89600.00000000","0.22034000"]]}}
{"rx":1788854522537548505, "m":{"e":"depthUpdate","E":1788854522514,"s":"BTCUSDT","U":99829848891,"u":99829848935,"b":[["78305.33000000","0.18676000"],["78255.50000000","1.26545000"],["78225.53000000","0.00000000"],["78215.67000000","0.00007000"],["78120.49000000","0.00000000"],["77130.75000000","0.00062000"],["70474.80000000","0.00208000"],["70474.79000000","0.00000000"]],"a":[["78305.40000000","0.05014000"],["78305.92000000","0.00652000"],["78305.93000000","0.04043000"],["78306.52000000","0.00652000"],["78307.85000000","0.02214000"],["78308.15000000","0.01200000"],["78310.00000000","0.07500000"],["78393.29000000","0.01513000"],["78396.61000000","0.02800000"],["78419.09000000","0.00000000"],["78489.04000000","0.00000000"]]}}
{"rx":1788854522638918559, "m":{"e":"depthUpdate","E":1788854522614,"s":"BTCUSDT","U":99829848936,"u":99829848983,"b":[["78305.33000000","0.01398000"],["78301.42000000","0.00014000"],["78293.81000000","0.00007000"],["78291.83000000","0.00000000"],["78290.22000000","0.00638000"],["78278.96000000","0.00000000"],["78278.01000000","0.31938000"],["78271.15000000","0.00000000"],["78270.01000000","0.31938000"],["78151.11000000","0.00667000"],["77996.83000000","0.00007000"],["77130.75000000","0.00062000"],["62644.27000000","0.00248000"]],"a":[["78305.34000000","9.24558000"],["78305.92000000","0.00014000"],["78306.52000000","0.00014000"],["78308.00000000","0.01000000"],["78308.75000000","0.03057000"],["78309.26000000","0.00000000"],["78310.00000000","0.08000000"],["78313.18000000","0.00142000"],["78317.10000000","0.00000000"],["78321.02000000","0.00000000"],["78328.86000000","0.00000000"],["78336.70000000","0.00000000"],["78355.69000000","0.00318000"],["78433.93000000","0.00127000"],["78438.26000000","0.00000000"]]}}
{"rx":1788854522738446005, "m":{"e":"depthUpdate","E":1788854522714,"s":"BTCUSDT","U":99829848984,"u":99829849010,"b":[["78301.41000000","0.90390000"],["78300.00000000","1.50955000"],["78275.24000000","0.00408000"],["77130.75000000","0.00062000"],["70474.80000000","0.00224000"]],"a":[["78305.40000000","0.05014000"],["78305.92000000","0.00000000"],["78305.93000000","0.04043000"],["78306.52000000","0.00000000"],["78307.85000000","0.02228000"],["78308.00000000","0.02014000"],["78310.00000000","0.07000000"],["78395.03000000","2.68103000"],["78421.33000000","0.00000000"]]}}
{"rx":1788854522838882997, "m":{"e":"depthUpdate","E":1788854522814,"s":"BTCUSDT","U":99829849011,"u":99829849066,"b":[["78305.33000000","0.19013000"],["78301.43000000","0.00014000"],["78301.42000000","0.48361000"],["78301.41000000","0.61549000"],["78293.81000000","0.00000000"],["78285.32000000","1.84602000"],["78279.64000000","0.38335000"],["78260.23000000","0.00000000"],["78141.28000000","0.00000000"],["78114.33000000","4.50551000"],["77130.75000000","0.00070000"],["62644.27000000","0.00217000"]],"a":[["78305.34000000","8.79473000"],["78305.92000000","0.00032000"],["78306.52000000","0.00638000"],["78308.15000000","0.00000000"],["78308.16000000","0.00400000"],["78308.75000000","0.00000000"],["78312.60000000","0.02000000"],["78317.09000000","0.00007000"],["78317.44000000","0.00000000"],["78319.17000000","0.31938000"],["78319.93000000","0.00000000"],["78328.26000000","0.00000000"],["78392.85000000","0.84653000"],["78421.32000000","0.00000000"],["78438.26000000","0.02892000"],["78448.90000000","0.00000000"],["78479.86000000","4.49918000"]]}}
{"rx":1788854522939103053, "m":{"e":"depthUpdate","E":1788854522914,"s":"BTCUSDT","U":99829849067,"u":99829849109,"b":[["78305.33000000","0.19852000"],["78305.32000000","0.00090000"],["78297.50000000","0.08845000"],["78162.22000000","0.00000000"],["78162.21000000","0.00000000"],["77130.75000000","0.00070000"],["70474.80000000","0.00240000"],["62644.00000000","0.00200000"]],"a":[["78305.93000000","0.04043000"],["78306.52000000","0.00652000"],["78308.00000000","0.02000000"],["78308.16000000","0.00400000"],["78312.59000000","0.00400000"],["78312.60000000","0.00800000"],["78416.47000000","0.20257000"]]}}
{"rx":1788854523046383731, "m":{"e":"depthUpdate","E":1788854523014,"s":"BTCUSDT","U":99829849110,"u":99829849142,"b":[["78305.33000000","0.19610000"],["78292.52000000","0.00638000"],["78290.22000000","0.00000000"],["78183.14000000","0.13543000"],["78180.97000000","0.20000000"],["77130.75000000","0.00070000"],["70474.00000000","0.00000000"],["62644.27000000","0.00310000"],["62644.26000000","0.00000000"],["62644.00000000","0.00000000"]],"a":[["78305.34000000","8.78835000"],["78305.39000000","0.00033000"],["78305.92000000","0.00000000"],["78306.51000000","0.00638000"],["78306.52000000","0.00014000"],["78306.77000000","0.00638000"],["78308.16000000","0.00800000"],["78312.59000000","0.00000000"],["78312.60000000","0.00800000"],["78397.61000000","0.20000000"],["78510.80000000","0.00000000"]]}}
{"rx":1788854523149984882, "m":{"e":"depthUpdate","E":1788854523114,"s":"BTCUSDT","U":99829849143,"u":99829849199,"b":[["78305.33000000","0.33955000"],["78305.32000000","0.00090000"],["78301.64000000","0.00014000"],["78301.63000000","0.15741000"],["78301.43000000","0.00000000"],["78301.42000000","0.00014000"],["78293.81000000","0.00000000"],["78286.01000000","0.81950000"],["78258.01000000","0.70604000"],["78234.86000000","0.06928000"],["78198.82000000","1.38777000"],["77130.75000000","0.00062000"],["70474.80000000","0.00256000"],["62644.26000000","0.00000000"],["62644.00000000","0.00000000"]],"a":[["78305.34000000","8.78868000"],["78305.39000000","0.00000000"],["78305.93000000","0.04043000"],["78306.51000000","0.00652000"],["78306.52000000","0.00000000"],["78306.60000000","0.01859000"],["78306.77000000","0.00014000"],["78307.14000000","0.00638000"],["78307.85000000","0.02214000"],["78308.16000000","0.01600000"],["78317.69000000","0.31938000"],["78319.17000000","0.00000000"],["78348.26000000","0.37068000"],["78359.22000000","0.00408000"],["78390.89000000","2.46990000"],["78419.99000000","0.01801000"],["78510.26000000","0.00000000"],["78555.50000000","3.67633000"]]}}
{"rx":1788854523254200827, "m":{"e":"depthUpdate","E":1788854523214,"s":"BTCUSDT","U":99829849200,"u":99829849231,"b":[["78305.33000000","0.19603000"],["78305.32000000","0.00083000"],["78301.64000000","0.00000000"],["78301.63000000","0.00000000"],["78293.81000000","0.00007000"],["77130.75000000","0.00062000"],["70474.80000000","0.00272000"],["62644.27000000","0.00279000"]],"a":[["78306.60000000","0.01859000"],["78306.77000000","0.00000000"],["78306.78000000","0.06863000"],["78307.14000000","0.00652000"],["78308.00000000","0.04000000"],["78310.00000000","0.05000000"],["78510.44000000","0.00000000"],["78511.55000000","0.00000000"]]}}
{"rx":1788854523363039669, "m":{"e":"depthUpdate","E":1788854523314,"s":"BTCUSDT","U":99829849232,"u":99829849243,"b":[["78290.98000000","0.01342000"],["78180.04000000","0.00068000"],["77130.75000000","0.00062000"],["62644.00000000","0.00000000"]],"a":[["78510.72000000","0.00000000"],["78510.88000000","0.00000000"],["79479.93000000","0.00030000"]]}}
{"rx":1788854523465495952, "m":{"e":"depthUpdate","E":1788854523414,"s":"BTCUSDT","U":99829849244,"u":99829849258,"b":[["78305.33000000","0.35122000"],["78142.69000000","0.00206000"],["77130.75000000","0.00062000"],["70474.80000000","0.00288000"],["62644.27000000","0.00248000"]],"a":[["78308.00000000","0.06000000"],["78310.00000000","0.03000000"],["78450.11000000","0.00206000"],["78510.35000000","0.00000000"]]}}
{"rx":1788854523582819660, "m":{"e":"depthUpdate","E":1788854523514,"s":"BTCUSDT","U":99829849259,"u":99829849272,"b":[["78305.33000000","0.19603000"],["78221.77000000","0.00007000"],["78140.94000000","0.00085000"],["77130.75000000","0.00062000"]],"a":[["78510.67000000","0.00000000"],["78510.79000000","0.00000000"],["78510.93000000","0.00000000"],["78511.47000000","0.00000000"]]}}
{"rx":1788854523677996689, "m":{"e":"depthUpdate","E":1788854523614,"s":"BTCUSDT","U":99829849273,"u":99829849300,"b":[["78305.33000000","0.19603000"],["78301.24000000","0.00014000"],["78301.23000000","0.16329000"],["78293.81000000","0.00000000"],["77989.11000000","0.00007000"],["77130.75000000","0.00062000"],["70474.80000000","0.00304000"],["62644.27000000","0.00217000"],["62644.00000000","0.00000000"]],"a":[["78306.58000000","0.01309000"],["78310.50000000","0.01280000"],["78314.42000000","0.01335000"],["78318.34000000","0.01340000"],["78322.26000000","0.01328000"],["78510.80000000","0.00000000"]]}}
{"rx":1788854523749442738, "m":{"e":"depthUpdate","E":1788854523714,"s":"BTCUSDT","U":99829849301,"u":99829849336,"b":[["78305.33000000","0.19246000"],["78305.32000000","0.00090000"],["78301.40000000","0.50014000"],["78301.23000000","0.16343000"],["78290.98000000","0.00000000"],["77130.75000000","0.00062000"],["70474.80000000","0.00329000"]],"a":[["78305.34000000","8.80958000"],["78306.51000000","0.00652000"],["78306.58000000","0.01323000"],["78307.15000000","0.15000000"],["78313.18000000","0.02310000"],["78321.02000000","0.02107000"],["78328.86000000","0.02080000"],["78336.70000000","0.02109000"],["78390.54000000","0.00408000"],["78430.62000000","0.00111000"],["78511.18000000","0.00000000"]]}}
{"rx":1788854523837722472, "m":{"e":"depthUpdate","E":1788854523814,"s":"BTCUSDT","U":99829849337,"u":99829849343,"b":[["78126.64000000","0.12779000"],["77130.75000000","0.00070000"],["62644.27000000","0.00186000"]],"a":[["78317.09000000","0.00007000"],["78509.24000000","0.00000000"]]}}
{"rx":1788854523943467979, "m":{"e":"depthUpdate","E":1788854523914,"s":"BTCUSDT","U":99829849344,"u":99829849360,"b":[["78126.64000000","0.00000000"],["77130.75000000","0.00070000"],["70474.80000000","0.00345000"],["62644.00000000","0.00000000"]],"a":[["78469.83000000","0.00111000"],["78508.26000000","0.00000000"],["78508.96000000","0.00000000"]]}}
{"rx":1788854524038578373, "m":{"e":"depthUpdate","E":1788854524014,"s":"BTCUSDT","U":99829849361,"u":99829849392,"b":[["78305.33000000","0.19589000"],["78305.32000000","0.00083000"],["78301.24000000","0.00000000"],["78301.23000000","0.00014000"],["78293.81000000","0.00007000"],["78292.52000000","0.00000000"],["78292.04000000","0.00638000"],["78228.01000000","0.00180000"],["78149.42000000","0.00072000"],["78126.45000000","0.00000000"],["77130.75000000","0.00070000"],["62644.27000000","0.00279000"],["62644.26000000","0.00000000"]],"a":[["78305.92000000","0.00638000"],["78306.51000000","0.00014000"],["78320.01000000","0.12768000"],["78442.76000000","0.00000000"],["78508.61000000","0.00000000"],["78508.62000000","0.00000000"]]}}
{"rx":1788854524136964817, "m":{"e":"depthUpdate","E":1788854524114,"s":"BTCUSDT","U":99829849393,"u":99829849433,"b":[["78301.40000000","0.50014000"],["78301.23000000","0.00000000"],["78297.50000000","0.08859000"],["78277.51000000","0.00000000"],["78277.41000000","0.70954000"],["78274.02000000","0.00024000"],["78218.60000000","0.59332000"],["78126.42000000","0.00000000"],["78126.24000000","0.12786000"],["77292.28000000","0.00000000"],["77130.75000000","0.00062000"],["70474.80000000","0.00352000"],["70474.79000000","0.00009000"],["70474.00000000","0.00020000"],["62644.26000000","0.00000000"]],"a":[["78305.34000000","8.50927000"],["78305.40000000","0.05014000"],["78305.92000000","0.00652000"],["78305.93000000","0.04043000"],["78306.51000000","0.00000000"],["78387.99000000","0.83296000"],["78423.05000000","0.16362000"],["78508.53000000","0.00000000"],["78508.88000000","0.12779000"],["79328.01000000","0.00214000"],["82921.18000000","0.00000000"]]}}
{"rx":1788854524256831026, "m":{"e":"depthUpdate","E":1788854524214,"s":"BTCUSDT","U":99829849434,"u":99829849489,"b":[["78305.33000000","0.36875000"],["78305.32000000","0.00090000"],["78301.74000000","0.14446000"],["78301.73000000","0.48347000"],["78301.43000000","0.00014000"],["78301.42000000","0.00014000"],["78301.41000000","0.54311000"],["78300.97000000","0.00014000"],["78300.96000000","0.14371000"],["78300.01000000","0.00063000"],["78297.50000000","0.08845000"],["78293.81000000","0.00000000"],["78291.21000000","0.01299000"],["78289.93000000","0.22019000"],["78286.02000000","0.15189000"],["78282.82000000","0.00000000"],["78280.22000000","0.31938000"],["78278.01000000","0.00000000"],["78216.21000000","1.00211000"],["78213.58000000","0.00000000"],["78126.24000000","0.00007000"],["77130.75000000","0.00062000"],["70474.00000000","0.00000000"],["62644.27000000","0.00248000"]],"a":[["78305.34000000","8.50494000"],["78305.91000000","0.00131000"],["78305.92000000","0.00014000"],["78306.43000000","0.00400000"],["78306.77000000","0.00638000"],["78307.14000000","0.00014000"],["78308.15000000","0.00638000"],["78308.16000000","0.00400000"],["78312.60000000","0.02000000"],["78317.69000000","0.00000000"],["78318.33000000","0.00000000"],["78319.17000000","0.31938000"],["78320.01000000","0.00000000"],["78321.59000000","0.00000000"],["78322.26000000","0.31328000"],["78322.90000000","0.31938000"],["78346.80000000","0.00400000"],["78347.52000000","0.00000000"],["78508.88000000","0.00000000"]]}}
{"rx":1788854524369464951, "m":{"e":"depthUpdate","E":1788854524314,"s":"BTCUSDT","U":99829849490,"u":99829849581,"b":[["78305.33000000","0.36874000"],["78305.32000000","0.00097000"],["78303.47000000","0.00014000"],["78303.46000000","0.04706000"],["78303.45000000","0.00000000"],["78301.75000000","0.00000000"],["78301.74000000","0.00014000"],["78301.73000000","0.00014000"],["78301.43000000","0.00000000"],["78301.40000000","0.50014000"],["78300.97000000","0.00000000"],["78300.96000000","0.00014000"],["78300.01000000","0.00070000"],["78298.21000000","0.00709000"],["78298.00000000","0.03000000"],["78297.50000000","0.08831000"],["78275.24000000","0.00000000"],["78236.10000000","0.00000000"],["78190.78000000","0.24376000"],["77130.75000000","0.00062000"],["70474.80000000","0.00368000"]],"a":[["78305.40000000","0.05014000"],["78305.92000000","0.00000000"],["78306.58000000","0.00014000"],["78306.60000000","0.01859000"],["78306.77000000","0.00652000"],["78306.78000000","0.06863000"],["78307.14000000","0.00000000"],["78307.15000000","0.15014000"],["78320.05000000","0.00408000"],["78322.90000000","0.61938000"],["78322.91000000","1.47547000"],["78322.92000000","0.00000000"],["78390.54000000","0.00000000"],["79479.93000000","0.00030000"]]}}
{"rx":1788854524464075538, "m":{"e":"depthUpdate","E":1788854524414,"s":"BTCUSDT","U":99829849582,"u":99829849831,"b":[["78305.33000000","3.23695000"],["78305.32000000","0.00048000"],["78303.75000000","0.00052000"],["78303.47000000","0.00000000"],["78303.46000000","0.00014000"],["78301.74000000","0.14229000"],["78301.73000000","0.00000000"],["78301.67000000","0.31937000"],["78301.42000000","0.00014000"],["78301.41000000","0.54311000"],["78301.40000000","0.50014000"],["78301.32000000","0.00000000"],["78300.96000000","0.00000000"],["78300.01000000","0.00077000"],["78299.76000000","0.00014000"],["78298.55000000","0.00014000"],["78298.33000000","0.03057000"],["78298.21000000","0.00723000"],["78298.00000000","0.03014000"],["78297.51000000","0.00000000"],["78297.50000000","0.08831000"],["78295.12000000","0.37581000"],["78294.28000000","0.02138000"],["78293.95000000","0.01287000"],["78293.57000000","0.00000000"],["78292.29000000","0.00000000"],["78292.04000000","0.00000000"],["78289.53000000","1.84602000"],["78287.21000000","0.38511000"],["78287.14000000","0.37581000"],["78285.88000000","0.31938000"],["78282.81000000","0.00000000"],["78282.48000000","0.00024000"],["78274.02000000","0.00000000"],["78263.85000000","0.00000000"],["78263.76000000","0.34508000"],["78259.86000000","0.00000000"],["78237.24000000","0.00008000"],["78230.70000000","0.00000000"],["78190.98000000","0.08040000"],["78190.78000000","0.00000000"],["78159.61000000","0.00000000"],["78142.69000000","0.00000000"],["77130.75000000","0.00062000"],["70474.80000000","0.00384000"],["62644.27000000","0.00217000"]],"a":[["78305.34000000","2.01029000"],["78305.35000000","0.00083000"],["78305.39000000","0.00014000"],["78305.40000000","0.00014000"],["78305.91000000","0.00000000"],["78305.93000000","0.04043000"],["78306.42000000","0.00000000"],["78306.43000000","0.00000000"],["78306.53000000","0.00000000"],["78306.58000000","0.00000000"],["78306.77000000","0.00014000"],["78306.80000000","0.00000000"],["78307.15000000","0.00014000"],["78307.65000000","0.00000000"],["78307.74000000","0.00007000"],["78307.85000000","0.02228000"],["78307.99000000","0.00000000"],["78308.15000000","0.00000000"],["78308.16000000","0.00000000"],["78308.17000000","0.74772000"],["78308.18000000","0.07233000"],["78308.49000000","0.00400000"],["78308.52000000","0.00000000"],["78309.07000000","0.00400000"],["78309.45000000","0.00000000"],["78309.85000000","0.01000000"],["78309.99000000","0.00179000"],["78310.50000000","0.00000000"],["78310.59000000","0.00000000"],["78310.61000000","0.00000000"],["78311.27000000","0.01334000"],["78311.73000000","0.00014000"],["78312.43000000","0.00000000"],["78312.60000000","0.00400000"],["78313.16000000","0.00132000"],["78313.26000000","0.14000000"],["78314.41000000","0.01200000"],["78314.99000000","0.00638000"],["78315.28000000","0.00000000"],["78315.32000000","2.30269000"],["78315.33000000","0.00000000"],["78315.36000000","0.00000000"],["78315.83000000","0.00000000"],["78316.77000000","0.00000000"],["78319.17000000","0.00000000"],["78319.18000000","0.00000000"],["78320.51000000","0.00000000"],["78320.79000000","0.17535000"],["78321.68000000","0.02000000"],["78322.89000000","0.00400000"],["78322.90000000","0.30000000"],["78323.55000000","0.00000000"],["78323.69000000","0.31938000"],["78325.54000000","0.00000000"],["78325.64000000","0.00000000"],["78326.00000000","0.03000000"],["78326.57000000","0.00000000"],["78327.62000000","0.31938000"],["78328.59000000","0.00000000"],["78329.39000000","0.00049000"],["78329.40000000","0.00000000"],["78331.65000000","0.31938000"],["78332.74000000","0.31938000"],["78332.88000000","0.00000000"],["78335.20000000","0.00000000"],["78337.80000000","0.00000000"],["78344.00000000","0.03000000"],["78353.25000000","0.34469000"],["78355.69000000","0.00000000"],["78369.13000000","1.26362000"],["78385.30000000","2.29869000"],["78395.03000000","0.00000000"],["78424.19000000","0.10344000"],["78433.93000000","0.00000000"],["78450.03000000","0.03057000"],["78450.11000000","0.00000000"],["78609.84000000","7.63488000"],["80034.13000000","0.00000000"]]}}
{"rx":1788854524567270707, "m":{"e":"depthUpdate","E":1788854524514,"s":"BTCUSDT","U":99829849832,"u":99829850110,"b":[["78305.33000000","3.00680000"],["78305.32000000","0.00027000"],["78303.70000000","0.00000000"],["78303.47000000","0.00014000"],["78303.46000000","0.04000000"],["78302.65000000","0.00400000"],["78301.75000000","0.00652000"],["78301.74000000","0.07252000"],["78301.68000000","0.00014000"],["78301.67000000","0.31951000"],["78301.63000000","0.02000000"],["78301.14000000","0.00400000"],["78301.00000000","0.02000000"],["78300.36000000","0.00008000"],["78300.01000000","0.00063000"],["78300.00000000","1.50955000"],["78298.55000000","0.00000000"],["78298.50000000","0.00000000"],["78298.42000000","0.00000000"],["78298.00000000","0.03000000"],["78297.50000000","0.20007000"],["78295.95000000","0.00000000"],["78295.72000000","0.00000000"],["78295.47000000","0.00070000"],["78295.13000000","0.37581000"],["78295.12000000","0.00000000"],["78294.14000000","0.00000000"],["78293.80000000","0.07840000"],["78293.28000000","0.00000000"],["78292.20000000","0.12008000"],["78289.93000000","1.57594000"],["78289.54000000","2.29869000"],["78288.85000000","0.00150000"],["78287.80000000","0.00000000"],["78281.11000000","0.00000000"],["78275.17000000","0.00000000"],["78272.52000000","0.00007000"],["78262.55000000","0.00000000"],["78237.94000000","1.26574000"],["78235.74000000","0.00408000"],["78227.24000000","0.00000000"],["78227.23000000","0.00000000"],["78224.82000000","0.00007000"],["78190.78000000","0.04344000"],["77130.75000000","0.00062000"],["70474.79000000","0.00000000"],["70474.00000000","0.00000000"],["62644.27000000","0.00341000"]],"a":[["78305.34000000","2.71323000"],["78305.35000000","0.00055000"],["78305.39000000","0.00000000"],["78305.40000000","0.00000000"],["78305.92000000","0.00000000"],["78305.93000000","0.00014000"],["78306.59000000","0.00014000"],["78306.60000000","0.01859000"],["78306.77000000","0.00014000"],["78306.78000000","0.06863000"],["78307.15000000","0.00000000"],["78307.60000000","0.00000000"],["78308.00000000","0.06014000"],["78308.16000000","2.29869000"],["78308.17000000","0.00014000"],["78308.18000000","0.07247000"],["78308.49000000","0.00000000"],["78308.53000000","0.11199000"],["78309.07000000","0.00000000"],["78309.85000000","0.00000000"],["78310.59000000","0.00000000"],["78310.60000000","0.84109000"],["78311.11000000","0.00000000"],["78311.64000000","0.00000000"],["78311.73000000","0.00021000"],["78312.53000000","0.00000000"],["78312.54000000","0.00000000"],["78312.96000000","0.01000000"],["78313.07000000","2.29869000"],["78313.25000000","0.00000000"],["78314.34000000","0.00000000"],["78315.24000000","0.00000000"],["78315.30000000","0.69306000"],["78315.31000000","2.00664000"],["78315.32000000","0.00400000"],["78315.34000000","0.00000000"],["78315.35000000","0.00010000"],["78315.86000000","0.00000000"],["78315.90000000","0.00026000"],["78316.57000000","0.00188000"],["78317.78000000","0.02000000"],["78318.00000000","1.46078000"],["78319.14000000","2.29869000"],["78320.79000000","0.00638000"],["78321.68000000","0.00000000"],["78322.25000000","1.30846000"],["78322.88000000","0.16897000"],["78322.89000000","0.67981000"],["78322.91000000","0.00000000"],["78323.27000000","0.00000000"],["78323.69000000","0.00000000"],["78324.00000000","0.13863000"],["78325.99000000","0.31937000"],["78327.09000000","0.00000000"],["78340.25000000","0.00000000"],["78342.84000000","0.02800000"],["78345.03000000","0.02460000"],["78346.99000000","0.00223000"],["78347.64000000","0.00000000"],["78354.36000000","0.00400000"],["78355.69000000","0.00319000"],["78392.85000000","0.04781000"],["78393.29000000","0.00000000"],["78396.61000000","0.00000000"],["78433.93000000","0.00127000"]]}}
{"rx":1788854524670528053, "m":{"e":"depthUpdate","E":1788854524614,"s":"BTCUSDT","U":99829850111,"u":99829850234,"b":[["78305.33000000","0.91864000"],["78303.75000000","0.00045000"],["78303.46000000","0.04014000"],["78302.65000000","0.00000000"],["78301.75000000","0.00028000"],["78301.67000000","0.31951000"],["78301.63000000","0.02014000"],["78301.40000000","0.50000000"],["78301.14000000","0.00000000"],["78301.00000000","0.00000000"],["78300.85000000","0.00574000"],["78300.17000000","0.00000000"],["78300.00000000","1.50941000"],["78298.98000000","0.00000000"],["78298.40000000","0.00000000"],["78298.33000000","0.00000000"],["78298.21000000","0.00709000"],["78298.00000000","0.05000000"],["78296.88000000","0.00400000"],["78295.47000000","0.00000000"],["78295.13000000","0.00000000"],["78294.29000000","0.00638000"],["78294.22000000","0.00000000"],["78289.54000000","0.00000000"],["78287.21000000","0.00180000"],["78277.97000000","0.02478000"],["78269.74000000","0.88540000"],["78267.52000000","0.63902000"],["78230.22000000","2.30188000"],["77981.39000000","0.00007000"],["77130.75000000","0.00062000"],["70474.80000000","0.00400000"],["62644.27000000","0.00310000"]],"a":[["78305.34000000","5.09263000"],["78305.35000000","0.00027000"],["78305.93000000","0.00000000"],["78306.59000000","0.00000000"],["78306.77000000","0.00000000"],["78307.74000000","0.00014000"],["78307.84000000","0.00141000"],["78307.99000000","0.00664000"],["78308.00000000","0.06014000"],["78308.15000000","0.74783000"],["78308.16000000","2.29883000"],["78308.17000000","0.00000000"],["78309.10000000","0.02228000"],["78311.38000000","0.00400000"],["78312.08000000","0.00400000"],["78313.06000000","0.37981000"],["78313.16000000","0.00000000"],["78314.41000000","0.00400000"],["78314.99000000","0.00000000"],["78315.32000000","0.00000000"],["78317.79000000","0.00400000"],["78322.25000000","1.60846000"],["78322.90000000","0.00000000"],["78343.91000000","1.26403000"],["78351.84000000","0.00400000"],["78354.36000000","0.00000000"],["78385.30000000","0.00000000"],["78599.13000000","0.00000000"]]}}
{"rx":1788854524764432504, "m":{"e":"depthUpdate","E":1788854524714,"s":"BTCUSDT","U":99829850235,"u":99829850357,"b":[["78305.33000000","0.91223000"],["78305.32000000","0.00076000"],["78303.46000000","0.04014000"],["78301.75000000","0.00014000"],["78301.40000000","0.50014000"],["78299.76000000","0.00007000"],["78298.00000000","0.03000000"],["78297.80000000","0.08228000"],["78297.50000000","0.10831000"],["78296.88000000","0.00000000"],["78296.66000000","0.00400000"],["78294.53000000","0.00070000"],["78294.50000000","0.00048000"],["78294.28000000","0.00000000"],["78293.95000000","0.00000000"],["78293.88000000","0.00400000"],["78293.80000000","0.17578000"],["78291.22000000","0.00800000"],["78290.01000000","0.37581000"],["78289.93000000","0.98742000"],["78288.85000000","0.00000000"],["78287.14000000","0.00000000"],["78282.48000000","0.00000000"],["78282.04000000","0.00150000"],["78277.97000000","0.00000000"],["78276.01000000","0.00024000"],["78263.85000000","0.00007000"],["78259.86000000","0.00000000"],["78258.74000000","0.00000000"],["78248.75000000","0.00022000"],["78085.17000000","0.00802000"],["78075.15000000","0.00000000"],["77130.75000000","0.00062000"],["70474.80000000","0.00384000"]],"a":[["78305.34000000","5.02152000"],["78306.48000000","0.00400000"],["78307.85000000","0.02228000"],["78307.99000000","0.00678000"],["78308.00000000","0.06014000"],["78308.13000000","1.34805000"],["78308.14000000","2.00664000"],["78308.15000000","0.00014000"],["78308.53000000","0.11185000"],["78309.00000000","0.00400000"],["78309.10000000","0.02214000"],["78309.99000000","0.00000000"],["78310.59000000","0.37581000"],["78311.38000000","0.00000000"],["78312.08000000","0.00000000"],["78313.05000000","0.00400000"],["78313.06000000","0.00400000"],["78313.78000000","0.03057000"],["78316.57000000","0.00000000"],["78319.13000000","0.37581000"],["78320.79000000","0.00000000"],["78322.89000000","0.30400000"],["78323.16000000","0.00223000"],["78327.61000000","0.37581000"],["78330.51000000","0.20168000"],["78332.92000000","0.00000000"],["78333.86000000","0.53042000"],["78344.28000000","0.00400000"],["78345.27000000","0.00000000"],["78346.80000000","0.00000000"],["78346.99000000","0.00000000"],["78349.32000000","0.00000000"],["78351.84000000","0.00000000"],["78358.86000000","1.08808000"],["78450.03000000","0.00000000"],["78513.40000000","0.00000000"]]}}
{"rx":1788854524859990338, "m":{"e":"depthUpdate","E":1788854524814,"s":"BTCUSDT","U":99829850358,"u":99829850414,"b":[["78305.33000000","0.91373000"],["78301.53000000","0.12336000"],["78300.12000000","0.00026000"],["78299.76000000","0.00014000"],["78293.98000000","0.00000000"],["78293.91000000","0.00000000"],["78293.88000000","0.00400000"],["78293.39000000","0.00000000"],["78293.27000000","0.00000000"],["77130.75000000","0.00070000"],["70474.80000000","0.00384000"],["62644.27000000","0.00279000"]],"a":[["78305.36000000","0.00013000"],["78305.74000000","0.00000000"],["78306.27000000","0.00400000"],["78306.97000000","0.00400000"],["78308.00000000","0.06014000"],["78308.12000000","0.01600000"],["78308.13000000","1.34819000"],["78308.14000000","2.00678000"],["78308.15000000","0.00000000"],["78308.18000000","0.07233000"],["78311.27000000","0.00000000"],["78313.05000000","0.00000000"],["78313.06000000","0.00000000"],["78313.18000000","0.00142000"],["78314.41000000","0.00000000"],["78314.42000000","0.00000000"],["78317.09000000","0.00000000"],["78317.79000000","0.00000000"],["78318.34000000","0.00000000"],["78321.02000000","0.00000000"],["78322.26000000","0.30000000"],["78328.86000000","0.00000000"],["78336.70000000","0.00000000"],["78356.48000000","0.50958000"],["78366.26000000","0.00000000"]]}}
{"rx":1788854524950832021, "m":{"e":"depthUpdate","E":1788854524914,"s":"BTCUSDT","U":99829850415,"u":99829850446,"b":[["78305.33000000","0.89242000"],["78305.32000000","0.00083000"],["78302.33000000","0.16320000"],["78301.63000000","0.02014000"],["78301.54000000","0.00014000"],["78301.53000000","0.00000000"],["78301.41000000","0.54297000"],["78274.88000000","0.00408000"],["77130.75000000","0.00070000"],["70474.80000000","0.00400000"]],"a":[["78308.00000000","0.06014000"],["78308.12000000","0.01614000"],["78308.16000000","2.29869000"],["78317.09000000","0.00007000"],["78356.25000000","0.00638000"],["78511.33000000","0.00000000"]]}}
{"rx":1788854525070515136, "m":{"e":"depthUpdate","E":1788854525014,"s":"BTCUSDT","U":99829850447,"u":99829850502,"b":[["78305.33000000","0.89244000"],["78305.32000000","0.00083000"],["78303.46000000","0.04014000"],["78302.35000000","0.00014000"],["78302.34000000","0.14435000"],["78302.33000000","0.00014000"],["78301.75000000","0.00000000"],["78301.74000000","0.00014000"],["78301.63000000","0.02000000"],["78301.54000000","0.00000000"],["78285.88000000","0.00000000"],["78284.22000000","0.31938000"],["78146.11000000","0.00206000"],["77292.28000000","0.00010000"],["77130.75000000","0.00070000"],["70474.80000000","0.00393000"],["70474.00000000","0.00010000"],["62644.27000000","0.00248000"]],"a":[["78305.34000000","5.01322000"],["78306.26000000","0.00134000"],["78307.83000000","0.00638000"],["78307.84000000","0.00000000"],["78319.12000000","0.48835000"],["78322.87000000","0.31938000"],["78322.88000000","0.00000000"],["78325.99000000","0.00000000"],["78326.81000000","0.31938000"],["78327.62000000","0.00000000"],["78328.78000000","0.12766000"],["78331.65000000","0.00000000"],["78452.70000000","0.00206000"],["78494.57000000","0.03188000"],["78511.27000000","0.00000000"],["79043.69000000","0.00000000"]]}}
{"rx":1788854525163319222, "m":{"e":"depthUpdate","E":1788854525114,"s":"BTCUSDT","U":99829850503,"u":99829850548,"b":[["78305.33000000","0.89237000"],["78305.32000000","0.00076000"],["78303.46000000","0.04014000"],["78302.34000000","0.07252000"],["78302.33000000","0.00000000"],["78301.74000000","0.00000000"],["78301.63000000","0.02014000"],["78301.41000000","0.54304000"],["78230.23000000","2.01025000"],["78230.21000000","0.00000000"],["78203.88000000","0.05627000"],["78203.51000000","0.00000000"],["77130.75000000","0.00062000"],["70474.80000000","0.00409000"],["70474.00000000","0.00000000"],["62644.26000000","0.00000000"],["62644.00000000","0.00200000"]],"a":[["78305.34000000","5.01302000"],["78306.78000000","0.06863000"],["78307.83000000","0.00652000"],["78308.14000000","2.00664000"],["78326.00000000","0.73000000"],["78330.51000000","0.00000000"],["78435.99000000","0.02696000"]]}}
{"rx":1788854525250443217, "m":{"e":"depthUpdate","E":1788854525214,"s":"BTCUSDT","U":99829850549,"u":99829850557,"b":[["77130.75000000","0.00062000"],["70474.80000000","0.00393000"],["62644.27000000","0.00217000"],["62644.00000000","0.00000000"]],"a":[["78306.26000000","0.00000000"],["78306.47000000","0.00134000"],["78438.46000000","0.02000000"],["78508.36000000","0.00000000"],["82921.18000000","0.00010000"]]}}
{"rx":1788854525367857173, "m":{"e":"depthUpdate","E":1788854525314,"s":"BTCUSDT","U":99829850558,"u":99829850587,"b":[["78305.33000000","0.89244000"],["78305.32000000","0.00083000"],["78302.50000000","0.00296000"],["78302.34000000","0.13222000"],["78302.24000000","0.00014000"],["78302.23000000","0.15384000"],["78301.41000000","0.54297000"],["78274.88000000","0.00000000"],["78269.00000000","0.70000000"],["78267.00000000","0.00000000"],["78235.74000000","0.00000000"],["77130.75000000","0.00062000"],["70474.80000000","0.00409000"],["70474.00000000","0.00000000"],["62644.00000000","0.00000000"]],"a":[["78376.99000000","0.12433000"],["78379.45000000","0.25539000"],["78390.42000000","0.00000000"],["78408.73000000","0.00000000"],["78489.65000000","0.00000000"],["78512.11000000","0.00000000"],["79479.93000000","0.00030000"]]}}
{"rx":1788854525482258335, "m":{"e":"depthUpdate","E":1788854525414,"s":"BTCUSDT","U":99829850588,"u":99829850639,"b":[["78305.33000000","0.89402000"],["78303.67000000","0.00014000"],["78303.66000000","0.14868000"],["78303.65000000","0.13430000"],["78302.35000000","0.00000000"],["78302.34000000","0.00014000"],["78302.24000000","0.00000000"],["78302.23000000","0.00000000"],["78278.01000000","0.31938000"],["78275.01000000","0.00000000"],["78171.25000000","0.05000000"],["77130.75000000","0.00062000"],["70474.80000000","0.00393000"],["70474.00000000","0.00000000"],["62644.27000000","0.00186000"]],"a":[["78305.34000000","2.71250000"],["78306.26000000","0.00000000"],["78306.27000000","0.00000000"],["78306.46000000","0.00183000"],["78306.47000000","0.00000000"],["78306.59000000","0.00014000"],["78306.77000000","0.00014000"],["78306.97000000","0.00000000"],["78307.51000000","0.00400000"],["78307.82000000","0.00134000"],["78307.83000000","0.00014000"],["78307.99000000","0.00014000"],["78308.87000000","0.00400000"],["78308.99000000","0.00000000"],["78309.99000000","0.00638000"],["78310.26000000","0.00638000"],["78310.59000000","0.00000000"],["78319.12000000","0.16897000"],["78320.51000000","0.31938000"],["78322.87000000","0.00000000"],["78324.32000000","0.31938000"],["78326.81000000","0.00000000"],["78328.59000000","0.31938000"],["78438.46000000","0.00000000"],["78486.51000000","0.02000000"]]}}
{"rx":1788854525585507515, "m":{"e":"depthUpdate","E":1788854525514,"s":"BTCUSDT","U":99829850640,"u":99829850708,"b":[["78305.33000000","0.89252000"],["78305.32000000","0.00083000"],["78303.66000000","0.07252000"],["78303.65000000","0.00014000"],["78303.46000000","0.04000000"],["78302.34000000","0.00000000"],["78301.41000000","0.54304000"],["78296.20000000","0.00400000"],["78293.90000000","0.00000000"],["78293.88000000","0.00000000"],["78293.36000000","0.00000000"],["78235.74000000","0.00408000"],["78230.92000000","0.00007000"],["77130.75000000","0.00062000"],["70474.80000000","0.00393000"],["70474.00000000","0.00000000"],["62644.27000000","0.00310000"]],"a":[["78305.34000000","5.01303000"],["78306.46000000","0.00000000"],["78306.59000000","0.00000000"],["78306.77000000","0.00000000"],["78306.78000000","0.06863000"],["78307.73000000","0.00638000"],["78307.83000000","0.00000000"],["78307.85000000","0.02228000"],["78307.99000000","0.00000000"],["78308.14000000","2.00678000"],["78308.16000000","2.29883000"],["78309.99000000","0.00000000"],["78512.25000000","0.00000000"]]}}
{"rx":1788854525701343449, "m":{"e":"depthUpdate","E":1788854525614,"s":"BTCUSDT","U":99829850709,"u":99829850729,"b":[["78303.66000000","0.07252000"],["78303.65000000","0.00000000"],["78303.46000000","0.04014000"],["77130.75000000","0.00062000"],["70474.80000000","0.00409000"],["62644.27000000","0.00279000"],["62644.00000000","0.00200000"]],"a":[["78306.78000000","0.06863000"],["78307.73000000","0.00652000"],["78308.16000000","2.29869000"]]}}
{"rx":1788854525774207299, "m":{"e":"depthUpdate","E":1788854525714,"s":"BTCUSDT","U":99829850730,"u":99829850739,"b":[["78305.33000000","0.89409000"],["78300.83000000","0.13980000"],["77130.75000000","0.00062000"],["70474.80000000","0.00393000"],["62644.00000000","0.00000000"]],"a":[["78305.34000000","5.01431000"],["78308.00000000","0.05014000"]]}}
{"rx":1788854525887888529, "m":{"e":"depthUpdate","E":1788854525814,"s":"BTCUSDT","U":99829850740,"u":99829850772,"b":[["78305.33000000","0.89259000"],["78303.66000000","0.14342000"],["78301.98000000","0.00014000"],["78301.97000000","0.14810000"],["78301.41000000","0.54297000"],["78300.83000000","0.00000000"],["78294.09000000","0.00000000"],["78293.21000000","0.00000000"],["78085.17000000","0.00000000"],["78075.15000000","0.00802000"],["77130.75000000","0.00070000"],["70474.80000000","0.00409000"],["62644.27000000","0.00248000"]],"a":[["78305.34000000","5.01430000"],["78305.54000000","0.02138000"],["78306.47000000","0.00000000"],["78306.89000000","0.01329000"],["78308.00000000","0.06014000"],["78310.81000000","0.01321000"],["78313.38000000","0.02121000"],["78314.73000000","0.01287000"],["78318.59000000","0.21339000"],["78318.65000000","0.01297000"],["78321.22000000","0.02121000"],["78322.57000000","0.01282000"],["78329.06000000","0.02088000"],["78336.90000000","0.02170000"],["78424.19000000","0.00000000"],["78511.95000000","0.12779000"]]}}
{"rx":1788854526002349423, "m":{"e":"depthUpdate","E":1788854525914,"s":"BTCUSDT","U":99829850773,"u":99829850916,"b":[["78305.33000000","0.18732000"],["78305.32000000","0.00090000"],["78303.76000000","0.00014000"],["78303.75000000","0.00045000"],["78303.67000000","0.00000000"],["78303.66000000","0.00014000"],["78303.46000000","0.04014000"],["78302.50000000","0.00000000"],["78301.99000000","0.00014000"],["78301.98000000","0.00000000"],["78301.97000000","0.00014000"],["78301.68000000","0.00000000"],["78301.67000000","0.00014000"],["78301.63000000","0.00014000"],["78301.41000000","0.54304000"],["78300.85000000","0.00588000"],["78300.12000000","0.00000000"],["78299.76000000","0.00007000"],["78298.58000000","0.00315000"],["78297.80000000","0.00000000"],["78297.50000000","0.08831000"],["78297.32000000","0.00000000"],["78297.03000000","0.02000000"],["78296.66000000","0.00000000"],["78296.20000000","0.00000000"],["78295.77000000","0.00007000"],["78294.66000000","0.00400000"],["78294.60000000","0.00000000"],["78294.29000000","0.00000000"],["78292.32000000","0.31941000"],["78292.20000000","0.00008000"],["78292.03000000","0.00426000"],["78291.21000000","0.00000000"],["78291.09000000","0.01311000"],["78290.22000000","0.00638000"],["78290.02000000","0.37581000"],["78290.01000000","0.00000000"],["78289.93000000","0.23499000"],["78289.80000000","0.15000000"],["78289.53000000","0.00000000"],["78286.02000000","0.00000000"],["78282.26000000","0.15190000"],["78278.01000000","0.00000000"],["78274.43000000","0.31937000"],["78259.86000000","0.00007000"],["78258.60000000","0.00223000"],["78251.04000000","0.00222000"],["78238.70000000","0.00000000"],["78228.01000000","0.00000000"],["78216.21000000","0.00000000"],["78215.09000000","0.06329000"],["78149.42000000","0.00000000"],["78146.11000000","0.00000000"],["77130.75000000","0.00070000"],["70474.80000000","0.00384000"],["70474.79000000","0.00009000"]],"a":[["78305.34000000","5.02812000"],["78305.54000000","0.02152000"],["78306.78000000","0.06863000"],["78306.89000000","0.01343000"],["78307.40000000","0.00000000"],["78307.45000000","0.03057000"],["78307.73000000","0.00014000"],["78307.82000000","0.00000000"],["78307.85000000","0.02254000"],["78308.00000000","0.06014000"],["78308.11000000","0.37581000"],["78308.13000000","1.34805000"],["78308.14000000","2.00664000"],["78310.26000000","0.00000000"],["78317.09000000","0.00007000"],["78317.99000000","0.16897000"],["78319.12000000","0.00000000"],["78320.79000000","0.00049000"],["78322.99000000","0.63857000"],["78328.78000000","0.00000000"],["78329.39000000","0.00000000"],["78334.76000000","0.34477000"],["78353.65000000","1.37122000"],["78355.19000000","0.00000000"],["78369.13000000","0.00000000"],["78390.42000000","0.00408000"],["78399.99000000","1.63488000"],["78400.29000000","2.68103000"],["78427.21000000","0.20702000"],["78438.26000000","0.00000000"],["78452.70000000","0.00000000"],["78511.95000000","0.00000000"]]}}
{"rx":1788854526064756926, "m":{"e":"depthUpdate","E":1788854526014,"s":"BTCUSDT","U":99829850917,"u":99829851006,"b":[["78305.33000000","0.18726000"],["78305.32000000","0.00076000"],["78303.76000000","0.00000000"],["78303.66000000","0.00000000"],["78303.46000000","0.04014000"],["78301.99000000","0.00000000"],["78301.97000000","0.00000000"],["78301.67000000","0.00000000"],["78301.63000000","0.00000000"],["78301.41000000","0.54311000"],["78300.01000000","0.00077000"],["78300.00000000","1.50955000"],["78299.90000000","0.00026000"],["78298.21000000","0.00723000"],["78298.00000000","0.03014000"],["78297.50000000","0.08838000"],["78295.77000000","0.00014000"],["78291.22000000","0.00000000"],["78288.74000000","0.00800000"],["78259.86000000","0.00007000"],["78228.01000000","0.00180000"],["78149.42000000","0.00072000"],["77130.75000000","0.00070000"],["70474.80000000","0.00384000"],["62644.27000000","0.00341000"]],"a":[["78305.34000000","5.01536000"],["78305.77000000","0.00400000"],["78306.47000000","0.00638000"],["78306.89000000","0.01343000"],["78307.40000000","0.00638000"],["78307.45000000","0.00014000"],["78307.73000000","0.00000000"],["78308.00000000","0.06014000"],["78308.11000000","0.37595000"],["78308.12000000","0.01600000"],["78308.87000000","0.00000000"],["78320.34000000","0.12768000"],["78340.23000000","0.02532000"],["78345.03000000","0.00000000"],["78435.99000000","0.00000000"],["78438.26000000","0.02892000"]]}}
{"rx":1788854526185694636, "m":{"e":"depthUpdate","E":1788854526114,"s":"BTCUSDT","U":99829851007,"u":99829851033,"b":[["78227.36000000","0.02904000"],["77130.75000000","0.00062000"],["62644.26000000","0.00000000"]],"a":[["78305.54000000","0.02152000"],["78306.47000000","0.00652000"],["78306.89000000","0.01343000"],["78307.40000000","0.00652000"],["78307.45000000","0.00000000"],["78307.85000000","0.02228000"],["78308.11000000","0.37581000"],["78331.91000000","0.10553000"],["78435.99000000","0.02696000"],["78509.50000000","0.00000000"]]}}
{"rx":1788854526280588685, "m":{"e":"depthUpdate","E":1788854526214,"s":"BTCUSDT","U":99829851034,"u":99829851082,"b":[["78305.33000000","0.59228000"],["78301.65000000","0.00014000"],["78301.64000000","0.13896000"],["78299.76000000","0.00014000"],["78297.50000000","0.08831000"],["78296.20000000","0.00400000"],["78293.80000000","0.77464000"],["78292.03000000","0.00026000"],["78290.03000000","1.84602000"],["78259.86000000","0.00000000"],["78253.56000000","0.00222000"],["78251.04000000","0.00000000"],["77130.75000000","0.00062000"],["70474.80000000","0.00384000"],["62644.27000000","0.00310000"]],"a":[["78305.34000000","5.01219000"],["78305.53000000","0.00181000"],["78305.77000000","0.00000000"],["78306.46000000","0.00000000"],["78306.47000000","0.00014000"],["78307.17000000","0.00400000"],["78307.39000000","0.00132000"],["78307.40000000","0.00014000"],["78307.50000000","0.00638000"],["78309.99000000","0.00638000"],["78320.34000000","0.00000000"],["78320.79000000","0.00000000"],["78324.31000000","0.00049000"],["78343.91000000","0.00000000"],["78608.60000000","7.63500000"]]}}
{"rx":1788854526400794541, "m":{"e":"depthUpdate","E":1788854526314,"s":"BTCUSDT","U":99829851083,"u":99829851123,"b":[["78305.33000000","0.38992000"],["78305.32000000","0.00083000"],["78303.46000000","0.04014000"],["78303.17000000","0.12004000"],["78301.64000000","0.00000000"],["78298.06000000","0.08228000"],["78289.93000000","0.16261000"],["78261.12000000","0.00222000"],["78253.56000000","0.00000000"],["78190.78000000","0.24760000"],["77130.75000000","0.00062000"],["70474.80000000","0.00400000"]],"a":[["78305.34000000","5.01402000"],["78305.53000000","0.00000000"],["78305.54000000","0.02152000"],["78306.46000000","0.00134000"],["78306.47000000","0.00000000"],["78306.89000000","0.01343000"],["78307.39000000","0.00000000"],["78307.40000000","0.00000000"],["78307.50000000","0.00652000"],["78308.11000000","0.37595000"],["78308.18000000","0.07736000"],["78427.21000000","0.10358000"],["79479.93000000","0.00000000"]]}}
{"rx":1788854526504921568, "m":{"e":"depthUpdate","E":1788854526414,"s":"BTCUSDT","U":99829851124,"u":99829851164,"b":[["78305.33000000","0.38985000"],["78305.32000000","0.00076000"],["78303.48000000","0.00000000"],["78303.47000000","0.00014000"],["78303.46000000","0.04014000"],["78303.18000000","0.00000000"],["78303.17000000","0.00014000"],["78301.65000000","0.00000000"],["78298.21000000","0.00723000"],["78298.00000000","0.03000000"],["78297.50000000","0.08838000"],["78293.80000000","0.70226000"],["78190.98000000","0.14384000"],["77130.75000000","0.00062000"],["70474.80000000","0.00384000"],["62644.27000000","0.00279000"]],"a":[["78308.00000000","0.06014000"],["78421.87000000","0.07568000"],["78510.70000000","0.00000000"],["79479.93000000","0.00030000"]]}}
{"rx":1788854526615695181, "m":{"e":"depthUpdate","E":1788854526514,"s":"BTCUSDT","U":99829851165,"u":99829851180,"b":[["78303.46000000","0.04014000"],["78303.17000000","0.00000000"],["78298.06000000","0.08242000"],["77130.75000000","0.00062000"],["70474.80000000","0.00400000"]],"a":[["78425.65000000","0.00055000"],["78510.31000000","0.00000000"],["78510.77000000","0.00000000"]]}}
{"rx":1788854526692918092, "m":{"e":"depthUpdate","E":1788854526614,"s":"BTCUSDT","U":99829851181,"u":99829851241,"b":[["78305.33000000","0.53270000"],["78305.32000000","0.00090000"],["78303.48000000","0.00014000"],["78303.47000000","0.05347000"],["78303.08000000","0.00014000"],["78303.07000000","0.13851000"],["78300.01000000","0.00063000"],["78298.00000000","0.03014000"],["78297.50000000","0.08831000"],["78190.98000000","0.08040000"],["78190.78000000","0.00000000"],["77130.75000000","0.00062000"],["72089.37000000","0.00014000"],["70474.80000000","0.00384000"],["70474.79000000","0.00000000"],["70474.00000000","0.00020000"],["62644.27000000","0.00248000"],["62644.00000000","0.00000000"]],"a":[["78308.00000000","0.06014000"],["78355.69000000","0.00000000"],["78421.87000000","0.10344000"],["78433.93000000","0.00000000"],["78511.39000000","0.00000000"],["78897.28000000","0.05862000"]]}}
{"rx":1788854526824382379, "m":{"e":"depthUpdate","E":1788854526714,"s":"BTCUSDT","U":99829851242,"u":99829851288,"b":[["78305.33000000","0.53566000"],["78305.32000000","0.00090000"],["78304.05000000","0.00014000"],["78304.04000000","0.05100000"],["78304.03000000","0.12924000"],["78303.48000000","0.00000000"],["78303.47000000","0.00028000"],["78303.46000000","0.04014000"],["78303.08000000","0.00000000"],["78303.07000000","0.00000000"],["78298.06000000","0.08228000"],["78298.00000000","0.03000000"],["78274.88000000","0.00408000"],["78192.27000000","0.04344000"],["77130.75000000","0.00062000"],["70474.80000000","0.00384000"],["70474.00000000","0.00000000"]],"a":[["78355.69000000","0.00319000"],["78433.93000000","0.00127000"],["78510.86000000","0.00000000"]]}}
{"rx":1788854526892275238, "m":{"e":"depthUpdate","E":1788854526814,"s":"BTCUSDT","U":99829851289,"u":99829851306,"b":[["78305.33000000","0.37302000"],["78304.04000000","0.05114000"],["78304.03000000","0.00000000"],["78303.47000000","0.00014000"],["78303.46000000","0.04000000"],["77130.75000000","0.00070000"],["70474.80000000","0.00400000"],["62644.27000000","0.00217000"]],"a":[["78305.53000000","0.00133000"],["78306.46000000","0.00000000"],["78511.09000000","0.00000000"],["79284.44000000","0.00299000"]]}}
{"rx":1788854526997830607, "m":{"e":"depthUpdate","E":1788854526914,"s":"BTCUSDT","U":99829851307,"u":99829851329,"b":[["78305.33000000","0.37288000"],["78305.32000000","0.00076000"],["78304.05000000","0.00000000"],["78304.04000000","0.00014000"],["78300.01000000","0.00077000"],["78297.50000000","0.08838000"],["77130.75000000","0.00070000"],["70474.80000000","0.00384000"]],"a":[["78317.09000000","0.00007000"]]}}
{"rx":1788854527083270390, "m":{"e":"depthUpdate","E":1788854527014,"s":"BTCUSDT","U":99829851330,"u":99829851348,"b":[["78305.33000000","0.53013000"],["78304.04000000","0.00000000"],["78303.46000000","0.04014000"],["78138.10000000","0.02000000"],["78110.81000000","0.00000000"],["77130.75000000","0.00070000"],["70474.80000000","0.00400000"],["62644.27000000","0.00310000"]],"a":[["78305.53000000","0.00000000"],["78306.47000000","0.00133000"],["78328.61000000","0.12766000"],["78478.30000000","0.01563000"],["78779.55000000","0.00000000"]]}}
{"rx":1788854527185869219, "m":{"e":"depthUpdate","E":1788854527114,"s":"BTCUSDT","U":99829851349,"u":99829851370,"b":[["78305.33000000","0.37295000"],["78305.32000000","0.00083000"],["78303.48000000","0.00014000"],["78303.47000000","0.05822000"],["78303.27000000","0.00014000"],["78303.26000000","0.15428000"],["78300.01000000","0.00063000"],["78297.50000000","0.08831000"],["77130.75000000","0.00062000"],["70474.80000000","0.00384000"],["62644.26000000","0.00000000"]],"a":[["78305.53000000","0.00000000"],["78306.46000000","0.00133000"],["78306.47000000","0.00000000"],["78419.99000000","0.04658000"]]}}
{"rx":1788854527285140643, "m":{"e":"depthUpdate","E":1788854527214,"s":"BTCUSDT","U":99829851371,"u":99829851416,"b":[["78305.33000000","0.62898000"],["78304.27000000","0.00014000"],["78304.26000000","0.05419000"],["78304.25000000","0.13978000"],["78303.48000000","0.00000000"],["78303.47000000","0.00028000"],["78303.46000000","0.04014000"],["78303.27000000","0.00000000"],["78303.26000000","0.00014000"],["77130.75000000","0.00062000"],["72089.37000000","0.00000000"],["70474.80000000","0.00409000"],["62644.27000000","0.00279000"]],"a":[["78305.34000000","4.95003000"],["78305.53000000","0.00014000"],["78305.54000000","0.00014000"],["78306.59000000","0.00014000"],["78306.89000000","0.00014000"],["78307.51000000","0.00000000"],["78307.96000000","0.00400000"]]}}
{"rx":1788854527379554660, "m":{"e":"depthUpdate","E":1788854527314,"s":"BTCUSDT","U":99829851417,"u":99829851585,"b":[["78305.33000000","2.43254000"],["78305.32000000","0.00076000"],["78304.27000000","0.00000000"],["78304.26000000","0.00014000"],["78304.25000000","0.00014000"],["78303.75000000","0.00052000"],["78303.47000000","0.00014000"],["78303.46000000","0.04000000"],["78303.26000000","0.00000000"],["78301.82000000","0.00400000"],["78300.01000000","0.00077000"],["78298.75000000","0.00400000"],["78298.58000000","0.00000000"],["78298.06000000","0.00000000"],["78297.50000000","0.08838000"],["78296.20000000","0.00000000"],["78296.01000000","0.00638000"],["78294.66000000","0.00000000"],["78293.88000000","0.02096000"],["78293.81000000","0.00800000"],["78293.80000000","1.39039000"],["78293.52000000","0.01342000"],["78290.22000000","0.00000000"],["78290.04000000","2.29869000"],["78289.93000000","0.35487000"],["78288.74000000","0.00000000"],["78287.31000000","0.31937000"],["78287.22000000","0.15189000"],["78284.22000000","0.00000000"],["78282.26000000","0.00000000"],["78279.82000000","0.31937000"],["78277.60000000","0.63894000"],["78275.01000000","0.31937000"],["78274.48000000","0.02455000"],["78274.43000000","0.00000000"],["78270.01000000","0.00000000"],["78263.85000000","0.00000000"],["78237.94000000","0.00000000"],["78230.23000000","1.32409000"],["78230.22000000","0.00319000"],["77130.75000000","0.00062000"],["70474.80000000","0.00393000"],["62644.00000000","0.00000000"]],"a":[["78305.34000000","2.64986000"],["78305.35000000","0.00062000"],["78305.53000000","0.00000000"],["78305.54000000","0.00000000"],["78306.46000000","0.00000000"],["78306.77000000","0.00014000"],["78306.78000000","0.06863000"],["78306.89000000","0.00000000"],["78306.94000000","0.00183000"],["78306.95000000","0.00000000"],["78306.96000000","0.00000000"],["78307.17000000","0.00000000"],["78307.50000000","0.00014000"],["78307.84000000","0.00000000"],["78307.96000000","0.00000000"],["78308.11000000","0.00014000"],["78308.12000000","0.01614000"],["78308.13000000","1.34819000"],["78308.86000000","0.00400000"],["78309.64000000","0.00400000"],["78309.98000000","0.00145000"],["78309.99000000","0.00000000"],["78310.81000000","0.00000000"],["78311.20000000","0.00638000"],["78313.38000000","0.00000000"],["78313.78000000","0.00000000"],["78314.73000000","0.00000000"],["78314.99000000","0.00638000"],["78318.65000000","0.00000000"],["78320.51000000","0.00000000"],["78321.22000000","0.00000000"],["78322.24000000","0.31937000"],["78322.57000000","0.00000000"],["78322.99000000","0.00000000"],["78324.32000000","0.00000000"],["78325.99000000","0.31937000"],["78329.06000000","0.00000000"],["78336.90000000","0.00000000"],["78344.79000000","1.26401000"],["78450.03000000","0.03057000"]]}}
{"rx":1788854527464706312, "m":{"e":"depthUpdate","E":1788854527414,"s":"BTCUSDT","U":99829851586,"u":99829851687,"b":[["78305.33000000","2.06210000"],["78305.32000000","0.00083000"],["78304.26000000","0.00000000"],["78304.25000000","0.00000000"],["78303.75000000","0.00045000"],["78303.48000000","0.00014000"],["78303.47000000","0.01327000"],["78303.46000000","0.04014000"],["78301.82000000","0.00000000"],["78299.80000000","0.00000000"],["78298.75000000","0.00000000"],["78298.21000000","0.00723000"],["78297.50000000","0.08831000"],["78296.71000000","0.00400000"],["78296.38000000","0.00400000"],["78294.21000000","0.00007000"],["78293.88000000","0.00000000"],["78293.81000000","0.00000000"],["78293.80000000","0.70226000"],["78293.52000000","0.00000000"],["78293.42000000","0.00000000"],["78292.01000000","0.00000000"],["78290.22000000","0.00800000"],["78290.04000000","0.00000000"],["78287.31000000","0.00000000"],["78284.59000000","0.31936000"],["78279.82000000","0.00000000"],["78276.71000000","0.31936000"],["78263.85000000","0.00007000"],["78230.24000000","2.29869000"],["77130.75000000","0.00062000"],["70474.80000000","0.00393000"],["62644.27000000","0.00248000"],["44000.00000000","18.30558000"]],"a":[["78305.34000000","4.95007000"],["78305.35000000","0.00027000"],["78306.58000000","0.00148000"],["78306.76000000","0.00638000"],["78306.78000000","0.06863000"],["78306.94000000","0.00000000"],["78307.50000000","0.00000000"],["78308.00000000","0.06014000"],["78308.11000000","0.00000000"],["78308.14000000","2.00678000"],["78308.16000000","2.29883000"],["78309.98000000","0.00000000"],["78311.20000000","0.00000000"],["78322.24000000","0.61937000"],["78322.25000000","1.26359000"],["78322.89000000","0.00400000"],["78511.71000000","0.00000000"],["79479.93000000","0.00030000"]]}}
{"rx":1788854527600129870, "m":{"e":"depthUpdate","E":1788854527514,"s":"BTCUSDT","U":99829851688,"u":99829851708,"b":[["78305.33000000","2.27029000"],["78305.32000000","0.00076000"],["77130.75000000","0.00062000"],["70474.80000000","0.00409000"]],"a":[["78306.60000000","0.01859000"],["78306.76000000","0.00014000"],["78308.16000000","2.29869000"],["78308.52000000","0.00638000"]]}}
{"rx":1788854527674678822, "m":{"e":"depthUpdate","E":1788854527614,"s":"BTCUSDT","U":99829851709,"u":99829851720,"b":[["77130.75000000","0.00062000"],["70474.80000000","0.00393000"],["62644.27000000","0.00217000"]],"a":[["78306.60000000","0.01859000"],["78306.76000000","0.00000000"],["78308.16000000","2.29883000"]]}}
{"rx":1788854527765699160, "m":{"e":"depthUpdate","E":1788854527714,"s":"BTCUSDT","U":99829851721,"u":99829851774,"b":[["78305.33000000","0.19360000"],["78305.32000000","0.00083000"],["78304.95000000","0.00014000"],["78304.94000000","0.00014000"],["78304.93000000","0.00000000"],["78303.48000000","0.00000000"],["78303.47000000","0.00014000"],["78300.01000000","0.00063000"],["78299.76000000","0.00007000"],["78296.71000000","0.00000000"],["78296.38000000","0.00000000"],["78296.01000000","0.00000000"],["78295.13000000","0.00400000"],["78292.70000000","0.00400000"],["78291.10000000","0.00638000"],["78267.52000000","0.00000000"],["78235.09000000","1.26654000"],["78228.01000000","0.00000000"],["78149.42000000","0.00000000"],["77130.75000000","0.00062000"],["70474.80000000","0.00409000"]],"a":[["78305.34000000","4.95643000"],["78306.47000000","0.00000000"],["78306.58000000","0.00000000"],["78306.59000000","0.00000000"],["78306.77000000","0.00000000"],["78307.84000000","0.00146000"],["78308.11000000","0.37581000"],["78312.76000000","0.03057000"],["78314.99000000","0.00000000"],["78328.61000000","0.00000000"],["78450.03000000","0.00000000"]]}}
{"rx":1788854527892444470, "m":{"e":"depthUpdate","E":1788854527814,"s":"BTCUSDT","U":99829851775,"u":99829851823,"b":[["78305.33000000","0.31745000"],["78305.32000000","0.00076000"],["78304.95000000","0.00000000"],["78304.94000000","0.00000000"],["78300.01000000","0.00077000"],["78299.76000000","0.00014000"],["78297.50000000","0.08838000"],["78289.93000000","0.16261000"],["78287.22000000","0.00000000"],["78283.26000000","0.15189000"],["78228.01000000","0.00180000"],["78216.21000000","1.00211000"],["78149.42000000","0.00072000"],["77130.75000000","0.00070000"],["70474.80000000","0.00393000"],["70474.00000000","0.00000000"],["62644.27000000","0.00186000"]],"a":[["78305.34000000","4.96043000"],["78305.91000000","0.00400000"],["78308.00000000","0.06040000"],["78308.11000000","0.37595000"],["78308.16000000","2.29869000"],["78308.86000000","0.00000000"],["78309.64000000","0.00000000"]]}}
{"rx":1788854527962965822, "m":{"e":"depthUpdate","E":1788854527914,"s":"BTCUSDT","U":99829851824,"u":99829851843,"b":[["78305.33000000","0.57468000"],["77130.75000000","0.00070000"],["70474.80000000","0.00393000"]],"a":[["78305.34000000","4.95005000"],["78305.91000000","0.00000000"],["78306.46000000","0.00400000"],["78307.02000000","0.00400000"],["78307.73000000","0.00638000"],["78317.09000000","0.00007000"],["78517.44000000","0.00000000"],["78525.87000000","0.20250000"]]}}
{"rx":1788854528063684682, "m":{"e":"depthUpdate","E":1788854528014,"s":"BTCUSDT","U":99829851844,"u":99829851885,"b":[["78305.33000000","0.57454000"],["78305.32000000","0.00090000"],["78303.74000000","0.00014000"],["78303.73000000","0.05832000"],["78303.72000000","0.15463000"],["78300.01000000","0.00063000"],["78298.00000000","0.03014000"],["78297.50000000","0.08845000"],["78275.01000000","0.00000000"],["78272.53000000","0.31938000"],["77130.75000000","0.00070000"],["70474.80000000","0.00400000"],["70474.79000000","0.00009000"],["62644.27000000","0.00279000"]],"a":[["78305.34000000","4.94998000"],["78306.45000000","0.00144000"],["78306.78000000","0.06863000"],["78307.73000000","0.00652000"],["78307.84000000","0.00000000"],["78308.14000000","2.00664000"],["78529.99000000","0.02000000"]]}}
{"rx":1788854528149251564, "m":{"e":"depthUpdate","E":1788854528114,"s":"BTCUSDT","U":99829851886,"u":99829851917,"b":[["78305.33000000","0.57464000"],["78303.74000000","0.00000000"],["78303.73000000","0.00014000"],["78303.72000000","0.00014000"],["78300.01000000","0.00077000"],["78298.00000000","0.03000000"],["78297.50000000","0.08838000"],["78295.85000000","0.00400000"],["78292.70000000","0.00000000"],["77130.75000000","0.00062000"],["70474.80000000","0.00384000"],["62644.26000000","0.00000000"],["62644.00000000","0.00200000"]],"a":[["78328.63000000","0.12766000"],["78508.38000000","0.00000000"]]}}
{"rx":1788854528254854120, "m":{"e":"depthUpdate","E":1788854528214,"s":"BTCUSDT","U":99829851918,"u":99829851941,"b":[["78305.33000000","0.57464000"],["78303.73000000","0.00000000"],["78303.72000000","0.00000000"],["78298.00000000","0.03014000"],["78297.50000000","0.08852000"],["77130.75000000","0.00062000"],["70474.80000000","0.00400000"],["62644.27000000","0.00248000"],["62644.26000000","0.00000000"],["62644.00000000","0.00000000"]],"a":[["78318.58000000","0.31938000"],["78322.24000000","0.30000000"]]}}
{"rx":1788854528381986256, "m":{"e":"depthUpdate","E":1788854528314,"s":"BTCUSDT","U":99829851942,"u":99829851957,"b":[["78305.33000000","0.57127000"],["78305.32000000","0.00076000"],["78301.40000000","0.50663000"],["78298.22000000","0.08228000"],["78145.89000000","0.00536000"],["77130.75000000","0.00062000"],["70474.80000000","0.00384000"]],"a":[["78421.87000000","0.00000000"],["78452.26000000","0.00206000"]]}}
{"rx":1788854528473458591, "m":{"e":"depthUpdate","E":1788854528414,"s":"BTCUSDT","U":99829851958,"u":99829851993,"b":[["78305.33000000","0.57148000"],["78305.32000000","0.00097000"],["78304.71000000","0.00014000"],["78304.70000000","0.05865000"],["78304.69000000","0.15527000"],["78300.01000000","0.00063000"],["78300.00000000","1.50955000"],["78299.46000000","0.00013000"],["78298.22000000","0.08242000"],["78297.50000000","0.08831000"],["77130.75000000","0.00062000"],["70474.80000000","0.00400000"],["62644.27000000","0.00217000"],["62644.00000000","0.00000000"]],"a":[["78419.99000000","0.01801000"],["78423.88000000","0.07550000"],["79479.93000000","0.00030000"]]}}
{"rx":1788854528602523284, "m":{"e":"depthUpdate","E":1788854528514,"s":"BTCUSDT","U":99829851994,"u":99829852038,"b":[["78305.33000000","0.42574000"],["78304.70000000","0.05879000"],["78304.69000000","0.00014000"],["78298.21000000","0.00709000"],["78298.00000000","0.03000000"],["78295.85000000","0.00000000"],["78294.43000000","0.00400000"],["78284.59000000","0.00000000"],["78283.27000000","0.31938000"],["78228.01000000","0.00000000"],["78149.42000000","0.00000000"],["77130.75000000","0.00062000"],["70474.80000000","0.00384000"],["70474.79000000","0.00000000"],["62644.27000000","0.00341000"]],"a":[["78307.29000000","0.02149000"],["78307.42000000","0.01340000"],["78311.34000000","0.01321000"],["78315.13000000","0.02157000"],["78315.26000000","0.01302000"],["78319.18000000","0.01328000"],["78322.97000000","0.02143000"],["78323.10000000","0.01298000"],["78328.01000000","0.17350000"],["78330.81000000","0.02096000"],["78338.65000000","0.02159000"],["78340.34000000","0.00200000"],["78423.88000000","0.10344000"],["79015.63000000","0.00960000"],["79134.16000000","0.01099000"]]}}
{"rx":1788854528669866742, "m":{"e":"depthUpdate","E":1788854528614,"s":"BTCUSDT","U":99829852039,"u":99829852076,"b":[["78305.33000000","0.42564000"],["78304.71000000","0.00000000"],["78304.70000000","0.00014000"],["78304.69000000","0.00000000"],["78301.41000000","0.55015000"],["78301.40000000","0.50014000"],["78300.01000000","0.00077000"],["78298.21000000","0.00723000"],["78297.50000000","0.08838000"],["78228.01000000","0.00180000"],["78149.42000000","0.00072000"],["77130.75000000","0.00062000"],["70474.80000000","0.00384000"],["62644.27000000","0.00310000"]],"a":[["78306.78000000","0.06863000"],["78307.29000000","0.02163000"],["78307.42000000","0.01354000"],["78308.12000000","0.01600000"],["78308.13000000","1.34805000"]]}}
{"rx":1788854528759057395, "m":{"e":"depthUpdate","E":1788854528714,"s":"BTCUSDT","U":99829852077,"u":99829852088,"b":[["78305.33000000","0.42578000"],["78304.70000000","0.00000000"],["78249.50000000","0.00200000"],["78231.77000000","0.00200000"],["77130.75000000","0.00062000"],["70474.80000000","0.00400000"]],"a":[["78477.27000000","0.01563000"],["78778.52000000","0.00000000"],["79252.87000000","0.01258000"],["79371.75000000","0.01441000"]]}}
{"rx":1788854528881056126, "m":{"e":"depthUpdate","E":1788854528814,"s":"BTCUSDT","U":99829852089,"u":99829852121,"b":[["78305.33000000","0.42564000"],["78305.32000000","0.00097000"],["78303.48000000","0.00014000"],["78303.47000000","0.05588000"],["78302.99000000","0.00014000"],["78302.98000000","0.14661000"],["78300.01000000","0.00063000"],["78298.00000000","0.03014000"],["78297.50000000","0.08831000"],["77130.75000000","0.00070000"],["70474.80000000","0.00393000"],["70474.00000000","0.00020000"],["62644.27000000","0.00279000"]],"a":[["78305.34000000","4.94682000"],["78477.27000000","0.00000000"],["78506.46000000","0.00000000"],["78508.71000000","0.00000000"],["78598.14000000","0.01563000"],["78719.00000000","0.01563000"]]}}
{"rx":1788854528975515768, "m":{"e":"depthUpdate","E":1788854528914,"s":"BTCUSDT","U":99829852122,"u":99829852152,"b":[["78305.33000000","0.45354000"],["78303.47000000","0.05602000"],["78303.46000000","0.04014000"],["78302.98000000","0.14675000"],["78301.41000000","0.54311000"],["78298.21000000","0.00709000"],["78298.00000000","0.03000000"],["77130.75000000","0.00070000"],["70474.80000000","0.00409000"],["70474.00000000","0.00000000"]],"a":[["78308.00000000","0.06040000"],["78317.09000000","0.00000000"],["79490.81000000","0.01654000"]]}}
{"rx":1788854529078395013, "m":{"e":"depthUpdate","E":1788854529014,"s":"BTCUSDT","U":99829852153,"u":99829852169,"b":[["78305.33000000","0.45204000"],["77130.75000000","0.00070000"],["70474.80000000","0.00393000"],["62644.27000000","0.00248000"],["62644.00000000","0.00000000"]],"a":[["78308.00000000","0.06040000"],["78317.09000000","0.00007000"],["78423.88000000","0.00000000"],["78427.21000000","0.20702000"]]}}
{"rx":1788854529168399353, "m":{"e":"depthUpdate","E":1788854529114,"s":"BTCUSDT","U":99829852170,"u":99829852207,"b":[["78305.33000000","0.42023000"],["78305.32000000","0.00097000"],["78303.89000000","0.00014000"],["78303.88000000","0.05781000"],["78303.87000000","0.15190000"],["78303.48000000","0.00000000"],["78303.47000000","0.00028000"],["78302.99000000","0.00000000"],["78302.98000000","0.00014000"],["78230.25000000","2.01020000"],["78230.23000000","0.00007000"],["77130.75000000","0.00062000"],["70474.80000000","0.00384000"],["70474.79000000","0.00009000"],["62644.26000000","0.00020000"],["62644.00000000","0.00000000"]],"a":[]}}
{"rx":1788854529269767592, "m":{"e":"depthUpdate","E":1788854529214,"s":"BTCUSDT","U":99829852208,"u":99829852235,"b":[["78305.33000000","0.39247000"],["78303.88000000","0.01423000"],["78303.87000000","0.00014000"],["78303.47000000","0.00014000"],["78303.46000000","0.04648000"],["78302.98000000","0.00000000"],["78300.01000000","0.00070000"],["77130.75000000","0.00062000"],["62644.27000000","0.00217000"],["62644.26000000","0.00000000"]],"a":[["79610.05000000","0.01889000"]]}}
{"rx":1788854529414541669, "m":{"e":"depthUpdate","E":1788854529314,"s":"BTCUSDT","U":99829852236,"u":99829852258,"b":[["78305.33000000","0.39226000"],["78305.32000000","0.00090000"],["78303.88000000","0.01423000"],["78303.87000000","0.00000000"],["78303.46000000","0.04662000"],["78298.21000000","0.00723000"],["77130.75000000","0.00062000"],["70474.80000000","0.00384000"],["62644.00000000","0.00000000"]],"a":[["78305.34000000","4.94651000"]]}}
{"rx":1788854529475705368, "m":{"e":"depthUpdate","E":1788854529414,"s":"BTCUSDT","U":99829852259,"u":99829852264,"b":[["77130.75000000","0.00062000"],["70474.80000000","0.00400000"],["62644.27000000","0.00186000"]],"a":[["79479.93000000","0.00030000"]]}}
{"rx":1788854529566575253, "m":{"e":"depthUpdate","E":1788854529514,"s":"BTCUSDT","U":99829852265,"u":99829852292,"b":[["78305.33000000","0.39233000"],["78305.32000000","0.00097000"],["78303.88000000","0.01423000"],["78303.46000000","0.04014000"],["78302.71000000","0.00000000"],["78302.70000000","0.00000000"],["78300.01000000","0.00070000"],["77130.75000000","0.00062000"],["70474.80000000","0.00384000"],["70474.79000000","0.00000000"],["70474.00000000","0.00000000"],["62644.27000000","0.00310000"]],"a":[["78305.34000000","4.94616000"],["78308.00000000","0.06040000"]]}}
{"rx":1788854529709957778, "m":{"e":"depthUpdate","E":1788854529614,"s":"BTCUSDT","U":99829852293,"u":99829852320,"b":[["78305.33000000","0.52435000"],["78305.32000000","0.00090000"],["78294.43000000","0.00000000"],["78293.37000000","0.00400000"],["77130.75000000","0.00062000"],["70474.80000000","0.00400000"],["62644.27000000","0.00279000"],["62644.00000000","0.00000000"]],"a":[["78305.34000000","3.84241000"],["78308.10000000","0.16897000"],["78317.99000000","0.00000000"],["78324.12000000","0.63856000"],["78609.84000000","0.00000000"]]}}
{"rx":1788854529817766756, "m":{"e":"depthUpdate","E":1788854529714,"s":"BTCUSDT","U":99829852321,"u":99829852353,"b":[["78305.33000000","0.51021000"],["78293.67000000","0.00400000"],["78276.80000000","0.00400000"],["78271.98000000","0.00400000"],["78269.57000000","0.00400000"],["77130.75000000","0.00062000"],["70474.80000000","0.00384000"],["41213.30000000","0.00036000"]],"a":[["78305.34000000","3.88330000"],["78306.14000000","0.00151000"],["78308.00000000","0.06040000"],["78308.10000000","0.16911000"],["78308.11000000","0.37581000"],["79729.47000000","0.02164000"]]}}
{"rx":1788854529916380535, "m":{"e":"depthUpdate","E":1788854529814,"s":"BTCUSDT","U":99829852354,"u":99829852361,"b":[["78301.41000000","0.54811000"],["77130.75000000","0.00070000"],["70474.80000000","0.00384000"],["62644.27000000","0.00248000"]],"a":[["78308.00000000","0.06040000"],["150000.00000000","113.41916000"]]}}
{"rx":1788854530014229629, "m":{"e":"depthUpdate","E":1788854529914,"s":"BTCUSDT","U":99829852362,"u":99829852376,"b":[["78305.33000000","0.51028000"],["78305.32000000","0.00097000"],["78303.88000000","0.05275000"],["78302.13000000","0.00014000"],["78302.12000000","0.14156000"],["78300.01000000","0.00063000"],["78018.00000000","0.09120000"],["77130.75000000","0.00070000"],["70474.80000000","0.00400000"],["70474.00000000","0.00000000"]],"a":[]}}
{"rx":1788854530096309265, "m":{"e":"depthUpdate","E":1788854530014,"s":"BTCUSDT","U":99829852377,"u":99829852400,"b":[["78303.46000000","0.04014000"],["78302.12000000","0.14170000"],["78298.21000000","0.00709000"],["77292.28000000","0.00000000"],["77130.75000000","0.00070000"],["70474.80000000","0.00384000"],["70474.00000000","0.00010000"],["62644.27000000","0.00341000"]],"a":[["78317.09000000","0.00007000"],["78430.14000000","0.00000000"],["79849.07000000","0.02479000"],["82921.18000000","0.00000000"]]}}
{"rx":1788854530220747844, "m":{"e":"depthUpdate","E":1788854530114,"s":"BTCUSDT","U":99829852401,"u":99829852419,"b":[["78305.33000000","0.51188000"],["78235.10000000","0.45291000"],["78234.86000000","0.00000000"],["78212.17000000","0.00000000"],["78194.56000000","0.00107000"],["77990.34000000","0.00000000"],["77600.58000000","0.00000000"],["77130.75000000","0.00062000"],["70474.80000000","0.00400000"],["70474.00000000","0.00000000"]],"a":[["78305.34000000","3.88184000"],["78313.18000000","0.00000000"],["78314.25000000","0.00007000"],["78315.66000000","0.00007000"],["78508.70000000","0.00000000"]]}}
{"rx":1788854530329338659, "m":{"e":"depthUpdate","E":1788854530214,"s":"BTCUSDT","U":99829852420,"u":99829852459,"b":[["78305.33000000","0.51188000"],["78305.32000000","0.00097000"],["78302.92000000","0.00014000"],["78302.91000000","0.13599000"],["78302.13000000","0.00698000"],["78302.12000000","0.00014000"],["78230.25000000","1.96606000"],["78203.88000000","0.10877000"],["78202.55000000","0.20000000"],["78183.14000000","0.07104000"],["78180.97000000","0.00000000"],["77130.75000000","0.00062000"],["70474.80000000","0.00393000"],["70474.00000000","0.00000000"],["62644.27000000","0.00310000"],["62644.26000000","0.00000000"]],"a":[["78305.34000000","3.88266000"],["78313.18000000","0.00113000"],["78321.01000000","0.00113000"],["78328.84000000","0.00113000"],["78336.67000000","0.00113000"],["78381.59000000","0.20000000"],["78397.61000000","0.00000000"],["78508.49000000","0.00000000"]]}}
{"rx":1788854530396481049, "m":{"e":"depthUpdate","E":1788854530314,"s":"BTCUSDT","U":99829852460,"u":99829852485,"b":[["78305.33000000","0.52655000"],["78305.32000000","0.00104000"],["78303.46000000","0.04014000"],["78302.91000000","0.14113000"],["78302.13000000","0.00712000"],["78302.12000000","0.00000000"],["78301.41000000","0.54311000"],["78298.22000000","0.08228000"],["77130.75000000","0.00062000"],["70474.80000000","0.00393000"],["70474.00000000","0.00000000"]],"a":[["78508.79000000","0.00000000"]]}}
{"rx":1788854530501979139, "m":{"e":"depthUpdate","E":1788854530414,"s":"BTCUSDT","U":99829852486,"u":99829852497,"b":[["78303.88000000","0.01423000"],["78302.92000000","0.00000000"],["78302.91000000","0.00514000"],["78300.01000000","0.00070000"],["77130.75000000","0.00062000"],["70474.00000000","0.00000000"],["62644.27000000","0.00279000"]],"a":[["79479.93000000","0.00030000"]]}}
{"rx":1788854530574429191, "m":{"e":"depthUpdate","E":1788854530514,"s":"BTCUSDT","U":99829852498,"u":99829852594,"b":[["78305.33000000","0.03433000"],["78305.32000000","0.00097000"],["78303.89000000","0.00000000"],["78303.88000000","0.16570000"],["78302.13000000","0.00014000"],["78301.42000000","0.00000000"],["78301.41000000","0.00028000"],["78300.01000000","0.00077000"],["78299.90000000","0.00000000"],["78299.76000000","0.00007000"],["78298.22000000","0.00000000"],["78297.50000000","0.02946000"],["78297.49000000","0.20250000"],["78295.13000000","0.00000000"],["78294.61000000","0.00400000"],["78293.81000000","0.00014000"],["78293.80000000","0.13748000"],["78293.37000000","0.00000000"],["78292.33000000","0.00007000"],["78291.73000000","0.00400000"],["78291.10000000","0.00000000"],["78290.03000000","0.00000000"],["78290.02000000","0.00000000"],["78288.92000000","0.00638000"],["78283.27000000","0.00000000"],["78281.68000000","0.31938000"],["78281.23000000","0.00000000"],["78280.22000000","0.00000000"],["78279.64000000","0.00000000"],["78277.61000000","0.31938000"],["78276.71000000","0.00000000"],["78274.02000000","0.31938000"],["78272.53000000","0.00000000"],["78269.75000000","0.31938000"],["78262.61000000","0.63906000"],["78259.86000000","0.00007000"],["78235.10000000","0.40371000"],["78218.61000000","2.29869000"],["78159.61000000","0.20250000"],["77130.75000000","0.00062000"],["70474.80000000","0.00384000"],["70474.79000000","0.00009000"],["70474.00000000","0.00000000"],["41213.30000000","0.00000000"]],"a":[["78305.34000000","3.89837000"],["78305.35000000","0.05027000"],["78305.40000000","0.05000000"],["78306.14000000","0.00000000"],["78306.45000000","0.00000000"],["78307.14000000","0.43915000"],["78307.33000000","0.03057000"],["78307.73000000","0.00014000"],["78307.99000000","0.48316000"],["78308.09000000","0.00000000"],["78308.52000000","0.00000000"],["78319.83000000","0.00000000"],["78319.99000000","0.31938000"],["78325.99000000","0.00000000"],["78328.63000000","0.00000000"],["78334.67000000","1.26418000"],["78344.79000000","0.00000000"],["78392.40000000","2.68103000"],["78400.29000000","0.00000000"],["78404.00000000","0.03000000"],["78438.26000000","0.00000000"],["78508.36000000","0.00000000"]]}}
{"rx":1788854530730289596, "m":{"e":"depthUpdate","E":1788854530614,"s":"BTCUSDT","U":99829852595,"u":99829852768,"b":[["78305.33000000","0.02895000"],["78305.32000000","0.00076000"],["78303.89000000","0.00000000"],["78303.88000000","0.00014000"],["78302.91000000","0.00014000"],["78302.13000000","0.00000000"],["78301.41000000","0.00514000"],["78300.00000000","1.50955000"],["78299.95000000","0.00000000"],["78298.21000000","0.00723000"],["78298.00000000","0.03014000"],["78297.51000000","0.00014000"],["78297.50000000","0.07859000"],["78297.49000000","0.00000000"],["78296.82000000","0.00007000"],["78296.81000000","0.16056000"],["78295.77000000","0.00007000"],["78293.81000000","0.00000000"],["78293.80000000","0.11280000"],["78293.06000000","0.00000000"],["78292.33000000","0.00000000"],["78291.96000000","0.08235000"],["78291.73000000","0.00000000"],["78290.22000000","0.00000000"],["78289.76000000","0.00000000"],["78288.17000000","0.00800000"],["78281.36000000","0.79127000"],["78263.76000000","0.00000000"],["78255.87000000","0.00007000"],["78244.42000000","0.34517000"],["78216.21000000","0.00000000"],["78192.27000000","0.24376000"],["78143.67000000","0.00000000"],["78135.12000000","0.00000000"],["77130.75000000","0.00062000"],["70474.80000000","0.00400000"],["62644.27000000","0.00248000"]],"a":[["78305.34000000","4.21130000"],["78305.35000000","0.05041000"],["78305.40000000","0.05014000"],["78306.24000000","0.00000000"],["78306.78000000","0.06863000"],["78307.14000000","0.00014000"],["78307.29000000","0.02163000"],["78307.33000000","0.03071000"],["78307.42000000","0.01354000"],["78307.73000000","0.00000000"],["78307.85000000","0.02214000"],["78307.97000000","0.16897000"],["78307.98000000","0.37581000"],["78307.99000000","0.00000000"],["78308.00000000","0.06026000"],["78308.09000000","0.00000000"],["78308.10000000","0.00000000"],["78308.11000000","0.00000000"],["78312.95000000","0.00400000"],["78317.99000000","0.00000000"],["78319.12000000","0.37581000"],["78319.13000000","0.00000000"],["78322.26000000","0.00000000"],["78327.41000000","0.00400000"],["78327.61000000","0.00000000"],["78331.91000000","0.20422000"],["78332.94000000","0.37581000"],["78342.34000000","0.00000000"],["78344.28000000","0.00000000"],["78399.99000000","0.95355000"],["78427.21000000","0.10358000"],["78435.99000000","0.01833000"]]}}
{"rx":1788854530838653976, "m":{"e":"depthUpdate","E":1788854530714,"s":"BTCUSDT","U":99829852769,"u":99829852832,"b":[["78305.33000000","0.20118000"],["78305.32000000","0.00076000"],["78303.88000000","0.00000000"],["78303.47000000","0.00000000"],["78303.46000000","0.00014000"],["78302.91000000","0.00000000"],["78301.41000000","0.00028000"],["78301.40000000","0.50514000"],["78300.36000000","0.00000000"],["78299.96000000","0.00026000"],["78298.02000000","0.00014000"],["78298.01000000","0.14767000"],["78297.51000000","0.00014000"],["78297.50000000","0.10188000"],["78297.49000000","0.20250000"],["78296.82000000","0.00000000"],["78296.81000000","0.00000000"],["78293.81000000","0.00000000"],["78292.16000000","0.00400000"],["78192.27000000","0.00000000"],["77130.75000000","0.00062000"],["70474.80000000","0.00384000"]],"a":[["78306.78000000","0.06863000"],["78307.14000000","0.00000000"],["78307.85000000","0.02228000"],["78310.25000000","0.04000000"],["78422.28000000","0.07550000"]]}}
{"rx":1788854530900779830, "m":{"e":"depthUpdate","E":1788854530814,"s":"BTCUSDT","U":99829852833,"u":99829852876,"b":[["78305.33000000","0.20115000"],["78305.32000000","0.00083000"],["78303.46000000","0.00000000"],["78301.42000000","0.00014000"],["78301.41000000","0.66031000"],["78298.88000000","0.00014000"],["78298.87000000","0.15777000"],["78298.21000000","0.00723000"],["78298.02000000","0.00000000"],["78298.01000000","0.00046000"],["78297.51000000","0.00000000"],["78297.50000000","0.09115000"],["78269.00000000","0.00000000"],["78192.27000000","0.04344000"],["77130.75000000","0.00070000"],["70474.80000000","0.00400000"],["62644.27000000","0.00217000"]],"a":[["78305.34000000","4.20986000"],["78306.45000000","0.00143000"],["78422.28000000","0.10344000"],["78507.31000000","0.00000000"],["79968.85000000","0.02455000"]]}}
{"rx":1788854530985969443, "m":{"e":"depthUpdate","E":1788854530914,"s":"BTCUSDT","U":99829852877,"u":99829852898,"b":[["78305.33000000","0.20137000"],["78301.41000000","0.66045000"],["78300.00000000","1.50955000"],["78298.21000000","0.00709000"],["78298.01000000","0.00032000"],["78255.87000000","0.00000000"],["77292.28000000","0.00010000"],["77130.75000000","0.00070000"],["70474.80000000","0.00384000"]],"a":[["78305.34000000","4.21129000"],["78306.45000000","0.00000000"],["78318.59000000","0.00000000"]]}}
