{"rx":1788854531106713398, "m":{"e":"depthUpdate","E":1788854531014,"s":"BTCUSDT","U":99829852899,"u":99829852914,"b":[["78298.88000000","0.00000000"],["78298.87000000","0.00000000"],["78297.50000000","0.09122000"],["78292.33000000","0.00007000"],["77130.75000000","0.00070000"],["70474.80000000","0.00384000"],["62644.27000000","0.00310000"]],"a":[["78317.09000000","0.00007000"]]}}
{"rx":1788854531184363399, "m":{"e":"depthUpdate","E":1788854531114,"s":"BTCUSDT","U":99829852915,"u":99829852927,"b":[["78300.00000000","1.50955000"],["78295.04000000","0.02176000"],["78293.47000000","0.01292000"],["78276.01000000","0.00000000"],["78272.01000000","0.00024000"],["77600.58000000","0.00010000"],["77130.75000000","0.00062000"],["70474.80000000","0.00400000"],["62644.00000000","0.00200000"]],"a":[["78393.29000000","0.01513000"],["82921.18000000","0.00010000"]]}}
{"rx":1788854531254350899, "m":{"e":"depthUpdate","E":1788854531214,"s":"BTCUSDT","U":99829852928,"u":99829852970,"b":[["78305.33000000","0.20095000"],["78305.32000000","0.00076000"],["78298.21000000","0.00723000"],["78297.50000000","0.09136000"],["78297.49000000","0.20264000"],["78281.37000000","2.29869000"],["78246.70000000","0.25282000"],["78218.62000000","0.00000000"],["78218.61000000","0.00000000"],["78218.60000000","0.00000000"],["78085.16000000","0.00000000"],["77130.75000000","0.00062000"],["70474.80000000","0.00384000"],["70474.79000000","0.00000000"],["70474.00000000","0.00000000"],["62644.27000000","0.00279000"],["62644.26000000","0.00000000"],["62644.00000000","0.00000000"],["41213.30000000","0.00036000"]],"a":[["78305.34000000","4.20300000"],["78306.45000000","0.00142000"],["78306.59000000","0.00638000"],["78315.07000000","0.35387000"],["78319.99000000","0.00000000"],["78322.23000000","0.31938000"],["78507.72000000","0.00000000"]]}}
{"rx":1788854531377965923, "m":{"e":"depthUpdate","E":1788854531314,"s":"BTCUSDT","U":99829852971,"u":99829853008,"b":[["78305.33000000","0.20095000"],["78297.55000000","0.08042000"],["78297.54000000","0.00000000"],["78297.50000000","0.00028000"],["78297.49000000","0.20264000"],["78292.33000000","0.00007000"],["77130.75000000","0.00062000"],["70474.80000000","0.00400000"],["62644.00000000","0.00000000"]],"a":[["78305.34000000","4.20938000"],["78305.40000000","0.05014000"],["78306.45000000","0.00142000"],["78306.59000000","0.00014000"],["78307.85000000","0.02214000"],["78309.77000000","0.02000000"],["78317.78000000","0.00000000"]]}}
{"rx":1788854531448783911, "m":{"e":"depthUpdate","E":1788854531414,"s":"BTCUSDT","U":99829853009,"u":99829853033,"b":[["78300.56000000","0.04011000"],["78298.00000000","0.03014000"],["78297.55000000","0.08056000"],["78297.50000000","0.00014000"],["78264.00000000","0.73000000"],["77130.75000000","0.00062000"],["70474.80000000","0.00384000"],["62644.27000000","0.00248000"]],"a":[["78305.34000000","4.21081000"],["78305.40000000","0.05014000"],["78306.45000000","0.00000000"],["78306.59000000","0.00000000"],["78307.85000000","0.02228000"],["79479.93000000","0.00030000"]]}}
{"rx":1788854531571983365, "m":{"e":"depthUpdate","E":1788854531514,"s":"BTCUSDT","U":99829853034,"u":99829853059,"b":[["78305.33000000","0.20102000"],["78305.32000000","0.00083000"],["78300.85000000","0.00588000"],["78300.56000000","0.04025000"],["78297.49000000","0.20250000"],["77130.75000000","0.00062000"],["70474.80000000","0.00400000"]],"a":[["78305.34000000","4.21164000"],["78313.18000000","0.00197000"],["78321.01000000","0.00197000"],["78328.50000000","0.12766000"],["78328.84000000","0.00197000"],["78336.67000000","0.00197000"]]}}
{"rx":1788854531667769406, "m":{"e":"depthUpdate","E":1788854531614,"s":"BTCUSDT","U":99829853060,"u":99829853186,"b":[["78305.33000000","1.27504000"],["78304.43000000","0.00000000"],["78302.63000000","0.00000000"],["78301.73000000","0.00000000"],["78301.69000000","0.00400000"],["78301.42000000","0.00014000"],["78299.76000000","0.00014000"],["78298.97000000","0.12935000"],["78298.40000000","0.00638000"],["78297.93000000","0.08229000"],["78297.55000000","0.08056000"],["78297.50000000","0.00014000"],["78296.42000000","0.00000000"],["78295.77000000","0.00014000"],["78294.22000000","0.00400000"],["78293.59000000","0.00400000"],["78292.33000000","0.00000000"],["78292.16000000","0.00000000"],["78291.96000000","0.00007000"],["78289.93000000","0.30953000"],["78288.92000000","0.00000000"],["78288.17000000","0.00000000"],["78287.34000000","0.37581000"],["78287.31000000","0.31938000"],["78283.81000000","0.31938000"],["78281.68000000","0.00000000"],["78279.82000000","0.31938000"],["78277.61000000","0.00000000"],["78274.02000000","0.00000000"],["78259.86000000","0.00000000"],["78145.89000000","0.00330000"],["78114.33000000","0.00000000"],["77130.75000000","0.00062000"],["70474.80000000","0.00384000"],["62644.27000000","0.00217000"],["62644.00000000","0.00200000"]],"a":[["78305.34000000","2.36337000"],["78305.39000000","0.00014000"],["78307.02000000","0.00000000"],["78307.33000000","0.00014000"],["78307.96000000","2.43922000"],["78307.97000000","0.00000000"],["78307.98000000","0.00000000"],["78308.00000000","0.06000000"],["78308.12000000","2.31069000"],["78308.14000000","0.00000000"],["78308.16000000","0.00000000"],["78309.77000000","0.00000000"],["78310.59000000","0.37581000"],["78311.53000000","0.00400000"],["78312.88000000","0.02000000"],["78315.07000000","0.00000000"],["78318.58000000","0.00000000"],["78322.23000000","0.30000000"],["78324.31000000","0.00000000"],["78326.00000000","0.03000000"],["78328.59000000","0.00000000"],["78331.91000000","0.10553000"],["78332.74000000","0.00000000"],["78333.86000000","0.00000000"],["78334.67000000","0.00000000"],["78355.69000000","0.00000000"],["78356.48000000","0.22479000"],["78358.86000000","0.00000000"],["78433.93000000","0.00000000"],["78438.26000000","0.02892000"],["78452.26000000","0.00000000"],["78479.86000000","0.00000000"],["78507.81000000","0.00000000"],["78607.49000000","7.63511000"]]}}
{"rx":1788854531767639983, "m":{"e":"depthUpdate","E":1788854531714,"s":"BTCUSDT","U":99829853187,"u":99829853253,"b":[["78305.33000000","1.27585000"],["78305.32000000","0.00090000"],["78302.21000000","0.15897000"],["78301.69000000","0.00000000"],["78301.08000000","0.00014000"],["78301.07000000","0.00000000"],["78300.00000000","1.50955000"],["78298.97000000","0.00014000"],["78298.91000000","0.00400000"],["78298.76000000","0.00400000"],["78298.40000000","0.00652000"],["78298.00000000","0.03000000"],["78297.55000000","0.08042000"],["78294.61000000","0.00000000"],["77130.75000000","0.00062000"],["70474.80000000","0.00384000"],["62644.00000000","0.00000000"]],"a":[["78306.46000000","0.00000000"],["78307.29000000","0.02163000"],["78307.33000000","0.00000000"],["78307.73000000","0.00187000"],["78307.85000000","0.02228000"],["78307.95000000","1.50004000"],["78307.96000000","2.43936000"],["78308.13000000","0.00000000"],["78309.99000000","0.00149000"],["78310.24000000","0.00638000"],["78311.20000000","0.00638000"],["78319.11000000","0.16897000"],["78321.76000000","0.31936000"],["78321.99000000","0.00049000"],["78325.99000000","0.31936000"],["78329.67000000","0.31936000"],["78333.55000000","0.31936000"],["78355.99000000","0.00318000"],["78392.40000000","0.00000000"],["78433.99000000","0.00127000"]]}}
{"rx":1788854531871795383, "m":{"e":"depthUpdate","E":1788854531814,"s":"BTCUSDT","U":99829853254,"u":99829853314,"b":[["78305.33000000","1.29573000"],["78305.32000000","0.00097000"],["78303.14000000","0.00500000"],["78302.23000000","0.00014000"],["78302.22000000","0.04759000"],["78302.21000000","0.15911000"],["78301.42000000","0.00715000"],["78301.41000000","0.55864000"],["78301.40000000","0.50014000"],["78301.08000000","0.00000000"],["78300.00000000","1.50955000"],["78298.97000000","0.00000000"],["78298.91000000","0.00000000"],["78297.73000000","0.00400000"],["78297.50000000","0.00000000"],["78294.22000000","0.00000000"],["78293.59000000","0.00000000"],["78292.52000000","0.00400000"],["78291.91000000","0.00400000"],["78216.21000000","1.00211000"],["78116.76000000","4.44640000"],["77130.75000000","0.00070000"],["70474.80000000","0.00409000"],["62644.27000000","0.00186000"]],"a":[["78305.34000000","2.36301000"],["78307.85000000","0.02228000"],["78307.95000000","1.50018000"],["78307.96000000","2.43922000"],["78309.19000000","0.00400000"],["78328.38000000","0.50102000"],["78352.70000000","1.76956000"],["78352.71000000","0.97673000"],["78353.65000000","0.37581000"],["78481.40000000","4.42247000"]]}}
{"rx":1788854531946573013, "m":{"e":"depthUpdate","E":1788854531914,"s":"BTCUSDT","U":99829853315,"u":99829853374,"b":[["78305.33000000","1.29725000"],["78305.32000000","0.00097000"],["78303.14000000","0.00514000"],["78302.23000000","0.00000000"],["78302.22000000","0.00014000"],["78302.21000000","0.00014000"],["78301.42000000","0.00729000"],["78300.00000000","1.50941000"],["78298.76000000","0.00000000"],["78298.40000000","0.00000000"],["78298.21000000","0.00709000"],["78297.73000000","0.00000000"],["78297.50000000","0.00014000"],["78297.18000000","0.00400000"],["78296.44000000","0.00400000"],["78296.01000000","0.00638000"],["78287.31000000","0.00000000"],["78284.69000000","0.31937000"],["77130.75000000","0.00070000"],["70474.80000000","0.00393000"]],"a":[["78305.34000000","4.66170000"],["78307.73000000","0.00000000"],["78311.53000000","0.00000000"]]}}
{"rx":1788854532038390305, "m":{"e":"depthUpdate","E":1788854532014,"s":"BTCUSDT","U":99829853375,"u":99829853405,"b":[["78303.14000000","0.00514000"],["78302.22000000","0.00000000"],["78302.21000000","0.00000000"],["78300.00000000","1.50955000"],["78298.21000000","0.00723000"],["78283.81000000","0.00000000"],["78280.82000000","0.31937000"],["78279.82000000","0.00000000"],["78276.86000000","0.31937000"],["77130.75000000","0.00070000"],["70474.80000000","0.00409000"],["62644.27000000","0.00279000"],["41213.30000000","0.00000000"]],"a":[["78307.28000000","0.00145000"],["78307.90000000","0.00400000"],["78309.99000000","0.00000000"],["78317.09000000","0.00000000"],["78318.87000000","0.15312000"],["78422.28000000","0.00000000"],["78427.21000000","0.20702000"],["79043.65000000","0.00018000"]]}}
{"rx":1788854532139090119, "m":{"e":"depthUpdate","E":1788854532114,"s":"BTCUSDT","U":99829853406,"u":99829853422,"b":[["78305.33000000","1.29744000"],["78299.76000000","0.00007000"],["78299.18000000","0.00014000"],["78299.17000000","0.13168000"],["78267.76000000","0.00000000"],["78242.78000000","0.00000000"],["77130.75000000","0.00062000"],["70474.80000000","0.00393000"]],"a":[["78308.00000000","0.06000000"],["78317.09000000","0.00007000"],["78328.38000000","0.00000000"],["78352.71000000","0.00000000"],["78427.21000000","0.16735000"],["78427.22000000","0.00000000"]]}}
{"rx":1788854532237082010, "m":{"e":"depthUpdate","E":1788854532214,"s":"BTCUSDT","U":99829853423,"u":99829853453,"b":[["78300.20000000","0.12375000"],["78300.00000000","1.50955000"],["78299.17000000","0.00014000"],["78298.21000000","0.00709000"],["78281.38000000","1.57276000"],["78281.36000000","0.00000000"],["78269.55000000","0.84756000"],["78218.60000000","0.89245000"],["77913.81000000","0.00140000"],["77130.75000000","0.00062000"],["70474.80000000","0.00393000"],["62644.27000000","0.00248000"],["62644.26000000","0.00000000"]],"a":[["78307.94000000","0.16897000"],["78308.00000000","0.06000000"],["78319.11000000","0.00000000"],["78326.00000000","0.73000000"],["78329.66000000","0.23451000"],["78331.91000000","0.00000000"]]}}
{"rx":1788854532338174731, "m":{"e":"depthUpdate","E":1788854532314,"s":"BTCUSDT","U":99829853454,"u":99829853533,"b":[["78305.33000000","0.20504000"],["78305.32000000","0.00090000"],["78301.42000000","0.00014000"],["78301.41000000","0.00028000"],["78300.57000000","0.00014000"],["78300.56000000","0.04025000"],["78300.21000000","0.00000000"],["78300.20000000","0.00014000"],["78300.00000000","1.50955000"],["78299.18000000","0.00000000"],["78299.17000000","0.00000000"],["78297.93000000","0.00000000"],["78297.18000000","0.00000000"],["78296.44000000","0.00000000"],["78296.08000000","0.00000000"],["78296.01000000","0.00000000"],["78295.77000000","0.00007000"],["78295.34000000","0.00000000"],["78292.52000000","0.00000000"],["78292.33000000","0.00007000"],["78292.04000000","0.00638000"],["78291.91000000","0.00000000"],["78289.94000000","0.00000000"],["78284.69000000","0.00000000"],["78282.81000000","0.31937000"],["78259.86000000","0.00007000"],["77130.75000000","0.00062000"],["72040.91000000","0.00014000"],["70474.80000000","0.00409000"],["70474.00000000","0.00020000"]],"a":[["78305.34000000","4.66939000"],["78305.39000000","0.00000000"],["78307.28000000","0.00000000"],["78307.42000000","0.01380000"],["78307.85000000","0.02228000"],["78307.93000000","0.00400000"],["78307.94000000","0.16911000"],["78307.95000000","1.50004000"],["78307.96000000","2.43522000"],["78310.24000000","0.00000000"],["78380.12000000","0.01563000"],["78391.86000000","0.00722000"],["78407.83000000","0.00000000"],["78429.48000000","0.00000000"]]}}
{"rx":1788854532450450952, "m":{"e":"depthUpdate","E":1788854532414,"s":"BTCUSDT","U":99829853534,"u":99829853577,"b":[["78303.14000000","0.00514000"],["78301.42000000","0.00014000"],["78301.41000000","0.62685000"],["78300.57000000","0.00000000"],["78300.56000000","0.04025000"],["78300.20000000","0.00000000"],["78298.21000000","0.00723000"],["78298.00000000","0.03014000"],["78297.55000000","0.08056000"],["78294.62000000","0.00400000"],["78293.35000000","0.00400000"],["78288.74000000","0.00800000"],["78281.38000000","1.47095000"],["78267.00000000","0.70000000"],["78264.00000000","0.03000000"],["77130.75000000","0.00062000"],["70474.80000000","0.00393000"],["70474.00000000","0.00000000"],["62644.27000000","0.00217000"]],"a":[["78305.34000000","4.67339000"],["78309.19000000","0.00000000"],["78508.70000000","0.00000000"],["79479.93000000","0.00030000"]]}}
{"rx":1788854532550443128, "m":{"e":"depthUpdate","E":1788854532514,"s":"BTCUSDT","U":99829853578,"u":99829853602,"b":[["78303.14000000","0.00514000"],["78301.41000000","0.62699000"],["78297.55000000","0.08042000"],["78295.77000000","0.00014000"],["78270.11000000","0.52224000"],["78246.70000000","0.55667000"],["78245.79000000","1.05852000"],["77130.75000000","0.00062000"],["70474.80000000","0.00409000"],["62644.27000000","0.00341000"]],"a":[["78327.02000000","0.52061000"],["78351.35000000","1.04533000"],["78508.97000000","0.00000000"]]}}
{"rx":1788854532651049506, "m":{"e":"depthUpdate","E":1788854532614,"s":"BTCUSDT","U":99829853603,"u":99829853629,"b":[["78305.33000000","0.20496000"],["78301.41000000","0.62699000"],["78301.12000000","0.00672000"],["78297.55000000","0.12570000"],["78296.60000000","0.12845000"],["78280.82000000","0.00000000"],["78278.41000000","0.31938000"],["78276.86000000","0.00000000"],["78274.49000000","0.31938000"],["77130.75000000","0.00062000"],["70474.80000000","0.00393000"],["62644.27000000","0.00310000"],["62644.00000000","0.00000000"]],"a":[["78307.42000000","0.01354000"],["78317.00000000","0.31938000"],["78319.65000000","0.00000000"],["78321.76000000","0.00000000"],["78328.50000000","0.00000000"],["78380.41000000","0.07541000"],["78427.21000000","0.06391000"]]}}
{"rx":1788854532740421058, "m":{"e":"depthUpdate","E":1788854532715,"s":"BTCUSDT","U":99829853630,"u":99829853646,"b":[["78305.33000000","0.20503000"],["78305.32000000","0.00097000"],["78301.40000000","0.50014000"],["78301.12000000","0.00686000"],["78298.00000000","0.03000000"],["77130.75000000","0.00062000"],["70474.80000000","0.00409000"],["41213.30000000","0.00036000"]],"a":[["78308.00000000","0.06000000"],["78427.21000000","0.16735000"]]}}
{"rx":1788854532853347349, "m":{"e":"depthUpdate","E":1788854532814,"s":"BTCUSDT","U":99829853647,"u":99829853658,"b":[["78305.33000000","0.20510000"],["78297.67000000","0.16393000"],["78296.60000000","0.00000000"],["78292.33000000","0.00000000"],["77130.75000000","0.00070000"],["72040.91000000","0.00000000"],["70474.80000000","0.00393000"],["62644.27000000","0.00279000"]],"a":[["78305.34000000","4.67181000"],["78306.47000000","0.00142000"],["78317.00000000","0.00000000"],["78318.86000000","0.31938000"],["80091.00000000","0.00065000"]]}}
{"rx":1788854532953422991, "m":{"e":"depthUpdate","E":1788854532914,"s":"BTCUSDT","U":99829853659,"u":99829853677,"b":[["78305.33000000","0.20518000"],["78298.94000000","0.15360000"],["78297.68000000","0.00014000"],["78297.67000000","0.00000000"],["77130.75000000","0.00070000"],["70474.80000000","0.00384000"],["70474.79000000","0.00009000"]],"a":[["78305.34000000","4.66543000"],["78307.28000000","0.00638000"],["78310.25000000","0.00000000"],["78570.00000000","0.03050000"]]}}
{"rx":1788854533069428141, "m":{"e":"depthUpdate","E":1788854533014,"s":"BTCUSDT","U":99829853678,"u":99829853712,"b":[["78305.33000000","0.34209000"],["78303.14000000","0.00014000"],["78300.85000000","0.01088000"],["78300.00000000","1.50955000"],["78298.95000000","0.00014000"],["78298.94000000","0.15374000"],["78298.21000000","0.00709000"],["78297.68000000","0.00000000"],["77130.75000000","0.00070000"],["70474.80000000","0.00400000"],["62644.27000000","0.00248000"]],"a":[["78306.78000000","0.06863000"],["78307.28000000","0.00652000"],["78307.94000000","0.16897000"],["78308.00000000","0.06000000"],["78509.59000000","0.00000000"]]}}
{"rx":1788854533154237099, "m":{"e":"depthUpdate","E":1788854533114,"s":"BTCUSDT","U":99829853713,"u":99829853745,"b":[["78305.33000000","0.20853000"],["78305.32000000","0.00090000"],["78303.14000000","0.00000000"],["78301.27000000","0.16846000"],["78301.12000000","0.00021000"],["78300.32000000","0.00014000"],["78300.31000000","0.00000000"],["78298.95000000","0.00000000"],["78298.94000000","0.00014000"],["78298.21000000","0.00723000"],["77130.75000000","0.00062000"],["70474.80000000","0.00384000"]],"a":[["78317.09000000","0.00007000"],["78387.14000000","2.68103000"],["78500.00000000","2.29111000"]]}}
{"rx":1788854533243160580, "m":{"e":"depthUpdate","E":1788854533214,"s":"BTCUSDT","U":99829853746,"u":99829853788,"b":[["78305.33000000","0.20861000"],["78305.32000000","0.00090000"],["78301.40000000","0.50101000"],["78301.28000000","0.00014000"],["78301.27000000","0.16860000"],["78301.12000000","0.00007000"],["78300.32000000","0.00000000"],["78300.00000000","1.50955000"],["78298.94000000","0.00000000"],["78298.00000000","0.03014000"],["78269.75000000","1.61883000"],["78269.55000000","0.00000000"],["77130.75000000","0.00062000"],["70474.80000000","0.00400000"],["62644.27000000","0.00217000"],["62644.26000000","0.00020000"]],"a":[["78305.34000000","4.66686000"],["78306.47000000","0.00000000"],["78384.51000000","1.47515000"],["78509.35000000","0.00000000"],["78509.85000000","0.00000000"]]}}
{"rx":1788854533342239390, "m":{"e":"depthUpdate","E":1788854533314,"s":"BTCUSDT","U":99829853789,"u":99829853797,"b":[["77130.75000000","0.00062000"],["75500.00000000","26.71210000"],["70474.80000000","0.00384000"],["62644.26000000","0.00000000"],["62644.00000000","0.00000000"]],"a":[["78509.83000000","0.00000000"]]}}
{"rx":1788854533437236340, "m":{"e":"depthUpdate","E":1788854533414,"s":"BTCUSDT","U":99829853798,"u":99829853814,"b":[["78301.28000000","0.00000000"],["78301.27000000","0.00014000"],["78127.06000000","0.00000000"],["77130.75000000","0.00062000"],["70474.80000000","0.00384000"],["62644.27000000","0.00186000"]],"a":[["78384.51000000","0.52148000"],["78387.14000000","0.00000000"],["78439.36000000","0.00000000"],["78487.77000000","0.01528000"],["78508.98000000","0.00000000"],["79479.93000000","0.00030000"]]}}
{"rx":1788854533537492000, "m":{"e":"depthUpdate","E":1788854533514,"s":"BTCUSDT","U":99829853815,"u":99829853843,"b":[["78305.33000000","0.20504000"],["78305.32000000","0.00083000"],["78301.40000000","0.50101000"],["78301.27000000","0.00000000"],["78297.55000000","0.12584000"],["78128.09000000","0.00000000"],["77130.75000000","0.00062000"],["70474.79000000","0.00000000"],["70474.00000000","0.00000000"],["62644.27000000","0.00310000"]],"a":[["78305.34000000","4.64132000"],["78509.71000000","0.00000000"],["78510.27000000","0.00000000"],["78510.38000000","0.00000000"]]}}
{"rx":1788854533643829585, "m":{"e":"depthUpdate","E":1788854533614,"s":"BTCUSDT","U":99829853844,"u":99829853864,"b":[["78305.33000000","0.20497000"],["78297.70000000","0.00014000"],["78297.69000000","0.14737000"],["78128.02000000","0.00000000"],["78127.92000000","0.00000000"],["77130.75000000","0.00062000"],["70474.80000000","0.00384000"],["62644.27000000","0.00279000"],["41213.30000000","0.00000000"]],"a":[["78328.39000000","0.12766000"],["78509.99000000","0.00000000"],["78510.00000000","0.03438000"],["78510.60000000","0.00000000"]]}}
{"rx":1788854533737498562, "m":{"e":"depthUpdate","E":1788854533714,"s":"BTCUSDT","U":99829853865,"u":99829853889,"b":[["78298.00000000","0.03014000"],["78297.71000000","0.00014000"],["78297.70000000","0.13532000"],["78297.69000000","0.14751000"],["78297.55000000","0.00000000"],["78297.50000000","0.00000000"],["78295.04000000","0.00000000"],["78293.47000000","0.00000000"],["77130.75000000","0.00062000"],["70474.80000000","0.00400000"],["62644.00000000","0.00000000"]],"a":[["78305.34000000","4.64770000"],["78307.28000000","0.00014000"],["78508.56000000","0.00000000"]]}}
{"rx":1788854533838085774, "m":{"e":"depthUpdate","E":1788854533814,"s":"BTCUSDT","U":99829853890,"u":99829853923,"b":[["78298.00000000","0.03014000"],["78297.71000000","0.00000000"],["78297.70000000","0.12583000"],["78297.69000000","0.14737000"],["78297.50000000","0.00007000"],["78297.49000000","0.20250000"],["78292.33000000","0.00007000"],["78126.42000000","0.00000000"],["77130.75000000","0.00070000"],["70474.80000000","0.00384000"],["62644.27000000","0.00248000"]],"a":[["78306.78000000","0.06863000"],["78307.28000000","0.00000000"],["78307.94000000","0.16911000"],["78508.71000000","0.00000000"]]}}
{"rx":1788854533938090132, "m":{"e":"depthUpdate","E":1788854533914,"s":"BTCUSDT","U":99829853924,"u":99829853959,"b":[["78305.33000000","0.03254000"],["78301.41000000","0.62699000"],["78300.85000000","0.01717000"],["78297.70000000","0.08732000"],["78297.69000000","0.00000000"],["78297.50000000","0.00014000"],["78297.49000000","0.20250000"],["78293.35000000","0.00000000"],["78292.38000000","0.00400000"],["78292.33000000","0.00014000"],["77130.75000000","0.00070000"],["70474.80000000","0.00400000"]],"a":[["78305.34000000","4.65408000"],["78307.40000000","0.03057000"],["78307.88000000","0.00026000"],["78311.20000000","0.00000000"],["78328.39000000","0.00000000"],["78438.26000000","0.00000000"],["78509.00000000","0.00000000"]]}}
{"rx":1788854534039429546, "m":{"e":"depthUpdate","E":1788854534014,"s":"BTCUSDT","U":99829853960,"u":99829853988,"b":[["78305.33000000","0.20496000"],["78300.85000000","0.01217000"],["78300.56000000","0.04525000"],["78297.70000000","0.08732000"],["78292.33000000","0.00000000"],["77130.75000000","0.00070000"],["70474.80000000","0.00393000"],["62644.27000000","0.00341000"]],"a":[["78305.34000000","4.65382000"],["78307.29000000","0.02163000"],["78307.40000000","0.03071000"],["78307.94000000","0.16897000"],["78507.16000000","0.00000000"]]}}
{"rx":1788854534138318931, "m":{"e":"depthUpdate","E":1788854534114,"s":"BTCUSDT","U":99829853989,"u":99829854012,"b":[["78305.33000000","0.39793000"],["78300.05000000","0.00014000"],["78300.04000000","0.15730000"],["77130.75000000","0.00062000"],["70474.80000000","0.00393000"],["62644.00000000","0.00200000"]],"a":[["78305.34000000","4.65239000"],["78306.47000000","0.00142000"],["78307.88000000","0.00000000"],["78317.09000000","0.00007000"],["78507.02000000","0.00000000"],["78508.84000000","0.00000000"]]}}
{"rx":1788854534236901600, "m":{"e":"depthUpdate","E":1788854534214,"s":"BTCUSDT","U":99829854013,"u":99829854040,"b":[["78305.33000000","0.20511000"],["78305.32000000","0.00090000"],["78300.56000000","0.04525000"],["78300.04000000","0.15744000"],["78297.70000000","0.08718000"],["77130.75000000","0.00062000"],["70474.80000000","0.00409000"],["62644.27000000","0.00310000"],["62644.26000000","0.00020000"],["62644.00000000","0.00000000"],["41213.30000000","0.00036000"]],"a":[["78305.34000000","4.65382000"],["78306.47000000","0.00000000"],["78340.80000000","0.00400000"],["78340.87000000","0.00000000"],["78508.46000000","0.00000000"],["78508.93000000","0.00000000"]]}}
{"rx":1788854534340994973, "m":{"e":"depthUpdate","E":1788854534314,"s":"BTCUSDT","U":99829854041,"u":99829854050,"b":[["78258.72000000","0.00400000"],["78258.60000000","0.00000000"],["78066.66000000","0.02220000"],["77832.63000000","0.00014000"],["77130.75000000","0.00062000"],["70474.80000000","0.00393000"],["62644.26000000","0.00000000"]],"a":[]}}
{"rx":1788854534440211251, "m":{"e":"depthUpdate","E":1788854534414,"s":"BTCUSDT","U":99829854051,"u":99829854065,"b":[["78295.04000000","0.08229000"],["78142.37000000","0.00206000"],["77130.75000000","0.00062000"],["70474.80000000","0.00409000"],["62644.27000000","0.00279000"],["62644.00000000","0.00000000"]],"a":[["78449.19000000","0.00206000"],["79479.93000000","0.00030000"]]}}
{"rx":1788854534536982441, "m":{"e":"depthUpdate","E":1788854534514,"s":"BTCUSDT","U":99829854066,"u":99829854078,"b":[["78126.92000000","0.12779000"],["77130.75000000","0.00062000"],["70474.80000000","0.00384000"],["70474.79000000","0.00009000"],["70474.00000000","0.00000000"]],"a":[["78305.34000000","4.65311000"],["78384.51000000","1.47515000"],["78387.14000000","2.68103000"]]}}
{"rx":1788854534638074731, "m":{"e":"depthUpdate","E":1788854534614,"s":"BTCUSDT","U":99829854079,"u":99829854092,"b":[["78305.33000000","0.20504000"],["78301.41000000","0.00028000"],["78300.85000000","0.00588000"],["78300.04000000","0.00014000"],["77130.75000000","0.00062000"],["76672.94000000","0.00728000"],["70474.80000000","0.00400000"],["70474.00000000","0.00000000"],["62644.27000000","0.00248000"]],"a":[["78305.34000000","4.65300000"],["78328.40000000","0.12766000"]]}}
{"rx":1788854534745014185, "m":{"e":"depthUpdate","E":1788854534714,"s":"BTCUSDT","U":99829854093,"u":99829855424,"b":[["78305.33000000","0.00000000"],["78305.32000000","0.00000000"],["78305.31000000","0.00000000"],["78303.75000000","0.00000000"],["78301.42000000","0.00000000"],["78301.41000000","0.00000000"],["78301.40000000","0.00000000"],["78301.12000000","0.00000000"],["78300.85000000","0.00000000"],["78300.57000000","0.00000000"],["78300.56000000","0.00000000"],["78300.05000000","0.00000000"],["78300.04000000","0.00000000"],["78300.01000000","0.00000000"],["78300.00000000","0.00000000"],["78299.96000000","0.00000000"],["78299.76000000","0.00000000"],["78299.66000000","0.00000000"],["78299.63000000","0.00000000"],["78299.47000000","0.00000000"],["78299.46000000","0.00000000"],["78298.39000000","0.00000000"],["78298.21000000","0.00000000"],["78298.07000000","0.00000000"],["78298.01000000","0.00000000"],["78298.00000000","0.00000000"],["78297.70000000","0.00000000"],["78297.50000000","0.00000000"],["78297.49000000","0.00000000"],["78297.42000000","0.00000000"],["78297.10000000","0.00000000"],["78297.03000000","0.00000000"],["78296.96000000","0.00000000"],["78296.25000000","0.00000000"],["78296.00000000","0.00000000"],["78295.77000000","0.00000000"],["78295.71000000","0.00000000"],["78295.04000000","0.00000000"],["78295.02000000","0.00000000"],["78294.62000000","0.00000000"],["78294.53000000","0.00000000"],["78294.50000000","0.00000000"],["78294.21000000","0.00000000"],["78294.00000000","0.00000000"],["78293.80000000","0.00000000"],["78293.67000000","0.00000000"],["78293.58000000","0.00000000"],["78293.14000000","0.00000000"],["78292.51000000","0.00000000"],["78292.47000000","0.00000000"],["78292.38000000","0.00000000"],["78292.33000000","0.00000000"],["78292.32000000","2.33373000"],["78292.31000000","0.00063000"],["78292.20000000","0.00000000"],["78292.19000000","0.00000000"],["78292.15000000","0.00000000"],["78292.14000000","0.00000000"],["78292.04000000","0.00000000"],["78292.03000000","0.00000000"],["78292.01000000","0.00000000"],["78292.00000000","0.00000000"],["78291.96000000","0.00000000"],["78291.90000000","0.00000000"],["78291.85000000","0.00014000"],["78291.84000000","0.11895000"],["78291.83000000","0.37788000"],["78291.82000000","0.00000000"],["78291.78000000","0.00007000"],["78291.09000000","0.00000000"],["78290.66000000","0.00000000"],["78290.22000000","0.00000000"],["78290.21000000","0.00000000"],["78290.00000000","0.00000000"],["78289.96000000","0.00000000"],["78289.93000000","0.00000000"],["78289.80000000","0.01000000"],["78289.60000000","0.00000000"],["78289.50000000","0.02000000"],["78289.02000000","0.00000000"],["78289.01000000","0.04967000"],["78289.00000000","0.12000000"],["78288.91000000","0.00000000"],["78288.74000000","0.00000000"],["78288.73000000","0.00000000"],["78288.59000000","0.00000000"],["78288.28000000","0.00000000"],["78288.21000000","0.00000000"],["78288.16000000","0.00000000"],["78288.08000000","0.00000000"],["78288.00000000","0.00000000"],["78287.94000000","0.00000000"],["78287.79000000","0.00007000"],["78287.67000000","0.02132000"],["78287.34000000","0.00000000"],["78287.30000000","0.00000000"],["78287.21000000","0.00000000"],["78287.05000000","0.00000000"],["78287.04000000","0.00000000"],["78286.59000000","0.00000000"],["78286.41000000","0.00400000"],["78286.40000000","0.00000000"],["78286.38000000","0.31943000"],["78286.32000000","0.03057000"],["78286.30000000","0.00026000"],["78286.21000000","0.00000000"],["78286.03000000","0.00000000"],["78286.02000000","0.04411000"],["78286.01000000","0.13316000"],["78285.86000000","0.00000000"],["78285.72000000","0.00000000"],["78285.71000000","0.00000000"],["78285.66000000","0.00000000"],["78285.64000000","0.01311000"],["78285.62000000","0.00000000"],["78285.52000000","0.00000000"],["78285.33000000","2.73565000"],["78285.32000000","0.00000000"],["78284.68000000","0.00000000"],["78284.49000000","0.20250000"],["78284.34000000","0.00000000"],["78284.21000000","0.00000000"],["78284.04000000","0.00000000"],["78284.00000000","0.03008000"],["78283.80000000","0.00014000"],["78283.77000000","0.00574000"],["78283.75000000","0.00000000"],["78283.26000000","0.00000000"],["78282.82000000","0.00000000"],["78282.81000000","0.00000000"],["78282.70000000","0.00063000"],["78282.68000000","0.00000000"],["78282.55000000","0.00007000"],["78282.25000000","0.00000000"],["78282.04000000","0.00000000"],["78282.01000000","0.95438000"],["78281.39000000","2.73565000"],["78281.38000000","0.00000000"],["78281.37000000","0.00000000"],["78281.35000000","0.00000000"],["78280.82000000","0.00000000"],["78280.76000000","0.00000000"],["78280.60000000","0.00150000"],["78280.18000000","0.00000000"],["78279.81000000","0.00014000"],["78279.27000000","0.37581000"],["78279.26000000","0.00000000"],["78278.95000000","0.00000000"],["78278.41000000","0.00000000"],["78278.18000000","0.00000000"],["78278.01000000","0.04452000"],["78277.60000000","0.00000000"],["78277.41000000","0.00000000"],["78277.40000000","0.00000000"],["78276.85000000","0.00000000"],["78276.17000000","0.00008000"],["78276.15000000","0.31942000"],["78275.82000000","0.00014000"],["78275.01000000","0.00000000"],["78274.88000000","0.00000000"],["78274.49000000","0.00000000"],["78274.48000000","0.00000000"],["78274.04000000","0.15191000"],["78274.03000000","1.39755000"],["78274.02000000","4.14509000"],["78274.01000000","0.00000000"],["78273.31000000","0.00000000"],["78273.23000000","0.00000000"],["78272.93000000","0.00000000"],["78272.26000000","0.00008000"],["78271.15000000","0.31942000"],["78270.56000000","0.38339000"],["78270.36000000","0.00008000"],["78270.35000000","0.00000000"],["78270.11000000","0.00000000"],["78269.75000000","0.00000000"],["78269.74000000","0.00000000"],["78269.55000000","0.62815000"],["78269.29000000","0.00007000"],["78269.02000000","0.00000000"],["78268.83000000","0.00127000"],["78268.31000000","0.31942000"],["78267.00000000","0.00000000"],["78266.44000000","0.00000000"],["78266.13000000","0.00664000"],["78266.00000000","0.03000000"],["78264.92000000","0.00008000"],["78264.85000000","2.29869000"],["78264.84000000","0.00000000"],["78263.85000000","0.00014000"],["78263.09000000","0.31942000"],["78262.52000000","0.00518000"],["78262.45000000","1.08079000"],["78262.15000000","0.00000000"],["78261.91000000","0.00000000"],["78261.00000000","0.00008000"],["78259.86000000","0.00014000"],["78258.61000000","0.00000000"],["78258.18000000","0.00000000"],["78258.01000000","0.00000000"],["78256.44000000","0.00400000"],["78256.02000000","0.00018000"],["78256.00000000","0.66911000"],["78255.87000000","0.00014000"],["78255.50000000","0.00000000"],["78255.08000000","0.00000000"],["78254.70000000","0.00008000"],["78254.30000000","0.34513000"],["78254.16000000","0.00400000"],["78254.00000000","0.69084000"],["78253.99000000","0.00000000"],["78253.69000000","0.00000000"],["78253.17000000","0.00008000"],["78252.81000000","0.00667000"],["78252.44000000","0.00000000"],["78252.00000000","0.04000000"],["78251.88000000","0.00400000"],["78251.66000000","0.00000000"],["78250.78000000","0.00008000"],["78250.17000000","0.74108000"],["78249.60000000","0.00400000"],["78249.49000000","0.00000000"],["78249.17000000","0.00000000"],["78247.89000000","0.00000000"],["78247.38000000","0.00000000"],["78247.32000000","0.00000000"],["78246.87000000","0.00000000"],["78246.70000000","0.27601000"],["78246.00000000","0.03000000"],["78245.79000000","0.00000000"],["78242.79000000","0.84067000"],["78242.71000000","0.00000000"],["78240.80000000","0.00000000"],["78239.45000000","0.34519000"],["78237.04000000","0.00424000"],["78235.79000000","0.36776000"],["78235.74000000","0.00000000"],["78235.23000000","0.34521000"],["78231.36000000","0.01154000"],["78231.18000000","0.00000000"],["78230.97000000","0.00000000"],["78230.84000000","0.00000000"],["78230.22000000","0.00000000"],["78229.35000000","0.00008000"],["78228.02000000","0.00345000"],["78228.01000000","0.00000000"],["78227.36000000","0.40319000"],["78226.94000000","0.00000000"],["78223.89000000","1.26597000"],["78221.26000000","0.00010000"],["78218.62000000","1.28043000"],["78218.61000000","2.29869000"],["78218.60000000","0.00000000"],["78216.61000000","0.00317000"],["78216.21000000","0.00000000"],["78215.25000000","0.00539000"],["78215.10000000","0.09798000"],["78214.98000000","0.01707000"],["78214.51000000","0.00180000"],["78213.54000000","0.00000000"],["78213.53000000","0.00000000"],["78213.42000000","0.00010000"],["78208.95000000","0.00000000"],["78208.43000000","0.59513000"],["78208.42000000","0.00000000"],["78208.41000000","0.00000000"],["78207.72000000","0.00008000"],["78204.79000000","0.00000000"],["78203.88000000","0.05627000"],["78203.47000000","0.00000000"],["78202.55000000","0.00000000"],["78198.21000000","0.00000000"],["78193.89000000","0.17082000"],["78192.27000000","0.20032000"],["78188.04000000","0.00000000"],["78188.03000000","0.00000000"],["78177.40000000","0.00000000"],["78166.04000000","0.20000000"],["78164.80000000","0.00008000"],["78162.23000000","0.00000000"],["78159.61000000","0.00000000"],["78151.42000000","0.00000000"],["78150.85000000","0.00000000"],["78149.43000000","0.00127000"],["78149.42000000","0.00000000"],["78148.64000000","0.00000000"],["78146.01000000","0.37581000"],["78142.37000000","0.00000000"],["78141.97000000","0.00000000"],["78141.10000000","0.00000000"],["78138.11000000","0.00127000"],["78137.13000000","0.00103000"],["78136.16000000","0.00072000"],["78135.77000000","0.00103000"],["78129.44000000","0.00008000"],["78126.92000000","0.00000000"],["78111.29000000","0.00000000"],["78098.83000000","3.84241000"],["78098.03000000","0.00000000"],["78090.09000000","0.00000000"],["78084.02000000","0.00000000"],["78073.34000000","0.00000000"],["78071.82000000","0.00220000"],["78070.33000000","0.00000000"],["78063.58000000","0.00007000"],["78061.21000000","0.29812000"],["78059.77000000","0.00220000"],["78051.15000000","0.00008000"],["78050.62000000","0.00220000"],["78031.48000000","0.00000000"],["78022.46000000","0.00011000"],["77992.03000000","0.00000000"],["77986.12000000","0.00000000"],["77975.38000000","0.00026000"],["77974.36000000","0.00028000"],["77972.87000000","0.00008000"],["77969.15000000","0.00009000"],["77967.55000000","0.00103000"],["77913.72000000","0.00000000"],["77894.58000000","0.00008000"],["77835.42000000","0.00000000"],["77816.29000000","0.00023000"],["77757.11000000","0.00000000"],["77738.01000000","0.00008000"],["77678.81000000","0.00000000"],["77659.72000000","0.00008000"],["77130.75000000","0.00000000"],["77117.94000000","0.00008000"],["70474.80000000","0.00000000"],["70474.79000000","0.00000000"]],"a":[["78291.10000000","0.00000000"],["78292.01000000","0.00000000"],["78292.33000000","0.28391000"],["78292.34000000","0.00041000"],["78292.35000000","0.05013000"],["78292.40000000","0.05000000"],["78292.71000000","0.00000000"],["78292.83000000","0.00000000"],["78293.15000000","0.00000000"],["78293.22000000","0.00000000"],["78293.81000000","0.00000000"],["78294.01000000","0.00000000"],["78294.12000000","0.00000000"],["78294.43000000","0.00000000"],["78294.86000000","0.00000000"],["78294.87000000","0.00151000"],["78295.02000000","0.00000000"],["78295.03000000","0.00000000"],["78295.05000000","0.00000000"],["78295.34000000","0.00000000"],["78295.38000000","0.00014000"],["78295.39000000","0.06828000"],["78295.73000000","0.00000000"],["78295.76000000","0.00000000"],["78295.77000000","0.00014000"],["78295.79000000","0.00000000"],["78295.92000000","0.00000000"],["78296.01000000","0.00000000"],["78296.66000000","0.00000000"],["78296.82000000","0.00000000"],["78296.83000000","0.48324000"],["78297.01000000","0.00000000"],["78297.02000000","0.00000000"],["78297.03000000","0.00000000"],["78297.04000000","0.00000000"],["78297.19000000","0.02172000"],["78297.40000000","0.00000000"],["78297.47000000","0.44556000"],["78297.48000000","0.63143000"],["78297.49000000","2.10194000"],["78297.50000000","0.00000000"],["78297.52000000","0.00000000"],["78297.71000000","0.00000000"],["78297.72000000","0.00000000"],["78297.95000000","0.00013000"],["78298.00000000","0.00000000"],["78298.01000000","0.00000000"],["78298.22000000","0.00000000"],["78298.53000000","0.01333000"],["78298.57000000","0.00000000"],["78298.58000000","1.35299000"],["78298.59000000","0.00000000"],["78298.62000000","0.00000000"],["78298.93000000","0.00007000"],["78299.04000000","0.00000000"],["78299.26000000","0.00000000"],["78299.48000000","0.00000000"],["78299.52000000","0.00000000"],["78299.76000000","0.00414000"],["78300.01000000","0.00000000"],["78300.16000000","0.00008000"],["78300.42000000","0.00000000"],["78300.54000000","0.12771000"],["78300.57000000","0.00000000"],["78300.58000000","0.01286000"],["78300.86000000","0.00000000"],["78301.32000000","0.00000000"],["78301.33000000","0.00000000"],["78301.41000000","0.00000000"],["78301.50000000","0.00129000"],["78301.51000000","2.10194000"],["78302.02000000","0.00000000"],["78302.04000000","0.00400000"],["78302.06000000","0.00007000"],["78302.10000000","0.00000000"],["78302.11000000","0.00007000"],["78302.22000000","0.00000000"],["78302.64000000","0.00000000"],["78303.12000000","0.00000000"],["78303.44000000","0.00638000"],["78303.45000000","0.03000000"],["78303.62000000","0.02160000"],["78303.75000000","0.00014000"],["78303.77000000","0.00000000"],["78304.02000000","0.00000000"],["78304.07000000","0.00007000"],["78304.17000000","0.00007000"],["78304.22000000","0.09686000"],["78304.32000000","0.00400000"],["78304.50000000","0.01289000"],["78304.92000000","0.00000000"],["78305.18000000","0.00000000"],["78305.19000000","0.00007000"],["78305.32000000","0.00638000"],["78305.33000000","0.86574000"],["78305.34000000","2.57934000"],["78305.35000000","0.00014000"],["78305.36000000","0.00000000"],["78305.39000000","0.00400000"],["78305.40000000","0.00014000"],["78305.67000000","0.02000000"],["78306.18000000","0.10273000"],["78306.77000000","0.01200000"],["78306.78000000","0.00014000"],["78306.90000000","0.00008000"],["78307.22000000","0.00007000"],["78307.32000000","0.00026000"],["78307.40000000","0.00014000"],["78307.51000000","0.00010000"],["78307.85000000","0.02214000"],["78307.90000000","0.00000000"],["78307.93000000","0.00000000"],["78307.94000000","0.00000000"],["78307.95000000","0.90215000"],["78307.99000000","0.00008000"],["78308.12000000","0.00000000"],["78308.18000000","0.06961000"],["78308.25000000","0.00008000"],["78308.52000000","0.00000000"],["78309.93000000","0.00007000"],["78310.66000000","0.00000000"],["78310.98000000","0.00574000"],["78311.21000000","0.00000000"],["78311.34000000","0.00000000"],["78311.40000000","0.00000000"],["78311.90000000","0.00008000"],["78312.44000000","0.00000000"],["78312.60000000","0.00000000"],["78312.61000000","0.00000000"],["78312.88000000","0.00000000"],["78312.96000000","0.00000000"],["78313.17000000","0.00000000"],["78313.18000000","0.00203000"],["78313.26000000","0.12000000"],["78313.94000000","0.00000000"],["78314.25000000","0.00000000"],["78314.99000000","0.31942000"],["78315.12000000","0.16904000"],["78315.26000000","0.00000000"],["78315.57000000","0.00000000"],["78315.82000000","0.00008000"],["78315.90000000","0.00026000"],["78316.37000000","0.00000000"],["78316.42000000","0.00063000"],["78317.09000000","0.00000000"],["78317.45000000","0.00000000"],["78317.69000000","0.31938000"],["78317.71000000","0.00255000"],["78318.86000000","0.00000000"],["78319.17000000","0.00127000"],["78319.18000000","0.00000000"],["78319.25000000","0.00000000"],["78319.41000000","0.00000000"],["78319.53000000","0.00060000"],["78319.73000000","0.00008000"],["78321.00000000","0.00000000"],["78321.01000000","0.00203000"],["78321.39000000","0.31938000"],["78321.83000000","0.00000000"],["78321.88000000","0.31942000"],["78322.01000000","1.80561000"],["78322.10000000","0.66027000"],["78322.25000000","0.00000000"],["78322.89000000","0.00000000"],["78323.10000000","0.00000000"],["78323.16000000","0.00000000"],["78323.31000000","0.34482000"],["78323.37000000","0.34482000"],["78323.65000000","0.00008000"],["78324.01000000","2.63787000"],["78324.33000000","0.00000000"],["78324.92000000","0.00000000"],["78325.69000000","0.00000000"],["78325.99000000","0.00000000"],["78326.51000000","0.19419000"],["78326.82000000","0.00000000"],["78327.02000000","0.00000000"],["78327.56000000","0.00008000"],["78328.40000000","0.00000000"],["78328.83000000","0.00000000"],["78328.84000000","0.00203000"],["78329.66000000","0.13840000"],["78329.67000000","0.00000000"],["78329.68000000","0.00000000"],["78331.48000000","0.00008000"],["78331.68000000","0.00407000"],["78331.82000000","0.00000000"],["78331.92000000","0.00008000"],["78332.00000000","0.04000000"],["78332.97000000","2.46059000"],["78333.55000000","0.00000000"],["78333.62000000","0.00000000"],["78334.84000000","0.00000000"],["78334.96000000","0.00000000"],["78335.13000000","0.10000000"],["78335.41000000","0.77445000"],["78335.67000000","0.00000000"],["78336.66000000","0.00000000"],["78336.67000000","0.00203000"],["78337.05000000","0.00270000"],["78337.08000000","0.00000000"],["78338.65000000","0.00000000"],["78338.85000000","0.00010000"],["78339.41000000","0.00000000"],["78339.66000000","2.00664000"],["78339.92000000","0.00000000"],["78340.23000000","0.00000000"],["78340.56000000","0.00000000"],["78340.58000000","0.00000000"],["78340.80000000","0.00000000"],["78341.21000000","0.00007000"],["78341.42000000","0.00000000"],["78342.04000000","0.00000000"],["78342.83000000","0.00319000"],["78343.65000000","0.00000000"],["78345.00000000","0.00000000"],["78345.81000000","0.00319000"],["78345.82000000","0.00000000"],["78351.35000000","0.00000000"],["78352.61000000","0.00000000"],["78352.70000000","1.14305000"],["78353.25000000","0.00000000"],["78355.35000000","0.00000000"],["78355.99000000","0.00000000"],["78356.48000000","0.04850000"],["78356.49000000","0.00000000"],["78359.16000000","0.00000000"],["78359.99000000","0.00318000"],["78361.95000000","0.77418000"],["78367.27000000","0.00127000"],["78370.62000000","0.00008000"],["78373.19000000","0.00000000"],["78373.91000000","0.09371000"],["78375.45000000","0.96267000"],["78375.89000000","0.00000000"],["78375.90000000","0.00000000"],["78376.99000000","1.25837000"],["78377.23000000","3.82877000"],["78381.59000000","0.00000000"],["78389.26000000","0.00000000"],["78389.72000000","0.00000000"],["78390.56000000","0.00000000"],["78395.83000000","0.00000000"],["78398.89000000","0.00000000"],["78409.46000000","0.00000000"],["78411.19000000","0.00000000"],["78411.20000000","0.00000000"],["78411.84000000","0.02327000"],["78415.14000000","0.19186000"],["78415.15000000","0.37581000"],["78423.99000000","0.00127000"],["78427.21000000","0.50203000"],["78429.11000000","1.53320000"],["78437.98000000","0.00127000"],["78437.99000000","0.00007000"],["78438.26000000","0.02892000"],["78442.12000000","0.00103000"],["78443.55000000","0.00103000"],["78448.38000000","0.00000000"],["78448.91000000","0.00008000"],["78449.19000000","0.00000000"],["78450.00000000","0.03011000"],["78450.03000000","0.03057000"],["78451.50000000","0.00000000"],["78453.32000000","0.00180000"],["78457.54000000","0.00022000"],["78464.31000000","0.00000000"],["78467.57000000","0.00000000"],["78468.46000000","0.00231000"],["78471.06000000","1.30829000"],["78471.99000000","3.82414000"],["78475.00000000","0.03049000"],["78480.00000000","0.05710000"],["78513.73000000","0.00000000"],["78517.67000000","0.00000000"],["78517.80000000","0.00000000"],["78527.21000000","0.00008000"],["78529.40000000","0.00000000"],["78529.75000000","0.00000000"],["78530.33000000","0.00255000"],["78533.53000000","0.00000000"],["78535.43000000","0.00000000"],["78565.96000000","0.00000000"],["78589.84000000","1.19998000"],["78605.50000000","0.00008000"],["78608.60000000","0.00000000"],["78624.19000000","0.00000000"],["78630.63000000","0.00000000"],["78668.13000000","0.54998000"],["78682.80000000","0.00014000"],["78683.79000000","0.00008000"],["78687.47000000","0.00000000"],["78702.50000000","0.00000000"],["78715.06000000","0.00000000"],["78733.80000000","0.00030000"],["78741.60000000","0.00000000"],["78762.08000000","0.00008000"],["78816.63000000","0.00000000"],["78840.38000000","0.00008000"],["78859.13000000","0.00000000"],["78918.67000000","0.00008000"],["78937.44000000","0.00000000"],["79069.85000000","0.00000000"],["79479.93000000","0.00000000"],["79499.99000000","0.00127000"]]}}
{"rx":1788854534837664310, "m":{"e":"depthUpdate","E":1788854534814,"s":"BTCUSDT","U":99829855425,"u":99829855616,"b":[["78292.32000000","2.81485000"],["78292.31000000","0.00014000"],["78291.85000000","0.00000000"],["78291.84000000","0.11895000"],["78291.83000000","0.37788000"],["78291.78000000","0.00014000"],["78291.18000000","0.03057000"],["78289.80000000","0.01014000"],["78289.50000000","0.02014000"],["78289.01000000","0.15491000"],["78289.00000000","0.12014000"],["78287.79000000","0.00014000"],["78287.67000000","0.02146000"],["78286.08000000","0.00400000"],["78286.01000000","0.93352000"],["78285.41000000","0.00356000"],["78284.15000000","0.00594000"],["78282.90000000","0.00712000"],["78282.04000000","1.66857000"],["78282.03000000","2.29907000"],["78282.01000000","0.00000000"],["78281.78000000","0.00000000"],["78281.65000000","0.00712000"],["78278.01000000","0.12685000"],["78270.28000000","0.32694000"],["78263.30000000","0.02474000"],["78259.40000000","0.03828000"],["78256.01000000","0.19992000"],["78253.00000000","0.01008000"],["78252.00000000","0.03000000"],["78249.60000000","0.00000000"],["78233.57000000","0.00430000"],["78233.34000000","0.00436000"],["78218.62000000","0.59460000"],["78218.61000000","0.00000000"],["78216.94000000","0.00112000"],["78198.82000000","0.79266000"],["78193.89000000","0.11245000"],["78192.27000000","0.00000000"],["78185.04000000","0.01835000"],["78185.03000000","0.05876000"],["78183.14000000","0.14999000"],["78182.18000000","0.24877000"],["78151.41000000","0.00000000"],["78140.41000000","0.00665000"],["78130.66000000","0.05619000"],["78059.67000000","0.00007000"],["78055.76000000","0.00113000"],["78051.85000000","0.00014000"],["78047.94000000","0.00007000"],["78044.03000000","0.00007000"],["78040.12000000","0.00007000"],["77117.94000000","0.00016000"],["75005.00000000","0.23887000"],["70463.09000000","0.00016000"],["62644.27000000","0.00217000"]],"a":[["78292.33000000","0.28314000"],["78292.35000000","0.05027000"],["78292.40000000","0.05014000"],["78295.39000000","0.06842000"],["78296.82000000","0.00000000"],["78296.83000000","0.00014000"],["78297.19000000","0.00014000"],["78297.47000000","0.00014000"],["78297.48000000","0.63157000"],["78297.49000000","2.10208000"],["78297.91000000","0.00000000"],["78298.53000000","0.00000000"],["78298.58000000","0.67105000"],["78301.50000000","0.00000000"],["78303.43000000","0.00137000"],["78303.97000000","0.00047000"],["78304.00000000","0.00048000"],["78305.24000000","0.31864000"],["78305.32000000","0.02238000"],["78305.33000000","0.86351000"],["78305.34000000","2.57920000"],["78305.35000000","0.00000000"],["78305.40000000","0.00000000"],["78306.37000000","0.00400000"],["78306.60000000","0.00000000"],["78306.77000000","0.00400000"],["78306.78000000","0.00000000"],["78307.29000000","0.02149000"],["78307.40000000","0.00000000"],["78307.42000000","0.01340000"],["78307.81000000","0.00007000"],["78307.85000000","0.00000000"],["78309.10000000","0.00000000"],["78311.89000000","0.00007000"],["78321.39000000","0.00000000"],["78321.92000000","0.00223000"],["78328.59000000","0.31939000"],["78335.35000000","0.00007000"],["78341.21000000","0.00000000"],["78343.00000000","0.00007000"],["78384.51000000","0.73456000"],["78386.02000000","0.20000000"],["78387.14000000","0.00000000"],["78425.96000000","0.00000000"],["78518.31000000","0.00000000"],["78521.31000000","0.00000000"],["78524.29000000","0.00000000"],["78526.89000000","0.00000000"],["78554.12000000","0.00026000"],["85986.00000000","0.00000000"]]}}
{"rx":1788854534938595818, "m":{"e":"depthUpdate","E":1788854534914,"s":"BTCUSDT","U":99829855617,"u":99829855708,"b":[["78292.32000000","2.50530000"],["78291.83000000","0.37780000"],["78290.64000000","0.00400000"],["78289.51000000","0.00638000"],["78288.36000000","0.00400000"],["78279.72000000","0.00000000"],["78268.83000000","0.00135000"],["78263.75000000","0.00012000"],["78262.52000000","0.00510000"],["78259.29000000","0.88552000"],["78257.09000000","0.02008000"],["78254.70000000","0.00000000"],["78254.16000000","0.00000000"],["78251.88000000","0.00000000"],["78250.78000000","0.00000000"],["78183.14000000","0.07104000"],["78182.18000000","0.00000000"],["78036.21000000","0.00172000"],["78032.30000000","0.00000000"],["77117.94000000","0.00024000"],["74390.06000000","0.00022000"],["70463.09000000","0.00032000"],["62634.00000000","0.00200000"]],"a":[["78292.33000000","0.31588000"],["78293.59000000","0.01960000"],["78294.08000000","0.00007000"],["78294.84000000","0.02352000"],["78294.87000000","0.00000000"],["78295.39000000","0.06842000"],["78296.09000000","0.02352000"],["78296.83000000","0.48284000"],["78297.19000000","0.00000000"],["78297.47000000","0.48284000"],["78297.48000000","0.62757000"],["78297.49000000","2.10208000"],["78298.58000000","0.67119000"],["78299.41000000","0.00026000"],["78300.54000000","0.12785000"],["78300.58000000","0.00014000"],["78302.73000000","0.00400000"],["78302.98000000","0.00151000"],["78304.11000000","0.00400000"],["78305.23000000","0.01600000"],["78305.32000000","0.00638000"],["78306.37000000","0.00000000"],["78306.62000000","0.00000000"],["78307.41000000","0.00000000"],["78307.99000000","0.00016000"],["78318.87000000","0.00000000"],["78323.31000000","0.00000000"],["78323.84000000","0.00000000"],["78332.75000000","0.00000000"],["78338.52000000","0.00400000"],["78343.46000000","0.34473000"],["78344.49000000","0.88456000"],["78355.39000000","0.00000000"],["78384.51000000","1.36707000"],["78386.47000000","2.21021000"],["78417.08000000","0.10344000"],["78545.88000000","0.00000000"],["78780.82000000","0.00000000"]]}}
{"rx":1788854535038329217, "m":{"e":"depthUpdate","E":1788854535014,"s":"BTCUSDT","U":99829855709,"u":99829855794,"b":[["78292.32000000","2.50130000"],["78291.18000000","0.03071000"],["78290.62000000","0.00400000"],["78289.80000000","0.01014000"],["78289.51000000","0.00000000"],["78288.37000000","0.00638000"],["78287.67000000","0.02132000"],["78286.39000000","0.15189000"],["78281.37000000","0.02000000"],["78281.19000000","0.02000000"],["78274.04000000","0.00000000"],["78272.01000000","0.00000000"],["78268.41000000","0.00024000"],["78262.99000000","0.52477000"],["78248.10000000","0.00008000"],["78238.98000000","1.55004000"],["78238.69000000","1.04932000"],["78227.01000000","0.02000000"],["78214.70000000","0.02000000"],["78182.18000000","0.04461000"],["78171.77000000","0.00000000"],["78075.15000000","0.00000000"],["78066.67000000","0.00802000"],["77117.94000000","0.00032000"],["77117.93000000","0.00030000"],["70463.00000000","0.00010000"],["62644.27000000","0.00186000"],["62634.00000000","0.00000000"],["62633.86000000","0.00124000"],["41213.30000000","0.00000000"]],"a":[["78292.40000000","0.05014000"],["78293.59000000","0.01974000"],["78294.84000000","0.02366000"],["78295.39000000","0.06842000"],["78296.09000000","0.02366000"],["78296.83000000","0.48298000"],["78297.46000000","0.00000000"],["78297.47000000","0.48298000"],["78297.48000000","0.62743000"],["78297.49000000","2.10194000"],["78298.58000000","0.67105000"],["78300.54000000","0.12771000"],["78300.58000000","0.00000000"],["78305.22000000","0.01600000"],["78305.23000000","0.00000000"],["78309.25000000","0.23583000"],["78311.80000000","0.00008000"],["78324.34000000","0.51595000"],["78339.40000000","0.00012000"],["78348.66000000","1.00681000"],["78355.90000000","0.00000000"],["78418.71000000","0.00000000"],["78420.52000000","0.00000000"]]}}
{"rx":1788854535137290677, "m":{"e":"depthUpdate","E":1788854535114,"s":"BTCUSDT","U":99829855795,"u":99829855843,"b":[["78289.80000000","0.01014000"],["78289.00000000","0.12014000"],["78155.95000000","0.00009000"],["78116.76000000","0.00000000"],["77600.58000000","0.00000000"],["70463.09000000","0.00048000"],["70463.00000000","0.00000000"],["62634.00000000","0.00000000"]],"a":[["78292.33000000","0.31799000"],["78295.77000000","0.00514000"],["78300.16000000","0.00219000"],["78301.59000000","0.00007000"],["78305.22000000","0.00000000"],["78305.23000000","0.01600000"],["78305.34000000","2.57706000"],["78307.99000000","0.00227000"],["78310.65000000","0.00408000"],["78313.18000000","0.00000000"],["78315.82000000","0.00219000"],["78320.05000000","0.00000000"],["78321.01000000","0.00000000"],["78323.65000000","0.00219000"],["78328.84000000","0.00000000"],["78336.67000000","0.00000000"],["78349.81000000","0.00408000"],["78359.22000000","0.00000000"],["78381.13000000","0.00408000"],["78389.40000000","0.00025000"],["78390.42000000","0.00000000"],["78399.56000000","0.00012000"],["78402.43000000","0.00000000"],["78404.66000000","0.00019000"],["78415.43000000","0.00000000"],["78425.48000000","0.00000000"],["78481.40000000","0.00000000"]]}}
{"rx":1788854535264371474, "m":{"e":"depthUpdate","E":1788854535214,"s":"BTCUSDT","U":99829855844,"u":99829855870,"b":[["78292.32000000","2.50170000"],["78292.17000000","0.00008000"],["78266.23000000","0.00000000"],["77117.94000000","0.00032000"],["70463.00000000","0.00000000"],["62644.27000000","0.00155000"],["62644.00000000","0.00000000"]],"a":[["78292.33000000","0.31814000"],["78295.39000000","0.06842000"],["78295.77000000","0.00528000"],["78296.83000000","0.00014000"],["78297.47000000","0.00000000"],["78306.00000000","0.00500000"],["78308.00000000","0.05500000"],["78313.17000000","0.09074000"],["78409.61000000","0.00031000"]]}}
{"rx":1788854535357906780, "m":{"e":"depthUpdate","E":1788854535314,"s":"BTCUSDT","U":99829855871,"u":99829855903,"b":[["78247.97000000","0.63918000"],["78215.57000000","0.50442000"],["78215.56000000","1.26610000"],["78215.10000000","0.00000000"],["78180.04000000","0.00000000"],["78110.22000000","4.43457000"],["78091.63000000","3.84277000"],["78071.28000000","0.00802000"],["78066.67000000","0.00000000"],["77117.94000000","0.00032000"],["70463.09000000","0.00064000"],["70463.00000000","0.00000000"],["62644.00000000","0.00000000"],["62633.86000000","0.00124000"]],"a":[["78296.09000000","0.02366000"],["78296.83000000","0.00000000"],["78297.48000000","0.62757000"],["78297.89000000","0.02128000"],["78299.44000000","0.01310000"],["78303.36000000","0.01341000"],["78335.04000000","1.26417000"],["78352.12000000","0.03000000"],["78475.64000000","4.48488000"]]}}
{"rx":1788854535447459160, "m":{"e":"depthUpdate","E":1788854535414,"s":"BTCUSDT","U":99829855904,"u":99829855918,"b":[["78288.53000000","0.01324000"],["77117.94000000","0.00032000"],["70463.09000000","0.00080000"],["70463.00000000","0.00000000"],["62644.27000000","0.00124000"]],"a":[["78296.83000000","0.44016000"],["78297.47000000","0.00000000"],["78306.00000000","0.01000000"],["78308.00000000","0.05000000"],["78353.75000000","0.03800000"],["78353.84000000","0.03200000"]]}}
{"rx":1788854535541226421, "m":{"e":"depthUpdate","E":1788854535514,"s":"BTCUSDT","U":99829855919,"u":99829856013,"b":[["78292.32000000","2.49861000"],["78292.31000000","0.00063000"],["78291.85000000","0.00014000"],["78291.84000000","0.11909000"],["78291.27000000","0.00400000"],["78291.19000000","0.00014000"],["78290.62000000","0.00000000"],["78289.58000000","0.00400000"],["78289.02000000","0.00014000"],["78289.01000000","0.15498000"],["78289.00000000","0.12014000"],["78288.53000000","0.00000000"],["78288.47000000","0.01316000"],["78288.37000000","0.00000000"],["78286.42000000","0.00638000"],["78282.03000000","0.00000000"],["78268.77000000","0.00408000"],["78266.01000000","1.75340000"],["78263.00000000","0.00000000"],["78229.63000000","0.00408000"],["78218.63000000","2.29907000"],["78214.70000000","0.00000000"],["78214.51000000","0.00000000"],["78198.32000000","0.00408000"],["78140.94000000","0.00017000"],["78136.16000000","0.00000000"],["77117.94000000","0.00032000"],["70463.00000000","0.00000000"]],"a":[["78292.33000000","1.54904000"],["78295.03000000","0.00000000"],["78295.93000000","0.00000000"],["78296.09000000","0.02366000"],["78296.83000000","0.00014000"],["78297.47000000","2.31507000"],["78297.48000000","0.62743000"],["78302.03000000","0.00638000"],["78305.23000000","0.00000000"],["78305.32000000","0.00000000"],["78308.99000000","0.00408000"],["78310.65000000","0.00000000"],["78349.81000000","0.00000000"],["78428.98000000","0.02000000"],["78486.51000000","0.00000000"],["79466.72000000","0.00030000"]]}}
{"rx":1788854535646690897, "m":{"e":"depthUpdate","E":1788854535614,"s":"BTCUSDT","U":99829856014,"u":99829856104,"b":[["78292.32000000","2.48600000"],["78292.31000000","0.00063000"],["78291.27000000","0.00000000"],["78291.19000000","0.00000000"],["78291.18000000","0.00014000"],["78290.38000000","0.00400000"],["78289.58000000","0.00000000"],["78289.01000000","0.15505000"],["78289.00000000","0.12014000"],["78288.56000000","0.00400000"],["78288.47000000","0.00014000"],["78287.67000000","0.03426000"],["78286.42000000","0.00000000"],["78286.39000000","0.15189000"],["78284.59000000","0.00638000"],["78282.04000000","0.99420000"],["78277.51000000","0.00000000"],["78238.73000000","0.01050000"],["78218.64000000","1.28088000"],["78218.62000000","0.00000000"],["78214.99000000","0.00180000"],["78136.16000000","0.00072000"],["77117.94000000","0.00032000"],["70463.09000000","0.00105000"],["62644.27000000","0.00093000"],["62634.00000000","0.00000000"]],"a":[["78292.33000000","0.61219000"],["78295.93000000","0.48284000"],["78296.08000000","0.00000000"],["78296.09000000","0.02366000"],["78296.83000000","0.00000000"],["78297.45000000","0.00000000"],["78297.46000000","1.31848000"],["78297.47000000","2.31521000"],["78297.48000000","0.00000000"],["78298.79000000","0.00400000"],["78300.15000000","0.00000000"],["78301.50000000","0.00133000"],["78302.73000000","0.00000000"],["78303.43000000","0.00000000"],["78308.34000000","0.12770000"],["78330.35000000","0.02516000"],["78339.16000000","0.10049000"],["78392.86000000","0.00000000"]]}}
{"rx":1788854535742509168, "m":{"e":"depthUpdate","E":1788854535714,"s":"BTCUSDT","U":99829856105,"u":99829856225,"b":[["78292.32000000","2.48593000"],["78291.83000000","0.37780000"],["78291.78000000","0.00007000"],["78291.18000000","0.00000000"],["78290.38000000","0.00000000"],["78289.00000000","0.12014000"],["78288.56000000","0.00000000"],["78288.47000000","0.00000000"],["78288.19000000","0.08230000"],["78287.67000000","0.00014000"],["78286.72000000","0.00400000"],["78286.40000000","0.00000000"],["78286.39000000","0.00021000"],["78286.30000000","0.00000000"],["78286.26000000","0.02158000"],["78286.02000000","0.00400000"],["78286.01000000","0.13316000"],["78285.64000000","0.00000000"],["78285.33000000","0.00000000"],["78284.59000000","0.00000000"],["78284.51000000","0.01297000"],["78284.02000000","0.00026000"],["78283.96000000","0.00400000"],["78282.91000000","0.00638000"],["78280.59000000","0.01292000"],["78276.67000000","0.01305000"],["78275.30000000","0.15191000"],["78272.75000000","0.01282000"],["78268.83000000","0.01444000"],["78268.41000000","0.00000000"],["78264.07000000","0.00024000"],["78137.89000000","1.53335000"],["77117.94000000","0.00032000"],["70463.00000000","0.00000000"],["41213.30000000","0.00036000"]],"a":[["78292.33000000","3.13726000"],["78293.16000000","0.00000000"],["78294.00000000","0.01000000"],["78294.73000000","0.00000000"],["78295.03000000","0.00000000"],["78295.39000000","0.07242000"],["78295.77000000","0.00528000"],["78295.93000000","0.00014000"],["78296.00000000","0.00500000"],["78296.09000000","0.02366000"],["78296.67000000","0.04011000"],["78297.45000000","0.01038000"],["78297.47000000","2.31507000"],["78297.89000000","0.00000000"],["78298.00000000","0.00500000"],["78298.78000000","0.00149000"],["78298.79000000","0.00000000"],["78299.44000000","0.00000000"],["78300.00000000","0.00500000"],["78301.11000000","0.00007000"],["78301.50000000","0.00000000"],["78302.00000000","0.00500000"],["78302.03000000","0.00000000"],["78303.36000000","0.00000000"],["78303.62000000","0.00000000"],["78304.00000000","0.00548000"],["78304.07000000","0.00007000"],["78304.50000000","0.00000000"],["78305.34000000","2.56427000"],["78305.39000000","0.00000000"],["78307.29000000","0.00000000"],["78307.42000000","0.00000000"],["78315.13000000","0.00000000"],["78315.99000000","0.12768000"],["78322.97000000","0.00000000"],["78330.81000000","0.00000000"],["78331.68000000","0.00400000"],["78336.72000000","0.00400000"],["78338.52000000","0.00000000"],["78348.15000000","0.00408000"],["78383.84000000","0.00007000"],["78392.85000000","0.03205000"],["78394.40000000","0.00000000"],["78428.98000000","0.00000000"],["78430.62000000","0.00000000"],["78479.79000000","0.02000000"]]}}
{"rx":1788854535841442716, "m":{"e":"depthUpdate","E":1788854535814,"s":"BTCUSDT","U":99829856226,"u":99829856303,"b":[["78292.32000000","2.16364000"],["78289.00000000","0.12014000"],["78288.20000000","0.00007000"],["78288.19000000","0.08244000"],["78287.67000000","0.00000000"],["78286.72000000","0.00000000"],["78286.42000000","0.00400000"],["78286.41000000","0.00000000"],["78286.39000000","0.00007000"],["78286.38000000","0.31957000"],["78286.26000000","0.00000000"],["78286.02000000","0.00000000"],["78284.51000000","0.00000000"],["78284.18000000","0.01280000"],["78282.19000000","0.02294000"],["78282.05000000","0.00800000"],["77292.28000000","0.00000000"],["77117.94000000","0.00040000"],["70463.09000000","0.00121000"],["62644.27000000","0.00062000"]],"a":[["78292.33000000","3.13726000"],["78293.59000000","0.01974000"],["78293.77000000","0.06878000"],["78294.00000000","0.02014000"],["78295.39000000","0.00414000"],["78295.77000000","0.00528000"],["78295.93000000","0.00000000"],["78296.00000000","0.01014000"],["78296.09000000","0.02352000"],["78297.44000000","0.00400000"],["78297.47000000","2.31107000"],["78297.83000000","0.00400000"],["78298.00000000","0.01000000"],["78300.00000000","0.01000000"],["78302.00000000","0.01000000"],["78304.00000000","0.01000000"],["78304.11000000","0.00000000"],["78307.94000000","0.16897000"],["78314.41000000","0.63864000"],["78315.12000000","0.00007000"],["78375.45000000","0.58550000"],["78375.46000000","0.00000000"],["78394.48000000","0.00000000"],["82921.18000000","0.00000000"]]}}
{"rx":1788854535943438731, "m":{"e":"depthUpdate","E":1788854535914,"s":"BTCUSDT","U":99829856304,"u":99829856358,"b":[["78292.32000000","2.16377000"],["78292.31000000","0.00076000"],["78292.30000000","0.00013000"],["78286.32000000","0.00000000"],["78268.77000000","0.00000000"],["78229.63000000","0.00000000"],["78198.32000000","0.00000000"],["78071.28000000","0.00000000"],["78066.67000000","0.00802000"],["77117.94000000","0.00040000"],["70463.09000000","0.00112000"],["70463.08000000","0.00009000"],["62634.00000000","0.00000000"]],"a":[["78292.33000000","3.13659000"],["78292.39000000","0.00014000"],["78293.59000000","0.01974000"],["78293.77000000","0.06892000"],["78294.84000000","0.02366000"],["78295.38000000","0.00000000"],["78295.39000000","0.00400000"],["78297.44000000","0.37981000"],["78303.97000000","0.00000000"],["78306.00000000","0.02000000"],["78308.00000000","0.04000000"],["78308.99000000","0.31941000"],["78314.99000000","0.00000000"],["78340.77000000","0.00000000"],["78348.15000000","0.00408000"],["78392.85000000","0.02310000"],["78469.83000000","0.00000000"]]}}
{"rx":1788854536041698725, "m":{"e":"depthUpdate","E":1788854536014,"s":"BTCUSDT","U":99829856359,"u":99829856381,"b":[["78286.38000000","0.31957000"],["78282.75000000","0.02098000"],["77117.94000000","0.00040000"],["77117.93000000","0.00030000"],["70463.09000000","0.00128000"],["62644.27000000","0.00031000"],["62633.86000000","0.00248000"]],"a":[["78297.43000000","0.16897000"],["78307.94000000","0.00000000"],["78308.62000000","0.03600000"],["78308.64000000","0.04400000"],["78309.44000000","0.03800000"],["78312.50000000","0.02600000"],["78313.48000000","0.03400000"],["78321.77000000","0.00000000"],["78327.61000000","0.32694000"]]}}
{"rx":1788854536138871768, "m":{"e":"depthUpdate","E":1788854536114,"s":"BTCUSDT","U":99829856382,"u":99829856533,"b":[["78292.32000000","1.31831000"],["78291.85000000","0.00000000"],["78291.84000000","0.00014000"],["78291.83000000","0.00014000"],["78290.64000000","0.00000000"],["78289.80000000","0.00014000"],["78289.51000000","0.00014000"],["78289.17000000","0.00014000"],["78289.16000000","0.02000000"],["78289.00000000","0.13014000"],["78288.20000000","0.00000000"],["78288.19000000","0.00014000"],["78287.79000000","0.00007000"],["78286.42000000","0.00000000"],["78286.39000000","0.00007000"],["78285.63000000","0.00000000"],["78285.61000000","0.00000000"],["78285.51000000","0.00000000"],["78285.46000000","0.00000000"],["78284.29000000","0.00400000"],["78284.19000000","0.00026000"],["78284.18000000","0.00000000"],["78284.06000000","0.00000000"],["78284.02000000","0.00000000"],["78283.96000000","0.00000000"],["78283.80000000","0.00007000"],["78283.72000000","0.00000000"],["78283.25000000","0.00000000"],["78282.91000000","0.00000000"],["78282.56000000","0.00400000"],["78282.47000000","0.00000000"],["78282.46000000","0.00000000"],["78282.05000000","0.00000000"],["78282.04000000","0.18337000"],["78282.02000000","0.00000000"],["78281.67000000","0.00000000"],["78281.62000000","0.00000000"],["78281.39000000","0.00000000"],["78280.82000000","0.00000000"],["78278.02000000","0.00638000"],["78278.01000000","0.08074000"],["78277.51000000","0.00000000"],["78276.15000000","0.00000000"],["78274.03000000","0.68433000"],["78274.02000000","1.84602000"],["78273.61000000","0.00000000"],["78271.16000000","0.31942000"],["78271.15000000","0.00000000"],["78268.31000000","0.00000000"],["78268.09000000","0.31942000"],["78266.13000000","0.00000000"],["78265.33000000","0.31942000"],["78258.01000000","0.03235000"],["78256.01000000","0.00000000"],["78256.00000000","0.03000000"],["78251.88000000","0.00007000"],["78248.94000000","0.00400000"],["78247.89000000","0.00000000"],["78235.10000000","0.08110000"],["78235.09000000","0.00076000"],["78222.36000000","0.59133000"],["78220.25000000","1.26602000"],["78208.45000000","1.28140000"],["78208.44000000","2.29907000"],["78208.43000000","0.00000000"],["78169.77000000","0.00000000"],["77979.05000000","7.69664000"],["77587.69000000","0.00010000"],["77117.94000000","0.00032000"],["70463.09000000","0.00144000"],["70463.08000000","0.00000000"]],"a":[["78292.33000000","3.66327000"],["78292.34000000","0.00027000"],["78292.39000000","0.00000000"],["78294.90000000","0.00400000"],["78295.39000000","0.00000000"],["78295.93000000","0.00000000"],["78296.08000000","0.00142000"],["78296.39000000","0.00638000"],["78296.40000000","0.00400000"],["78296.66000000","0.00638000"],["78296.83000000","0.00000000"],["78297.42000000","0.00000000"],["78297.44000000","0.00400000"],["78297.45000000","0.00400000"],["78297.83000000","0.00000000"],["78298.78000000","0.00000000"],["78301.50000000","0.37581000"],["78303.44000000","0.00000000"],["78308.52000000","0.00049000"],["78309.85000000","0.37581000"],["78310.59000000","0.00000000"],["78317.01000000","0.00000000"],["78317.80000000","0.00000000"],["78320.84000000","0.04000000"],["78321.99000000","0.00000000"],["78324.92000000","0.34481000"],["78331.08000000","0.00000000"],["78331.77000000","0.00000000"],["78334.41000000","0.00400000"],["78336.72000000","0.00000000"],["78343.98000000","0.00000000"]]}}
{"rx":1788854536237058824, "m":{"e":"depthUpdate","E":1788854536214,"s":"BTCUSDT","U":99829856534,"u":99829856610,"b":[["78292.32000000","1.31803000"],["78292.31000000","0.00062000"],["78291.84000000","0.00000000"],["78291.83000000","0.00000000"],["78289.80000000","0.00000000"],["78289.50000000","0.02014000"],["78289.16000000","0.02014000"],["78289.00000000","0.13014000"],["78288.19000000","0.00000000"],["78287.79000000","0.00014000"],["78286.01000000","0.13330000"],["78286.00000000","0.03014000"],["78284.49000000","0.20264000"],["78283.80000000","0.00014000"],["78282.70000000","0.00133000"],["78281.09000000","0.00096000"],["78278.41000000","0.00400000"],["78278.04000000","0.81009000"],["78278.03000000","2.41792000"],["78278.01000000","0.00000000"],["78275.03000000","0.02000000"],["78257.74000000","0.00663000"],["78251.20000000","0.00222000"],["78246.70000000","0.61552000"],["78246.53000000","1.26560000"],["78213.04000000","0.02000000"],["78138.34000000","0.09288000"],["78091.63000000","0.00000000"],["77117.94000000","0.00032000"],["62644.27000000","0.00000000"]],"a":[["78292.33000000","3.67026000"],["78295.77000000","0.00028000"],["78297.45000000","0.00800000"],["78305.34000000","2.56240000"],["78306.00000000","0.03000000"],["78308.00000000","0.03000000"],["78309.00000000","0.70400000"],["78309.42000000","0.02800000"],["78316.91000000","0.00012000"],["78316.95000000","0.00000000"],["78316.97000000","0.00193000"],["78334.41000000","0.00000000"],["78355.68000000","0.00537000"],["78369.99000000","0.00000000"],["78417.08000000","0.00000000"]]}}
{"rx":1788854536337511363, "m":{"e":"depthUpdate","E":1788854536314,"s":"BTCUSDT","U":99829856611,"u":99829856728,"b":[["78292.32000000","0.37833000"],["78292.31000000","0.00069000"],["78289.02000000","0.00014000"],["78289.01000000","0.17637000"],["78288.82000000","0.16346000"],["78287.79000000","0.00007000"],["78287.70000000","0.00014000"],["78287.69000000","0.00000000"],["78286.39000000","0.00000000"],["78284.29000000","0.00000000"],["78283.80000000","0.00007000"],["78282.56000000","0.00000000"],["78282.35000000","0.00400000"],["78281.59000000","0.00000000"],["78281.29000000","0.00400000"],["78279.81000000","0.00007000"],["78279.28000000","0.37581000"],["78279.27000000","0.00000000"],["78278.41000000","0.00000000"],["78278.06000000","0.77069000"],["78278.05000000","2.42192000"],["78278.04000000","0.00000000"],["78278.03000000","0.00000000"],["78275.82000000","0.00007000"],["78275.30000000","0.00000000"],["78272.65000000","0.02000000"],["78271.83000000","0.00007000"],["78270.56000000","0.00000000"],["78270.29000000","0.15192000"],["78267.84000000","0.00007000"],["78263.85000000","0.00007000"],["78263.09000000","0.00000000"],["78259.86000000","0.00007000"],["78258.73000000","0.31942000"],["78258.04000000","0.43403000"],["78258.03000000","0.63910000"],["78258.01000000","0.00000000"],["78256.00000000","0.73000000"],["78255.87000000","0.00007000"],["78251.88000000","0.00000000"],["78243.90000000","0.00007000"],["78240.32000000","0.00000000"],["78229.57000000","0.00408000"],["78215.57000000","0.00000000"],["78215.56000000","0.00000000"],["78215.10000000","0.11556000"],["78213.97000000","0.02000000"],["78208.47000000","1.28140000"],["78208.46000000","2.29907000"],["78208.45000000","0.00000000"],["78208.44000000","0.00000000"],["78198.84000000","1.52356000"],["78198.83000000","2.41792000"],["78198.82000000","0.00000000"],["78183.14000000","0.09838000"],["78181.68000000","0.03127000"],["78159.02000000","0.00000000"],["78137.13000000","0.00000000"],["78135.77000000","0.00000000"],["78094.78000000","3.84261000"],["77963.14000000","0.00000000"],["77117.94000000","0.00032000"],["70463.09000000","0.00160000"],["62633.86000000","0.00248000"]],"a":[["78294.00000000","0.04014000"],["78294.84000000","0.02366000"],["78295.77000000","0.00014000"],["78296.09000000","0.02366000"],["78296.40000000","0.00000000"],["78302.18000000","0.03057000"],["78308.52000000","0.00000000"],["78311.73000000","0.03021000"],["78312.75000000","0.00049000"],["78313.25000000","0.31942000"],["78317.74000000","0.00000000"],["78320.07000000","0.00000000"],["78321.88000000","0.00000000"],["78341.45000000","0.00000000"],["78411.92000000","0.10344000"],["78442.12000000","0.00000000"],["78443.55000000","0.00000000"],["78450.03000000","0.00000000"],["78480.00000000","0.05760000"],["78550.80000000","0.00000000"],["78746.68000000","0.00000000"]]}}
{"rx":1788854536438685386, "m":{"e":"depthUpdate","E":1788854536414,"s":"BTCUSDT","U":99829856729,"u":99829856821,"b":[["78292.32000000","0.18673000"],["78292.31000000","0.00069000"],["78289.17000000","0.00000000"],["78289.16000000","0.00014000"],["78289.04000000","0.00014000"],["78289.03000000","0.17916000"],["78289.02000000","0.00000000"],["78289.01000000","0.00028000"],["78289.00000000","0.13014000"],["78288.83000000","0.00000000"],["78288.82000000","0.00014000"],["78287.70000000","0.00000000"],["78286.46000000","0.02000000"],["78286.39000000","0.00014000"],["78286.02000000","0.00007000"],["78284.49000000","0.20250000"],["78283.80000000","0.00014000"],["78282.35000000","0.00000000"],["78281.84000000","0.00400000"],["78279.81000000","0.00014000"],["78275.82000000","0.00014000"],["78271.83000000","0.00014000"],["78271.01000000","0.04000000"],["78267.84000000","0.00014000"],["78263.85000000","0.00014000"],["78259.86000000","0.00014000"],["78258.04000000","0.22510000"],["78256.00000000","0.03000000"],["78255.87000000","0.00014000"],["78251.88000000","0.00007000"],["78247.89000000","0.00007000"],["78243.90000000","0.00014000"],["78222.24000000","0.02000000"],["78212.81000000","0.02000000"],["78203.06000000","1.00228000"],["77117.94000000","0.00032000"],["62633.86000000","0.00217000"]],"a":[["78292.33000000","3.97649000"],["78292.86000000","0.00136000"],["78292.87000000","0.00400000"],["78296.00000000","0.02014000"],["78296.08000000","0.00000000"],["78296.66000000","0.00000000"],["78298.00000000","0.02000000"],["78300.00000000","0.02000000"],["78302.00000000","0.02000000"],["78304.00000000","0.02000000"],["78313.26000000","0.15800000"],["78313.35000000","0.03200000"],["78331.96000000","0.00424000"],["78411.84000000","0.05117000"]]}}
{"rx":1788854536543557309, "m":{"e":"depthUpdate","E":1788854536514,"s":"BTCUSDT","U":99829856822,"u":99829856906,"b":[["78292.32000000","0.18618000"],["78292.31000000","0.00062000"],["78289.50000000","0.02014000"],["78289.16000000","0.00000000"],["78289.03000000","0.26411000"],["78289.01000000","0.00014000"],["78289.00000000","0.13014000"],["78288.82000000","0.00000000"],["78286.93000000","0.00014000"],["78286.92000000","0.48286000"],["78286.47000000","0.00000000"],["78286.46000000","0.02014000"],["78286.02000000","0.00000000"],["78284.49000000","0.20264000"],["78282.72000000","0.00048000"],["78274.89000000","0.02000000"],["78274.79000000","0.00000000"],["78274.42000000","0.00000000"],["78271.43000000","0.02000000"],["78265.33000000","0.00000000"],["78262.23000000","0.31943000"],["78261.46000000","0.00000000"],["78261.33000000","0.00060000"],["78261.00000000","0.00020000"],["78258.04000000","0.20934000"],["78223.86000000","0.00000000"],["78217.87000000","0.02000000"],["78213.04000000","0.00000000"],["78203.88000000","0.34823000"],["78198.26000000","0.00408000"],["78182.18000000","0.00000000"],["78177.21000000","0.03961000"],["78096.59000000","0.00012000"],["77117.94000000","0.00032000"],["70463.09000000","0.00176000"],["62633.86000000","0.00341000"]],"a":[["78292.33000000","3.97799000"],["78292.86000000","0.00000000"],["78309.38000000","0.03400000"],["78312.97000000","0.02800000"],["78321.64000000","0.03200000"],["78321.78000000","0.00000000"],["78329.89000000","0.00623000"],["78335.43000000","0.00431000"],["78340.04000000","0.00000000"],["78345.93000000","0.00000000"],["78354.10000000","0.00110000"],["78368.15000000","0.00000000"],["78377.00000000","0.00000000"],["78411.84000000","0.02327000"],["78411.92000000","0.00000000"],["78412.11000000","0.04107000"],["79466.72000000","0.00030000"],["85000.00000000","145.76537000"]]}}
{"rx":1788854536645419604, "m":{"e":"depthUpdate","E":1788854536614,"s":"BTCUSDT","U":99829856907,"u":99829857454,"b":[["78292.32000000","0.00000000"],["78292.31000000","0.00000000"],["78292.30000000","0.00000000"],["78292.17000000","0.00000000"],["78291.78000000","0.00000000"],["78291.50000000","0.00000000"],["78289.51000000","0.00000000"],["78289.50000000","0.17869000"],["78289.49000000","0.00063000"],["78289.03000000","0.00014000"],["78289.01000000","0.00000000"],["78289.00000000","0.00014000"],["78288.36000000","0.00000000"],["78286.93000000","0.00000000"],["78286.92000000","0.00014000"],["78286.47000000","0.00014000"],["78286.39000000","0.00000000"],["78286.38000000","0.00014000"],["78286.08000000","0.00000000"],["78286.02000000","0.00014000"],["78286.01000000","0.03399000"],["78285.99000000","0.00000000"],["78284.97000000","0.00000000"],["78284.96000000","0.00000000"],["78284.49000000","0.00014000"],["78284.19000000","0.00000000"],["78284.01000000","0.00007000"],["78284.00000000","0.03000000"],["78283.80000000","0.00007000"],["78282.72000000","0.00000000"],["78282.19000000","0.00188000"],["78282.04000000","0.13645000"],["78281.84000000","0.00000000"],["78281.68000000","0.20258000"],["78281.29000000","0.00000000"],["78280.60000000","0.00000000"],["78280.59000000","0.00000000"],["78279.81000000","0.00007000"],["78279.59000000","0.15000000"],["78279.28000000","0.00000000"],["78278.79000000","0.00000000"],["78278.07000000","0.00400000"],["78278.06000000","0.13304000"],["78278.05000000","0.00000000"],["78278.02000000","0.00000000"],["78277.83000000","0.00000000"],["78277.48000000","0.00000000"],["78276.67000000","0.00000000"],["78276.24000000","0.31947000"],["78275.87000000","0.00000000"],["78275.82000000","0.00007000"],["78275.79000000","0.01286000"],["78274.04000000","2.41792000"],["78274.03000000","0.05472000"],["78274.02000000","0.00000000"],["78273.10000000","0.00150000"],["78271.16000000","0.00000000"],["78271.14000000","0.00000000"],["78271.08000000","0.02000000"],["78270.29000000","0.00000000"],["78269.57000000","0.93443000"],["78269.56000000","2.79373000"],["78269.55000000","0.00000000"],["78269.54000000","0.00000000"],["78268.09000000","0.00000000"],["78264.86000000","4.71699000"],["78264.85000000","0.00000000"],["78264.77000000","0.00000000"],["78264.07000000","0.00000000"],["78263.30000000","0.00000000"],["78263.08000000","0.00000000"],["78262.23000000","0.00000000"],["78258.73000000","0.00000000"],["78258.04000000","0.19234000"],["78254.30000000","0.00000000"],["78253.77000000","0.00000000"],["78253.56000000","0.00400000"],["78253.00000000","0.00008000"],["78252.68000000","0.00000000"],["78251.88000000","0.00014000"],["78250.00000000","0.07904000"],["78246.70000000","0.27601000"],["78246.53000000","0.00000000"],["78244.32000000","0.00400000"],["78235.10000000","0.17379000"],["78231.73000000","0.34523000"],["78224.35000000","0.00007000"],["78222.37000000","0.02000000"],["78217.87000000","0.00000000"],["78215.10000000","0.47221000"],["78214.99000000","0.00000000"],["78214.52000000","1.26612000"],["78213.97000000","0.00000000"],["78203.88000000","0.05627000"],["78203.87000000","0.00000000"],["78203.06000000","0.00000000"],["78202.97000000","0.00000000"],["78198.85000000","0.00000000"],["78190.98000000","0.79168000"],["78188.65000000","2.41792000"],["78178.94000000","2.18414000"],["78178.93000000","2.41792000"],["78178.41000000","0.00000000"],["78166.45000000","0.00000000"],["78159.62000000","0.20250000"],["78155.00000000","1.00735000"],["78151.11000000","0.00000000"],["78136.16000000","0.00000000"],["78127.35000000","0.00206000"],["78025.44000000","0.01081000"],["77976.72000000","0.00000000"],["77117.94000000","0.00000000"],["77117.93000000","0.00000000"],["70463.09000000","0.00000000"],["70463.08000000","0.00009000"],["62633.86000000","0.00310000"],["41213.30000000","0.00000000"]],"a":[["78289.51000000","8.15046000"],["78289.52000000","5.32214000"],["78289.53000000","0.00013000"],["78290.42000000","0.00000000"],["78290.94000000","0.06887000"],["78291.32000000","0.00000000"],["78291.50000000","0.00000000"],["78291.51000000","0.65301000"],["78291.55000000","0.05000000"],["78291.60000000","0.05000000"],["78291.78000000","0.00014000"],["78291.79000000","0.00000000"],["78292.18000000","0.00000000"],["78292.31000000","0.00000000"],["78292.32000000","0.07500000"],["78292.33000000","0.57164000"],["78292.34000000","0.00000000"],["78292.35000000","0.00014000"],["78292.40000000","0.00014000"],["78292.87000000","0.00000000"],["78293.23000000","0.00000000"],["78293.30000000","0.00007000"],["78293.77000000","0.00014000"],["78294.07000000","0.00400000"],["78294.13000000","0.00000000"],["78294.63000000","0.00000000"],["78294.84000000","0.02352000"],["78294.94000000","0.00151000"],["78295.03000000","0.00000000"],["78295.14000000","0.00400000"],["78295.93000000","0.00000000"],["78296.00000000","0.02000000"],["78296.09000000","0.02352000"],["78296.39000000","0.00000000"],["78296.83000000","0.00000000"],["78297.11000000","0.00223000"],["78297.26000000","0.02000000"],["78297.34000000","0.00008000"],["78297.36000000","0.00000000"],["78297.42000000","0.00000000"],["78297.45000000","0.12400000"],["78299.29000000","0.00007000"],["78299.67000000","0.00010000"],["78300.16000000","0.00211000"],["78300.36000000","0.00008000"],["78301.99000000","0.31943000"],["78302.00000000","0.02008000"],["78302.98000000","0.00000000"],["78303.45000000","0.00000000"],["78305.67000000","0.00000000"],["78306.76000000","0.31943000"],["78308.18000000","0.06948000"],["78308.99000000","0.00000000"],["78313.16000000","0.03200000"],["78313.26000000","0.03800000"],["78314.99000000","0.31943000"],["78315.99000000","0.00000000"],["78317.69000000","0.00000000"],["78317.82000000","0.00000000"],["78321.40000000","0.00000000"],["78321.92000000","0.00000000"],["78322.23000000","0.00000000"],["78322.24000000","0.00000000"],["78325.72000000","1.46111000"],["78325.73000000","1.26432000"],["78326.50000000","0.00008000"],["78328.59000000","0.00000000"],["78331.68000000","0.00000000"],["78332.97000000","2.29930000"],["78335.04000000","0.00000000"],["78336.13000000","0.12547000"],["78339.16000000","0.00007000"],["78344.90000000","0.00000000"],["78349.89000000","2.29734000"],["78351.46000000","0.00000000"],["78361.95000000","0.00000000"],["78364.60000000","0.00000000"],["78366.19000000","0.94605000"],["78366.20000000","0.00000000"],["78367.17000000","0.00000000"],["78367.28000000","0.00000000"],["78368.33000000","0.61454000"],["78370.91000000","1.83845000"],["78383.84000000","0.00000000"],["78399.62000000","0.00000000"],["78407.27000000","0.39634000"],["78407.28000000","0.00000000"],["78433.54000000","0.00206000"],["78438.26000000","0.02892000"],["78456.47000000","0.00000000"],["78458.80000000","0.00000000"],["78499.95000000","0.00011000"],["78506.92000000","0.00000000"],["78506.93000000","0.00000000"],["78569.15000000","0.00000000"],["78612.67000000","0.00009000"],["78678.35000000","0.00000000"],["78682.80000000","0.00000000"],["78792.00000000","0.00000000"],["78808.78000000","0.00000000"],["79466.72000000","0.00000000"]]}}
{"rx":1788854536747671058, "m":{"e":"depthUpdate","E":1788854536714,"s":"BTCUSDT","U":99829857455,"u":99829858004,"b":[["78289.50000000","0.00000000"],["78289.49000000","0.00000000"],["78289.27000000","0.00000000"],["78289.04000000","0.00000000"],["78289.03000000","0.00000000"],["78289.00000000","0.00000000"],["78287.79000000","0.47016000"],["78287.78000000","0.00063000"],["78286.92000000","0.00000000"],["78286.46000000","0.02014000"],["78286.38000000","0.00000000"],["78286.01000000","0.02915000"],["78286.00000000","0.03014000"],["78285.41000000","0.00000000"],["78284.88000000","0.00026000"],["78284.49000000","0.00000000"],["78284.15000000","0.00014000"],["78284.11000000","0.00000000"],["78284.10000000","0.00000000"],["78284.01000000","0.00014000"],["78284.00000000","0.03014000"],["78283.77000000","0.00588000"],["78283.21000000","0.00000000"],["78283.20000000","0.00000000"],["78282.90000000","0.00014000"],["78282.76000000","0.00007000"],["78282.75000000","0.02112000"],["78282.55000000","0.00000000"],["78282.30000000","0.00000000"],["78282.07000000","0.00007000"],["78282.06000000","0.16325000"],["78282.05000000","0.00000000"],["78282.04000000","0.00000000"],["78281.65000000","0.00000000"],["78281.60000000","0.00400000"],["78279.81000000","0.00007000"],["78278.69000000","0.00047000"],["78278.52000000","0.00000000"],["78278.07000000","0.00000000"],["78277.17000000","0.00000000"],["78276.26000000","0.00000000"],["78276.17000000","0.00000000"],["78275.91000000","0.00400000"],["78275.83000000","0.00638000"],["78275.82000000","0.00014000"],["78274.05000000","0.78047000"],["78274.03000000","0.00000000"],["78272.26000000","0.00000000"],["78272.13000000","0.00008000"],["78270.25000000","0.02000000"],["78269.58000000","0.15192000"],["78269.24000000","0.09690000"],["78268.83000000","0.01436000"],["78268.22000000","0.00008000"],["78267.29000000","0.10278000"],["78265.78000000","0.31945000"],["78264.92000000","0.00000000"],["78264.30000000","0.00008000"],["78261.60000000","0.31945000"],["78261.59000000","0.00000000"],["78261.00000000","0.00012000"],["78260.39000000","0.00008000"],["78260.01000000","0.00024000"],["78258.04000000","0.29586000"],["78258.01000000","0.31945000"],["78257.09000000","0.02000000"],["78256.47000000","0.00008000"],["78254.04000000","0.31945000"],["78253.17000000","0.00000000"],["78252.56000000","0.00008000"],["78250.00000000","0.06904000"],["78248.65000000","0.00008000"],["78248.00000000","0.04000000"],["78240.79000000","0.00000000"],["78240.45000000","0.00335000"],["78239.91000000","0.00000000"],["78238.73000000","0.00389000"],["78235.10000000","0.39340000"],["78234.67000000","0.77544000"],["78230.24000000","2.30530000"],["78228.02000000","0.00026000"],["78227.73000000","0.00621000"],["78222.75000000","0.00316000"],["78222.37000000","0.00000000"],["78221.36000000","0.77558000"],["78216.61000000","0.00000000"],["78212.81000000","0.00000000"],["78212.02000000","0.00315000"],["78212.01000000","0.00180000"],["78211.96000000","0.02000000"],["78203.88000000","0.03373000"],["78194.75000000","0.00000000"],["78177.21000000","0.24377000"],["78172.13000000","0.04553000"],["78149.43000000","0.00000000"],["78143.33000000","0.00127000"],["78132.44000000","0.00072000"],["78036.21000000","0.00165000"],["77292.09000000","0.00010000"],["77115.16000000","0.00000000"],["70460.55000000","0.00000000"],["62644.00000000","0.00000000"]],"a":[["78287.80000000","7.92026000"],["78287.81000000","0.00027000"],["78287.82000000","0.00013000"],["78288.70000000","0.00000000"],["78289.00000000","0.00000000"],["78289.01000000","0.00014000"],["78289.04000000","0.00000000"],["78289.05000000","0.00000000"],["78289.23000000","0.06887000"],["78289.27000000","0.69934000"],["78289.28000000","1.88554000"],["78289.50000000","3.44952000"],["78289.51000000","3.32442000"],["78289.52000000","1.95074000"],["78289.53000000","0.00000000"],["78289.55000000","0.05000000"],["78289.60000000","0.05000000"],["78290.94000000","0.00014000"],["78291.38000000","0.00026000"],["78291.51000000","0.40433000"],["78291.55000000","0.00014000"],["78291.60000000","0.00014000"],["78291.77000000","0.00000000"],["78292.00000000","0.01000000"],["78292.32000000","0.07500000"],["78292.33000000","0.55974000"],["78292.35000000","0.00000000"],["78292.40000000","0.00000000"],["78293.59000000","0.00000000"],["78293.77000000","0.00000000"],["78294.00000000","0.05000000"],["78294.84000000","0.00000000"],["78294.90000000","0.00000000"],["78295.01000000","0.00007000"],["78295.15000000","0.03000000"],["78295.80000000","0.00007000"],["78296.00000000","0.03000000"],["78296.09000000","0.00000000"],["78296.25000000","0.00000000"],["78296.29000000","0.12771000"],["78298.00000000","0.03000000"],["78298.06000000","0.00007000"],["78299.47000000","0.09687000"],["78300.00000000","0.03000000"],["78300.16000000","0.00211000"],["78300.17000000","0.00000000"],["78301.43000000","0.10274000"],["78302.00000000","0.03008000"],["78303.46000000","0.00008000"],["78304.00000000","0.03000000"],["78304.07000000","0.00000000"],["78304.09000000","0.00000000"],["78304.22000000","0.00000000"],["78305.19000000","0.00000000"],["78306.18000000","0.00000000"],["78307.37000000","0.00008000"],["78307.99000000","0.00219000"],["78308.01000000","0.00000000"],["78311.29000000","0.00008000"],["78311.90000000","0.00000000"],["78312.37000000","0.04000000"],["78313.72000000","0.00255000"],["78315.20000000","0.00008000"],["78315.82000000","0.00211000"],["78317.71000000","0.00000000"],["78319.12000000","0.37589000"],["78319.23000000","0.00000000"],["78319.73000000","0.00000000"],["78320.84000000","0.00000000"],["78321.64000000","0.00000000"],["78322.01000000","1.50561000"],["78322.02000000","0.00000000"],["78323.03000000","0.00008000"],["78323.65000000","0.00211000"],["78324.00000000","0.06363000"],["78325.47000000","0.02531000"],["78326.94000000","0.00008000"],["78327.56000000","0.00000000"],["78327.59000000","0.01143000"],["78327.69000000","0.00000000"],["78327.70000000","0.00000000"],["78328.01000000","0.01522000"],["78329.00000000","0.01000000"],["78330.35000000","0.00000000"],["78331.00000000","0.00000000"],["78331.44000000","0.00426000"],["78331.48000000","0.00000000"],["78332.00000000","0.03000000"],["78333.18000000","0.37075000"],["78343.96000000","0.77436000"],["78344.49000000","0.00000000"],["78348.26000000","0.00000000"],["78350.18000000","0.01693000"],["78375.05000000","0.04568000"],["78383.61000000","0.00000000"],["78386.02000000","0.00000000"],["78391.99000000","0.02254000"],["78392.85000000","0.00000000"],["78393.83000000","0.00000000"],["78428.69000000","0.00000000"],["78495.99000000","0.00000000"],["78515.56000000","0.00000000"],["78517.29000000","0.11412000"],["78524.02000000","0.11527000"],["78573.96000000","0.00000000"],["78783.66000000","0.20962000"],["78843.15000000","0.00000000"],["78885.62000000","0.00000000"]]}}
{"rx":1788854536838090997, "m":{"e":"depthUpdate","E":1788854536814,"s":"BTCUSDT","U":99829858005,"u":99829858439,"b":[["78287.79000000","0.00000000"],["78287.78000000","0.18012000"],["78287.77000000","0.00063000"],["78286.02000000","0.00014000"],["78286.01000000","0.02901000"],["78286.00000000","0.03014000"],["78284.88000000","0.00000000"],["78284.15000000","0.00000000"],["78284.05000000","0.00026000"],["78283.77000000","0.00588000"],["78283.74000000","0.00000000"],["78282.90000000","0.00000000"],["78282.76000000","0.00014000"],["78282.75000000","0.00014000"],["78282.07000000","0.00000000"],["78282.06000000","0.00014000"],["78282.01000000","0.00000000"],["78282.00000000","0.03014000"],["78281.69000000","0.24586000"],["78281.60000000","0.00000000"],["78281.37000000","0.00000000"],["78281.19000000","0.00000000"],["78280.88000000","0.00356000"],["78279.81000000","0.00014000"],["78279.68000000","0.45501000"],["78279.62000000","0.00594000"],["78278.69000000","0.00000000"],["78278.62000000","0.00048000"],["78278.37000000","0.00713000"],["78277.37000000","0.00400000"],["78277.12000000","0.00713000"],["78276.96000000","0.00000000"],["78275.91000000","0.00000000"],["78275.83000000","0.00000000"],["78275.82000000","0.00014000"],["78275.79000000","0.00000000"],["78275.73000000","0.01285000"],["78275.39000000","0.00400000"],["78274.10000000","0.00000000"],["78274.07000000","0.77645000"],["78274.06000000","2.42192000"],["78274.05000000","0.00000000"],["78274.04000000","0.00000000"],["78271.83000000","0.00014000"],["78269.58000000","0.00000000"],["78269.57000000","1.31024000"],["78269.56000000","2.41792000"],["78269.48000000","0.00000000"],["78267.84000000","0.00014000"],["78264.86000000","2.41792000"],["78263.85000000","0.00014000"],["78263.00000000","2.29907000"],["78261.07000000","0.00000000"],["78259.86000000","0.00014000"],["78259.36000000","0.37581000"],["78259.29000000","0.00000000"],["78258.04000000","0.10352000"],["78258.03000000","0.00000000"],["78255.87000000","0.00014000"],["78255.23000000","0.00192000"],["78251.88000000","0.00014000"],["78246.70000000","0.42974000"],["78245.06000000","0.63920000"],["78240.45000000","0.00000000"],["78239.70000000","0.00400000"],["78230.25000000","1.35868000"],["78229.66000000","0.00000000"],["78227.49000000","0.02000000"],["78205.58000000","0.00017000"],["78198.85000000","0.00000000"],["78177.21000000","0.00000000"],["78175.94000000","0.13164000"],["78166.04000000","0.00000000"],["78161.52000000","0.06092000"],["78161.51000000","0.20000000"],["78137.90000000","0.37581000"],["78127.35000000","0.00000000"],["78123.99000000","0.00206000"],["78037.04000000","0.00007000"],["78033.13000000","0.00000000"],["77113.47000000","0.00008000"],["70459.01000000","0.00016000"],["62633.86000000","0.00279000"]],"a":[["78287.79000000","9.39023000"],["78287.80000000","3.63808000"],["78287.81000000","0.00013000"],["78287.82000000","0.00000000"],["78287.85000000","0.05000000"],["78289.01000000","0.00000000"],["78289.06000000","0.01960000"],["78289.22000000","0.01200000"],["78289.23000000","0.06901000"],["78289.27000000","0.00014000"],["78289.28000000","0.55408000"],["78289.50000000","0.07514000"],["78289.51000000","0.61744000"],["78289.52000000","1.95074000"],["78289.55000000","0.00014000"],["78289.59000000","0.04035000"],["78289.60000000","0.00000000"],["78290.31000000","0.02352000"],["78290.52000000","0.00400000"],["78290.94000000","0.00000000"],["78291.50000000","0.17812000"],["78291.51000000","0.40419000"],["78291.55000000","0.00000000"],["78291.56000000","0.02352000"],["78291.60000000","0.00000000"],["78292.33000000","0.05324000"],["78292.83000000","0.00400000"],["78293.38000000","0.00000000"],["78296.67000000","0.00000000"],["78297.44000000","0.00000000"],["78297.47000000","2.30307000"],["78299.54000000","0.00007000"],["78300.34000000","0.00063000"],["78305.00000000","0.63871000"],["78305.33000000","0.78851000"],["78309.30000000","0.04200000"],["78309.73000000","0.00255000"],["78313.72000000","0.00000000"],["78316.42000000","0.00000000"],["78325.17000000","0.00400000"],["78326.04000000","0.00000000"],["78326.51000000","0.10419000"],["78327.41000000","0.00000000"],["78328.80000000","0.00000000"],["78329.00000000","0.00000000"],["78352.92000000","0.00000000"],["78381.49000000","2.58905000"],["78411.84000000","0.04204000"],["78412.11000000","0.07285000"],["78430.46000000","0.00206000"],["78433.54000000","0.00000000"],["78438.26000000","0.02892000"],["78488.05000000","0.00012000"],["78521.99000000","0.00000000"],["78535.01000000","0.01884000"],["78535.22000000","0.01923000"],["78586.71000000","0.00000000"],["78586.75000000","0.00062000"]]}}
{"rx":1788854536941369750, "m":{"e":"depthUpdate","E":1788854536914,"s":"BTCUSDT","U":99829858440,"u":99829858536,"b":[["78287.78000000","0.34757000"],["78287.77000000","0.00063000"],["78283.98000000","0.00000000"],["78283.77000000","0.00588000"],["78282.76000000","0.00000000"],["78282.75000000","0.00000000"],["78282.06000000","0.00000000"],["78282.01000000","0.00007000"],["78282.00000000","0.03014000"],["78281.69000000","0.24600000"],["78281.68000000","0.20272000"],["78281.61000000","0.13958000"],["78279.68000000","0.00000000"],["78268.71000000","0.00408000"],["78193.35000000","0.00007000"],["77113.47000000","0.00016000"],["70463.08000000","0.00000000"],["70463.07000000","0.00009000"],["70459.00000000","0.00020000"]],"a":[["78287.79000000","9.39208000"],["78287.80000000","3.43558000"],["78287.85000000","0.05014000"],["78288.51000000","0.00400000"],["78289.06000000","0.01974000"],["78289.22000000","0.00014000"],["78289.23000000","0.06901000"],["78289.27000000","0.00000000"],["78289.28000000","0.30014000"],["78289.51000000","0.41494000"],["78289.52000000","1.95060000"],["78289.55000000","0.00000000"],["78292.33000000","0.05113000"],["78294.07000000","0.01600000"],["78295.62000000","0.00211000"],["78300.16000000","0.00000000"],["78303.45000000","0.00211000"],["78307.99000000","0.00008000"],["78311.28000000","0.00211000"],["78315.82000000","0.00000000"],["78319.11000000","0.00211000"],["78323.65000000","0.00000000"],["78327.00000000","0.01000000"],["78405.42000000","0.04298000"],["79390.54000000","0.00025000"],["82921.37000000","0.00010000"]]}}
{"rx":1788854537044999171, "m":{"e":"depthUpdate","E":1788854537014,"s":"BTCUSDT","U":99829858537,"u":99829858607,"b":[["78287.78000000","0.20792000"],["78287.77000000","0.00070000"],["78286.01000000","0.05860000"],["78284.13000000","0.00014000"],["78284.12000000","0.13172000"],["78283.22000000","0.00000000"],["78283.21000000","0.00000000"],["78282.01000000","0.00000000"],["78281.69000000","0.08211000"],["78281.68000000","0.20272000"],["78281.61000000","0.00000000"],["78274.08000000","0.15829000"],["78273.37000000","0.02000000"],["78273.18000000","0.02000000"],["78272.43000000","0.02000000"],["78269.43000000","0.02000000"],["78268.58000000","0.02000000"],["78251.43000000","0.88561000"],["78251.25000000","0.00400000"],["78239.70000000","0.00000000"],["78217.29000000","0.02000000"],["78214.70000000","0.02000000"],["78213.79000000","0.02000000"],["78212.75000000","0.02000000"],["78209.45000000","1.94287000"],["78209.44000000","2.21521000"],["78208.47000000","0.00000000"],["78207.40000000","0.02000000"],["78147.28000000","0.02001000"],["78138.10000000","0.00000000"],["78066.67000000","0.00000000"],["78050.05000000","0.00803000"],["78037.04000000","0.00000000"],["77900.86000000","0.00012000"],["77880.60000000","0.00018000"],["77113.47000000","0.00024000"],["77113.46000000","0.00030000"],["75235.87000000","0.00027000"],["70459.01000000","0.00032000"],["70459.00000000","0.00000000"],["62633.86000000","0.00248000"]],"a":[["78287.79000000","9.39162000"],["78289.06000000","0.01974000"],["78289.22000000","0.00000000"],["78289.52000000","1.95074000"],["78317.70000000","0.00000000"],["78336.75000000","0.88465000"],["78400.00000000","0.04288000"],["78403.84000000","0.00000000"],["78403.99000000","0.03341000"]]}}
{"rx":1788854537137892952, "m":{"e":"depthUpdate","E":1788854537114,"s":"BTCUSDT","U":99829858608,"u":99829858655,"b":[["78287.78000000","0.17995000"],["78287.77000000","0.00063000"],["78286.01000000","0.02901000"],["78286.00000000","0.03014000"],["78284.13000000","0.00000000"],["78284.12000000","0.00014000"],["78282.01000000","0.00007000"],["78281.69000000","0.12560000"],["78281.68000000","0.20258000"],["78279.50000000","0.08230000"],["78277.51000000","0.00000000"],["78275.39000000","0.00000000"],["78274.49000000","0.00400000"],["78274.09000000","0.00400000"],["78211.96000000","0.00000000"],["78209.45000000","1.89938000"],["78155.95000000","0.00000000"],["78151.41000000","0.00009000"],["62644.00000000","0.00200000"]],"a":[["78287.79000000","9.39150000"],["78287.80000000","3.74552000"],["78288.59000000","0.00007000"],["78293.30000000","0.00000000"],["78294.08000000","0.00000000"],["78297.47000000","2.29907000"],["78297.95000000","0.00000000"],["78384.86000000","0.00025000"],["78389.40000000","0.00000000"],["78395.01000000","0.00012000"],["78399.56000000","0.00000000"],["78404.66000000","0.00000000"],["78409.61000000","0.00000000"]]}}
{"rx":1788854537237273478, "m":{"e":"depthUpdate","E":1788854537214,"s":"BTCUSDT","U":99829858656,"u":99829858673,"b":[["78286.00000000","0.03014000"],["78284.12000000","0.00000000"],["78281.68000000","0.20272000"],["78273.28000000","0.01415000"],["77113.47000000","0.00032000"],["70459.01000000","0.00048000"],["62644.00000000","0.00000000"],["62633.86000000","0.00217000"]],"a":[["78294.06000000","0.00400000"],["78302.75000000","0.24747000"],["78400.11000000","0.00019000"],["78405.06000000","0.00031000"],["78683.78000000","0.00012000"]]}}
{"rx":1788854537350096144, "m":{"e":"depthUpdate","E":1788854537314,"s":"BTCUSDT","U":99829858674,"u":99829858690,"b":[["78287.78000000","0.18003000"],["78281.69000000","0.26243000"],["78279.68000000","0.43899000"],["78162.52000000","0.00068000"],["77113.47000000","0.00032000"],["70459.01000000","0.00064000"],["62630.22000000","0.00000000"]],"a":[["78287.79000000","9.39454000"],["78292.33000000","0.04613000"]]}}
{"rx":1788854537439658623, "m":{"e":"depthUpdate","E":1788854537414,"s":"BTCUSDT","U":99829858691,"u":99829858714,"b":[["78287.78000000","0.18003000"],["78228.27000000","0.00007000"],["78212.75000000","0.00000000"],["78059.85000000","0.00802000"],["78050.05000000","0.00000000"],["78040.12000000","0.00000000"],["77113.47000000","0.00032000"],["62633.86000000","0.00186000"]],"a":[["78287.79000000","9.39681000"],["78295.62000000","0.00226000"],["78303.45000000","0.00226000"],["78311.28000000","0.00226000"],["78319.11000000","0.00226000"],["78498.17000000","0.00000000"]]}}
{"rx":1788854537537400714, "m":{"e":"depthUpdate","E":1788854537514,"s":"BTCUSDT","U":99829858715,"u":99829858761,"b":[["78287.78000000","0.17753000"],["78286.01000000","0.06204000"],["78282.74000000","0.00007000"],["78282.73000000","0.14715000"],["78281.73000000","0.14217000"],["78281.72000000","0.00000000"],["78281.71000000","0.00000000"],["78281.70000000","0.00000000"],["78281.69000000","0.00014000"],["78279.68000000","0.00000000"],["78240.33000000","0.00007000"],["78239.15000000","0.00335000"],["78223.86000000","0.02000000"],["78217.29000000","0.00000000"],["78214.70000000","0.00000000"],["78213.79000000","0.00000000"],["78207.40000000","0.00000000"],["78123.43000000","0.00068000"],["78044.03000000","0.00000000"],["77113.47000000","0.00032000"],["70459.01000000","0.00080000"],["62630.23000000","0.00124000"]],"a":[["78362.45000000","0.02800000"],["78367.28000000","0.03400000"]]}}
{"rx":1788854537637437512, "m":{"e":"depthUpdate","E":1788854537614,"s":"BTCUSDT","U":99829858762,"u":99829858799,"b":[["78287.78000000","0.17410000"],["78287.77000000","0.00070000"],["78286.01000000","0.02901000"],["78283.77000000","0.00588000"],["78282.74000000","0.00000000"],["78282.73000000","0.00014000"],["78282.00000000","0.03014000"],["78281.73000000","0.14231000"],["78281.69000000","0.00000000"],["78281.68000000","0.20258000"],["78246.70000000","0.61903000"],["78246.00000000","0.73000000"],["78222.37000000","0.02000000"],["77113.47000000","0.00032000"],["62633.86000000","0.00155000"],["62630.00000000","0.01796000"]],"a":[["78287.79000000","9.39937000"],["78380.78000000","0.03200000"],["79462.11000000","0.00030000"]]}}
{"rx":1788854537737763282, "m":{"e":"depthUpdate","E":1788854537714,"s":"BTCUSDT","U":99829858800,"u":99829858834,"b":[["78287.78000000","0.17388000"],["78287.77000000","0.00063000"],["78283.77000000","0.00588000"],["78282.73000000","0.00000000"],["78281.68000000","0.20272000"],["78268.71000000","0.00000000"],["78229.57000000","0.00000000"],["78199.68000000","0.07639000"],["78198.26000000","0.00000000"],["78197.37000000","0.00007000"],["78109.09000000","0.02001000"],["77113.47000000","0.00032000"],["70463.07000000","0.00000000"],["70459.01000000","0.00096000"],["62630.00000000","0.01596000"]],"a":[["78289.38000000","0.00007000"],["78291.95000000","0.00007000"],["78293.66000000","0.00013000"],["78308.99000000","0.00000000"],["78318.26000000","0.03828000"],["78340.67000000","0.00000000"],["78348.15000000","0.00000000"],["78381.13000000","0.00000000"],["78413.04000000","0.00111000"]]}}
{"rx":1788854537843445596, "m":{"e":"depthUpdate","E":1788854537814,"s":"BTCUSDT","U":99829858835,"u":99829858855,"b":[["78287.78000000","0.17395000"],["78281.73000000","0.29932000"],["78281.19000000","0.13319000"],["78279.68000000","0.00000000"],["77113.47000000","0.00040000"],["62633.86000000","0.00124000"],["41213.30000000","0.00036000"]],"a":[["78287.80000000","3.75888000"],["78291.72000000","0.01341000"],["78295.64000000","0.01299000"],["78299.53000000","0.00007000"],["78299.54000000","0.00000000"],["78299.56000000","0.01291000"],["78303.46000000","0.02098000"],["78303.48000000","0.01319000"],["78311.29000000","0.02171000"],["78319.12000000","0.39720000"]]}}
{"rx":1788854537939013497, "m":{"e":"depthUpdate","E":1788854537914,"s":"BTCUSDT","U":99829858856,"u":99829858919,"b":[["78287.78000000","0.18157000"],["78282.03000000","0.00007000"],["78282.02000000","0.12380000"],["78281.75000000","0.13795000"],["78281.74000000","0.00000000"],["78281.73000000","0.00014000"],["78281.68000000","0.20272000"],["78281.19000000","0.00000000"],["77113.47000000","0.00040000"],["72040.91000000","0.00014000"],["70459.01000000","0.00112000"]],"a":[["78287.80000000","3.74552000"],["78291.72000000","0.00000000"],["78295.64000000","0.00000000"],["78299.56000000","0.00000000"],["78303.46000000","0.00008000"],["78303.48000000","0.00000000"],["78304.16000000","0.00408000"],["78311.29000000","0.00008000"],["78319.12000000","0.37589000"],["78412.11000000","0.10344000"],["78452.24000000","0.00111000"]]}}
{"rx":1788854538071379112, "m":{"e":"depthUpdate","E":1788854538014,"s":"BTCUSDT","U":99829858920,"u":99829858954,"b":[["78287.78000000","0.20802000"],["78287.77000000","0.00076000"],["78287.76000000","0.00013000"],["78283.77000000","0.00588000"],["78282.02000000","0.12394000"],["78282.00000000","0.03014000"],["78281.75000000","0.13809000"],["78281.73000000","0.00000000"],["78281.68000000","0.20258000"],["78273.28000000","0.00000000"],["77113.47000000","0.00040000"],["77113.46000000","0.00030000"],["70459.01000000","0.00128000"],["62633.86000000","0.00093000"],["62630.23000000","0.00248000"],["45000.00000000","182.62609000"]],"a":[["78498.89000000","0.02001000"],["78529.99000000","0.00000000"]]}}
{"rx":1788854538149348632, "m":{"e":"depthUpdate","E":1788854538114,"s":"BTCUSDT","U":99829858955,"u":99829858960,"b":[["78287.78000000","0.17762000"],["78258.20000000","0.00408000"],["77587.69000000","0.00000000"],["77113.47000000","0.00032000"]],"a":[]}}
{"rx":1788854538264852590, "m":{"e":"depthUpdate","E":1788854538214,"s":"BTCUSDT","U":99829858961,"u":99829858968,"b":[["77113.47000000","0.00032000"],["70459.01000000","0.00144000"],["62633.86000000","0.00062000"]],"a":[["78292.33000000","0.04603000"],["78348.66000000","0.00000000"],["78496.08000000","0.00000000"]]}}
{"rx":1788854538347084239, "m":{"e":"depthUpdate","E":1788854538314,"s":"BTCUSDT","U":99829858969,"u":99829858983,"b":[["78287.78000000","0.18020000"],["78278.61000000","0.01027000"],["78235.96000000","0.55714000"],["78140.41000000","0.00000000"],["78130.12000000","0.00665000"],["77113.47000000","0.00032000"],["70459.00000000","0.00020000"],["62630.22000000","0.00000000"]],"a":[]}}
{"rx":1788854538450311485, "m":{"e":"depthUpdate","E":1788854538414,"s":"BTCUSDT","U":99829858984,"u":99829859005,"b":[["78287.78000000","0.17993000"],["78286.01000000","0.05967000"],["78283.01000000","0.00007000"],["78283.00000000","0.13920000"],["78282.03000000","0.00000000"],["78282.02000000","0.00014000"],["78281.75000000","0.14216000"],["78199.68000000","0.07759000"],["77113.47000000","0.00032000"],["72040.91000000","0.00000000"],["70459.01000000","0.00160000"],["70459.00000000","0.00000000"],["62633.86000000","0.00031000"]],"a":[]}}
{"rx":1788854538548713675, "m":{"e":"depthUpdate","E":1788854538514,"s":"BTCUSDT","U":99829859006,"u":99829859026,"b":[["78287.78000000","0.18000000"],["78287.77000000","0.00083000"],["78283.77000000","0.00588000"],["78283.00000000","0.13934000"],["78282.02000000","0.00000000"],["78219.07000000","0.00408000"],["78199.68000000","0.00000000"],["77113.47000000","0.00032000"],["70459.01000000","0.00176000"]],"a":[["78292.00000000","0.01500000"],["78294.00000000","0.04500000"],["78314.18000000","0.52269000"],["78352.18000000","0.00000000"]]}}
{"rx":1788854538640326572, "m":{"e":"depthUpdate","E":1788854538614,"s":"BTCUSDT","U":99829859027,"u":99829859061,"b":[["78287.78000000","0.36311000"],["78284.56000000","0.13617000"],["78283.00000000","0.00014000"],["78282.38000000","0.47615000"],["78281.76000000","0.00000000"],["78257.46000000","0.63910000"],["78250.17000000","1.04658000"],["78247.00000000","0.70000000"],["78246.00000000","0.03000000"],["78214.52000000","0.00000000"],["77113.47000000","0.00032000"],["62633.86000000","0.00000000"],["62630.00000000","0.01596000"]],"a":[["78287.79000000","8.91937000"],["78287.80000000","3.64133000"],["78292.00000000","0.02000000"],["78294.00000000","0.04000000"],["78315.56000000","0.00000000"],["78336.18000000","0.00000000"],["79462.11000000","0.00030000"]]}}
{"rx":1788854538736822314, "m":{"e":"depthUpdate","E":1788854538714,"s":"BTCUSDT","U":99829859062,"u":99829859116,"b":[["78287.78000000","0.37167000"],["78287.77000000","0.00083000"],["78286.01000000","0.06257000"],["78286.00000000","0.03014000"],["78284.57000000","0.00014000"],["78284.56000000","0.13631000"],["78283.77000000","0.00588000"],["78283.01000000","0.00000000"],["78283.00000000","0.00000000"],["78282.38000000","0.00014000"],["78282.01000000","0.00000000"],["78281.76000000","0.44048000"],["78281.75000000","0.13758000"],["78215.10000000","0.11556000"],["78203.88000000","0.32861000"],["78200.43000000","1.00372000"],["78200.42000000","0.00007000"],["78194.32000000","0.00007000"],["77113.47000000","0.00032000"],["70459.01000000","0.00192000"],["41213.30000000","0.00000000"]],"a":[["78295.17000000","0.00179000"]]}}
{"rx":1788854538836902192, "m":{"e":"depthUpdate","E":1788854538814,"s":"BTCUSDT","U":99829859117,"u":99829859166,"b":[["78287.78000000","0.34535000"],["78283.77000000","0.00588000"],["78282.38000000","0.00000000"],["78282.00000000","0.03014000"],["78281.77000000","0.14530000"],["78281.76000000","0.00014000"],["78281.75000000","0.00000000"],["77113.47000000","0.00040000"],["70459.01000000","0.00201000"],["62630.23000000","0.00217000"]],"a":[["78287.79000000","8.91909000"],["78291.71000000","0.00000000"],["78295.62000000","0.00226000"],["78295.63000000","0.00000000"],["78299.53000000","0.00007000"],["78299.55000000","0.00000000"],["78303.45000000","0.00226000"],["78303.47000000","0.00000000"],["78311.28000000","0.00226000"],["78319.11000000","0.00226000"]]}}
{"rx":1788854538936798036, "m":{"e":"depthUpdate","E":1788854538914,"s":"BTCUSDT","U":99829859167,"u":99829859189,"b":[["78287.78000000","0.37303000"],["78282.00000000","0.03014000"],["78281.77000000","0.14544000"],["78281.76000000","0.00000000"],["78203.88000000","0.28909000"],["78061.22000000","0.00809000"],["78059.85000000","0.00000000"],["77113.47000000","0.00040000"],["70459.01000000","0.00217000"]],"a":[["78374.64000000","0.00408000"],["78495.23000000","0.00000000"]]}}
{"rx":1788854539039788257, "m":{"e":"depthUpdate","E":1788854539014,"s":"BTCUSDT","U":99829859190,"u":99829859216,"b":[["78287.78000000","0.18293000"],["78286.01000000","0.02188000"],["78284.57000000","0.00000000"],["78284.56000000","0.00014000"],["78282.01000000","0.00007000"],["78281.79000000","0.29446000"],["78281.78000000","0.48289000"],["78281.77000000","0.00014000"],["77113.47000000","0.00040000"],["77113.46000000","0.00030000"],["62630.23000000","0.00310000"]],"a":[]}}
{"rx":1788854539137564752, "m":{"e":"depthUpdate","E":1788854539114,"s":"BTCUSDT","U":99829859217,"u":99829859341,"b":[["78287.78000000","0.33048000"],["78287.77000000","0.00090000"],["78286.01000000","0.02188000"],["78286.00000000","0.03014000"],["78285.09000000","0.00000000"],["78285.08000000","0.00000000"],["78284.56000000","0.00000000"],["78284.19000000","0.00000000"],["78284.18000000","0.00000000"],["78284.01000000","0.00014000"],["78282.38000000","0.00000000"],["78282.01000000","0.00007000"],["78282.00000000","0.03014000"],["78281.79000000","0.15050000"],["78281.78000000","0.00014000"],["78281.77000000","0.00000000"],["78281.68000000","0.00008000"],["78279.95000000","0.20250000"],["78278.62000000","0.00000000"],["78274.11000000","0.79867000"],["78274.10000000","0.00000000"],["78274.08000000","0.00638000"],["78274.07000000","0.00000000"],["78269.58000000","0.15192000"],["78209.46000000","2.29920000"],["78209.45000000","0.00000000"],["78208.46000000","0.00000000"],["78159.62000000","0.00000000"],["78123.99000000","0.00000000"],["77583.19000000","0.00010000"],["77113.47000000","0.00032000"],["70459.01000000","0.00233000"]],"a":[["78287.79000000","8.53031000"],["78287.80000000","1.04226000"],["78287.84000000","0.00007000"],["78288.51000000","0.00000000"],["78289.22000000","0.00132000"],["78289.64000000","0.00400000"],["78290.30000000","0.01276000"],["78292.00000000","0.03000000"],["78293.65000000","0.00400000"],["78294.00000000","0.03000000"],["78294.06000000","0.00000000"],["78294.07000000","0.00000000"],["78295.61000000","0.01600000"],["78295.79000000","0.00000000"],["78295.99000000","0.00400000"],["78306.77000000","0.00000000"],["78343.32000000","0.00408000"],["78430.46000000","0.00000000"]]}}
{"rx":1788854539238605012, "m":{"e":"depthUpdate","E":1788854539214,"s":"BTCUSDT","U":99829859342,"u":99829859444,"b":[["78287.78000000","2.02135000"],["78287.77000000","0.00076000"],["78287.03000000","0.06383000"],["78287.02000000","0.12081000"],["78286.01000000","0.00028000"],["78284.00000000","0.03014000"],["78283.80000000","0.00014000"],["78282.39000000","0.00000000"],["78282.38000000","0.00000000"],["78282.01000000","0.00000000"],["78281.80000000","0.00000000"],["78281.79000000","0.15050000"],["78281.78000000","0.00000000"],["78280.88000000","0.00756000"],["78280.00000000","0.03127000"],["78279.02000000","0.00400000"],["78279.00000000","0.03057000"],["78278.58000000","0.00000000"],["78278.06000000","0.66890000"],["78278.01000000","1.96971000"],["78277.37000000","0.00000000"],["78274.49000000","0.00000000"],["78274.11000000","0.71846000"],["78257.29000000","0.02529000"],["77397.20000000","0.00248000"],["77113.47000000","0.00032000"],["70459.01000000","0.00249000"],["62630.23000000","0.00279000"]],"a":[["78287.79000000","4.84432000"],["78287.84000000","0.00014000"],["78289.22000000","0.00000000"],["78289.28000000","0.00014000"],["78289.50000000","0.00014000"],["78289.51000000","0.11094000"],["78289.64000000","0.00000000"],["78290.29000000","0.00000000"],["78290.30000000","0.00638000"],["78290.77000000","0.00400000"],["78291.37000000","0.00136000"],["78291.38000000","0.00000000"],["78291.43000000","0.00400000"],["78291.51000000","0.30000000"],["78292.82000000","0.00638000"],["78295.61000000","0.00800000"],["78297.25000000","0.00800000"],["78305.00000000","0.00000000"],["78350.28000000","1.26392000"]]}}
{"rx":1788854539341237121, "m":{"e":"depthUpdate","E":1788854539314,"s":"BTCUSDT","U":99829859445,"u":99829859521,"b":[["78287.78000000","2.02135000"],["78287.77000000","0.00076000"],["78287.04000000","0.00014000"],["78287.03000000","0.02775000"],["78287.02000000","0.00014000"],["78286.46000000","0.02014000"],["78286.02000000","0.00000000"],["78286.01000000","0.00014000"],["78284.01000000","0.00014000"],["78282.01000000","0.00007000"],["78281.79000000","0.15050000"],["78280.88000000","0.00356000"],["78280.00000000","0.03113000"],["78279.89000000","0.00400000"],["78219.07000000","0.00000000"],["78187.76000000","0.00408000"],["77113.47000000","0.00032000"],["62630.22000000","0.00000000"],["62630.00000000","0.01596000"]],"a":[["78287.79000000","7.14540000"],["78289.23000000","0.06901000"],["78289.28000000","0.00000000"],["78289.50000000","0.00000000"],["78289.59000000","0.04049000"],["78290.30000000","0.00652000"],["78297.65000000","0.00000000"],["78304.16000000","0.00000000"],["78374.64000000","0.00000000"],["78405.34000000","0.07552000"],["78411.84000000","0.02327000"],["78412.11000000","0.00000000"]]}}
{"rx":1788854539449588865, "m":{"e":"depthUpdate","E":1788854539414,"s":"BTCUSDT","U":99829859522,"u":99829859545,"b":[["78287.78000000","1.81885000"],["78287.03000000","0.02775000"],["78287.02000000","0.00000000"],["78281.79000000","0.15050000"],["78280.00000000","0.03127000"],["78278.87000000","0.02089000"],["78277.89000000","0.01311000"],["77113.47000000","0.00032000"],["70459.01000000","0.00265000"],["62630.23000000","0.00248000"],["62630.22000000","0.00000000"]],"a":[["78291.55000000","0.00026000"],["78403.99000000","0.05188000"],["78405.34000000","0.10344000"]]}}
{"rx":1788854539537106936, "m":{"e":"depthUpdate","E":1788854539514,"s":"BTCUSDT","U":99829859546,"u":99829859637,"b":[["78287.78000000","0.62422000"],["78287.04000000","0.00000000"],["78287.03000000","0.00014000"],["78284.05000000","0.00000000"],["78284.00000000","0.03014000"],["78283.95000000","0.00014000"],["78283.94000000","0.12888000"],["78283.80000000","0.00007000"],["78279.89000000","0.00000000"],["78279.81000000","0.00007000"],["78279.50000000","0.00000000"],["78279.02000000","0.00000000"],["78279.00000000","0.00000000"],["78278.87000000","0.00000000"],["78278.54000000","0.00400000"],["78278.06000000","0.14306000"],["78278.01000000","0.00000000"],["78277.89000000","0.00000000"],["78277.84000000","0.00000000"],["78275.82000000","0.00414000"],["78274.84000000","0.00000000"],["78274.08000000","0.00000000"],["78272.84000000","0.00255000"],["78269.59000000","0.37581000"],["78269.58000000","0.00000000"],["78269.57000000","0.93443000"],["78252.81000000","0.00000000"],["78244.82000000","0.00667000"],["78218.96000000","0.00408000"],["78137.89000000","0.00015000"],["78133.93000000","1.53085000"],["78066.67000000","0.00802000"],["78061.22000000","0.00007000"],["77113.47000000","0.00032000"],["70459.00000000","0.00000000"]],"a":[["78287.79000000","7.73897000"],["78289.51000000","0.02864000"],["78290.49000000","0.00000000"],["78291.43000000","0.00000000"],["78293.46000000","0.03057000"],["78380.39000000","0.01513000"],["78393.29000000","0.00000000"],["78427.21000000","0.00000000"],["78429.11000000","0.00000000"],["78431.39000000","0.64797000"],["78431.40000000","1.53085000"],["78432.48000000","0.00000000"],["78438.26000000","0.00000000"],["79043.65000000","0.00000000"]]}}
{"rx":1788854539637246717, "m":{"e":"depthUpdate","E":1788854539614,"s":"BTCUSDT","U":99829859638,"u":99829859728,"b":[["78287.78000000","0.65021000"],["78287.77000000","0.00083000"],["78287.03000000","0.00000000"],["78286.02000000","0.00014000"],["78286.01000000","0.02166000"],["78284.00000000","0.03014000"],["78283.95000000","0.00000000"],["78283.94000000","0.00014000"],["78282.01000000","0.00007000"],["78279.81000000","0.00014000"],["78278.71000000","0.00048000"],["78274.78000000","0.00638000"],["78274.12000000","0.15191000"],["78272.84000000","0.00000000"],["77113.47000000","0.00032000"],["70459.01000000","0.00281000"],["62630.23000000","0.00217000"]],"a":[["78287.79000000","7.74549000"],["78287.80000000","1.04254000"],["78287.84000000","0.00000000"],["78292.82000000","0.00000000"],["78305.24000000","0.00000000"],["79462.11000000","0.00030000"]]}}
{"rx":1788854539737272344, "m":{"e":"depthUpdate","E":1788854539714,"s":"BTCUSDT","U":99829859729,"u":99829859759,"b":[["78287.78000000","0.77665000"],["78287.77000000","0.00076000"],["78286.46000000","0.02014000"],["78286.02000000","0.00040000"],["78286.01000000","0.02180000"],["78286.00000000","0.03062000"],["78284.00000000","0.03014000"],["78283.94000000","0.00000000"],["78206.52000000","0.00007000"],["77973.67000000","0.00007000"],["77113.47000000","0.00032000"],["70459.01000000","0.00288000"],["70459.00000000","0.00009000"]],"a":[["78287.79000000","7.66787000"],["78374.51000000","0.00408000"],["78495.64000000","0.00000000"],["78496.13000000","0.00000000"]]}}
{"rx":1788854539837046107, "m":{"e":"depthUpdate","E":1788854539814,"s":"BTCUSDT","U":99829859760,"u":99829859772,"b":[["78287.78000000","0.62224000"],["78249.00000000","0.70000000"],["78247.00000000","0.00000000"],["77113.47000000","0.00040000"],["62630.23000000","0.00186000"]],"a":[["78287.79000000","7.66773000"],["78287.80000000","1.04240000"],["78299.53000000","0.00007000"]]}}
{"rx":1788854539938787083, "m":{"e":"depthUpdate","E":1788854539914,"s":"BTCUSDT","U":99829859773,"u":99829859789,"b":[["78287.78000000","0.62243000"],["78286.02000000","0.00026000"],["78286.01000000","0.00028000"],["78282.01000000","0.00014000"],["78281.80000000","0.00007000"],["78281.50000000","0.14689000"],["77113.47000000","0.00040000"],["70459.01000000","0.00304000"]],"a":[["78287.79000000","7.66759000"],["78287.80000000","1.04226000"],["78405.34000000","0.00000000"]]}}
{"rx":1788854540037876172, "m":{"e":"depthUpdate","E":1788854540014,"s":"BTCUSDT","U":99829859790,"u":99829859875,"b":[["78287.78000000","0.31887000"],["78287.77000000","0.00076000"],["78286.48000000","0.00014000"],["78286.47000000","0.21725000"],["78286.46000000","0.02014000"],["78286.01000000","0.00014000"],["78284.29000000","0.00026000"],["78282.94000000","0.00007000"],["78282.93000000","0.16349000"],["78282.38000000","0.48289000"],["78282.01000000","0.00000000"],["78281.81000000","0.26697000"],["78281.80000000","0.00007000"],["78281.79000000","0.00014000"],["78281.50000000","0.00014000"],["78280.58000000","0.00000000"],["78278.61000000","0.00000000"],["78278.54000000","0.00000000"],["78277.65000000","0.00400000"],["78275.82000000","0.00014000"],["78274.75000000","0.00400000"],["78274.12000000","0.00000000"],["78272.96000000","0.00007000"],["78269.60000000","0.15192000"],["78049.44000000","0.00007000"],["77113.47000000","0.00040000"],["77113.46000000","0.00030000"],["70459.00000000","0.00019000"],["62630.23000000","0.00279000"]],"a":[["78287.79000000","7.70230000"],["78291.71000000","0.01302000"],["78295.62000000","0.02347000"],["78295.63000000","0.01333000"],["78296.46000000","0.00007000"],["78299.55000000","0.01342000"],["78300.00000000","0.03007000"],["78303.45000000","0.02303000"],["78303.47000000","0.01313000"],["78319.11000000","0.02335000"],["78403.99000000","0.03341000"],["78406.73000000","0.07285000"]]}}
{"rx":1788854540137434852, "m":{"e":"depthUpdate","E":1788854540114,"s":"BTCUSDT","U":99829859876,"u":99829859945,"b":[["78287.78000000","0.18171000"],["78287.77000000","0.00090000"],["78286.47000000","0.10209000"],["78283.77000000","0.00588000"],["78282.93000000","0.16363000"],["78282.38000000","0.00014000"],["78282.00000000","0.03014000"],["78281.81000000","0.12279000"],["78281.80000000","0.00000000"],["78281.79000000","0.00000000"],["78281.50000000","0.00000000"],["78280.58000000","0.47108000"],["78280.00000000","0.03113000"],["78278.06000000","0.10380000"],["77113.47000000","0.00032000"],["70459.01000000","0.00320000"],["70459.00000000","0.00009000"],["62630.00000000","0.01796000"]],"a":[["78287.79000000","7.66770000"],["78291.71000000","0.00000000"],["78295.62000000","0.00226000"],["78295.63000000","0.00000000"],["78299.55000000","0.00000000"],["78303.45000000","0.00226000"],["78303.47000000","0.00000000"],["78319.11000000","0.00226000"],["78496.76000000","0.00000000"]]}}
{"rx":1788854540237788464, "m":{"e":"depthUpdate","E":1788854540214,"s":"BTCUSDT","U":99829859946,"u":99829860242,"b":[["78287.78000000","0.00000000"],["78287.77000000","0.00000000"],["78287.76000000","0.00000000"],["78286.48000000","0.00000000"],["78286.47000000","0.42595000"],["78286.46000000","0.02077000"],["78284.29000000","0.00000000"],["78283.84000000","0.00000000"],["78283.83000000","0.00000000"],["78282.94000000","0.00000000"],["78282.93000000","0.00014000"],["78282.38000000","0.00000000"],["78282.01000000","0.00014000"],["78281.99000000","0.06584000"],["78281.82000000","0.00007000"],["78281.81000000","0.24774000"],["78281.80000000","0.00206000"],["78281.68000000","0.00000000"],["78280.58000000","0.00014000"],["78278.64000000","0.00008000"],["78277.65000000","0.00000000"],["78276.03000000","0.00400000"],["78275.73000000","0.00000000"],["78275.66000000","0.01293000"],["78274.78000000","0.00000000"],["78274.75000000","0.00000000"],["78274.06000000","0.00400000"],["78273.89000000","0.00400000"],["78272.73000000","0.02974000"],["78272.14000000","0.00638000"],["78269.59000000","0.00000000"],["78269.58000000","0.37581000"],["78260.01000000","0.00000000"],["78258.04000000","0.31534000"],["78255.34000000","0.00024000"],["78250.17000000","0.74108000"],["78249.00000000","0.00000000"],["78248.00000000","0.03000000"],["78247.97000000","0.00000000"],["78247.89000000","0.00014000"],["78247.00000000","0.01000000"],["78238.30000000","0.00008000"],["78214.93000000","1.26611000"],["78209.47000000","1.94291000"],["78200.43000000","0.00138000"],["78185.65000000","0.00007000"],["78047.94000000","0.00000000"],["77977.42000000","0.00250000"],["77113.47000000","0.00000000"],["77113.46000000","0.00000000"],["70459.01000000","0.00000000"],["70459.00000000","0.00000000"],["62630.23000000","0.00248000"],["62630.00000000","0.01596000"]],"a":[["78286.48000000","8.47067000"],["78286.49000000","3.31897000"],["78286.50000000","0.05013000"],["78286.55000000","0.05000000"],["78287.38000000","0.00000000"],["78287.78000000","2.77248000"],["78287.79000000","0.47598000"],["78287.80000000","0.20278000"],["78287.81000000","0.00000000"],["78287.85000000","0.00014000"],["78287.91000000","0.06887000"],["78289.23000000","0.00014000"],["78290.30000000","0.00000000"],["78291.37000000","0.00000000"],["78291.56000000","0.32352000"],["78292.00000000","0.33000000"],["78292.31000000","0.00400000"],["78292.32000000","0.37500000"],["78292.82000000","0.00400000"],["78294.31000000","0.00008000"],["78296.46000000","0.00000000"],["78297.10000000","0.00008000"],["78297.25000000","0.00000000"],["78297.34000000","0.00000000"],["78324.01000000","2.50059000"],["78346.10000000","0.00000000"],["78495.01000000","0.00000000"],["78842.44000000","0.00250000"],["79462.11000000","0.00000000"]]}}
{"rx":1788854540337886676, "m":{"e":"depthUpdate","E":1788854540314,"s":"BTCUSDT","U":99829860243,"u":99829860401,"b":[["78286.47000000","0.18378000"],["78286.46000000","0.02077000"],["78283.77000000","0.00588000"],["78282.93000000","0.00000000"],["78282.19000000","0.00000000"],["78282.00000000","0.03014000"],["78281.99000000","0.00014000"],["78281.81000000","0.12293000"],["78281.80000000","0.00000000"],["78280.88000000","0.00000000"],["78280.58000000","0.00000000"],["78280.00000000","0.03127000"],["78279.62000000","0.00000000"],["78279.14000000","0.00206000"],["78278.71000000","0.00000000"],["78278.37000000","0.00000000"],["78277.12000000","0.00000000"],["78276.62000000","0.00048000"],["78274.11000000","0.08701000"],["78274.09000000","0.00000000"],["78274.06000000","0.00000000"],["78272.21000000","0.00190000"],["78269.61000000","0.00800000"],["78258.04000000","0.21353000"],["78234.56000000","0.00000000"],["78209.69000000","0.01152000"],["78203.88000000","0.03373000"],["78130.66000000","0.00000000"],["78110.75000000","0.05619000"],["77112.18000000","0.00008000"],["70459.00000000","0.00000000"],["70457.83000000","0.00016000"],["41213.30000000","0.00036000"]],"a":[["78286.48000000","8.49110000"],["78286.49000000","3.31897000"],["78286.50000000","0.05027000"],["78286.55000000","0.05014000"],["78286.75000000","0.00000000"],["78287.78000000","0.70465000"],["78287.79000000","0.44912000"],["78287.80000000","0.19102000"],["78287.85000000","0.00000000"],["78287.91000000","0.06901000"],["78289.06000000","0.00000000"],["78289.23000000","0.00000000"],["78289.51000000","0.02850000"],["78289.52000000","1.95060000"],["78289.59000000","0.04035000"],["78290.31000000","0.00000000"],["78290.77000000","0.00000000"],["78291.50000000","0.40161000"],["78291.56000000","0.30000000"],["78292.31000000","0.30400000"],["78296.26000000","0.00007000"],["78326.00000000","0.74000000"],["78327.00000000","0.00000000"],["78512.47000000","0.00000000"],["78789.76000000","0.21037000"],["78893.99000000","0.00000000"]]}}
{"rx":1788854540438419635, "m":{"e":"depthUpdate","E":1788854540414,"s":"BTCUSDT","U":99829860402,"u":99829860473,"b":[["78286.47000000","0.18537000"],["78286.46000000","0.02077000"],["78282.00000000","0.03014000"],["78281.99000000","0.00000000"],["78281.81000000","0.24113000"],["78280.21000000","0.00000000"],["78280.01000000","0.45420000"],["78279.95000000","0.20264000"],["78279.56000000","0.00356000"],["78278.30000000","0.00594000"],["78277.05000000","0.00713000"],["78275.80000000","0.00713000"],["78274.11000000","0.08519000"],["78175.95000000","0.13325000"],["78175.94000000","0.24377000"],["77112.18000000","0.00016000"],["70457.83000000","0.00032000"],["70457.00000000","0.00000000"],["62630.23000000","0.00217000"],["62629.18000000","0.00000000"],["62629.00000000","0.00000000"]],"a":[["78286.48000000","8.50305000"],["78286.49000000","3.31897000"],["78287.35000000","0.00400000"],["78287.74000000","0.01960000"],["78287.77000000","0.00129000"],["78287.79000000","0.24162000"],["78287.91000000","0.06901000"],["78288.99000000","0.02352000"],["78290.24000000","0.02352000"],["78404.15000000","0.04108000"],["78406.73000000","0.00000000"],["78494.99000000","0.00000000"]]}}
{"rx":1788854540537322444, "m":{"e":"depthUpdate","E":1788854540514,"s":"BTCUSDT","U":99829860474,"u":99829860558,"b":[["78286.47000000","0.52472000"],["78286.46000000","0.02091000"],["78284.02000000","0.00014000"],["78284.01000000","0.05710000"],["78283.46000000","0.00014000"],["78283.45000000","0.15326000"],["78282.01000000","0.00000000"],["78281.82000000","0.00000000"],["78281.81000000","0.13932000"],["78280.22000000","0.06584000"],["78280.01000000","0.00000000"],["78279.95000000","0.20250000"],["78275.66000000","0.00000000"],["78272.73000000","0.00000000"],["78199.53000000","0.07555000"],["78048.34000000","0.00007000"],["78044.43000000","0.00000000"],["77112.18000000","0.00024000"],["70457.00000000","0.00000000"],["62629.18000000","0.00124000"],["62629.00000000","0.00000000"]],"a":[["78286.48000000","8.49950000"],["78286.49000000","3.31932000"],["78286.55000000","0.05014000"],["78287.35000000","0.00000000"],["78287.74000000","0.01974000"],["78287.79000000","0.23935000"],["78287.91000000","0.06901000"],["78288.60000000","0.00400000"],["78288.98000000","0.00638000"],["78292.31000000","0.30000000"],["78294.30000000","0.00400000"],["78294.31000000","0.00234000"],["78295.62000000","0.00000000"],["78301.52000000","0.03400000"],["78302.14000000","0.00226000"],["78303.45000000","0.00000000"],["78305.09000000","0.02800000"],["78309.97000000","0.00226000"],["78311.28000000","0.00000000"],["78317.80000000","0.00226000"],["78319.11000000","0.00000000"],["78362.45000000","0.00000000"],["78494.63000000","0.00000000"]]}}
{"rx":1788854540637230590, "m":{"e":"depthUpdate","E":1788854540614,"s":"BTCUSDT","U":99829860559,"u":99829860595,"b":[["78286.00000000","0.03062000"],["78284.01000000","0.05724000"],["78283.77000000","0.00588000"],["78283.45000000","0.15340000"],["78281.81000000","0.13918000"],["78280.00000000","0.03113000"],["78175.95000000","0.00000000"],["78175.94000000","0.00000000"],["78110.22000000","0.00000000"],["78066.67000000","0.00000000"],["78050.05000000","0.00803000"],["77112.18000000","0.00032000"],["70457.83000000","0.00048000"],["62630.23000000","0.00186000"]],"a":[["78287.91000000","0.06901000"],["78309.38000000","0.00000000"],["78312.97000000","0.00000000"],["78367.28000000","0.00000000"],["78404.15000000","0.07285000"],["78475.64000000","0.00000000"],["78494.62000000","0.00000000"],["78498.37000000","0.12781000"],["79460.78000000","0.00030000"]]}}
{"rx":1788854540737338721, "m":{"e":"depthUpdate","E":1788854540714,"s":"BTCUSDT","U":99829860596,"u":99829860621,"b":[["78286.47000000","0.36743000"],["78280.60000000","0.00013000"],["78275.34000000","0.01286000"],["78271.81000000","0.00255000"],["78209.57000000","0.00007000"],["78187.76000000","0.00000000"],["78170.75000000","0.03961000"],["78112.85000000","0.12788000"],["77965.95000000","0.00007000"],["77112.18000000","0.00032000"]],"a":[["78286.48000000","8.49894000"],["78286.49000000","3.31897000"],["78304.03000000","0.00408000"],["78374.51000000","0.00000000"]]}}
{"rx":1788854540837330574, "m":{"e":"depthUpdate","E":1788854540814,"s":"BTCUSDT","U":99829860622,"u":99829860632,"b":[["78249.00000000","0.70000000"],["78099.66000000","4.61855000"],["77112.18000000","0.00040000"],["70457.83000000","0.00064000"],["70457.00000000","0.00000000"],["62630.23000000","0.00155000"]],"a":[["78286.48000000","8.49639000"],["78299.53000000","0.00000000"],["78301.41000000","0.04200000"],["78464.17000000","4.50519000"]]}}
{"rx":1788854540939249413, "m":{"e":"depthUpdate","E":1788854540914,"s":"BTCUSDT","U":99829860633,"u":99829860669,"b":[["78286.47000000","0.76049000"],["78284.36000000","0.14519000"],["78283.45000000","0.00014000"],["77112.18000000","0.00040000"],["70457.83000000","0.00073000"],["62629.00000000","0.00200000"]],"a":[["78286.48000000","8.49667000"],["78286.49000000","3.31932000"],["78286.71000000","0.00255000"],["78287.77000000","0.00143000"],["78292.82000000","0.00000000"],["78298.22000000","0.00007000"],["78373.67000000","0.00408000"],["78414.32000000","0.00107000"],["78435.77000000","0.00000000"]]}}
{"rx":1788854541037904067, "m":{"e":"depthUpdate","E":1788854541014,"s":"BTCUSDT","U":99829860670,"u":99829860905,"b":[["78286.47000000","4.19554000"],["78286.46000000","0.02091000"],["78286.37000000","0.00000000"],["78286.02000000","0.00040000"],["78286.01000000","0.02112000"],["78286.00000000","0.03062000"],["78284.77000000","0.00026000"],["78284.38000000","0.00000000"],["78284.37000000","0.00000000"],["78284.36000000","0.00014000"],["78284.17000000","0.00000000"],["78284.16000000","0.00000000"],["78284.02000000","0.00000000"],["78284.01000000","0.00028000"],["78283.81000000","0.00000000"],["78283.80000000","0.00014000"],["78283.77000000","0.00588000"],["78283.46000000","0.00000000"],["78283.45000000","0.00000000"],["78282.70000000","0.00063000"],["78282.01000000","0.00007000"],["78280.22000000","0.00000000"],["78279.95000000","0.00000000"],["78279.14000000","0.00000000"],["78278.64000000","0.20258000"],["78278.36000000","0.02145000"],["78278.06000000","0.14368000"],["78278.00000000","0.06057000"],["78277.69000000","0.01285000"],["78277.68000000","0.00000000"],["78277.43000000","0.00255000"],["78276.62000000","0.00000000"],["78276.47000000","0.00000000"],["78276.03000000","0.00000000"],["78274.01000000","0.00000000"],["78273.89000000","0.00000000"],["78271.81000000","0.00000000"],["78269.61000000","0.00000000"],["78245.80000000","0.00400000"],["78244.32000000","0.00000000"],["78200.43000000","1.00372000"],["78112.85000000","0.00007000"],["78065.55000000","0.00007000"],["78048.34000000","0.00000000"],["77112.18000000","0.00040000"],["77112.17000000","0.00030000"],["70457.83000000","0.00089000"],["66663.80000000","0.00646000"],["62630.23000000","0.00124000"],["62629.00000000","0.00000000"]],"a":[["78286.48000000","2.63039000"],["78286.49000000","0.00090000"],["78286.71000000","0.00000000"],["78286.87000000","0.00000000"],["78287.77000000","0.00014000"],["78287.78000000","0.17680000"],["78287.79000000","0.16738000"],["78288.10000000","0.00000000"],["78288.60000000","0.00000000"],["78288.98000000","0.00000000"],["78289.50000000","1.95060000"],["78289.52000000","0.00000000"],["78289.66000000","0.00000000"],["78290.23000000","0.00000000"],["78290.57000000","0.00000000"],["78291.50000000","1.00571000"],["78291.55000000","0.00000000"],["78291.94000000","0.00000000"],["78292.11000000","0.00000000"],["78292.32000000","0.30000000"],["78292.82000000","0.00638000"],["78293.08000000","0.00255000"],["78293.45000000","0.00132000"],["78293.46000000","0.00000000"],["78293.50000000","1.95060000"],["78293.65000000","0.00000000"],["78294.30000000","0.00000000"],["78294.31000000","0.20484000"],["78294.70000000","0.00000000"],["78295.00000000","0.00638000"],["78295.61000000","0.00000000"],["78295.94000000","0.00000000"],["78295.99000000","0.00000000"],["78296.28000000","0.00400000"],["78297.11000000","0.00000000"],["78297.42000000","0.01600000"],["78297.43000000","0.00000000"],["78297.50000000","0.00191000"],["78299.86000000","0.00000000"],["78300.70000000","0.03600000"],["78301.49000000","0.00000000"],["78301.99000000","0.00000000"],["78302.53000000","0.00000000"],["78303.78000000","0.00000000"],["78304.31000000","0.16897000"],["78304.61000000","0.02600000"],["78305.32000000","0.31945000"],["78305.46000000","0.03400000"],["78308.62000000","0.00000000"],["78309.30000000","0.00000000"],["78310.36000000","0.00000000"],["78313.48000000","0.00000000"],["78314.34000000","0.00223000"],["78318.19000000","0.00000000"],["78402.33000000","0.00000000"],["78438.26000000","0.02892000"]]}}
{"rx":1788854541137266478, "m":{"e":"depthUpdate","E":1788854541114,"s":"BTCUSDT","U":99829860906,"u":99829860981,"b":[["78286.47000000","4.19561000"],["78286.46000000","0.02091000"],["78286.01000000","0.04055000"],["78286.00000000","0.03062000"],["78285.31000000","0.00014000"],["78285.30000000","0.06584000"],["78284.77000000","0.00000000"],["78284.36000000","0.00000000"],["78284.01000000","0.00014000"],["78283.43000000","0.00000000"],["78283.03000000","0.00000000"],["78282.01000000","0.00000000"],["78277.43000000","0.00000000"],["78277.06000000","0.00800000"],["78276.38000000","0.04420000"],["78276.20000000","0.00255000"],["78186.80000000","0.00408000"],["77583.19000000","0.00000000"],["77112.18000000","0.00032000"],["70457.83000000","0.00105000"],["62629.00000000","0.00000000"],["41213.30000000","0.00000000"]],"a":[["78286.48000000","2.80327000"],["78286.49000000","0.00076000"],["78287.78000000","0.71500000"],["78287.79000000","0.16745000"],["78287.91000000","0.06901000"],["78288.99000000","0.02366000"],["78291.45000000","0.00026000"],["78291.48000000","1.74338000"],["78291.49000000","2.29924000"],["78291.50000000","0.00000000"],["78291.85000000","0.00255000"],["78293.08000000","0.00000000"],["78293.49000000","0.37581000"],["78304.03000000","0.00000000"],["78312.50000000","0.00000000"],["78373.67000000","0.00000000"],["78383.55000000","0.00025000"],["78384.86000000","0.00000000"],["78399.99000000","0.00000000"],["78404.15000000","0.10344000"]]}}
{"rx":1788854541241843476, "m":{"e":"depthUpdate","E":1788854541214,"s":"BTCUSDT","U":99829860982,"u":99829861013,"b":[["78286.47000000","4.19568000"],["78286.46000000","0.02091000"],["78286.00000000","0.03062000"],["78282.54000000","0.00400000"],["78281.92000000","0.00400000"],["78112.19000000","0.12791000"],["77112.18000000","0.00032000"],["74390.06000000","0.00013000"],["66543.51000000","0.06000000"],["62630.23000000","0.00093000"]],"a":[["78287.79000000","0.16735000"],["78289.49000000","0.01600000"],["78296.28000000","0.00000000"],["78297.42000000","0.00800000"],["78301.46000000","0.02800000"],["78404.15000000","0.00000000"],["78406.90000000","0.07286000"]]}}
{"rx":1788854541337132673, "m":{"e":"depthUpdate","E":1788854541314,"s":"BTCUSDT","U":99829861014,"u":99829861039,"b":[["78258.04000000","0.30135000"],["78215.10000000","0.46772000"],["77112.18000000","0.00032000"],["70457.83000000","0.00121000"],["62629.00000000","0.00000000"]],"a":[["78286.48000000","2.80533000"],["78288.99000000","0.02366000"],["78292.49000000","0.00400000"],["78293.58000000","0.00400000"],["78303.85000000","0.03000000"],["78309.42000000","0.00000000"],["78311.73000000","0.00021000"],["78399.99000000","0.10776000"],["78406.90000000","0.00000000"],["78427.99000000","0.03558000"]]}}
{"rx":1788854541443274759, "m":{"e":"depthUpdate","E":1788854541414,"s":"BTCUSDT","U":99829861040,"u":99829861048,"b":[["77112.18000000","0.00032000"],["62630.23000000","0.00062000"],["62629.18000000","0.00124000"]],"a":[["78296.61000000","0.31864000"],["78404.37000000","0.04392000"]]}}
{"rx":1788854541537455294, "m":{"e":"depthUpdate","E":1788854541514,"s":"BTCUSDT","U":99829861049,"u":99829861062,"b":[["78286.47000000","4.19575000"],["78281.92000000","0.00000000"],["78280.67000000","0.00400000"],["78112.19000000","0.00010000"],["77112.18000000","0.00032000"],["70457.83000000","0.00137000"],["62629.18000000","0.00248000"]],"a":[["78321.19000000","0.03400000"],["78362.45000000","0.02800000"],["78367.28000000","0.03400000"]]}}
{"rx":1788854541638264872, "m":{"e":"depthUpdate","E":1788854541614,"s":"BTCUSDT","U":99829861063,"u":99829861074,"b":[["78286.47000000","4.19568000"],["77112.18000000","0.00032000"],["70457.83000000","0.00153000"],["62630.23000000","0.00031000"],["62629.00000000","0.00000000"]],"a":[["78367.28000000","0.00000000"],["79460.78000000","0.00030000"]]}}
{"rx":1788854541738437293, "m":{"e":"depthUpdate","E":1788854541714,"s":"BTCUSDT","U":99829861075,"u":99829861090,"b":[["78286.47000000","4.19556000"],["78285.30000000","0.06598000"],["78276.20000000","0.00000000"],["78275.41000000","0.00255000"],["78061.22000000","0.00809000"],["78050.05000000","0.00000000"],["77292.09000000","0.00000000"],["77112.18000000","0.00032000"],["70457.83000000","0.00144000"],["70457.82000000","0.00009000"]],"a":[["78286.48000000","2.80519000"],["78291.06000000","0.00255000"],["78291.85000000","0.00000000"],["78373.53000000","0.00408000"],["82921.37000000","0.00000000"]]}}
{"rx":1788854541840396829, "m":{"e":"depthUpdate","E":1788854541814,"s":"BTCUSDT","U":99829861091,"u":99829861099,"b":[["78284.51000000","0.00206000"],["77112.18000000","0.00040000"],["70457.83000000","0.00160000"],["62630.23000000","0.00000000"]],"a":[["78309.00000000","0.00400000"],["78321.08000000","0.04200000"],["78326.00000000","0.04000000"],["78362.00000000","0.03000000"]]}}
{"rx":1788854541936964064, "m":{"e":"depthUpdate","E":1788854541914,"s":"BTCUSDT","U":99829861100,"u":99829861111,"b":[["78277.76000000","0.01285000"],["78277.69000000","0.00000000"],["78248.75000000","0.00000000"],["78233.76000000","0.00015000"],["77112.18000000","0.00040000"],["70457.00000000","0.00000000"]],"a":[["78298.22000000","0.00007000"],["78345.24000000","0.00638000"],["78356.25000000","0.00000000"]]}}
{"rx":1788854542041652121, "m":{"e":"depthUpdate","E":1788854542014,"s":"BTCUSDT","U":99829861112,"u":99829861133,"b":[["78286.47000000","4.19569000"],["78286.46000000","0.02104000"],["78286.45000000","0.00013000"],["78280.35000000","0.00000000"],["78279.77000000","0.00000000"],["78277.76000000","0.00000000"],["78277.69000000","0.01334000"],["77112.18000000","0.00040000"],["77112.17000000","0.00030000"],["70457.83000000","0.00176000"],["62629.18000000","0.00341000"]],"a":[["78320.37000000","0.03600000"],["78324.27000000","0.02600000"],["78325.13000000","0.03400000"]]}}
{"rx":1788854542149046757, "m":{"e":"depthUpdate","E":1788854542114,"s":"BTCUSDT","U":99829861134,"u":99829861145,"b":[["77581.89000000","0.00010000"],["77112.18000000","0.00032000"]],"a":[["78286.54000000","0.02139000"],["78287.90000000","0.01298000"],["78291.82000000","0.01326000"],["78294.37000000","0.02123000"],["78295.74000000","0.01291000"],["78299.66000000","0.01287000"],["78302.20000000","0.02164000"],["78310.03000000","0.02111000"],["78317.86000000","0.02163000"],["78404.37000000","0.10344000"]]}}
{"rx":1788854542249241761, "m":{"e":"depthUpdate","E":1788854542214,"s":"BTCUSDT","U":99829861146,"u":99829861196,"b":[["78286.47000000","4.19569000"],["78286.46000000","0.02104000"],["78286.01000000","0.02126000"],["78285.31000000","0.00000000"],["78285.30000000","0.00014000"],["78282.01000000","0.00007000"],["78275.41000000","0.00000000"],["78274.19000000","0.00255000"],["77600.00000000","3.51812000"],["77112.18000000","0.00032000"],["70457.83000000","0.00192000"],["70457.82000000","0.00000000"],["62629.18000000","0.00310000"]],"a":[["78286.48000000","2.86725000"],["78286.50000000","0.05027000"],["78286.54000000","0.00014000"],["78287.80000000","0.19102000"],["78287.90000000","0.00014000"],["78287.91000000","0.06887000"],["78288.99000000","0.02352000"],["78289.84000000","0.00255000"],["78291.06000000","0.00000000"],["78291.44000000","0.00239000"],["78291.82000000","0.00000000"],["78294.37000000","0.00000000"],["78295.74000000","0.00000000"],["78299.66000000","0.00000000"],["78302.20000000","0.00000000"],["78310.03000000","0.00000000"],["78317.86000000","0.00000000"],["78321.13000000","0.02800000"],["78373.49000000","0.00000000"]]}}
{"rx":1788854542341334348, "m":{"e":"depthUpdate","E":1788854542314,"s":"BTCUSDT","U":99829861197,"u":99829861237,"b":[["78286.00000000","0.03062000"],["78285.30000000","0.00000000"],["78281.81000000","0.13932000"],["78252.00000000","0.73000000"],["78249.00000000","0.00000000"],["78203.88000000","0.32863000"],["78186.80000000","0.00000000"],["78175.30000000","0.07522000"],["77112.18000000","0.00032000"],["70457.83000000","0.00208000"]],"a":[["78286.50000000","0.05027000"],["78286.54000000","0.00000000"],["78287.80000000","0.19102000"],["78287.90000000","0.00000000"],["78287.91000000","0.06901000"],["78288.99000000","0.02366000"],["78303.05000000","0.00408000"],["78309.00000000","0.70400000"],["78323.51000000","0.03000000"],["78373.53000000","0.00000000"],["78380.37000000","1.63387000"],["78381.88000000","2.68103000"],["78403.99000000","0.05935000"],["78404.76000000","0.00000000"]]}}
{"rx":1788854542468994671, "m":{"e":"depthUpdate","E":1788854542414,"s":"BTCUSDT","U":99829861238,"u":99829861253,"b":[["78279.48000000","0.00000000"],["78277.69000000","0.00000000"],["78277.32000000","0.00000000"],["78277.30000000","0.01336000"],["78111.60000000","0.12781000"],["77112.18000000","0.00032000"],["62629.18000000","0.00279000"],["41213.30000000","0.00036000"]],"a":[["78384.63000000","0.00000000"]]}}
{"rx":1788854542568245572, "m":{"e":"depthUpdate","E":1788854542514,"s":"BTCUSDT","U":99829861254,"u":99829861281,"b":[["78286.47000000","3.45407000"],["78284.51000000","0.00000000"],["78283.80000000","0.00007000"],["78282.54000000","0.00000000"],["78281.67000000","0.00400000"],["78280.67000000","0.00000000"],["78278.33000000","0.00400000"],["78277.06000000","0.00000000"],["78275.53000000","0.00800000"],["78190.70000000","0.00408000"],["77292.28000000","0.00010000"],["77112.18000000","0.00032000"],["70457.83000000","0.00224000"]],"a":[["78286.48000000","5.16458000"],["78289.83000000","0.00171000"],["78293.45000000","0.00000000"],["78378.19000000","0.00000000"],["78379.85000000","0.00000000"],["78383.75000000","0.00000000"],["78403.99000000","0.03341000"],["78404.37000000","0.00000000"]]}}
{"rx":1788854542642438113, "m":{"e":"depthUpdate","E":1788854542614,"s":"BTCUSDT","U":99829861282,"u":99829861366,"b":[["78286.47000000","2.16337000"],["78286.46000000","0.02090000"],["78286.02000000","0.00026000"],["78286.01000000","0.00028000"],["78282.25000000","0.00000000"],["78282.24000000","0.00000000"],["78282.01000000","0.00014000"],["78281.82000000","0.00000000"],["78281.81000000","0.00014000"],["78281.67000000","0.00000000"],["78280.01000000","0.00007000"],["78279.81000000","0.00007000"],["78279.60000000","0.10181000"],["78278.56000000","0.00400000"],["78278.36000000","0.00000000"],["78278.33000000","0.00000000"],["78278.06000000","0.14435000"],["78278.00000000","0.03000000"],["78277.44000000","0.00069000"],["78277.43000000","0.00000000"],["78277.30000000","0.00000000"],["78275.99000000","0.00400000"],["78275.53000000","0.00000000"],["78274.19000000","0.00000000"],["78272.97000000","0.00000000"],["78272.44000000","0.00800000"],["78203.88000000","0.03373000"],["78200.43000000","0.00138000"],["77112.18000000","0.00032000"],["62629.18000000","0.00248000"],["61872.22000000","0.00000000"]],"a":[["78286.48000000","5.71069000"],["78287.73000000","0.00235000"],["78288.62000000","0.00000000"],["78289.49000000","0.00000000"],["78289.84000000","0.00000000"],["78291.44000000","0.00000000"],["78291.47000000","0.00800000"],["78292.49000000","0.00000000"],["78293.58000000","0.00000000"],["78297.50000000","0.00000000"],["78375.74000000","0.00000000"],["78406.90000000","0.07285000"],["79460.78000000","0.00030000"]]}}
{"rx":1788854542744468932, "m":{"e":"depthUpdate","E":1788854542714,"s":"BTCUSDT","U":99829861367,"u":99829861444,"b":[["78286.47000000","1.34252000"],["78286.46000000","0.02090000"],["78286.02000000","0.00040000"],["78286.01000000","0.02095000"],["78282.00000000","0.03014000"],["78281.81000000","0.00000000"],["78280.08000000","0.00206000"],["78280.04000000","0.06584000"],["78280.01000000","0.00000000"],["78280.00000000","0.03127000"],["78279.81000000","0.00014000"],["78279.60000000","0.11089000"],["78275.99000000","0.00000000"],["78274.34000000","0.00400000"],["78272.13000000","0.00008000"],["78271.58000000","0.00000000"],["77112.18000000","0.00032000"],["77000.00000000","95.20048000"],["70457.83000000","0.00240000"],["70457.82000000","0.00009000"]],"a":[["78286.48000000","5.71528000"],["78286.49000000","0.00090000"],["78287.07000000","0.00151000"],["78287.77000000","0.00000000"],["78288.96000000","0.00400000"],["78288.99000000","0.02366000"],["78291.47000000","0.01600000"],["78294.94000000","0.00000000"],["78304.99000000","0.63871000"],["78321.81000000","0.00400000"],["78325.17000000","0.00000000"],["78350.28000000","0.00000000"],["78371.53000000","0.00408000"],["82921.18000000","0.00010000"]]}}
{"rx":1788854542840056278, "m":{"e":"depthUpdate","E":1788854542814,"s":"BTCUSDT","U":99829861445,"u":99829861480,"b":[["78286.47000000","1.32046000"],["78286.46000000","0.02090000"],["78286.01000000","0.02109000"],["78282.08000000","0.00007000"],["78282.07000000","0.19232000"],["78282.06000000","0.13807000"],["78282.01000000","0.00000000"],["78282.00000000","0.03014000"],["78279.60000000","0.00000000"],["78271.59000000","0.00255000"],["78258.04000000","0.27969000"],["78111.60000000","0.00000000"],["77112.18000000","0.00040000"],["75120.00000000","0.04111000"],["70457.83000000","0.00256000"],["62629.18000000","0.00217000"]],"a":[["78286.48000000","5.71921000"]]}}
{"rx":1788854542938603178, "m":{"e":"depthUpdate","E":1788854542915,"s":"BTCUSDT","U":99829861481,"u":99829861511,"b":[["78286.47000000","1.32060000"],["78286.46000000","0.02104000"],["78286.01000000","0.06662000"],["78283.77000000","0.00588000"],["78283.01000000","0.00007000"],["78283.00000000","0.16144000"],["78282.07000000","0.11139000"],["78282.06000000","0.00000000"],["78280.00000000","0.03113000"],["78246.46000000","0.00667000"],["78061.22000000","0.00007000"],["78059.85000000","0.00802000"],["77112.18000000","0.00040000"],["70457.00000000","0.00000000"]],"a":[["78286.48000000","5.71928000"],["78298.22000000","0.00007000"]]}}
{"rx":1788854543046300943, "m":{"e":"depthUpdate","E":1788854543014,"s":"BTCUSDT","U":99829861512,"u":99829861534,"b":[["78286.01000000","0.02109000"],["78283.77000000","0.00588000"],["78283.01000000","0.00000000"],["78283.00000000","0.00014000"],["78282.07000000","0.11125000"],["78271.62000000","0.00255000"],["78271.59000000","0.00000000"],["77112.18000000","0.00040000"],["77112.17000000","0.00030000"],["70457.83000000","0.00272000"],["62629.18000000","0.00310000"]],"a":[]}}
{"rx":1788854543147116652, "m":{"e":"depthUpdate","E":1788854543114,"s":"BTCUSDT","U":99829861535,"u":99829861549,"b":[["78286.47000000","1.32053000"],["78286.46000000","0.02097000"],["78283.77000000","0.00588000"],["78283.00000000","0.00000000"],["78282.07000000","0.11139000"],["78190.70000000","0.00000000"],["78186.70000000","0.00408000"],["77112.18000000","0.00032000"],["62630.00000000","0.01796000"]],"a":[["78371.53000000","0.00000000"]]}}
{"rx":1788854543257694954, "m":{"e":"depthUpdate","E":1788854543214,"s":"BTCUSDT","U":99829861550,"u":99829861592,"b":[["78286.47000000","1.31933000"],["78286.46000000","0.02104000"],["78286.01000000","0.06853000"],["78284.58000000","0.13646000"],["78282.77000000","0.00007000"],["78282.76000000","0.00000000"],["78271.62000000","0.00000000"],["78271.56000000","0.00255000"],["78197.80000000","1.00235000"],["78111.47000000","0.12781000"],["77112.18000000","0.00032000"],["70457.83000000","0.00288000"],["70457.82000000","0.00000000"],["70457.81000000","0.00009000"],["62630.00000000","0.01596000"],["62629.18000000","0.00279000"],["41213.30000000","0.00000000"]],"a":[["78286.48000000","5.73991000"],["78286.49000000","0.00097000"],["78286.83000000","0.01324000"],["78290.75000000","0.01315000"],["78294.31000000","0.22663000"],["78294.67000000","0.01327000"],["78298.59000000","0.01333000"],["78302.14000000","0.02325000"],["78302.51000000","0.01292000"],["78309.97000000","0.02358000"],["78317.80000000","0.02368000"]]}}
{"rx":1788854543346904088, "m":{"e":"depthUpdate","E":1788854543314,"s":"BTCUSDT","U":99829861593,"u":99829861621,"b":[["78286.47000000","1.31933000"],["78286.46000000","0.02104000"],["78286.00000000","0.03062000"],["78284.59000000","0.00014000"],["78282.77000000","0.00000000"],["78282.08000000","0.00000000"],["78271.59000000","0.00255000"],["78271.56000000","0.00000000"],["78170.75000000","0.24761000"],["77112.18000000","0.00032000"],["62629.00000000","0.00000000"]],"a":[["78286.55000000","0.05014000"],["78286.83000000","0.01338000"],["78288.99000000","0.02352000"],["78402.68000000","0.04375000"],["78406.90000000","0.00000000"]]}}
{"rx":1788854543441257838, "m":{"e":"depthUpdate","E":1788854543414,"s":"BTCUSDT","U":99829861622,"u":99829861631,"b":[["78271.62000000","0.00255000"],["78271.59000000","0.00000000"],["77112.18000000","0.00032000"],["70457.83000000","0.00304000"],["62629.18000000","0.00248000"]],"a":[]}}
{"rx":1788854543537604559, "m":{"e":"depthUpdate","E":1788854543515,"s":"BTCUSDT","U":99829861632,"u":99829861638,"b":[["78186.70000000","0.00000000"],["77112.18000000","0.00032000"],["70457.83000000","0.00320000"],["70457.81000000","0.00000000"]],"a":[["78286.48000000","5.73875000"],["78373.42000000","0.00408000"]]}}
{"rx":1788854543636982709, "m":{"e":"depthUpdate","E":1788854543614,"s":"BTCUSDT","U":99829861639,"u":99829861644,"b":[["77112.18000000","0.00032000"],["62629.18000000","0.00217000"],["62629.00000000","0.00200000"]],"a":[["79460.78000000","0.00030000"]]}}
{"rx":1788854543748568763, "m":{"e":"depthUpdate","E":1788854543714,"s":"BTCUSDT","U":99829861645,"u":99829861648,"b":[["77112.18000000","0.00032000"],["70457.83000000","0.00336000"],["62629.00000000","0.00000000"]],"a":[]}}
{"rx":1788854543838100392, "m":{"e":"depthUpdate","E":1788854543814,"s":"BTCUSDT","U":99829861649,"u":99829861650,"b":[["77112.18000000","0.00040000"],["62629.18000000","0.00186000"]],"a":[]}}
{"rx":1788854543940336537, "m":{"e":"depthUpdate","E":1788854543914,"s":"BTCUSDT","U":99829861651,"u":99829861674,"b":[["78286.47000000","1.16337000"],["78286.46000000","0.02097000"],["78286.01000000","0.02109000"],["78284.59000000","0.00000000"],["78284.58000000","0.00008000"],["78282.08000000","0.00007000"],["78186.74000000","0.00408000"],["78180.00000000","0.05120000"],["78172.02000000","0.03961000"],["78170.75000000","0.00000000"],["77112.18000000","0.00040000"],["70457.83000000","0.00352000"],["70457.82000000","0.00009000"]],"a":[["78286.48000000","5.73868000"],["78286.54000000","0.00255000"],["78287.73000000","0.00000000"],["78298.22000000","0.00007000"],["78402.68000000","0.07269000"],["78450.00000000","0.25049000"]]}}
{"rx":1788854544040126049, "m":{"e":"depthUpdate","E":1788854544014,"s":"BTCUSDT","U":99829861675,"u":99829861705,"b":[["78286.00000000","0.03062000"],["78273.61000000","0.00638000"],["78272.14000000","0.00000000"],["78222.75000000","0.00000000"],["78222.38000000","0.00319000"],["78212.02000000","0.00000000"],["78211.12000000","0.00318000"],["78138.11000000","0.00000000"],["78132.45000000","0.00127000"],["78112.50000000","0.12781000"],["78111.47000000","0.00000000"],["77112.18000000","0.00040000"],["77112.17000000","0.00030000"],["70457.00000000","0.00020000"],["62629.18000000","0.00279000"]],"a":[["78286.48000000","5.73868000"],["78286.49000000","0.00097000"],["78287.77000000","0.00638000"],["78289.37000000","0.00638000"],["78292.82000000","0.00000000"],["78295.00000000","0.00000000"],["78339.99000000","0.00319000"],["78345.81000000","0.00000000"],["78354.09000000","0.00319000"],["78359.99000000","0.00000000"],["78402.68000000","0.10344000"],["78419.98000000","0.00127000"],["78423.99000000","0.00000000"],["78432.48000000","0.00127000"],["78437.98000000","0.00000000"]]}}
{"rx":1788854544137992261, "m":{"e":"depthUpdate","E":1788854544114,"s":"BTCUSDT","U":99829861706,"u":99829861725,"b":[["78286.01000000","0.05548000"],["78282.55000000","0.00007000"],["78282.54000000","0.12412000"],["78275.34000000","0.00000000"],["78199.53000000","0.00000000"],["78112.50000000","0.00000000"],["78111.60000000","0.12781000"],["77112.18000000","0.00032000"],["70457.83000000","0.00368000"],["70457.00000000","0.00000000"]],"a":[["78286.48000000","5.73875000"],["78286.49000000","0.00104000"],["78287.74000000","0.01974000"],["78287.77000000","0.00652000"],["78287.91000000","0.06887000"]]}}
{"rx":1788854544256917579, "m":{"e":"depthUpdate","E":1788854544214,"s":"BTCUSDT","U":99829861726,"u":99829861751,"b":[["78286.47000000","1.16344000"],["78286.46000000","0.02104000"],["78284.25000000","0.00014000"],["78284.24000000","0.12779000"],["78283.77000000","0.00588000"],["78282.55000000","0.00000000"],["78282.54000000","0.00000000"],["78282.08000000","0.00000000"],["78275.26000000","0.01330000"],["77112.18000000","0.00032000"],["70457.83000000","0.00384000"],["62629.18000000","0.00248000"]],"a":[["78286.48000000","5.73875000"],["78286.49000000","0.00097000"],["78286.54000000","0.00000000"],["78287.06000000","0.00000000"],["78287.73000000","0.00255000"]]}}
{"rx":1788854544340985454, "m":{"e":"depthUpdate","E":1788854544314,"s":"BTCUSDT","U":99829861752,"u":99829861792,"b":[["78286.47000000","1.31635000"],["78286.46000000","0.02104000"],["78286.00000000","0.03062000"],["78285.09000000","0.00014000"],["78285.08000000","0.15165000"],["78284.25000000","0.00000000"],["78284.24000000","0.00014000"],["78283.77000000","0.00574000"],["78186.74000000","0.00000000"],["77112.18000000","0.00032000"]],"a":[["78286.48000000","5.73234000"],["78286.49000000","0.00111000"],["78286.54000000","0.00014000"],["78286.70000000","0.00255000"],["78287.39000000","0.00400000"],["78337.99000000","0.00317000"],["78342.83000000","0.00000000"],["78415.99000000","0.00127000"],["78433.99000000","0.00000000"]]}}
{"rx":1788854544437378612, "m":{"e":"depthUpdate","E":1788854544414,"s":"BTCUSDT","U":99829861793,"u":99829861827,"b":[["78286.47000000","2.17107000"],["78286.01000000","0.02109000"],["78286.00000000","0.03062000"],["78285.09000000","0.00000000"],["78285.08000000","0.00014000"],["78284.24000000","0.00000000"],["78282.08000000","0.00007000"],["78278.08000000","0.00400000"],["78274.34000000","0.00000000"],["77112.18000000","0.00032000"],["70457.83000000","0.00400000"],["62629.18000000","0.00217000"]],"a":[["78286.48000000","5.18829000"],["78286.70000000","0.00000000"],["78286.72000000","0.00255000"],["78287.73000000","0.00000000"],["78287.77000000","0.00014000"],["78288.58000000","0.00255000"],["78288.96000000","0.00000000"],["78289.37000000","0.00000000"],["78289.96000000","0.00400000"],["78290.74000000","0.00638000"],["78291.44000000","0.00638000"]]}}
{"rx":1788854544543329568, "m":{"e":"depthUpdate","E":1788854544514,"s":"BTCUSDT","U":99829861828,"u":99829861878,"b":[["78286.47000000","2.17100000"],["78286.46000000","0.02097000"],["78286.00000000","0.03062000"],["78285.08000000","0.00000000"],["78283.77000000","0.00588000"],["78203.88000000","0.32864000"],["78200.43000000","1.00373000"],["78197.80000000","0.00000000"],["77112.18000000","0.00032000"],["70457.83000000","0.00384000"],["70457.00000000","0.00000000"],["62629.18000000","0.00341000"]],"a":[["78286.48000000","5.18822000"],["78286.49000000","0.00090000"],["78286.72000000","0.00000000"],["78286.73000000","0.00255000"],["78287.39000000","0.00000000"],["78287.74000000","0.01974000"],["78287.77000000","0.00000000"],["78287.91000000","0.06901000"],["78288.75000000","0.00400000"],["78289.96000000","0.00000000"],["78290.88000000","0.00400000"]]}}
{"rx":1788854544654212020, "m":{"e":"depthUpdate","E":1788854544614,"s":"BTCUSDT","U":99829861879,"u":99829861902,"b":[["78181.89000000","0.20000000"],["78161.52000000","0.00000000"],["78161.51000000","0.00000000"],["77112.18000000","0.00032000"],["70457.83000000","0.00384000"],["62629.18000000","0.00310000"],["62629.00000000","0.00000000"]],"a":[["78286.48000000","5.18822000"],["78286.49000000","0.00090000"],["78286.73000000","0.00000000"],["78286.74000000","0.00255000"],["78328.01000000","0.01322000"],["78364.07000000","0.20000000"],["78381.49000000","2.38905000"],["79460.78000000","0.00000000"]]}}
{"rx":1788854544742255877, "m":{"e":"depthUpdate","E":1788854544714,"s":"BTCUSDT","U":99829861903,"u":99829861916,"b":[["78278.46000000","0.00000000"],["78277.56000000","0.00000000"],["78277.35000000","0.00000000"],["78186.81000000","0.00408000"],["78061.22000000","0.00809000"],["78059.85000000","0.00000000"],["77112.18000000","0.00032000"],["70457.83000000","0.00400000"]],"a":[["78286.48000000","5.18829000"],["78286.49000000","0.00097000"],["79460.78000000","0.00030000"]]}}
{"rx":1788854544839567880, "m":{"e":"depthUpdate","E":1788854544814,"s":"BTCUSDT","U":99829861917,"u":99829861927,"b":[["78286.47000000","2.17086000"],["78280.08000000","0.00000000"],["78280.04000000","0.00000000"],["78271.62000000","0.00000000"],["77112.18000000","0.00040000"],["70457.83000000","0.00384000"],["62629.18000000","0.00279000"]],"a":[["78286.74000000","0.00000000"],["78286.83000000","0.00014000"]]}}
{"rx":1788854544945327216, "m":{"e":"depthUpdate","E":1788854544914,"s":"BTCUSDT","U":99829861928,"u":99829861968,"b":[["78286.47000000","1.79006000"],["78282.00000000","0.03014000"],["78272.70000000","0.00255000"],["78250.00000000","0.06897000"],["77112.18000000","0.00040000"],["77000.00000000","95.20041000"],["70457.83000000","0.00400000"],["70457.82000000","0.00000000"],["70457.81000000","0.00009000"]],"a":[["78286.48000000","5.19006000"],["78286.55000000","0.05014000"],["78286.83000000","0.00000000"],["78287.23000000","0.01339000"],["78288.35000000","0.00255000"],["78288.99000000","0.02366000"],["78298.22000000","0.00000000"]]}}
{"rx":1788854545039027660, "m":{"e":"depthUpdate","E":1788854545014,"s":"BTCUSDT","U":99829861969,"u":99829861992,"b":[["78286.47000000","1.78998000"],["78275.83000000","0.00638000"],["78273.61000000","0.00000000"],["77112.18000000","0.00040000"],["77112.17000000","0.00030000"],["72040.91000000","0.00014000"],["70457.83000000","0.00384000"],["70457.00000000","0.00010000"],["62629.18000000","0.00248000"]],"a":[["78286.55000000","0.05014000"],["78287.23000000","0.01353000"],["78288.99000000","0.02352000"],["78289.82000000","0.00638000"],["78291.44000000","0.00000000"],["78298.22000000","0.00007000"],["78300.77000000","0.04400000"],["78301.57000000","0.03800000"]]}}
{"rx":1788854545139296822, "m":{"e":"depthUpdate","E":1788854545114,"s":"BTCUSDT","U":99829861993,"u":99829862011,"b":[["78286.47000000","1.99240000"],["78275.83000000","0.00000000"],["78275.53000000","0.00638000"],["77112.18000000","0.00032000"],["70457.83000000","0.00384000"],["70457.00000000","0.00000000"]],"a":[["78286.48000000","5.19006000"],["78286.49000000","0.00090000"],["78289.82000000","0.00000000"],["78290.23000000","0.00638000"],["78308.64000000","0.00000000"],["78309.44000000","0.00000000"]]}}
{"rx":1788854545246482015, "m":{"e":"depthUpdate","E":1788854545214,"s":"BTCUSDT","U":99829862012,"u":99829862028,"b":[["78286.47000000","2.25329000"],["77112.18000000","0.00032000"],["70457.81000000","0.00000000"],["70457.00000000","0.00000000"],["62629.18000000","0.00217000"]],"a":[["78287.23000000","0.00014000"],["78287.43000000","0.00000000"],["78288.75000000","0.00000000"],["78290.02000000","0.00400000"],["78290.23000000","0.00000000"],["78290.74000000","0.00000000"],["78290.87000000","0.00638000"],["78291.44000000","0.00638000"],["78350.32000000","0.00290000"]]}}
{"rx":1788854545352258824, "m":{"e":"depthUpdate","E":1788854545314,"s":"BTCUSDT","U":99829862029,"u":99829862062,"b":[["78262.99000000","0.00000000"],["78246.00000000","0.03400000"],["78245.80000000","0.00000000"],["78238.69000000","0.00000000"],["78090.14000000","0.00000000"],["78089.46000000","0.02320000"],["77112.18000000","0.00032000"],["70457.83000000","0.00384000"],["70457.00000000","0.00000000"],["62629.00000000","0.00000000"]],"a":[["78286.48000000","5.18790000"],["78286.49000000","0.00090000"],["78286.55000000","0.05014000"],["78287.23000000","0.00000000"],["78287.68000000","0.01320000"],["78288.99000000","0.02366000"],["78296.27000000","0.00189000"],["78314.18000000","0.00000000"],["78324.34000000","0.00000000"],["78379.25000000","2.68103000"],["78381.88000000","0.00000000"]]}}
{"rx":1788854545444135114, "m":{"e":"depthUpdate","E":1788854545414,"s":"BTCUSDT","U":99829862063,"u":99829862082,"b":[["78286.47000000","2.25399000"],["78277.44000000","0.00000000"],["77112.18000000","0.00032000"],["70457.83000000","0.00400000"],["70457.00000000","0.00000000"],["62629.18000000","0.00186000"]],"a":[["78286.48000000","5.18777000"],["78286.55000000","0.05014000"],["78287.68000000","0.01334000"],["78288.99000000","0.02352000"],["78305.39000000","0.03800000"],["78376.99000000","1.88801000"],["78380.37000000","0.82020000"]]}}
{"rx":1788854545537440917, "m":{"e":"depthUpdate","E":1788854545514,"s":"BTCUSDT","U":99829862083,"u":99829862182,"b":[["78286.47000000","2.72907000"],["78286.46000000","0.00069000"],["78284.02000000","0.00000000"],["78284.01000000","0.00000000"],["78283.80000000","0.00014000"],["78282.08000000","0.00000000"],["78278.56000000","0.00000000"],["78278.07000000","1.86166000"],["78277.48000000","0.00070000"],["78274.12000000","1.86166000"],["78272.70000000","0.00000000"],["78209.46000000","0.00000000"],["77112.18000000","0.00032000"],["72040.91000000","0.00000000"],["70457.83000000","0.00384000"],["70457.00000000","0.00000000"],["62629.18000000","0.00310000"]],"a":[["78286.48000000","0.77249000"],["78287.68000000","0.00014000"],["78287.78000000","0.00014000"],["78287.79000000","0.00277000"],["78287.80000000","0.00194000"],["78288.35000000","0.00000000"],["78289.50000000","0.00000000"],["78289.51000000","0.00000000"],["78290.52000000","0.00000000"],["78291.45000000","0.00000000"],["78291.49000000","0.00000000"],["78293.48000000","1.95060000"],["78293.49000000","0.00000000"],["78293.50000000","0.00000000"],["78294.31000000","0.22780000"],["78297.26000000","0.00000000"],["78297.45000000","0.04400000"],["78297.47000000","0.00000000"],["78300.54000000","2.42695000"],["78301.50000000","0.00000000"],["78301.57000000","0.05800000"],["78302.14000000","0.02442000"],["78302.75000000","0.00000000"],["78304.99000000","0.00000000"],["78309.97000000","0.02475000"],["78313.26000000","0.00000000"],["78317.80000000","0.02485000"],["78337.99000000","0.00000000"],["78349.89000000","3.56127000"],["78370.68000000","2.29924000"]]}}
{"rx":1788854545642469102, "m":{"e":"depthUpdate","E":1788854545614,"s":"BTCUSDT","U":99829862183,"u":99829862654,"b":[["78286.47000000","3.61676000"],["78286.46000000","0.00027000"],["78286.45000000","0.05013000"],["78286.40000000","0.05000000"],["78286.02000000","0.00026000"],["78286.01000000","0.11608000"],["78285.40000000","0.31943000"],["78284.97000000","0.00026000"],["78284.59000000","0.00000000"],["78284.26000000","0.00000000"],["78284.25000000","0.00400000"],["78284.23000000","0.00400000"],["78284.02000000","0.00000000"],["78284.01000000","0.00000000"],["78283.81000000","0.00400000"],["78283.46000000","0.00000000"],["78283.37000000","0.01286000"],["78283.17000000","0.02094000"],["78282.09000000","0.81857000"],["78282.08000000","1.86166000"],["78282.07000000","0.00014000"],["78281.97000000","0.03057000"],["78281.30000000","0.01302000"],["78281.09000000","0.00000000"],["78280.68000000","0.00150000"],["78280.00000000","0.03127000"],["78279.61000000","0.37581000"],["78279.59000000","0.00014000"],["78279.20000000","0.01311000"],["78279.18000000","0.02138000"],["78278.08000000","0.63338000"],["78278.06000000","0.00000000"],["78277.76000000","0.00000000"],["78277.51000000","0.00000000"],["78277.48000000","0.00000000"],["78276.24000000","0.00000000"],["78275.53000000","0.00000000"],["78275.03000000","0.00000000"],["78274.13000000","1.55353000"],["78274.11000000","0.00000000"],["78273.10000000","0.00000000"],["78272.44000000","0.00000000"],["78272.29000000","0.00024000"],["78272.28000000","2.29924000"],["78272.21000000","0.00000000"],["78270.07000000","0.38340000"],["78269.44000000","0.31941000"],["78265.78000000","0.00000000"],["78258.01000000","0.00000000"],["78257.29000000","0.00000000"],["78255.34000000","0.00000000"],["78255.00000000","0.00400000"],["78253.73000000","0.34513000"],["78252.26000000","0.00000000"],["78251.43000000","0.00000000"],["78250.06000000","0.00335000"],["78248.94000000","0.00000000"],["78246.14000000","1.26561000"],["78246.00000000","0.03000000"],["78245.06000000","0.00000000"],["78235.96000000","0.00000000"],["78232.65000000","0.00000000"],["78231.73000000","0.00000000"],["78220.25000000","0.00000000"],["78209.47000000","0.00000000"],["78203.88000000","0.24764000"],["78199.53000000","0.07665000"],["78148.19000000","1.53085000"],["78133.93000000","0.00000000"],["78094.78000000","0.00000000"],["77112.18000000","0.00032000"],["70457.83000000","0.00409000"],["62629.18000000","0.00279000"]],"a":[["78286.48000000","0.22343000"],["78286.49000000","0.00055000"],["78286.50000000","0.00027000"],["78286.54000000","0.00000000"],["78286.55000000","0.00014000"],["78287.07000000","0.00000000"],["78287.68000000","0.00000000"],["78287.69000000","0.00000000"],["78287.73000000","0.00014000"],["78287.74000000","0.01974000"],["78287.78000000","0.00000000"],["78287.79000000","0.00263000"],["78287.80000000","0.00180000"],["78287.91000000","0.00014000"],["78288.32000000","0.00000000"],["78288.58000000","0.00000000"],["78288.98000000","0.00007000"],["78288.99000000","0.02366000"],["78289.23000000","0.00000000"],["78289.59000000","0.00014000"],["78289.83000000","0.00000000"],["78290.02000000","0.00000000"],["78290.24000000","0.02366000"],["78290.48000000","0.06865000"],["78290.75000000","0.00014000"],["78290.87000000","0.00000000"],["78290.88000000","0.00000000"],["78291.44000000","0.00000000"],["78291.46000000","0.00000000"],["78291.47000000","0.00000000"],["78291.48000000","0.00000000"],["78291.51000000","0.00000000"],["78291.55000000","0.00000000"],["78291.56000000","0.00000000"],["78291.78000000","0.00007000"],["78292.00000000","0.03000000"],["78292.31000000","0.00000000"],["78292.32000000","0.00000000"],["78292.33000000","0.00787000"],["78292.83000000","0.00000000"],["78293.48000000","0.00000000"],["78293.60000000","0.47753000"],["78294.31000000","0.20616000"],["78294.49000000","0.00000000"],["78294.61000000","0.00000000"],["78294.66000000","0.00000000"],["78294.67000000","0.00000000"],["78294.81000000","0.00000000"],["78294.89000000","0.00000000"],["78295.08000000","0.02081000"],["78295.14000000","0.00000000"],["78295.15000000","0.00000000"],["78295.30000000","0.00000000"],["78295.35000000","0.00000000"],["78295.38000000","0.00000000"],["78295.77000000","0.00007000"],["78295.88000000","0.00000000"],["78296.04000000","0.00069000"],["78296.20000000","0.00000000"],["78296.27000000","0.00189000"],["78296.28000000","0.70201000"],["78296.33000000","0.00000000"],["78296.73000000","0.00000000"],["78297.09000000","0.00000000"],["78297.42000000","0.00000000"],["78297.44000000","0.00047000"],["78297.45000000","1.95060000"],["78297.46000000","0.00000000"],["78297.49000000","0.00000000"],["78297.99000000","0.00000000"],["78298.21000000","0.00052000"],["78298.25000000","0.00000000"],["78298.57000000","0.00000000"],["78298.58000000","1.41250000"],["78299.03000000","0.00400000"],["78299.28000000","0.00000000"],["78299.35000000","0.00000000"],["78299.41000000","0.00000000"],["78299.45000000","0.00026000"],["78299.76000000","0.00007000"],["78299.96000000","0.00047000"],["78299.99000000","0.00000000"],["78300.15000000","0.00000000"],["78300.34000000","0.00000000"],["78300.35000000","0.00000000"],["78300.36000000","0.00055000"],["78300.53000000","2.29924000"],["78300.54000000","0.00000000"],["78300.77000000","0.00000000"],["78300.85000000","0.00000000"],["78301.02000000","0.00400000"],["78301.40000000","0.00000000"],["78301.42000000","0.00000000"],["78301.46000000","0.00000000"],["78301.57000000","0.00000000"],["78302.03000000","0.00000000"],["78302.18000000","0.00000000"],["78302.45000000","0.00000000"],["78303.75000000","0.00014000"],["78303.99000000","0.00638000"],["78304.25000000","0.01000000"],["78304.31000000","0.00000000"],["78304.35000000","0.02000000"],["78304.60000000","0.00000000"],["78304.61000000","0.00000000"],["78304.75000000","0.12000000"],["78305.08000000","0.00638000"],["78305.09000000","0.00000000"],["78305.31000000","0.00000000"],["78305.32000000","0.00000000"],["78305.57000000","0.00151000"],["78306.76000000","0.00000000"],["78307.74000000","0.00014000"],["78307.80000000","0.00000000"],["78307.94000000","0.01600000"],["78308.99000000","0.00000000"],["78309.00000000","0.00400000"],["78309.85000000","0.00000000"],["78310.59000000","0.16897000"],["78310.67000000","0.02400000"],["78310.97000000","0.00000000"],["78311.79000000","0.00000000"],["78312.51000000","0.00000000"],["78312.75000000","0.00000000"],["78312.76000000","0.00000000"],["78313.25000000","0.00000000"],["78314.34000000","0.00000000"],["78314.41000000","0.00000000"],["78314.99000000","0.31941000"],["78315.11000000","0.31944000"],["78319.10000000","0.00049000"],["78319.11000000","0.31944000"],["78319.87000000","0.52098000"],["78321.13000000","0.00000000"],["78321.61000000","0.00063000"],["78323.02000000","0.31944000"],["78323.37000000","0.00000000"],["78325.47000000","0.00000000"],["78325.72000000","0.75723000"],["78325.73000000","0.00000000"],["78327.00000000","0.00400000"],["78327.69000000","0.00007000"],["78329.25000000","0.00400000"],["78331.50000000","0.00400000"],["78331.68000000","0.00007000"],["78335.24000000","1.26417000"],["78335.35000000","0.00007000"],["78335.67000000","0.00007000"],["78336.00000000","0.03400000"],["78336.75000000","0.00000000"],["78337.99000000","0.00317000"],["78339.66000000","2.00664000"],["78340.50000000","0.00400000"],["78343.27000000","0.34473000"],["78344.18000000","1.01544000"],["78358.58000000","0.00000000"],["78359.57000000","0.00223000"],["78375.90000000","2.29924000"],["78376.99000000","1.25837000"],["78379.25000000","0.00000000"],["78380.39000000","0.00000000"],["78402.68000000","0.00000000"],["78415.99000000","0.00127000"],["78431.39000000","0.00000000"],["78431.40000000","0.00000000"],["78443.99000000","0.47364000"],["78445.71000000","1.53085000"],["78450.03000000","0.03057000"],["78461.80000000","0.03057000"],["78498.37000000","0.00000000"],["78498.89000000","0.00000000"],["78682.80000000","0.00007000"]]}}
{"rx":1788854545737329733, "m":{"e":"depthUpdate","E":1788854545714,"s":"BTCUSDT","U":99829862655,"u":99829862794,"b":[["78286.47000000","3.61755000"],["78286.45000000","0.05027000"],["78286.40000000","0.05014000"],["78286.03000000","0.68456000"],["78286.02000000","1.86192000"],["78286.01000000","0.00014000"],["78286.00000000","0.03062000"],["78285.40000000","0.31957000"],["78283.81000000","0.00000000"],["78283.77000000","0.00588000"],["78283.37000000","0.01300000"],["78282.11000000","1.46474000"],["78282.10000000","2.30724000"],["78282.09000000","0.00000000"],["78282.07000000","0.00000000"],["78282.00000000","0.03000000"],["78280.00000000","0.03113000"],["78279.59000000","0.00000000"],["78277.17000000","0.38336000"],["78268.20000000","0.02462000"],["78262.61000000","0.00000000"],["78239.15000000","0.00000000"],["78218.64000000","0.00000000"],["78218.63000000","0.00000000"],["78180.27000000","0.03961000"],["78172.02000000","0.00000000"],["78103.29000000","3.84219000"],["77112.18000000","0.00032000"],["70457.83000000","0.00393000"]],"a":[["78286.48000000","0.23694000"],["78286.49000000","0.00062000"],["78286.50000000","0.00013000"],["78286.55000000","0.00000000"],["78287.74000000","0.01974000"],["78287.91000000","0.00000000"],["78288.99000000","0.02366000"],["78289.59000000","0.00000000"],["78290.24000000","0.02366000"],["78290.48000000","0.00014000"],["78290.75000000","0.00000000"],["78291.99000000","0.03196000"],["78292.00000000","0.03014000"],["78292.33000000","0.00801000"],["78292.65000000","0.06865000"],["78293.60000000","0.00014000"],["78294.00000000","0.03014000"],["78294.31000000","0.20616000"],["78295.07000000","0.29486000"],["78296.26000000","0.47760000"],["78296.27000000","0.01789000"],["78296.28000000","0.00000000"],["78297.45000000","0.00000000"],["78299.76000000","0.00014000"],["78300.70000000","0.00000000"],["78301.41000000","0.00000000"],["78301.52000000","0.00000000"],["78303.85000000","0.00000000"],["78305.39000000","0.00000000"],["78305.46000000","0.00000000"],["78307.94000000","0.00800000"],["78414.32000000","0.00000000"],["78415.17000000","0.10344000"],["78429.94000000","0.00107000"],["78479.79000000","0.00000000"],["79460.78000000","0.00030000"]]}}
{"rx":1788854545837144412, "m":{"e":"depthUpdate","E":1788854545814,"s":"BTCUSDT","U":99829862795,"u":99829862855,"b":[["78286.40000000","0.05014000"],["78286.03000000","0.68470000"],["78286.02000000","1.86206000"],["78286.01000000","0.00000000"],["78284.97000000","0.00000000"],["78283.37000000","0.01286000"],["78263.62000000","0.88547000"],["77112.18000000","0.00040000"],["70457.83000000","0.00384000"],["70457.82000000","0.00009000"],["62629.18000000","0.00248000"]],"a":[["78286.48000000","0.24955000"],["78290.24000000","0.02366000"],["78290.48000000","0.00000000"],["78291.42000000","0.00026000"],["78291.99000000","0.03210000"],["78292.33000000","0.00801000"],["78292.65000000","0.06879000"],["78293.60000000","0.00000000"],["78296.27000000","0.00189000"],["78296.60000000","0.01277000"],["78298.57000000","0.01600000"],["78311.36000000","0.04200000"],["78321.08000000","0.00000000"],["78335.70000000","0.00223000"],["78344.90000000","0.88456000"],["78359.57000000","0.00000000"],["78376.88000000","0.04200000"],["78416.96000000","0.02001000"]]}}
{"rx":1788854545950732352, "m":{"e":"depthUpdate","E":1788854545914,"s":"BTCUSDT","U":99829862856,"u":99829862888,"b":[["78282.11000000","0.77842000"],["78282.10000000","0.00800000"],["78276.38000000","0.00000000"],["78268.37000000","0.50485000"],["78258.20000000","0.00000000"],["78246.70000000","0.87732000"],["78244.07000000","1.01061000"],["78218.96000000","0.00000000"],["78218.60000000","2.29924000"],["78186.81000000","0.00000000"],["78066.67000000","0.00802000"],["78061.22000000","0.00007000"],["77112.18000000","0.00040000"],["70457.83000000","0.00400000"]],"a":[["78286.48000000","0.24861000"],["78287.81000000","0.00007000"],["78288.59000000","0.00000000"],["78292.77000000","0.00206000"],["78294.29000000","0.48980000"],["78294.30000000","0.47753000"],["78295.06000000","0.00000000"],["78295.07000000","0.00000000"],["78295.71000000","0.00007000"],["78296.26000000","0.00007000"],["78303.05000000","0.00000000"],["78311.22000000","0.37581000"],["78373.42000000","0.00000000"],["78375.56000000","0.00408000"],["78416.96000000","0.00000000"]]}}
{"rx":1788854546039716313, "m":{"e":"depthUpdate","E":1788854546014,"s":"BTCUSDT","U":99829862889,"u":99829862941,"b":[["78286.47000000","3.61445000"],["78285.41000000","0.00638000"],["77112.18000000","0.00040000"],["77112.17000000","0.00030000"],["70457.83000000","0.00384000"],["62629.18000000","0.00341000"]],"a":[["78294.00000000","0.03014000"],["78294.28000000","0.47753000"],["78294.29000000","0.47288000"],["78294.30000000","0.00000000"],["78296.25000000","0.00028000"],["78296.27000000","0.00189000"],["78296.28000000","0.00000000"],["78297.99000000","0.00000000"],["78298.21000000","0.00000000"],["78298.22000000","0.00007000"],["78298.56000000","0.00638000"],["78299.95000000","0.00638000"],["78303.99000000","0.00000000"],["78305.08000000","0.00000000"],["78310.58000000","0.03600000"],["78310.65000000","0.04400000"],["78311.46000000","0.03800000"],["78314.48000000","0.02600000"],["78315.39000000","0.03400000"],["78325.13000000","0.00000000"],["78333.75000000","0.00400000"],["78335.67000000","0.00000000"],["78340.50000000","0.00000000"],["78375.78000000","0.03600000"],["78379.67000000","0.02600000"],["78380.59000000","0.03400000"],["78384.48000000","0.04400000"],["78386.83000000","0.03800000"],["78432.55000000","0.00000000"],["78475.79000000","0.02001000"]]}}
{"rx":1788854546138363781, "m":{"e":"depthUpdate","E":1788854546114,"s":"BTCUSDT","U":99829862942,"u":99829863203,"b":[["78287.73000000","12.06117000"],["78287.72000000","0.00027000"],["78287.71000000","0.00013000"],["78287.70000000","0.05000000"],["78287.65000000","0.05000000"],["78286.50000000","0.00400000"],["78286.49000000","0.00000000"],["78286.48000000","0.86902000"],["78286.47000000","0.20741000"],["78286.46000000","0.00000000"],["78286.45000000","0.00014000"],["78286.40000000","0.00014000"],["78286.04000000","0.00800000"],["78286.03000000","0.00014000"],["78286.00000000","0.03062000"],["78285.41000000","0.00652000"],["78284.23000000","0.00000000"],["78284.00000000","0.03000000"],["78283.77000000","0.00574000"],["78282.10000000","0.00000000"],["78278.09000000","0.15190000"],["78269.60000000","0.00000000"],["78251.25000000","0.00000000"],["78248.00000000","0.04000000"],["78247.89000000","0.00000000"],["78247.00000000","0.00000000"],["78223.58000000","0.00408000"],["77581.89000000","0.00000000"],["77112.18000000","0.00000000"],["77112.17000000","0.00000000"],["70693.31000000","3.37566000"],["70458.96000000","0.00016000"],["70457.83000000","0.00000000"],["70457.82000000","0.00000000"],["62630.00000000","0.01796000"]],"a":[["78286.48000000","0.00000000"],["78286.49000000","0.00000000"],["78286.50000000","0.00000000"],["78287.73000000","0.00000000"],["78287.74000000","0.05093000"],["78287.75000000","0.00049000"],["78287.79000000","0.00256000"],["78288.98000000","0.00014000"],["78291.99000000","0.00014000"],["78292.10000000","0.06584000"],["78294.00000000","0.03014000"],["78294.27000000","0.31738000"],["78294.28000000","0.00014000"],["78294.29000000","0.00000000"],["78294.31000000","0.00366000"],["78295.08000000","0.00000000"],["78295.56000000","0.44143000"],["78295.57000000","0.20250000"],["78296.25000000","0.00000000"],["78296.60000000","0.00000000"],["78297.09000000","0.00028000"],["78298.42000000","0.47752000"],["78298.56000000","0.00000000"],["78299.03000000","0.00000000"],["78299.93000000","0.00400000"],["78299.94000000","0.00638000"],["78299.95000000","0.00000000"],["78301.42000000","0.00638000"],["78320.37000000","0.00000000"],["78326.00000000","0.03000000"],["78327.00000000","0.01400000"],["78339.99000000","0.00000000"],["78341.66000000","0.00317000"],["78354.09000000","0.00000000"],["78355.67000000","0.00318000"],["79460.78000000","0.00000000"]]}}
{"rx":1788854546238713645, "m":{"e":"depthUpdate","E":1788854546214,"s":"BTCUSDT","U":99829863204,"u":99829863280,"b":[["78287.73000000","12.06131000"],["78287.70000000","0.05014000"],["78287.65000000","0.05014000"],["78286.48000000","0.86916000"],["78286.47000000","0.20725000"],["78286.45000000","0.00000000"],["78286.40000000","0.00000000"],["78286.04000000","0.00000000"],["78286.03000000","0.00000000"],["78285.40000000","0.31943000"],["78284.28000000","0.00500000"],["78283.54000000","0.02733000"],["78283.18000000","0.00800000"],["78279.56000000","0.00000000"],["78278.30000000","0.00000000"],["78277.05000000","0.00000000"],["78275.80000000","0.00000000"],["78273.43000000","0.02000000"],["78234.21000000","0.02000000"],["78075.15000000","0.00802000"],["78066.67000000","0.00000000"],["77113.42000000","0.00008000"],["62630.00000000","0.01596000"],["62629.18000000","0.00310000"]],"a":[["78287.74000000","0.03219000"],["78287.75000000","0.00049000"],["78288.98000000","0.00000000"],["78288.99000000","0.00014000"],["78290.24000000","0.00014000"],["78291.99000000","0.00014000"],["78292.00000000","0.03014000"],["78292.10000000","0.06598000"],["78294.00000000","0.03014000"],["78294.27000000","0.31752000"],["78294.28000000","0.00000000"],["78295.35000000","0.02079000"],["78298.42000000","0.00000000"],["78300.36000000","0.00047000"],["78311.34000000","0.02800000"],["78324.27000000","0.00000000"],["78326.00000000","0.73000000"],["78330.95000000","0.02800000"]]}}
{"rx":1788854546337251517, "m":{"e":"depthUpdate","E":1788854546314,"s":"BTCUSDT","U":99829863281,"u":99829863335,"b":[["78286.47000000","0.20456000"],["78285.58000000","0.01334000"],["78281.60000000","0.00407000"],["78280.34000000","0.00679000"],["78279.09000000","0.00815000"],["78277.84000000","0.00815000"],["78268.83000000","0.00127000"],["78218.61000000","1.27998000"],["78183.14000000","0.14127000"],["78162.52000000","0.00000000"],["77113.42000000","0.00016000"],["70458.96000000","0.00032000"]],"a":[["78287.74000000","0.04653000"],["78287.75000000","0.00063000"],["78288.99000000","0.00000000"],["78289.00000000","0.01875000"],["78290.24000000","0.00000000"],["78290.25000000","0.02250000"],["78291.50000000","0.02250000"],["78294.27000000","0.31752000"],["78294.31000000","0.00008000"],["78295.35000000","0.00014000"],["78295.37000000","0.02111000"],["78295.56000000","0.44157000"],["78295.57000000","0.20536000"],["78295.77000000","0.00014000"],["78302.14000000","0.02084000"],["78303.40000000","0.00286000"],["78305.08000000","0.00408000"],["78309.97000000","0.02117000"],["78311.23000000","0.00286000"],["78313.68000000","0.03000000"],["78317.80000000","0.02127000"],["78319.06000000","0.00286000"],["78358.17000000","1.26380000"],["78371.73000000","0.03000000"]]}}
{"rx":1788854546441287429, "m":{"e":"depthUpdate","E":1788854546414,"s":"BTCUSDT","U":99829863336,"u":99829863403,"b":[["78287.73000000","12.06106000"],["78287.41000000","0.00000000"],["78286.48000000","1.42217000"],["78286.47000000","0.20470000"],["78286.00000000","0.03062000"],["78285.58000000","0.00000000"],["78285.50000000","0.01322000"],["78284.06000000","0.00026000"],["78282.12000000","2.29924000"],["78218.61000000","0.00000000"],["78218.60000000","0.00000000"],["77113.42000000","0.00024000"],["70458.95000000","0.00009000"],["70458.00000000","0.00000000"],["62630.00000000","0.01596000"],["62629.18000000","0.00279000"]],"a":[["78287.74000000","0.21896000"],["78289.00000000","0.01889000"],["78290.25000000","0.02264000"],["78291.50000000","0.02264000"],["78294.27000000","0.15501000"],["78295.35000000","0.00000000"],["78295.37000000","0.00000000"],["78295.56000000","0.00000000"],["78295.77000000","0.00007000"],["78296.27000000","0.00000000"],["78296.53000000","0.00000000"],["78296.56000000","0.00000000"],["78296.62000000","0.00000000"],["78296.63000000","0.02136000"],["78297.09000000","0.00000000"],["78297.99000000","0.00030000"],["78298.56000000","0.47752000"],["78299.94000000","0.00000000"],["78301.01000000","0.00638000"],["78306.07000000","0.00192000"],["78315.23000000","0.03800000"],["78323.51000000","0.00000000"],["78331.44000000","0.00000000"],["78341.29000000","0.00430000"],["78396.90000000","0.03800000"]]}}
{"rx":1788854546541625450, "m":{"e":"depthUpdate","E":1788854546514,"s":"BTCUSDT","U":99829863404,"u":99829863427,"b":[["78287.73000000","12.06073000"],["78286.00000000","0.03062000"],["78274.89000000","0.00000000"],["78257.09000000","0.00000000"],["78237.48000000","0.00000000"],["78192.28000000","0.00408000"],["78123.43000000","0.00000000"],["77113.42000000","0.00032000"],["70458.96000000","0.00048000"],["62630.18000000","0.00000000"]],"a":[["78287.74000000","0.04646000"],["78298.42000000","0.47752000"],["78298.56000000","0.00000000"],["78311.42000000","0.00000000"],["78314.95000000","0.02800000"],["78321.19000000","0.00000000"],["78347.67000000","0.00000000"],["78367.28000000","0.00000000"],["78382.06000000","0.02800000"],["78384.48000000","0.00000000"],["78386.83000000","0.00000000"],["79043.65000000","0.00018000"]]}}
{"rx":1788854546637090305, "m":{"e":"depthUpdate","E":1788854546614,"s":"BTCUSDT","U":99829863428,"u":99829863447,"b":[["78287.73000000","12.06695000"],["78285.50000000","0.00000000"],["78285.46000000","0.01291000"],["78285.41000000","0.00014000"],["77113.42000000","0.00032000"],["70458.96000000","0.00064000"],["62629.18000000","0.00248000"]],"a":[["78287.74000000","0.04651000"],["78295.57000000","0.00286000"],["78301.70000000","0.00255000"],["78312.68000000","0.12769000"],["78334.81000000","0.03200000"]]}}
{"rx":1788854546748558536, "m":{"e":"depthUpdate","E":1788854546714,"s":"BTCUSDT","U":99829863448,"u":99829863466,"b":[["78286.00000000","0.03062000"],["78285.46000000","0.00014000"],["78285.41000000","0.00000000"],["77113.42000000","0.00032000"]],"a":[["78287.74000000","0.21886000"],["78295.57000000","0.20536000"],["78334.03000000","0.04000000"],["78380.78000000","0.00000000"],["78396.90000000","0.00000000"],["78413.04000000","0.00000000"],["79462.06000000","0.00030000"]]}}
{"rx":1788854546839910803, "m":{"e":"depthUpdate","E":1788854546814,"s":"BTCUSDT","U":99829863467,"u":99829863485,"b":[["78286.00000000","0.03062000"],["78285.46000000","0.00000000"],["78285.40000000","0.31957000"],["78268.20000000","0.00000000"],["78265.37000000","0.02467000"],["77113.42000000","0.00040000"],["70458.96000000","0.00080000"],["70458.95000000","0.00000000"],["70458.94000000","0.00009000"],["62629.18000000","0.00217000"]],"a":[["78287.74000000","0.21522000"]]}}
{"rx":1788854546937280012, "m":{"e":"depthUpdate","E":1788854546914,"s":"BTCUSDT","U":99829863486,"u":99829863489,"b":[["77113.42000000","0.00040000"],["62630.00000000","0.01796000"]],"a":[["78452.24000000","0.00000000"]]}}
{"rx":1788854547038131767, "m":{"e":"depthUpdate","E":1788854547014,"s":"BTCUSDT","U":99829863490,"u":99829863508,"b":[["78287.73000000","12.06057000"],["78286.51000000","0.00638000"],["77113.42000000","0.00040000"],["77113.41000000","0.00030000"],["70458.96000000","0.00096000"],["62630.19000000","0.00124000"],["62630.00000000","0.01596000"],["62629.18000000","0.00186000"]],"a":[["78287.74000000","0.21535000"],["78287.75000000","0.00076000"],["78287.76000000","0.00013000"],["78298.22000000","0.00000000"],["78299.48000000","0.00007000"],["78382.06000000","0.00000000"],["78384.51000000","4.04810000"],["78415.17000000","0.00000000"]]}}
{"rx":1788854547137284113, "m":{"e":"depthUpdate","E":1788854547114,"s":"BTCUSDT","U":99829863509,"u":99829863530,"b":[["78287.65000000","0.05014000"],["78262.72000000","0.00419000"],["78223.58000000","0.00000000"],["78156.78000000","0.02001000"],["78147.28000000","0.00000000"],["77583.14000000","0.00010000"],["77113.42000000","0.00032000"],["70458.96000000","0.00112000"],["62630.00000000","0.01596000"]],"a":[["78287.81000000","0.00000000"],["78305.08000000","0.00000000"],["78343.32000000","0.00000000"],["78375.56000000","0.00000000"],["78383.55000000","0.00000000"],["78384.81000000","0.00025000"],["78399.63000000","0.00000000"],["78417.11000000","0.10344000"],["87566.26000000","0.00850000"]]}}
{"rx":1788854547237652110, "m":{"e":"depthUpdate","E":1788854547214,"s":"BTCUSDT","U":99829863531,"u":99829863538,"b":[["78287.73000000","12.06073000"],["78214.60000000","0.02000000"],["77113.42000000","0.00032000"],["62629.18000000","0.00155000"]],"a":[["78287.74000000","0.21545000"],["78350.56000000","0.02800000"],["87566.26000000","0.00925000"]]}}
{"rx":1788854547338280336, "m":{"e":"depthUpdate","E":1788854547314,"s":"BTCUSDT","U":99829863539,"u":99829863549,"b":[["78286.73000000","0.00255000"],["78209.45000000","1.25660000"],["77113.42000000","0.00032000"],["70458.96000000","0.00128000"],["62629.00000000","0.00000000"]],"a":[["78306.09000000","0.00408000"],["78368.33000000","1.24767000"],["78432.48000000","0.18292000"],["87566.26000000","0.00946000"]]}}
{"rx":1788854547437574467, "m":{"e":"depthUpdate","E":1788854547414,"s":"BTCUSDT","U":99829863550,"u":99829863555,"b":[["78286.73000000","0.00000000"],["78286.72000000","0.00255000"],["78264.00000000","0.73000000"],["77113.42000000","0.00032000"],["62629.18000000","0.00124000"]],"a":[]}}
{"rx":1788854547540776975, "m":{"e":"depthUpdate","E":1788854547514,"s":"BTCUSDT","U":99829863556,"u":99829863570,"b":[["78286.72000000","0.00000000"],["78273.24000000","0.02000000"],["78272.43000000","0.00000000"],["78256.50000000","0.00000000"],["78236.89000000","0.00000000"],["78234.03000000","0.02000000"],["77292.28000000","0.00000000"],["77113.42000000","0.00032000"],["70458.96000000","0.00144000"],["62630.18000000","0.00000000"]],"a":[["78311.29000000","0.03408000"],["78311.46000000","0.00000000"],["78330.90000000","0.03400000"],["78345.25000000","0.00408000"],["78347.61000000","0.00000000"],["78367.22000000","0.00000000"],["82921.18000000","0.00000000"]]}}
{"rx":1788854547638594836, "m":{"e":"depthUpdate","E":1788854547614,"s":"BTCUSDT","U":99829863571,"u":99829863581,"b":[["78286.71000000","0.00255000"],["77113.42000000","0.00032000"],["70458.00000000","0.00000000"],["62630.00000000","0.01596000"],["62629.18000000","0.00093000"]],"a":[["78308.17000000","0.10216000"]]}}
{"rx":1788854547737165630, "m":{"e":"depthUpdate","E":1788854547714,"s":"BTCUSDT","U":99829863582,"u":99829863590,"b":[["78286.71000000","0.00000000"],["78286.69000000","0.00255000"],["78224.58000000","0.00408000"],["77113.42000000","0.00032000"],["70458.96000000","0.00160000"]],"a":[["78505.31000000","0.02000000"],["79462.06000000","0.00030000"]]}}
{"rx":1788854547837888984, "m":{"e":"depthUpdate","E":1788854547814,"s":"BTCUSDT","U":99829863591,"u":99829863600,"b":[["78286.69000000","0.00000000"],["78286.67000000","0.00255000"],["78128.63000000","0.02000000"],["78109.09000000","0.00000000"],["78099.66000000","0.00000000"],["78000.00000000","77.71791000"],["77113.42000000","0.00040000"],["70458.96000000","0.00176000"],["62629.18000000","0.00062000"]],"a":[["78464.17000000","0.00000000"]]}}
{"rx":1788854547937633341, "m":{"e":"depthUpdate","E":1788854547914,"s":"BTCUSDT","U":99829863601,"u":99829863616,"b":[["78286.67000000","0.00000000"],["78286.66000000","0.00255000"],["78262.72000000","0.00011000"],["77113.42000000","0.00040000"],["62630.00000000","0.01596000"]],"a":[["78287.74000000","0.04295000"],["78306.09000000","0.00000000"],["78345.25000000","0.00000000"],["78376.57000000","0.00408000"],["78390.71000000","0.01513000"]]}}
{"rx":1788854548038279290, "m":{"e":"depthUpdate","E":1788854548014,"s":"BTCUSDT","U":99829863617,"u":99829863639,"b":[["78286.66000000","0.00000000"],["78286.65000000","0.00255000"],["78273.19000000","0.02000000"],["78233.97000000","0.02000000"],["78115.61000000","4.46584000"],["77113.42000000","0.00040000"],["77113.41000000","0.00000000"],["70458.96000000","0.00192000"],["62630.19000000","0.00248000"],["62629.18000000","0.00031000"]],"a":[["78287.74000000","0.04423000"],["78299.48000000","0.00007000"],["78311.07000000","0.03800000"],["78330.68000000","0.03800000"],["78477.67000000","4.48096000"]]}}
{"rx":1788854548137275843, "m":{"e":"depthUpdate","E":1788854548114,"s":"BTCUSDT","U":99829863640,"u":99829863648,"b":[["78287.73000000","12.06036000"],["78286.65000000","0.00000000"],["78286.64000000","0.00255000"],["78285.47000000","0.01325000"],["77113.42000000","0.00032000"],["77113.41000000","0.00030000"],["70458.94000000","0.00000000"]],"a":[["78287.74000000","0.21658000"]]}}
{"rx":1788854548242144687, "m":{"e":"depthUpdate","E":1788854548214,"s":"BTCUSDT","U":99829863649,"u":99829863664,"b":[["78286.64000000","0.00000000"],["78286.51000000","0.00652000"],["78286.00000000","0.03062000"],["78285.40000000","0.31943000"],["77113.42000000","0.00032000"],["70458.96000000","0.00208000"],["62629.18000000","0.00000000"]],"a":[["78287.74000000","0.21673000"]]}}
{"rx":1788854548337495768, "m":{"e":"depthUpdate","E":1788854548314,"s":"BTCUSDT","U":99829863665,"u":99829863677,"b":[["78218.60000000","0.59366000"],["78162.47000000","0.00068000"],["78150.00000000","0.42877000"],["77292.28000000","0.00010000"],["77113.42000000","0.00032000"],["70458.96000000","0.00224000"]],"a":[["78287.74000000","0.21663000"],["78345.31000000","0.00408000"],["78356.48000000","0.40902000"],["78384.50000000","2.19149000"],["78384.51000000","2.68103000"]]}}
{"rx":1788854548436825286, "m":{"e":"depthUpdate","E":1788854548414,"s":"BTCUSDT","U":99829863678,"u":99829863682,"b":[["77113.42000000","0.00032000"],["70458.96000000","0.00224000"],["62630.19000000","0.00217000"]],"a":[]}}
{"rx":1788854548537103755, "m":{"e":"depthUpdate","E":1788854548514,"s":"BTCUSDT","U":99829863683,"u":99829863699,"b":[["78273.18000000","0.00000000"],["78253.92000000","0.00000000"],["78234.31000000","0.00000000"],["78214.42000000","0.02000000"],["78123.38000000","0.00068000"],["77113.42000000","0.00032000"],["70458.96000000","0.00240000"],["62630.19000000","0.00341000"],["62630.18000000","0.00000000"]],"a":[["78306.15000000","0.00408000"],["78310.65000000","0.00000000"],["78345.26000000","0.00000000"],["78350.51000000","0.03400000"],["78364.87000000","0.00000000"],["82921.18000000","0.00010000"]]}}
{"rx":1788854548638820183, "m":{"e":"depthUpdate","E":1788854548614,"s":"BTCUSDT","U":99829863700,"u":99829863706,"b":[["78241.90000000","0.00127000"],["77113.42000000","0.00032000"],["62630.19000000","0.00310000"]],"a":[["78298.42000000","0.00000000"],["78337.99000000","0.00000000"],["78415.99000000","0.00000000"]]}}
{"rx":1788854548737215668, "m":{"e":"depthUpdate","E":1788854548714,"s":"BTCUSDT","U":99829863707,"u":99829863716,"b":[["78263.78000000","0.00408000"],["77113.42000000","0.00032000"],["70458.96000000","0.00256000"]],"a":[["78306.15000000","0.00000000"],["78339.11000000","0.00317000"],["78412.99000000","0.00111000"],["78417.01000000","0.00127000"],["79462.06000000","0.00030000"]]}}
{"rx":1788854548837477976, "m":{"e":"depthUpdate","E":1788854548814,"s":"BTCUSDT","U":99829863717,"u":99829863719,"b":[["77113.42000000","0.00040000"],["70458.00000000","0.00020000"],["62630.19000000","0.00279000"]],"a":[]}}
{"rx":1788854548937548074, "m":{"e":"depthUpdate","E":1788854548914,"s":"BTCUSDT","U":99829863720,"u":99829863738,"b":[["78089.46000000","0.00000000"],["78088.77000000","0.02320000"],["77113.42000000","0.00040000"],["70458.96000000","0.00281000"],["70458.00000000","0.00000000"]],"a":[["78287.74000000","0.21638000"],["78294.27000000","0.47616000"],["78295.56000000","0.47752000"],["78296.28000000","0.00000000"],["78298.42000000","0.00000000"],["78298.56000000","0.00000000"],["78301.70000000","0.00000000"],["78306.11000000","0.00408000"],["78335.67000000","0.00007000"],["78452.19000000","0.00111000"]]}}
{"rx":1788854549037618182, "m":{"e":"depthUpdate","E":1788854549014,"s":"BTCUSDT","U":99829863739,"u":99829863753,"b":[["78273.91000000","0.02000000"],["78234.70000000","0.02000000"],["78214.36000000","0.02000000"],["77113.42000000","0.00040000"],["70458.96000000","0.00297000"],["62630.19000000","0.00248000"]],"a":[["78294.27000000","0.33362000"],["78299.48000000","0.00000000"],["78302.86000000","0.00255000"],["78310.13000000","0.04400000"],["78329.74000000","0.04400000"],["78350.29000000","0.03800000"]]}}
{"rx":1788854549137540613, "m":{"e":"depthUpdate","E":1788854549114,"s":"BTCUSDT","U":99829863754,"u":99829863763,"b":[["78263.78000000","0.00000000"],["77113.42000000","0.00032000"],["77113.41000000","0.00030000"],["62630.00000000","0.01796000"]],"a":[["78299.48000000","0.00007000"],["78301.92000000","0.00255000"],["78302.86000000","0.00000000"],["78306.11000000","0.00000000"],["78306.13000000","0.00408000"]]}}
