{"rx":1788854559452494335, "m":{"e":"depthUpdate","E":1788854559414,"s":"BTCUSDT","U":99829876143,"u":99829877513,"b":[["78318.73000000","0.00000000"],["78318.72000000","0.00000000"],["78318.39000000","0.00000000"],["78318.37000000","0.00000000"],["78318.36000000","0.00000000"],["78317.49000000","0.00000000"],["78317.48000000","0.00000000"],["78317.10000000","0.00000000"],["78317.09000000","0.00000000"],["78316.24000000","0.00000000"],["78316.23000000","0.00000000"],["78316.14000000","0.00000000"],["78316.00000000","0.00000000"],["78315.99000000","0.00000000"],["78315.72000000","0.00000000"],["78315.70000000","0.00000000"],["78315.63000000","0.00000000"],["78315.38000000","0.00000000"],["78315.33000000","0.00000000"],["78315.32000000","0.00000000"],["78315.31000000","0.00000000"],["78314.72000000","0.00000000"],["78314.12000000","0.00000000"],["78314.04000000","0.00000000"],["78314.03000000","0.00000000"],["78314.01000000","0.00000000"],["78314.00000000","0.00000000"],["78313.34000000","0.00000000"],["78312.16000000","0.00000000"],["78312.00000000","0.00000000"],["78311.73000000","0.00000000"],["78311.35000000","0.00000000"],["78310.74000000","0.00000000"],["78310.68000000","0.00000000"],["78310.28000000","0.00000000"],["78310.00000000","0.00000000"],["78309.70000000","0.00000000"],["78309.63000000","0.00000000"],["78309.57000000","0.00000000"],["78309.34000000","0.00000000"],["78309.25000000","0.00000000"],["78309.24000000","0.00000000"],["78309.12000000","0.00000000"],["78309.06000000","0.00000000"],["78309.05000000","0.00000000"],["78309.02000000","0.00000000"],["78308.69000000","0.00000000"],["78308.25000000","0.00000000"],["78308.17000000","0.00000000"],["78308.16000000","0.00000000"],["78308.00000000","0.00000000"],["78307.99000000","0.00000000"],["78307.93000000","0.00000000"],["78307.81000000","0.00000000"],["78307.74000000","0.00000000"],["78307.59000000","0.00000000"],["78307.51000000","0.00000000"],["78307.50000000","0.00000000"],["78307.40000000","0.00000000"],["78307.23000000","0.00000000"],["78306.96000000","0.00000000"],["78306.90000000","0.00000000"],["78306.11000000","2.18562000"],["78306.10000000","0.00042000"],["78306.05000000","0.00000000"],["78306.04000000","0.00000000"],["78306.00000000","0.00000000"],["78305.28000000","0.00000000"],["78304.84000000","0.00000000"],["78304.83000000","0.00000000"],["78304.65000000","0.00000000"],["78304.64000000","0.00000000"],["78304.46000000","0.00014000"],["78304.45000000","0.06003000"],["78304.30000000","0.00000000"],["78304.18000000","0.00000000"],["78304.17000000","0.00000000"],["78304.02000000","0.00014000"],["78304.01000000","0.20613000"],["78304.00000000","0.64000000"],["78303.99000000","0.00000000"],["78303.92000000","0.00000000"],["78303.84000000","0.00000000"],["78303.83000000","0.00000000"],["78303.76000000","0.00000000"],["78303.75000000","0.00007000"],["78303.38000000","0.00103000"],["78303.35000000","0.00000000"],["78302.79000000","0.00000000"],["78302.78000000","0.00000000"],["78302.60000000","0.01000000"],["78302.51000000","0.00014000"],["78302.50000000","0.06000000"],["78302.42000000","0.00000000"],["78302.33000000","0.00000000"],["78302.32000000","0.00000000"],["78302.30000000","0.00000000"],["78302.07000000","0.00000000"],["78302.06000000","0.00000000"],["78302.00000000","0.00000000"],["78301.69000000","0.00000000"],["78301.60000000","0.00000000"],["78301.34000000","0.00000000"],["78301.14000000","0.00026000"],["78301.12000000","0.00574000"],["78300.82000000","0.00000000"],["78300.59000000","0.00000000"],["78300.36000000","0.00008000"],["78300.33000000","0.00000000"],["78300.26000000","0.00000000"],["78300.22000000","0.00000000"],["78300.15000000","0.00000000"],["78300.01000000","0.00000000"],["78300.00000000","0.00000000"],["78299.99000000","0.00000000"],["78299.76000000","0.00014000"],["78299.66000000","0.00000000"],["78299.50000000","0.00000000"],["78299.31000000","0.00000000"],["78299.30000000","0.00000000"],["78298.42000000","0.00000000"],["78298.41000000","0.00000000"],["78298.28000000","0.00008000"],["78298.21000000","0.00000000"],["78298.14000000","0.00400000"],["78298.07000000","0.00000000"],["78298.00000000","0.00000000"],["78297.73000000","0.00350000"],["78297.70000000","0.00000000"],["78297.16000000","0.00000000"],["78297.11000000","0.00000000"],["78297.10000000","0.00000000"],["78296.36000000","0.00011000"],["78296.35000000","0.00000000"],["78296.34000000","0.20264000"],["78296.21000000","0.00000000"],["78296.08000000","0.00000000"],["78296.00000000","0.00000000"],["78295.77000000","0.00014000"],["78295.68000000","0.00007000"],["78295.49000000","0.00000000"],["78295.45000000","0.00000000"],["78295.44000000","0.00000000"],["78295.43000000","0.00000000"],["78295.02000000","0.00000000"],["78294.50000000","0.00000000"],["78294.49000000","0.00000000"],["78294.44000000","0.01278000"],["78294.09000000","0.00000000"],["78294.08000000","0.00400000"],["78294.07000000","0.00000000"],["78294.04000000","0.00000000"],["78294.03000000","0.55571000"],["78294.02000000","1.86166000"],["78294.00000000","0.00000000"],["78293.99000000","0.00000000"],["78293.85000000","0.00000000"],["78293.84000000","0.00000000"],["78293.83000000","0.17864000"],["78293.43000000","0.00000000"],["78293.29000000","0.00000000"],["78293.02000000","0.00000000"],["78293.01000000","0.00000000"],["78292.79000000","0.00000000"],["78292.42000000","0.00000000"],["78292.04000000","0.00000000"],["78292.03000000","0.00000000"],["78292.02000000","0.00000000"],["78291.85000000","0.00000000"],["78291.84000000","0.77571000"],["78291.78000000","0.00014000"],["78291.50000000","0.00000000"],["78291.15000000","0.00000000"],["78290.93000000","0.00000000"],["78290.58000000","0.00000000"],["78290.45000000","0.00008000"],["78290.26000000","2.29826000"],["78290.07000000","0.00000000"],["78289.18000000","0.00024000"],["78289.17000000","0.00000000"],["78289.12000000","0.00000000"],["78288.51000000","0.00000000"],["78288.46000000","0.00000000"],["78288.18000000","0.03057000"],["78288.14000000","0.02000000"],["78288.01000000","0.00000000"],["78287.81000000","0.37581000"],["78287.79000000","0.00014000"],["78287.42000000","0.00000000"],["78287.13000000","0.00000000"],["78286.67000000","0.00000000"],["78286.66000000","0.00000000"],["78286.53000000","0.00008000"],["78286.47000000","0.00025000"],["78286.00000000","0.05134000"],["78285.88000000","0.00000000"],["78285.46000000","0.00000000"],["78284.74000000","0.00000000"],["78284.59000000","0.00000000"],["78283.80000000","0.00014000"],["78282.81000000","0.22777000"],["78282.75000000","0.00000000"],["78282.62000000","0.00008000"],["78282.11000000","0.77842000"],["78281.17000000","0.22080000"],["78280.68000000","0.00000000"],["78280.00000000","0.03113000"],["78279.81000000","0.00014000"],["78279.61000000","0.00000000"],["78279.48000000","0.00000000"],["78279.00000000","0.00000000"],["78278.83000000","0.00000000"],["78278.70000000","0.00008000"],["78278.18000000","0.00008000"],["78278.17000000","0.02095000"],["78278.08000000","0.85418000"],["78277.53000000","0.00000000"],["78277.46000000","0.53166000"],["78277.07000000","0.22080000"],["78276.77000000","0.00000000"],["78276.76000000","0.00000000"],["78275.99000000","0.00000000"],["78275.82000000","0.00014000"],["78274.79000000","0.00008000"],["78274.71000000","0.00000000"],["78273.74000000","0.00000000"],["78273.21000000","0.00000000"],["78272.84000000","0.00000000"],["78271.83000000","0.00014000"],["78271.04000000","0.00000000"],["78270.87000000","0.00008000"],["78270.34000000","0.02088000"],["78268.80000000","0.00408000"],["78268.72000000","0.00000000"],["78267.84000000","0.00014000"],["78266.96000000","0.00008000"],["78266.17000000","0.00349000"],["78266.11000000","0.00000000"],["78265.57000000","0.00000000"],["78263.85000000","0.00007000"],["78263.54000000","0.00400000"],["78262.68000000","0.00000000"],["78262.51000000","0.02147000"],["78261.30000000","0.00000000"],["78261.14000000","1.26536000"],["78261.06000000","0.20000000"],["78259.86000000","0.02000000"],["78258.97000000","0.00000000"],["78258.28000000","0.00400000"],["78257.90000000","0.00008000"],["78257.00000000","0.01288000"],["78255.87000000","0.00000000"],["78255.65000000","0.00000000"],["78254.00000000","0.03000000"],["78253.02000000","0.00015000"],["78252.79000000","0.77161000"],["78252.25000000","1.08934000"],["78250.94000000","0.00000000"],["78249.92000000","0.00000000"],["78249.64000000","0.00000000"],["78249.32000000","0.00431000"],["78248.16000000","0.00633000"],["78245.38000000","0.00000000"],["78244.30000000","0.00424000"],["78243.70000000","0.00431000"],["78238.98000000","0.99866000"],["78238.74000000","0.00000000"],["78238.06000000","0.00319000"],["78235.45000000","0.00000000"],["78232.41000000","0.02000000"],["78228.92000000","0.00000000"],["78228.79000000","0.00180000"],["78227.36000000","0.02904000"],["78226.74000000","0.00318000"],["78226.73000000","0.00000000"],["78224.02000000","0.00008000"],["78222.23000000","0.02000000"],["78193.61000000","0.03127000"],["78183.13000000","0.00000000"],["78174.23000000","0.00000000"],["78171.26000000","0.00000000"],["78167.92000000","0.00000000"],["78167.91000000","0.00000000"],["78158.02000000","0.00127000"],["78157.32000000","1.53085000"],["78157.13000000","0.00000000"],["78150.02000000","0.00072000"],["78147.69000000","0.00000000"],["78145.72000000","0.00021000"],["78136.08000000","2.59826000"],["78121.59000000","1.20000000"],["78089.92000000","0.00007000"],["78089.89000000","0.00000000"],["78086.01000000","0.00007000"],["78080.62000000","0.00007000"],["78078.82000000","0.00000000"],["78077.37000000","0.00007000"],["78073.46000000","0.00007000"],["78067.41000000","0.00008000"],["78002.26000000","0.00000000"],["78000.50000000","0.00145000"],["77991.10000000","0.00026000"],["77989.11000000","0.00015000"],["77924.70000000","0.00021000"],["77922.19000000","0.00000000"],["77910.81000000","0.00008000"],["77843.88000000","0.00000000"],["77832.51000000","0.00008000"],["77765.56000000","0.00025000"],["77754.20000000","0.00008000"],["77687.25000000","0.00000000"],["77675.90000000","0.00008000"],["77292.28000000","0.00000000"],["77143.95000000","0.00000000"],["70486.86000000","0.00000000"],["62656.00000000","0.00248000"]],"a":[["78304.01000000","0.00000000"],["78306.01000000","0.00000000"],["78306.11000000","0.00000000"],["78306.12000000","2.52684000"],["78306.13000000","0.00027000"],["78306.14000000","0.00013000"],["78306.98000000","0.00000000"],["78307.23000000","0.00014000"],["78307.24000000","0.00014000"],["78307.53000000","0.00000000"],["78307.59000000","0.93613000"],["78307.60000000","0.00000000"],["78307.74000000","0.00007000"],["78307.78000000","0.00000000"],["78307.79000000","0.00022000"],["78307.80000000","0.00000000"],["78307.81000000","0.00000000"],["78307.93000000","0.00000000"],["78307.94000000","0.00014000"],["78307.97000000","0.00000000"],["78307.98000000","0.00000000"],["78308.00000000","0.00014000"],["78308.01000000","0.00014000"],["78308.67000000","0.00400000"],["78308.70000000","0.00000000"],["78308.74000000","0.00000000"],["78309.06000000","0.00000000"],["78309.07000000","0.00014000"],["78309.12000000","0.00000000"],["78309.20000000","0.00400000"],["78309.25000000","0.00000000"],["78309.26000000","0.00000000"],["78309.38000000","0.00000000"],["78309.65000000","0.67160000"],["78309.66000000","1.97967000"],["78310.01000000","0.00014000"],["78310.11000000","0.00000000"],["78310.88000000","0.00400000"],["78310.90000000","0.12769000"],["78310.97000000","0.00000000"],["78311.04000000","0.00000000"],["78311.36000000","0.00000000"],["78311.50000000","0.00000000"],["78311.73000000","0.00014000"],["78311.74000000","0.13814000"],["78311.76000000","0.06768000"],["78311.84000000","0.00000000"],["78311.90000000","0.00000000"],["78312.00000000","0.00000000"],["78312.01000000","0.00000000"],["78312.18000000","0.00638000"],["78312.19000000","0.04014000"],["78312.67000000","0.00000000"],["78312.72000000","0.00000000"],["78313.00000000","0.00000000"],["78313.27000000","0.02114000"],["78313.35000000","0.00026000"],["78313.51000000","0.00400000"],["78313.55000000","0.00000000"],["78313.57000000","0.63365000"],["78313.58000000","1.97967000"],["78313.62000000","0.00000000"],["78313.95000000","0.00008000"],["78314.01000000","0.00000000"],["78314.04000000","0.00000000"],["78314.58000000","0.00007000"],["78315.27000000","0.00000000"],["78315.28000000","0.01313000"],["78315.34000000","0.00000000"],["78315.35000000","0.00010000"],["78315.40000000","0.00000000"],["78315.71000000","0.00000000"],["78315.72000000","0.00014000"],["78315.90000000","0.00007000"],["78316.01000000","0.00000000"],["78316.14000000","0.00400000"],["78316.20000000","0.00000000"],["78316.24000000","0.00000000"],["78316.70000000","0.00008000"],["78317.10000000","0.13875000"],["78317.49000000","0.00000000"],["78317.50000000","0.14709000"],["78317.71000000","0.00007000"],["78317.87000000","0.00007000"],["78318.16000000","0.00000000"],["78318.37000000","0.00000000"],["78318.38000000","0.00000000"],["78318.40000000","0.00000000"],["78318.66000000","0.00000000"],["78318.73000000","1.62597000"],["78318.74000000","3.50378000"],["78318.75000000","2.35948000"],["78318.76000000","0.00000000"],["78318.77000000","0.00400000"],["78319.18000000","0.02000000"],["78319.20000000","0.01310000"],["78319.34000000","0.02145000"],["78319.67000000","0.00008000"],["78319.96000000","0.00000000"],["78319.97000000","0.00000000"],["78319.98000000","0.00000000"],["78319.99000000","0.07500000"],["78320.00000000","0.37727000"],["78320.05000000","0.00000000"],["78320.22000000","0.00000000"],["78320.76000000","0.00000000"],["78320.77000000","0.00000000"],["78320.84000000","0.00007000"],["78321.40000000","0.00400000"],["78321.48000000","0.00000000"],["78321.50000000","0.18109000"],["78321.51000000","0.31934000"],["78321.96000000","0.04000000"],["78321.99000000","0.00000000"],["78322.00000000","0.03200000"],["78322.23000000","0.02124000"],["78323.19000000","0.00010000"],["78323.22000000","0.00000000"],["78323.23000000","0.01335000"],["78323.58000000","0.31937000"],["78323.59000000","0.00008000"],["78323.72000000","0.00007000"],["78323.91000000","0.11516000"],["78323.97000000","0.00000000"],["78324.03000000","0.00008000"],["78325.15000000","0.00000000"],["78325.27000000","0.00000000"],["78325.46000000","0.00000000"],["78325.47000000","0.00000000"],["78325.69000000","0.00000000"],["78326.49000000","0.00000000"],["78326.53000000","0.00000000"],["78326.84000000","0.09424000"],["78327.10000000","0.00000000"],["78327.26000000","0.00000000"],["78327.47000000","0.37581000"],["78327.50000000","2.44002000"],["78327.63000000","0.00007000"],["78327.78000000","0.00000000"],["78327.83000000","0.21096000"],["78327.84000000","0.00000000"],["78327.98000000","0.00000000"],["78328.25000000","0.31934000"],["78328.38000000","0.00000000"],["78328.49000000","0.00000000"],["78328.79000000","0.10255000"],["78329.03000000","0.00000000"],["78329.63000000","0.00000000"],["78329.68000000","0.20505000"],["78330.22000000","0.00000000"],["78330.23000000","0.00000000"],["78330.34000000","0.00000000"],["78330.51000000","0.00191000"],["78331.42000000","0.00008000"],["78331.75000000","0.00000000"],["78332.42000000","0.00000000"],["78333.36000000","0.00000000"],["78333.66000000","0.00008000"],["78335.02000000","0.00000000"],["78335.15000000","0.03800000"],["78335.26000000","0.03200000"],["78335.33000000","0.00008000"],["78335.67000000","0.00014000"],["78335.85000000","0.34477000"],["78335.98000000","0.00000000"],["78336.17000000","0.00000000"],["78337.46000000","0.00000000"],["78337.58000000","0.00000000"],["78337.66000000","0.00000000"],["78339.25000000","0.00008000"],["78340.01000000","0.00000000"],["78341.50000000","0.00000000"],["78343.14000000","0.00000000"],["78343.16000000","0.00008000"],["78343.50000000","0.00000000"],["78343.65000000","0.00014000"],["78344.45000000","0.00000000"],["78345.41000000","0.00000000"],["78346.06000000","0.00627000"],["78346.70000000","0.00000000"],["78346.96000000","0.00000000"],["78347.32000000","1.26397000"],["78347.64000000","0.00000000"],["78347.68000000","0.00000000"],["78349.33000000","0.00000000"],["78350.35000000","0.00425000"],["78350.55000000","0.00000000"],["78350.62000000","0.00424000"],["78350.87000000","0.00000000"],["78351.33000000","0.00000000"],["78351.63000000","0.00000000"],["78352.61000000","0.00000000"],["78353.24000000","0.00000000"],["78353.36000000","0.00000000"],["78354.54000000","0.00000000"],["78355.11000000","0.00000000"],["78355.62000000","0.00000000"],["78355.67000000","0.00318000"],["78355.68000000","0.00000000"],["78356.79000000","0.00000000"],["78357.16000000","0.00000000"],["78358.00000000","0.04000000"],["78358.11000000","0.00000000"],["78360.00000000","0.03000000"],["78360.32000000","0.00000000"],["78361.60000000","0.00000000"],["78364.49000000","0.00000000"],["78365.04000000","0.00000000"],["78365.70000000","0.00000000"],["78367.70000000","0.00000000"],["78369.58000000","0.01734000"],["78369.64000000","0.00007000"],["78369.76000000","0.00529000"],["78369.89000000","0.00318000"],["78373.35000000","0.00000000"],["78376.39000000","0.00000000"],["78376.40000000","0.00000000"],["78378.74000000","0.00000000"],["78382.31000000","0.00008000"],["78385.71000000","0.00000000"],["78386.36000000","0.00026000"],["78386.43000000","0.00000000"],["78387.98000000","0.00000000"],["78391.99000000","0.02254000"],["78393.89000000","0.00000000"],["78396.32000000","0.00000000"],["78398.89000000","0.00000000"],["78399.99000000","0.10776000"],["78403.29000000","0.00000000"],["78405.01000000","0.00000000"],["78411.12000000","0.00000000"],["78411.84000000","0.05353000"],["78414.89000000","0.00000000"],["78448.62000000","1.53085000"],["78458.68000000","0.31784000"],["78458.69000000","0.77521000"],["78459.99000000","0.00000000"],["78460.62000000","0.00008000"],["78469.88000000","0.00000000"],["78474.64000000","0.00000000"],["78481.99000000","0.02129000"],["78485.35000000","0.03057000"],["78489.85000000","0.09606000"],["78490.60000000","0.00000000"],["78538.92000000","0.00008000"],["78552.95000000","0.00000000"],["78570.98000000","0.00028000"],["78582.22000000","0.00000000"],["78617.23000000","0.00008000"],["78631.27000000","0.00000000"],["78695.53000000","0.00008000"],["78709.59000000","0.00000000"],["78773.83000000","0.00008000"],["78787.91000000","0.00000000"],["78852.14000000","0.00008000"],["78866.23000000","0.00000000"],["78930.44000000","0.00008000"],["78944.54000000","0.00000000"],["82921.18000000","0.00000000"]]}}
{"rx":1788854559550901539, "m":{"e":"depthUpdate","E":1788854559514,"s":"BTCUSDT","U":99829877514,"u":99829877723,"b":[["78306.11000000","2.21497000"],["78306.10000000","0.00077000"],["78305.75000000","0.00783000"],["78304.50000000","0.00014000"],["78304.49000000","0.01306000"],["78304.45000000","0.06017000"],["78304.03000000","0.00000000"],["78304.01000000","0.20627000"],["78304.00000000","0.64014000"],["78303.75000000","0.00014000"],["78303.38000000","0.00000000"],["78303.24000000","0.01567000"],["78303.22000000","0.00000000"],["78302.60000000","0.01014000"],["78302.50000000","0.06014000"],["78302.12000000","0.00400000"],["78301.99000000","0.01567000"],["78301.15000000","0.00007000"],["78301.12000000","0.00588000"],["78300.28000000","0.01453000"],["78300.27000000","0.01327000"],["78298.28000000","0.02183000"],["78298.14000000","0.00000000"],["78298.12000000","0.01342000"],["78297.95000000","0.03057000"],["78296.36000000","0.00000000"],["78296.34000000","0.20257000"],["78294.03000000","0.55571000"],["78292.32000000","0.00192000"],["78291.84000000","1.33642000"],["78291.14000000","0.00000000"],["78288.50000000","0.20250000"],["78288.45000000","0.02000000"],["78288.04000000","0.38331000"],["78285.22000000","0.00150000"],["78283.10000000","0.32698000"],["78278.39000000","0.03828000"],["78275.71000000","0.00012000"],["78275.61000000","0.02490000"],["78269.83000000","0.00000000"],["78266.00000000","0.04000000"],["78263.85000000","0.00000000"],["78257.00000000","0.00288000"],["78234.12000000","0.02000000"],["78225.66000000","0.00000000"],["78223.64000000","0.00408000"],["78155.58000000","0.00068000"],["78069.55000000","0.00007000"],["78065.64000000","0.00007000"],["77131.52000000","0.00008000"],["70475.50000000","0.00016000"],["70475.00000000","0.00000000"]],"a":[["78306.12000000","2.35861000"],["78307.02000000","0.00748000"],["78307.23000000","0.00000000"],["78307.24000000","0.00000000"],["78307.58000000","0.00000000"],["78307.59000000","0.00014000"],["78307.74000000","0.00007000"],["78307.79000000","0.00008000"],["78307.94000000","0.00000000"],["78308.00000000","0.00000000"],["78308.01000000","0.00000000"],["78308.28000000","0.01247000"],["78308.67000000","0.00000000"],["78309.07000000","0.00000000"],["78309.20000000","0.00000000"],["78309.53000000","0.01496000"],["78309.64000000","0.00014000"],["78309.65000000","0.67174000"],["78309.66000000","1.97981000"],["78310.01000000","0.00000000"],["78310.03000000","0.00159000"],["78310.78000000","0.01496000"],["78310.90000000","0.12783000"],["78311.74000000","0.13814000"],["78311.76000000","0.06782000"],["78312.01000000","0.00400000"],["78312.18000000","0.00652000"],["78312.19000000","0.04028000"],["78313.27000000","0.00000000"],["78313.35000000","0.00000000"],["78313.55000000","1.32477000"],["78313.56000000","2.29867000"],["78313.57000000","0.00000000"],["78313.71000000","0.00400000"],["78313.96000000","0.00020000"],["78315.02000000","0.00026000"],["78315.28000000","0.00000000"],["78316.69000000","0.01600000"],["78317.97000000","0.00192000"],["78318.74000000","3.30128000"],["78318.75000000","2.65948000"],["78318.77000000","0.30400000"],["78319.18000000","0.30000000"],["78319.20000000","0.00000000"],["78319.34000000","0.00000000"],["78319.99000000","0.37500000"],["78320.00000000","0.16141000"],["78320.98000000","0.02000000"],["78321.26000000","0.00000000"],["78321.50000000","0.18109000"],["78321.51000000","0.00000000"],["78321.79000000","0.00020000"],["78322.23000000","0.00000000"],["78323.23000000","0.00000000"],["78326.76000000","0.00000000"],["78327.99000000","0.31936000"],["78329.62000000","0.00020000"],["78330.47000000","0.00012000"],["78331.09000000","0.00060000"],["78331.24000000","0.00000000"],["78331.32000000","0.03407000"],["78334.86000000","0.02800000"],["78337.45000000","0.00020000"],["78338.86000000","0.00000000"],["78339.55000000","0.20000000"],["78342.67000000","0.02481000"],["78344.81000000","0.00000000"],["78346.00000000","0.04000000"],["78347.29000000","0.00436000"],["78358.00000000","0.03000000"],["78369.22000000","0.00109000"],["78382.07000000","0.00000000"],["78533.01000000","0.00000000"],["78535.39000000","0.00000000"],["78538.93000000","0.00000000"],["78540.92000000","0.00000000"]]}}
{"rx":1788854559646121742, "m":{"e":"depthUpdate","E":1788854559614,"s":"BTCUSDT","U":99829877724,"u":99829877801,"b":[["78306.11000000","2.21504000"],["78305.75000000","0.00797000"],["78305.07000000","0.00007000"],["78304.49000000","0.01320000"],["78304.00000000","0.64007000"],["78302.50000000","0.06000000"],["78302.12000000","0.00000000"],["78302.00000000","0.00000000"],["78301.15000000","0.00007000"],["78301.12000000","0.00574000"],["78300.92000000","0.00400000"],["78296.34000000","0.20250000"],["78295.47000000","0.00048000"],["78290.45000000","0.00016000"],["78289.18000000","0.00000000"],["78288.15000000","0.02000000"],["78287.41000000","0.00000000"],["78282.63000000","0.00024000"],["78278.18000000","0.00000000"],["78277.54000000","0.00012000"],["78272.22000000","0.88538000"],["78230.42000000","2.21473000"],["78225.35000000","0.02000000"],["78183.58000000","0.00000000"],["77131.52000000","0.00016000"],["62656.00000000","0.00217000"],["62645.00000000","0.00284000"]],"a":[["78306.12000000","2.09313000"],["78307.02000000","0.00762000"],["78307.59000000","0.00000000"],["78308.28000000","0.01261000"],["78309.53000000","0.01510000"],["78309.66000000","1.97981000"],["78310.78000000","0.01510000"],["78311.76000000","0.06768000"],["78312.18000000","0.00638000"],["78312.19000000","0.04014000"],["78320.98000000","0.00000000"],["78321.52000000","0.00000000"],["78321.78000000","0.00008000"],["78322.30000000","0.00000000"],["78323.38000000","0.02000000"],["78325.42000000","0.03200000"],["78328.25000000","0.00000000"],["78332.93000000","0.31935000"],["78333.66000000","0.00000000"],["78344.69000000","0.00000000"],["78356.93000000","0.88442000"],["78363.09000000","0.00000000"],["78389.74000000","0.00000000"],["78427.27000000","0.00000000"],["78432.37000000","0.00000000"],["78437.33000000","0.00000000"]]}}
{"rx":1788854559745707468, "m":{"e":"depthUpdate","E":1788854559714,"s":"BTCUSDT","U":99829877802,"u":99829877847,"b":[["78306.11000000","2.21460000"],["78304.00000000","0.64014000"],["78303.24000000","0.01581000"],["78303.16000000","0.00007000"],["78302.50000000","0.06007000"],["78299.30000000","0.31938000"],["78295.72000000","0.00007000"],["78254.08000000","0.34513000"],["78231.57000000","0.02000000"],["78225.35000000","0.00000000"],["78169.72000000","0.00009000"],["77131.52000000","0.00024000"],["70487.99000000","0.00000000"],["70487.98000000","0.00009000"],["70475.50000000","0.00032000"],["62644.89000000","0.00000000"]],"a":[["78306.12000000","1.98840000"],["78308.27000000","0.00007000"],["78309.64000000","0.01214000"],["78316.69000000","0.00400000"],["78318.73000000","2.22740000"],["78324.62000000","0.04000000"],["78336.87000000","0.00000000"],["78337.95000000","0.52553000"],["78340.90000000","0.00000000"],["78344.42000000","0.00000000"],["78353.21000000","0.00012000"],["78363.83000000","1.05156000"],["78380.79000000","0.00000000"],["78413.38000000","0.00012000"],["78418.47000000","0.00019000"],["78445.30000000","0.00111000"]]}}
{"rx":1788854559849476135, "m":{"e":"depthUpdate","E":1788854559814,"s":"BTCUSDT","U":99829877848,"u":99829877882,"b":[["78306.11000000","2.21460000"],["78301.15000000","0.00000000"],["78300.92000000","0.00000000"],["78300.28000000","0.11713000"],["78300.27000000","0.00000000"],["78300.23000000","0.01331000"],["78300.07000000","0.00400000"],["78295.47000000","0.00000000"],["78292.07000000","0.02000000"],["78258.51000000","0.00335000"],["78227.49000000","0.02000000"],["77131.52000000","0.00032000"],["70475.00000000","0.00020000"],["62656.00000000","0.00186000"]],"a":[["78306.14000000","0.03615000"],["78306.15000000","0.05000000"],["78306.20000000","0.05000000"],["78308.27000000","0.00000000"],["78309.53000000","0.01510000"],["78309.64000000","0.01228000"],["78311.74000000","0.13800000"],["78321.48000000","0.04200000"],["78335.03000000","0.00000000"],["78423.43000000","0.00031000"]]}}
{"rx":1788854559948169587, "m":{"e":"depthUpdate","E":1788854559914,"s":"BTCUSDT","U":99829877883,"u":99829877920,"b":[["78306.11000000","2.21468000"],["78298.05000000","0.00255000"],["78296.53000000","0.00047000"],["78294.11000000","0.00408000"],["78222.23000000","0.00000000"],["77131.52000000","0.00040000"],["70475.50000000","0.00048000"],["70475.00000000","0.00000000"],["62645.00000000","0.00284000"]],"a":[["78306.12000000","1.82328000"],["78306.14000000","0.03629000"],["78306.15000000","0.05014000"],["78306.20000000","0.05014000"],["78309.66000000","1.97967000"],["78310.78000000","0.01496000"],["78310.90000000","0.12769000"],["78313.33000000","0.00007000"],["78313.70000000","0.00255000"],["78316.38000000","0.00007000"],["78484.52000000","0.00111000"]]}}
{"rx":1788854560057382101, "m":{"e":"depthUpdate","E":1788854560014,"s":"BTCUSDT","U":99829877921,"u":99829877959,"b":[["78306.11000000","2.23791000"],["78304.02000000","0.00654000"],["78296.53000000","0.00000000"],["78295.25000000","0.00063000"],["78291.96000000","0.02007000"],["78291.52000000","0.00007000"],["78289.00000000","0.18865000"],["78288.05000000","0.02000000"],["78284.34000000","0.00007000"],["78282.81000000","0.00000000"],["78278.09000000","0.37581000"],["78240.24000000","0.02000000"],["78232.36000000","0.02000000"],["78113.87000000","0.02000000"],["78079.17000000","0.00000000"],["77131.52000000","0.00040000"],["76397.20000000","0.00252000"],["70475.00000000","0.00010000"],["62656.00000000","0.00155000"],["62644.89000000","0.00124000"]],"a":[["78306.12000000","1.62236000"],["78310.77000000","0.00011000"],["78315.03000000","0.00007000"],["78315.66000000","0.00007000"],["78321.53000000","0.03800000"],["78325.56000000","0.03400000"],["78326.34000000","0.00574000"]]}}
{"rx":1788854560146127351, "m":{"e":"depthUpdate","E":1788854560114,"s":"BTCUSDT","U":99829877960,"u":99829878000,"b":[["78306.11000000","2.23798000"],["78306.10000000","0.00084000"],["78304.45000000","0.06017000"],["78304.02000000","0.00661000"],["78302.50000000","0.06000000"],["78292.88000000","0.02000000"],["78292.72000000","0.02000000"],["78291.53000000","0.00007000"],["78291.52000000","0.00000000"],["78288.95000000","0.02000000"],["78282.41000000","0.00000000"],["78277.63000000","0.00000000"],["78258.51000000","0.00000000"],["78241.00000000","0.02000000"],["78233.39000000","0.02000000"],["78227.01000000","0.02000000"],["78113.87000000","0.00000000"],["77615.11000000","0.00000000"],["77131.52000000","0.00032000"],["77131.51000000","0.00030000"],["70475.50000000","0.00064000"],["70475.00000000","0.00000000"]],"a":[["78306.12000000","1.99456000"],["78310.53000000","0.00400000"],["78313.71000000","0.00000000"],["78315.88000000","0.00000000"],["78320.72000000","0.08000000"],["78324.60000000","0.02600000"],["78326.00000000","0.73000000"],["78334.29000000","0.00000000"],["78339.11000000","0.00000000"],["79480.72000000","0.00030000"]]}}
{"rx":1788854560245049823, "m":{"e":"depthUpdate","E":1788854560214,"s":"BTCUSDT","U":99829878001,"u":99829878023,"b":[["78304.28000000","0.00007000"],["78300.00000000","0.00200000"],["78292.09000000","0.02000000"],["78282.21000000","0.00000000"],["78281.45000000","0.00000000"],["78278.46000000","0.00000000"],["78259.50000000","0.00200000"],["78258.28000000","0.00000000"],["78240.39000000","0.02000000"],["78227.49000000","0.00000000"],["78099.77000000","0.00000000"],["78079.18000000","0.00802000"],["78078.71000000","0.02000000"],["77131.52000000","0.00032000"],["70475.50000000","0.00080000"],["70475.00000000","0.00000000"],["62656.00000000","0.00124000"]],"a":[["78313.35000000","0.00007000"],["78320.00000000","0.16131000"],["78321.50000000","0.20909000"],["78338.17000000","0.00000000"],["78379.97000000","0.00000000"]]}}
{"rx":1788854560338605571, "m":{"e":"depthUpdate","E":1788854560314,"s":"BTCUSDT","U":99829878024,"u":99829878041,"b":[["78306.11000000","2.23765000"],["78303.16000000","0.00000000"],["78239.38000000","1.26572000"],["78233.57000000","0.02000000"],["77292.28000000","0.00010000"],["77131.52000000","0.00032000"],["70487.98000000","0.00000000"],["70475.00000000","0.00000000"]],"a":[["78306.12000000","1.99408000"],["78309.43000000","0.00007000"],["78311.72000000","0.00017000"],["78315.83000000","0.00047000"],["78323.82000000","0.03000000"],["78511.41000000","0.00000000"],["82288.74000000","0.00000000"]]}}
{"rx":1788854560437875955, "m":{"e":"depthUpdate","E":1788854560414,"s":"BTCUSDT","U":99829878042,"u":99829878070,"b":[["78306.11000000","2.23775000"],["78306.10000000","0.00077000"],["78304.02000000","0.00021000"],["78281.64000000","0.00000000"],["78258.51000000","0.00335000"],["78250.17000000","1.02535000"],["77131.52000000","0.00032000"],["70475.50000000","0.00096000"],["70475.00000000","0.00000000"],["62656.00000000","0.00093000"]],"a":[["78306.12000000","2.05469000"],["78312.19000000","0.00000000"],["78317.87000000","0.00007000"],["78321.87000000","0.12767000"],["78321.96000000","0.00000000"],["78325.37000000","0.03800000"],["78325.53000000","0.03200000"],["78329.52000000","0.12766000"],["78335.06000000","0.00000000"],["78376.88000000","0.04977000"]]}}
{"rx":1788854560537238342, "m":{"e":"depthUpdate","E":1788854560514,"s":"BTCUSDT","U":99829878071,"u":99829878095,"b":[["78304.45000000","0.06017000"],["78304.02000000","0.00014000"],["78302.50000000","0.06007000"],["77131.52000000","0.00032000"],["70475.00000000","0.00000000"],["62644.89000000","0.00248000"]],"a":[["78321.58000000","0.03400000"],["78325.14000000","0.02800000"],["78335.26000000","0.00000000"],["78382.07000000","0.00000000"],["78388.58000000","0.00000000"],["78389.52000000","0.00000000"],["78389.73000000","0.03400000"],["78511.21000000","0.00000000"],["82921.18000000","0.00010000"]]}}
{"rx":1788854560638082350, "m":{"e":"depthUpdate","E":1788854560614,"s":"BTCUSDT","U":99829878096,"u":99829878140,"b":[["78306.11000000","2.23765000"],["78306.10000000","0.00084000"],["78304.28000000","0.00610000"],["78294.17000000","0.03110000"],["78256.63000000","0.00664000"],["78088.77000000","0.00000000"],["78088.08000000","0.02320000"],["78079.18000000","0.00000000"],["78078.72000000","0.00802000"],["77131.52000000","0.00032000"],["70475.50000000","0.00112000"],["70475.49000000","0.00009000"],["62656.00000000","0.00062000"]],"a":[["78306.12000000","1.68297000"],["78309.63000000","0.01200000"],["78310.53000000","0.00000000"],["78311.72000000","0.00417000"],["78313.69000000","0.02106000"],["78314.46000000","0.02000000"],["78314.89000000","0.01334000"],["78316.69000000","0.00000000"],["78318.75000000","2.65548000"],["78318.81000000","0.01295000"],["78321.53000000","0.05964000"],["78322.73000000","0.01321000"],["78326.65000000","0.01297000"],["78328.26000000","0.00000000"],["78329.37000000","0.02164000"],["78330.57000000","0.01281000"],["78335.15000000","0.00000000"],["78337.21000000","0.02152000"],["78345.05000000","0.02134000"],["78389.73000000","0.00000000"],["78389.79000000","0.00000000"],["78511.37000000","0.00000000"]]}}
{"rx":1788854560740474614, "m":{"e":"depthUpdate","E":1788854560714,"s":"BTCUSDT","U":99829878141,"u":99829878310,"b":[["78306.11000000","2.37934000"],["78306.10000000","0.00021000"],["78304.98000000","0.03057000"],["78304.45000000","0.06017000"],["78304.44000000","0.01295000"],["78304.28000000","0.00624000"],["78302.51000000","0.00000000"],["78302.50000000","0.06000000"],["78302.30000000","0.02088000"],["78301.16000000","0.00000000"],["78300.07000000","0.00000000"],["78299.31000000","0.00400000"],["78298.05000000","0.00000000"],["78296.35000000","0.37581000"],["78294.08000000","0.00000000"],["78292.32000000","0.00000000"],["78283.81000000","0.31935000"],["78278.08000000","0.63338000"],["78275.56000000","0.34503000"],["78269.16000000","1.26523000"],["78263.49000000","0.55696000"],["78262.51000000","0.00000000"],["78259.24000000","0.37069000"],["78239.38000000","0.00000000"],["77131.52000000","0.00032000"],["70475.50000000","0.00128000"],["62644.89000000","0.00248000"]],"a":[["78306.12000000","0.66835000"],["78306.14000000","0.00034000"],["78306.52000000","0.06580000"],["78307.41000000","0.00007000"],["78307.74000000","0.00000000"],["78308.91000000","0.00206000"],["78309.53000000","0.01510000"],["78309.62000000","0.00000000"],["78309.63000000","0.00014000"],["78309.64000000","0.00028000"],["78309.65000000","0.06461000"],["78309.66000000","0.00000000"],["78310.77000000","0.00000000"],["78311.72000000","0.00000000"],["78311.74000000","0.00000000"],["78312.01000000","0.00000000"],["78312.18000000","0.00000000"],["78313.32000000","0.00024000"],["78313.51000000","0.00400000"],["78313.54000000","0.02000000"],["78313.55000000","0.60573000"],["78313.56000000","0.00000000"],["78313.69000000","0.00000000"],["78313.70000000","0.00000000"],["78314.45000000","0.00017000"],["78314.89000000","0.00000000"],["78315.34000000","0.00000000"],["78315.78000000","0.00400000"],["78315.89000000","0.00638000"],["78316.67000000","0.00048000"],["78316.81000000","0.00000000"],["78317.10000000","0.00000000"],["78317.50000000","0.00000000"],["78318.81000000","0.30000000"],["78319.99000000","0.07500000"],["78321.53000000","0.03800000"],["78322.73000000","0.00000000"],["78323.38000000","0.00000000"],["78323.58000000","0.00000000"],["78325.38000000","0.00000000"],["78326.00000000","0.03000000"],["78326.33000000","0.31935000"],["78326.65000000","0.00000000"],["78328.79000000","0.12255000"],["78329.37000000","0.00000000"],["78330.57000000","0.00000000"],["78331.32000000","0.00007000"],["78332.93000000","0.00000000"],["78334.86000000","0.00000000"],["78335.66000000","0.31935000"],["78335.85000000","0.00000000"],["78337.21000000","0.00000000"],["78345.05000000","0.00000000"],["78347.64000000","0.00007000"],["78367.84000000","0.34463000"],["78393.89000000","2.29867000"],["78513.21000000","0.00000000"],["78541.92000000","2.46841000"]]}}
{"rx":1788854560841199518, "m":{"e":"depthUpdate","E":1788854560814,"s":"BTCUSDT","U":99829878311,"u":99829878385,"b":[["78306.11000000","2.38131000"],["78306.10000000","0.00028000"],["78305.75000000","0.00797000"],["78305.73000000","0.00400000"],["78304.98000000","0.03071000"],["78304.45000000","0.06017000"],["78303.24000000","0.01567000"],["78302.70000000","0.00200000"],["78302.60000000","0.01000000"],["78301.99000000","0.01822000"],["78290.42000000","0.00150000"],["78285.22000000","0.00000000"],["78259.50000000","0.00000000"],["77131.52000000","0.00040000"],["62656.00000000","0.00031000"]],"a":[["78306.12000000","0.66864000"],["78306.14000000","0.00020000"],["78306.20000000","0.05014000"],["78306.52000000","0.06594000"],["78309.53000000","0.01510000"],["78309.63000000","0.00000000"],["78309.64000000","0.00014000"],["78309.65000000","0.19499000"],["78310.78000000","0.01510000"],["78310.88000000","0.00000000"],["78311.99000000","0.00013000"],["78313.08000000","0.46385000"],["78313.35000000","0.00000000"],["78313.53000000","0.00000000"],["78313.54000000","0.00000000"],["78315.78000000","0.00000000"],["78317.11000000","0.00400000"],["78318.72000000","0.02400000"],["78318.73000000","2.22517000"],["78326.33000000","0.00000000"],["78327.98000000","0.31934000"],["78339.94000000","0.00223000"],["78359.40000000","0.00400000"],["78512.50000000","0.12777000"],["78512.54000000","0.00000000"]]}}
{"rx":1788854560947991198, "m":{"e":"depthUpdate","E":1788854560914,"s":"BTCUSDT","U":99829878386,"u":99829878426,"b":[["78306.11000000","2.38180000"],["78306.10000000","0.00063000"],["78305.73000000","0.00000000"],["78304.99000000","0.00014000"],["78304.46000000","0.00692000"],["78304.28000000","0.00021000"],["78295.02000000","0.00007000"],["78294.11000000","0.00000000"],["78255.83000000","0.00000000"],["78223.64000000","0.00000000"],["78221.77000000","0.00007000"],["77131.52000000","0.00040000"],["70475.50000000","0.00144000"]],"a":[["78306.12000000","0.67014000"],["78306.52000000","0.00014000"],["78311.34000000","0.46385000"],["78312.21000000","0.46385000"],["78313.54000000","2.29867000"],["78316.58000000","0.00400000"],["78337.33000000","0.00000000"],["78375.96000000","0.00000000"],["78407.84000000","0.00000000"],["78426.97000000","0.04298000"],["78512.50000000","0.00000000"],["78512.74000000","0.00000000"]]}}
{"rx":1788854561067727393, "m":{"e":"depthUpdate","E":1788854561014,"s":"BTCUSDT","U":99829878427,"u":99829878547,"b":[["78306.11000000","2.07166000"],["78306.10000000","0.00076000"],["78306.09000000","0.00013000"],["78304.99000000","0.00000000"],["78304.98000000","0.00014000"],["78304.49000000","0.01320000"],["78304.46000000","0.00706000"],["78304.44000000","0.00014000"],["78304.28000000","0.00007000"],["78304.25000000","0.00000000"],["78303.98000000","0.00000000"],["78302.51000000","0.00007000"],["78302.30000000","0.00000000"],["78301.99000000","0.01567000"],["78301.14000000","0.00000000"],["78299.64000000","0.00255000"],["78299.31000000","0.00000000"],["77131.52000000","0.00040000"],["70475.49000000","0.00000000"],["70475.48000000","0.00009000"],["62656.00000000","0.00000000"]],"a":[["78306.12000000","1.73563000"],["78306.14000000","0.05588000"],["78306.20000000","0.05014000"],["78306.52000000","0.00000000"],["78306.64000000","0.06580000"],["78307.86000000","0.00000000"],["78308.73000000","0.46385000"],["78308.91000000","0.00000000"],["78309.59000000","0.20638000"],["78309.60000000","0.46246000"],["78309.65000000","0.00014000"],["78310.46000000","0.00000000"],["78310.47000000","0.00000000"],["78310.90000000","0.12783000"],["78311.33000000","0.01600000"],["78311.34000000","0.00000000"],["78312.21000000","0.00000000"],["78313.08000000","0.46385000"],["78313.52000000","0.46385000"],["78313.53000000","1.28924000"],["78313.55000000","0.00000000"],["78314.06000000","0.00400000"],["78316.58000000","0.00000000"],["78317.11000000","0.00000000"],["78318.72000000","0.00800000"],["78319.68000000","0.02000000"],["78328.79000000","0.10255000"],["78347.64000000","0.00000000"]]}}
{"rx":1788854561154190320, "m":{"e":"depthUpdate","E":1788854561114,"s":"BTCUSDT","U":99829878548,"u":99829878725,"b":[["78306.11000000","1.25426000"],["78306.10000000","0.00076000"],["78305.75000000","0.00797000"],["78304.98000000","0.00000000"],["78304.45000000","0.06017000"],["78304.44000000","0.00000000"],["78303.24000000","0.01581000"],["78302.60000000","0.01014000"],["78300.23000000","0.00000000"],["78299.64000000","0.00000000"],["78298.55000000","0.00000000"],["78298.28000000","0.00008000"],["78298.19000000","0.00000000"],["78298.12000000","0.00000000"],["78297.95000000","0.00000000"],["78297.94000000","0.00000000"],["78297.93000000","0.00000000"],["78297.91000000","0.00000000"],["78297.60000000","0.00000000"],["78297.41000000","0.01336000"],["78296.36000000","0.00000000"],["78295.68000000","0.00054000"],["78295.63000000","0.00255000"],["78295.49000000","0.00190000"],["78294.08000000","0.00400000"],["78291.84000000","0.77571000"],["78290.42000000","0.00000000"],["78290.26000000","0.00000000"],["78289.00000000","0.00000000"],["78288.04000000","0.00000000"],["78287.31000000","0.31934000"],["78285.08000000","0.00150000"],["78283.81000000","0.00000000"],["78282.63000000","0.00000000"],["78279.07000000","0.31934000"],["78275.56000000","0.00000000"],["78275.34000000","0.00024000"],["78273.25000000","0.02000000"],["78269.16000000","0.00000000"],["78244.32000000","1.26564000"],["78244.31000000","0.34517000"],["78236.50000000","1.26576000"],["78230.43000000","2.29867000"],["77601.35000000","0.00010000"],["77131.52000000","0.00032000"],["77131.51000000","0.00030000"],["70475.50000000","0.00160000"],["70475.00000000","0.00000000"],["62656.00000000","0.00000000"]],"a":[["78306.12000000","4.67798000"],["78306.13000000","0.00041000"],["78306.14000000","0.05602000"],["78306.20000000","0.05014000"],["78306.59000000","0.00026000"],["78306.64000000","0.06594000"],["78307.74000000","0.00007000"],["78308.00000000","0.03000000"],["78308.27000000","0.00030000"],["78308.28000000","0.01261000"],["78308.73000000","0.00014000"],["78309.42000000","0.00025000"],["78309.53000000","0.01510000"],["78309.57000000","0.66496000"],["78309.58000000","2.00341000"],["78309.59000000","0.00000000"],["78309.60000000","0.00000000"],["78309.64000000","0.00000000"],["78309.65000000","0.00000000"],["78309.71000000","0.00400000"],["78310.00000000","0.00500000"],["78310.78000000","0.01496000"],["78310.90000000","0.12769000"],["78311.33000000","0.00000000"],["78311.34000000","0.00000000"],["78312.00000000","0.00500000"],["78312.21000000","0.00000000"],["78313.06000000","0.00000000"],["78313.07000000","0.01200000"],["78313.08000000","0.00000000"],["78313.32000000","0.00000000"],["78313.52000000","0.00000000"],["78314.00000000","0.00500000"],["78314.06000000","0.00000000"],["78314.45000000","0.00000000"],["78315.83000000","0.00000000"],["78316.00000000","0.00500000"],["78316.67000000","0.00000000"],["78321.99000000","0.31934000"],["78327.98000000","0.00000000"],["78329.99000000","0.31934000"],["78335.66000000","0.00000000"],["78354.00000000","0.03400000"],["78356.70000000","0.00000000"],["78359.40000000","0.00000000"],["78403.21000000","0.00025000"],["78417.11000000","0.00000000"],["78512.49000000","0.00000000"],["79480.72000000","0.00030000"]]}}
{"rx":1788854561270702293, "m":{"e":"depthUpdate","E":1788854561214,"s":"BTCUSDT","U":99829878726,"u":99829878757,"b":[["78306.11000000","1.23254000"],["78304.46000000","0.00028000"],["78301.31000000","0.00026000"],["78297.41000000","0.00000000"],["78294.04000000","0.00400000"],["78274.00000000","0.73000000"],["77131.52000000","0.00032000"],["62644.89000000","0.00217000"]],"a":[["78306.12000000","4.68208000"],["78306.59000000","0.00000000"],["78307.02000000","0.00762000"],["78308.00000000","0.06014000"],["78308.28000000","0.01261000"],["78308.73000000","0.00000000"],["78309.53000000","0.01510000"],["78310.00000000","0.01000000"],["78312.00000000","0.01000000"],["78318.00000000","0.00500000"]]}}
{"rx":1788854561354120866, "m":{"e":"depthUpdate","E":1788854561314,"s":"BTCUSDT","U":99829878758,"u":99829878794,"b":[["78306.11000000","1.23254000"],["78306.10000000","0.00076000"],["78305.79000000","0.00014000"],["78305.78000000","0.14038000"],["78304.50000000","0.00000000"],["78304.49000000","0.01320000"],["78304.46000000","0.00014000"],["78303.75000000","0.00007000"],["78302.50000000","0.06014000"],["77131.52000000","0.00032000"],["70475.50000000","0.00176000"],["62645.00000000","0.00284000"]],"a":[["78306.14000000","0.08730000"],["78307.58000000","0.06768000"],["78308.19000000","0.00007000"],["78309.71000000","0.00000000"],["78311.19000000","0.00400000"],["78311.76000000","0.00000000"],["78313.52000000","0.00400000"],["78314.00000000","0.01000000"],["78316.00000000","0.01000000"],["78318.00000000","0.01000000"],["78340.00000000","0.73000000"],["78362.98000000","0.00408000"],["78512.50000000","0.00000000"]]}}
{"rx":1788854561451471257, "m":{"e":"depthUpdate","E":1788854561414,"s":"BTCUSDT","U":99829878795,"u":99829878831,"b":[["78306.11000000","1.55275000"],["78302.50000000","0.06000000"],["78297.89000000","0.02122000"],["78297.65000000","0.00000000"],["78296.75000000","0.00000000"],["78262.45000000","1.59346000"],["78230.44000000","2.03025000"],["78228.91000000","0.00000000"],["78218.85000000","0.89245000"],["78218.84000000","1.00210000"],["78218.60000000","0.00000000"],["77131.52000000","0.00032000"],["70475.50000000","0.00192000"],["62644.89000000","0.00186000"]],"a":[["78306.12000000","4.63747000"],["78307.02000000","0.00762000"],["78307.58000000","0.06782000"],["78307.60000000","0.00400000"],["78307.97000000","0.04032000"],["78309.43000000","0.00000000"],["78309.53000000","0.01496000"],["78313.99000000","0.31864000"],["78317.87000000","0.00000000"],["78391.99000000","0.72928000"]]}}
{"rx":1788854561545185893, "m":{"e":"depthUpdate","E":1788854561514,"s":"BTCUSDT","U":99829878832,"u":99829878863,"b":[["78306.11000000","1.48489000"],["78297.89000000","0.00000000"],["78295.63000000","0.00000000"],["78285.38000000","0.00500000"],["78284.28000000","0.00000000"],["78227.01000000","0.00000000"],["78157.32000000","0.00000000"],["78154.49000000","1.53303000"],["77131.52000000","0.00032000"],["62644.89000000","0.00310000"]],"a":[["78306.12000000","4.63541000"],["78306.64000000","0.00014000"],["78307.58000000","0.06782000"],["78307.97000000","0.04046000"],["78308.28000000","0.01247000"],["78317.87000000","0.00007000"],["78382.07000000","0.02800000"],["78389.73000000","0.03400000"],["78448.62000000","0.00000000"],["78512.87000000","0.00000000"]]}}
{"rx":1788854561657993004, "m":{"e":"depthUpdate","E":1788854561614,"s":"BTCUSDT","U":99829878864,"u":99829878910,"b":[["78306.11000000","1.16482000"],["78305.79000000","0.00000000"],["78305.78000000","0.00000000"],["78304.50000000","0.00014000"],["78302.70000000","0.00000000"],["78301.31000000","0.00000000"],["78296.35000000","0.00000000"],["78294.44000000","0.00000000"],["78294.20000000","0.01289000"],["78294.08000000","0.00000000"],["78293.83000000","0.02109000"],["78292.92000000","0.00400000"],["78287.31000000","0.00000000"],["78285.39000000","0.31936000"],["78254.10000000","0.00200000"],["77131.52000000","0.00032000"],["70475.50000000","0.00208000"],["62645.00000000","0.00484000"],["62644.89000000","0.00279000"]],"a":[["78306.12000000","4.63559000"],["78306.13000000","0.00027000"],["78306.14000000","0.08723000"],["78306.20000000","0.05014000"],["78306.64000000","0.00000000"],["78307.17000000","0.00000000"],["78308.03000000","0.00400000"],["78308.28000000","0.01261000"],["78309.42000000","0.00000000"],["78309.56000000","0.37581000"],["78310.80000000","0.00400000"],["78311.19000000","0.00000000"],["78316.14000000","0.00408000"],["78317.97000000","0.00000000"],["78335.52000000","0.34477000"],["78354.00000000","0.03000000"],["78367.84000000","0.00000000"]]}}
{"rx":1788854561759781113, "m":{"e":"depthUpdate","E":1788854561714,"s":"BTCUSDT","U":99829878911,"u":99829878950,"b":[["78306.11000000","1.16482000"],["78306.10000000","0.00076000"],["78301.55000000","0.08228000"],["78301.14000000","0.00026000"],["78294.17000000","0.00000000"],["78241.98000000","0.00408000"],["78148.36000000","0.00206000"],["77131.52000000","0.00032000"],["72040.91000000","0.00014000"],["62645.00000000","0.00284000"],["62644.89000000","0.00299000"]],"a":[["78306.12000000","4.71963000"],["78308.00000000","0.12014000"],["78309.57000000","0.68645000"],["78310.00000000","0.02000000"],["78311.58000000","0.01283000"],["78315.50000000","0.01328000"],["78317.41000000","0.02082000"],["78319.42000000","0.01304000"],["78323.34000000","0.01303000"],["78325.25000000","0.02138000"],["78327.26000000","0.01279000"],["78333.09000000","0.02112000"],["78340.93000000","0.02176000"],["78443.99000000","0.47463000"],["78445.78000000","1.53303000"],["78455.18000000","0.00103000"],["79043.65000000","0.00018000"]]}}
{"rx":1788854561838783167, "m":{"e":"depthUpdate","E":1788854561814,"s":"BTCUSDT","U":99829878951,"u":99829879067,"b":[["78306.11000000","1.96853000"],["78303.75000000","0.00014000"],["78301.55000000","0.00000000"],["78299.67000000","0.02101000"],["78298.32000000","0.01328000"],["78297.93000000","0.03057000"],["78294.06000000","1.24186000"],["78294.05000000","2.29867000"],["78294.04000000","0.00000000"],["78294.03000000","0.00000000"],["78292.92000000","0.00000000"],["78286.82000000","0.38331000"],["78279.67000000","0.09430000"],["78277.72000000","0.10262000"],["78269.63000000","0.00000000"],["78256.80000000","0.00200000"],["78254.10000000","0.00000000"],["78244.32000000","0.00000000"],["78230.45000000","0.00000000"],["78230.44000000","0.00000000"],["78230.43000000","0.00000000"],["78148.36000000","0.00000000"],["77131.52000000","0.00040000"],["70475.50000000","0.00224000"],["70475.48000000","0.00000000"],["62644.89000000","0.00248000"]],"a":[["78306.12000000","1.70029000"],["78306.13000000","0.00041000"],["78307.60000000","0.00000000"],["78307.74000000","0.00000000"],["78308.03000000","0.00000000"],["78308.27000000","0.00000000"],["78308.92000000","0.00000000"],["78309.52000000","0.00018000"],["78309.55000000","0.00000000"],["78309.56000000","0.00000000"],["78309.57000000","0.06645000"],["78309.58000000","0.00000000"],["78309.85000000","0.00000000"],["78309.93000000","0.00000000"],["78309.99000000","0.00000000"],["78310.18000000","0.02102000"],["78311.58000000","0.00000000"],["78311.59000000","0.01289000"],["78311.73000000","0.00007000"],["78312.00000000","0.02000000"],["78313.07000000","0.00000000"],["78313.32000000","0.00027000"],["78313.50000000","0.00638000"],["78313.52000000","0.00000000"],["78314.00000000","0.02000000"],["78314.93000000","0.00000000"],["78315.72000000","0.00007000"],["78315.89000000","0.00000000"],["78316.00000000","0.02000000"],["78317.67000000","0.00189000"],["78317.99000000","0.00800000"],["78318.00000000","0.02000000"],["78318.72000000","0.01200000"],["78320.00000000","0.17131000"],["78321.99000000","0.00000000"],["78324.59000000","0.31936000"],["78329.99000000","0.00000000"],["78332.93000000","0.31936000"],["78455.18000000","0.00000000"],["78485.35000000","0.03057000"]]}}
{"rx":1788854561938088286, "m":{"e":"depthUpdate","E":1788854561914,"s":"BTCUSDT","U":99829879068,"u":99829879111,"b":[["78306.11000000","1.93021000"],["78304.45000000","0.06638000"],["78300.64000000","0.00400000"],["78299.67000000","0.00000000"],["78299.48000000","0.02093000"],["78298.32000000","0.00000000"],["78298.07000000","0.00007000"],["78298.01000000","0.01286000"],["78295.26000000","0.00400000"],["78289.83000000","0.00007000"],["78215.67000000","0.00007000"],["77131.52000000","0.00040000"],["70475.50000000","0.00240000"]],"a":[["78307.74000000","0.00007000"],["78309.57000000","0.19749000"],["78311.34000000","0.00000000"],["78311.73000000","0.00014000"],["78312.07000000","0.00400000"],["78312.21000000","0.00000000"],["78313.08000000","0.46385000"],["78313.49000000","0.00000000"],["78313.52000000","0.01200000"],["78315.72000000","0.00014000"],["78317.99000000","0.00000000"],["78318.72000000","0.00800000"]]}}
{"rx":1788854562038182195, "m":{"e":"depthUpdate","E":1788854562014,"s":"BTCUSDT","U":99829879112,"u":99829879130,"b":[["78306.11000000","1.93406000"],["78300.64000000","0.00000000"],["78299.66000000","0.00400000"],["77131.52000000","0.00040000"],["62644.89000000","0.00341000"]],"a":[["78309.52000000","0.00000000"],["78310.77000000","0.00024000"],["78313.07000000","0.00400000"]]}}
{"rx":1788854562137704542, "m":{"e":"depthUpdate","E":1788854562114,"s":"BTCUSDT","U":99829879131,"u":99829879139,"b":[["78306.11000000","1.81222000"],["77131.52000000","0.00032000"],["70475.50000000","0.00256000"]],"a":[["78306.12000000","1.70077000"],["78310.01000000","0.00400000"],["78312.07000000","0.00000000"],["78313.40000000","0.00400000"],["78510.65000000","0.00000000"]]}}
{"rx":1788854562237679378, "m":{"e":"depthUpdate","E":1788854562214,"s":"BTCUSDT","U":99829879140,"u":99829879149,"b":[["77131.52000000","0.00032000"],["77131.51000000","0.00030000"],["72040.91000000","0.00000000"],["62644.89000000","0.00310000"]],"a":[["78370.90000000","0.00000000"],["78449.37000000","0.00000000"],["79480.72000000","0.00030000"]]}}
{"rx":1788854562343759643, "m":{"e":"depthUpdate","E":1788854562314,"s":"BTCUSDT","U":99829879150,"u":99829879170,"b":[["78306.11000000","1.81236000"],["78306.10000000","0.00090000"],["78305.79000000","0.00014000"],["78305.78000000","0.12253000"],["78305.07000000","0.00000000"],["78304.50000000","0.00000000"],["78304.46000000","0.00598000"],["78304.45000000","0.06017000"],["78281.13000000","0.00408000"],["77131.52000000","0.00032000"],["70475.50000000","0.00272000"],["70475.00000000","0.00000000"]],"a":[["78337.00000000","0.70000000"],["78357.08000000","0.00319000"],["78435.92000000","0.00127000"]]}}
